File: Data/Dataset2_Water_Organic/4_XRD/No_01_Hematite_Butanol_1.ras
*RAS_DATA_START
*RAS_HEADER_START
*DISP_FMT_X "%.2f"
*DISP_FMT_Y "%.0f"
*DISP_FULLSCALE "14715.0000000000"
*DISP_LINE_COLOR "255.0000000000"
*DISP_LINE_STYLE "0.0000000000"
*DISP_LINE_WIDTH "0.2500000000"
*DISP_NOTE "測定データ-1"
*DISP_OFFSET_Y "0.0000000000"
*DISP_PEAKSEARCH_UNIT_Y "cps"
*DISP_RANGE_BOTTOM "0.0000000000"
*DISP_RANGE_LEFT "20.0000000000"
*DISP_RANGE_LOGCUTOFF "0.0100000000"
*DISP_RANGE_RIGHT "70.0000000000"
*DISP_RANGE_TOP "14715.0000000000"
*DISP_SCALE_MODE_Y "0.0000000000"
*DISP_TAB_NAME "2θ/θ"
*DISP_TITLE_Y "強度"
*DISP_UNIT_Y "cps"
*DISP_WINDOW_NAME "MSG_MACROENGINE"
*FILE_COMMENT " "
*FILE_MD5 ""
*FILE_MEMO " "
*FILE_OPERATOR "Administrator"
*FILE_SAMPLE " "
*FILE_TYPE "RAS_RAW"
*FILE_USERGROUP "システムマネージャ"
*FILE_VERSION "1.0000000000"
*HW_ATTACHMENT_ID "ATT0025"
*HW_ATTACHMENT_NAME "標準|Standard"
*HW_COUNTER_ID-0 "CUT0025"
*HW_COUNTER_ID-1 "CUT0020"
*HW_COUNTER_ID-2 "CUT0020"
*HW_COUNTER_ID-3 "CSL0021"
*HW_COUNTER_ID-4 "CMC0021"
*HW_COUNTER_NAME-0 "D/teX Ultra|D/teX Ultra"
*HW_COUNTER_NAME-1 "None|None"
*HW_COUNTER_NAME-2 "None|None"
*HW_COUNTER_NAME-3 "BBM|BBM"
*HW_COUNTER_NAME-4 "検出器モノクロメータ|Detector monochromator"
*HW_COUNTER_SELECT_NAME "D/teX Ultra|D/teX Ultra"
*HW_GONIOMETER_ID "GON0023"
*HW_GONIOMETER_NAME "SmartLab|SmartLab"
*HW_GONIOMETER_RADIUS-0 "90.0"
*HW_GONIOMETER_RADIUS-1 "114.0"
*HW_GONIOMETER_RADIUS-2 "190.0"
*HW_GONIOMETER_RADIUS-3 "300.0"
*HW_GONIOMETER_RADIUS-4 "187.0"
*HW_GONIOMETER_RADIUS-5 "300.0"
*HW_GONIOMETER_RADIUS-6 "113.0"
*HW_GONIOMETER_RADIUS-7 "331.0"
*HW_I_OPT_ID-0 "CBO0021"
*HW_I_OPT_ID-1 "ICR0023"
*HW_I_OPT_ID-2 "ISL0021"
*HW_I_OPT_ID-3 "ISO0021"
*HW_I_OPT_ID-4 "IAD0021"
*HW_I_OPT_ID-5 "IPR0001"
*HW_I_OPT_NAME-0 "CBOユニット|CBO unit"
*HW_I_OPT_NAME-1 "標準入射光学ユニット|Standard incident optical unit"
*HW_I_OPT_NAME-2 "標準入射スリットボックス|Standard incident slit box"
*HW_I_OPT_NAME-3 "入射平行スリット|Incident parallel slit"
*HW_I_OPT_NAME-4 "長手制限スリット|Length limiting slit"
*HW_I_OPT_NAME-5 "None|None"
*HW_R_ATTENUATER_AUTOMODE "0"
*HW_R_OPT_ID-0 "RSS0021"
*HW_R_OPT_ID-1 "RCR0023"
*HW_R_OPT_ID-2 "RSO0021"
*HW_R_OPT_ID-3 "RRS0021"
*HW_R_OPT_ID-4 "ATN0021"
*HW_R_OPT_ID-5 "RFL0021"
*HW_R_OPT_ID-6 "RAD0021"
*HW_R_OPT_NAME-0 "標準受光スリットボックス1|Standard receiving slit box # 1"
*HW_R_OPT_NAME-1 "標準受光光学ユニット1|Standard receiving unit # 1"
*HW_R_OPT_NAME-2 "標準受光光学ユニット2|Standard receiving optical unit # 2"
*HW_R_OPT_NAME-3 "標準受光スリットボックス2|Standard receiving slit box # 2"
*HW_R_OPT_NAME-4 "標準アッテネータ|Standard Attenuator"
*HW_R_OPT_NAME-5 "Cu Kβ|Cu K-beta"
*HW_R_OPT_NAME-6 "調整用受光スリット|Alignment receiving slit"
*HW_SAMPLE_HOLDER_ID "SMP0023"
*HW_SAMPLE_HOLDER_NAME "標準Zステージ|Standard Z stage"
*HW_XG_CURRENT_MAX "50"
*HW_XG_CURRENT_MIN "2"
*HW_XG_CURRENT_RESOLUTION "1"
*HW_XG_CURRENT_UNIT "mA"
*HW_XG_FOCUS "1mm x 10mm"
*HW_XG_FOCUS_TYPE "Normal"
*HW_XG_ID ""
*HW_XG_NAME "3kW 封入管(ID:1200)|3kW Sealed tube(ID:1200)"
*HW_XG_TARGET_ATOMIC_NUMBER "29.0000000000"
*HW_XG_TARGET_NAME "Cu"
*HW_XG_TYPE "Hermetic"
*HW_XG_VOLTAGE_MAX "60"
*HW_XG_VOLTAGE_MIN "20"
*HW_XG_VOLTAGE_RESOLUTION "1"
*HW_XG_VOLTAGE_UNIT "kV"
*HW_XG_WATT_MAX "1.500"
*HW_XG_WATT_UNIT "kW"
*HW_XG_WAVE_LENGTH_ALPHA1 "1.540593"
*HW_XG_WAVE_LENGTH_ALPHA2 "1.544414"
*HW_XG_WAVE_LENGTH_BETA "1.392250"
*MEAS_COND_AXIS_NAME-0 "2θ/θ"
*MEAS_COND_AXIS_NAME-1 "2θ"
*MEAS_COND_AXIS_NAME-2 "ω"
*MEAS_COND_AXIS_NAME-3 "Z"
*MEAS_COND_AXIS_NAME-4 "2θ/ω"
*MEAS_COND_AXIS_NAME-5 "θs"
*MEAS_COND_AXIS_NAME-6 "θd"
*MEAS_COND_AXIS_NAME-7 "Ts"
*MEAS_COND_AXIS_NAME-8 "CBO選択スリット"
*MEAS_COND_AXIS_NAME-9 "M"
*MEAS_COND_AXIS_NAME-10 "入射平行スリット"
*MEAS_COND_AXIS_NAME-11 "入射スリット"
*MEAS_COND_AXIS_NAME-12 ""
*MEAS_COND_AXIS_NAME-13 "Zs"
*MEAS_COND_AXIS_NAME-14 "入射光学素子"
*MEAS_COND_AXIS_NAME-15 "長手制限スリット"
*MEAS_COND_AXIS_NAME-16 "センタースリット"
*MEAS_COND_AXIS_NAME-17 "フィルター"
*MEAS_COND_AXIS_NAME-18 "受光スリット1"
*MEAS_COND_AXIS_NAME-19 "受光スリット2"
*MEAS_COND_AXIS_NAME-20 "受光光学素子"
*MEAS_COND_AXIS_NAME-21 "受光平行スリット"
*MEAS_COND_AXIS_NAME-22 "調整用受光スリット"
*MEAS_COND_AXIS_NAME-23 ""
*MEAS_COND_AXIS_NAME-24 ""
*MEAS_COND_AXIS_NAME-25 "Zd"
*MEAS_COND_AXIS_NAME-26 "アッテネータ"
*MEAS_COND_AXIS_NAME-27 "検出器モノクロメータ"
*MEAS_COND_AXIS_NAME-28 "モノクロメータスリット"
*MEAS_COND_AXIS_NAME-29 "プライマリビーム"
*MEAS_COND_AXIS_NAME-30 "PHA"
*MEAS_COND_AXIS_NAME_INTERNAL-0 "TwoThetaTheta"
*MEAS_COND_AXIS_NAME_INTERNAL-1 "TwoTheta"
*MEAS_COND_AXIS_NAME_INTERNAL-2 "Omega"
*MEAS_COND_AXIS_NAME_INTERNAL-3 "Z"
*MEAS_COND_AXIS_NAME_INTERNAL-4 "TwoThetaOmega"
*MEAS_COND_AXIS_NAME_INTERNAL-5 "ThetaS"
*MEAS_COND_AXIS_NAME_INTERNAL-6 "ThetaD"
*MEAS_COND_AXIS_NAME_INTERNAL-7 "Ts"
*MEAS_COND_AXIS_NAME_INTERNAL-8 "CBO"
*MEAS_COND_AXIS_NAME_INTERNAL-9 "CBO-M"
*MEAS_COND_AXIS_NAME_INTERNAL-10 "IncidentSollerSlit"
*MEAS_COND_AXIS_NAME_INTERNAL-11 "IncidentSlitBox"
*MEAS_COND_AXIS_NAME_INTERNAL-12 "IncidentSlitBox-_Axis"
*MEAS_COND_AXIS_NAME_INTERNAL-13 "Zs"
*MEAS_COND_AXIS_NAME_INTERNAL-14 "IncidentMonochromator"
*MEAS_COND_AXIS_NAME_INTERNAL-15 "IncidentAxdSlit"
*MEAS_COND_AXIS_NAME_INTERNAL-16 "CenterSlit"
*MEAS_COND_AXIS_NAME_INTERNAL-17 "Filter"
*MEAS_COND_AXIS_NAME_INTERNAL-18 "ReceivingSlitBox1"
*MEAS_COND_AXIS_NAME_INTERNAL-19 "ReceivingSlitBox2"
*MEAS_COND_AXIS_NAME_INTERNAL-20 "ReceivingOptics"
*MEAS_COND_AXIS_NAME_INTERNAL-21 "ReceivingSollerSlit"
*MEAS_COND_AXIS_NAME_INTERNAL-22 "ReceivingAxdSlit"
*MEAS_COND_AXIS_NAME_INTERNAL-23 "ReceivingSlitBox1-_Axis"
*MEAS_COND_AXIS_NAME_INTERNAL-24 "ReceivingSlitBox2-_Axis"
*MEAS_COND_AXIS_NAME_INTERNAL-25 "ReceivingSlitBox2-Zd"
*MEAS_COND_AXIS_NAME_INTERNAL-26 "Attenuator"
*MEAS_COND_AXIS_NAME_INTERNAL-27 "CounterMonochromator"
*MEAS_COND_AXIS_NAME_INTERNAL-28 "CounterSlit"
*MEAS_COND_AXIS_NAME_INTERNAL-29 "IncidentPrimary"
*MEAS_COND_AXIS_NAME_INTERNAL-30 "PHA"
*MEAS_COND_AXIS_NAME_MAGICNO-0 "83951616.0000000000"
*MEAS_COND_AXIS_NAME_MAGICNO-1 "268632064.0000000000"
*MEAS_COND_AXIS_NAME_MAGICNO-2 "268500992.0000000000"
*MEAS_COND_AXIS_NAME_MAGICNO-3 "285278208.0000000000"
*MEAS_COND_AXIS_NAME_MAGICNO-4 "83951616.0000000000"
*MEAS_COND_AXIS_NAME_MAGICNO-5 "131072.0000000000"
*MEAS_COND_AXIS_NAME_MAGICNO-6 "131072.0000000000"
*MEAS_COND_AXIS_NAME_MAGICNO-7 "318898176.0000000000"
*MEAS_COND_AXIS_NAME_MAGICNO-8 "20971521.0000000000"
*MEAS_COND_AXIS_NAME_MAGICNO-9 "285343744.0000000000"
*MEAS_COND_AXIS_NAME_MAGICNO-10 "20971521.0000000000"
*MEAS_COND_AXIS_NAME_MAGICNO-11 "22020097.0000000000"
*MEAS_COND_AXIS_NAME_MAGICNO-12 "25165824.0000000000"
*MEAS_COND_AXIS_NAME_MAGICNO-13 "318898176.0000000000"
*MEAS_COND_AXIS_NAME_MAGICNO-14 "1.0000000000"
*MEAS_COND_AXIS_NAME_MAGICNO-15 "20971521.0000000000"
*MEAS_COND_AXIS_NAME_MAGICNO-16 "20971521.0000000000"
*MEAS_COND_AXIS_NAME_MAGICNO-17 "20971521.0000000000"
*MEAS_COND_AXIS_NAME_MAGICNO-18 "23068673.0000000000"
*MEAS_COND_AXIS_NAME_MAGICNO-19 "23068673.0000000000"
*MEAS_COND_AXIS_NAME_MAGICNO-20 "20971521.0000000000"
*MEAS_COND_AXIS_NAME_MAGICNO-21 "20971521.0000000000"
*MEAS_COND_AXIS_NAME_MAGICNO-22 "20971521.0000000000"
*MEAS_COND_AXIS_NAME_MAGICNO-23 "25165824.0000000000"
*MEAS_COND_AXIS_NAME_MAGICNO-24 "25165824.0000000000"
*MEAS_COND_AXIS_NAME_MAGICNO-25 "285343744.0000000000"
*MEAS_COND_AXIS_NAME_MAGICNO-26 "17301505.0000000000"
*MEAS_COND_AXIS_NAME_MAGICNO-27 "20971521.0000000000"
*MEAS_COND_AXIS_NAME_MAGICNO-28 "20971521.0000000000"
*MEAS_COND_AXIS_NAME_MAGICNO-29 "20971521.0000000000"
*MEAS_COND_AXIS_NAME_MAGICNO-30 "0.0000000000"
*MEAS_COND_AXIS_OFFSET-0 "-"
*MEAS_COND_AXIS_OFFSET-1 "-0.0310000000"
*MEAS_COND_AXIS_OFFSET-2 "0.5056000000"
*MEAS_COND_AXIS_OFFSET-3 "-"
*MEAS_COND_AXIS_OFFSET-4 "-"
*MEAS_COND_AXIS_OFFSET-5 "0.5056000000"
*MEAS_COND_AXIS_OFFSET-6 "-0.5366000000"
*MEAS_COND_AXIS_OFFSET-7 "-"
*MEAS_COND_AXIS_OFFSET-8 "-"
*MEAS_COND_AXIS_OFFSET-9 "-"
*MEAS_COND_AXIS_OFFSET-10 "-"
*MEAS_COND_AXIS_OFFSET-11 "-"
*MEAS_COND_AXIS_OFFSET-12 "-"
*MEAS_COND_AXIS_OFFSET-13 "-"
*MEAS_COND_AXIS_OFFSET-14 "-"
*MEAS_COND_AXIS_OFFSET-15 "-"
*MEAS_COND_AXIS_OFFSET-16 "-"
*MEAS_COND_AXIS_OFFSET-17 "-"
*MEAS_COND_AXIS_OFFSET-18 "-"
*MEAS_COND_AXIS_OFFSET-19 "-"
*MEAS_COND_AXIS_OFFSET-20 "-"
*MEAS_COND_AXIS_OFFSET-21 "-"
*MEAS_COND_AXIS_OFFSET-22 "-"
*MEAS_COND_AXIS_OFFSET-23 "-"
*MEAS_COND_AXIS_OFFSET-24 "-"
*MEAS_COND_AXIS_OFFSET-25 "-"
*MEAS_COND_AXIS_OFFSET-26 "-"
*MEAS_COND_AXIS_OFFSET-27 "-"
*MEAS_COND_AXIS_OFFSET-28 "-"
*MEAS_COND_AXIS_OFFSET-29 "-"
*MEAS_COND_AXIS_OFFSET-30 "-"
*MEAS_COND_AXIS_POSITION-0 "0.0000000000"
*MEAS_COND_AXIS_POSITION-1 "0.0000000000"
*MEAS_COND_AXIS_POSITION-2 "0.0000000000"
*MEAS_COND_AXIS_POSITION-3 "-2.9031400000"
*MEAS_COND_AXIS_POSITION-4 "0.0000000000"
*MEAS_COND_AXIS_POSITION-5 "0.0000000000"
*MEAS_COND_AXIS_POSITION-6 "0.0000000000"
*MEAS_COND_AXIS_POSITION-7 "-0.7498700000"
*MEAS_COND_AXIS_POSITION-8 "BB"
*MEAS_COND_AXIS_POSITION-9 "0.0000000000"
*MEAS_COND_AXIS_POSITION-10 "Soller_slit_5.0deg"
*MEAS_COND_AXIS_POSITION-11 "2/3deg"
*MEAS_COND_AXIS_POSITION-12 "2.2088000000"
*MEAS_COND_AXIS_POSITION-13 "-0.6412500000"
*MEAS_COND_AXIS_POSITION-14 "0.0000000000"
*MEAS_COND_AXIS_POSITION-15 "10.0mm"
*MEAS_COND_AXIS_POSITION-16 "None"
*MEAS_COND_AXIS_POSITION-17 "Cu_K-beta"
*MEAS_COND_AXIS_POSITION-18 "13.000mm"
*MEAS_COND_AXIS_POSITION-19 "13.000mm"
*MEAS_COND_AXIS_POSITION-20 "No_unit"
*MEAS_COND_AXIS_POSITION-21 "Soller_slit_5.0deg"
*MEAS_COND_AXIS_POSITION-22 "None"
*MEAS_COND_AXIS_POSITION-23 "13.0000000000"
*MEAS_COND_AXIS_POSITION-24 "13.0000000000"
*MEAS_COND_AXIS_POSITION-25 "0.0281300000"
*MEAS_COND_AXIS_POSITION-26 "Open"
*MEAS_COND_AXIS_POSITION-27 "None"
*MEAS_COND_AXIS_POSITION-28 "None"
*MEAS_COND_AXIS_POSITION-29 "None"
*MEAS_COND_AXIS_POSITION-30 "38.0000000000"
*MEAS_COND_AXIS_UNIT-0 "deg"
*MEAS_COND_AXIS_UNIT-1 "deg"
*MEAS_COND_AXIS_UNIT-2 "deg"
*MEAS_COND_AXIS_UNIT-3 "mm"
*MEAS_COND_AXIS_UNIT-4 "deg"
*MEAS_COND_AXIS_UNIT-5 "deg"
*MEAS_COND_AXIS_UNIT-6 "deg"
*MEAS_COND_AXIS_UNIT-7 "mm"
*MEAS_COND_AXIS_UNIT-8 ""
*MEAS_COND_AXIS_UNIT-9 "pulse"
*MEAS_COND_AXIS_UNIT-10 ""
*MEAS_COND_AXIS_UNIT-11 ""
*MEAS_COND_AXIS_UNIT-12 "mm"
*MEAS_COND_AXIS_UNIT-13 "mm"
*MEAS_COND_AXIS_UNIT-14 ""
*MEAS_COND_AXIS_UNIT-15 ""
*MEAS_COND_AXIS_UNIT-16 ""
*MEAS_COND_AXIS_UNIT-17 ""
*MEAS_COND_AXIS_UNIT-18 ""
*MEAS_COND_AXIS_UNIT-19 ""
*MEAS_COND_AXIS_UNIT-20 ""
*MEAS_COND_AXIS_UNIT-21 ""
*MEAS_COND_AXIS_UNIT-22 ""
*MEAS_COND_AXIS_UNIT-23 "mm"
*MEAS_COND_AXIS_UNIT-24 "mm"
*MEAS_COND_AXIS_UNIT-25 "mm"
*MEAS_COND_AXIS_UNIT-26 ""
*MEAS_COND_AXIS_UNIT-27 ""
*MEAS_COND_AXIS_UNIT-28 ""
*MEAS_COND_AXIS_UNIT-29 ""
*MEAS_COND_AXIS_UNIT-30 "div"
*MEAS_COND_COUNTER_CNTLOSS_CORR "0.0000000000"
*MEAS_COND_COUNTER_PHABASE "38.0000000000"
*MEAS_COND_COUNTER_PHAWINDOW "16.0000000000"
*MEAS_COND_COUNTER_PHA_UNIT "div"
*MEAS_COND_COUNTER_TAUDIFF "30.0000000000"
*MEAS_COND_COUNTER_TAUINT "0.0000000000"
*MEAS_COND_IRRADIATION_MODE "OFF"
*MEAS_COND_IRRADIATION_WIDTH ""
*MEAS_COND_OPT_ATTR "集中法"
*MEAS_COND_OPT_NAME "@集中法"
*MEAS_COND_UNSYMMETRIC_MODE "OFF"
*MEAS_COND_XG_CURRENT "30.0000000000"
*MEAS_COND_XG_VOLTAGE "40.0000000000"
*MEAS_COND_XG_WAVE_TYPE "Ka"
*MEAS_DATA_COUNT "5001.0000000000"
*MEAS_SCAN_AXIS_X "2θ/θ"
*MEAS_SCAN_AXIS_X_INTERNAL "TwoThetaTheta"
*MEAS_SCAN_END_TIME "07/27/23 19:42:44"
*MEAS_SCAN_MODE "CONTINUOUS"
*MEAS_SCAN_MONITOR "0"
*MEAS_SCAN_RESOLUTION_X "0.0002"
*MEAS_SCAN_SPEED "2.5"
*MEAS_SCAN_SPEED_UNIT "deg/min"
*MEAS_SCAN_START "20.0000000000"
*MEAS_SCAN_START_TIME "07/27/23 19:21:20"
*MEAS_SCAN_STEP "0.0100000000"
*MEAS_SCAN_STOP "70.0000000000"
*MEAS_SCAN_UNIT_X "deg"
*MEAS_SCAN_UNIT_Y "counts"
*RAS_HEADER_END
*RAS_INT_START
20.0000 1149.0000 1.0000
20.0400 1153.0000 1.0000
20.0800 1066.0000 1.0000
20.1200 1096.0000 1.0000
20.1600 1147.0000 1.0000
20.2000 1097.0000 1.0000
20.2400 1172.0000 1.0000
20.2800 1139.0000 1.0000
20.3200 1175.0000 1.0000
20.3600 1109.0000 1.0000
20.4000 1133.0000 1.0000
20.4400 1090.0000 1.0000
20.4800 1105.0000 1.0000
20.5200 1058.0000 1.0000
20.5600 1082.0000 1.0000
20.6000 1101.0000 1.0000
20.6400 1091.0000 1.0000
20.6800 1127.0000 1.0000
20.7200 1097.0000 1.0000
20.7600 1113.0000 1.0000
20.8000 1139.0000 1.0000
20.8400 1077.0000 1.0000
20.8800 1124.0000 1.0000
20.9200 1118.0000 1.0000
20.9600 1079.0000 1.0000
21.0000 1124.0000 1.0000
21.0400 1134.0000 1.0000
21.0800 1068.0000 1.0000
21.1200 1088.0000 1.0000
21.1600 1119.0000 1.0000
21.2000 1040.0000 1.0000
21.2400 1114.0000 1.0000
21.2800 1081.0000 1.0000
21.3200 1098.0000 1.0000
21.3600 1065.0000 1.0000
21.4000 1090.0000 1.0000
21.4400 1062.0000 1.0000
21.4800 1102.0000 1.0000
21.5200 1113.0000 1.0000
21.5600 1060.0000 1.0000
21.6000 1058.0000 1.0000
21.6400 1098.0000 1.0000
21.6800 1035.0000 1.0000
21.7200 1091.0000 1.0000
21.7600 1086.0000 1.0000
21.8000 1053.0000 1.0000
21.8400 1092.0000 1.0000
21.8800 1068.0000 1.0000
21.9200 1132.0000 1.0000
21.9600 1074.0000 1.0000
22.0000 1114.0000 1.0000
22.0400 1079.0000 1.0000
22.0800 1052.0000 1.0000
22.1200 1073.0000 1.0000
22.1600 1104.0000 1.0000
22.2000 1069.0000 1.0000
22.2400 1039.0000 1.0000
22.2800 1080.0000 1.0000
22.3200 1062.0000 1.0000
22.3600 1090.0000 1.0000
22.4000 1080.0000 1.0000
22.4400 1056.0000 1.0000
22.4800 1078.0000 1.0000
22.5200 1061.0000 1.0000
22.5600 1063.0000 1.0000
22.6000 1081.0000 1.0000
22.6400 1052.0000 1.0000
22.6800 1047.0000 1.0000
22.7200 1063.0000 1.0000
22.7600 1067.0000 1.0000
22.8000 1012.0000 1.0000
22.8400 1102.0000 1.0000
22.8800 1071.0000 1.0000
22.9200 1117.0000 1.0000
22.9600 1009.0000 1.0000
23.0000 1127.0000 1.0000
23.0400 1092.0000 1.0000
23.0800 997.0000 1.0000
23.1200 1027.0000 1.0000
23.1600 1061.0000 1.0000
23.2000 1018.0000 1.0000
23.2400 1045.0000 1.0000
23.2800 1007.0000 1.0000
23.3200 1053.0000 1.0000
23.3600 1046.0000 1.0000
23.4000 1075.0000 1.0000
23.4400 1129.0000 1.0000
23.4800 995.0000 1.0000
23.5200 1074.0000 1.0000
23.5600 1030.0000 1.0000
23.6000 1021.0000 1.0000
23.6400 1046.0000 1.0000
23.6800 1012.0000 1.0000
23.7200 1023.0000 1.0000
23.7600 1075.0000 1.0000
23.8000 1055.0000 1.0000
23.8400 1090.0000 1.0000
23.8800 1095.0000 1.0000
23.9200 1042.0000 1.0000
23.9600 1132.0000 1.0000
24.0000 1134.0000 1.0000
24.0400 1127.0000 1.0000
24.0800 1152.0000 1.0000
24.1200 1124.0000 1.0000
24.1600 1150.0000 1.0000
24.2000 1027.0000 1.0000
24.2400 1049.0000 1.0000
24.2800 1052.0000 1.0000
24.3200 1064.0000 1.0000
24.3600 1031.0000 1.0000
24.4000 1007.0000 1.0000
24.4400 1008.0000 1.0000
24.4800 1035.0000 1.0000
24.5200 1053.0000 1.0000
24.5600 990.0000 1.0000
24.6000 1050.0000 1.0000
24.6400 1022.0000 1.0000
24.6800 1011.0000 1.0000
24.7200 1025.0000 1.0000
24.7600 1001.0000 1.0000
24.8000 979.0000 1.0000
24.8400 1008.0000 1.0000
24.8800 990.0000 1.0000
24.9200 1067.0000 1.0000
24.9600 999.0000 1.0000
25.0000 974.0000 1.0000
25.0400 1039.0000 1.0000
25.0800 966.0000 1.0000
25.1200 993.0000 1.0000
25.1600 1005.0000 1.0000
25.2000 989.0000 1.0000
25.2400 997.0000 1.0000
25.2800 987.0000 1.0000
25.3200 984.0000 1.0000
25.3600 1019.0000 1.0000
25.4000 1006.0000 1.0000
25.4400 955.0000 1.0000
25.4800 1056.0000 1.0000
25.5200 994.0000 1.0000
25.5600 1009.0000 1.0000
25.6000 992.0000 1.0000
25.6400 970.0000 1.0000
25.6800 966.0000 1.0000
25.7200 1015.0000 1.0000
25.7600 1030.0000 1.0000
25.8000 950.0000 1.0000
25.8400 977.0000 1.0000
25.8800 1026.0000 1.0000
25.9200 1013.0000 1.0000
25.9600 992.0000 1.0000
26.0000 1058.0000 1.0000
26.0400 1072.0000 1.0000
26.0800 1074.0000 1.0000
26.1200 1113.0000 1.0000
26.1600 1150.0000 1.0000
26.2000 1281.0000 1.0000
26.2400 1379.0000 1.0000
26.2800 1552.0000 1.0000
26.3200 1860.0000 1.0000
26.3600 2287.0000 1.0000
26.4000 2686.0000 1.0000
26.4400 2826.0000 1.0000
26.4800 2739.0000 1.0000
26.5200 2366.0000 1.0000
26.5600 1893.0000 1.0000
26.6000 1626.0000 1.0000
26.6400 1403.0000 1.0000
26.6800 1301.0000 1.0000
26.7200 1171.0000 1.0000
26.7600 1089.0000 1.0000
26.8000 1069.0000 1.0000
26.8400 1050.0000 1.0000
26.8800 1016.0000 1.0000
26.9200 1005.0000 1.0000
26.9600 987.0000 1.0000
27.0000 1002.0000 1.0000
27.0400 978.0000 1.0000
27.0800 965.0000 1.0000
27.1200 954.0000 1.0000
27.1600 979.0000 1.0000
27.2000 930.0000 1.0000
27.2400 936.0000 1.0000
27.2800 956.0000 1.0000
27.3200 906.0000 1.0000
27.3600 979.0000 1.0000
27.4000 964.0000 1.0000
27.4400 921.0000 1.0000
27.4800 868.0000 1.0000
27.5200 841.0000 1.0000
27.5600 914.0000 1.0000
27.6000 898.0000 1.0000
27.6400 856.0000 1.0000
27.6800 928.0000 1.0000
27.7200 907.0000 1.0000
27.7600 849.0000 1.0000
27.8000 880.0000 1.0000
27.8400 899.0000 1.0000
27.8800 877.0000 1.0000
27.9200 840.0000 1.0000
27.9600 847.0000 1.0000
28.0000 890.0000 1.0000
28.0400 944.0000 1.0000
28.0800 898.0000 1.0000
28.1200 884.0000 1.0000
28.1600 871.0000 1.0000
28.2000 890.0000 1.0000
28.2400 916.0000 1.0000
28.2800 896.0000 1.0000
28.3200 877.0000 1.0000
28.3600 852.0000 1.0000
28.4000 893.0000 1.0000
28.4400 865.0000 1.0000
28.4800 841.0000 1.0000
28.5200 871.0000 1.0000
28.5600 842.0000 1.0000
28.6000 846.0000 1.0000
28.6400 867.0000 1.0000
28.6800 886.0000 1.0000
28.7200 877.0000 1.0000
28.7600 860.0000 1.0000
28.8000 849.0000 1.0000
28.8400 850.0000 1.0000
28.8800 799.0000 1.0000
28.9200 886.0000 1.0000
28.9600 820.0000 1.0000
29.0000 850.0000 1.0000
29.0400 864.0000 1.0000
29.0800 788.0000 1.0000
29.1200 808.0000 1.0000
29.1600 867.0000 1.0000
29.2000 812.0000 1.0000
29.2400 824.0000 1.0000
29.2800 811.0000 1.0000
29.3200 807.0000 1.0000
29.3600 789.0000 1.0000
29.4000 832.0000 1.0000
29.4400 778.0000 1.0000
29.4800 790.0000 1.0000
29.5200 791.0000 1.0000
29.5600 805.0000 1.0000
29.6000 812.0000 1.0000
29.6400 757.0000 1.0000
29.6800 764.0000 1.0000
29.7200 784.0000 1.0000
29.7600 783.0000 1.0000
29.8000 775.0000 1.0000
29.8400 802.0000 1.0000
29.8800 735.0000 1.0000
29.9200 720.0000 1.0000
29.9600 733.0000 1.0000
30.0000 787.0000 1.0000
30.0400 727.0000 1.0000
30.0800 767.0000 1.0000
30.1200 793.0000 1.0000
30.1600 745.0000 1.0000
30.2000 753.0000 1.0000
30.2400 733.0000 1.0000
30.2800 797.0000 1.0000
30.3200 735.0000 1.0000
30.3600 764.0000 1.0000
30.4000 721.0000 1.0000
30.4400 779.0000 1.0000
30.4800 744.0000 1.0000
30.5200 714.0000 1.0000
30.5600 715.0000 1.0000
30.6000 718.0000 1.0000
30.6400 750.0000 1.0000
30.6800 687.0000 1.0000
30.7200 682.0000 1.0000
30.7600 686.0000 1.0000
30.8000 728.0000 1.0000
30.8400 684.0000 1.0000
30.8800 724.0000 1.0000
30.9200 707.0000 1.0000
30.9600 707.0000 1.0000
31.0000 685.0000 1.0000
31.0400 679.0000 1.0000
31.0800 690.0000 1.0000
31.1200 705.0000 1.0000
31.1600 743.0000 1.0000
31.2000 681.0000 1.0000
31.2400 727.0000 1.0000
31.2800 657.0000 1.0000
31.3200 668.0000 1.0000
31.3600 674.0000 1.0000
31.4000 626.0000 1.0000
31.4400 696.0000 1.0000
31.4800 669.0000 1.0000
31.5200 695.0000 1.0000
31.5600 704.0000 1.0000
31.6000 701.0000 1.0000
31.6400 691.0000 1.0000
31.6800 674.0000 1.0000
31.7200 680.0000 1.0000
31.7600 649.0000 1.0000
31.8000 635.0000 1.0000
31.8400 692.0000 1.0000
31.8800 645.0000 1.0000
31.9200 683.0000 1.0000
31.9600 680.0000 1.0000
32.0000 659.0000 1.0000
32.0400 656.0000 1.0000
32.0800 634.0000 1.0000
32.1200 669.0000 1.0000
32.1600 698.0000 1.0000
32.2000 657.0000 1.0000
32.2400 685.0000 1.0000
32.2800 668.0000 1.0000
32.3200 646.0000 1.0000
32.3600 713.0000 1.0000
32.4000 686.0000 1.0000
32.4400 657.0000 1.0000
32.4800 654.0000 1.0000
32.5200 677.0000 1.0000
32.5600 719.0000 1.0000
32.6000 683.0000 1.0000
32.6400 643.0000 1.0000
32.6800 659.0000 1.0000
32.7200 667.0000 1.0000
32.7600 685.0000 1.0000
32.8000 701.0000 1.0000
32.8400 682.0000 1.0000
32.8800 673.0000 1.0000
32.9200 694.0000 1.0000
32.9600 727.0000 1.0000
33.0000 833.0000 1.0000
33.0400 843.0000 1.0000
33.0800 877.0000 1.0000
33.1200 873.0000 1.0000
33.1600 816.0000 1.0000
33.2000 811.0000 1.0000
33.2400 760.0000 1.0000
33.2800 769.0000 1.0000
33.3200 725.0000 1.0000
33.3600 760.0000 1.0000
33.4000 761.0000 1.0000
33.4400 801.0000 1.0000
33.4800 880.0000 1.0000
33.5200 981.0000 1.0000
33.5600 1066.0000 1.0000
33.6000 1330.0000 1.0000
33.6400 1346.0000 1.0000
33.6800 1368.0000 1.0000
33.7200 1282.0000 1.0000
33.7600 1149.0000 1.0000
33.8000 962.0000 1.0000
33.8400 852.0000 1.0000
33.8800 806.0000 1.0000
33.9200 746.0000 1.0000
33.9600 746.0000 1.0000
34.0000 703.0000 1.0000
34.0400 694.0000 1.0000
34.0800 681.0000 1.0000
34.1200 665.0000 1.0000
34.1600 656.0000 1.0000
34.2000 654.0000 1.0000
34.2400 680.0000 1.0000
34.2800 672.0000 1.0000
34.3200 630.0000 1.0000
34.3600 668.0000 1.0000
34.4000 632.0000 1.0000
34.4400 634.0000 1.0000
34.4800 618.0000 1.0000
34.5200 620.0000 1.0000
34.5600 626.0000 1.0000
34.6000 588.0000 1.0000
34.6400 635.0000 1.0000
34.6800 623.0000 1.0000
34.7200 601.0000 1.0000
34.7600 637.0000 1.0000
34.8000 606.0000 1.0000
34.8400 573.0000 1.0000
34.8800 625.0000 1.0000
34.9200 605.0000 1.0000
34.9600 556.0000 1.0000
35.0000 592.0000 1.0000
35.0400 553.0000 1.0000
35.0800 579.0000 1.0000
35.1200 607.0000 1.0000
35.1600 624.0000 1.0000
35.2000 622.0000 1.0000
35.2400 667.0000 1.0000
35.2800 664.0000 1.0000
35.3200 645.0000 1.0000
35.3600 669.0000 1.0000
35.4000 775.0000 1.0000
35.4400 865.0000 1.0000
35.4800 992.0000 1.0000
35.5200 1266.0000 1.0000
35.5600 1516.0000 1.0000
35.6000 1499.0000 1.0000
35.6400 1258.0000 1.0000
35.6800 1090.0000 1.0000
35.7200 866.0000 1.0000
35.7600 736.0000 1.0000
35.8000 658.0000 1.0000
35.8400 629.0000 1.0000
35.8800 596.0000 1.0000
35.9200 623.0000 1.0000
35.9600 587.0000 1.0000
36.0000 557.0000 1.0000
36.0400 528.0000 1.0000
36.0800 571.0000 1.0000
36.1200 574.0000 1.0000
36.1600 589.0000 1.0000
36.2000 573.0000 1.0000
36.2400 546.0000 1.0000
36.2800 552.0000 1.0000
36.3200 581.0000 1.0000
36.3600 533.0000 1.0000
36.4000 581.0000 1.0000
36.4400 584.0000 1.0000
36.4800 534.0000 1.0000
36.5200 597.0000 1.0000
36.5600 544.0000 1.0000
36.6000 571.0000 1.0000
36.6400 559.0000 1.0000
36.6800 547.0000 1.0000
36.7200 552.0000 1.0000
36.7600 545.0000 1.0000
36.8000 555.0000 1.0000
36.8400 544.0000 1.0000
36.8800 574.0000 1.0000
36.9200 601.0000 1.0000
36.9600 573.0000 1.0000
37.0000 558.0000 1.0000
37.0400 573.0000 1.0000
37.0800 574.0000 1.0000
37.1200 604.0000 1.0000
37.1600 569.0000 1.0000
37.2000 572.0000 1.0000
37.2400 616.0000 1.0000
37.2800 582.0000 1.0000
37.3200 617.0000 1.0000
37.3600 643.0000 1.0000
37.4000 686.0000 1.0000
37.4400 721.0000 1.0000
37.4800 899.0000 1.0000
37.5200 940.0000 1.0000
37.5600 1180.0000 1.0000
37.6000 1459.0000 1.0000
37.6400 1763.0000 1.0000
37.6800 2018.0000 1.0000
37.7200 2121.0000 1.0000
37.7600 1965.0000 1.0000
37.8000 1737.0000 1.0000
37.8400 1463.0000 1.0000
37.8800 1189.0000 1.0000
37.9200 974.0000 1.0000
37.9600 823.0000 1.0000
38.0000 714.0000 1.0000
38.0400 657.0000 1.0000
38.0800 600.0000 1.0000
38.1200 574.0000 1.0000
38.1600 609.0000 1.0000
38.2000 544.0000 1.0000
38.2400 553.0000 1.0000
38.2800 543.0000 1.0000
38.3200 542.0000 1.0000
38.3600 548.0000 1.0000
38.4000 526.0000 1.0000
38.4400 516.0000 1.0000
38.4800 543.0000 1.0000
38.5200 519.0000 1.0000
38.5600 501.0000 1.0000
38.6000 519.0000 1.0000
38.6400 497.0000 1.0000
38.6800 532.0000 1.0000
38.7200 532.0000 1.0000
38.7600 527.0000 1.0000
38.8000 518.0000 1.0000
38.8400 531.0000 1.0000
38.8800 512.0000 1.0000
38.9200 513.0000 1.0000
38.9600 521.0000 1.0000
39.0000 526.0000 1.0000
39.0400 503.0000 1.0000
39.0800 487.0000 1.0000
39.1200 516.0000 1.0000
39.1600 484.0000 1.0000
39.2000 493.0000 1.0000
39.2400 508.0000 1.0000
39.2800 518.0000 1.0000
39.3200 537.0000 1.0000
39.3600 503.0000 1.0000
39.4000 485.0000 1.0000
39.4400 499.0000 1.0000
39.4800 513.0000 1.0000
39.5200 472.0000 1.0000
39.5600 543.0000 1.0000
39.6000 494.0000 1.0000
39.6400 482.0000 1.0000
39.6800 492.0000 1.0000
39.7200 459.0000 1.0000
39.7600 452.0000 1.0000
39.8000 485.0000 1.0000
39.8400 506.0000 1.0000
39.8800 512.0000 1.0000
39.9200 465.0000 1.0000
39.9600 455.0000 1.0000
40.0000 480.0000 1.0000
40.0400 507.0000 1.0000
40.0800 466.0000 1.0000
40.1200 464.0000 1.0000
40.1600 502.0000 1.0000
40.2000 503.0000 1.0000
40.2400 492.0000 1.0000
40.2800 480.0000 1.0000
40.3200 517.0000 1.0000
40.3600 473.0000 1.0000
40.4000 442.0000 1.0000
40.4400 500.0000 1.0000
40.4800 486.0000 1.0000
40.5200 486.0000 1.0000
40.5600 470.0000 1.0000
40.6000 474.0000 1.0000
40.6400 518.0000 1.0000
40.6800 451.0000 1.0000
40.7200 463.0000 1.0000
40.7600 532.0000 1.0000
40.8000 513.0000 1.0000
40.8400 530.0000 1.0000
40.8800 522.0000 1.0000
40.9200 477.0000 1.0000
40.9600 470.0000 1.0000
41.0000 468.0000 1.0000
41.0400 465.0000 1.0000
41.0800 481.0000 1.0000
41.1200 443.0000 1.0000
41.1600 464.0000 1.0000
41.2000 427.0000 1.0000
41.2400 477.0000 1.0000
41.2800 482.0000 1.0000
41.3200 475.0000 1.0000
41.3600 466.0000 1.0000
41.4000 440.0000 1.0000
41.4400 481.0000 1.0000
41.4800 486.0000 1.0000
41.5200 470.0000 1.0000
41.5600 431.0000 1.0000
41.6000 442.0000 1.0000
41.6400 470.0000 1.0000
41.6800 477.0000 1.0000
41.7200 443.0000 1.0000
41.7600 452.0000 1.0000
41.8000 446.0000 1.0000
41.8400 458.0000 1.0000
41.8800 476.0000 1.0000
41.9200 449.0000 1.0000
41.9600 480.0000 1.0000
42.0000 473.0000 1.0000
42.0400 423.0000 1.0000
42.0800 477.0000 1.0000
42.1200 449.0000 1.0000
42.1600 447.0000 1.0000
42.2000 442.0000 1.0000
42.2400 465.0000 1.0000
42.2800 478.0000 1.0000
42.3200 462.0000 1.0000
42.3600 464.0000 1.0000
42.4000 474.0000 1.0000
42.4400 472.0000 1.0000
42.4800 487.0000 1.0000
42.5200 499.0000 1.0000
42.5600 458.0000 1.0000
42.6000 487.0000 1.0000
42.6400 461.0000 1.0000
42.6800 430.0000 1.0000
42.7200 471.0000 1.0000
42.7600 447.0000 1.0000
42.8000 455.0000 1.0000
42.8400 450.0000 1.0000
42.8800 462.0000 1.0000
42.9200 486.0000 1.0000
42.9600 453.0000 1.0000
43.0000 408.0000 1.0000
43.0400 447.0000 1.0000
43.0800 484.0000 1.0000
43.1200 450.0000 1.0000
43.1600 437.0000 1.0000
43.2000 394.0000 1.0000
43.2400 416.0000 1.0000
43.2800 451.0000 1.0000
43.3200 450.0000 1.0000
43.3600 450.0000 1.0000
43.4000 455.0000 1.0000
43.4400 470.0000 1.0000
43.4800 451.0000 1.0000
43.5200 454.0000 1.0000
43.5600 483.0000 1.0000
43.6000 486.0000 1.0000
43.6400 457.0000 1.0000
43.6800 413.0000 1.0000
43.7200 440.0000 1.0000
43.7600 415.0000 1.0000
43.8000 442.0000 1.0000
43.8400 432.0000 1.0000
43.8800 457.0000 1.0000
43.9200 411.0000 1.0000
43.9600 489.0000 1.0000
44.0000 437.0000 1.0000
44.0400 410.0000 1.0000
44.0800 448.0000 1.0000
44.1200 428.0000 1.0000
44.1600 417.0000 1.0000
44.2000 445.0000 1.0000
44.2400 416.0000 1.0000
44.2800 429.0000 1.0000
44.3200 428.0000 1.0000
44.3600 431.0000 1.0000
44.4000 425.0000 1.0000
44.4400 417.0000 1.0000
44.4800 422.0000 1.0000
44.5200 411.0000 1.0000
44.5600 427.0000 1.0000
44.6000 457.0000 1.0000
44.6400 422.0000 1.0000
44.6800 416.0000 1.0000
44.7200 450.0000 1.0000
44.7600 421.0000 1.0000
44.8000 435.0000 1.0000
44.8400 418.0000 1.0000
44.8800 417.0000 1.0000
44.9200 450.0000 1.0000
44.9600 419.0000 1.0000
45.0000 452.0000 1.0000
45.0400 410.0000 1.0000
45.0800 444.0000 1.0000
45.1200 420.0000 1.0000
45.1600 434.0000 1.0000
45.2000 419.0000 1.0000
45.2400 408.0000 1.0000
45.2800 430.0000 1.0000
45.3200 449.0000 1.0000
45.3600 411.0000 1.0000
45.4000 421.0000 1.0000
45.4400 434.0000 1.0000
45.4800 397.0000 1.0000
45.5200 413.0000 1.0000
45.5600 393.0000 1.0000
45.6000 444.0000 1.0000
45.6400 411.0000 1.0000
45.6800 444.0000 1.0000
45.7200 428.0000 1.0000
45.7600 433.0000 1.0000
45.8000 429.0000 1.0000
45.8400 430.0000 1.0000
45.8800 428.0000 1.0000
45.9200 437.0000 1.0000
45.9600 390.0000 1.0000
46.0000 381.0000 1.0000
46.0400 438.0000 1.0000
46.0800 418.0000 1.0000
46.1200 442.0000 1.0000
46.1600 415.0000 1.0000
46.2000 433.0000 1.0000
46.2400 425.0000 1.0000
46.2800 430.0000 1.0000
46.3200 438.0000 1.0000
46.3600 371.0000 1.0000
46.4000 426.0000 1.0000
46.4400 396.0000 1.0000
46.4800 417.0000 1.0000
46.5200 430.0000 1.0000
46.5600 393.0000 1.0000
46.6000 387.0000 1.0000
46.6400 413.0000 1.0000
46.6800 413.0000 1.0000
46.7200 437.0000 1.0000
46.7600 387.0000 1.0000
46.8000 431.0000 1.0000
46.8400 428.0000 1.0000
46.8800 399.0000 1.0000
46.9200 379.0000 1.0000
46.9600 388.0000 1.0000
47.0000 400.0000 1.0000
47.0400 388.0000 1.0000
47.0800 404.0000 1.0000
47.1200 390.0000 1.0000
47.1600 403.0000 1.0000
47.2000 394.0000 1.0000
47.2400 397.0000 1.0000
47.2800 399.0000 1.0000
47.3200 366.0000 1.0000
47.3600 359.0000 1.0000
47.4000 385.0000 1.0000
47.4400 413.0000 1.0000
47.4800 443.0000 1.0000
47.5200 389.0000 1.0000
47.5600 394.0000 1.0000
47.6000 411.0000 1.0000
47.6400 420.0000 1.0000
47.6800 406.0000 1.0000
47.7200 401.0000 1.0000
47.7600 413.0000 1.0000
47.8000 365.0000 1.0000
47.8400 425.0000 1.0000
47.8800 395.0000 1.0000
47.9200 366.0000 1.0000
47.9600 407.0000 1.0000
48.0000 403.0000 1.0000
48.0400 385.0000 1.0000
48.0800 376.0000 1.0000
48.1200 385.0000 1.0000
48.1600 390.0000 1.0000
48.2000 404.0000 1.0000
48.2400 413.0000 1.0000
48.2800 386.0000 1.0000
48.3200 434.0000 1.0000
48.3600 408.0000 1.0000
48.4000 416.0000 1.0000
48.4400 395.0000 1.0000
48.4800 411.0000 1.0000
48.5200 418.0000 1.0000
48.5600 404.0000 1.0000
48.6000 388.0000 1.0000
48.6400 401.0000 1.0000
48.6800 391.0000 1.0000
48.7200 394.0000 1.0000
48.7600 365.0000 1.0000
48.8000 364.0000 1.0000
48.8400 389.0000 1.0000
48.8800 414.0000 1.0000
48.9200 400.0000 1.0000
48.9600 400.0000 1.0000
49.0000 409.0000 1.0000
49.0400 406.0000 1.0000
49.0800 430.0000 1.0000
49.1200 380.0000 1.0000
49.1600 373.0000 1.0000
49.2000 392.0000 1.0000
49.2400 399.0000 1.0000
49.2800 408.0000 1.0000
49.3200 394.0000 1.0000
49.3600 446.0000 1.0000
49.4000 429.0000 1.0000
49.4400 460.0000 1.0000
49.4800 456.0000 1.0000
49.5200 457.0000 1.0000
49.5600 426.0000 1.0000
49.6000 436.0000 1.0000
49.6400 375.0000 1.0000
49.6800 422.0000 1.0000
49.7200 385.0000 1.0000
49.7600 381.0000 1.0000
49.8000 374.0000 1.0000
49.8400 366.0000 1.0000
49.8800 388.0000 1.0000
49.9200 410.0000 1.0000
49.9600 415.0000 1.0000
50.0000 396.0000 1.0000
50.0400 397.0000 1.0000
50.0800 407.0000 1.0000
50.1200 392.0000 1.0000
50.1600 388.0000 1.0000
50.2000 368.0000 1.0000
50.2400 398.0000 1.0000
50.2800 373.0000 1.0000
50.3200 398.0000 1.0000
50.3600 370.0000 1.0000
50.4000 410.0000 1.0000
50.4400 383.0000 1.0000
50.4800 397.0000 1.0000
50.5200 383.0000 1.0000
50.5600 362.0000 1.0000
50.6000 385.0000 1.0000
50.6400 408.0000 1.0000
50.6800 388.0000 1.0000
50.7200 404.0000 1.0000
50.7600 429.0000 1.0000
50.8000 382.0000 1.0000
50.8400 387.0000 1.0000
50.8800 415.0000 1.0000
50.9200 394.0000 1.0000
50.9600 393.0000 1.0000
51.0000 399.0000 1.0000
51.0400 449.0000 1.0000
51.0800 421.0000 1.0000
51.1200 447.0000 1.0000
51.1600 509.0000 1.0000
51.2000 517.0000 1.0000
51.2400 586.0000 1.0000
51.2800 682.0000 1.0000
51.3200 809.0000 1.0000
51.3600 1046.0000 1.0000
51.4000 1322.0000 1.0000
51.4400 1747.0000 1.0000
51.4800 1973.0000 1.0000
51.5200 1912.0000 1.0000
51.5600 1688.0000 1.0000
51.6000 1587.0000 1.0000
51.6400 1357.0000 1.0000
51.6800 1072.0000 1.0000
51.7200 832.0000 1.0000
51.7600 695.0000 1.0000
51.8000 592.0000 1.0000
51.8400 570.0000 1.0000
51.8800 493.0000 1.0000
51.9200 468.0000 1.0000
51.9600 418.0000 1.0000
52.0000 446.0000 1.0000
52.0400 436.0000 1.0000
52.0800 413.0000 1.0000
52.1200 394.0000 1.0000
52.1600 387.0000 1.0000
52.2000 388.0000 1.0000
52.2400 404.0000 1.0000
52.2800 380.0000 1.0000
52.3200 397.0000 1.0000
52.3600 388.0000 1.0000
52.4000 394.0000 1.0000
52.4400 389.0000 1.0000
52.4800 416.0000 1.0000
52.5200 391.0000 1.0000
52.5600 387.0000 1.0000
52.6000 365.0000 1.0000
52.6400 386.0000 1.0000
52.6800 367.0000 1.0000
52.7200 392.0000 1.0000
52.7600 369.0000 1.0000
52.8000 382.0000 1.0000
52.8400 410.0000 1.0000
52.8800 362.0000 1.0000
52.9200 394.0000 1.0000
52.9600 365.0000 1.0000
53.0000 376.0000 1.0000
53.0400 380.0000 1.0000
53.0800 362.0000 1.0000
53.1200 381.0000 1.0000
53.1600 383.0000 1.0000
53.2000 354.0000 1.0000
53.2400 374.0000 1.0000
53.2800 370.0000 1.0000
53.3200 395.0000 1.0000
53.3600 377.0000 1.0000
53.4000 354.0000 1.0000
53.4400 388.0000 1.0000
53.4800 392.0000 1.0000
53.5200 381.0000 1.0000
53.5600 364.0000 1.0000
53.6000 353.0000 1.0000
53.6400 374.0000 1.0000
53.6800 362.0000 1.0000
53.7200 386.0000 1.0000
53.7600 372.0000 1.0000
53.8000 395.0000 1.0000
53.8400 359.0000 1.0000
53.8800 384.0000 1.0000
53.9200 366.0000 1.0000
53.9600 431.0000 1.0000
54.0000 414.0000 1.0000
54.0400 403.0000 1.0000
54.0800 399.0000 1.0000
54.1200 402.0000 1.0000
54.1600 414.0000 1.0000
54.2000 429.0000 1.0000
54.2400 378.0000 1.0000
54.2800 410.0000 1.0000
54.3200 436.0000 1.0000
54.3600 416.0000 1.0000
54.4000 433.0000 1.0000
54.4400 449.0000 1.0000
54.4800 517.0000 1.0000
54.5200 532.0000 1.0000
54.5600 487.0000 1.0000
54.6000 504.0000 1.0000
54.6400 440.0000 1.0000
54.6800 450.0000 1.0000
54.7200 445.0000 1.0000
54.7600 444.0000 1.0000
54.8000 393.0000 1.0000
54.8400 401.0000 1.0000
54.8800 389.0000 1.0000
54.9200 360.0000 1.0000
54.9600 402.0000 1.0000
55.0000 400.0000 1.0000
55.0400 395.0000 1.0000
55.0800 399.0000 1.0000
55.1200 386.0000 1.0000
55.1600 333.0000 1.0000
55.2000 382.0000 1.0000
55.2400 347.0000 1.0000
55.2800 377.0000 1.0000
55.3200 380.0000 1.0000
55.3600 388.0000 1.0000
55.4000 340.0000 1.0000
55.4400 358.0000 1.0000
55.4800 395.0000 1.0000
55.5200 354.0000 1.0000
55.5600 346.0000 1.0000
55.6000 347.0000 1.0000
55.6400 353.0000 1.0000
55.6800 378.0000 1.0000
55.7200 351.0000 1.0000
55.7600 351.0000 1.0000
55.8000 373.0000 1.0000
55.8400 389.0000 1.0000
55.8800 374.0000 1.0000
55.9200 355.0000 1.0000
55.9600 345.0000 1.0000
56.0000 336.0000 1.0000
56.0400 396.0000 1.0000
56.0800 358.0000 1.0000
56.1200 367.0000 1.0000
56.1600 402.0000 1.0000
56.2000 365.0000 1.0000
56.2400 371.0000 1.0000
56.2800 358.0000 1.0000
56.3200 336.0000 1.0000
56.3600 361.0000 1.0000
56.4000 342.0000 1.0000
56.4400 320.0000 1.0000
56.4800 375.0000 1.0000
56.5200 371.0000 1.0000
56.5600 333.0000 1.0000
56.6000 347.0000 1.0000
56.6400 348.0000 1.0000
56.6800 358.0000 1.0000
56.7200 361.0000 1.0000
56.7600 342.0000 1.0000
56.8000 379.0000 1.0000
56.8400 306.0000 1.0000
56.8800 338.0000 1.0000
56.9200 343.0000 1.0000
56.9600 345.0000 1.0000
57.0000 351.0000 1.0000
57.0400 333.0000 1.0000
57.0800 327.0000 1.0000
57.1200 368.0000 1.0000
57.1600 349.0000 1.0000
57.2000 347.0000 1.0000
57.2400 339.0000 1.0000
57.2800 380.0000 1.0000
57.3200 383.0000 1.0000
57.3600 352.0000 1.0000
57.4000 378.0000 1.0000
57.4400 356.0000 1.0000
57.4800 376.0000 1.0000
57.5200 332.0000 1.0000
57.5600 357.0000 1.0000
57.6000 362.0000 1.0000
57.6400 368.0000 1.0000
57.6800 341.0000 1.0000
57.7200 382.0000 1.0000
57.7600 351.0000 1.0000
57.8000 372.0000 1.0000
57.8400 357.0000 1.0000
57.8800 357.0000 1.0000
57.9200 372.0000 1.0000
57.9600 378.0000 1.0000
58.0000 333.0000 1.0000
58.0400 341.0000 1.0000
58.0800 315.0000 1.0000
58.1200 336.0000 1.0000
58.1600 378.0000 1.0000
58.2000 342.0000 1.0000
58.2400 372.0000 1.0000
58.2800 352.0000 1.0000
58.3200 353.0000 1.0000
58.3600 361.0000 1.0000
58.4000 379.0000 1.0000
58.4400 367.0000 1.0000
58.4800 347.0000 1.0000
58.5200 353.0000 1.0000
58.5600 355.0000 1.0000
58.6000 317.0000 1.0000
58.6400 380.0000 1.0000
58.6800 350.0000 1.0000
58.7200 332.0000 1.0000
58.7600 342.0000 1.0000
58.8000 328.0000 1.0000
58.8400 335.0000 1.0000
58.8800 340.0000 1.0000
58.9200 354.0000 1.0000
58.9600 327.0000 1.0000
59.0000 340.0000 1.0000
59.0400 338.0000 1.0000
59.0800 345.0000 1.0000
59.1200 346.0000 1.0000
59.1600 348.0000 1.0000
59.2000 337.0000 1.0000
59.2400 346.0000 1.0000
59.2800 366.0000 1.0000
59.3200 352.0000 1.0000
59.3600 328.0000 1.0000
59.4000 328.0000 1.0000
59.4400 333.0000 1.0000
59.4800 340.0000 1.0000
59.5200 337.0000 1.0000
59.5600 336.0000 1.0000
59.6000 359.0000 1.0000
59.6400 339.0000 1.0000
59.6800 345.0000 1.0000
59.7200 359.0000 1.0000
59.7600 346.0000 1.0000
59.8000 349.0000 1.0000
59.8400 337.0000 1.0000
59.8800 337.0000 1.0000
59.9200 342.0000 1.0000
59.9600 381.0000 1.0000
60.0000 356.0000 1.0000
60.0400 332.0000 1.0000
60.0800 322.0000 1.0000
60.1200 338.0000 1.0000
60.1600 353.0000 1.0000
60.2000 349.0000 1.0000
60.2400 340.0000 1.0000
60.2800 331.0000 1.0000
60.3200 359.0000 1.0000
60.3600 326.0000 1.0000
60.4000 355.0000 1.0000
60.4400 358.0000 1.0000
60.4800 335.0000 1.0000
60.5200 352.0000 1.0000
60.5600 328.0000 1.0000
60.6000 349.0000 1.0000
60.6400 358.0000 1.0000
60.6800 340.0000 1.0000
60.7200 330.0000 1.0000
60.7600 330.0000 1.0000
60.8000 363.0000 1.0000
60.8400 350.0000 1.0000
60.8800 375.0000 1.0000
60.9200 370.0000 1.0000
60.9600 333.0000 1.0000
61.0000 344.0000 1.0000
61.0400 367.0000 1.0000
61.0800 351.0000 1.0000
61.1200 357.0000 1.0000
61.1600 393.0000 1.0000
61.2000 376.0000 1.0000
61.2400 406.0000 1.0000
61.2800 435.0000 1.0000
61.3200 422.0000 1.0000
61.3600 469.0000 1.0000
61.4000 519.0000 1.0000
61.4400 575.0000 1.0000
61.4800 617.0000 1.0000
61.5200 593.0000 1.0000
61.5600 595.0000 1.0000
61.6000 593.0000 1.0000
61.6400 578.0000 1.0000
61.6800 561.0000 1.0000
61.7200 560.0000 1.0000
61.7600 525.0000 1.0000
61.8000 486.0000 1.0000
61.8400 438.0000 1.0000
61.8800 433.0000 1.0000
61.9200 412.0000 1.0000
61.9600 417.0000 1.0000
62.0000 379.0000 1.0000
62.0400 378.0000 1.0000
62.0800 360.0000 1.0000
62.1200 387.0000 1.0000
62.1600 362.0000 1.0000
62.2000 348.0000 1.0000
62.2400 375.0000 1.0000
62.2800 412.0000 1.0000
62.3200 421.0000 1.0000
62.3600 430.0000 1.0000
62.4000 414.0000 1.0000
62.4400 399.0000 1.0000
62.4800 382.0000 1.0000
62.5200 400.0000 1.0000
62.5600 379.0000 1.0000
62.6000 397.0000 1.0000
62.6400 372.0000 1.0000
62.6800 340.0000 1.0000
62.7200 363.0000 1.0000
62.7600 357.0000 1.0000
62.8000 338.0000 1.0000
62.8400 350.0000 1.0000
62.8800 318.0000 1.0000
62.9200 346.0000 1.0000
62.9600 358.0000 1.0000
63.0000 328.0000 1.0000
63.0400 348.0000 1.0000
63.0800 349.0000 1.0000
63.1200 350.0000 1.0000
63.1600 367.0000 1.0000
63.2000 323.0000 1.0000
63.2400 307.0000 1.0000
63.2800 330.0000 1.0000
63.3200 351.0000 1.0000
63.3600 342.0000 1.0000
63.4000 307.0000 1.0000
63.4400 309.0000 1.0000
63.4800 353.0000 1.0000
63.5200 366.0000 1.0000
63.5600 385.0000 1.0000
63.6000 367.0000 1.0000
63.6400 365.0000 1.0000
63.6800 397.0000 1.0000
63.7200 404.0000 1.0000
63.7600 451.0000 1.0000
63.8000 457.0000 1.0000
63.8400 552.0000 1.0000
63.8800 629.0000 1.0000
63.9200 711.0000 1.0000
63.9600 724.0000 1.0000
64.0000 676.0000 1.0000
64.0400 652.0000 1.0000
64.0800 635.0000 1.0000
64.1200 584.0000 1.0000
64.1600 563.0000 1.0000
64.2000 457.0000 1.0000
64.2400 458.0000 1.0000
64.2800 410.0000 1.0000
64.3200 416.0000 1.0000
64.3600 401.0000 1.0000
64.4000 357.0000 1.0000
64.4400 350.0000 1.0000
64.4800 347.0000 1.0000
64.5200 391.0000 1.0000
64.5600 358.0000 1.0000
64.6000 373.0000 1.0000
64.6400 341.0000 1.0000
64.6800 365.0000 1.0000
64.7200 347.0000 1.0000
64.7600 362.0000 1.0000
64.8000 355.0000 1.0000
64.8400 340.0000 1.0000
64.8800 358.0000 1.0000
64.9200 346.0000 1.0000
64.9600 387.0000 1.0000
65.0000 368.0000 1.0000
65.0400 345.0000 1.0000
65.0800 369.0000 1.0000
65.1200 382.0000 1.0000
65.1600 425.0000 1.0000
65.2000 416.0000 1.0000
65.2400 406.0000 1.0000
65.2800 477.0000 1.0000
65.3200 476.0000 1.0000
65.3600 565.0000 1.0000
65.4000 685.0000 1.0000
65.4400 726.0000 1.0000
65.4800 909.0000 1.0000
65.5200 985.0000 1.0000
65.5600 1028.0000 1.0000
65.6000 988.0000 1.0000
65.6400 906.0000 1.0000
65.6800 869.0000 1.0000
65.7200 821.0000 1.0000
65.7600 738.0000 1.0000
65.8000 621.0000 1.0000
65.8400 567.0000 1.0000
65.8800 514.0000 1.0000
65.9200 468.0000 1.0000
65.9600 395.0000 1.0000
66.0000 429.0000 1.0000
66.0400 383.0000 1.0000
66.0800 376.0000 1.0000
66.1200 360.0000 1.0000
66.1600 365.0000 1.0000
66.2000 339.0000 1.0000
66.2400 340.0000 1.0000
66.2800 331.0000 1.0000
66.3200 331.0000 1.0000
66.3600 312.0000 1.0000
66.4000 293.0000 1.0000
66.4400 319.0000 1.0000
66.4800 329.0000 1.0000
66.5200 328.0000 1.0000
66.5600 324.0000 1.0000
66.6000 305.0000 1.0000
66.6400 338.0000 1.0000
66.6800 323.0000 1.0000
66.7200 343.0000 1.0000
66.7600 306.0000 1.0000
66.8000 300.0000 1.0000
66.8400 351.0000 1.0000
66.8800 322.0000 1.0000
66.9200 311.0000 1.0000
66.9600 324.0000 1.0000
67.0000 306.0000 1.0000
67.0400 328.0000 1.0000
67.0800 333.0000 1.0000
67.1200 320.0000 1.0000
67.1600 310.0000 1.0000
67.2000 324.0000 1.0000
67.2400 334.0000 1.0000
67.2800 313.0000 1.0000
67.3200 314.0000 1.0000
67.3600 336.0000 1.0000
67.4000 303.0000 1.0000
67.4400 310.0000 1.0000
67.4800 333.0000 1.0000
67.5200 331.0000 1.0000
67.5600 310.0000 1.0000
67.6000 306.0000 1.0000
67.6400 295.0000 1.0000
67.6800 291.0000 1.0000
67.7200 313.0000 1.0000
67.7600 287.0000 1.0000
67.8000 329.0000 1.0000
67.8400 318.0000 1.0000
67.8800 355.0000 1.0000
67.9200 307.0000 1.0000
67.9600 283.0000 1.0000
68.0000 305.0000 1.0000
68.0400 304.0000 1.0000
68.0800 295.0000 1.0000
68.1200 305.0000 1.0000
68.1600 316.0000 1.0000
68.2000 316.0000 1.0000
68.2400 321.0000 1.0000
68.2800 311.0000 1.0000
68.3200 306.0000 1.0000
68.3600 311.0000 1.0000
68.4000 314.0000 1.0000
68.4400 305.0000 1.0000
68.4800 297.0000 1.0000
68.5200 324.0000 1.0000
68.5600 323.0000 1.0000
68.6000 321.0000 1.0000
68.6400 273.0000 1.0000
68.6800 324.0000 1.0000
68.7200 305.0000 1.0000
68.7600 329.0000 1.0000
68.8000 301.0000 1.0000
68.8400 301.0000 1.0000
68.8800 314.0000 1.0000
68.9200 283.0000 1.0000
68.9600 319.0000 1.0000
69.0000 292.0000 1.0000
69.0400 294.0000 1.0000
69.0800 292.0000 1.0000
69.1200 310.0000 1.0000
69.1600 285.0000 1.0000
69.2000 327.0000 1.0000
69.2400 288.0000 1.0000
69.2800 315.0000 1.0000
69.3200 296.0000 1.0000
69.3600 304.0000 1.0000
69.4000 312.0000 1.0000
69.4400 315.0000 1.0000
69.4800 289.0000 1.0000
69.5200 304.0000 1.0000
69.5600 344.0000 1.0000
69.6000 310.0000 1.0000
69.6400 325.0000 1.0000
69.6800 308.0000 1.0000
69.7200 285.0000 1.0000
69.7600 318.0000 1.0000
69.8000 298.0000 1.0000
69.8400 284.0000 1.0000
69.8800 290.0000 1.0000
69.9200 309.0000 1.0000
69.9600 300.0000 1.0000
70.0000 303.0000 1.0000
*RAS_INT_END
*RAS_TEMPERATURE_START
*RAS_TEMPERATURE_END
*RAS_DATA_END