File: Data/Dataset2_Water_Organic/4_XRD/No_07_Hematite_EtOH_01_4.ras
*RAS_DATA_START
*RAS_HEADER_START
*DISP_FMT_X "%.2f"
*DISP_FMT_Y "%.0f"
*DISP_FULLSCALE "13485.0000000000"
*DISP_LINE_COLOR "255.0000000000"
*DISP_LINE_STYLE "0.0000000000"
*DISP_LINE_WIDTH "0.2500000000"
*DISP_NOTE "測定データ-7"
*DISP_OFFSET_Y "0.0000000000"
*DISP_PEAKSEARCH_UNIT_Y "cps"
*DISP_RANGE_BOTTOM "0.0000000000"
*DISP_RANGE_LEFT "20.0000000000"
*DISP_RANGE_LOGCUTOFF "0.0100000000"
*DISP_RANGE_RIGHT "70.0000000000"
*DISP_RANGE_TOP "13485.0000000000"
*DISP_SCALE_MODE_Y "0.0000000000"
*DISP_TAB_NAME "2θ/θ"
*DISP_TITLE_Y "強度"
*DISP_UNIT_Y "cps"
*DISP_WINDOW_NAME "MSG_MACROENGINE"
*FILE_COMMENT " "
*FILE_MD5 ""
*FILE_MEMO " "
*FILE_OPERATOR "Administrator"
*FILE_SAMPLE " "
*FILE_TYPE "RAS_RAW"
*FILE_USERGROUP "システムマネージャ"
*FILE_VERSION "1.0000000000"
*HW_ATTACHMENT_ID "ATT0025"
*HW_ATTACHMENT_NAME "標準|Standard"
*HW_COUNTER_ID-0 "CUT0025"
*HW_COUNTER_ID-1 "CUT0020"
*HW_COUNTER_ID-2 "CUT0020"
*HW_COUNTER_ID-3 "CSL0021"
*HW_COUNTER_ID-4 "CMC0021"
*HW_COUNTER_NAME-0 "D/teX Ultra|D/teX Ultra"
*HW_COUNTER_NAME-1 "None|None"
*HW_COUNTER_NAME-2 "None|None"
*HW_COUNTER_NAME-3 "BBM|BBM"
*HW_COUNTER_NAME-4 "検出器モノクロメータ|Detector monochromator"
*HW_COUNTER_SELECT_NAME "D/teX Ultra|D/teX Ultra"
*HW_GONIOMETER_ID "GON0023"
*HW_GONIOMETER_NAME "SmartLab|SmartLab"
*HW_GONIOMETER_RADIUS-0 "90.0"
*HW_GONIOMETER_RADIUS-1 "114.0"
*HW_GONIOMETER_RADIUS-2 "190.0"
*HW_GONIOMETER_RADIUS-3 "300.0"
*HW_GONIOMETER_RADIUS-4 "187.0"
*HW_GONIOMETER_RADIUS-5 "300.0"
*HW_GONIOMETER_RADIUS-6 "113.0"
*HW_GONIOMETER_RADIUS-7 "331.0"
*HW_I_OPT_ID-0 "CBO0021"
*HW_I_OPT_ID-1 "ICR0023"
*HW_I_OPT_ID-2 "ISL0021"
*HW_I_OPT_ID-3 "ISO0021"
*HW_I_OPT_ID-4 "IAD0021"
*HW_I_OPT_ID-5 "IPR0001"
*HW_I_OPT_NAME-0 "CBOユニット|CBO unit"
*HW_I_OPT_NAME-1 "標準入射光学ユニット|Standard incident optical unit"
*HW_I_OPT_NAME-2 "標準入射スリットボックス|Standard incident slit box"
*HW_I_OPT_NAME-3 "入射平行スリット|Incident parallel slit"
*HW_I_OPT_NAME-4 "長手制限スリット|Length limiting slit"
*HW_I_OPT_NAME-5 "None|None"
*HW_R_ATTENUATER_AUTOMODE "0"
*HW_R_OPT_ID-0 "RSS0021"
*HW_R_OPT_ID-1 "RCR0023"
*HW_R_OPT_ID-2 "RSO0021"
*HW_R_OPT_ID-3 "RRS0021"
*HW_R_OPT_ID-4 "ATN0021"
*HW_R_OPT_ID-5 "RFL0021"
*HW_R_OPT_ID-6 "RAD0021"
*HW_R_OPT_NAME-0 "標準受光スリットボックス1|Standard receiving slit box # 1"
*HW_R_OPT_NAME-1 "標準受光光学ユニット1|Standard receiving unit # 1"
*HW_R_OPT_NAME-2 "標準受光光学ユニット2|Standard receiving optical unit # 2"
*HW_R_OPT_NAME-3 "標準受光スリットボックス2|Standard receiving slit box # 2"
*HW_R_OPT_NAME-4 "標準アッテネータ|Standard Attenuator"
*HW_R_OPT_NAME-5 "Cu Kβ|Cu K-beta"
*HW_R_OPT_NAME-6 "調整用受光スリット|Alignment receiving slit"
*HW_SAMPLE_HOLDER_ID "SMP0023"
*HW_SAMPLE_HOLDER_NAME "標準Zステージ|Standard Z stage"
*HW_XG_CURRENT_MAX "50"
*HW_XG_CURRENT_MIN "2"
*HW_XG_CURRENT_RESOLUTION "1"
*HW_XG_CURRENT_UNIT "mA"
*HW_XG_FOCUS "1mm x 10mm"
*HW_XG_FOCUS_TYPE "Normal"
*HW_XG_ID ""
*HW_XG_NAME "3kW 封入管(ID:1200)|3kW Sealed tube(ID:1200)"
*HW_XG_TARGET_ATOMIC_NUMBER "29.0000000000"
*HW_XG_TARGET_NAME "Cu"
*HW_XG_TYPE "Hermetic"
*HW_XG_VOLTAGE_MAX "60"
*HW_XG_VOLTAGE_MIN "20"
*HW_XG_VOLTAGE_RESOLUTION "1"
*HW_XG_VOLTAGE_UNIT "kV"
*HW_XG_WATT_MAX "1.500"
*HW_XG_WATT_UNIT "kW"
*HW_XG_WAVE_LENGTH_ALPHA1 "1.540593"
*HW_XG_WAVE_LENGTH_ALPHA2 "1.544414"
*HW_XG_WAVE_LENGTH_BETA "1.392250"
*MEAS_COND_AXIS_NAME-0 "2θ/θ"
*MEAS_COND_AXIS_NAME-1 "2θ"
*MEAS_COND_AXIS_NAME-2 "ω"
*MEAS_COND_AXIS_NAME-3 "Z"
*MEAS_COND_AXIS_NAME-4 "2θ/ω"
*MEAS_COND_AXIS_NAME-5 "θs"
*MEAS_COND_AXIS_NAME-6 "θd"
*MEAS_COND_AXIS_NAME-7 "Ts"
*MEAS_COND_AXIS_NAME-8 "CBO選択スリット"
*MEAS_COND_AXIS_NAME-9 "M"
*MEAS_COND_AXIS_NAME-10 "入射平行スリット"
*MEAS_COND_AXIS_NAME-11 "入射スリット"
*MEAS_COND_AXIS_NAME-12 ""
*MEAS_COND_AXIS_NAME-13 "Zs"
*MEAS_COND_AXIS_NAME-14 "入射光学素子"
*MEAS_COND_AXIS_NAME-15 "長手制限スリット"
*MEAS_COND_AXIS_NAME-16 "センタースリット"
*MEAS_COND_AXIS_NAME-17 "フィルター"
*MEAS_COND_AXIS_NAME-18 "受光スリット1"
*MEAS_COND_AXIS_NAME-19 "受光スリット2"
*MEAS_COND_AXIS_NAME-20 "受光光学素子"
*MEAS_COND_AXIS_NAME-21 "受光平行スリット"
*MEAS_COND_AXIS_NAME-22 "調整用受光スリット"
*MEAS_COND_AXIS_NAME-23 ""
*MEAS_COND_AXIS_NAME-24 ""
*MEAS_COND_AXIS_NAME-25 "Zd"
*MEAS_COND_AXIS_NAME-26 "アッテネータ"
*MEAS_COND_AXIS_NAME-27 "検出器モノクロメータ"
*MEAS_COND_AXIS_NAME-28 "モノクロメータスリット"
*MEAS_COND_AXIS_NAME-29 "プライマリビーム"
*MEAS_COND_AXIS_NAME-30 "PHA"
*MEAS_COND_AXIS_NAME_INTERNAL-0 "TwoThetaTheta"
*MEAS_COND_AXIS_NAME_INTERNAL-1 "TwoTheta"
*MEAS_COND_AXIS_NAME_INTERNAL-2 "Omega"
*MEAS_COND_AXIS_NAME_INTERNAL-3 "Z"
*MEAS_COND_AXIS_NAME_INTERNAL-4 "TwoThetaOmega"
*MEAS_COND_AXIS_NAME_INTERNAL-5 "ThetaS"
*MEAS_COND_AXIS_NAME_INTERNAL-6 "ThetaD"
*MEAS_COND_AXIS_NAME_INTERNAL-7 "Ts"
*MEAS_COND_AXIS_NAME_INTERNAL-8 "CBO"
*MEAS_COND_AXIS_NAME_INTERNAL-9 "CBO-M"
*MEAS_COND_AXIS_NAME_INTERNAL-10 "IncidentSollerSlit"
*MEAS_COND_AXIS_NAME_INTERNAL-11 "IncidentSlitBox"
*MEAS_COND_AXIS_NAME_INTERNAL-12 "IncidentSlitBox-_Axis"
*MEAS_COND_AXIS_NAME_INTERNAL-13 "Zs"
*MEAS_COND_AXIS_NAME_INTERNAL-14 "IncidentMonochromator"
*MEAS_COND_AXIS_NAME_INTERNAL-15 "IncidentAxdSlit"
*MEAS_COND_AXIS_NAME_INTERNAL-16 "CenterSlit"
*MEAS_COND_AXIS_NAME_INTERNAL-17 "Filter"
*MEAS_COND_AXIS_NAME_INTERNAL-18 "ReceivingSlitBox1"
*MEAS_COND_AXIS_NAME_INTERNAL-19 "ReceivingSlitBox2"
*MEAS_COND_AXIS_NAME_INTERNAL-20 "ReceivingOptics"
*MEAS_COND_AXIS_NAME_INTERNAL-21 "ReceivingSollerSlit"
*MEAS_COND_AXIS_NAME_INTERNAL-22 "ReceivingAxdSlit"
*MEAS_COND_AXIS_NAME_INTERNAL-23 "ReceivingSlitBox1-_Axis"
*MEAS_COND_AXIS_NAME_INTERNAL-24 "ReceivingSlitBox2-_Axis"
*MEAS_COND_AXIS_NAME_INTERNAL-25 "ReceivingSlitBox2-Zd"
*MEAS_COND_AXIS_NAME_INTERNAL-26 "Attenuator"
*MEAS_COND_AXIS_NAME_INTERNAL-27 "CounterMonochromator"
*MEAS_COND_AXIS_NAME_INTERNAL-28 "CounterSlit"
*MEAS_COND_AXIS_NAME_INTERNAL-29 "IncidentPrimary"
*MEAS_COND_AXIS_NAME_INTERNAL-30 "PHA"
*MEAS_COND_AXIS_NAME_MAGICNO-0 "83951616.0000000000"
*MEAS_COND_AXIS_NAME_MAGICNO-1 "268632064.0000000000"
*MEAS_COND_AXIS_NAME_MAGICNO-2 "268500992.0000000000"
*MEAS_COND_AXIS_NAME_MAGICNO-3 "285278208.0000000000"
*MEAS_COND_AXIS_NAME_MAGICNO-4 "83951616.0000000000"
*MEAS_COND_AXIS_NAME_MAGICNO-5 "131072.0000000000"
*MEAS_COND_AXIS_NAME_MAGICNO-6 "131072.0000000000"
*MEAS_COND_AXIS_NAME_MAGICNO-7 "318898176.0000000000"
*MEAS_COND_AXIS_NAME_MAGICNO-8 "20971521.0000000000"
*MEAS_COND_AXIS_NAME_MAGICNO-9 "285343744.0000000000"
*MEAS_COND_AXIS_NAME_MAGICNO-10 "20971521.0000000000"
*MEAS_COND_AXIS_NAME_MAGICNO-11 "22020097.0000000000"
*MEAS_COND_AXIS_NAME_MAGICNO-12 "25165824.0000000000"
*MEAS_COND_AXIS_NAME_MAGICNO-13 "318898176.0000000000"
*MEAS_COND_AXIS_NAME_MAGICNO-14 "1.0000000000"
*MEAS_COND_AXIS_NAME_MAGICNO-15 "20971521.0000000000"
*MEAS_COND_AXIS_NAME_MAGICNO-16 "20971521.0000000000"
*MEAS_COND_AXIS_NAME_MAGICNO-17 "20971521.0000000000"
*MEAS_COND_AXIS_NAME_MAGICNO-18 "23068673.0000000000"
*MEAS_COND_AXIS_NAME_MAGICNO-19 "23068673.0000000000"
*MEAS_COND_AXIS_NAME_MAGICNO-20 "20971521.0000000000"
*MEAS_COND_AXIS_NAME_MAGICNO-21 "20971521.0000000000"
*MEAS_COND_AXIS_NAME_MAGICNO-22 "20971521.0000000000"
*MEAS_COND_AXIS_NAME_MAGICNO-23 "25165824.0000000000"
*MEAS_COND_AXIS_NAME_MAGICNO-24 "25165824.0000000000"
*MEAS_COND_AXIS_NAME_MAGICNO-25 "285343744.0000000000"
*MEAS_COND_AXIS_NAME_MAGICNO-26 "17301505.0000000000"
*MEAS_COND_AXIS_NAME_MAGICNO-27 "20971521.0000000000"
*MEAS_COND_AXIS_NAME_MAGICNO-28 "20971521.0000000000"
*MEAS_COND_AXIS_NAME_MAGICNO-29 "20971521.0000000000"
*MEAS_COND_AXIS_NAME_MAGICNO-30 "0.0000000000"
*MEAS_COND_AXIS_OFFSET-0 "-"
*MEAS_COND_AXIS_OFFSET-1 "-0.0310000000"
*MEAS_COND_AXIS_OFFSET-2 "0.5056000000"
*MEAS_COND_AXIS_OFFSET-3 "-"
*MEAS_COND_AXIS_OFFSET-4 "-"
*MEAS_COND_AXIS_OFFSET-5 "0.5056000000"
*MEAS_COND_AXIS_OFFSET-6 "-0.5366000000"
*MEAS_COND_AXIS_OFFSET-7 "-"
*MEAS_COND_AXIS_OFFSET-8 "-"
*MEAS_COND_AXIS_OFFSET-9 "-"
*MEAS_COND_AXIS_OFFSET-10 "-"
*MEAS_COND_AXIS_OFFSET-11 "-"
*MEAS_COND_AXIS_OFFSET-12 "-"
*MEAS_COND_AXIS_OFFSET-13 "-"
*MEAS_COND_AXIS_OFFSET-14 "-"
*MEAS_COND_AXIS_OFFSET-15 "-"
*MEAS_COND_AXIS_OFFSET-16 "-"
*MEAS_COND_AXIS_OFFSET-17 "-"
*MEAS_COND_AXIS_OFFSET-18 "-"
*MEAS_COND_AXIS_OFFSET-19 "-"
*MEAS_COND_AXIS_OFFSET-20 "-"
*MEAS_COND_AXIS_OFFSET-21 "-"
*MEAS_COND_AXIS_OFFSET-22 "-"
*MEAS_COND_AXIS_OFFSET-23 "-"
*MEAS_COND_AXIS_OFFSET-24 "-"
*MEAS_COND_AXIS_OFFSET-25 "-"
*MEAS_COND_AXIS_OFFSET-26 "-"
*MEAS_COND_AXIS_OFFSET-27 "-"
*MEAS_COND_AXIS_OFFSET-28 "-"
*MEAS_COND_AXIS_OFFSET-29 "-"
*MEAS_COND_AXIS_OFFSET-30 "-"
*MEAS_COND_AXIS_POSITION-0 "0.0000000000"
*MEAS_COND_AXIS_POSITION-1 "0.0000000000"
*MEAS_COND_AXIS_POSITION-2 "0.0000000000"
*MEAS_COND_AXIS_POSITION-3 "-2.9031400000"
*MEAS_COND_AXIS_POSITION-4 "0.0000000000"
*MEAS_COND_AXIS_POSITION-5 "0.0000000000"
*MEAS_COND_AXIS_POSITION-6 "0.0000000000"
*MEAS_COND_AXIS_POSITION-7 "-0.7498700000"
*MEAS_COND_AXIS_POSITION-8 "BB"
*MEAS_COND_AXIS_POSITION-9 "0.0000000000"
*MEAS_COND_AXIS_POSITION-10 "Soller_slit_5.0deg"
*MEAS_COND_AXIS_POSITION-11 "2/3deg"
*MEAS_COND_AXIS_POSITION-12 "2.2088000000"
*MEAS_COND_AXIS_POSITION-13 "-0.6412500000"
*MEAS_COND_AXIS_POSITION-14 "0.0000000000"
*MEAS_COND_AXIS_POSITION-15 "10.0mm"
*MEAS_COND_AXIS_POSITION-16 "None"
*MEAS_COND_AXIS_POSITION-17 "Cu_K-beta"
*MEAS_COND_AXIS_POSITION-18 "13.000mm"
*MEAS_COND_AXIS_POSITION-19 "13.000mm"
*MEAS_COND_AXIS_POSITION-20 "No_unit"
*MEAS_COND_AXIS_POSITION-21 "Soller_slit_5.0deg"
*MEAS_COND_AXIS_POSITION-22 "None"
*MEAS_COND_AXIS_POSITION-23 "13.0000000000"
*MEAS_COND_AXIS_POSITION-24 "13.0000000000"
*MEAS_COND_AXIS_POSITION-25 "0.0281300000"
*MEAS_COND_AXIS_POSITION-26 "Open"
*MEAS_COND_AXIS_POSITION-27 "None"
*MEAS_COND_AXIS_POSITION-28 "None"
*MEAS_COND_AXIS_POSITION-29 "None"
*MEAS_COND_AXIS_POSITION-30 "38.0000000000"
*MEAS_COND_AXIS_UNIT-0 "deg"
*MEAS_COND_AXIS_UNIT-1 "deg"
*MEAS_COND_AXIS_UNIT-2 "deg"
*MEAS_COND_AXIS_UNIT-3 "mm"
*MEAS_COND_AXIS_UNIT-4 "deg"
*MEAS_COND_AXIS_UNIT-5 "deg"
*MEAS_COND_AXIS_UNIT-6 "deg"
*MEAS_COND_AXIS_UNIT-7 "mm"
*MEAS_COND_AXIS_UNIT-8 ""
*MEAS_COND_AXIS_UNIT-9 "pulse"
*MEAS_COND_AXIS_UNIT-10 ""
*MEAS_COND_AXIS_UNIT-11 ""
*MEAS_COND_AXIS_UNIT-12 "mm"
*MEAS_COND_AXIS_UNIT-13 "mm"
*MEAS_COND_AXIS_UNIT-14 ""
*MEAS_COND_AXIS_UNIT-15 ""
*MEAS_COND_AXIS_UNIT-16 ""
*MEAS_COND_AXIS_UNIT-17 ""
*MEAS_COND_AXIS_UNIT-18 ""
*MEAS_COND_AXIS_UNIT-19 ""
*MEAS_COND_AXIS_UNIT-20 ""
*MEAS_COND_AXIS_UNIT-21 ""
*MEAS_COND_AXIS_UNIT-22 ""
*MEAS_COND_AXIS_UNIT-23 "mm"
*MEAS_COND_AXIS_UNIT-24 "mm"
*MEAS_COND_AXIS_UNIT-25 "mm"
*MEAS_COND_AXIS_UNIT-26 ""
*MEAS_COND_AXIS_UNIT-27 ""
*MEAS_COND_AXIS_UNIT-28 ""
*MEAS_COND_AXIS_UNIT-29 ""
*MEAS_COND_AXIS_UNIT-30 "div"
*MEAS_COND_COUNTER_CNTLOSS_CORR "0.0000000000"
*MEAS_COND_COUNTER_PHABASE "38.0000000000"
*MEAS_COND_COUNTER_PHAWINDOW "16.0000000000"
*MEAS_COND_COUNTER_PHA_UNIT "div"
*MEAS_COND_COUNTER_TAUDIFF "30.0000000000"
*MEAS_COND_COUNTER_TAUINT "0.0000000000"
*MEAS_COND_IRRADIATION_MODE "OFF"
*MEAS_COND_IRRADIATION_WIDTH ""
*MEAS_COND_OPT_ATTR "集中法"
*MEAS_COND_OPT_NAME "@集中法"
*MEAS_COND_UNSYMMETRIC_MODE "OFF"
*MEAS_COND_XG_CURRENT "30.0000000000"
*MEAS_COND_XG_VOLTAGE "40.0000000000"
*MEAS_COND_XG_WAVE_TYPE "Ka"
*MEAS_DATA_COUNT "5001.0000000000"
*MEAS_SCAN_AXIS_X "2θ/θ"
*MEAS_SCAN_AXIS_X_INTERNAL "TwoThetaTheta"
*MEAS_SCAN_END_TIME "07/27/23 21:58:36"
*MEAS_SCAN_MODE "CONTINUOUS"
*MEAS_SCAN_MONITOR "0"
*MEAS_SCAN_RESOLUTION_X "0.0002"
*MEAS_SCAN_SPEED "2.5"
*MEAS_SCAN_SPEED_UNIT "deg/min"
*MEAS_SCAN_START "20.0000000000"
*MEAS_SCAN_START_TIME "07/27/23 21:37:13"
*MEAS_SCAN_STEP "0.0100000000"
*MEAS_SCAN_STOP "70.0000000000"
*MEAS_SCAN_UNIT_X "deg"
*MEAS_SCAN_UNIT_Y "counts"
*RAS_HEADER_END
*RAS_INT_START
20.0000 998.0000 1.0000
20.0400 968.0000 1.0000
20.0800 988.0000 1.0000
20.1200 972.0000 1.0000
20.1600 1019.0000 1.0000
20.2000 1009.0000 1.0000
20.2400 956.0000 1.0000
20.2800 995.0000 1.0000
20.3200 1007.0000 1.0000
20.3600 941.0000 1.0000
20.4000 982.0000 1.0000
20.4400 1045.0000 1.0000
20.4800 953.0000 1.0000
20.5200 971.0000 1.0000
20.5600 942.0000 1.0000
20.6000 984.0000 1.0000
20.6400 966.0000 1.0000
20.6800 963.0000 1.0000
20.7200 975.0000 1.0000
20.7600 969.0000 1.0000
20.8000 935.0000 1.0000
20.8400 966.0000 1.0000
20.8800 942.0000 1.0000
20.9200 991.0000 1.0000
20.9600 920.0000 1.0000
21.0000 1004.0000 1.0000
21.0400 984.0000 1.0000
21.0800 929.0000 1.0000
21.1200 938.0000 1.0000
21.1600 927.0000 1.0000
21.2000 937.0000 1.0000
21.2400 923.0000 1.0000
21.2800 927.0000 1.0000
21.3200 985.0000 1.0000
21.3600 934.0000 1.0000
21.4000 928.0000 1.0000
21.4400 932.0000 1.0000
21.4800 915.0000 1.0000
21.5200 959.0000 1.0000
21.5600 946.0000 1.0000
21.6000 962.0000 1.0000
21.6400 978.0000 1.0000
21.6800 947.0000 1.0000
21.7200 921.0000 1.0000
21.7600 965.0000 1.0000
21.8000 1002.0000 1.0000
21.8400 952.0000 1.0000
21.8800 940.0000 1.0000
21.9200 977.0000 1.0000
21.9600 919.0000 1.0000
22.0000 941.0000 1.0000
22.0400 899.0000 1.0000
22.0800 923.0000 1.0000
22.1200 985.0000 1.0000
22.1600 927.0000 1.0000
22.2000 958.0000 1.0000
22.2400 888.0000 1.0000
22.2800 941.0000 1.0000
22.3200 923.0000 1.0000
22.3600 956.0000 1.0000
22.4000 977.0000 1.0000
22.4400 967.0000 1.0000
22.4800 965.0000 1.0000
22.5200 888.0000 1.0000
22.5600 947.0000 1.0000
22.6000 945.0000 1.0000
22.6400 921.0000 1.0000
22.6800 957.0000 1.0000
22.7200 888.0000 1.0000
22.7600 956.0000 1.0000
22.8000 922.0000 1.0000
22.8400 952.0000 1.0000
22.8800 911.0000 1.0000
22.9200 919.0000 1.0000
22.9600 948.0000 1.0000
23.0000 873.0000 1.0000
23.0400 948.0000 1.0000
23.0800 948.0000 1.0000
23.1200 928.0000 1.0000
23.1600 950.0000 1.0000
23.2000 912.0000 1.0000
23.2400 932.0000 1.0000
23.2800 929.0000 1.0000
23.3200 945.0000 1.0000
23.3600 925.0000 1.0000
23.4000 895.0000 1.0000
23.4400 896.0000 1.0000
23.4800 950.0000 1.0000
23.5200 930.0000 1.0000
23.5600 955.0000 1.0000
23.6000 923.0000 1.0000
23.6400 926.0000 1.0000
23.6800 946.0000 1.0000
23.7200 895.0000 1.0000
23.7600 973.0000 1.0000
23.8000 896.0000 1.0000
23.8400 943.0000 1.0000
23.8800 955.0000 1.0000
23.9200 961.0000 1.0000
23.9600 1013.0000 1.0000
24.0000 995.0000 1.0000
24.0400 1050.0000 1.0000
24.0800 1018.0000 1.0000
24.1200 1042.0000 1.0000
24.1600 979.0000 1.0000
24.2000 969.0000 1.0000
24.2400 920.0000 1.0000
24.2800 930.0000 1.0000
24.3200 894.0000 1.0000
24.3600 953.0000 1.0000
24.4000 904.0000 1.0000
24.4400 917.0000 1.0000
24.4800 899.0000 1.0000
24.5200 904.0000 1.0000
24.5600 892.0000 1.0000
24.6000 898.0000 1.0000
24.6400 915.0000 1.0000
24.6800 897.0000 1.0000
24.7200 952.0000 1.0000
24.7600 915.0000 1.0000
24.8000 941.0000 1.0000
24.8400 903.0000 1.0000
24.8800 900.0000 1.0000
24.9200 899.0000 1.0000
24.9600 843.0000 1.0000
25.0000 898.0000 1.0000
25.0400 867.0000 1.0000
25.0800 882.0000 1.0000
25.1200 901.0000 1.0000
25.1600 887.0000 1.0000
25.2000 874.0000 1.0000
25.2400 903.0000 1.0000
25.2800 846.0000 1.0000
25.3200 868.0000 1.0000
25.3600 875.0000 1.0000
25.4000 942.0000 1.0000
25.4400 888.0000 1.0000
25.4800 847.0000 1.0000
25.5200 922.0000 1.0000
25.5600 886.0000 1.0000
25.6000 917.0000 1.0000
25.6400 895.0000 1.0000
25.6800 944.0000 1.0000
25.7200 890.0000 1.0000
25.7600 943.0000 1.0000
25.8000 919.0000 1.0000
25.8400 930.0000 1.0000
25.8800 914.0000 1.0000
25.9200 938.0000 1.0000
25.9600 930.0000 1.0000
26.0000 974.0000 1.0000
26.0400 1014.0000 1.0000
26.0800 983.0000 1.0000
26.1200 1048.0000 1.0000
26.1600 1103.0000 1.0000
26.2000 1126.0000 1.0000
26.2400 1361.0000 1.0000
26.2800 1451.0000 1.0000
26.3200 1800.0000 1.0000
26.3600 2204.0000 1.0000
26.4000 2645.0000 1.0000
26.4400 2678.0000 1.0000
26.4800 2461.0000 1.0000
26.5200 2046.0000 1.0000
26.5600 1641.0000 1.0000
26.6000 1455.0000 1.0000
26.6400 1212.0000 1.0000
26.6800 1123.0000 1.0000
26.7200 1082.0000 1.0000
26.7600 973.0000 1.0000
26.8000 982.0000 1.0000
26.8400 932.0000 1.0000
26.8800 909.0000 1.0000
26.9200 916.0000 1.0000
26.9600 889.0000 1.0000
27.0000 875.0000 1.0000
27.0400 880.0000 1.0000
27.0800 881.0000 1.0000
27.1200 858.0000 1.0000
27.1600 870.0000 1.0000
27.2000 834.0000 1.0000
27.2400 804.0000 1.0000
27.2800 858.0000 1.0000
27.3200 829.0000 1.0000
27.3600 835.0000 1.0000
27.4000 866.0000 1.0000
27.4400 809.0000 1.0000
27.4800 850.0000 1.0000
27.5200 803.0000 1.0000
27.5600 794.0000 1.0000
27.6000 836.0000 1.0000
27.6400 835.0000 1.0000
27.6800 800.0000 1.0000
27.7200 810.0000 1.0000
27.7600 793.0000 1.0000
27.8000 850.0000 1.0000
27.8400 822.0000 1.0000
27.8800 813.0000 1.0000
27.9200 806.0000 1.0000
27.9600 742.0000 1.0000
28.0000 774.0000 1.0000
28.0400 780.0000 1.0000
28.0800 802.0000 1.0000
28.1200 807.0000 1.0000
28.1600 823.0000 1.0000
28.2000 771.0000 1.0000
28.2400 821.0000 1.0000
28.2800 794.0000 1.0000
28.3200 812.0000 1.0000
28.3600 817.0000 1.0000
28.4000 792.0000 1.0000
28.4400 821.0000 1.0000
28.4800 805.0000 1.0000
28.5200 778.0000 1.0000
28.5600 779.0000 1.0000
28.6000 746.0000 1.0000
28.6400 769.0000 1.0000
28.6800 719.0000 1.0000
28.7200 760.0000 1.0000
28.7600 736.0000 1.0000
28.8000 806.0000 1.0000
28.8400 819.0000 1.0000
28.8800 772.0000 1.0000
28.9200 812.0000 1.0000
28.9600 809.0000 1.0000
29.0000 788.0000 1.0000
29.0400 719.0000 1.0000
29.0800 742.0000 1.0000
29.1200 764.0000 1.0000
29.1600 764.0000 1.0000
29.2000 754.0000 1.0000
29.2400 751.0000 1.0000
29.2800 763.0000 1.0000
29.3200 733.0000 1.0000
29.3600 820.0000 1.0000
29.4000 763.0000 1.0000
29.4400 696.0000 1.0000
29.4800 762.0000 1.0000
29.5200 771.0000 1.0000
29.5600 730.0000 1.0000
29.6000 698.0000 1.0000
29.6400 738.0000 1.0000
29.6800 717.0000 1.0000
29.7200 729.0000 1.0000
29.7600 743.0000 1.0000
29.8000 705.0000 1.0000
29.8400 739.0000 1.0000
29.8800 739.0000 1.0000
29.9200 706.0000 1.0000
29.9600 772.0000 1.0000
30.0000 737.0000 1.0000
30.0400 758.0000 1.0000
30.0800 747.0000 1.0000
30.1200 727.0000 1.0000
30.1600 780.0000 1.0000
30.2000 716.0000 1.0000
30.2400 692.0000 1.0000
30.2800 747.0000 1.0000
30.3200 716.0000 1.0000
30.3600 746.0000 1.0000
30.4000 749.0000 1.0000
30.4400 729.0000 1.0000
30.4800 740.0000 1.0000
30.5200 732.0000 1.0000
30.5600 727.0000 1.0000
30.6000 701.0000 1.0000
30.6400 723.0000 1.0000
30.6800 723.0000 1.0000
30.7200 725.0000 1.0000
30.7600 710.0000 1.0000
30.8000 690.0000 1.0000
30.8400 674.0000 1.0000
30.8800 727.0000 1.0000
30.9200 733.0000 1.0000
30.9600 701.0000 1.0000
31.0000 678.0000 1.0000
31.0400 762.0000 1.0000
31.0800 678.0000 1.0000
31.1200 692.0000 1.0000
31.1600 760.0000 1.0000
31.2000 666.0000 1.0000
31.2400 762.0000 1.0000
31.2800 685.0000 1.0000
31.3200 678.0000 1.0000
31.3600 702.0000 1.0000
31.4000 703.0000 1.0000
31.4400 699.0000 1.0000
31.4800 691.0000 1.0000
31.5200 718.0000 1.0000
31.5600 674.0000 1.0000
31.6000 679.0000 1.0000
31.6400 659.0000 1.0000
31.6800 652.0000 1.0000
31.7200 677.0000 1.0000
31.7600 677.0000 1.0000
31.8000 660.0000 1.0000
31.8400 669.0000 1.0000
31.8800 682.0000 1.0000
31.9200 737.0000 1.0000
31.9600 689.0000 1.0000
32.0000 697.0000 1.0000
32.0400 656.0000 1.0000
32.0800 672.0000 1.0000
32.1200 652.0000 1.0000
32.1600 630.0000 1.0000
32.2000 693.0000 1.0000
32.2400 689.0000 1.0000
32.2800 668.0000 1.0000
32.3200 639.0000 1.0000
32.3600 619.0000 1.0000
32.4000 676.0000 1.0000
32.4400 676.0000 1.0000
32.4800 654.0000 1.0000
32.5200 652.0000 1.0000
32.5600 653.0000 1.0000
32.6000 663.0000 1.0000
32.6400 681.0000 1.0000
32.6800 676.0000 1.0000
32.7200 682.0000 1.0000
32.7600 657.0000 1.0000
32.8000 654.0000 1.0000
32.8400 694.0000 1.0000
32.8800 663.0000 1.0000
32.9200 679.0000 1.0000
32.9600 725.0000 1.0000
33.0000 766.0000 1.0000
33.0400 785.0000 1.0000
33.0800 834.0000 1.0000
33.1200 768.0000 1.0000
33.1600 758.0000 1.0000
33.2000 766.0000 1.0000
33.2400 759.0000 1.0000
33.2800 740.0000 1.0000
33.3200 723.0000 1.0000
33.3600 765.0000 1.0000
33.4000 881.0000 1.0000
33.4400 799.0000 1.0000
33.4800 862.0000 1.0000
33.5200 1014.0000 1.0000
33.5600 1154.0000 1.0000
33.6000 1371.0000 1.0000
33.6400 1477.0000 1.0000
33.6800 1415.0000 1.0000
33.7200 1255.0000 1.0000
33.7600 1100.0000 1.0000
33.8000 951.0000 1.0000
33.8400 880.0000 1.0000
33.8800 806.0000 1.0000
33.9200 743.0000 1.0000
33.9600 723.0000 1.0000
34.0000 731.0000 1.0000
34.0400 704.0000 1.0000
34.0800 627.0000 1.0000
34.1200 634.0000 1.0000
34.1600 652.0000 1.0000
34.2000 619.0000 1.0000
34.2400 632.0000 1.0000
34.2800 681.0000 1.0000
34.3200 624.0000 1.0000
34.3600 605.0000 1.0000
34.4000 609.0000 1.0000
34.4400 612.0000 1.0000
34.4800 615.0000 1.0000
34.5200 612.0000 1.0000
34.5600 633.0000 1.0000
34.6000 608.0000 1.0000
34.6400 607.0000 1.0000
34.6800 578.0000 1.0000
34.7200 625.0000 1.0000
34.7600 611.0000 1.0000
34.8000 585.0000 1.0000
34.8400 616.0000 1.0000
34.8800 571.0000 1.0000
34.9200 603.0000 1.0000
34.9600 599.0000 1.0000
35.0000 553.0000 1.0000
35.0400 584.0000 1.0000
35.0800 588.0000 1.0000
35.1200 580.0000 1.0000
35.1600 585.0000 1.0000
35.2000 599.0000 1.0000
35.2400 598.0000 1.0000
35.2800 620.0000 1.0000
35.3200 649.0000 1.0000
35.3600 664.0000 1.0000
35.4000 738.0000 1.0000
35.4400 869.0000 1.0000
35.4800 1108.0000 1.0000
35.5200 1398.0000 1.0000
35.5600 1462.0000 1.0000
35.6000 1349.0000 1.0000
35.6400 1225.0000 1.0000
35.6800 982.0000 1.0000
35.7200 812.0000 1.0000
35.7600 677.0000 1.0000
35.8000 609.0000 1.0000
35.8400 607.0000 1.0000
35.8800 569.0000 1.0000
35.9200 567.0000 1.0000
35.9600 577.0000 1.0000
36.0000 558.0000 1.0000
36.0400 557.0000 1.0000
36.0800 571.0000 1.0000
36.1200 579.0000 1.0000
36.1600 518.0000 1.0000
36.2000 561.0000 1.0000
36.2400 542.0000 1.0000
36.2800 570.0000 1.0000
36.3200 521.0000 1.0000
36.3600 592.0000 1.0000
36.4000 549.0000 1.0000
36.4400 506.0000 1.0000
36.4800 559.0000 1.0000
36.5200 547.0000 1.0000
36.5600 550.0000 1.0000
36.6000 518.0000 1.0000
36.6400 520.0000 1.0000
36.6800 589.0000 1.0000
36.7200 536.0000 1.0000
36.7600 572.0000 1.0000
36.8000 569.0000 1.0000
36.8400 540.0000 1.0000
36.8800 551.0000 1.0000
36.9200 557.0000 1.0000
36.9600 529.0000 1.0000
37.0000 580.0000 1.0000
37.0400 547.0000 1.0000
37.0800 541.0000 1.0000
37.1200 521.0000 1.0000
37.1600 617.0000 1.0000
37.2000 578.0000 1.0000
37.2400 577.0000 1.0000
37.2800 588.0000 1.0000
37.3200 562.0000 1.0000
37.3600 662.0000 1.0000
37.4000 681.0000 1.0000
37.4400 773.0000 1.0000
37.4800 911.0000 1.0000
37.5200 1000.0000 1.0000
37.5600 1277.0000 1.0000
37.6000 1606.0000 1.0000
37.6400 1855.0000 1.0000
37.6800 2137.0000 1.0000
37.7200 2105.0000 1.0000
37.7600 1967.0000 1.0000
37.8000 1641.0000 1.0000
37.8400 1371.0000 1.0000
37.8800 1060.0000 1.0000
37.9200 895.0000 1.0000
37.9600 773.0000 1.0000
38.0000 692.0000 1.0000
38.0400 596.0000 1.0000
38.0800 608.0000 1.0000
38.1200 573.0000 1.0000
38.1600 525.0000 1.0000
38.2000 546.0000 1.0000
38.2400 549.0000 1.0000
38.2800 547.0000 1.0000
38.3200 532.0000 1.0000
38.3600 534.0000 1.0000
38.4000 482.0000 1.0000
38.4400 503.0000 1.0000
38.4800 444.0000 1.0000
38.5200 525.0000 1.0000
38.5600 516.0000 1.0000
38.6000 520.0000 1.0000
38.6400 546.0000 1.0000
38.6800 508.0000 1.0000
38.7200 501.0000 1.0000
38.7600 508.0000 1.0000
38.8000 512.0000 1.0000
38.8400 514.0000 1.0000
38.8800 494.0000 1.0000
38.9200 513.0000 1.0000
38.9600 509.0000 1.0000
39.0000 484.0000 1.0000
39.0400 487.0000 1.0000
39.0800 508.0000 1.0000
39.1200 469.0000 1.0000
39.1600 511.0000 1.0000
39.2000 479.0000 1.0000
39.2400 469.0000 1.0000
39.2800 496.0000 1.0000
39.3200 513.0000 1.0000
39.3600 491.0000 1.0000
39.4000 463.0000 1.0000
39.4400 475.0000 1.0000
39.4800 490.0000 1.0000
39.5200 488.0000 1.0000
39.5600 491.0000 1.0000
39.6000 468.0000 1.0000
39.6400 464.0000 1.0000
39.6800 469.0000 1.0000
39.7200 449.0000 1.0000
39.7600 474.0000 1.0000
39.8000 502.0000 1.0000
39.8400 468.0000 1.0000
39.8800 486.0000 1.0000
39.9200 492.0000 1.0000
39.9600 455.0000 1.0000
40.0000 463.0000 1.0000
40.0400 461.0000 1.0000
40.0800 465.0000 1.0000
40.1200 485.0000 1.0000
40.1600 435.0000 1.0000
40.2000 455.0000 1.0000
40.2400 426.0000 1.0000
40.2800 442.0000 1.0000
40.3200 457.0000 1.0000
40.3600 476.0000 1.0000
40.4000 487.0000 1.0000
40.4400 503.0000 1.0000
40.4800 487.0000 1.0000
40.5200 486.0000 1.0000
40.5600 484.0000 1.0000
40.6000 434.0000 1.0000
40.6400 493.0000 1.0000
40.6800 456.0000 1.0000
40.7200 473.0000 1.0000
40.7600 475.0000 1.0000
40.8000 504.0000 1.0000
40.8400 486.0000 1.0000
40.8800 479.0000 1.0000
40.9200 464.0000 1.0000
40.9600 466.0000 1.0000
41.0000 438.0000 1.0000
41.0400 481.0000 1.0000
41.0800 460.0000 1.0000
41.1200 439.0000 1.0000
41.1600 432.0000 1.0000
41.2000 449.0000 1.0000
41.2400 451.0000 1.0000
41.2800 463.0000 1.0000
41.3200 445.0000 1.0000
41.3600 448.0000 1.0000
41.4000 455.0000 1.0000
41.4400 428.0000 1.0000
41.4800 471.0000 1.0000
41.5200 463.0000 1.0000
41.5600 449.0000 1.0000
41.6000 432.0000 1.0000
41.6400 438.0000 1.0000
41.6800 444.0000 1.0000
41.7200 459.0000 1.0000
41.7600 466.0000 1.0000
41.8000 421.0000 1.0000
41.8400 449.0000 1.0000
41.8800 450.0000 1.0000
41.9200 440.0000 1.0000
41.9600 429.0000 1.0000
42.0000 434.0000 1.0000
42.0400 442.0000 1.0000
42.0800 475.0000 1.0000
42.1200 437.0000 1.0000
42.1600 460.0000 1.0000
42.2000 432.0000 1.0000
42.2400 473.0000 1.0000
42.2800 446.0000 1.0000
42.3200 461.0000 1.0000
42.3600 493.0000 1.0000
42.4000 492.0000 1.0000
42.4400 459.0000 1.0000
42.4800 464.0000 1.0000
42.5200 489.0000 1.0000
42.5600 434.0000 1.0000
42.6000 447.0000 1.0000
42.6400 459.0000 1.0000
42.6800 483.0000 1.0000
42.7200 478.0000 1.0000
42.7600 427.0000 1.0000
42.8000 438.0000 1.0000
42.8400 451.0000 1.0000
42.8800 412.0000 1.0000
42.9200 422.0000 1.0000
42.9600 450.0000 1.0000
43.0000 418.0000 1.0000
43.0400 481.0000 1.0000
43.0800 444.0000 1.0000
43.1200 435.0000 1.0000
43.1600 449.0000 1.0000
43.2000 432.0000 1.0000
43.2400 460.0000 1.0000
43.2800 456.0000 1.0000
43.3200 419.0000 1.0000
43.3600 461.0000 1.0000
43.4000 469.0000 1.0000
43.4400 428.0000 1.0000
43.4800 444.0000 1.0000
43.5200 421.0000 1.0000
43.5600 464.0000 1.0000
43.6000 428.0000 1.0000
43.6400 438.0000 1.0000
43.6800 434.0000 1.0000
43.7200 422.0000 1.0000
43.7600 374.0000 1.0000
43.8000 392.0000 1.0000
43.8400 491.0000 1.0000
43.8800 423.0000 1.0000
43.9200 405.0000 1.0000
43.9600 396.0000 1.0000
44.0000 398.0000 1.0000
44.0400 408.0000 1.0000
44.0800 414.0000 1.0000
44.1200 401.0000 1.0000
44.1600 418.0000 1.0000
44.2000 435.0000 1.0000
44.2400 414.0000 1.0000
44.2800 413.0000 1.0000
44.3200 408.0000 1.0000
44.3600 429.0000 1.0000
44.4000 402.0000 1.0000
44.4400 396.0000 1.0000
44.4800 409.0000 1.0000
44.5200 433.0000 1.0000
44.5600 418.0000 1.0000
44.6000 422.0000 1.0000
44.6400 452.0000 1.0000
44.6800 417.0000 1.0000
44.7200 422.0000 1.0000
44.7600 404.0000 1.0000
44.8000 390.0000 1.0000
44.8400 400.0000 1.0000
44.8800 428.0000 1.0000
44.9200 404.0000 1.0000
44.9600 426.0000 1.0000
45.0000 395.0000 1.0000
45.0400 405.0000 1.0000
45.0800 420.0000 1.0000
45.1200 407.0000 1.0000
45.1600 413.0000 1.0000
45.2000 414.0000 1.0000
45.2400 454.0000 1.0000
45.2800 432.0000 1.0000
45.3200 438.0000 1.0000
45.3600 432.0000 1.0000
45.4000 398.0000 1.0000
45.4400 411.0000 1.0000
45.4800 417.0000 1.0000
45.5200 394.0000 1.0000
45.5600 400.0000 1.0000
45.6000 377.0000 1.0000
45.6400 416.0000 1.0000
45.6800 413.0000 1.0000
45.7200 423.0000 1.0000
45.7600 428.0000 1.0000
45.8000 408.0000 1.0000
45.8400 378.0000 1.0000
45.8800 408.0000 1.0000
45.9200 407.0000 1.0000
45.9600 411.0000 1.0000
46.0000 398.0000 1.0000
46.0400 389.0000 1.0000
46.0800 397.0000 1.0000
46.1200 405.0000 1.0000
46.1600 434.0000 1.0000
46.2000 416.0000 1.0000
46.2400 407.0000 1.0000
46.2800 416.0000 1.0000
46.3200 385.0000 1.0000
46.3600 413.0000 1.0000
46.4000 380.0000 1.0000
46.4400 387.0000 1.0000
46.4800 412.0000 1.0000
46.5200 415.0000 1.0000
46.5600 398.0000 1.0000
46.6000 397.0000 1.0000
46.6400 390.0000 1.0000
46.6800 383.0000 1.0000
46.7200 363.0000 1.0000
46.7600 388.0000 1.0000
46.8000 410.0000 1.0000
46.8400 414.0000 1.0000
46.8800 397.0000 1.0000
46.9200 381.0000 1.0000
46.9600 393.0000 1.0000
47.0000 382.0000 1.0000
47.0400 396.0000 1.0000
47.0800 407.0000 1.0000
47.1200 358.0000 1.0000
47.1600 396.0000 1.0000
47.2000 394.0000 1.0000
47.2400 400.0000 1.0000
47.2800 398.0000 1.0000
47.3200 380.0000 1.0000
47.3600 378.0000 1.0000
47.4000 400.0000 1.0000
47.4400 417.0000 1.0000
47.4800 413.0000 1.0000
47.5200 380.0000 1.0000
47.5600 384.0000 1.0000
47.6000 373.0000 1.0000
47.6400 382.0000 1.0000
47.6800 386.0000 1.0000
47.7200 389.0000 1.0000
47.7600 398.0000 1.0000
47.8000 405.0000 1.0000
47.8400 389.0000 1.0000
47.8800 385.0000 1.0000
47.9200 395.0000 1.0000
47.9600 376.0000 1.0000
48.0000 356.0000 1.0000
48.0400 377.0000 1.0000
48.0800 373.0000 1.0000
48.1200 360.0000 1.0000
48.1600 379.0000 1.0000
48.2000 364.0000 1.0000
48.2400 403.0000 1.0000
48.2800 402.0000 1.0000
48.3200 360.0000 1.0000
48.3600 380.0000 1.0000
48.4000 357.0000 1.0000
48.4400 410.0000 1.0000
48.4800 362.0000 1.0000
48.5200 350.0000 1.0000
48.5600 406.0000 1.0000
48.6000 375.0000 1.0000
48.6400 377.0000 1.0000
48.6800 411.0000 1.0000
48.7200 389.0000 1.0000
48.7600 400.0000 1.0000
48.8000 389.0000 1.0000
48.8400 391.0000 1.0000
48.8800 385.0000 1.0000
48.9200 368.0000 1.0000
48.9600 372.0000 1.0000
49.0000 351.0000 1.0000
49.0400 408.0000 1.0000
49.0800 368.0000 1.0000
49.1200 338.0000 1.0000
49.1600 391.0000 1.0000
49.2000 406.0000 1.0000
49.2400 390.0000 1.0000
49.2800 424.0000 1.0000
49.3200 434.0000 1.0000
49.3600 431.0000 1.0000
49.4000 454.0000 1.0000
49.4400 456.0000 1.0000
49.4800 427.0000 1.0000
49.5200 423.0000 1.0000
49.5600 416.0000 1.0000
49.6000 380.0000 1.0000
49.6400 360.0000 1.0000
49.6800 358.0000 1.0000
49.7200 409.0000 1.0000
49.7600 413.0000 1.0000
49.8000 387.0000 1.0000
49.8400 392.0000 1.0000
49.8800 382.0000 1.0000
49.9200 367.0000 1.0000
49.9600 399.0000 1.0000
50.0000 404.0000 1.0000
50.0400 378.0000 1.0000
50.0800 393.0000 1.0000
50.1200 370.0000 1.0000
50.1600 410.0000 1.0000
50.2000 356.0000 1.0000
50.2400 373.0000 1.0000
50.2800 369.0000 1.0000
50.3200 390.0000 1.0000
50.3600 381.0000 1.0000
50.4000 383.0000 1.0000
50.4400 367.0000 1.0000
50.4800 373.0000 1.0000
50.5200 387.0000 1.0000
50.5600 374.0000 1.0000
50.6000 385.0000 1.0000
50.6400 362.0000 1.0000
50.6800 383.0000 1.0000
50.7200 363.0000 1.0000
50.7600 370.0000 1.0000
50.8000 346.0000 1.0000
50.8400 402.0000 1.0000
50.8800 409.0000 1.0000
50.9200 396.0000 1.0000
50.9600 416.0000 1.0000
51.0000 401.0000 1.0000
51.0400 410.0000 1.0000
51.0800 431.0000 1.0000
51.1200 466.0000 1.0000
51.1600 458.0000 1.0000
51.2000 561.0000 1.0000
51.2400 532.0000 1.0000
51.2800 719.0000 1.0000
51.3200 868.0000 1.0000
51.3600 1117.0000 1.0000
51.4000 1508.0000 1.0000
51.4400 1940.0000 1.0000
51.4800 2029.0000 1.0000
51.5200 1950.0000 1.0000
51.5600 1697.0000 1.0000
51.6000 1477.0000 1.0000
51.6400 1352.0000 1.0000
51.6800 1024.0000 1.0000
51.7200 772.0000 1.0000
51.7600 648.0000 1.0000
51.8000 543.0000 1.0000
51.8400 511.0000 1.0000
51.8800 510.0000 1.0000
51.9200 433.0000 1.0000
51.9600 428.0000 1.0000
52.0000 426.0000 1.0000
52.0400 410.0000 1.0000
52.0800 421.0000 1.0000
52.1200 373.0000 1.0000
52.1600 425.0000 1.0000
52.2000 392.0000 1.0000
52.2400 382.0000 1.0000
52.2800 412.0000 1.0000
52.3200 364.0000 1.0000
52.3600 396.0000 1.0000
52.4000 384.0000 1.0000
52.4400 407.0000 1.0000
52.4800 374.0000 1.0000
52.5200 406.0000 1.0000
52.5600 356.0000 1.0000
52.6000 387.0000 1.0000
52.6400 357.0000 1.0000
52.6800 362.0000 1.0000
52.7200 343.0000 1.0000
52.7600 357.0000 1.0000
52.8000 368.0000 1.0000
52.8400 362.0000 1.0000
52.8800 372.0000 1.0000
52.9200 362.0000 1.0000
52.9600 353.0000 1.0000
53.0000 385.0000 1.0000
53.0400 356.0000 1.0000
53.0800 356.0000 1.0000
53.1200 340.0000 1.0000
53.1600 357.0000 1.0000
53.2000 379.0000 1.0000
53.2400 337.0000 1.0000
53.2800 375.0000 1.0000
53.3200 338.0000 1.0000
53.3600 366.0000 1.0000
53.4000 356.0000 1.0000
53.4400 378.0000 1.0000
53.4800 368.0000 1.0000
53.5200 350.0000 1.0000
53.5600 369.0000 1.0000
53.6000 372.0000 1.0000
53.6400 348.0000 1.0000
53.6800 367.0000 1.0000
53.7200 372.0000 1.0000
53.7600 363.0000 1.0000
53.8000 370.0000 1.0000
53.8400 351.0000 1.0000
53.8800 369.0000 1.0000
53.9200 394.0000 1.0000
53.9600 385.0000 1.0000
54.0000 420.0000 1.0000
54.0400 380.0000 1.0000
54.0800 357.0000 1.0000
54.1200 408.0000 1.0000
54.1600 387.0000 1.0000
54.2000 408.0000 1.0000
54.2400 379.0000 1.0000
54.2800 405.0000 1.0000
54.3200 391.0000 1.0000
54.3600 394.0000 1.0000
54.4000 455.0000 1.0000
54.4400 494.0000 1.0000
54.4800 480.0000 1.0000
54.5200 505.0000 1.0000
54.5600 499.0000 1.0000
54.6000 477.0000 1.0000
54.6400 493.0000 1.0000
54.6800 448.0000 1.0000
54.7200 408.0000 1.0000
54.7600 397.0000 1.0000
54.8000 369.0000 1.0000
54.8400 362.0000 1.0000
54.8800 381.0000 1.0000
54.9200 389.0000 1.0000
54.9600 349.0000 1.0000
55.0000 376.0000 1.0000
55.0400 343.0000 1.0000
55.0800 344.0000 1.0000
55.1200 371.0000 1.0000
55.1600 359.0000 1.0000
55.2000 374.0000 1.0000
55.2400 359.0000 1.0000
55.2800 341.0000 1.0000
55.3200 337.0000 1.0000
55.3600 327.0000 1.0000
55.4000 353.0000 1.0000
55.4400 353.0000 1.0000
55.4800 359.0000 1.0000
55.5200 353.0000 1.0000
55.5600 331.0000 1.0000
55.6000 339.0000 1.0000
55.6400 337.0000 1.0000
55.6800 328.0000 1.0000
55.7200 362.0000 1.0000
55.7600 343.0000 1.0000
55.8000 339.0000 1.0000
55.8400 369.0000 1.0000
55.8800 359.0000 1.0000
55.9200 354.0000 1.0000
55.9600 342.0000 1.0000
56.0000 323.0000 1.0000
56.0400 340.0000 1.0000
56.0800 348.0000 1.0000
56.1200 346.0000 1.0000
56.1600 332.0000 1.0000
56.2000 378.0000 1.0000
56.2400 347.0000 1.0000
56.2800 321.0000 1.0000
56.3200 338.0000 1.0000
56.3600 329.0000 1.0000
56.4000 364.0000 1.0000
56.4400 355.0000 1.0000
56.4800 349.0000 1.0000
56.5200 351.0000 1.0000
56.5600 359.0000 1.0000
56.6000 329.0000 1.0000
56.6400 351.0000 1.0000
56.6800 351.0000 1.0000
56.7200 331.0000 1.0000
56.7600 373.0000 1.0000
56.8000 344.0000 1.0000
56.8400 343.0000 1.0000
56.8800 330.0000 1.0000
56.9200 328.0000 1.0000
56.9600 348.0000 1.0000
57.0000 319.0000 1.0000
57.0400 346.0000 1.0000
57.0800 330.0000 1.0000
57.1200 342.0000 1.0000
57.1600 353.0000 1.0000
57.2000 341.0000 1.0000
57.2400 362.0000 1.0000
57.2800 344.0000 1.0000
57.3200 349.0000 1.0000
57.3600 334.0000 1.0000
57.4000 371.0000 1.0000
57.4400 356.0000 1.0000
57.4800 342.0000 1.0000
57.5200 389.0000 1.0000
57.5600 355.0000 1.0000
57.6000 331.0000 1.0000
57.6400 361.0000 1.0000
57.6800 385.0000 1.0000
57.7200 357.0000 1.0000
57.7600 339.0000 1.0000
57.8000 330.0000 1.0000
57.8400 331.0000 1.0000
57.8800 348.0000 1.0000
57.9200 332.0000 1.0000
57.9600 301.0000 1.0000
58.0000 350.0000 1.0000
58.0400 337.0000 1.0000
58.0800 299.0000 1.0000
58.1200 348.0000 1.0000
58.1600 336.0000 1.0000
58.2000 350.0000 1.0000
58.2400 306.0000 1.0000
58.2800 331.0000 1.0000
58.3200 346.0000 1.0000
58.3600 334.0000 1.0000
58.4000 317.0000 1.0000
58.4400 356.0000 1.0000
58.4800 324.0000 1.0000
58.5200 325.0000 1.0000
58.5600 349.0000 1.0000
58.6000 334.0000 1.0000
58.6400 353.0000 1.0000
58.6800 341.0000 1.0000
58.7200 345.0000 1.0000
58.7600 331.0000 1.0000
58.8000 322.0000 1.0000
58.8400 363.0000 1.0000
58.8800 355.0000 1.0000
58.9200 340.0000 1.0000
58.9600 326.0000 1.0000
59.0000 340.0000 1.0000
59.0400 354.0000 1.0000
59.0800 344.0000 1.0000
59.1200 345.0000 1.0000
59.1600 338.0000 1.0000
59.2000 323.0000 1.0000
59.2400 371.0000 1.0000
59.2800 354.0000 1.0000
59.3200 360.0000 1.0000
59.3600 358.0000 1.0000
59.4000 312.0000 1.0000
59.4400 353.0000 1.0000
59.4800 345.0000 1.0000
59.5200 339.0000 1.0000
59.5600 342.0000 1.0000
59.6000 342.0000 1.0000
59.6400 340.0000 1.0000
59.6800 327.0000 1.0000
59.7200 317.0000 1.0000
59.7600 327.0000 1.0000
59.8000 347.0000 1.0000
59.8400 337.0000 1.0000
59.8800 360.0000 1.0000
59.9200 345.0000 1.0000
59.9600 336.0000 1.0000
60.0000 328.0000 1.0000
60.0400 331.0000 1.0000
60.0800 302.0000 1.0000
60.1200 324.0000 1.0000
60.1600 319.0000 1.0000
60.2000 329.0000 1.0000
60.2400 339.0000 1.0000
60.2800 346.0000 1.0000
60.3200 334.0000 1.0000
60.3600 327.0000 1.0000
60.4000 355.0000 1.0000
60.4400 351.0000 1.0000
60.4800 338.0000 1.0000
60.5200 320.0000 1.0000
60.5600 320.0000 1.0000
60.6000 338.0000 1.0000
60.6400 319.0000 1.0000
60.6800 363.0000 1.0000
60.7200 341.0000 1.0000
60.7600 328.0000 1.0000
60.8000 319.0000 1.0000
60.8400 324.0000 1.0000
60.8800 330.0000 1.0000
60.9200 355.0000 1.0000
60.9600 389.0000 1.0000
61.0000 358.0000 1.0000
61.0400 334.0000 1.0000
61.0800 329.0000 1.0000
61.1200 336.0000 1.0000
61.1600 362.0000 1.0000
61.2000 362.0000 1.0000
61.2400 396.0000 1.0000
61.2800 380.0000 1.0000
61.3200 431.0000 1.0000
61.3600 488.0000 1.0000
61.4000 502.0000 1.0000
61.4400 577.0000 1.0000
61.4800 574.0000 1.0000
61.5200 589.0000 1.0000
61.5600 629.0000 1.0000
61.6000 583.0000 1.0000
61.6400 625.0000 1.0000
61.6800 582.0000 1.0000
61.7200 563.0000 1.0000
61.7600 494.0000 1.0000
61.8000 474.0000 1.0000
61.8400 486.0000 1.0000
61.8800 369.0000 1.0000
61.9200 369.0000 1.0000
61.9600 397.0000 1.0000
62.0000 358.0000 1.0000
62.0400 369.0000 1.0000
62.0800 384.0000 1.0000
62.1200 356.0000 1.0000
62.1600 365.0000 1.0000
62.2000 367.0000 1.0000
62.2400 341.0000 1.0000
62.2800 371.0000 1.0000
62.3200 373.0000 1.0000
62.3600 396.0000 1.0000
62.4000 390.0000 1.0000
62.4400 413.0000 1.0000
62.4800 368.0000 1.0000
62.5200 365.0000 1.0000
62.5600 350.0000 1.0000
62.6000 334.0000 1.0000
62.6400 356.0000 1.0000
62.6800 361.0000 1.0000
62.7200 344.0000 1.0000
62.7600 316.0000 1.0000
62.8000 333.0000 1.0000
62.8400 333.0000 1.0000
62.8800 310.0000 1.0000
62.9200 328.0000 1.0000
62.9600 364.0000 1.0000
63.0000 344.0000 1.0000
63.0400 332.0000 1.0000
63.0800 354.0000 1.0000
63.1200 345.0000 1.0000
63.1600 304.0000 1.0000
63.2000 325.0000 1.0000
63.2400 338.0000 1.0000
63.2800 331.0000 1.0000
63.3200 330.0000 1.0000
63.3600 342.0000 1.0000
63.4000 351.0000 1.0000
63.4400 330.0000 1.0000
63.4800 342.0000 1.0000
63.5200 372.0000 1.0000
63.5600 355.0000 1.0000
63.6000 392.0000 1.0000
63.6400 397.0000 1.0000
63.6800 365.0000 1.0000
63.7200 397.0000 1.0000
63.7600 399.0000 1.0000
63.8000 481.0000 1.0000
63.8400 556.0000 1.0000
63.8800 705.0000 1.0000
63.9200 704.0000 1.0000
63.9600 708.0000 1.0000
64.0000 641.0000 1.0000
64.0400 614.0000 1.0000
64.0800 536.0000 1.0000
64.1200 569.0000 1.0000
64.1600 504.0000 1.0000
64.2000 451.0000 1.0000
64.2400 409.0000 1.0000
64.2800 371.0000 1.0000
64.3200 405.0000 1.0000
64.3600 367.0000 1.0000
64.4000 373.0000 1.0000
64.4400 375.0000 1.0000
64.4800 346.0000 1.0000
64.5200 368.0000 1.0000
64.5600 359.0000 1.0000
64.6000 348.0000 1.0000
64.6400 337.0000 1.0000
64.6800 335.0000 1.0000
64.7200 318.0000 1.0000
64.7600 346.0000 1.0000
64.8000 319.0000 1.0000
64.8400 326.0000 1.0000
64.8800 355.0000 1.0000
64.9200 366.0000 1.0000
64.9600 363.0000 1.0000
65.0000 357.0000 1.0000
65.0400 365.0000 1.0000
65.0800 382.0000 1.0000
65.1200 387.0000 1.0000
65.1600 404.0000 1.0000
65.2000 388.0000 1.0000
65.2400 441.0000 1.0000
65.2800 487.0000 1.0000
65.3200 524.0000 1.0000
65.3600 604.0000 1.0000
65.4000 740.0000 1.0000
65.4400 819.0000 1.0000
65.4800 917.0000 1.0000
65.5200 1018.0000 1.0000
65.5600 1009.0000 1.0000
65.6000 944.0000 1.0000
65.6400 878.0000 1.0000
65.6800 861.0000 1.0000
65.7200 785.0000 1.0000
65.7600 728.0000 1.0000
65.8000 572.0000 1.0000
65.8400 557.0000 1.0000
65.8800 484.0000 1.0000
65.9200 448.0000 1.0000
65.9600 420.0000 1.0000
66.0000 390.0000 1.0000
66.0400 353.0000 1.0000
66.0800 366.0000 1.0000
66.1200 364.0000 1.0000
66.1600 359.0000 1.0000
66.2000 354.0000 1.0000
66.2400 318.0000 1.0000
66.2800 339.0000 1.0000
66.3200 321.0000 1.0000
66.3600 347.0000 1.0000
66.4000 325.0000 1.0000
66.4400 342.0000 1.0000
66.4800 309.0000 1.0000
66.5200 344.0000 1.0000
66.5600 320.0000 1.0000
66.6000 311.0000 1.0000
66.6400 322.0000 1.0000
66.6800 285.0000 1.0000
66.7200 290.0000 1.0000
66.7600 302.0000 1.0000
66.8000 309.0000 1.0000
66.8400 317.0000 1.0000
66.8800 310.0000 1.0000
66.9200 288.0000 1.0000
66.9600 330.0000 1.0000
67.0000 313.0000 1.0000
67.0400 308.0000 1.0000
67.0800 325.0000 1.0000
67.1200 301.0000 1.0000
67.1600 327.0000 1.0000
67.2000 307.0000 1.0000
67.2400 289.0000 1.0000
67.2800 300.0000 1.0000
67.3200 303.0000 1.0000
67.3600 303.0000 1.0000
67.4000 293.0000 1.0000
67.4400 309.0000 1.0000
67.4800 297.0000 1.0000
67.5200 309.0000 1.0000
67.5600 290.0000 1.0000
67.6000 289.0000 1.0000
67.6400 283.0000 1.0000
67.6800 304.0000 1.0000
67.7200 306.0000 1.0000
67.7600 338.0000 1.0000
67.8000 305.0000 1.0000
67.8400 285.0000 1.0000
67.8800 294.0000 1.0000
67.9200 302.0000 1.0000
67.9600 327.0000 1.0000
68.0000 295.0000 1.0000
68.0400 313.0000 1.0000
68.0800 286.0000 1.0000
68.1200 280.0000 1.0000
68.1600 319.0000 1.0000
68.2000 298.0000 1.0000
68.2400 308.0000 1.0000
68.2800 272.0000 1.0000
68.3200 299.0000 1.0000
68.3600 289.0000 1.0000
68.4000 285.0000 1.0000
68.4400 298.0000 1.0000
68.4800 315.0000 1.0000
68.5200 312.0000 1.0000
68.5600 293.0000 1.0000
68.6000 298.0000 1.0000
68.6400 300.0000 1.0000
68.6800 307.0000 1.0000
68.7200 313.0000 1.0000
68.7600 294.0000 1.0000
68.8000 267.0000 1.0000
68.8400 294.0000 1.0000
68.8800 291.0000 1.0000
68.9200 308.0000 1.0000
68.9600 329.0000 1.0000
69.0000 331.0000 1.0000
69.0400 298.0000 1.0000
69.0800 297.0000 1.0000
69.1200 313.0000 1.0000
69.1600 293.0000 1.0000
69.2000 305.0000 1.0000
69.2400 278.0000 1.0000
69.2800 288.0000 1.0000
69.3200 285.0000 1.0000
69.3600 294.0000 1.0000
69.4000 320.0000 1.0000
69.4400 308.0000 1.0000
69.4800 328.0000 1.0000
69.5200 317.0000 1.0000
69.5600 280.0000 1.0000
69.6000 312.0000 1.0000
69.6400 308.0000 1.0000
69.6800 282.0000 1.0000
69.7200 296.0000 1.0000
69.7600 299.0000 1.0000
69.8000 301.0000 1.0000
69.8400 282.0000 1.0000
69.8800 319.0000 1.0000
69.9200 309.0000 1.0000
69.9600 296.0000 1.0000
70.0000 272.0000 1.0000
*RAS_INT_END
*RAS_TEMPERATURE_START
*RAS_TEMPERATURE_END
*RAS_DATA_END