File: Data/Dataset2_Water_Organic/4_XRD/No_03_Hematite_Butanol_3.ras
*RAS_DATA_START
*RAS_HEADER_START
*DISP_FMT_X "%.2f"
*DISP_FMT_Y "%.0f"
*DISP_FULLSCALE "13705.0000000000"
*DISP_LINE_COLOR "255.0000000000"
*DISP_LINE_STYLE "0.0000000000"
*DISP_LINE_WIDTH "0.2500000000"
*DISP_NOTE "測定データ-3"
*DISP_OFFSET_Y "0.0000000000"
*DISP_PEAKSEARCH_UNIT_Y "cps"
*DISP_RANGE_BOTTOM "0.0000000000"
*DISP_RANGE_LEFT "20.0000000000"
*DISP_RANGE_LOGCUTOFF "0.0100000000"
*DISP_RANGE_RIGHT "70.0000000000"
*DISP_RANGE_TOP "13705.0000000000"
*DISP_SCALE_MODE_Y "0.0000000000"
*DISP_TAB_NAME "2θ/θ"
*DISP_TITLE_Y "強度"
*DISP_UNIT_Y "cps"
*DISP_WINDOW_NAME "MSG_MACROENGINE"
*FILE_COMMENT " "
*FILE_MD5 ""
*FILE_MEMO " "
*FILE_OPERATOR "Administrator"
*FILE_SAMPLE " "
*FILE_TYPE "RAS_RAW"
*FILE_USERGROUP "システムマネージャ"
*FILE_VERSION "1.0000000000"
*HW_ATTACHMENT_ID "ATT0025"
*HW_ATTACHMENT_NAME "標準|Standard"
*HW_COUNTER_ID-0 "CUT0025"
*HW_COUNTER_ID-1 "CUT0020"
*HW_COUNTER_ID-2 "CUT0020"
*HW_COUNTER_ID-3 "CSL0021"
*HW_COUNTER_ID-4 "CMC0021"
*HW_COUNTER_NAME-0 "D/teX Ultra|D/teX Ultra"
*HW_COUNTER_NAME-1 "None|None"
*HW_COUNTER_NAME-2 "None|None"
*HW_COUNTER_NAME-3 "BBM|BBM"
*HW_COUNTER_NAME-4 "検出器モノクロメータ|Detector monochromator"
*HW_COUNTER_SELECT_NAME "D/teX Ultra|D/teX Ultra"
*HW_GONIOMETER_ID "GON0023"
*HW_GONIOMETER_NAME "SmartLab|SmartLab"
*HW_GONIOMETER_RADIUS-0 "90.0"
*HW_GONIOMETER_RADIUS-1 "114.0"
*HW_GONIOMETER_RADIUS-2 "190.0"
*HW_GONIOMETER_RADIUS-3 "300.0"
*HW_GONIOMETER_RADIUS-4 "187.0"
*HW_GONIOMETER_RADIUS-5 "300.0"
*HW_GONIOMETER_RADIUS-6 "113.0"
*HW_GONIOMETER_RADIUS-7 "331.0"
*HW_I_OPT_ID-0 "CBO0021"
*HW_I_OPT_ID-1 "ICR0023"
*HW_I_OPT_ID-2 "ISL0021"
*HW_I_OPT_ID-3 "ISO0021"
*HW_I_OPT_ID-4 "IAD0021"
*HW_I_OPT_ID-5 "IPR0001"
*HW_I_OPT_NAME-0 "CBOユニット|CBO unit"
*HW_I_OPT_NAME-1 "標準入射光学ユニット|Standard incident optical unit"
*HW_I_OPT_NAME-2 "標準入射スリットボックス|Standard incident slit box"
*HW_I_OPT_NAME-3 "入射平行スリット|Incident parallel slit"
*HW_I_OPT_NAME-4 "長手制限スリット|Length limiting slit"
*HW_I_OPT_NAME-5 "None|None"
*HW_R_ATTENUATER_AUTOMODE "0"
*HW_R_OPT_ID-0 "RSS0021"
*HW_R_OPT_ID-1 "RCR0023"
*HW_R_OPT_ID-2 "RSO0021"
*HW_R_OPT_ID-3 "RRS0021"
*HW_R_OPT_ID-4 "ATN0021"
*HW_R_OPT_ID-5 "RFL0021"
*HW_R_OPT_ID-6 "RAD0021"
*HW_R_OPT_NAME-0 "標準受光スリットボックス1|Standard receiving slit box # 1"
*HW_R_OPT_NAME-1 "標準受光光学ユニット1|Standard receiving unit # 1"
*HW_R_OPT_NAME-2 "標準受光光学ユニット2|Standard receiving optical unit # 2"
*HW_R_OPT_NAME-3 "標準受光スリットボックス2|Standard receiving slit box # 2"
*HW_R_OPT_NAME-4 "標準アッテネータ|Standard Attenuator"
*HW_R_OPT_NAME-5 "Cu Kβ|Cu K-beta"
*HW_R_OPT_NAME-6 "調整用受光スリット|Alignment receiving slit"
*HW_SAMPLE_HOLDER_ID "SMP0023"
*HW_SAMPLE_HOLDER_NAME "標準Zステージ|Standard Z stage"
*HW_XG_CURRENT_MAX "50"
*HW_XG_CURRENT_MIN "2"
*HW_XG_CURRENT_RESOLUTION "1"
*HW_XG_CURRENT_UNIT "mA"
*HW_XG_FOCUS "1mm x 10mm"
*HW_XG_FOCUS_TYPE "Normal"
*HW_XG_ID ""
*HW_XG_NAME "3kW 封入管(ID:1200)|3kW Sealed tube(ID:1200)"
*HW_XG_TARGET_ATOMIC_NUMBER "29.0000000000"
*HW_XG_TARGET_NAME "Cu"
*HW_XG_TYPE "Hermetic"
*HW_XG_VOLTAGE_MAX "60"
*HW_XG_VOLTAGE_MIN "20"
*HW_XG_VOLTAGE_RESOLUTION "1"
*HW_XG_VOLTAGE_UNIT "kV"
*HW_XG_WATT_MAX "1.500"
*HW_XG_WATT_UNIT "kW"
*HW_XG_WAVE_LENGTH_ALPHA1 "1.540593"
*HW_XG_WAVE_LENGTH_ALPHA2 "1.544414"
*HW_XG_WAVE_LENGTH_BETA "1.392250"
*MEAS_COND_AXIS_NAME-0 "2θ/θ"
*MEAS_COND_AXIS_NAME-1 "2θ"
*MEAS_COND_AXIS_NAME-2 "ω"
*MEAS_COND_AXIS_NAME-3 "Z"
*MEAS_COND_AXIS_NAME-4 "2θ/ω"
*MEAS_COND_AXIS_NAME-5 "θs"
*MEAS_COND_AXIS_NAME-6 "θd"
*MEAS_COND_AXIS_NAME-7 "Ts"
*MEAS_COND_AXIS_NAME-8 "CBO選択スリット"
*MEAS_COND_AXIS_NAME-9 "M"
*MEAS_COND_AXIS_NAME-10 "入射平行スリット"
*MEAS_COND_AXIS_NAME-11 "入射スリット"
*MEAS_COND_AXIS_NAME-12 ""
*MEAS_COND_AXIS_NAME-13 "Zs"
*MEAS_COND_AXIS_NAME-14 "入射光学素子"
*MEAS_COND_AXIS_NAME-15 "長手制限スリット"
*MEAS_COND_AXIS_NAME-16 "センタースリット"
*MEAS_COND_AXIS_NAME-17 "フィルター"
*MEAS_COND_AXIS_NAME-18 "受光スリット1"
*MEAS_COND_AXIS_NAME-19 "受光スリット2"
*MEAS_COND_AXIS_NAME-20 "受光光学素子"
*MEAS_COND_AXIS_NAME-21 "受光平行スリット"
*MEAS_COND_AXIS_NAME-22 "調整用受光スリット"
*MEAS_COND_AXIS_NAME-23 ""
*MEAS_COND_AXIS_NAME-24 ""
*MEAS_COND_AXIS_NAME-25 "Zd"
*MEAS_COND_AXIS_NAME-26 "アッテネータ"
*MEAS_COND_AXIS_NAME-27 "検出器モノクロメータ"
*MEAS_COND_AXIS_NAME-28 "モノクロメータスリット"
*MEAS_COND_AXIS_NAME-29 "プライマリビーム"
*MEAS_COND_AXIS_NAME-30 "PHA"
*MEAS_COND_AXIS_NAME_INTERNAL-0 "TwoThetaTheta"
*MEAS_COND_AXIS_NAME_INTERNAL-1 "TwoTheta"
*MEAS_COND_AXIS_NAME_INTERNAL-2 "Omega"
*MEAS_COND_AXIS_NAME_INTERNAL-3 "Z"
*MEAS_COND_AXIS_NAME_INTERNAL-4 "TwoThetaOmega"
*MEAS_COND_AXIS_NAME_INTERNAL-5 "ThetaS"
*MEAS_COND_AXIS_NAME_INTERNAL-6 "ThetaD"
*MEAS_COND_AXIS_NAME_INTERNAL-7 "Ts"
*MEAS_COND_AXIS_NAME_INTERNAL-8 "CBO"
*MEAS_COND_AXIS_NAME_INTERNAL-9 "CBO-M"
*MEAS_COND_AXIS_NAME_INTERNAL-10 "IncidentSollerSlit"
*MEAS_COND_AXIS_NAME_INTERNAL-11 "IncidentSlitBox"
*MEAS_COND_AXIS_NAME_INTERNAL-12 "IncidentSlitBox-_Axis"
*MEAS_COND_AXIS_NAME_INTERNAL-13 "Zs"
*MEAS_COND_AXIS_NAME_INTERNAL-14 "IncidentMonochromator"
*MEAS_COND_AXIS_NAME_INTERNAL-15 "IncidentAxdSlit"
*MEAS_COND_AXIS_NAME_INTERNAL-16 "CenterSlit"
*MEAS_COND_AXIS_NAME_INTERNAL-17 "Filter"
*MEAS_COND_AXIS_NAME_INTERNAL-18 "ReceivingSlitBox1"
*MEAS_COND_AXIS_NAME_INTERNAL-19 "ReceivingSlitBox2"
*MEAS_COND_AXIS_NAME_INTERNAL-20 "ReceivingOptics"
*MEAS_COND_AXIS_NAME_INTERNAL-21 "ReceivingSollerSlit"
*MEAS_COND_AXIS_NAME_INTERNAL-22 "ReceivingAxdSlit"
*MEAS_COND_AXIS_NAME_INTERNAL-23 "ReceivingSlitBox1-_Axis"
*MEAS_COND_AXIS_NAME_INTERNAL-24 "ReceivingSlitBox2-_Axis"
*MEAS_COND_AXIS_NAME_INTERNAL-25 "ReceivingSlitBox2-Zd"
*MEAS_COND_AXIS_NAME_INTERNAL-26 "Attenuator"
*MEAS_COND_AXIS_NAME_INTERNAL-27 "CounterMonochromator"
*MEAS_COND_AXIS_NAME_INTERNAL-28 "CounterSlit"
*MEAS_COND_AXIS_NAME_INTERNAL-29 "IncidentPrimary"
*MEAS_COND_AXIS_NAME_INTERNAL-30 "PHA"
*MEAS_COND_AXIS_NAME_MAGICNO-0 "83951616.0000000000"
*MEAS_COND_AXIS_NAME_MAGICNO-1 "268632064.0000000000"
*MEAS_COND_AXIS_NAME_MAGICNO-2 "268500992.0000000000"
*MEAS_COND_AXIS_NAME_MAGICNO-3 "285278208.0000000000"
*MEAS_COND_AXIS_NAME_MAGICNO-4 "83951616.0000000000"
*MEAS_COND_AXIS_NAME_MAGICNO-5 "131072.0000000000"
*MEAS_COND_AXIS_NAME_MAGICNO-6 "131072.0000000000"
*MEAS_COND_AXIS_NAME_MAGICNO-7 "318898176.0000000000"
*MEAS_COND_AXIS_NAME_MAGICNO-8 "20971521.0000000000"
*MEAS_COND_AXIS_NAME_MAGICNO-9 "285343744.0000000000"
*MEAS_COND_AXIS_NAME_MAGICNO-10 "20971521.0000000000"
*MEAS_COND_AXIS_NAME_MAGICNO-11 "22020097.0000000000"
*MEAS_COND_AXIS_NAME_MAGICNO-12 "25165824.0000000000"
*MEAS_COND_AXIS_NAME_MAGICNO-13 "318898176.0000000000"
*MEAS_COND_AXIS_NAME_MAGICNO-14 "1.0000000000"
*MEAS_COND_AXIS_NAME_MAGICNO-15 "20971521.0000000000"
*MEAS_COND_AXIS_NAME_MAGICNO-16 "20971521.0000000000"
*MEAS_COND_AXIS_NAME_MAGICNO-17 "20971521.0000000000"
*MEAS_COND_AXIS_NAME_MAGICNO-18 "23068673.0000000000"
*MEAS_COND_AXIS_NAME_MAGICNO-19 "23068673.0000000000"
*MEAS_COND_AXIS_NAME_MAGICNO-20 "20971521.0000000000"
*MEAS_COND_AXIS_NAME_MAGICNO-21 "20971521.0000000000"
*MEAS_COND_AXIS_NAME_MAGICNO-22 "20971521.0000000000"
*MEAS_COND_AXIS_NAME_MAGICNO-23 "25165824.0000000000"
*MEAS_COND_AXIS_NAME_MAGICNO-24 "25165824.0000000000"
*MEAS_COND_AXIS_NAME_MAGICNO-25 "285343744.0000000000"
*MEAS_COND_AXIS_NAME_MAGICNO-26 "17301505.0000000000"
*MEAS_COND_AXIS_NAME_MAGICNO-27 "20971521.0000000000"
*MEAS_COND_AXIS_NAME_MAGICNO-28 "20971521.0000000000"
*MEAS_COND_AXIS_NAME_MAGICNO-29 "20971521.0000000000"
*MEAS_COND_AXIS_NAME_MAGICNO-30 "0.0000000000"
*MEAS_COND_AXIS_OFFSET-0 "-"
*MEAS_COND_AXIS_OFFSET-1 "-0.0310000000"
*MEAS_COND_AXIS_OFFSET-2 "0.5056000000"
*MEAS_COND_AXIS_OFFSET-3 "-"
*MEAS_COND_AXIS_OFFSET-4 "-"
*MEAS_COND_AXIS_OFFSET-5 "0.5056000000"
*MEAS_COND_AXIS_OFFSET-6 "-0.5366000000"
*MEAS_COND_AXIS_OFFSET-7 "-"
*MEAS_COND_AXIS_OFFSET-8 "-"
*MEAS_COND_AXIS_OFFSET-9 "-"
*MEAS_COND_AXIS_OFFSET-10 "-"
*MEAS_COND_AXIS_OFFSET-11 "-"
*MEAS_COND_AXIS_OFFSET-12 "-"
*MEAS_COND_AXIS_OFFSET-13 "-"
*MEAS_COND_AXIS_OFFSET-14 "-"
*MEAS_COND_AXIS_OFFSET-15 "-"
*MEAS_COND_AXIS_OFFSET-16 "-"
*MEAS_COND_AXIS_OFFSET-17 "-"
*MEAS_COND_AXIS_OFFSET-18 "-"
*MEAS_COND_AXIS_OFFSET-19 "-"
*MEAS_COND_AXIS_OFFSET-20 "-"
*MEAS_COND_AXIS_OFFSET-21 "-"
*MEAS_COND_AXIS_OFFSET-22 "-"
*MEAS_COND_AXIS_OFFSET-23 "-"
*MEAS_COND_AXIS_OFFSET-24 "-"
*MEAS_COND_AXIS_OFFSET-25 "-"
*MEAS_COND_AXIS_OFFSET-26 "-"
*MEAS_COND_AXIS_OFFSET-27 "-"
*MEAS_COND_AXIS_OFFSET-28 "-"
*MEAS_COND_AXIS_OFFSET-29 "-"
*MEAS_COND_AXIS_OFFSET-30 "-"
*MEAS_COND_AXIS_POSITION-0 "0.0000000000"
*MEAS_COND_AXIS_POSITION-1 "0.0000000000"
*MEAS_COND_AXIS_POSITION-2 "0.0000000000"
*MEAS_COND_AXIS_POSITION-3 "-2.9031400000"
*MEAS_COND_AXIS_POSITION-4 "0.0000000000"
*MEAS_COND_AXIS_POSITION-5 "0.0000000000"
*MEAS_COND_AXIS_POSITION-6 "0.0000000000"
*MEAS_COND_AXIS_POSITION-7 "-0.7498700000"
*MEAS_COND_AXIS_POSITION-8 "BB"
*MEAS_COND_AXIS_POSITION-9 "0.0000000000"
*MEAS_COND_AXIS_POSITION-10 "Soller_slit_5.0deg"
*MEAS_COND_AXIS_POSITION-11 "2/3deg"
*MEAS_COND_AXIS_POSITION-12 "2.2088000000"
*MEAS_COND_AXIS_POSITION-13 "-0.6412500000"
*MEAS_COND_AXIS_POSITION-14 "0.0000000000"
*MEAS_COND_AXIS_POSITION-15 "10.0mm"
*MEAS_COND_AXIS_POSITION-16 "None"
*MEAS_COND_AXIS_POSITION-17 "Cu_K-beta"
*MEAS_COND_AXIS_POSITION-18 "13.000mm"
*MEAS_COND_AXIS_POSITION-19 "13.000mm"
*MEAS_COND_AXIS_POSITION-20 "No_unit"
*MEAS_COND_AXIS_POSITION-21 "Soller_slit_5.0deg"
*MEAS_COND_AXIS_POSITION-22 "None"
*MEAS_COND_AXIS_POSITION-23 "13.0000000000"
*MEAS_COND_AXIS_POSITION-24 "13.0000000000"
*MEAS_COND_AXIS_POSITION-25 "0.0281300000"
*MEAS_COND_AXIS_POSITION-26 "Open"
*MEAS_COND_AXIS_POSITION-27 "None"
*MEAS_COND_AXIS_POSITION-28 "None"
*MEAS_COND_AXIS_POSITION-29 "None"
*MEAS_COND_AXIS_POSITION-30 "38.0000000000"
*MEAS_COND_AXIS_UNIT-0 "deg"
*MEAS_COND_AXIS_UNIT-1 "deg"
*MEAS_COND_AXIS_UNIT-2 "deg"
*MEAS_COND_AXIS_UNIT-3 "mm"
*MEAS_COND_AXIS_UNIT-4 "deg"
*MEAS_COND_AXIS_UNIT-5 "deg"
*MEAS_COND_AXIS_UNIT-6 "deg"
*MEAS_COND_AXIS_UNIT-7 "mm"
*MEAS_COND_AXIS_UNIT-8 ""
*MEAS_COND_AXIS_UNIT-9 "pulse"
*MEAS_COND_AXIS_UNIT-10 ""
*MEAS_COND_AXIS_UNIT-11 ""
*MEAS_COND_AXIS_UNIT-12 "mm"
*MEAS_COND_AXIS_UNIT-13 "mm"
*MEAS_COND_AXIS_UNIT-14 ""
*MEAS_COND_AXIS_UNIT-15 ""
*MEAS_COND_AXIS_UNIT-16 ""
*MEAS_COND_AXIS_UNIT-17 ""
*MEAS_COND_AXIS_UNIT-18 ""
*MEAS_COND_AXIS_UNIT-19 ""
*MEAS_COND_AXIS_UNIT-20 ""
*MEAS_COND_AXIS_UNIT-21 ""
*MEAS_COND_AXIS_UNIT-22 ""
*MEAS_COND_AXIS_UNIT-23 "mm"
*MEAS_COND_AXIS_UNIT-24 "mm"
*MEAS_COND_AXIS_UNIT-25 "mm"
*MEAS_COND_AXIS_UNIT-26 ""
*MEAS_COND_AXIS_UNIT-27 ""
*MEAS_COND_AXIS_UNIT-28 ""
*MEAS_COND_AXIS_UNIT-29 ""
*MEAS_COND_AXIS_UNIT-30 "div"
*MEAS_COND_COUNTER_CNTLOSS_CORR "0.0000000000"
*MEAS_COND_COUNTER_PHABASE "38.0000000000"
*MEAS_COND_COUNTER_PHAWINDOW "16.0000000000"
*MEAS_COND_COUNTER_PHA_UNIT "div"
*MEAS_COND_COUNTER_TAUDIFF "30.0000000000"
*MEAS_COND_COUNTER_TAUINT "0.0000000000"
*MEAS_COND_IRRADIATION_MODE "OFF"
*MEAS_COND_IRRADIATION_WIDTH ""
*MEAS_COND_OPT_ATTR "集中法"
*MEAS_COND_OPT_NAME "@集中法"
*MEAS_COND_UNSYMMETRIC_MODE "OFF"
*MEAS_COND_XG_CURRENT "30.0000000000"
*MEAS_COND_XG_VOLTAGE "40.0000000000"
*MEAS_COND_XG_WAVE_TYPE "Ka"
*MEAS_DATA_COUNT "5001.0000000000"
*MEAS_SCAN_AXIS_X "2θ/θ"
*MEAS_SCAN_AXIS_X_INTERNAL "TwoThetaTheta"
*MEAS_SCAN_END_TIME "07/27/23 20:27:35"
*MEAS_SCAN_MODE "CONTINUOUS"
*MEAS_SCAN_MONITOR "0"
*MEAS_SCAN_RESOLUTION_X "0.0002"
*MEAS_SCAN_SPEED "2.5"
*MEAS_SCAN_SPEED_UNIT "deg/min"
*MEAS_SCAN_START "20.0000000000"
*MEAS_SCAN_START_TIME "07/27/23 20:06:11"
*MEAS_SCAN_STEP "0.0100000000"
*MEAS_SCAN_STOP "70.0000000000"
*MEAS_SCAN_UNIT_X "deg"
*MEAS_SCAN_UNIT_Y "counts"
*RAS_HEADER_END
*RAS_INT_START
20.0000 967.0000 1.0000
20.0400 965.0000 1.0000
20.0800 927.0000 1.0000
20.1200 965.0000 1.0000
20.1600 954.0000 1.0000
20.2000 964.0000 1.0000
20.2400 970.0000 1.0000
20.2800 891.0000 1.0000
20.3200 940.0000 1.0000
20.3600 930.0000 1.0000
20.4000 940.0000 1.0000
20.4400 886.0000 1.0000
20.4800 860.0000 1.0000
20.5200 959.0000 1.0000
20.5600 970.0000 1.0000
20.6000 920.0000 1.0000
20.6400 930.0000 1.0000
20.6800 917.0000 1.0000
20.7200 936.0000 1.0000
20.7600 925.0000 1.0000
20.8000 971.0000 1.0000
20.8400 921.0000 1.0000
20.8800 885.0000 1.0000
20.9200 929.0000 1.0000
20.9600 957.0000 1.0000
21.0000 960.0000 1.0000
21.0400 925.0000 1.0000
21.0800 883.0000 1.0000
21.1200 942.0000 1.0000
21.1600 888.0000 1.0000
21.2000 872.0000 1.0000
21.2400 905.0000 1.0000
21.2800 907.0000 1.0000
21.3200 941.0000 1.0000
21.3600 859.0000 1.0000
21.4000 930.0000 1.0000
21.4400 945.0000 1.0000
21.4800 943.0000 1.0000
21.5200 922.0000 1.0000
21.5600 885.0000 1.0000
21.6000 894.0000 1.0000
21.6400 888.0000 1.0000
21.6800 890.0000 1.0000
21.7200 893.0000 1.0000
21.7600 901.0000 1.0000
21.8000 912.0000 1.0000
21.8400 906.0000 1.0000
21.8800 841.0000 1.0000
21.9200 909.0000 1.0000
21.9600 885.0000 1.0000
22.0000 861.0000 1.0000
22.0400 858.0000 1.0000
22.0800 848.0000 1.0000
22.1200 876.0000 1.0000
22.1600 893.0000 1.0000
22.2000 922.0000 1.0000
22.2400 883.0000 1.0000
22.2800 897.0000 1.0000
22.3200 912.0000 1.0000
22.3600 903.0000 1.0000
22.4000 903.0000 1.0000
22.4400 883.0000 1.0000
22.4800 941.0000 1.0000
22.5200 850.0000 1.0000
22.5600 866.0000 1.0000
22.6000 874.0000 1.0000
22.6400 904.0000 1.0000
22.6800 868.0000 1.0000
22.7200 877.0000 1.0000
22.7600 919.0000 1.0000
22.8000 891.0000 1.0000
22.8400 908.0000 1.0000
22.8800 874.0000 1.0000
22.9200 901.0000 1.0000
22.9600 857.0000 1.0000
23.0000 851.0000 1.0000
23.0400 822.0000 1.0000
23.0800 824.0000 1.0000
23.1200 851.0000 1.0000
23.1600 885.0000 1.0000
23.2000 875.0000 1.0000
23.2400 859.0000 1.0000
23.2800 892.0000 1.0000
23.3200 846.0000 1.0000
23.3600 877.0000 1.0000
23.4000 882.0000 1.0000
23.4400 913.0000 1.0000
23.4800 841.0000 1.0000
23.5200 877.0000 1.0000
23.5600 861.0000 1.0000
23.6000 850.0000 1.0000
23.6400 892.0000 1.0000
23.6800 881.0000 1.0000
23.7200 843.0000 1.0000
23.7600 905.0000 1.0000
23.8000 858.0000 1.0000
23.8400 921.0000 1.0000
23.8800 925.0000 1.0000
23.9200 897.0000 1.0000
23.9600 949.0000 1.0000
24.0000 915.0000 1.0000
24.0400 931.0000 1.0000
24.0800 1026.0000 1.0000
24.1200 971.0000 1.0000
24.1600 955.0000 1.0000
24.2000 907.0000 1.0000
24.2400 948.0000 1.0000
24.2800 876.0000 1.0000
24.3200 886.0000 1.0000
24.3600 869.0000 1.0000
24.4000 883.0000 1.0000
24.4400 888.0000 1.0000
24.4800 914.0000 1.0000
24.5200 884.0000 1.0000
24.5600 930.0000 1.0000
24.6000 839.0000 1.0000
24.6400 893.0000 1.0000
24.6800 844.0000 1.0000
24.7200 840.0000 1.0000
24.7600 864.0000 1.0000
24.8000 853.0000 1.0000
24.8400 888.0000 1.0000
24.8800 867.0000 1.0000
24.9200 881.0000 1.0000
24.9600 868.0000 1.0000
25.0000 832.0000 1.0000
25.0400 869.0000 1.0000
25.0800 810.0000 1.0000
25.1200 849.0000 1.0000
25.1600 800.0000 1.0000
25.2000 830.0000 1.0000
25.2400 849.0000 1.0000
25.2800 847.0000 1.0000
25.3200 886.0000 1.0000
25.3600 869.0000 1.0000
25.4000 869.0000 1.0000
25.4400 864.0000 1.0000
25.4800 939.0000 1.0000
25.5200 842.0000 1.0000
25.5600 853.0000 1.0000
25.6000 888.0000 1.0000
25.6400 873.0000 1.0000
25.6800 848.0000 1.0000
25.7200 912.0000 1.0000
25.7600 882.0000 1.0000
25.8000 865.0000 1.0000
25.8400 918.0000 1.0000
25.8800 878.0000 1.0000
25.9200 886.0000 1.0000
25.9600 934.0000 1.0000
26.0000 928.0000 1.0000
26.0400 936.0000 1.0000
26.0800 974.0000 1.0000
26.1200 975.0000 1.0000
26.1600 1065.0000 1.0000
26.2000 1145.0000 1.0000
26.2400 1297.0000 1.0000
26.2800 1389.0000 1.0000
26.3200 1642.0000 1.0000
26.3600 2076.0000 1.0000
26.4000 2493.0000 1.0000
26.4400 2630.0000 1.0000
26.4800 2315.0000 1.0000
26.5200 1984.0000 1.0000
26.5600 1653.0000 1.0000
26.6000 1329.0000 1.0000
26.6400 1174.0000 1.0000
26.6800 1126.0000 1.0000
26.7200 983.0000 1.0000
26.7600 1003.0000 1.0000
26.8000 915.0000 1.0000
26.8400 883.0000 1.0000
26.8800 880.0000 1.0000
26.9200 904.0000 1.0000
26.9600 893.0000 1.0000
27.0000 927.0000 1.0000
27.0400 829.0000 1.0000
27.0800 836.0000 1.0000
27.1200 843.0000 1.0000
27.1600 877.0000 1.0000
27.2000 852.0000 1.0000
27.2400 837.0000 1.0000
27.2800 778.0000 1.0000
27.3200 808.0000 1.0000
27.3600 790.0000 1.0000
27.4000 800.0000 1.0000
27.4400 776.0000 1.0000
27.4800 795.0000 1.0000
27.5200 807.0000 1.0000
27.5600 771.0000 1.0000
27.6000 788.0000 1.0000
27.6400 761.0000 1.0000
27.6800 776.0000 1.0000
27.7200 797.0000 1.0000
27.7600 803.0000 1.0000
27.8000 782.0000 1.0000
27.8400 829.0000 1.0000
27.8800 764.0000 1.0000
27.9200 753.0000 1.0000
27.9600 764.0000 1.0000
28.0000 815.0000 1.0000
28.0400 765.0000 1.0000
28.0800 800.0000 1.0000
28.1200 760.0000 1.0000
28.1600 757.0000 1.0000
28.2000 756.0000 1.0000
28.2400 793.0000 1.0000
28.2800 764.0000 1.0000
28.3200 743.0000 1.0000
28.3600 771.0000 1.0000
28.4000 770.0000 1.0000
28.4400 767.0000 1.0000
28.4800 761.0000 1.0000
28.5200 735.0000 1.0000
28.5600 767.0000 1.0000
28.6000 777.0000 1.0000
28.6400 785.0000 1.0000
28.6800 744.0000 1.0000
28.7200 784.0000 1.0000
28.7600 766.0000 1.0000
28.8000 775.0000 1.0000
28.8400 747.0000 1.0000
28.8800 755.0000 1.0000
28.9200 815.0000 1.0000
28.9600 768.0000 1.0000
29.0000 725.0000 1.0000
29.0400 748.0000 1.0000
29.0800 764.0000 1.0000
29.1200 789.0000 1.0000
29.1600 756.0000 1.0000
29.2000 755.0000 1.0000
29.2400 730.0000 1.0000
29.2800 742.0000 1.0000
29.3200 751.0000 1.0000
29.3600 769.0000 1.0000
29.4000 712.0000 1.0000
29.4400 738.0000 1.0000
29.4800 707.0000 1.0000
29.5200 722.0000 1.0000
29.5600 736.0000 1.0000
29.6000 752.0000 1.0000
29.6400 782.0000 1.0000
29.6800 735.0000 1.0000
29.7200 667.0000 1.0000
29.7600 743.0000 1.0000
29.8000 704.0000 1.0000
29.8400 740.0000 1.0000
29.8800 767.0000 1.0000
29.9200 752.0000 1.0000
29.9600 794.0000 1.0000
30.0000 764.0000 1.0000
30.0400 682.0000 1.0000
30.0800 710.0000 1.0000
30.1200 700.0000 1.0000
30.1600 749.0000 1.0000
30.2000 685.0000 1.0000
30.2400 739.0000 1.0000
30.2800 696.0000 1.0000
30.3200 736.0000 1.0000
30.3600 707.0000 1.0000
30.4000 733.0000 1.0000
30.4400 712.0000 1.0000
30.4800 693.0000 1.0000
30.5200 710.0000 1.0000
30.5600 712.0000 1.0000
30.6000 720.0000 1.0000
30.6400 704.0000 1.0000
30.6800 702.0000 1.0000
30.7200 723.0000 1.0000
30.7600 697.0000 1.0000
30.8000 684.0000 1.0000
30.8400 710.0000 1.0000
30.8800 715.0000 1.0000
30.9200 675.0000 1.0000
30.9600 686.0000 1.0000
31.0000 692.0000 1.0000
31.0400 686.0000 1.0000
31.0800 694.0000 1.0000
31.1200 691.0000 1.0000
31.1600 673.0000 1.0000
31.2000 692.0000 1.0000
31.2400 654.0000 1.0000
31.2800 680.0000 1.0000
31.3200 674.0000 1.0000
31.3600 640.0000 1.0000
31.4000 658.0000 1.0000
31.4400 669.0000 1.0000
31.4800 690.0000 1.0000
31.5200 665.0000 1.0000
31.5600 674.0000 1.0000
31.6000 682.0000 1.0000
31.6400 655.0000 1.0000
31.6800 694.0000 1.0000
31.7200 686.0000 1.0000
31.7600 681.0000 1.0000
31.8000 660.0000 1.0000
31.8400 642.0000 1.0000
31.8800 673.0000 1.0000
31.9200 685.0000 1.0000
31.9600 674.0000 1.0000
32.0000 649.0000 1.0000
32.0400 680.0000 1.0000
32.0800 688.0000 1.0000
32.1200 644.0000 1.0000
32.1600 674.0000 1.0000
32.2000 660.0000 1.0000
32.2400 671.0000 1.0000
32.2800 657.0000 1.0000
32.3200 658.0000 1.0000
32.3600 671.0000 1.0000
32.4000 678.0000 1.0000
32.4400 679.0000 1.0000
32.4800 624.0000 1.0000
32.5200 683.0000 1.0000
32.5600 678.0000 1.0000
32.6000 680.0000 1.0000
32.6400 646.0000 1.0000
32.6800 649.0000 1.0000
32.7200 670.0000 1.0000
32.7600 699.0000 1.0000
32.8000 695.0000 1.0000
32.8400 660.0000 1.0000
32.8800 664.0000 1.0000
32.9200 700.0000 1.0000
32.9600 728.0000 1.0000
33.0000 831.0000 1.0000
33.0400 849.0000 1.0000
33.0800 906.0000 1.0000
33.1200 896.0000 1.0000
33.1600 829.0000 1.0000
33.2000 777.0000 1.0000
33.2400 732.0000 1.0000
33.2800 725.0000 1.0000
33.3200 739.0000 1.0000
33.3600 724.0000 1.0000
33.4000 774.0000 1.0000
33.4400 806.0000 1.0000
33.4800 877.0000 1.0000
33.5200 972.0000 1.0000
33.5600 1130.0000 1.0000
33.6000 1349.0000 1.0000
33.6400 1396.0000 1.0000
33.6800 1397.0000 1.0000
33.7200 1191.0000 1.0000
33.7600 1080.0000 1.0000
33.8000 918.0000 1.0000
33.8400 854.0000 1.0000
33.8800 730.0000 1.0000
33.9200 749.0000 1.0000
33.9600 724.0000 1.0000
34.0000 676.0000 1.0000
34.0400 703.0000 1.0000
34.0800 648.0000 1.0000
34.1200 648.0000 1.0000
34.1600 650.0000 1.0000
34.2000 633.0000 1.0000
34.2400 650.0000 1.0000
34.2800 607.0000 1.0000
34.3200 602.0000 1.0000
34.3600 610.0000 1.0000
34.4000 622.0000 1.0000
34.4400 590.0000 1.0000
34.4800 633.0000 1.0000
34.5200 610.0000 1.0000
34.5600 581.0000 1.0000
34.6000 600.0000 1.0000
34.6400 618.0000 1.0000
34.6800 556.0000 1.0000
34.7200 546.0000 1.0000
34.7600 572.0000 1.0000
34.8000 597.0000 1.0000
34.8400 623.0000 1.0000
34.8800 604.0000 1.0000
34.9200 588.0000 1.0000
34.9600 596.0000 1.0000
35.0000 617.0000 1.0000
35.0400 596.0000 1.0000
35.0800 594.0000 1.0000
35.1200 581.0000 1.0000
35.1600 603.0000 1.0000
35.2000 621.0000 1.0000
35.2400 589.0000 1.0000
35.2800 631.0000 1.0000
35.3200 662.0000 1.0000
35.3600 718.0000 1.0000
35.4000 780.0000 1.0000
35.4400 832.0000 1.0000
35.4800 1085.0000 1.0000
35.5200 1343.0000 1.0000
35.5600 1464.0000 1.0000
35.6000 1350.0000 1.0000
35.6400 1212.0000 1.0000
35.6800 974.0000 1.0000
35.7200 831.0000 1.0000
35.7600 663.0000 1.0000
35.8000 616.0000 1.0000
35.8400 638.0000 1.0000
35.8800 590.0000 1.0000
35.9200 535.0000 1.0000
35.9600 563.0000 1.0000
36.0000 556.0000 1.0000
36.0400 570.0000 1.0000
36.0800 577.0000 1.0000
36.1200 530.0000 1.0000
36.1600 539.0000 1.0000
36.2000 599.0000 1.0000
36.2400 532.0000 1.0000
36.2800 549.0000 1.0000
36.3200 522.0000 1.0000
36.3600 569.0000 1.0000
36.4000 535.0000 1.0000
36.4400 570.0000 1.0000
36.4800 553.0000 1.0000
36.5200 509.0000 1.0000
36.5600 545.0000 1.0000
36.6000 508.0000 1.0000
36.6400 563.0000 1.0000
36.6800 543.0000 1.0000
36.7200 516.0000 1.0000
36.7600 534.0000 1.0000
36.8000 566.0000 1.0000
36.8400 585.0000 1.0000
36.8800 514.0000 1.0000
36.9200 519.0000 1.0000
36.9600 550.0000 1.0000
37.0000 520.0000 1.0000
37.0400 533.0000 1.0000
37.0800 575.0000 1.0000
37.1200 534.0000 1.0000
37.1600 560.0000 1.0000
37.2000 575.0000 1.0000
37.2400 594.0000 1.0000
37.2800 579.0000 1.0000
37.3200 607.0000 1.0000
37.3600 613.0000 1.0000
37.4000 697.0000 1.0000
37.4400 732.0000 1.0000
37.4800 843.0000 1.0000
37.5200 1010.0000 1.0000
37.5600 1192.0000 1.0000
37.6000 1451.0000 1.0000
37.6400 1753.0000 1.0000
37.6800 2003.0000 1.0000
37.7200 2072.0000 1.0000
37.7600 1892.0000 1.0000
37.8000 1584.0000 1.0000
37.8400 1358.0000 1.0000
37.8800 1084.0000 1.0000
37.9200 876.0000 1.0000
37.9600 745.0000 1.0000
38.0000 649.0000 1.0000
38.0400 635.0000 1.0000
38.0800 570.0000 1.0000
38.1200 551.0000 1.0000
38.1600 554.0000 1.0000
38.2000 520.0000 1.0000
38.2400 520.0000 1.0000
38.2800 497.0000 1.0000
38.3200 540.0000 1.0000
38.3600 496.0000 1.0000
38.4000 524.0000 1.0000
38.4400 520.0000 1.0000
38.4800 473.0000 1.0000
38.5200 474.0000 1.0000
38.5600 489.0000 1.0000
38.6000 472.0000 1.0000
38.6400 530.0000 1.0000
38.6800 545.0000 1.0000
38.7200 538.0000 1.0000
38.7600 480.0000 1.0000
38.8000 510.0000 1.0000
38.8400 501.0000 1.0000
38.8800 475.0000 1.0000
38.9200 495.0000 1.0000
38.9600 493.0000 1.0000
39.0000 484.0000 1.0000
39.0400 490.0000 1.0000
39.0800 483.0000 1.0000
39.1200 491.0000 1.0000
39.1600 464.0000 1.0000
39.2000 470.0000 1.0000
39.2400 460.0000 1.0000
39.2800 473.0000 1.0000
39.3200 464.0000 1.0000
39.3600 492.0000 1.0000
39.4000 466.0000 1.0000
39.4400 488.0000 1.0000
39.4800 463.0000 1.0000
39.5200 478.0000 1.0000
39.5600 469.0000 1.0000
39.6000 466.0000 1.0000
39.6400 425.0000 1.0000
39.6800 465.0000 1.0000
39.7200 463.0000 1.0000
39.7600 452.0000 1.0000
39.8000 445.0000 1.0000
39.8400 439.0000 1.0000
39.8800 449.0000 1.0000
39.9200 456.0000 1.0000
39.9600 441.0000 1.0000
40.0000 441.0000 1.0000
40.0400 458.0000 1.0000
40.0800 475.0000 1.0000
40.1200 456.0000 1.0000
40.1600 469.0000 1.0000
40.2000 464.0000 1.0000
40.2400 466.0000 1.0000
40.2800 477.0000 1.0000
40.3200 459.0000 1.0000
40.3600 449.0000 1.0000
40.4000 475.0000 1.0000
40.4400 440.0000 1.0000
40.4800 448.0000 1.0000
40.5200 498.0000 1.0000
40.5600 470.0000 1.0000
40.6000 462.0000 1.0000
40.6400 482.0000 1.0000
40.6800 516.0000 1.0000
40.7200 486.0000 1.0000
40.7600 483.0000 1.0000
40.8000 533.0000 1.0000
40.8400 483.0000 1.0000
40.8800 458.0000 1.0000
40.9200 478.0000 1.0000
40.9600 445.0000 1.0000
41.0000 466.0000 1.0000
41.0400 455.0000 1.0000
41.0800 463.0000 1.0000
41.1200 457.0000 1.0000
41.1600 405.0000 1.0000
41.2000 423.0000 1.0000
41.2400 425.0000 1.0000
41.2800 457.0000 1.0000
41.3200 405.0000 1.0000
41.3600 430.0000 1.0000
41.4000 404.0000 1.0000
41.4400 457.0000 1.0000
41.4800 460.0000 1.0000
41.5200 482.0000 1.0000
41.5600 451.0000 1.0000
41.6000 430.0000 1.0000
41.6400 420.0000 1.0000
41.6800 400.0000 1.0000
41.7200 423.0000 1.0000
41.7600 450.0000 1.0000
41.8000 433.0000 1.0000
41.8400 443.0000 1.0000
41.8800 430.0000 1.0000
41.9200 427.0000 1.0000
41.9600 436.0000 1.0000
42.0000 442.0000 1.0000
42.0400 462.0000 1.0000
42.0800 461.0000 1.0000
42.1200 451.0000 1.0000
42.1600 439.0000 1.0000
42.2000 451.0000 1.0000
42.2400 428.0000 1.0000
42.2800 452.0000 1.0000
42.3200 443.0000 1.0000
42.3600 492.0000 1.0000
42.4000 477.0000 1.0000
42.4400 473.0000 1.0000
42.4800 472.0000 1.0000
42.5200 442.0000 1.0000
42.5600 452.0000 1.0000
42.6000 450.0000 1.0000
42.6400 418.0000 1.0000
42.6800 465.0000 1.0000
42.7200 442.0000 1.0000
42.7600 418.0000 1.0000
42.8000 449.0000 1.0000
42.8400 437.0000 1.0000
42.8800 403.0000 1.0000
42.9200 444.0000 1.0000
42.9600 433.0000 1.0000
43.0000 441.0000 1.0000
43.0400 462.0000 1.0000
43.0800 437.0000 1.0000
43.1200 427.0000 1.0000
43.1600 428.0000 1.0000
43.2000 447.0000 1.0000
43.2400 428.0000 1.0000
43.2800 440.0000 1.0000
43.3200 426.0000 1.0000
43.3600 438.0000 1.0000
43.4000 452.0000 1.0000
43.4400 440.0000 1.0000
43.4800 461.0000 1.0000
43.5200 453.0000 1.0000
43.5600 457.0000 1.0000
43.6000 412.0000 1.0000
43.6400 454.0000 1.0000
43.6800 452.0000 1.0000
43.7200 434.0000 1.0000
43.7600 431.0000 1.0000
43.8000 405.0000 1.0000
43.8400 407.0000 1.0000
43.8800 420.0000 1.0000
43.9200 437.0000 1.0000
43.9600 401.0000 1.0000
44.0000 397.0000 1.0000
44.0400 440.0000 1.0000
44.0800 372.0000 1.0000
44.1200 386.0000 1.0000
44.1600 447.0000 1.0000
44.2000 435.0000 1.0000
44.2400 432.0000 1.0000
44.2800 407.0000 1.0000
44.3200 444.0000 1.0000
44.3600 414.0000 1.0000
44.4000 445.0000 1.0000
44.4400 445.0000 1.0000
44.4800 404.0000 1.0000
44.5200 400.0000 1.0000
44.5600 446.0000 1.0000
44.6000 419.0000 1.0000
44.6400 386.0000 1.0000
44.6800 421.0000 1.0000
44.7200 450.0000 1.0000
44.7600 425.0000 1.0000
44.8000 419.0000 1.0000
44.8400 408.0000 1.0000
44.8800 425.0000 1.0000
44.9200 436.0000 1.0000
44.9600 416.0000 1.0000
45.0000 417.0000 1.0000
45.0400 415.0000 1.0000
45.0800 408.0000 1.0000
45.1200 395.0000 1.0000
45.1600 416.0000 1.0000
45.2000 418.0000 1.0000
45.2400 407.0000 1.0000
45.2800 426.0000 1.0000
45.3200 427.0000 1.0000
45.3600 409.0000 1.0000
45.4000 401.0000 1.0000
45.4400 395.0000 1.0000
45.4800 418.0000 1.0000
45.5200 417.0000 1.0000
45.5600 430.0000 1.0000
45.6000 426.0000 1.0000
45.6400 392.0000 1.0000
45.6800 413.0000 1.0000
45.7200 400.0000 1.0000
45.7600 391.0000 1.0000
45.8000 359.0000 1.0000
45.8400 386.0000 1.0000
45.8800 409.0000 1.0000
45.9200 417.0000 1.0000
45.9600 382.0000 1.0000
46.0000 399.0000 1.0000
46.0400 384.0000 1.0000
46.0800 394.0000 1.0000
46.1200 419.0000 1.0000
46.1600 403.0000 1.0000
46.2000 441.0000 1.0000
46.2400 409.0000 1.0000
46.2800 394.0000 1.0000
46.3200 403.0000 1.0000
46.3600 400.0000 1.0000
46.4000 375.0000 1.0000
46.4400 393.0000 1.0000
46.4800 424.0000 1.0000
46.5200 403.0000 1.0000
46.5600 387.0000 1.0000
46.6000 411.0000 1.0000
46.6400 392.0000 1.0000
46.6800 400.0000 1.0000
46.7200 400.0000 1.0000
46.7600 385.0000 1.0000
46.8000 411.0000 1.0000
46.8400 397.0000 1.0000
46.8800 403.0000 1.0000
46.9200 380.0000 1.0000
46.9600 398.0000 1.0000
47.0000 380.0000 1.0000
47.0400 394.0000 1.0000
47.0800 377.0000 1.0000
47.1200 402.0000 1.0000
47.1600 434.0000 1.0000
47.2000 390.0000 1.0000
47.2400 393.0000 1.0000
47.2800 400.0000 1.0000
47.3200 382.0000 1.0000
47.3600 378.0000 1.0000
47.4000 347.0000 1.0000
47.4400 381.0000 1.0000
47.4800 391.0000 1.0000
47.5200 410.0000 1.0000
47.5600 363.0000 1.0000
47.6000 358.0000 1.0000
47.6400 380.0000 1.0000
47.6800 407.0000 1.0000
47.7200 386.0000 1.0000
47.7600 415.0000 1.0000
47.8000 367.0000 1.0000
47.8400 398.0000 1.0000
47.8800 372.0000 1.0000
47.9200 376.0000 1.0000
47.9600 401.0000 1.0000
48.0000 395.0000 1.0000
48.0400 402.0000 1.0000
48.0800 360.0000 1.0000
48.1200 367.0000 1.0000
48.1600 400.0000 1.0000
48.2000 388.0000 1.0000
48.2400 370.0000 1.0000
48.2800 386.0000 1.0000
48.3200 372.0000 1.0000
48.3600 376.0000 1.0000
48.4000 372.0000 1.0000
48.4400 387.0000 1.0000
48.4800 380.0000 1.0000
48.5200 387.0000 1.0000
48.5600 385.0000 1.0000
48.6000 344.0000 1.0000
48.6400 396.0000 1.0000
48.6800 375.0000 1.0000
48.7200 380.0000 1.0000
48.7600 387.0000 1.0000
48.8000 408.0000 1.0000
48.8400 380.0000 1.0000
48.8800 378.0000 1.0000
48.9200 407.0000 1.0000
48.9600 411.0000 1.0000
49.0000 371.0000 1.0000
49.0400 403.0000 1.0000
49.0800 398.0000 1.0000
49.1200 382.0000 1.0000
49.1600 396.0000 1.0000
49.2000 354.0000 1.0000
49.2400 395.0000 1.0000
49.2800 413.0000 1.0000
49.3200 404.0000 1.0000
49.3600 450.0000 1.0000
49.4000 465.0000 1.0000
49.4400 470.0000 1.0000
49.4800 439.0000 1.0000
49.5200 446.0000 1.0000
49.5600 444.0000 1.0000
49.6000 403.0000 1.0000
49.6400 405.0000 1.0000
49.6800 366.0000 1.0000
49.7200 433.0000 1.0000
49.7600 409.0000 1.0000
49.8000 378.0000 1.0000
49.8400 367.0000 1.0000
49.8800 356.0000 1.0000
49.9200 379.0000 1.0000
49.9600 373.0000 1.0000
50.0000 394.0000 1.0000
50.0400 384.0000 1.0000
50.0800 391.0000 1.0000
50.1200 391.0000 1.0000
50.1600 384.0000 1.0000
50.2000 365.0000 1.0000
50.2400 379.0000 1.0000
50.2800 392.0000 1.0000
50.3200 358.0000 1.0000
50.3600 357.0000 1.0000
50.4000 384.0000 1.0000
50.4400 374.0000 1.0000
50.4800 387.0000 1.0000
50.5200 384.0000 1.0000
50.5600 353.0000 1.0000
50.6000 377.0000 1.0000
50.6400 391.0000 1.0000
50.6800 357.0000 1.0000
50.7200 413.0000 1.0000
50.7600 367.0000 1.0000
50.8000 405.0000 1.0000
50.8400 342.0000 1.0000
50.8800 409.0000 1.0000
50.9200 385.0000 1.0000
50.9600 397.0000 1.0000
51.0000 417.0000 1.0000
51.0400 424.0000 1.0000
51.0800 425.0000 1.0000
51.1200 470.0000 1.0000
51.1600 504.0000 1.0000
51.2000 543.0000 1.0000
51.2400 618.0000 1.0000
51.2800 682.0000 1.0000
51.3200 867.0000 1.0000
51.3600 1142.0000 1.0000
51.4000 1543.0000 1.0000
51.4400 1845.0000 1.0000
51.4800 2025.0000 1.0000
51.5200 1883.0000 1.0000
51.5600 1639.0000 1.0000
51.6000 1449.0000 1.0000
51.6400 1274.0000 1.0000
51.6800 1000.0000 1.0000
51.7200 799.0000 1.0000
51.7600 696.0000 1.0000
51.8000 600.0000 1.0000
51.8400 512.0000 1.0000
51.8800 496.0000 1.0000
51.9200 438.0000 1.0000
51.9600 440.0000 1.0000
52.0000 391.0000 1.0000
52.0400 425.0000 1.0000
52.0800 412.0000 1.0000
52.1200 383.0000 1.0000
52.1600 379.0000 1.0000
52.2000 416.0000 1.0000
52.2400 411.0000 1.0000
52.2800 381.0000 1.0000
52.3200 394.0000 1.0000
52.3600 383.0000 1.0000
52.4000 387.0000 1.0000
52.4400 362.0000 1.0000
52.4800 356.0000 1.0000
52.5200 369.0000 1.0000
52.5600 378.0000 1.0000
52.6000 390.0000 1.0000
52.6400 399.0000 1.0000
52.6800 354.0000 1.0000
52.7200 347.0000 1.0000
52.7600 368.0000 1.0000
52.8000 377.0000 1.0000
52.8400 385.0000 1.0000
52.8800 351.0000 1.0000
52.9200 374.0000 1.0000
52.9600 379.0000 1.0000
53.0000 351.0000 1.0000
53.0400 380.0000 1.0000
53.0800 343.0000 1.0000
53.1200 367.0000 1.0000
53.1600 344.0000 1.0000
53.2000 369.0000 1.0000
53.2400 399.0000 1.0000
53.2800 395.0000 1.0000
53.3200 388.0000 1.0000
53.3600 364.0000 1.0000
53.4000 367.0000 1.0000
53.4400 385.0000 1.0000
53.4800 382.0000 1.0000
53.5200 375.0000 1.0000
53.5600 385.0000 1.0000
53.6000 352.0000 1.0000
53.6400 351.0000 1.0000
53.6800 363.0000 1.0000
53.7200 377.0000 1.0000
53.7600 375.0000 1.0000
53.8000 356.0000 1.0000
53.8400 363.0000 1.0000
53.8800 367.0000 1.0000
53.9200 434.0000 1.0000
53.9600 429.0000 1.0000
54.0000 409.0000 1.0000
54.0400 400.0000 1.0000
54.0800 435.0000 1.0000
54.1200 412.0000 1.0000
54.1600 407.0000 1.0000
54.2000 405.0000 1.0000
54.2400 385.0000 1.0000
54.2800 366.0000 1.0000
54.3200 399.0000 1.0000
54.3600 435.0000 1.0000
54.4000 459.0000 1.0000
54.4400 489.0000 1.0000
54.4800 535.0000 1.0000
54.5200 489.0000 1.0000
54.5600 480.0000 1.0000
54.6000 513.0000 1.0000
54.6400 487.0000 1.0000
54.6800 445.0000 1.0000
54.7200 437.0000 1.0000
54.7600 421.0000 1.0000
54.8000 405.0000 1.0000
54.8400 400.0000 1.0000
54.8800 401.0000 1.0000
54.9200 374.0000 1.0000
54.9600 355.0000 1.0000
55.0000 340.0000 1.0000
55.0400 382.0000 1.0000
55.0800 360.0000 1.0000
55.1200 362.0000 1.0000
55.1600 361.0000 1.0000
55.2000 338.0000 1.0000
55.2400 371.0000 1.0000
55.2800 369.0000 1.0000
55.3200 363.0000 1.0000
55.3600 363.0000 1.0000
55.4000 345.0000 1.0000
55.4400 377.0000 1.0000
55.4800 353.0000 1.0000
55.5200 324.0000 1.0000
55.5600 345.0000 1.0000
55.6000 334.0000 1.0000
55.6400 357.0000 1.0000
55.6800 341.0000 1.0000
55.7200 343.0000 1.0000
55.7600 326.0000 1.0000
55.8000 333.0000 1.0000
55.8400 336.0000 1.0000
55.8800 342.0000 1.0000
55.9200 359.0000 1.0000
55.9600 357.0000 1.0000
56.0000 346.0000 1.0000
56.0400 343.0000 1.0000
56.0800 347.0000 1.0000
56.1200 360.0000 1.0000
56.1600 361.0000 1.0000
56.2000 316.0000 1.0000
56.2400 366.0000 1.0000
56.2800 334.0000 1.0000
56.3200 354.0000 1.0000
56.3600 343.0000 1.0000
56.4000 307.0000 1.0000
56.4400 317.0000 1.0000
56.4800 341.0000 1.0000
56.5200 333.0000 1.0000
56.5600 323.0000 1.0000
56.6000 318.0000 1.0000
56.6400 339.0000 1.0000
56.6800 341.0000 1.0000
56.7200 344.0000 1.0000
56.7600 346.0000 1.0000
56.8000 349.0000 1.0000
56.8400 312.0000 1.0000
56.8800 342.0000 1.0000
56.9200 350.0000 1.0000
56.9600 372.0000 1.0000
57.0000 368.0000 1.0000
57.0400 373.0000 1.0000
57.0800 300.0000 1.0000
57.1200 354.0000 1.0000
57.1600 359.0000 1.0000
57.2000 318.0000 1.0000
57.2400 370.0000 1.0000
57.2800 381.0000 1.0000
57.3200 375.0000 1.0000
57.3600 355.0000 1.0000
57.4000 347.0000 1.0000
57.4400 352.0000 1.0000
57.4800 364.0000 1.0000
57.5200 378.0000 1.0000
57.5600 385.0000 1.0000
57.6000 341.0000 1.0000
57.6400 347.0000 1.0000
57.6800 329.0000 1.0000
57.7200 343.0000 1.0000
57.7600 324.0000 1.0000
57.8000 359.0000 1.0000
57.8400 341.0000 1.0000
57.8800 324.0000 1.0000
57.9200 353.0000 1.0000
57.9600 342.0000 1.0000
58.0000 361.0000 1.0000
58.0400 353.0000 1.0000
58.0800 339.0000 1.0000
58.1200 331.0000 1.0000
58.1600 315.0000 1.0000
58.2000 311.0000 1.0000
58.2400 352.0000 1.0000
58.2800 347.0000 1.0000
58.3200 347.0000 1.0000
58.3600 341.0000 1.0000
58.4000 349.0000 1.0000
58.4400 333.0000 1.0000
58.4800 349.0000 1.0000
58.5200 344.0000 1.0000
58.5600 317.0000 1.0000
58.6000 341.0000 1.0000
58.6400 366.0000 1.0000
58.6800 359.0000 1.0000
58.7200 324.0000 1.0000
58.7600 343.0000 1.0000
58.8000 335.0000 1.0000
58.8400 357.0000 1.0000
58.8800 352.0000 1.0000
58.9200 347.0000 1.0000
58.9600 330.0000 1.0000
59.0000 349.0000 1.0000
59.0400 329.0000 1.0000
59.0800 304.0000 1.0000
59.1200 343.0000 1.0000
59.1600 334.0000 1.0000
59.2000 340.0000 1.0000
59.2400 308.0000 1.0000
59.2800 362.0000 1.0000
59.3200 353.0000 1.0000
59.3600 352.0000 1.0000
59.4000 310.0000 1.0000
59.4400 369.0000 1.0000
59.4800 353.0000 1.0000
59.5200 327.0000 1.0000
59.5600 348.0000 1.0000
59.6000 351.0000 1.0000
59.6400 344.0000 1.0000
59.6800 341.0000 1.0000
59.7200 355.0000 1.0000
59.7600 307.0000 1.0000
59.8000 345.0000 1.0000
59.8400 350.0000 1.0000
59.8800 334.0000 1.0000
59.9200 328.0000 1.0000
59.9600 352.0000 1.0000
60.0000 313.0000 1.0000
60.0400 357.0000 1.0000
60.0800 366.0000 1.0000
60.1200 353.0000 1.0000
60.1600 320.0000 1.0000
60.2000 348.0000 1.0000
60.2400 371.0000 1.0000
60.2800 343.0000 1.0000
60.3200 333.0000 1.0000
60.3600 345.0000 1.0000
60.4000 335.0000 1.0000
60.4400 313.0000 1.0000
60.4800 322.0000 1.0000
60.5200 363.0000 1.0000
60.5600 352.0000 1.0000
60.6000 336.0000 1.0000
60.6400 351.0000 1.0000
60.6800 326.0000 1.0000
60.7200 343.0000 1.0000
60.7600 362.0000 1.0000
60.8000 358.0000 1.0000
60.8400 362.0000 1.0000
60.8800 336.0000 1.0000
60.9200 355.0000 1.0000
60.9600 358.0000 1.0000
61.0000 342.0000 1.0000
61.0400 337.0000 1.0000
61.0800 352.0000 1.0000
61.1200 338.0000 1.0000
61.1600 380.0000 1.0000
61.2000 389.0000 1.0000
61.2400 415.0000 1.0000
61.2800 394.0000 1.0000
61.3200 459.0000 1.0000
61.3600 483.0000 1.0000
61.4000 519.0000 1.0000
61.4400 552.0000 1.0000
61.4800 563.0000 1.0000
61.5200 628.0000 1.0000
61.5600 588.0000 1.0000
61.6000 590.0000 1.0000
61.6400 628.0000 1.0000
61.6800 603.0000 1.0000
61.7200 539.0000 1.0000
61.7600 507.0000 1.0000
61.8000 473.0000 1.0000
61.8400 438.0000 1.0000
61.8800 441.0000 1.0000
61.9200 403.0000 1.0000
61.9600 386.0000 1.0000
62.0000 403.0000 1.0000
62.0400 415.0000 1.0000
62.0800 363.0000 1.0000
62.1200 367.0000 1.0000
62.1600 337.0000 1.0000
62.2000 385.0000 1.0000
62.2400 387.0000 1.0000
62.2800 357.0000 1.0000
62.3200 416.0000 1.0000
62.3600 395.0000 1.0000
62.4000 414.0000 1.0000
62.4400 380.0000 1.0000
62.4800 355.0000 1.0000
62.5200 386.0000 1.0000
62.5600 376.0000 1.0000
62.6000 340.0000 1.0000
62.6400 364.0000 1.0000
62.6800 319.0000 1.0000
62.7200 338.0000 1.0000
62.7600 320.0000 1.0000
62.8000 332.0000 1.0000
62.8400 307.0000 1.0000
62.8800 336.0000 1.0000
62.9200 351.0000 1.0000
62.9600 325.0000 1.0000
63.0000 327.0000 1.0000
63.0400 336.0000 1.0000
63.0800 337.0000 1.0000
63.1200 351.0000 1.0000
63.1600 330.0000 1.0000
63.2000 329.0000 1.0000
63.2400 327.0000 1.0000
63.2800 360.0000 1.0000
63.3200 348.0000 1.0000
63.3600 313.0000 1.0000
63.4000 347.0000 1.0000
63.4400 340.0000 1.0000
63.4800 371.0000 1.0000
63.5200 324.0000 1.0000
63.5600 322.0000 1.0000
63.6000 389.0000 1.0000
63.6400 352.0000 1.0000
63.6800 403.0000 1.0000
63.7200 394.0000 1.0000
63.7600 423.0000 1.0000
63.8000 460.0000 1.0000
63.8400 516.0000 1.0000
63.8800 575.0000 1.0000
63.9200 693.0000 1.0000
63.9600 698.0000 1.0000
64.0000 619.0000 1.0000
64.0400 581.0000 1.0000
64.0800 606.0000 1.0000
64.1200 541.0000 1.0000
64.1600 517.0000 1.0000
64.2000 424.0000 1.0000
64.2400 421.0000 1.0000
64.2800 422.0000 1.0000
64.3200 380.0000 1.0000
64.3600 370.0000 1.0000
64.4000 354.0000 1.0000
64.4400 348.0000 1.0000
64.4800 368.0000 1.0000
64.5200 372.0000 1.0000
64.5600 331.0000 1.0000
64.6000 347.0000 1.0000
64.6400 367.0000 1.0000
64.6800 346.0000 1.0000
64.7200 300.0000 1.0000
64.7600 348.0000 1.0000
64.8000 310.0000 1.0000
64.8400 335.0000 1.0000
64.8800 334.0000 1.0000
64.9200 355.0000 1.0000
64.9600 351.0000 1.0000
65.0000 373.0000 1.0000
65.0400 365.0000 1.0000
65.0800 379.0000 1.0000
65.1200 383.0000 1.0000
65.1600 377.0000 1.0000
65.2000 419.0000 1.0000
65.2400 442.0000 1.0000
65.2800 442.0000 1.0000
65.3200 493.0000 1.0000
65.3600 607.0000 1.0000
65.4000 671.0000 1.0000
65.4400 820.0000 1.0000
65.4800 866.0000 1.0000
65.5200 1002.0000 1.0000
65.5600 995.0000 1.0000
65.6000 995.0000 1.0000
65.6400 864.0000 1.0000
65.6800 867.0000 1.0000
65.7200 800.0000 1.0000
65.7600 743.0000 1.0000
65.8000 640.0000 1.0000
65.8400 530.0000 1.0000
65.8800 506.0000 1.0000
65.9200 459.0000 1.0000
65.9600 390.0000 1.0000
66.0000 394.0000 1.0000
66.0400 384.0000 1.0000
66.0800 370.0000 1.0000
66.1200 376.0000 1.0000
66.1600 341.0000 1.0000
66.2000 333.0000 1.0000
66.2400 337.0000 1.0000
66.2800 347.0000 1.0000
66.3200 304.0000 1.0000
66.3600 321.0000 1.0000
66.4000 334.0000 1.0000
66.4400 325.0000 1.0000
66.4800 337.0000 1.0000
66.5200 351.0000 1.0000
66.5600 314.0000 1.0000
66.6000 298.0000 1.0000
66.6400 303.0000 1.0000
66.6800 312.0000 1.0000
66.7200 322.0000 1.0000
66.7600 314.0000 1.0000
66.8000 310.0000 1.0000
66.8400 330.0000 1.0000
66.8800 304.0000 1.0000
66.9200 318.0000 1.0000
66.9600 297.0000 1.0000
67.0000 312.0000 1.0000
67.0400 322.0000 1.0000
67.0800 325.0000 1.0000
67.1200 316.0000 1.0000
67.1600 304.0000 1.0000
67.2000 315.0000 1.0000
67.2400 325.0000 1.0000
67.2800 293.0000 1.0000
67.3200 336.0000 1.0000
67.3600 285.0000 1.0000
67.4000 304.0000 1.0000
67.4400 314.0000 1.0000
67.4800 315.0000 1.0000
67.5200 318.0000 1.0000
67.5600 302.0000 1.0000
67.6000 341.0000 1.0000
67.6400 303.0000 1.0000
67.6800 305.0000 1.0000
67.7200 311.0000 1.0000
67.7600 336.0000 1.0000
67.8000 306.0000 1.0000
67.8400 327.0000 1.0000
67.8800 298.0000 1.0000
67.9200 311.0000 1.0000
67.9600 305.0000 1.0000
68.0000 326.0000 1.0000
68.0400 302.0000 1.0000
68.0800 303.0000 1.0000
68.1200 310.0000 1.0000
68.1600 308.0000 1.0000
68.2000 320.0000 1.0000
68.2400 312.0000 1.0000
68.2800 294.0000 1.0000
68.3200 291.0000 1.0000
68.3600 302.0000 1.0000
68.4000 292.0000 1.0000
68.4400 315.0000 1.0000
68.4800 314.0000 1.0000
68.5200 286.0000 1.0000
68.5600 294.0000 1.0000
68.6000 271.0000 1.0000
68.6400 308.0000 1.0000
68.6800 294.0000 1.0000
68.7200 304.0000 1.0000
68.7600 291.0000 1.0000
68.8000 317.0000 1.0000
68.8400 304.0000 1.0000
68.8800 332.0000 1.0000
68.9200 313.0000 1.0000
68.9600 311.0000 1.0000
69.0000 288.0000 1.0000
69.0400 303.0000 1.0000
69.0800 307.0000 1.0000
69.1200 291.0000 1.0000
69.1600 278.0000 1.0000
69.2000 279.0000 1.0000
69.2400 290.0000 1.0000
69.2800 290.0000 1.0000
69.3200 289.0000 1.0000
69.3600 288.0000 1.0000
69.4000 296.0000 1.0000
69.4400 300.0000 1.0000
69.4800 287.0000 1.0000
69.5200 309.0000 1.0000
69.5600 296.0000 1.0000
69.6000 262.0000 1.0000
69.6400 276.0000 1.0000
69.6800 281.0000 1.0000
69.7200 288.0000 1.0000
69.7600 279.0000 1.0000
69.8000 286.0000 1.0000
69.8400 302.0000 1.0000
69.8800 310.0000 1.0000
69.9200 301.0000 1.0000
69.9600 307.0000 1.0000
70.0000 292.0000 1.0000
*RAS_INT_END
*RAS_TEMPERATURE_START
*RAS_TEMPERATURE_END
*RAS_DATA_END