File: Data/Dataset2_Water_Organic/4_XRD/No_15_Hematite_EtOH_0025_3.ras
*RAS_DATA_START
*RAS_HEADER_START
*DISP_FMT_X "%.2f"
*DISP_FMT_Y "%.0f"
*DISP_FULLSCALE "14170.0000000000"
*DISP_LINE_COLOR "255.0000000000"
*DISP_LINE_STYLE "0.0000000000"
*DISP_LINE_WIDTH "0.2500000000"
*DISP_NOTE "測定データ-16"
*DISP_OFFSET_Y "0.0000000000"
*DISP_PEAKSEARCH_UNIT_Y "cps"
*DISP_RANGE_BOTTOM "0.0000000000"
*DISP_RANGE_LEFT "20.0000000000"
*DISP_RANGE_LOGCUTOFF "0.0100000000"
*DISP_RANGE_RIGHT "70.0000000000"
*DISP_RANGE_TOP "14170.0000000000"
*DISP_SCALE_MODE_Y "0.0000000000"
*DISP_TAB_NAME "2θ/θ"
*DISP_TITLE_Y "強度"
*DISP_UNIT_Y "cps"
*DISP_WINDOW_NAME "MSG_MACROENGINE"
*FILE_COMMENT " "
*FILE_MD5 ""
*FILE_MEMO " "
*FILE_OPERATOR "Administrator"
*FILE_SAMPLE " "
*FILE_TYPE "RAS_RAW"
*FILE_USERGROUP "システムマネージャ"
*FILE_VERSION "1.0000000000"
*HW_ATTACHMENT_ID "ATT0025"
*HW_ATTACHMENT_NAME "標準|Standard"
*HW_COUNTER_ID-0 "CUT0025"
*HW_COUNTER_ID-1 "CUT0020"
*HW_COUNTER_ID-2 "CUT0020"
*HW_COUNTER_ID-3 "CSL0021"
*HW_COUNTER_ID-4 "CMC0021"
*HW_COUNTER_NAME-0 "D/teX Ultra|D/teX Ultra"
*HW_COUNTER_NAME-1 "None|None"
*HW_COUNTER_NAME-2 "None|None"
*HW_COUNTER_NAME-3 "BBM|BBM"
*HW_COUNTER_NAME-4 "検出器モノクロメータ|Detector monochromator"
*HW_COUNTER_SELECT_NAME "D/teX Ultra|D/teX Ultra"
*HW_GONIOMETER_ID "GON0023"
*HW_GONIOMETER_NAME "SmartLab|SmartLab"
*HW_GONIOMETER_RADIUS-0 "90.0"
*HW_GONIOMETER_RADIUS-1 "114.0"
*HW_GONIOMETER_RADIUS-2 "190.0"
*HW_GONIOMETER_RADIUS-3 "300.0"
*HW_GONIOMETER_RADIUS-4 "187.0"
*HW_GONIOMETER_RADIUS-5 "300.0"
*HW_GONIOMETER_RADIUS-6 "113.0"
*HW_GONIOMETER_RADIUS-7 "331.0"
*HW_I_OPT_ID-0 "CBO0021"
*HW_I_OPT_ID-1 "ICR0023"
*HW_I_OPT_ID-2 "ISL0021"
*HW_I_OPT_ID-3 "ISO0021"
*HW_I_OPT_ID-4 "IAD0021"
*HW_I_OPT_ID-5 "IPR0001"
*HW_I_OPT_NAME-0 "CBOユニット|CBO unit"
*HW_I_OPT_NAME-1 "標準入射光学ユニット|Standard incident optical unit"
*HW_I_OPT_NAME-2 "標準入射スリットボックス|Standard incident slit box"
*HW_I_OPT_NAME-3 "入射平行スリット|Incident parallel slit"
*HW_I_OPT_NAME-4 "長手制限スリット|Length limiting slit"
*HW_I_OPT_NAME-5 "None|None"
*HW_R_ATTENUATER_AUTOMODE "0"
*HW_R_OPT_ID-0 "RSS0021"
*HW_R_OPT_ID-1 "RCR0023"
*HW_R_OPT_ID-2 "RSO0021"
*HW_R_OPT_ID-3 "RRS0021"
*HW_R_OPT_ID-4 "ATN0021"
*HW_R_OPT_ID-5 "RFL0021"
*HW_R_OPT_ID-6 "RAD0021"
*HW_R_OPT_NAME-0 "標準受光スリットボックス1|Standard receiving slit box # 1"
*HW_R_OPT_NAME-1 "標準受光光学ユニット1|Standard receiving unit # 1"
*HW_R_OPT_NAME-2 "標準受光光学ユニット2|Standard receiving optical unit # 2"
*HW_R_OPT_NAME-3 "標準受光スリットボックス2|Standard receiving slit box # 2"
*HW_R_OPT_NAME-4 "標準アッテネータ|Standard Attenuator"
*HW_R_OPT_NAME-5 "Cu Kβ|Cu K-beta"
*HW_R_OPT_NAME-6 "調整用受光スリット|Alignment receiving slit"
*HW_SAMPLE_HOLDER_ID "SMP0023"
*HW_SAMPLE_HOLDER_NAME "標準Zステージ|Standard Z stage"
*HW_XG_CURRENT_MAX "50"
*HW_XG_CURRENT_MIN "2"
*HW_XG_CURRENT_RESOLUTION "1"
*HW_XG_CURRENT_UNIT "mA"
*HW_XG_FOCUS "1mm x 10mm"
*HW_XG_FOCUS_TYPE "Normal"
*HW_XG_ID ""
*HW_XG_NAME "3kW 封入管(ID:1200)|3kW Sealed tube(ID:1200)"
*HW_XG_TARGET_ATOMIC_NUMBER "29.0000000000"
*HW_XG_TARGET_NAME "Cu"
*HW_XG_TYPE "Hermetic"
*HW_XG_VOLTAGE_MAX "60"
*HW_XG_VOLTAGE_MIN "20"
*HW_XG_VOLTAGE_RESOLUTION "1"
*HW_XG_VOLTAGE_UNIT "kV"
*HW_XG_WATT_MAX "1.500"
*HW_XG_WATT_UNIT "kW"
*HW_XG_WAVE_LENGTH_ALPHA1 "1.540593"
*HW_XG_WAVE_LENGTH_ALPHA2 "1.544414"
*HW_XG_WAVE_LENGTH_BETA "1.392250"
*MEAS_COND_AXIS_NAME-0 "2θ/θ"
*MEAS_COND_AXIS_NAME-1 "2θ"
*MEAS_COND_AXIS_NAME-2 "ω"
*MEAS_COND_AXIS_NAME-3 "Z"
*MEAS_COND_AXIS_NAME-4 "2θ/ω"
*MEAS_COND_AXIS_NAME-5 "θs"
*MEAS_COND_AXIS_NAME-6 "θd"
*MEAS_COND_AXIS_NAME-7 "Ts"
*MEAS_COND_AXIS_NAME-8 "CBO選択スリット"
*MEAS_COND_AXIS_NAME-9 "M"
*MEAS_COND_AXIS_NAME-10 "入射平行スリット"
*MEAS_COND_AXIS_NAME-11 "入射スリット"
*MEAS_COND_AXIS_NAME-12 ""
*MEAS_COND_AXIS_NAME-13 "Zs"
*MEAS_COND_AXIS_NAME-14 "入射光学素子"
*MEAS_COND_AXIS_NAME-15 "長手制限スリット"
*MEAS_COND_AXIS_NAME-16 "センタースリット"
*MEAS_COND_AXIS_NAME-17 "フィルター"
*MEAS_COND_AXIS_NAME-18 "受光スリット1"
*MEAS_COND_AXIS_NAME-19 "受光スリット2"
*MEAS_COND_AXIS_NAME-20 "受光光学素子"
*MEAS_COND_AXIS_NAME-21 "受光平行スリット"
*MEAS_COND_AXIS_NAME-22 "調整用受光スリット"
*MEAS_COND_AXIS_NAME-23 ""
*MEAS_COND_AXIS_NAME-24 ""
*MEAS_COND_AXIS_NAME-25 "Zd"
*MEAS_COND_AXIS_NAME-26 "アッテネータ"
*MEAS_COND_AXIS_NAME-27 "検出器モノクロメータ"
*MEAS_COND_AXIS_NAME-28 "モノクロメータスリット"
*MEAS_COND_AXIS_NAME-29 "プライマリビーム"
*MEAS_COND_AXIS_NAME-30 "PHA"
*MEAS_COND_AXIS_NAME_INTERNAL-0 "TwoThetaTheta"
*MEAS_COND_AXIS_NAME_INTERNAL-1 "TwoTheta"
*MEAS_COND_AXIS_NAME_INTERNAL-2 "Omega"
*MEAS_COND_AXIS_NAME_INTERNAL-3 "Z"
*MEAS_COND_AXIS_NAME_INTERNAL-4 "TwoThetaOmega"
*MEAS_COND_AXIS_NAME_INTERNAL-5 "ThetaS"
*MEAS_COND_AXIS_NAME_INTERNAL-6 "ThetaD"
*MEAS_COND_AXIS_NAME_INTERNAL-7 "Ts"
*MEAS_COND_AXIS_NAME_INTERNAL-8 "CBO"
*MEAS_COND_AXIS_NAME_INTERNAL-9 "CBO-M"
*MEAS_COND_AXIS_NAME_INTERNAL-10 "IncidentSollerSlit"
*MEAS_COND_AXIS_NAME_INTERNAL-11 "IncidentSlitBox"
*MEAS_COND_AXIS_NAME_INTERNAL-12 "IncidentSlitBox-_Axis"
*MEAS_COND_AXIS_NAME_INTERNAL-13 "Zs"
*MEAS_COND_AXIS_NAME_INTERNAL-14 "IncidentMonochromator"
*MEAS_COND_AXIS_NAME_INTERNAL-15 "IncidentAxdSlit"
*MEAS_COND_AXIS_NAME_INTERNAL-16 "CenterSlit"
*MEAS_COND_AXIS_NAME_INTERNAL-17 "Filter"
*MEAS_COND_AXIS_NAME_INTERNAL-18 "ReceivingSlitBox1"
*MEAS_COND_AXIS_NAME_INTERNAL-19 "ReceivingSlitBox2"
*MEAS_COND_AXIS_NAME_INTERNAL-20 "ReceivingOptics"
*MEAS_COND_AXIS_NAME_INTERNAL-21 "ReceivingSollerSlit"
*MEAS_COND_AXIS_NAME_INTERNAL-22 "ReceivingAxdSlit"
*MEAS_COND_AXIS_NAME_INTERNAL-23 "ReceivingSlitBox1-_Axis"
*MEAS_COND_AXIS_NAME_INTERNAL-24 "ReceivingSlitBox2-_Axis"
*MEAS_COND_AXIS_NAME_INTERNAL-25 "ReceivingSlitBox2-Zd"
*MEAS_COND_AXIS_NAME_INTERNAL-26 "Attenuator"
*MEAS_COND_AXIS_NAME_INTERNAL-27 "CounterMonochromator"
*MEAS_COND_AXIS_NAME_INTERNAL-28 "CounterSlit"
*MEAS_COND_AXIS_NAME_INTERNAL-29 "IncidentPrimary"
*MEAS_COND_AXIS_NAME_INTERNAL-30 "PHA"
*MEAS_COND_AXIS_NAME_MAGICNO-0 "83951616.0000000000"
*MEAS_COND_AXIS_NAME_MAGICNO-1 "268632064.0000000000"
*MEAS_COND_AXIS_NAME_MAGICNO-2 "268500992.0000000000"
*MEAS_COND_AXIS_NAME_MAGICNO-3 "285278208.0000000000"
*MEAS_COND_AXIS_NAME_MAGICNO-4 "83951616.0000000000"
*MEAS_COND_AXIS_NAME_MAGICNO-5 "131072.0000000000"
*MEAS_COND_AXIS_NAME_MAGICNO-6 "131072.0000000000"
*MEAS_COND_AXIS_NAME_MAGICNO-7 "318898176.0000000000"
*MEAS_COND_AXIS_NAME_MAGICNO-8 "20971521.0000000000"
*MEAS_COND_AXIS_NAME_MAGICNO-9 "285343744.0000000000"
*MEAS_COND_AXIS_NAME_MAGICNO-10 "20971521.0000000000"
*MEAS_COND_AXIS_NAME_MAGICNO-11 "22020097.0000000000"
*MEAS_COND_AXIS_NAME_MAGICNO-12 "25165824.0000000000"
*MEAS_COND_AXIS_NAME_MAGICNO-13 "318898176.0000000000"
*MEAS_COND_AXIS_NAME_MAGICNO-14 "1.0000000000"
*MEAS_COND_AXIS_NAME_MAGICNO-15 "20971521.0000000000"
*MEAS_COND_AXIS_NAME_MAGICNO-16 "20971521.0000000000"
*MEAS_COND_AXIS_NAME_MAGICNO-17 "20971521.0000000000"
*MEAS_COND_AXIS_NAME_MAGICNO-18 "23068673.0000000000"
*MEAS_COND_AXIS_NAME_MAGICNO-19 "23068673.0000000000"
*MEAS_COND_AXIS_NAME_MAGICNO-20 "20971521.0000000000"
*MEAS_COND_AXIS_NAME_MAGICNO-21 "20971521.0000000000"
*MEAS_COND_AXIS_NAME_MAGICNO-22 "20971521.0000000000"
*MEAS_COND_AXIS_NAME_MAGICNO-23 "25165824.0000000000"
*MEAS_COND_AXIS_NAME_MAGICNO-24 "25165824.0000000000"
*MEAS_COND_AXIS_NAME_MAGICNO-25 "285343744.0000000000"
*MEAS_COND_AXIS_NAME_MAGICNO-26 "17301505.0000000000"
*MEAS_COND_AXIS_NAME_MAGICNO-27 "20971521.0000000000"
*MEAS_COND_AXIS_NAME_MAGICNO-28 "20971521.0000000000"
*MEAS_COND_AXIS_NAME_MAGICNO-29 "20971521.0000000000"
*MEAS_COND_AXIS_NAME_MAGICNO-30 "0.0000000000"
*MEAS_COND_AXIS_OFFSET-0 "-"
*MEAS_COND_AXIS_OFFSET-1 "-0.0310000000"
*MEAS_COND_AXIS_OFFSET-2 "0.4064000000"
*MEAS_COND_AXIS_OFFSET-3 "-"
*MEAS_COND_AXIS_OFFSET-4 "-"
*MEAS_COND_AXIS_OFFSET-5 "0.4064000000"
*MEAS_COND_AXIS_OFFSET-6 "-0.4374000000"
*MEAS_COND_AXIS_OFFSET-7 "-"
*MEAS_COND_AXIS_OFFSET-8 "-"
*MEAS_COND_AXIS_OFFSET-9 "-"
*MEAS_COND_AXIS_OFFSET-10 "-"
*MEAS_COND_AXIS_OFFSET-11 "-"
*MEAS_COND_AXIS_OFFSET-12 "-"
*MEAS_COND_AXIS_OFFSET-13 "-"
*MEAS_COND_AXIS_OFFSET-14 "-"
*MEAS_COND_AXIS_OFFSET-15 "-"
*MEAS_COND_AXIS_OFFSET-16 "-"
*MEAS_COND_AXIS_OFFSET-17 "-"
*MEAS_COND_AXIS_OFFSET-18 "-"
*MEAS_COND_AXIS_OFFSET-19 "-"
*MEAS_COND_AXIS_OFFSET-20 "-"
*MEAS_COND_AXIS_OFFSET-21 "-"
*MEAS_COND_AXIS_OFFSET-22 "-"
*MEAS_COND_AXIS_OFFSET-23 "-"
*MEAS_COND_AXIS_OFFSET-24 "-"
*MEAS_COND_AXIS_OFFSET-25 "-"
*MEAS_COND_AXIS_OFFSET-26 "-"
*MEAS_COND_AXIS_OFFSET-27 "-"
*MEAS_COND_AXIS_OFFSET-28 "-"
*MEAS_COND_AXIS_OFFSET-29 "-"
*MEAS_COND_AXIS_OFFSET-30 "-"
*MEAS_COND_AXIS_POSITION-0 "0.0000000000"
*MEAS_COND_AXIS_POSITION-1 "0.0000000000"
*MEAS_COND_AXIS_POSITION-2 "0.0000000000"
*MEAS_COND_AXIS_POSITION-3 "-2.8286000000"
*MEAS_COND_AXIS_POSITION-4 "0.0000000000"
*MEAS_COND_AXIS_POSITION-5 "0.0000000000"
*MEAS_COND_AXIS_POSITION-6 "0.0000000000"
*MEAS_COND_AXIS_POSITION-7 "-0.7498700000"
*MEAS_COND_AXIS_POSITION-8 "BB"
*MEAS_COND_AXIS_POSITION-9 "0.0000000000"
*MEAS_COND_AXIS_POSITION-10 "Soller_slit_5.0deg"
*MEAS_COND_AXIS_POSITION-11 "2/3deg"
*MEAS_COND_AXIS_POSITION-12 "2.2088000000"
*MEAS_COND_AXIS_POSITION-13 "-0.6412500000"
*MEAS_COND_AXIS_POSITION-14 "0.0000000000"
*MEAS_COND_AXIS_POSITION-15 "10.0mm"
*MEAS_COND_AXIS_POSITION-16 "None"
*MEAS_COND_AXIS_POSITION-17 "Cu_K-beta"
*MEAS_COND_AXIS_POSITION-18 "13.000mm"
*MEAS_COND_AXIS_POSITION-19 "13.000mm"
*MEAS_COND_AXIS_POSITION-20 "No_unit"
*MEAS_COND_AXIS_POSITION-21 "Soller_slit_5.0deg"
*MEAS_COND_AXIS_POSITION-22 "None"
*MEAS_COND_AXIS_POSITION-23 "13.0000000000"
*MEAS_COND_AXIS_POSITION-24 "13.0000000000"
*MEAS_COND_AXIS_POSITION-25 "0.0281300000"
*MEAS_COND_AXIS_POSITION-26 "Open"
*MEAS_COND_AXIS_POSITION-27 "None"
*MEAS_COND_AXIS_POSITION-28 "None"
*MEAS_COND_AXIS_POSITION-29 "None"
*MEAS_COND_AXIS_POSITION-30 "38.0000000000"
*MEAS_COND_AXIS_UNIT-0 "deg"
*MEAS_COND_AXIS_UNIT-1 "deg"
*MEAS_COND_AXIS_UNIT-2 "deg"
*MEAS_COND_AXIS_UNIT-3 "mm"
*MEAS_COND_AXIS_UNIT-4 "deg"
*MEAS_COND_AXIS_UNIT-5 "deg"
*MEAS_COND_AXIS_UNIT-6 "deg"
*MEAS_COND_AXIS_UNIT-7 "mm"
*MEAS_COND_AXIS_UNIT-8 ""
*MEAS_COND_AXIS_UNIT-9 "pulse"
*MEAS_COND_AXIS_UNIT-10 ""
*MEAS_COND_AXIS_UNIT-11 ""
*MEAS_COND_AXIS_UNIT-12 "mm"
*MEAS_COND_AXIS_UNIT-13 "mm"
*MEAS_COND_AXIS_UNIT-14 ""
*MEAS_COND_AXIS_UNIT-15 ""
*MEAS_COND_AXIS_UNIT-16 ""
*MEAS_COND_AXIS_UNIT-17 ""
*MEAS_COND_AXIS_UNIT-18 ""
*MEAS_COND_AXIS_UNIT-19 ""
*MEAS_COND_AXIS_UNIT-20 ""
*MEAS_COND_AXIS_UNIT-21 ""
*MEAS_COND_AXIS_UNIT-22 ""
*MEAS_COND_AXIS_UNIT-23 "mm"
*MEAS_COND_AXIS_UNIT-24 "mm"
*MEAS_COND_AXIS_UNIT-25 "mm"
*MEAS_COND_AXIS_UNIT-26 ""
*MEAS_COND_AXIS_UNIT-27 ""
*MEAS_COND_AXIS_UNIT-28 ""
*MEAS_COND_AXIS_UNIT-29 ""
*MEAS_COND_AXIS_UNIT-30 "div"
*MEAS_COND_COUNTER_CNTLOSS_CORR "0.0000000000"
*MEAS_COND_COUNTER_PHABASE "38.0000000000"
*MEAS_COND_COUNTER_PHAWINDOW "16.0000000000"
*MEAS_COND_COUNTER_PHA_UNIT "div"
*MEAS_COND_COUNTER_TAUDIFF "30.0000000000"
*MEAS_COND_COUNTER_TAUINT "0.0000000000"
*MEAS_COND_IRRADIATION_MODE "OFF"
*MEAS_COND_IRRADIATION_WIDTH ""
*MEAS_COND_OPT_ATTR "集中法"
*MEAS_COND_OPT_NAME "@集中法"
*MEAS_COND_UNSYMMETRIC_MODE "OFF"
*MEAS_COND_XG_CURRENT "30.0000000000"
*MEAS_COND_XG_VOLTAGE "40.0000000000"
*MEAS_COND_XG_WAVE_TYPE "Ka"
*MEAS_DATA_COUNT "5001.0000000000"
*MEAS_SCAN_AXIS_X "2θ/θ"
*MEAS_SCAN_AXIS_X_INTERNAL "TwoThetaTheta"
*MEAS_SCAN_END_TIME "08/01/23 21:32:45"
*MEAS_SCAN_MODE "CONTINUOUS"
*MEAS_SCAN_MONITOR "0"
*MEAS_SCAN_RESOLUTION_X "0.0002"
*MEAS_SCAN_SPEED "2.5"
*MEAS_SCAN_SPEED_UNIT "deg/min"
*MEAS_SCAN_START "20.0000000000"
*MEAS_SCAN_START_TIME "08/01/23 21:11:22"
*MEAS_SCAN_STEP "0.0100000000"
*MEAS_SCAN_STOP "70.0000000000"
*MEAS_SCAN_UNIT_X "deg"
*MEAS_SCAN_UNIT_Y "counts"
*RAS_HEADER_END
*RAS_INT_START
20.0000 913.0000 1.0000
20.0400 929.0000 1.0000
20.0800 934.0000 1.0000
20.1200 963.0000 1.0000
20.1600 934.0000 1.0000
20.2000 952.0000 1.0000
20.2400 942.0000 1.0000
20.2800 953.0000 1.0000
20.3200 977.0000 1.0000
20.3600 946.0000 1.0000
20.4000 925.0000 1.0000
20.4400 924.0000 1.0000
20.4800 942.0000 1.0000
20.5200 938.0000 1.0000
20.5600 983.0000 1.0000
20.6000 975.0000 1.0000
20.6400 942.0000 1.0000
20.6800 929.0000 1.0000
20.7200 919.0000 1.0000
20.7600 932.0000 1.0000
20.8000 906.0000 1.0000
20.8400 955.0000 1.0000
20.8800 956.0000 1.0000
20.9200 986.0000 1.0000
20.9600 945.0000 1.0000
21.0000 946.0000 1.0000
21.0400 947.0000 1.0000
21.0800 891.0000 1.0000
21.1200 955.0000 1.0000
21.1600 987.0000 1.0000
21.2000 974.0000 1.0000
21.2400 909.0000 1.0000
21.2800 954.0000 1.0000
21.3200 929.0000 1.0000
21.3600 938.0000 1.0000
21.4000 943.0000 1.0000
21.4400 870.0000 1.0000
21.4800 937.0000 1.0000
21.5200 942.0000 1.0000
21.5600 967.0000 1.0000
21.6000 925.0000 1.0000
21.6400 943.0000 1.0000
21.6800 954.0000 1.0000
21.7200 844.0000 1.0000
21.7600 943.0000 1.0000
21.8000 1016.0000 1.0000
21.8400 946.0000 1.0000
21.8800 957.0000 1.0000
21.9200 924.0000 1.0000
21.9600 941.0000 1.0000
22.0000 910.0000 1.0000
22.0400 905.0000 1.0000
22.0800 941.0000 1.0000
22.1200 942.0000 1.0000
22.1600 927.0000 1.0000
22.2000 926.0000 1.0000
22.2400 914.0000 1.0000
22.2800 950.0000 1.0000
22.3200 922.0000 1.0000
22.3600 933.0000 1.0000
22.4000 945.0000 1.0000
22.4400 924.0000 1.0000
22.4800 915.0000 1.0000
22.5200 883.0000 1.0000
22.5600 916.0000 1.0000
22.6000 925.0000 1.0000
22.6400 925.0000 1.0000
22.6800 882.0000 1.0000
22.7200 951.0000 1.0000
22.7600 881.0000 1.0000
22.8000 880.0000 1.0000
22.8400 927.0000 1.0000
22.8800 884.0000 1.0000
22.9200 925.0000 1.0000
22.9600 870.0000 1.0000
23.0000 952.0000 1.0000
23.0400 870.0000 1.0000
23.0800 909.0000 1.0000
23.1200 875.0000 1.0000
23.1600 903.0000 1.0000
23.2000 889.0000 1.0000
23.2400 924.0000 1.0000
23.2800 883.0000 1.0000
23.3200 947.0000 1.0000
23.3600 921.0000 1.0000
23.4000 879.0000 1.0000
23.4400 935.0000 1.0000
23.4800 910.0000 1.0000
23.5200 923.0000 1.0000
23.5600 902.0000 1.0000
23.6000 879.0000 1.0000
23.6400 862.0000 1.0000
23.6800 884.0000 1.0000
23.7200 882.0000 1.0000
23.7600 916.0000 1.0000
23.8000 862.0000 1.0000
23.8400 924.0000 1.0000
23.8800 961.0000 1.0000
23.9200 970.0000 1.0000
23.9600 990.0000 1.0000
24.0000 1026.0000 1.0000
24.0400 998.0000 1.0000
24.0800 1034.0000 1.0000
24.1200 1034.0000 1.0000
24.1600 974.0000 1.0000
24.2000 914.0000 1.0000
24.2400 944.0000 1.0000
24.2800 921.0000 1.0000
24.3200 889.0000 1.0000
24.3600 881.0000 1.0000
24.4000 905.0000 1.0000
24.4400 883.0000 1.0000
24.4800 919.0000 1.0000
24.5200 865.0000 1.0000
24.5600 939.0000 1.0000
24.6000 883.0000 1.0000
24.6400 891.0000 1.0000
24.6800 907.0000 1.0000
24.7200 893.0000 1.0000
24.7600 849.0000 1.0000
24.8000 868.0000 1.0000
24.8400 905.0000 1.0000
24.8800 887.0000 1.0000
24.9200 852.0000 1.0000
24.9600 828.0000 1.0000
25.0000 852.0000 1.0000
25.0400 928.0000 1.0000
25.0800 862.0000 1.0000
25.1200 838.0000 1.0000
25.1600 898.0000 1.0000
25.2000 831.0000 1.0000
25.2400 867.0000 1.0000
25.2800 904.0000 1.0000
25.3200 898.0000 1.0000
25.3600 886.0000 1.0000
25.4000 871.0000 1.0000
25.4400 926.0000 1.0000
25.4800 857.0000 1.0000
25.5200 888.0000 1.0000
25.5600 872.0000 1.0000
25.6000 926.0000 1.0000
25.6400 848.0000 1.0000
25.6800 899.0000 1.0000
25.7200 908.0000 1.0000
25.7600 884.0000 1.0000
25.8000 889.0000 1.0000
25.8400 879.0000 1.0000
25.8800 898.0000 1.0000
25.9200 937.0000 1.0000
25.9600 942.0000 1.0000
26.0000 939.0000 1.0000
26.0400 932.0000 1.0000
26.0800 956.0000 1.0000
26.1200 1021.0000 1.0000
26.1600 1056.0000 1.0000
26.2000 1145.0000 1.0000
26.2400 1314.0000 1.0000
26.2800 1426.0000 1.0000
26.3200 1728.0000 1.0000
26.3600 2067.0000 1.0000
26.4000 2421.0000 1.0000
26.4400 2795.0000 1.0000
26.4800 2567.0000 1.0000
26.5200 2202.0000 1.0000
26.5600 1820.0000 1.0000
26.6000 1554.0000 1.0000
26.6400 1299.0000 1.0000
26.6800 1125.0000 1.0000
26.7200 1090.0000 1.0000
26.7600 988.0000 1.0000
26.8000 966.0000 1.0000
26.8400 932.0000 1.0000
26.8800 913.0000 1.0000
26.9200 922.0000 1.0000
26.9600 893.0000 1.0000
27.0000 849.0000 1.0000
27.0400 804.0000 1.0000
27.0800 883.0000 1.0000
27.1200 824.0000 1.0000
27.1600 856.0000 1.0000
27.2000 858.0000 1.0000
27.2400 820.0000 1.0000
27.2800 815.0000 1.0000
27.3200 825.0000 1.0000
27.3600 816.0000 1.0000
27.4000 800.0000 1.0000
27.4400 832.0000 1.0000
27.4800 793.0000 1.0000
27.5200 819.0000 1.0000
27.5600 784.0000 1.0000
27.6000 786.0000 1.0000
27.6400 793.0000 1.0000
27.6800 802.0000 1.0000
27.7200 731.0000 1.0000
27.7600 748.0000 1.0000
27.8000 804.0000 1.0000
27.8400 797.0000 1.0000
27.8800 763.0000 1.0000
27.9200 794.0000 1.0000
27.9600 746.0000 1.0000
28.0000 788.0000 1.0000
28.0400 801.0000 1.0000
28.0800 795.0000 1.0000
28.1200 820.0000 1.0000
28.1600 746.0000 1.0000
28.2000 776.0000 1.0000
28.2400 784.0000 1.0000
28.2800 761.0000 1.0000
28.3200 768.0000 1.0000
28.3600 793.0000 1.0000
28.4000 754.0000 1.0000
28.4400 753.0000 1.0000
28.4800 730.0000 1.0000
28.5200 728.0000 1.0000
28.5600 746.0000 1.0000
28.6000 719.0000 1.0000
28.6400 744.0000 1.0000
28.6800 698.0000 1.0000
28.7200 716.0000 1.0000
28.7600 765.0000 1.0000
28.8000 716.0000 1.0000
28.8400 757.0000 1.0000
28.8800 742.0000 1.0000
28.9200 748.0000 1.0000
28.9600 708.0000 1.0000
29.0000 731.0000 1.0000
29.0400 724.0000 1.0000
29.0800 731.0000 1.0000
29.1200 763.0000 1.0000
29.1600 735.0000 1.0000
29.2000 743.0000 1.0000
29.2400 735.0000 1.0000
29.2800 750.0000 1.0000
29.3200 694.0000 1.0000
29.3600 715.0000 1.0000
29.4000 790.0000 1.0000
29.4400 721.0000 1.0000
29.4800 776.0000 1.0000
29.5200 735.0000 1.0000
29.5600 713.0000 1.0000
29.6000 747.0000 1.0000
29.6400 742.0000 1.0000
29.6800 711.0000 1.0000
29.7200 707.0000 1.0000
29.7600 720.0000 1.0000
29.8000 715.0000 1.0000
29.8400 679.0000 1.0000
29.8800 699.0000 1.0000
29.9200 715.0000 1.0000
29.9600 697.0000 1.0000
30.0000 705.0000 1.0000
30.0400 744.0000 1.0000
30.0800 739.0000 1.0000
30.1200 717.0000 1.0000
30.1600 678.0000 1.0000
30.2000 715.0000 1.0000
30.2400 685.0000 1.0000
30.2800 672.0000 1.0000
30.3200 696.0000 1.0000
30.3600 671.0000 1.0000
30.4000 696.0000 1.0000
30.4400 702.0000 1.0000
30.4800 696.0000 1.0000
30.5200 694.0000 1.0000
30.5600 643.0000 1.0000
30.6000 709.0000 1.0000
30.6400 682.0000 1.0000
30.6800 694.0000 1.0000
30.7200 683.0000 1.0000
30.7600 679.0000 1.0000
30.8000 694.0000 1.0000
30.8400 722.0000 1.0000
30.8800 698.0000 1.0000
30.9200 630.0000 1.0000
30.9600 660.0000 1.0000
31.0000 673.0000 1.0000
31.0400 674.0000 1.0000
31.0800 732.0000 1.0000
31.1200 667.0000 1.0000
31.1600 678.0000 1.0000
31.2000 720.0000 1.0000
31.2400 689.0000 1.0000
31.2800 629.0000 1.0000
31.3200 665.0000 1.0000
31.3600 642.0000 1.0000
31.4000 707.0000 1.0000
31.4400 717.0000 1.0000
31.4800 654.0000 1.0000
31.5200 689.0000 1.0000
31.5600 689.0000 1.0000
31.6000 682.0000 1.0000
31.6400 723.0000 1.0000
31.6800 675.0000 1.0000
31.7200 669.0000 1.0000
31.7600 627.0000 1.0000
31.8000 682.0000 1.0000
31.8400 628.0000 1.0000
31.8800 672.0000 1.0000
31.9200 620.0000 1.0000
31.9600 647.0000 1.0000
32.0000 654.0000 1.0000
32.0400 674.0000 1.0000
32.0800 697.0000 1.0000
32.1200 641.0000 1.0000
32.1600 647.0000 1.0000
32.2000 654.0000 1.0000
32.2400 613.0000 1.0000
32.2800 664.0000 1.0000
32.3200 647.0000 1.0000
32.3600 648.0000 1.0000
32.4000 626.0000 1.0000
32.4400 613.0000 1.0000
32.4800 616.0000 1.0000
32.5200 638.0000 1.0000
32.5600 612.0000 1.0000
32.6000 598.0000 1.0000
32.6400 674.0000 1.0000
32.6800 659.0000 1.0000
32.7200 614.0000 1.0000
32.7600 628.0000 1.0000
32.8000 613.0000 1.0000
32.8400 637.0000 1.0000
32.8800 679.0000 1.0000
32.9200 644.0000 1.0000
32.9600 630.0000 1.0000
33.0000 734.0000 1.0000
33.0400 766.0000 1.0000
33.0800 832.0000 1.0000
33.1200 880.0000 1.0000
33.1600 805.0000 1.0000
33.2000 775.0000 1.0000
33.2400 729.0000 1.0000
33.2800 720.0000 1.0000
33.3200 752.0000 1.0000
33.3600 722.0000 1.0000
33.4000 746.0000 1.0000
33.4400 784.0000 1.0000
33.4800 912.0000 1.0000
33.5200 960.0000 1.0000
33.5600 1119.0000 1.0000
33.6000 1358.0000 1.0000
33.6400 1386.0000 1.0000
33.6800 1446.0000 1.0000
33.7200 1332.0000 1.0000
33.7600 1132.0000 1.0000
33.8000 957.0000 1.0000
33.8400 879.0000 1.0000
33.8800 789.0000 1.0000
33.9200 696.0000 1.0000
33.9600 730.0000 1.0000
34.0000 683.0000 1.0000
34.0400 680.0000 1.0000
34.0800 616.0000 1.0000
34.1200 647.0000 1.0000
34.1600 646.0000 1.0000
34.2000 613.0000 1.0000
34.2400 601.0000 1.0000
34.2800 615.0000 1.0000
34.3200 643.0000 1.0000
34.3600 607.0000 1.0000
34.4000 594.0000 1.0000
34.4400 610.0000 1.0000
34.4800 596.0000 1.0000
34.5200 581.0000 1.0000
34.5600 553.0000 1.0000
34.6000 576.0000 1.0000
34.6400 609.0000 1.0000
34.6800 584.0000 1.0000
34.7200 561.0000 1.0000
34.7600 613.0000 1.0000
34.8000 568.0000 1.0000
34.8400 519.0000 1.0000
34.8800 569.0000 1.0000
34.9200 547.0000 1.0000
34.9600 585.0000 1.0000
35.0000 549.0000 1.0000
35.0400 576.0000 1.0000
35.0800 582.0000 1.0000
35.1200 587.0000 1.0000
35.1600 569.0000 1.0000
35.2000 547.0000 1.0000
35.2400 585.0000 1.0000
35.2800 610.0000 1.0000
35.3200 598.0000 1.0000
35.3600 658.0000 1.0000
35.4000 717.0000 1.0000
35.4400 758.0000 1.0000
35.4800 890.0000 1.0000
35.5200 1131.0000 1.0000
35.5600 1278.0000 1.0000
35.6000 1246.0000 1.0000
35.6400 1120.0000 1.0000
35.6800 964.0000 1.0000
35.7200 779.0000 1.0000
35.7600 664.0000 1.0000
35.8000 599.0000 1.0000
35.8400 585.0000 1.0000
35.8800 586.0000 1.0000
35.9200 532.0000 1.0000
35.9600 556.0000 1.0000
36.0000 573.0000 1.0000
36.0400 526.0000 1.0000
36.0800 547.0000 1.0000
36.1200 548.0000 1.0000
36.1600 509.0000 1.0000
36.2000 533.0000 1.0000
36.2400 508.0000 1.0000
36.2800 546.0000 1.0000
36.3200 519.0000 1.0000
36.3600 518.0000 1.0000
36.4000 529.0000 1.0000
36.4400 538.0000 1.0000
36.4800 515.0000 1.0000
36.5200 533.0000 1.0000
36.5600 535.0000 1.0000
36.6000 549.0000 1.0000
36.6400 509.0000 1.0000
36.6800 515.0000 1.0000
36.7200 500.0000 1.0000
36.7600 551.0000 1.0000
36.8000 513.0000 1.0000
36.8400 507.0000 1.0000
36.8800 492.0000 1.0000
36.9200 524.0000 1.0000
36.9600 519.0000 1.0000
37.0000 535.0000 1.0000
37.0400 535.0000 1.0000
37.0800 510.0000 1.0000
37.1200 516.0000 1.0000
37.1600 533.0000 1.0000
37.2000 556.0000 1.0000
37.2400 567.0000 1.0000
37.2800 561.0000 1.0000
37.3200 591.0000 1.0000
37.3600 631.0000 1.0000
37.4000 655.0000 1.0000
37.4400 676.0000 1.0000
37.4800 788.0000 1.0000
37.5200 967.0000 1.0000
37.5600 1162.0000 1.0000
37.6000 1427.0000 1.0000
37.6400 1758.0000 1.0000
37.6800 2118.0000 1.0000
37.7200 2116.0000 1.0000
37.7600 2033.0000 1.0000
37.8000 1677.0000 1.0000
37.8400 1457.0000 1.0000
37.8800 1113.0000 1.0000
37.9200 914.0000 1.0000
37.9600 778.0000 1.0000
38.0000 688.0000 1.0000
38.0400 660.0000 1.0000
38.0800 589.0000 1.0000
38.1200 550.0000 1.0000
38.1600 526.0000 1.0000
38.2000 514.0000 1.0000
38.2400 498.0000 1.0000
38.2800 536.0000 1.0000
38.3200 499.0000 1.0000
38.3600 498.0000 1.0000
38.4000 534.0000 1.0000
38.4400 483.0000 1.0000
38.4800 459.0000 1.0000
38.5200 508.0000 1.0000
38.5600 491.0000 1.0000
38.6000 463.0000 1.0000
38.6400 500.0000 1.0000
38.6800 446.0000 1.0000
38.7200 500.0000 1.0000
38.7600 525.0000 1.0000
38.8000 512.0000 1.0000
38.8400 471.0000 1.0000
38.8800 512.0000 1.0000
38.9200 472.0000 1.0000
38.9600 440.0000 1.0000
39.0000 474.0000 1.0000
39.0400 478.0000 1.0000
39.0800 484.0000 1.0000
39.1200 472.0000 1.0000
39.1600 436.0000 1.0000
39.2000 459.0000 1.0000
39.2400 491.0000 1.0000
39.2800 432.0000 1.0000
39.3200 468.0000 1.0000
39.3600 437.0000 1.0000
39.4000 438.0000 1.0000
39.4400 482.0000 1.0000
39.4800 470.0000 1.0000
39.5200 422.0000 1.0000
39.5600 455.0000 1.0000
39.6000 461.0000 1.0000
39.6400 441.0000 1.0000
39.6800 498.0000 1.0000
39.7200 419.0000 1.0000
39.7600 496.0000 1.0000
39.8000 445.0000 1.0000
39.8400 465.0000 1.0000
39.8800 394.0000 1.0000
39.9200 433.0000 1.0000
39.9600 442.0000 1.0000
40.0000 435.0000 1.0000
40.0400 440.0000 1.0000
40.0800 436.0000 1.0000
40.1200 421.0000 1.0000
40.1600 454.0000 1.0000
40.2000 451.0000 1.0000
40.2400 433.0000 1.0000
40.2800 428.0000 1.0000
40.3200 433.0000 1.0000
40.3600 443.0000 1.0000
40.4000 416.0000 1.0000
40.4400 441.0000 1.0000
40.4800 474.0000 1.0000
40.5200 473.0000 1.0000
40.5600 450.0000 1.0000
40.6000 429.0000 1.0000
40.6400 429.0000 1.0000
40.6800 467.0000 1.0000
40.7200 480.0000 1.0000
40.7600 467.0000 1.0000
40.8000 481.0000 1.0000
40.8400 478.0000 1.0000
40.8800 423.0000 1.0000
40.9200 465.0000 1.0000
40.9600 452.0000 1.0000
41.0000 441.0000 1.0000
41.0400 423.0000 1.0000
41.0800 482.0000 1.0000
41.1200 392.0000 1.0000
41.1600 409.0000 1.0000
41.2000 475.0000 1.0000
41.2400 451.0000 1.0000
41.2800 417.0000 1.0000
41.3200 422.0000 1.0000
41.3600 396.0000 1.0000
41.4000 434.0000 1.0000
41.4400 434.0000 1.0000
41.4800 436.0000 1.0000
41.5200 451.0000 1.0000
41.5600 401.0000 1.0000
41.6000 455.0000 1.0000
41.6400 441.0000 1.0000
41.6800 420.0000 1.0000
41.7200 404.0000 1.0000
41.7600 433.0000 1.0000
41.8000 441.0000 1.0000
41.8400 420.0000 1.0000
41.8800 418.0000 1.0000
41.9200 431.0000 1.0000
41.9600 454.0000 1.0000
42.0000 419.0000 1.0000
42.0400 437.0000 1.0000
42.0800 430.0000 1.0000
42.1200 465.0000 1.0000
42.1600 406.0000 1.0000
42.2000 431.0000 1.0000
42.2400 460.0000 1.0000
42.2800 425.0000 1.0000
42.3200 470.0000 1.0000
42.3600 447.0000 1.0000
42.4000 472.0000 1.0000
42.4400 457.0000 1.0000
42.4800 478.0000 1.0000
42.5200 471.0000 1.0000
42.5600 453.0000 1.0000
42.6000 465.0000 1.0000
42.6400 438.0000 1.0000
42.6800 436.0000 1.0000
42.7200 421.0000 1.0000
42.7600 407.0000 1.0000
42.8000 430.0000 1.0000
42.8400 420.0000 1.0000
42.8800 427.0000 1.0000
42.9200 397.0000 1.0000
42.9600 444.0000 1.0000
43.0000 441.0000 1.0000
43.0400 399.0000 1.0000
43.0800 411.0000 1.0000
43.1200 389.0000 1.0000
43.1600 430.0000 1.0000
43.2000 397.0000 1.0000
43.2400 408.0000 1.0000
43.2800 384.0000 1.0000
43.3200 444.0000 1.0000
43.3600 422.0000 1.0000
43.4000 434.0000 1.0000
43.4400 423.0000 1.0000
43.4800 466.0000 1.0000
43.5200 443.0000 1.0000
43.5600 408.0000 1.0000
43.6000 413.0000 1.0000
43.6400 411.0000 1.0000
43.6800 430.0000 1.0000
43.7200 409.0000 1.0000
43.7600 391.0000 1.0000
43.8000 391.0000 1.0000
43.8400 398.0000 1.0000
43.8800 388.0000 1.0000
43.9200 410.0000 1.0000
43.9600 393.0000 1.0000
44.0000 402.0000 1.0000
44.0400 387.0000 1.0000
44.0800 386.0000 1.0000
44.1200 406.0000 1.0000
44.1600 438.0000 1.0000
44.2000 409.0000 1.0000
44.2400 368.0000 1.0000
44.2800 449.0000 1.0000
44.3200 370.0000 1.0000
44.3600 408.0000 1.0000
44.4000 389.0000 1.0000
44.4400 409.0000 1.0000
44.4800 429.0000 1.0000
44.5200 384.0000 1.0000
44.5600 391.0000 1.0000
44.6000 403.0000 1.0000
44.6400 418.0000 1.0000
44.6800 381.0000 1.0000
44.7200 409.0000 1.0000
44.7600 400.0000 1.0000
44.8000 395.0000 1.0000
44.8400 401.0000 1.0000
44.8800 387.0000 1.0000
44.9200 369.0000 1.0000
44.9600 394.0000 1.0000
45.0000 370.0000 1.0000
45.0400 371.0000 1.0000
45.0800 379.0000 1.0000
45.1200 383.0000 1.0000
45.1600 424.0000 1.0000
45.2000 392.0000 1.0000
45.2400 373.0000 1.0000
45.2800 375.0000 1.0000
45.3200 423.0000 1.0000
45.3600 413.0000 1.0000
45.4000 376.0000 1.0000
45.4400 426.0000 1.0000
45.4800 390.0000 1.0000
45.5200 418.0000 1.0000
45.5600 378.0000 1.0000
45.6000 389.0000 1.0000
45.6400 417.0000 1.0000
45.6800 368.0000 1.0000
45.7200 387.0000 1.0000
45.7600 383.0000 1.0000
45.8000 399.0000 1.0000
45.8400 377.0000 1.0000
45.8800 360.0000 1.0000
45.9200 378.0000 1.0000
45.9600 381.0000 1.0000
46.0000 353.0000 1.0000
46.0400 383.0000 1.0000
46.0800 417.0000 1.0000
46.1200 433.0000 1.0000
46.1600 405.0000 1.0000
46.2000 421.0000 1.0000
46.2400 369.0000 1.0000
46.2800 384.0000 1.0000
46.3200 368.0000 1.0000
46.3600 430.0000 1.0000
46.4000 420.0000 1.0000
46.4400 381.0000 1.0000
46.4800 356.0000 1.0000
46.5200 387.0000 1.0000
46.5600 399.0000 1.0000
46.6000 348.0000 1.0000
46.6400 367.0000 1.0000
46.6800 354.0000 1.0000
46.7200 373.0000 1.0000
46.7600 357.0000 1.0000
46.8000 370.0000 1.0000
46.8400 322.0000 1.0000
46.8800 362.0000 1.0000
46.9200 388.0000 1.0000
46.9600 341.0000 1.0000
47.0000 380.0000 1.0000
47.0400 367.0000 1.0000
47.0800 375.0000 1.0000
47.1200 372.0000 1.0000
47.1600 369.0000 1.0000
47.2000 358.0000 1.0000
47.2400 387.0000 1.0000
47.2800 382.0000 1.0000
47.3200 359.0000 1.0000
47.3600 350.0000 1.0000
47.4000 349.0000 1.0000
47.4400 379.0000 1.0000
47.4800 411.0000 1.0000
47.5200 350.0000 1.0000
47.5600 411.0000 1.0000
47.6000 377.0000 1.0000
47.6400 379.0000 1.0000
47.6800 380.0000 1.0000
47.7200 357.0000 1.0000
47.7600 376.0000 1.0000
47.8000 361.0000 1.0000
47.8400 360.0000 1.0000
47.8800 345.0000 1.0000
47.9200 365.0000 1.0000
47.9600 369.0000 1.0000
48.0000 368.0000 1.0000
48.0400 383.0000 1.0000
48.0800 377.0000 1.0000
48.1200 353.0000 1.0000
48.1600 380.0000 1.0000
48.2000 378.0000 1.0000
48.2400 367.0000 1.0000
48.2800 359.0000 1.0000
48.3200 367.0000 1.0000
48.3600 349.0000 1.0000
48.4000 369.0000 1.0000
48.4400 374.0000 1.0000
48.4800 348.0000 1.0000
48.5200 370.0000 1.0000
48.5600 373.0000 1.0000
48.6000 345.0000 1.0000
48.6400 376.0000 1.0000
48.6800 339.0000 1.0000
48.7200 351.0000 1.0000
48.7600 383.0000 1.0000
48.8000 348.0000 1.0000
48.8400 385.0000 1.0000
48.8800 351.0000 1.0000
48.9200 379.0000 1.0000
48.9600 361.0000 1.0000
49.0000 336.0000 1.0000
49.0400 386.0000 1.0000
49.0800 383.0000 1.0000
49.1200 380.0000 1.0000
49.1600 363.0000 1.0000
49.2000 357.0000 1.0000
49.2400 373.0000 1.0000
49.2800 368.0000 1.0000
49.3200 406.0000 1.0000
49.3600 413.0000 1.0000
49.4000 417.0000 1.0000
49.4400 424.0000 1.0000
49.4800 423.0000 1.0000
49.5200 411.0000 1.0000
49.5600 393.0000 1.0000
49.6000 385.0000 1.0000
49.6400 403.0000 1.0000
49.6800 384.0000 1.0000
49.7200 344.0000 1.0000
49.7600 362.0000 1.0000
49.8000 389.0000 1.0000
49.8400 394.0000 1.0000
49.8800 395.0000 1.0000
49.9200 358.0000 1.0000
49.9600 365.0000 1.0000
50.0000 362.0000 1.0000
50.0400 372.0000 1.0000
50.0800 350.0000 1.0000
50.1200 340.0000 1.0000
50.1600 387.0000 1.0000
50.2000 355.0000 1.0000
50.2400 392.0000 1.0000
50.2800 386.0000 1.0000
50.3200 390.0000 1.0000
50.3600 339.0000 1.0000
50.4000 350.0000 1.0000
50.4400 326.0000 1.0000
50.4800 354.0000 1.0000
50.5200 387.0000 1.0000
50.5600 363.0000 1.0000
50.6000 390.0000 1.0000
50.6400 402.0000 1.0000
50.6800 345.0000 1.0000
50.7200 357.0000 1.0000
50.7600 416.0000 1.0000
50.8000 374.0000 1.0000
50.8400 394.0000 1.0000
50.8800 353.0000 1.0000
50.9200 397.0000 1.0000
50.9600 393.0000 1.0000
51.0000 387.0000 1.0000
51.0400 384.0000 1.0000
51.0800 413.0000 1.0000
51.1200 427.0000 1.0000
51.1600 460.0000 1.0000
51.2000 497.0000 1.0000
51.2400 597.0000 1.0000
51.2800 656.0000 1.0000
51.3200 835.0000 1.0000
51.3600 1124.0000 1.0000
51.4000 1411.0000 1.0000
51.4400 1787.0000 1.0000
51.4800 2051.0000 1.0000
51.5200 1953.0000 1.0000
51.5600 1719.0000 1.0000
51.6000 1541.0000 1.0000
51.6400 1419.0000 1.0000
51.6800 1022.0000 1.0000
51.7200 852.0000 1.0000
51.7600 684.0000 1.0000
51.8000 575.0000 1.0000
51.8400 511.0000 1.0000
51.8800 449.0000 1.0000
51.9200 452.0000 1.0000
51.9600 452.0000 1.0000
52.0000 413.0000 1.0000
52.0400 384.0000 1.0000
52.0800 391.0000 1.0000
52.1200 391.0000 1.0000
52.1600 380.0000 1.0000
52.2000 367.0000 1.0000
52.2400 375.0000 1.0000
52.2800 380.0000 1.0000
52.3200 331.0000 1.0000
52.3600 393.0000 1.0000
52.4000 363.0000 1.0000
52.4400 348.0000 1.0000
52.4800 357.0000 1.0000
52.5200 367.0000 1.0000
52.5600 367.0000 1.0000
52.6000 327.0000 1.0000
52.6400 362.0000 1.0000
52.6800 341.0000 1.0000
52.7200 357.0000 1.0000
52.7600 365.0000 1.0000
52.8000 389.0000 1.0000
52.8400 353.0000 1.0000
52.8800 323.0000 1.0000
52.9200 344.0000 1.0000
52.9600 340.0000 1.0000
53.0000 340.0000 1.0000
53.0400 352.0000 1.0000
53.0800 332.0000 1.0000
53.1200 334.0000 1.0000
53.1600 350.0000 1.0000
53.2000 339.0000 1.0000
53.2400 363.0000 1.0000
53.2800 382.0000 1.0000
53.3200 347.0000 1.0000
53.3600 341.0000 1.0000
53.4000 356.0000 1.0000
53.4400 339.0000 1.0000
53.4800 341.0000 1.0000
53.5200 339.0000 1.0000
53.5600 363.0000 1.0000
53.6000 341.0000 1.0000
53.6400 342.0000 1.0000
53.6800 372.0000 1.0000
53.7200 352.0000 1.0000
53.7600 337.0000 1.0000
53.8000 342.0000 1.0000
53.8400 367.0000 1.0000
53.8800 392.0000 1.0000
53.9200 373.0000 1.0000
53.9600 391.0000 1.0000
54.0000 414.0000 1.0000
54.0400 423.0000 1.0000
54.0800 380.0000 1.0000
54.1200 375.0000 1.0000
54.1600 392.0000 1.0000
54.2000 355.0000 1.0000
54.2400 360.0000 1.0000
54.2800 386.0000 1.0000
54.3200 411.0000 1.0000
54.3600 395.0000 1.0000
54.4000 433.0000 1.0000
54.4400 439.0000 1.0000
54.4800 505.0000 1.0000
54.5200 440.0000 1.0000
54.5600 494.0000 1.0000
54.6000 474.0000 1.0000
54.6400 412.0000 1.0000
54.6800 438.0000 1.0000
54.7200 403.0000 1.0000
54.7600 435.0000 1.0000
54.8000 386.0000 1.0000
54.8400 374.0000 1.0000
54.8800 387.0000 1.0000
54.9200 376.0000 1.0000
54.9600 320.0000 1.0000
55.0000 368.0000 1.0000
55.0400 324.0000 1.0000
55.0800 336.0000 1.0000
55.1200 348.0000 1.0000
55.1600 341.0000 1.0000
55.2000 353.0000 1.0000
55.2400 302.0000 1.0000
55.2800 349.0000 1.0000
55.3200 305.0000 1.0000
55.3600 338.0000 1.0000
55.4000 337.0000 1.0000
55.4400 334.0000 1.0000
55.4800 356.0000 1.0000
55.5200 339.0000 1.0000
55.5600 338.0000 1.0000
55.6000 350.0000 1.0000
55.6400 327.0000 1.0000
55.6800 349.0000 1.0000
55.7200 328.0000 1.0000
55.7600 328.0000 1.0000
55.8000 339.0000 1.0000
55.8400 338.0000 1.0000
55.8800 351.0000 1.0000
55.9200 395.0000 1.0000
55.9600 333.0000 1.0000
56.0000 354.0000 1.0000
56.0400 327.0000 1.0000
56.0800 323.0000 1.0000
56.1200 363.0000 1.0000
56.1600 323.0000 1.0000
56.2000 336.0000 1.0000
56.2400 326.0000 1.0000
56.2800 353.0000 1.0000
56.3200 345.0000 1.0000
56.3600 334.0000 1.0000
56.4000 337.0000 1.0000
56.4400 312.0000 1.0000
56.4800 329.0000 1.0000
56.5200 315.0000 1.0000
56.5600 322.0000 1.0000
56.6000 310.0000 1.0000
56.6400 355.0000 1.0000
56.6800 343.0000 1.0000
56.7200 352.0000 1.0000
56.7600 355.0000 1.0000
56.8000 337.0000 1.0000
56.8400 349.0000 1.0000
56.8800 333.0000 1.0000
56.9200 320.0000 1.0000
56.9600 328.0000 1.0000
57.0000 313.0000 1.0000
57.0400 367.0000 1.0000
57.0800 348.0000 1.0000
57.1200 326.0000 1.0000
57.1600 318.0000 1.0000
57.2000 324.0000 1.0000
57.2400 348.0000 1.0000
57.2800 325.0000 1.0000
57.3200 349.0000 1.0000
57.3600 308.0000 1.0000
57.4000 360.0000 1.0000
57.4400 330.0000 1.0000
57.4800 339.0000 1.0000
57.5200 330.0000 1.0000
57.5600 386.0000 1.0000
57.6000 352.0000 1.0000
57.6400 333.0000 1.0000
57.6800 326.0000 1.0000
57.7200 364.0000 1.0000
57.7600 321.0000 1.0000
57.8000 344.0000 1.0000
57.8400 342.0000 1.0000
57.8800 359.0000 1.0000
57.9200 364.0000 1.0000
57.9600 334.0000 1.0000
58.0000 328.0000 1.0000
58.0400 330.0000 1.0000
58.0800 339.0000 1.0000
58.1200 324.0000 1.0000
58.1600 339.0000 1.0000
58.2000 328.0000 1.0000
58.2400 311.0000 1.0000
58.2800 328.0000 1.0000
58.3200 355.0000 1.0000
58.3600 334.0000 1.0000
58.4000 341.0000 1.0000
58.4400 325.0000 1.0000
58.4800 348.0000 1.0000
58.5200 309.0000 1.0000
58.5600 328.0000 1.0000
58.6000 329.0000 1.0000
58.6400 359.0000 1.0000
58.6800 328.0000 1.0000
58.7200 321.0000 1.0000
58.7600 317.0000 1.0000
58.8000 324.0000 1.0000
58.8400 318.0000 1.0000
58.8800 347.0000 1.0000
58.9200 332.0000 1.0000
58.9600 318.0000 1.0000
59.0000 320.0000 1.0000
59.0400 338.0000 1.0000
59.0800 343.0000 1.0000
59.1200 311.0000 1.0000
59.1600 320.0000 1.0000
59.2000 324.0000 1.0000
59.2400 334.0000 1.0000
59.2800 352.0000 1.0000
59.3200 321.0000 1.0000
59.3600 304.0000 1.0000
59.4000 314.0000 1.0000
59.4400 319.0000 1.0000
59.4800 334.0000 1.0000
59.5200 356.0000 1.0000
59.5600 314.0000 1.0000
59.6000 313.0000 1.0000
59.6400 331.0000 1.0000
59.6800 345.0000 1.0000
59.7200 355.0000 1.0000
59.7600 333.0000 1.0000
59.8000 332.0000 1.0000
59.8400 349.0000 1.0000
59.8800 317.0000 1.0000
59.9200 297.0000 1.0000
59.9600 355.0000 1.0000
60.0000 320.0000 1.0000
60.0400 324.0000 1.0000
60.0800 339.0000 1.0000
60.1200 302.0000 1.0000
60.1600 340.0000 1.0000
60.2000 323.0000 1.0000
60.2400 332.0000 1.0000
60.2800 315.0000 1.0000
60.3200 345.0000 1.0000
60.3600 330.0000 1.0000
60.4000 313.0000 1.0000
60.4400 316.0000 1.0000
60.4800 303.0000 1.0000
60.5200 328.0000 1.0000
60.5600 328.0000 1.0000
60.6000 302.0000 1.0000
60.6400 297.0000 1.0000
60.6800 330.0000 1.0000
60.7200 320.0000 1.0000
60.7600 356.0000 1.0000
60.8000 328.0000 1.0000
60.8400 356.0000 1.0000
60.8800 315.0000 1.0000
60.9200 303.0000 1.0000
60.9600 321.0000 1.0000
61.0000 328.0000 1.0000
61.0400 372.0000 1.0000
61.0800 349.0000 1.0000
61.1200 336.0000 1.0000
61.1600 328.0000 1.0000
61.2000 359.0000 1.0000
61.2400 370.0000 1.0000
61.2800 414.0000 1.0000
61.3200 396.0000 1.0000
61.3600 457.0000 1.0000
61.4000 508.0000 1.0000
61.4400 551.0000 1.0000
61.4800 599.0000 1.0000
61.5200 596.0000 1.0000
61.5600 600.0000 1.0000
61.6000 594.0000 1.0000
61.6400 600.0000 1.0000
61.6800 519.0000 1.0000
61.7200 504.0000 1.0000
61.7600 476.0000 1.0000
61.8000 464.0000 1.0000
61.8400 436.0000 1.0000
61.8800 418.0000 1.0000
61.9200 384.0000 1.0000
61.9600 380.0000 1.0000
62.0000 390.0000 1.0000
62.0400 376.0000 1.0000
62.0800 389.0000 1.0000
62.1200 355.0000 1.0000
62.1600 367.0000 1.0000
62.2000 364.0000 1.0000
62.2400 357.0000 1.0000
62.2800 386.0000 1.0000
62.3200 383.0000 1.0000
62.3600 374.0000 1.0000
62.4000 407.0000 1.0000
62.4400 375.0000 1.0000
62.4800 341.0000 1.0000
62.5200 356.0000 1.0000
62.5600 360.0000 1.0000
62.6000 328.0000 1.0000
62.6400 340.0000 1.0000
62.6800 346.0000 1.0000
62.7200 292.0000 1.0000
62.7600 313.0000 1.0000
62.8000 322.0000 1.0000
62.8400 317.0000 1.0000
62.8800 323.0000 1.0000
62.9200 317.0000 1.0000
62.9600 314.0000 1.0000
63.0000 310.0000 1.0000
63.0400 315.0000 1.0000
63.0800 349.0000 1.0000
63.1200 312.0000 1.0000
63.1600 346.0000 1.0000
63.2000 295.0000 1.0000
63.2400 324.0000 1.0000
63.2800 346.0000 1.0000
63.3200 324.0000 1.0000
63.3600 312.0000 1.0000
63.4000 310.0000 1.0000
63.4400 332.0000 1.0000
63.4800 318.0000 1.0000
63.5200 308.0000 1.0000
63.5600 322.0000 1.0000
63.6000 355.0000 1.0000
63.6400 340.0000 1.0000
63.6800 357.0000 1.0000
63.7200 349.0000 1.0000
63.7600 361.0000 1.0000
63.8000 411.0000 1.0000
63.8400 469.0000 1.0000
63.8800 521.0000 1.0000
63.9200 608.0000 1.0000
63.9600 616.0000 1.0000
64.0000 548.0000 1.0000
64.0400 512.0000 1.0000
64.0800 504.0000 1.0000
64.1200 505.0000 1.0000
64.1600 460.0000 1.0000
64.2000 384.0000 1.0000
64.2400 355.0000 1.0000
64.2800 392.0000 1.0000
64.3200 367.0000 1.0000
64.3600 342.0000 1.0000
64.4000 346.0000 1.0000
64.4400 337.0000 1.0000
64.4800 348.0000 1.0000
64.5200 343.0000 1.0000
64.5600 332.0000 1.0000
64.6000 381.0000 1.0000
64.6400 327.0000 1.0000
64.6800 331.0000 1.0000
64.7200 344.0000 1.0000
64.7600 320.0000 1.0000
64.8000 283.0000 1.0000
64.8400 338.0000 1.0000
64.8800 336.0000 1.0000
64.9200 338.0000 1.0000
64.9600 337.0000 1.0000
65.0000 355.0000 1.0000
65.0400 385.0000 1.0000
65.0800 366.0000 1.0000
65.1200 370.0000 1.0000
65.1600 340.0000 1.0000
65.2000 371.0000 1.0000
65.2400 437.0000 1.0000
65.2800 474.0000 1.0000
65.3200 497.0000 1.0000
65.3600 573.0000 1.0000
65.4000 709.0000 1.0000
65.4400 790.0000 1.0000
65.4800 872.0000 1.0000
65.5200 1025.0000 1.0000
65.5600 1015.0000 1.0000
65.6000 985.0000 1.0000
65.6400 956.0000 1.0000
65.6800 831.0000 1.0000
65.7200 806.0000 1.0000
65.7600 731.0000 1.0000
65.8000 671.0000 1.0000
65.8400 564.0000 1.0000
65.8800 494.0000 1.0000
65.9200 468.0000 1.0000
65.9600 439.0000 1.0000
66.0000 383.0000 1.0000
66.0400 362.0000 1.0000
66.0800 329.0000 1.0000
66.1200 360.0000 1.0000
66.1600 343.0000 1.0000
66.2000 308.0000 1.0000
66.2400 322.0000 1.0000
66.2800 347.0000 1.0000
66.3200 348.0000 1.0000
66.3600 298.0000 1.0000
66.4000 275.0000 1.0000
66.4400 311.0000 1.0000
66.4800 310.0000 1.0000
66.5200 321.0000 1.0000
66.5600 304.0000 1.0000
66.6000 273.0000 1.0000
66.6400 304.0000 1.0000
66.6800 325.0000 1.0000
66.7200 292.0000 1.0000
66.7600 293.0000 1.0000
66.8000 284.0000 1.0000
66.8400 296.0000 1.0000
66.8800 338.0000 1.0000
66.9200 315.0000 1.0000
66.9600 332.0000 1.0000
67.0000 245.0000 1.0000
67.0400 308.0000 1.0000
67.0800 302.0000 1.0000
67.1200 302.0000 1.0000
67.1600 308.0000 1.0000
67.2000 304.0000 1.0000
67.2400 298.0000 1.0000
67.2800 324.0000 1.0000
67.3200 311.0000 1.0000
67.3600 265.0000 1.0000
67.4000 294.0000 1.0000
67.4400 274.0000 1.0000
67.4800 329.0000 1.0000
67.5200 281.0000 1.0000
67.5600 301.0000 1.0000
67.6000 299.0000 1.0000
67.6400 286.0000 1.0000
67.6800 293.0000 1.0000
67.7200 282.0000 1.0000
67.7600 304.0000 1.0000
67.8000 285.0000 1.0000
67.8400 293.0000 1.0000
67.8800 300.0000 1.0000
67.9200 291.0000 1.0000
67.9600 306.0000 1.0000
68.0000 319.0000 1.0000
68.0400 297.0000 1.0000
68.0800 320.0000 1.0000
68.1200 274.0000 1.0000
68.1600 289.0000 1.0000
68.2000 281.0000 1.0000
68.2400 300.0000 1.0000
68.2800 275.0000 1.0000
68.3200 286.0000 1.0000
68.3600 285.0000 1.0000
68.4000 308.0000 1.0000
68.4400 263.0000 1.0000
68.4800 282.0000 1.0000
68.5200 311.0000 1.0000
68.5600 275.0000 1.0000
68.6000 300.0000 1.0000
68.6400 302.0000 1.0000
68.6800 303.0000 1.0000
68.7200 290.0000 1.0000
68.7600 288.0000 1.0000
68.8000 281.0000 1.0000
68.8400 275.0000 1.0000
68.8800 280.0000 1.0000
68.9200 264.0000 1.0000
68.9600 278.0000 1.0000
69.0000 298.0000 1.0000
69.0400 310.0000 1.0000
69.0800 293.0000 1.0000
69.1200 310.0000 1.0000
69.1600 281.0000 1.0000
69.2000 247.0000 1.0000
69.2400 274.0000 1.0000
69.2800 279.0000 1.0000
69.3200 300.0000 1.0000
69.3600 290.0000 1.0000
69.4000 271.0000 1.0000
69.4400 296.0000 1.0000
69.4800 276.0000 1.0000
69.5200 301.0000 1.0000
69.5600 287.0000 1.0000
69.6000 253.0000 1.0000
69.6400 283.0000 1.0000
69.6800 278.0000 1.0000
69.7200 284.0000 1.0000
69.7600 268.0000 1.0000
69.8000 276.0000 1.0000
69.8400 277.0000 1.0000
69.8800 285.0000 1.0000
69.9200 252.0000 1.0000
69.9600 306.0000 1.0000
70.0000 272.0000 1.0000
*RAS_INT_END
*RAS_TEMPERATURE_START
*RAS_TEMPERATURE_END
*RAS_DATA_END