File: Data/Dataset2_Water_Organic/4_XRD/No_25_FTO_Hematite_700_10.ras
*RAS_DATA_START
*RAS_HEADER_START
*DISP_FMT_X "%.2f"
*DISP_FMT_Y "%.0f"
*DISP_FULLSCALE "14715.0000000000"
*DISP_LINE_COLOR "255.0000000000"
*DISP_LINE_STYLE "0.0000000000"
*DISP_LINE_WIDTH "0.2500000000"
*DISP_NOTE "測定データ-1"
*DISP_OFFSET_Y "0.0000000000"
*DISP_PEAKSEARCH_UNIT_Y "cps"
*DISP_RANGE_BOTTOM "0.0000000000"
*DISP_RANGE_LEFT "20.0000000000"
*DISP_RANGE_LOGCUTOFF "0.0100000000"
*DISP_RANGE_RIGHT "70.0000000000"
*DISP_RANGE_TOP "14715.0000000000"
*DISP_SCALE_MODE_Y "0.0000000000"
*DISP_TAB_NAME "2θ/θ"
*DISP_TITLE_Y "強度"
*DISP_UNIT_Y "cps"
*DISP_WINDOW_NAME "MSG_MACROENGINE"
*FILE_COMMENT " "
*FILE_MD5 ""
*FILE_MEMO " "
*FILE_OPERATOR "Administrator"
*FILE_SAMPLE " "
*FILE_TYPE "RAS_RAW"
*FILE_USERGROUP "システムマネージャ"
*FILE_VERSION "1.0000000000"
*HW_ATTACHMENT_ID "ATT0025"
*HW_ATTACHMENT_NAME "標準|Standard"
*HW_COUNTER_ID-0 "CUT0025"
*HW_COUNTER_ID-1 "CUT0020"
*HW_COUNTER_ID-2 "CUT0020"
*HW_COUNTER_ID-3 "CSL0021"
*HW_COUNTER_ID-4 "CMC0021"
*HW_COUNTER_NAME-0 "D/teX Ultra|D/teX Ultra"
*HW_COUNTER_NAME-1 "None|None"
*HW_COUNTER_NAME-2 "None|None"
*HW_COUNTER_NAME-3 "BBM|BBM"
*HW_COUNTER_NAME-4 "検出器モノクロメータ|Detector monochromator"
*HW_COUNTER_SELECT_NAME "D/teX Ultra|D/teX Ultra"
*HW_GONIOMETER_ID "GON0023"
*HW_GONIOMETER_NAME "SmartLab|SmartLab"
*HW_GONIOMETER_RADIUS-0 "90.0"
*HW_GONIOMETER_RADIUS-1 "114.0"
*HW_GONIOMETER_RADIUS-2 "190.0"
*HW_GONIOMETER_RADIUS-3 "300.0"
*HW_GONIOMETER_RADIUS-4 "187.0"
*HW_GONIOMETER_RADIUS-5 "300.0"
*HW_GONIOMETER_RADIUS-6 "113.0"
*HW_GONIOMETER_RADIUS-7 "331.0"
*HW_I_OPT_ID-0 "CBO0021"
*HW_I_OPT_ID-1 "ICR0023"
*HW_I_OPT_ID-2 "ISL0021"
*HW_I_OPT_ID-3 "ISO0021"
*HW_I_OPT_ID-4 "IAD0021"
*HW_I_OPT_ID-5 "IPR0001"
*HW_I_OPT_NAME-0 "CBOユニット|CBO unit"
*HW_I_OPT_NAME-1 "標準入射光学ユニット|Standard incident optical unit"
*HW_I_OPT_NAME-2 "標準入射スリットボックス|Standard incident slit box"
*HW_I_OPT_NAME-3 "入射平行スリット|Incident parallel slit"
*HW_I_OPT_NAME-4 "長手制限スリット|Length limiting slit"
*HW_I_OPT_NAME-5 "None|None"
*HW_R_ATTENUATER_AUTOMODE "0"
*HW_R_OPT_ID-0 "RSS0021"
*HW_R_OPT_ID-1 "RCR0023"
*HW_R_OPT_ID-2 "RSO0021"
*HW_R_OPT_ID-3 "RRS0021"
*HW_R_OPT_ID-4 "ATN0021"
*HW_R_OPT_ID-5 "RFL0021"
*HW_R_OPT_ID-6 "RAD0021"
*HW_R_OPT_NAME-0 "標準受光スリットボックス1|Standard receiving slit box # 1"
*HW_R_OPT_NAME-1 "標準受光光学ユニット1|Standard receiving unit # 1"
*HW_R_OPT_NAME-2 "標準受光光学ユニット2|Standard receiving optical unit # 2"
*HW_R_OPT_NAME-3 "標準受光スリットボックス2|Standard receiving slit box # 2"
*HW_R_OPT_NAME-4 "標準アッテネータ|Standard Attenuator"
*HW_R_OPT_NAME-5 "Cu Kβ|Cu K-beta"
*HW_R_OPT_NAME-6 "調整用受光スリット|Alignment receiving slit"
*HW_SAMPLE_HOLDER_ID "SMP0023"
*HW_SAMPLE_HOLDER_NAME "標準Zステージ|Standard Z stage"
*HW_XG_CURRENT_MAX "50"
*HW_XG_CURRENT_MIN "2"
*HW_XG_CURRENT_RESOLUTION "1"
*HW_XG_CURRENT_UNIT "mA"
*HW_XG_FOCUS "1mm x 10mm"
*HW_XG_FOCUS_TYPE "Normal"
*HW_XG_ID ""
*HW_XG_NAME "3kW 封入管(ID:1200)|3kW Sealed tube(ID:1200)"
*HW_XG_TARGET_ATOMIC_NUMBER "29.0000000000"
*HW_XG_TARGET_NAME "Cu"
*HW_XG_TYPE "Hermetic"
*HW_XG_VOLTAGE_MAX "60"
*HW_XG_VOLTAGE_MIN "20"
*HW_XG_VOLTAGE_RESOLUTION "1"
*HW_XG_VOLTAGE_UNIT "kV"
*HW_XG_WATT_MAX "1.500"
*HW_XG_WATT_UNIT "kW"
*HW_XG_WAVE_LENGTH_ALPHA1 "1.540593"
*HW_XG_WAVE_LENGTH_ALPHA2 "1.544414"
*HW_XG_WAVE_LENGTH_BETA "1.392250"
*MEAS_COND_AXIS_NAME-0 "2θ/θ"
*MEAS_COND_AXIS_NAME-1 "2θ"
*MEAS_COND_AXIS_NAME-2 "ω"
*MEAS_COND_AXIS_NAME-3 "Z"
*MEAS_COND_AXIS_NAME-4 "2θ/ω"
*MEAS_COND_AXIS_NAME-5 "θs"
*MEAS_COND_AXIS_NAME-6 "θd"
*MEAS_COND_AXIS_NAME-7 "Ts"
*MEAS_COND_AXIS_NAME-8 "CBO選択スリット"
*MEAS_COND_AXIS_NAME-9 "M"
*MEAS_COND_AXIS_NAME-10 "入射平行スリット"
*MEAS_COND_AXIS_NAME-11 "入射スリット"
*MEAS_COND_AXIS_NAME-12 ""
*MEAS_COND_AXIS_NAME-13 "Zs"
*MEAS_COND_AXIS_NAME-14 "入射光学素子"
*MEAS_COND_AXIS_NAME-15 "長手制限スリット"
*MEAS_COND_AXIS_NAME-16 "センタースリット"
*MEAS_COND_AXIS_NAME-17 "フィルター"
*MEAS_COND_AXIS_NAME-18 "受光スリット1"
*MEAS_COND_AXIS_NAME-19 "受光スリット2"
*MEAS_COND_AXIS_NAME-20 "受光光学素子"
*MEAS_COND_AXIS_NAME-21 "受光平行スリット"
*MEAS_COND_AXIS_NAME-22 "調整用受光スリット"
*MEAS_COND_AXIS_NAME-23 ""
*MEAS_COND_AXIS_NAME-24 ""
*MEAS_COND_AXIS_NAME-25 "Zd"
*MEAS_COND_AXIS_NAME-26 "アッテネータ"
*MEAS_COND_AXIS_NAME-27 "検出器モノクロメータ"
*MEAS_COND_AXIS_NAME-28 "モノクロメータスリット"
*MEAS_COND_AXIS_NAME-29 "プライマリビーム"
*MEAS_COND_AXIS_NAME-30 "PHA"
*MEAS_COND_AXIS_NAME_INTERNAL-0 "TwoThetaTheta"
*MEAS_COND_AXIS_NAME_INTERNAL-1 "TwoTheta"
*MEAS_COND_AXIS_NAME_INTERNAL-2 "Omega"
*MEAS_COND_AXIS_NAME_INTERNAL-3 "Z"
*MEAS_COND_AXIS_NAME_INTERNAL-4 "TwoThetaOmega"
*MEAS_COND_AXIS_NAME_INTERNAL-5 "ThetaS"
*MEAS_COND_AXIS_NAME_INTERNAL-6 "ThetaD"
*MEAS_COND_AXIS_NAME_INTERNAL-7 "Ts"
*MEAS_COND_AXIS_NAME_INTERNAL-8 "CBO"
*MEAS_COND_AXIS_NAME_INTERNAL-9 "CBO-M"
*MEAS_COND_AXIS_NAME_INTERNAL-10 "IncidentSollerSlit"
*MEAS_COND_AXIS_NAME_INTERNAL-11 "IncidentSlitBox"
*MEAS_COND_AXIS_NAME_INTERNAL-12 "IncidentSlitBox-_Axis"
*MEAS_COND_AXIS_NAME_INTERNAL-13 "Zs"
*MEAS_COND_AXIS_NAME_INTERNAL-14 "IncidentMonochromator"
*MEAS_COND_AXIS_NAME_INTERNAL-15 "IncidentAxdSlit"
*MEAS_COND_AXIS_NAME_INTERNAL-16 "CenterSlit"
*MEAS_COND_AXIS_NAME_INTERNAL-17 "Filter"
*MEAS_COND_AXIS_NAME_INTERNAL-18 "ReceivingSlitBox1"
*MEAS_COND_AXIS_NAME_INTERNAL-19 "ReceivingSlitBox2"
*MEAS_COND_AXIS_NAME_INTERNAL-20 "ReceivingOptics"
*MEAS_COND_AXIS_NAME_INTERNAL-21 "ReceivingSollerSlit"
*MEAS_COND_AXIS_NAME_INTERNAL-22 "ReceivingAxdSlit"
*MEAS_COND_AXIS_NAME_INTERNAL-23 "ReceivingSlitBox1-_Axis"
*MEAS_COND_AXIS_NAME_INTERNAL-24 "ReceivingSlitBox2-_Axis"
*MEAS_COND_AXIS_NAME_INTERNAL-25 "ReceivingSlitBox2-Zd"
*MEAS_COND_AXIS_NAME_INTERNAL-26 "Attenuator"
*MEAS_COND_AXIS_NAME_INTERNAL-27 "CounterMonochromator"
*MEAS_COND_AXIS_NAME_INTERNAL-28 "CounterSlit"
*MEAS_COND_AXIS_NAME_INTERNAL-29 "IncidentPrimary"
*MEAS_COND_AXIS_NAME_INTERNAL-30 "PHA"
*MEAS_COND_AXIS_NAME_MAGICNO-0 "83951616.0000000000"
*MEAS_COND_AXIS_NAME_MAGICNO-1 "268632064.0000000000"
*MEAS_COND_AXIS_NAME_MAGICNO-2 "268500992.0000000000"
*MEAS_COND_AXIS_NAME_MAGICNO-3 "285278208.0000000000"
*MEAS_COND_AXIS_NAME_MAGICNO-4 "83951616.0000000000"
*MEAS_COND_AXIS_NAME_MAGICNO-5 "131072.0000000000"
*MEAS_COND_AXIS_NAME_MAGICNO-6 "131072.0000000000"
*MEAS_COND_AXIS_NAME_MAGICNO-7 "318898176.0000000000"
*MEAS_COND_AXIS_NAME_MAGICNO-8 "20971521.0000000000"
*MEAS_COND_AXIS_NAME_MAGICNO-9 "285343744.0000000000"
*MEAS_COND_AXIS_NAME_MAGICNO-10 "20971521.0000000000"
*MEAS_COND_AXIS_NAME_MAGICNO-11 "22020097.0000000000"
*MEAS_COND_AXIS_NAME_MAGICNO-12 "25165824.0000000000"
*MEAS_COND_AXIS_NAME_MAGICNO-13 "318898176.0000000000"
*MEAS_COND_AXIS_NAME_MAGICNO-14 "1.0000000000"
*MEAS_COND_AXIS_NAME_MAGICNO-15 "20971521.0000000000"
*MEAS_COND_AXIS_NAME_MAGICNO-16 "20971521.0000000000"
*MEAS_COND_AXIS_NAME_MAGICNO-17 "20971521.0000000000"
*MEAS_COND_AXIS_NAME_MAGICNO-18 "23068673.0000000000"
*MEAS_COND_AXIS_NAME_MAGICNO-19 "23068673.0000000000"
*MEAS_COND_AXIS_NAME_MAGICNO-20 "20971521.0000000000"
*MEAS_COND_AXIS_NAME_MAGICNO-21 "20971521.0000000000"
*MEAS_COND_AXIS_NAME_MAGICNO-22 "20971521.0000000000"
*MEAS_COND_AXIS_NAME_MAGICNO-23 "25165824.0000000000"
*MEAS_COND_AXIS_NAME_MAGICNO-24 "25165824.0000000000"
*MEAS_COND_AXIS_NAME_MAGICNO-25 "285343744.0000000000"
*MEAS_COND_AXIS_NAME_MAGICNO-26 "17301505.0000000000"
*MEAS_COND_AXIS_NAME_MAGICNO-27 "20971521.0000000000"
*MEAS_COND_AXIS_NAME_MAGICNO-28 "20971521.0000000000"
*MEAS_COND_AXIS_NAME_MAGICNO-29 "20971521.0000000000"
*MEAS_COND_AXIS_NAME_MAGICNO-30 "0.0000000000"
*MEAS_COND_AXIS_OFFSET-0 "-"
*MEAS_COND_AXIS_OFFSET-1 "-0.0310000000"
*MEAS_COND_AXIS_OFFSET-2 "0.2529000000"
*MEAS_COND_AXIS_OFFSET-3 "-"
*MEAS_COND_AXIS_OFFSET-4 "-"
*MEAS_COND_AXIS_OFFSET-5 "0.2529000000"
*MEAS_COND_AXIS_OFFSET-6 "-0.2839000000"
*MEAS_COND_AXIS_OFFSET-7 "-"
*MEAS_COND_AXIS_OFFSET-8 "-"
*MEAS_COND_AXIS_OFFSET-9 "-"
*MEAS_COND_AXIS_OFFSET-10 "-"
*MEAS_COND_AXIS_OFFSET-11 "-"
*MEAS_COND_AXIS_OFFSET-12 "-"
*MEAS_COND_AXIS_OFFSET-13 "-"
*MEAS_COND_AXIS_OFFSET-14 "-"
*MEAS_COND_AXIS_OFFSET-15 "-"
*MEAS_COND_AXIS_OFFSET-16 "-"
*MEAS_COND_AXIS_OFFSET-17 "-"
*MEAS_COND_AXIS_OFFSET-18 "-"
*MEAS_COND_AXIS_OFFSET-19 "-"
*MEAS_COND_AXIS_OFFSET-20 "-"
*MEAS_COND_AXIS_OFFSET-21 "-"
*MEAS_COND_AXIS_OFFSET-22 "-"
*MEAS_COND_AXIS_OFFSET-23 "-"
*MEAS_COND_AXIS_OFFSET-24 "-"
*MEAS_COND_AXIS_OFFSET-25 "-"
*MEAS_COND_AXIS_OFFSET-26 "-"
*MEAS_COND_AXIS_OFFSET-27 "-"
*MEAS_COND_AXIS_OFFSET-28 "-"
*MEAS_COND_AXIS_OFFSET-29 "-"
*MEAS_COND_AXIS_OFFSET-30 "-"
*MEAS_COND_AXIS_POSITION-0 "0.0000000000"
*MEAS_COND_AXIS_POSITION-1 "0.0000000000"
*MEAS_COND_AXIS_POSITION-2 "0.0000000000"
*MEAS_COND_AXIS_POSITION-3 "-2.8813000000"
*MEAS_COND_AXIS_POSITION-4 "0.0000000000"
*MEAS_COND_AXIS_POSITION-5 "0.0000000000"
*MEAS_COND_AXIS_POSITION-6 "0.0000000000"
*MEAS_COND_AXIS_POSITION-7 "-0.7498700000"
*MEAS_COND_AXIS_POSITION-8 "BB"
*MEAS_COND_AXIS_POSITION-9 "0.0000000000"
*MEAS_COND_AXIS_POSITION-10 "Soller_slit_5.0deg"
*MEAS_COND_AXIS_POSITION-11 "2/3deg"
*MEAS_COND_AXIS_POSITION-12 "2.2088000000"
*MEAS_COND_AXIS_POSITION-13 "-0.6412500000"
*MEAS_COND_AXIS_POSITION-14 "0.0000000000"
*MEAS_COND_AXIS_POSITION-15 "10.0mm"
*MEAS_COND_AXIS_POSITION-16 "None"
*MEAS_COND_AXIS_POSITION-17 "Cu_K-beta"
*MEAS_COND_AXIS_POSITION-18 "13.000mm"
*MEAS_COND_AXIS_POSITION-19 "13.000mm"
*MEAS_COND_AXIS_POSITION-20 "No_unit"
*MEAS_COND_AXIS_POSITION-21 "Soller_slit_5.0deg"
*MEAS_COND_AXIS_POSITION-22 "None"
*MEAS_COND_AXIS_POSITION-23 "13.0000000000"
*MEAS_COND_AXIS_POSITION-24 "13.0000000000"
*MEAS_COND_AXIS_POSITION-25 "0.0281300000"
*MEAS_COND_AXIS_POSITION-26 "Open"
*MEAS_COND_AXIS_POSITION-27 "None"
*MEAS_COND_AXIS_POSITION-28 "None"
*MEAS_COND_AXIS_POSITION-29 "None"
*MEAS_COND_AXIS_POSITION-30 "38.0000000000"
*MEAS_COND_AXIS_UNIT-0 "deg"
*MEAS_COND_AXIS_UNIT-1 "deg"
*MEAS_COND_AXIS_UNIT-2 "deg"
*MEAS_COND_AXIS_UNIT-3 "mm"
*MEAS_COND_AXIS_UNIT-4 "deg"
*MEAS_COND_AXIS_UNIT-5 "deg"
*MEAS_COND_AXIS_UNIT-6 "deg"
*MEAS_COND_AXIS_UNIT-7 "mm"
*MEAS_COND_AXIS_UNIT-8 ""
*MEAS_COND_AXIS_UNIT-9 "pulse"
*MEAS_COND_AXIS_UNIT-10 ""
*MEAS_COND_AXIS_UNIT-11 ""
*MEAS_COND_AXIS_UNIT-12 "mm"
*MEAS_COND_AXIS_UNIT-13 "mm"
*MEAS_COND_AXIS_UNIT-14 ""
*MEAS_COND_AXIS_UNIT-15 ""
*MEAS_COND_AXIS_UNIT-16 ""
*MEAS_COND_AXIS_UNIT-17 ""
*MEAS_COND_AXIS_UNIT-18 ""
*MEAS_COND_AXIS_UNIT-19 ""
*MEAS_COND_AXIS_UNIT-20 ""
*MEAS_COND_AXIS_UNIT-21 ""
*MEAS_COND_AXIS_UNIT-22 ""
*MEAS_COND_AXIS_UNIT-23 "mm"
*MEAS_COND_AXIS_UNIT-24 "mm"
*MEAS_COND_AXIS_UNIT-25 "mm"
*MEAS_COND_AXIS_UNIT-26 ""
*MEAS_COND_AXIS_UNIT-27 ""
*MEAS_COND_AXIS_UNIT-28 ""
*MEAS_COND_AXIS_UNIT-29 ""
*MEAS_COND_AXIS_UNIT-30 "div"
*MEAS_COND_COUNTER_CNTLOSS_CORR "0.0000000000"
*MEAS_COND_COUNTER_PHABASE "38.0000000000"
*MEAS_COND_COUNTER_PHAWINDOW "16.0000000000"
*MEAS_COND_COUNTER_PHA_UNIT "div"
*MEAS_COND_COUNTER_TAUDIFF "30.0000000000"
*MEAS_COND_COUNTER_TAUINT "0.0000000000"
*MEAS_COND_IRRADIATION_MODE "OFF"
*MEAS_COND_IRRADIATION_WIDTH ""
*MEAS_COND_OPT_ATTR "集中法"
*MEAS_COND_OPT_NAME "@集中法"
*MEAS_COND_UNSYMMETRIC_MODE "OFF"
*MEAS_COND_XG_CURRENT "30.0000000000"
*MEAS_COND_XG_VOLTAGE "40.0000000000"
*MEAS_COND_XG_WAVE_TYPE "Ka"
*MEAS_DATA_COUNT "5001.0000000000"
*MEAS_SCAN_AXIS_X "2θ/θ"
*MEAS_SCAN_AXIS_X_INTERNAL "TwoThetaTheta"
*MEAS_SCAN_END_TIME "12/22/22 12:39:59"
*MEAS_SCAN_MODE "CONTINUOUS"
*MEAS_SCAN_MONITOR "0"
*MEAS_SCAN_RESOLUTION_X "0.0002"
*MEAS_SCAN_SPEED "2.5"
*MEAS_SCAN_SPEED_UNIT "deg/min"
*MEAS_SCAN_START "20.0000000000"
*MEAS_SCAN_START_TIME "12/22/22 12:18:35"
*MEAS_SCAN_STEP "0.0100000000"
*MEAS_SCAN_STOP "70.0000000000"
*MEAS_SCAN_UNIT_X "deg"
*MEAS_SCAN_UNIT_Y "counts"
*RAS_HEADER_END
*RAS_INT_START
20.0000 904.0000 1.0000
20.0400 845.0000 1.0000
20.0800 888.0000 1.0000
20.1200 851.0000 1.0000
20.1600 873.0000 1.0000
20.2000 814.0000 1.0000
20.2400 872.0000 1.0000
20.2800 850.0000 1.0000
20.3200 864.0000 1.0000
20.3600 849.0000 1.0000
20.4000 833.0000 1.0000
20.4400 877.0000 1.0000
20.4800 852.0000 1.0000
20.5200 850.0000 1.0000
20.5600 854.0000 1.0000
20.6000 893.0000 1.0000
20.6400 835.0000 1.0000
20.6800 871.0000 1.0000
20.7200 863.0000 1.0000
20.7600 782.0000 1.0000
20.8000 913.0000 1.0000
20.8400 818.0000 1.0000
20.8800 873.0000 1.0000
20.9200 865.0000 1.0000
20.9600 809.0000 1.0000
21.0000 850.0000 1.0000
21.0400 848.0000 1.0000
21.0800 804.0000 1.0000
21.1200 851.0000 1.0000
21.1600 873.0000 1.0000
21.2000 843.0000 1.0000
21.2400 850.0000 1.0000
21.2800 842.0000 1.0000
21.3200 853.0000 1.0000
21.3600 863.0000 1.0000
21.4000 848.0000 1.0000
21.4400 812.0000 1.0000
21.4800 835.0000 1.0000
21.5200 838.0000 1.0000
21.5600 814.0000 1.0000
21.6000 833.0000 1.0000
21.6400 853.0000 1.0000
21.6800 837.0000 1.0000
21.7200 827.0000 1.0000
21.7600 826.0000 1.0000
21.8000 868.0000 1.0000
21.8400 795.0000 1.0000
21.8800 818.0000 1.0000
21.9200 872.0000 1.0000
21.9600 865.0000 1.0000
22.0000 820.0000 1.0000
22.0400 862.0000 1.0000
22.0800 784.0000 1.0000
22.1200 821.0000 1.0000
22.1600 847.0000 1.0000
22.2000 800.0000 1.0000
22.2400 843.0000 1.0000
22.2800 847.0000 1.0000
22.3200 827.0000 1.0000
22.3600 877.0000 1.0000
22.4000 810.0000 1.0000
22.4400 805.0000 1.0000
22.4800 790.0000 1.0000
22.5200 765.0000 1.0000
22.5600 851.0000 1.0000
22.6000 798.0000 1.0000
22.6400 834.0000 1.0000
22.6800 806.0000 1.0000
22.7200 825.0000 1.0000
22.7600 833.0000 1.0000
22.8000 811.0000 1.0000
22.8400 839.0000 1.0000
22.8800 773.0000 1.0000
22.9200 757.0000 1.0000
22.9600 792.0000 1.0000
23.0000 814.0000 1.0000
23.0400 810.0000 1.0000
23.0800 852.0000 1.0000
23.1200 790.0000 1.0000
23.1600 778.0000 1.0000
23.2000 743.0000 1.0000
23.2400 782.0000 1.0000
23.2800 813.0000 1.0000
23.3200 788.0000 1.0000
23.3600 766.0000 1.0000
23.4000 822.0000 1.0000
23.4400 841.0000 1.0000
23.4800 760.0000 1.0000
23.5200 821.0000 1.0000
23.5600 827.0000 1.0000
23.6000 822.0000 1.0000
23.6400 820.0000 1.0000
23.6800 795.0000 1.0000
23.7200 850.0000 1.0000
23.7600 780.0000 1.0000
23.8000 813.0000 1.0000
23.8400 819.0000 1.0000
23.8800 786.0000 1.0000
23.9200 809.0000 1.0000
23.9600 833.0000 1.0000
24.0000 851.0000 1.0000
24.0400 838.0000 1.0000
24.0800 858.0000 1.0000
24.1200 845.0000 1.0000
24.1600 818.0000 1.0000
24.2000 839.0000 1.0000
24.2400 848.0000 1.0000
24.2800 830.0000 1.0000
24.3200 794.0000 1.0000
24.3600 886.0000 1.0000
24.4000 796.0000 1.0000
24.4400 814.0000 1.0000
24.4800 827.0000 1.0000
24.5200 810.0000 1.0000
24.5600 818.0000 1.0000
24.6000 799.0000 1.0000
24.6400 772.0000 1.0000
24.6800 784.0000 1.0000
24.7200 775.0000 1.0000
24.7600 763.0000 1.0000
24.8000 787.0000 1.0000
24.8400 781.0000 1.0000
24.8800 824.0000 1.0000
24.9200 789.0000 1.0000
24.9600 763.0000 1.0000
25.0000 821.0000 1.0000
25.0400 817.0000 1.0000
25.0800 765.0000 1.0000
25.1200 769.0000 1.0000
25.1600 795.0000 1.0000
25.2000 806.0000 1.0000
25.2400 804.0000 1.0000
25.2800 806.0000 1.0000
25.3200 734.0000 1.0000
25.3600 830.0000 1.0000
25.4000 775.0000 1.0000
25.4400 781.0000 1.0000
25.4800 790.0000 1.0000
25.5200 784.0000 1.0000
25.5600 813.0000 1.0000
25.6000 765.0000 1.0000
25.6400 795.0000 1.0000
25.6800 836.0000 1.0000
25.7200 846.0000 1.0000
25.7600 834.0000 1.0000
25.8000 798.0000 1.0000
25.8400 802.0000 1.0000
25.8800 859.0000 1.0000
25.9200 815.0000 1.0000
25.9600 845.0000 1.0000
26.0000 854.0000 1.0000
26.0400 902.0000 1.0000
26.0800 907.0000 1.0000
26.1200 961.0000 1.0000
26.1600 1003.0000 1.0000
26.2000 1083.0000 1.0000
26.2400 1243.0000 1.0000
26.2800 1412.0000 1.0000
26.3200 1655.0000 1.0000
26.3600 2112.0000 1.0000
26.4000 2535.0000 1.0000
26.4400 2820.0000 1.0000
26.4800 2817.0000 1.0000
26.5200 2399.0000 1.0000
26.5600 1914.0000 1.0000
26.6000 1519.0000 1.0000
26.6400 1405.0000 1.0000
26.6800 1160.0000 1.0000
26.7200 993.0000 1.0000
26.7600 945.0000 1.0000
26.8000 905.0000 1.0000
26.8400 833.0000 1.0000
26.8800 868.0000 1.0000
26.9200 852.0000 1.0000
26.9600 814.0000 1.0000
27.0000 719.0000 1.0000
27.0400 802.0000 1.0000
27.0800 764.0000 1.0000
27.1200 746.0000 1.0000
27.1600 790.0000 1.0000
27.2000 811.0000 1.0000
27.2400 725.0000 1.0000
27.2800 739.0000 1.0000
27.3200 760.0000 1.0000
27.3600 752.0000 1.0000
27.4000 747.0000 1.0000
27.4400 737.0000 1.0000
27.4800 741.0000 1.0000
27.5200 727.0000 1.0000
27.5600 712.0000 1.0000
27.6000 750.0000 1.0000
27.6400 703.0000 1.0000
27.6800 748.0000 1.0000
27.7200 695.0000 1.0000
27.7600 679.0000 1.0000
27.8000 720.0000 1.0000
27.8400 737.0000 1.0000
27.8800 717.0000 1.0000
27.9200 692.0000 1.0000
27.9600 682.0000 1.0000
28.0000 704.0000 1.0000
28.0400 711.0000 1.0000
28.0800 724.0000 1.0000
28.1200 680.0000 1.0000
28.1600 690.0000 1.0000
28.2000 700.0000 1.0000
28.2400 702.0000 1.0000
28.2800 710.0000 1.0000
28.3200 728.0000 1.0000
28.3600 672.0000 1.0000
28.4000 686.0000 1.0000
28.4400 676.0000 1.0000
28.4800 662.0000 1.0000
28.5200 648.0000 1.0000
28.5600 695.0000 1.0000
28.6000 731.0000 1.0000
28.6400 706.0000 1.0000
28.6800 744.0000 1.0000
28.7200 649.0000 1.0000
28.7600 672.0000 1.0000
28.8000 663.0000 1.0000
28.8400 686.0000 1.0000
28.8800 607.0000 1.0000
28.9200 654.0000 1.0000
28.9600 632.0000 1.0000
29.0000 676.0000 1.0000
29.0400 672.0000 1.0000
29.0800 700.0000 1.0000
29.1200 685.0000 1.0000
29.1600 634.0000 1.0000
29.2000 693.0000 1.0000
29.2400 660.0000 1.0000
29.2800 677.0000 1.0000
29.3200 626.0000 1.0000
29.3600 687.0000 1.0000
29.4000 657.0000 1.0000
29.4400 638.0000 1.0000
29.4800 619.0000 1.0000
29.5200 675.0000 1.0000
29.5600 666.0000 1.0000
29.6000 639.0000 1.0000
29.6400 651.0000 1.0000
29.6800 691.0000 1.0000
29.7200 626.0000 1.0000
29.7600 661.0000 1.0000
29.8000 656.0000 1.0000
29.8400 617.0000 1.0000
29.8800 670.0000 1.0000
29.9200 661.0000 1.0000
29.9600 658.0000 1.0000
30.0000 650.0000 1.0000
30.0400 683.0000 1.0000
30.0800 636.0000 1.0000
30.1200 633.0000 1.0000
30.1600 631.0000 1.0000
30.2000 651.0000 1.0000
30.2400 650.0000 1.0000
30.2800 665.0000 1.0000
30.3200 627.0000 1.0000
30.3600 640.0000 1.0000
30.4000 619.0000 1.0000
30.4400 585.0000 1.0000
30.4800 623.0000 1.0000
30.5200 616.0000 1.0000
30.5600 592.0000 1.0000
30.6000 577.0000 1.0000
30.6400 631.0000 1.0000
30.6800 617.0000 1.0000
30.7200 569.0000 1.0000
30.7600 630.0000 1.0000
30.8000 613.0000 1.0000
30.8400 616.0000 1.0000
30.8800 611.0000 1.0000
30.9200 611.0000 1.0000
30.9600 560.0000 1.0000
31.0000 602.0000 1.0000
31.0400 632.0000 1.0000
31.0800 642.0000 1.0000
31.1200 553.0000 1.0000
31.1600 622.0000 1.0000
31.2000 629.0000 1.0000
31.2400 629.0000 1.0000
31.2800 593.0000 1.0000
31.3200 610.0000 1.0000
31.3600 576.0000 1.0000
31.4000 612.0000 1.0000
31.4400 616.0000 1.0000
31.4800 604.0000 1.0000
31.5200 609.0000 1.0000
31.5600 635.0000 1.0000
31.6000 593.0000 1.0000
31.6400 605.0000 1.0000
31.6800 614.0000 1.0000
31.7200 571.0000 1.0000
31.7600 622.0000 1.0000
31.8000 592.0000 1.0000
31.8400 583.0000 1.0000
31.8800 633.0000 1.0000
31.9200 589.0000 1.0000
31.9600 553.0000 1.0000
32.0000 599.0000 1.0000
32.0400 564.0000 1.0000
32.0800 562.0000 1.0000
32.1200 567.0000 1.0000
32.1600 576.0000 1.0000
32.2000 561.0000 1.0000
32.2400 571.0000 1.0000
32.2800 554.0000 1.0000
32.3200 506.0000 1.0000
32.3600 522.0000 1.0000
32.4000 565.0000 1.0000
32.4400 567.0000 1.0000
32.4800 593.0000 1.0000
32.5200 581.0000 1.0000
32.5600 532.0000 1.0000
32.6000 561.0000 1.0000
32.6400 556.0000 1.0000
32.6800 583.0000 1.0000
32.7200 582.0000 1.0000
32.7600 575.0000 1.0000
32.8000 556.0000 1.0000
32.8400 565.0000 1.0000
32.8800 571.0000 1.0000
32.9200 578.0000 1.0000
32.9600 553.0000 1.0000
33.0000 610.0000 1.0000
33.0400 610.0000 1.0000
33.0800 652.0000 1.0000
33.1200 682.0000 1.0000
33.1600 667.0000 1.0000
33.2000 631.0000 1.0000
33.2400 628.0000 1.0000
33.2800 567.0000 1.0000
33.3200 640.0000 1.0000
33.3600 695.0000 1.0000
33.4000 684.0000 1.0000
33.4400 711.0000 1.0000
33.4800 775.0000 1.0000
33.5200 903.0000 1.0000
33.5600 1035.0000 1.0000
33.6000 1260.0000 1.0000
33.6400 1477.0000 1.0000
33.6800 1481.0000 1.0000
33.7200 1325.0000 1.0000
33.7600 1181.0000 1.0000
33.8000 1003.0000 1.0000
33.8400 821.0000 1.0000
33.8800 765.0000 1.0000
33.9200 697.0000 1.0000
33.9600 663.0000 1.0000
34.0000 607.0000 1.0000
34.0400 610.0000 1.0000
34.0800 592.0000 1.0000
34.1200 555.0000 1.0000
34.1600 546.0000 1.0000
34.2000 559.0000 1.0000
34.2400 555.0000 1.0000
34.2800 581.0000 1.0000
34.3200 521.0000 1.0000
34.3600 524.0000 1.0000
34.4000 489.0000 1.0000
34.4400 504.0000 1.0000
34.4800 514.0000 1.0000
34.5200 465.0000 1.0000
34.5600 513.0000 1.0000
34.6000 538.0000 1.0000
34.6400 526.0000 1.0000
34.6800 484.0000 1.0000
34.7200 540.0000 1.0000
34.7600 473.0000 1.0000
34.8000 491.0000 1.0000
34.8400 531.0000 1.0000
34.8800 492.0000 1.0000
34.9200 497.0000 1.0000
34.9600 489.0000 1.0000
35.0000 485.0000 1.0000
35.0400 489.0000 1.0000
35.0800 514.0000 1.0000
35.1200 460.0000 1.0000
35.1600 493.0000 1.0000
35.2000 478.0000 1.0000
35.2400 457.0000 1.0000
35.2800 521.0000 1.0000
35.3200 498.0000 1.0000
35.3600 476.0000 1.0000
35.4000 614.0000 1.0000
35.4400 597.0000 1.0000
35.4800 635.0000 1.0000
35.5200 751.0000 1.0000
35.5600 848.0000 1.0000
35.6000 865.0000 1.0000
35.6400 793.0000 1.0000
35.6800 738.0000 1.0000
35.7200 621.0000 1.0000
35.7600 536.0000 1.0000
35.8000 505.0000 1.0000
35.8400 501.0000 1.0000
35.8800 463.0000 1.0000
35.9200 480.0000 1.0000
35.9600 462.0000 1.0000
36.0000 444.0000 1.0000
36.0400 476.0000 1.0000
36.0800 458.0000 1.0000
36.1200 453.0000 1.0000
36.1600 481.0000 1.0000
36.2000 471.0000 1.0000
36.2400 442.0000 1.0000
36.2800 464.0000 1.0000
36.3200 439.0000 1.0000
36.3600 465.0000 1.0000
36.4000 488.0000 1.0000
36.4400 472.0000 1.0000
36.4800 456.0000 1.0000
36.5200 460.0000 1.0000
36.5600 452.0000 1.0000
36.6000 459.0000 1.0000
36.6400 410.0000 1.0000
36.6800 416.0000 1.0000
36.7200 467.0000 1.0000
36.7600 441.0000 1.0000
36.8000 432.0000 1.0000
36.8400 438.0000 1.0000
36.8800 424.0000 1.0000
36.9200 443.0000 1.0000
36.9600 436.0000 1.0000
37.0000 441.0000 1.0000
37.0400 464.0000 1.0000
37.0800 452.0000 1.0000
37.1200 448.0000 1.0000
37.1600 498.0000 1.0000
37.2000 468.0000 1.0000
37.2400 450.0000 1.0000
37.2800 507.0000 1.0000
37.3200 521.0000 1.0000
37.3600 576.0000 1.0000
37.4000 629.0000 1.0000
37.4400 674.0000 1.0000
37.4800 784.0000 1.0000
37.5200 874.0000 1.0000
37.5600 1115.0000 1.0000
37.6000 1465.0000 1.0000
37.6400 1830.0000 1.0000
37.6800 2158.0000 1.0000
37.7200 2246.0000 1.0000
37.7600 2203.0000 1.0000
37.8000 1875.0000 1.0000
37.8400 1610.0000 1.0000
37.8800 1212.0000 1.0000
37.9200 928.0000 1.0000
37.9600 735.0000 1.0000
38.0000 653.0000 1.0000
38.0400 545.0000 1.0000
38.0800 544.0000 1.0000
38.1200 501.0000 1.0000
38.1600 457.0000 1.0000
38.2000 443.0000 1.0000
38.2400 448.0000 1.0000
38.2800 427.0000 1.0000
38.3200 416.0000 1.0000
38.3600 445.0000 1.0000
38.4000 422.0000 1.0000
38.4400 416.0000 1.0000
38.4800 422.0000 1.0000
38.5200 401.0000 1.0000
38.5600 385.0000 1.0000
38.6000 388.0000 1.0000
38.6400 424.0000 1.0000
38.6800 435.0000 1.0000
38.7200 417.0000 1.0000
38.7600 430.0000 1.0000
38.8000 410.0000 1.0000
38.8400 399.0000 1.0000
38.8800 405.0000 1.0000
38.9200 416.0000 1.0000
38.9600 433.0000 1.0000
39.0000 422.0000 1.0000
39.0400 398.0000 1.0000
39.0800 423.0000 1.0000
39.1200 418.0000 1.0000
39.1600 401.0000 1.0000
39.2000 365.0000 1.0000
39.2400 390.0000 1.0000
39.2800 380.0000 1.0000
39.3200 404.0000 1.0000
39.3600 386.0000 1.0000
39.4000 391.0000 1.0000
39.4400 363.0000 1.0000
39.4800 352.0000 1.0000
39.5200 380.0000 1.0000
39.5600 356.0000 1.0000
39.6000 406.0000 1.0000
39.6400 380.0000 1.0000
39.6800 372.0000 1.0000
39.7200 377.0000 1.0000
39.7600 359.0000 1.0000
39.8000 378.0000 1.0000
39.8400 374.0000 1.0000
39.8800 399.0000 1.0000
39.9200 368.0000 1.0000
39.9600 369.0000 1.0000
40.0000 378.0000 1.0000
40.0400 377.0000 1.0000
40.0800 371.0000 1.0000
40.1200 362.0000 1.0000
40.1600 359.0000 1.0000
40.2000 351.0000 1.0000
40.2400 355.0000 1.0000
40.2800 355.0000 1.0000
40.3200 357.0000 1.0000
40.3600 376.0000 1.0000
40.4000 372.0000 1.0000
40.4400 345.0000 1.0000
40.4800 358.0000 1.0000
40.5200 339.0000 1.0000
40.5600 381.0000 1.0000
40.6000 369.0000 1.0000
40.6400 393.0000 1.0000
40.6800 354.0000 1.0000
40.7200 362.0000 1.0000
40.7600 360.0000 1.0000
40.8000 384.0000 1.0000
40.8400 403.0000 1.0000
40.8800 358.0000 1.0000
40.9200 380.0000 1.0000
40.9600 363.0000 1.0000
41.0000 365.0000 1.0000
41.0400 377.0000 1.0000
41.0800 373.0000 1.0000
41.1200 351.0000 1.0000
41.1600 344.0000 1.0000
41.2000 365.0000 1.0000
41.2400 348.0000 1.0000
41.2800 361.0000 1.0000
41.3200 345.0000 1.0000
41.3600 325.0000 1.0000
41.4000 339.0000 1.0000
41.4400 360.0000 1.0000
41.4800 353.0000 1.0000
41.5200 335.0000 1.0000
41.5600 364.0000 1.0000
41.6000 357.0000 1.0000
41.6400 317.0000 1.0000
41.6800 333.0000 1.0000
41.7200 385.0000 1.0000
41.7600 364.0000 1.0000
41.8000 345.0000 1.0000
41.8400 329.0000 1.0000
41.8800 339.0000 1.0000
41.9200 353.0000 1.0000
41.9600 353.0000 1.0000
42.0000 358.0000 1.0000
42.0400 376.0000 1.0000
42.0800 345.0000 1.0000
42.1200 368.0000 1.0000
42.1600 328.0000 1.0000
42.2000 350.0000 1.0000
42.2400 365.0000 1.0000
42.2800 372.0000 1.0000
42.3200 346.0000 1.0000
42.3600 365.0000 1.0000
42.4000 417.0000 1.0000
42.4400 425.0000 1.0000
42.4800 381.0000 1.0000
42.5200 408.0000 1.0000
42.5600 354.0000 1.0000
42.6000 357.0000 1.0000
42.6400 368.0000 1.0000
42.6800 341.0000 1.0000
42.7200 330.0000 1.0000
42.7600 358.0000 1.0000
42.8000 346.0000 1.0000
42.8400 338.0000 1.0000
42.8800 320.0000 1.0000
42.9200 351.0000 1.0000
42.9600 334.0000 1.0000
43.0000 342.0000 1.0000
43.0400 329.0000 1.0000
43.0800 308.0000 1.0000
43.1200 327.0000 1.0000
43.1600 328.0000 1.0000
43.2000 343.0000 1.0000
43.2400 352.0000 1.0000
43.2800 342.0000 1.0000
43.3200 338.0000 1.0000
43.3600 333.0000 1.0000
43.4000 332.0000 1.0000
43.4400 367.0000 1.0000
43.4800 346.0000 1.0000
43.5200 361.0000 1.0000
43.5600 360.0000 1.0000
43.6000 369.0000 1.0000
43.6400 329.0000 1.0000
43.6800 327.0000 1.0000
43.7200 328.0000 1.0000
43.7600 374.0000 1.0000
43.8000 334.0000 1.0000
43.8400 380.0000 1.0000
43.8800 340.0000 1.0000
43.9200 340.0000 1.0000
43.9600 353.0000 1.0000
44.0000 336.0000 1.0000
44.0400 336.0000 1.0000
44.0800 327.0000 1.0000
44.1200 345.0000 1.0000
44.1600 338.0000 1.0000
44.2000 353.0000 1.0000
44.2400 360.0000 1.0000
44.2800 325.0000 1.0000
44.3200 336.0000 1.0000
44.3600 339.0000 1.0000
44.4000 329.0000 1.0000
44.4400 342.0000 1.0000
44.4800 329.0000 1.0000
44.5200 351.0000 1.0000
44.5600 328.0000 1.0000
44.6000 321.0000 1.0000
44.6400 328.0000 1.0000
44.6800 326.0000 1.0000
44.7200 308.0000 1.0000
44.7600 326.0000 1.0000
44.8000 348.0000 1.0000
44.8400 345.0000 1.0000
44.8800 343.0000 1.0000
44.9200 323.0000 1.0000
44.9600 318.0000 1.0000
45.0000 319.0000 1.0000
45.0400 337.0000 1.0000
45.0800 348.0000 1.0000
45.1200 307.0000 1.0000
45.1600 333.0000 1.0000
45.2000 337.0000 1.0000
45.2400 327.0000 1.0000
45.2800 341.0000 1.0000
45.3200 362.0000 1.0000
45.3600 327.0000 1.0000
45.4000 312.0000 1.0000
45.4400 325.0000 1.0000
45.4800 342.0000 1.0000
45.5200 356.0000 1.0000
45.5600 317.0000 1.0000
45.6000 351.0000 1.0000
45.6400 314.0000 1.0000
45.6800 342.0000 1.0000
45.7200 311.0000 1.0000
45.7600 316.0000 1.0000
45.8000 323.0000 1.0000
45.8400 307.0000 1.0000
45.8800 298.0000 1.0000
45.9200 320.0000 1.0000
45.9600 303.0000 1.0000
46.0000 336.0000 1.0000
46.0400 337.0000 1.0000
46.0800 304.0000 1.0000
46.1200 337.0000 1.0000
46.1600 340.0000 1.0000
46.2000 318.0000 1.0000
46.2400 332.0000 1.0000
46.2800 309.0000 1.0000
46.3200 358.0000 1.0000
46.3600 338.0000 1.0000
46.4000 325.0000 1.0000
46.4400 326.0000 1.0000
46.4800 325.0000 1.0000
46.5200 297.0000 1.0000
46.5600 342.0000 1.0000
46.6000 306.0000 1.0000
46.6400 335.0000 1.0000
46.6800 315.0000 1.0000
46.7200 330.0000 1.0000
46.7600 336.0000 1.0000
46.8000 307.0000 1.0000
46.8400 316.0000 1.0000
46.8800 341.0000 1.0000
46.9200 313.0000 1.0000
46.9600 303.0000 1.0000
47.0000 318.0000 1.0000
47.0400 307.0000 1.0000
47.0800 307.0000 1.0000
47.1200 302.0000 1.0000
47.1600 311.0000 1.0000
47.2000 325.0000 1.0000
47.2400 301.0000 1.0000
47.2800 295.0000 1.0000
47.3200 302.0000 1.0000
47.3600 331.0000 1.0000
47.4000 312.0000 1.0000
47.4400 325.0000 1.0000
47.4800 306.0000 1.0000
47.5200 302.0000 1.0000
47.5600 295.0000 1.0000
47.6000 307.0000 1.0000
47.6400 316.0000 1.0000
47.6800 330.0000 1.0000
47.7200 310.0000 1.0000
47.7600 309.0000 1.0000
47.8000 309.0000 1.0000
47.8400 299.0000 1.0000
47.8800 292.0000 1.0000
47.9200 328.0000 1.0000
47.9600 303.0000 1.0000
48.0000 298.0000 1.0000
48.0400 294.0000 1.0000
48.0800 281.0000 1.0000
48.1200 282.0000 1.0000
48.1600 293.0000 1.0000
48.2000 297.0000 1.0000
48.2400 288.0000 1.0000
48.2800 274.0000 1.0000
48.3200 320.0000 1.0000
48.3600 299.0000 1.0000
48.4000 297.0000 1.0000
48.4400 295.0000 1.0000
48.4800 324.0000 1.0000
48.5200 316.0000 1.0000
48.5600 276.0000 1.0000
48.6000 308.0000 1.0000
48.6400 305.0000 1.0000
48.6800 283.0000 1.0000
48.7200 292.0000 1.0000
48.7600 272.0000 1.0000
48.8000 302.0000 1.0000
48.8400 309.0000 1.0000
48.8800 292.0000 1.0000
48.9200 310.0000 1.0000
48.9600 296.0000 1.0000
49.0000 312.0000 1.0000
49.0400 311.0000 1.0000
49.0800 298.0000 1.0000
49.1200 310.0000 1.0000
49.1600 325.0000 1.0000
49.2000 300.0000 1.0000
49.2400 298.0000 1.0000
49.2800 295.0000 1.0000
49.3200 299.0000 1.0000
49.3600 319.0000 1.0000
49.4000 342.0000 1.0000
49.4400 316.0000 1.0000
49.4800 292.0000 1.0000
49.5200 315.0000 1.0000
49.5600 343.0000 1.0000
49.6000 317.0000 1.0000
49.6400 300.0000 1.0000
49.6800 290.0000 1.0000
49.7200 319.0000 1.0000
49.7600 318.0000 1.0000
49.8000 323.0000 1.0000
49.8400 299.0000 1.0000
49.8800 338.0000 1.0000
49.9200 310.0000 1.0000
49.9600 333.0000 1.0000
50.0000 304.0000 1.0000
50.0400 280.0000 1.0000
50.0800 331.0000 1.0000
50.1200 303.0000 1.0000
50.1600 319.0000 1.0000
50.2000 310.0000 1.0000
50.2400 296.0000 1.0000
50.2800 289.0000 1.0000
50.3200 278.0000 1.0000
50.3600 301.0000 1.0000
50.4000 289.0000 1.0000
50.4400 307.0000 1.0000
50.4800 301.0000 1.0000
50.5200 315.0000 1.0000
50.5600 297.0000 1.0000
50.6000 296.0000 1.0000
50.6400 295.0000 1.0000
50.6800 286.0000 1.0000
50.7200 325.0000 1.0000
50.7600 319.0000 1.0000
50.8000 288.0000 1.0000
50.8400 312.0000 1.0000
50.8800 331.0000 1.0000
50.9200 332.0000 1.0000
50.9600 320.0000 1.0000
51.0000 357.0000 1.0000
51.0400 364.0000 1.0000
51.0800 332.0000 1.0000
51.1200 404.0000 1.0000
51.1600 399.0000 1.0000
51.2000 470.0000 1.0000
51.2400 504.0000 1.0000
51.2800 600.0000 1.0000
51.3200 768.0000 1.0000
51.3600 994.0000 1.0000
51.4000 1393.0000 1.0000
51.4400 1835.0000 1.0000
51.4800 2266.0000 1.0000
51.5200 2148.0000 1.0000
51.5600 1836.0000 1.0000
51.6000 1772.0000 1.0000
51.6400 1494.0000 1.0000
51.6800 1155.0000 1.0000
51.7200 905.0000 1.0000
51.7600 707.0000 1.0000
51.8000 579.0000 1.0000
51.8400 485.0000 1.0000
51.8800 428.0000 1.0000
51.9200 397.0000 1.0000
51.9600 389.0000 1.0000
52.0000 360.0000 1.0000
52.0400 347.0000 1.0000
52.0800 392.0000 1.0000
52.1200 333.0000 1.0000
52.1600 357.0000 1.0000
52.2000 340.0000 1.0000
52.2400 308.0000 1.0000
52.2800 332.0000 1.0000
52.3200 316.0000 1.0000
52.3600 304.0000 1.0000
52.4000 306.0000 1.0000
52.4400 301.0000 1.0000
52.4800 321.0000 1.0000
52.5200 298.0000 1.0000
52.5600 293.0000 1.0000
52.6000 325.0000 1.0000
52.6400 296.0000 1.0000
52.6800 290.0000 1.0000
52.7200 304.0000 1.0000
52.7600 305.0000 1.0000
52.8000 300.0000 1.0000
52.8400 285.0000 1.0000
52.8800 300.0000 1.0000
52.9200 304.0000 1.0000
52.9600 303.0000 1.0000
53.0000 308.0000 1.0000
53.0400 280.0000 1.0000
53.0800 309.0000 1.0000
53.1200 275.0000 1.0000
53.1600 307.0000 1.0000
53.2000 285.0000 1.0000
53.2400 254.0000 1.0000
53.2800 269.0000 1.0000
53.3200 320.0000 1.0000
53.3600 290.0000 1.0000
53.4000 295.0000 1.0000
53.4400 258.0000 1.0000
53.4800 275.0000 1.0000
53.5200 281.0000 1.0000
53.5600 292.0000 1.0000
53.6000 277.0000 1.0000
53.6400 298.0000 1.0000
53.6800 280.0000 1.0000
53.7200 290.0000 1.0000
53.7600 271.0000 1.0000
53.8000 294.0000 1.0000
53.8400 278.0000 1.0000
53.8800 287.0000 1.0000
53.9200 286.0000 1.0000
53.9600 324.0000 1.0000
54.0000 325.0000 1.0000
54.0400 332.0000 1.0000
54.0800 316.0000 1.0000
54.1200 321.0000 1.0000
54.1600 286.0000 1.0000
54.2000 332.0000 1.0000
54.2400 280.0000 1.0000
54.2800 326.0000 1.0000
54.3200 343.0000 1.0000
54.3600 338.0000 1.0000
54.4000 399.0000 1.0000
54.4400 406.0000 1.0000
54.4800 436.0000 1.0000
54.5200 437.0000 1.0000
54.5600 441.0000 1.0000
54.6000 393.0000 1.0000
54.6400 441.0000 1.0000
54.6800 400.0000 1.0000
54.7200 365.0000 1.0000
54.7600 345.0000 1.0000
54.8000 348.0000 1.0000
54.8400 310.0000 1.0000
54.8800 335.0000 1.0000
54.9200 304.0000 1.0000
54.9600 286.0000 1.0000
55.0000 299.0000 1.0000
55.0400 310.0000 1.0000
55.0800 320.0000 1.0000
55.1200 284.0000 1.0000
55.1600 273.0000 1.0000
55.2000 281.0000 1.0000
55.2400 294.0000 1.0000
55.2800 285.0000 1.0000
55.3200 291.0000 1.0000
55.3600 271.0000 1.0000
55.4000 275.0000 1.0000
55.4400 298.0000 1.0000
55.4800 287.0000 1.0000
55.5200 261.0000 1.0000
55.5600 311.0000 1.0000
55.6000 299.0000 1.0000
55.6400 297.0000 1.0000
55.6800 272.0000 1.0000
55.7200 262.0000 1.0000
55.7600 266.0000 1.0000
55.8000 294.0000 1.0000
55.8400 294.0000 1.0000
55.8800 276.0000 1.0000
55.9200 282.0000 1.0000
55.9600 285.0000 1.0000
56.0000 292.0000 1.0000
56.0400 298.0000 1.0000
56.0800 276.0000 1.0000
56.1200 300.0000 1.0000
56.1600 304.0000 1.0000
56.2000 298.0000 1.0000
56.2400 264.0000 1.0000
56.2800 262.0000 1.0000
56.3200 272.0000 1.0000
56.3600 273.0000 1.0000
56.4000 278.0000 1.0000
56.4400 264.0000 1.0000
56.4800 310.0000 1.0000
56.5200 288.0000 1.0000
56.5600 291.0000 1.0000
56.6000 277.0000 1.0000
56.6400 279.0000 1.0000
56.6800 293.0000 1.0000
56.7200 287.0000 1.0000
56.7600 292.0000 1.0000
56.8000 273.0000 1.0000
56.8400 276.0000 1.0000
56.8800 269.0000 1.0000
56.9200 274.0000 1.0000
56.9600 286.0000 1.0000
57.0000 285.0000 1.0000
57.0400 275.0000 1.0000
57.0800 294.0000 1.0000
57.1200 282.0000 1.0000
57.1600 280.0000 1.0000
57.2000 264.0000 1.0000
57.2400 282.0000 1.0000
57.2800 259.0000 1.0000
57.3200 319.0000 1.0000
57.3600 279.0000 1.0000
57.4000 312.0000 1.0000
57.4400 295.0000 1.0000
57.4800 277.0000 1.0000
57.5200 251.0000 1.0000
57.5600 287.0000 1.0000
57.6000 273.0000 1.0000
57.6400 290.0000 1.0000
57.6800 274.0000 1.0000
57.7200 294.0000 1.0000
57.7600 290.0000 1.0000
57.8000 280.0000 1.0000
57.8400 283.0000 1.0000
57.8800 253.0000 1.0000
57.9200 271.0000 1.0000
57.9600 286.0000 1.0000
58.0000 257.0000 1.0000
58.0400 287.0000 1.0000
58.0800 288.0000 1.0000
58.1200 260.0000 1.0000
58.1600 291.0000 1.0000
58.2000 266.0000 1.0000
58.2400 271.0000 1.0000
58.2800 258.0000 1.0000
58.3200 294.0000 1.0000
58.3600 289.0000 1.0000
58.4000 289.0000 1.0000
58.4400 289.0000 1.0000
58.4800 275.0000 1.0000
58.5200 298.0000 1.0000
58.5600 320.0000 1.0000
58.6000 289.0000 1.0000
58.6400 258.0000 1.0000
58.6800 297.0000 1.0000
58.7200 237.0000 1.0000
58.7600 256.0000 1.0000
58.8000 273.0000 1.0000
58.8400 278.0000 1.0000
58.8800 243.0000 1.0000
58.9200 299.0000 1.0000
58.9600 274.0000 1.0000
59.0000 258.0000 1.0000
59.0400 273.0000 1.0000
59.0800 278.0000 1.0000
59.1200 270.0000 1.0000
59.1600 261.0000 1.0000
59.2000 274.0000 1.0000
59.2400 275.0000 1.0000
59.2800 281.0000 1.0000
59.3200 273.0000 1.0000
59.3600 269.0000 1.0000
59.4000 269.0000 1.0000
59.4400 265.0000 1.0000
59.4800 281.0000 1.0000
59.5200 260.0000 1.0000
59.5600 267.0000 1.0000
59.6000 282.0000 1.0000
59.6400 250.0000 1.0000
59.6800 278.0000 1.0000
59.7200 255.0000 1.0000
59.7600 288.0000 1.0000
59.8000 248.0000 1.0000
59.8400 282.0000 1.0000
59.8800 280.0000 1.0000
59.9200 267.0000 1.0000
59.9600 272.0000 1.0000
60.0000 293.0000 1.0000
60.0400 286.0000 1.0000
60.0800 266.0000 1.0000
60.1200 268.0000 1.0000
60.1600 258.0000 1.0000
60.2000 280.0000 1.0000
60.2400 283.0000 1.0000
60.2800 268.0000 1.0000
60.3200 273.0000 1.0000
60.3600 297.0000 1.0000
60.4000 286.0000 1.0000
60.4400 270.0000 1.0000
60.4800 294.0000 1.0000
60.5200 270.0000 1.0000
60.5600 279.0000 1.0000
60.6000 276.0000 1.0000
60.6400 296.0000 1.0000
60.6800 283.0000 1.0000
60.7200 269.0000 1.0000
60.7600 260.0000 1.0000
60.8000 278.0000 1.0000
60.8400 281.0000 1.0000
60.8800 255.0000 1.0000
60.9200 275.0000 1.0000
60.9600 301.0000 1.0000
61.0000 275.0000 1.0000
61.0400 283.0000 1.0000
61.0800 282.0000 1.0000
61.1200 302.0000 1.0000
61.1600 328.0000 1.0000
61.2000 308.0000 1.0000
61.2400 326.0000 1.0000
61.2800 360.0000 1.0000
61.3200 397.0000 1.0000
61.3600 385.0000 1.0000
61.4000 482.0000 1.0000
61.4400 517.0000 1.0000
61.4800 578.0000 1.0000
61.5200 590.0000 1.0000
61.5600 590.0000 1.0000
61.6000 584.0000 1.0000
61.6400 541.0000 1.0000
61.6800 529.0000 1.0000
61.7200 486.0000 1.0000
61.7600 491.0000 1.0000
61.8000 440.0000 1.0000
61.8400 393.0000 1.0000
61.8800 358.0000 1.0000
61.9200 379.0000 1.0000
61.9600 353.0000 1.0000
62.0000 314.0000 1.0000
62.0400 324.0000 1.0000
62.0800 322.0000 1.0000
62.1200 336.0000 1.0000
62.1600 325.0000 1.0000
62.2000 273.0000 1.0000
62.2400 276.0000 1.0000
62.2800 301.0000 1.0000
62.3200 305.0000 1.0000
62.3600 325.0000 1.0000
62.4000 309.0000 1.0000
62.4400 295.0000 1.0000
62.4800 288.0000 1.0000
62.5200 284.0000 1.0000
62.5600 282.0000 1.0000
62.6000 297.0000 1.0000
62.6400 265.0000 1.0000
62.6800 283.0000 1.0000
62.7200 293.0000 1.0000
62.7600 279.0000 1.0000
62.8000 270.0000 1.0000
62.8400 282.0000 1.0000
62.8800 270.0000 1.0000
62.9200 298.0000 1.0000
62.9600 295.0000 1.0000
63.0000 260.0000 1.0000
63.0400 267.0000 1.0000
63.0800 287.0000 1.0000
63.1200 280.0000 1.0000
63.1600 285.0000 1.0000
63.2000 260.0000 1.0000
63.2400 276.0000 1.0000
63.2800 269.0000 1.0000
63.3200 296.0000 1.0000
63.3600 273.0000 1.0000
63.4000 289.0000 1.0000
63.4400 296.0000 1.0000
63.4800 298.0000 1.0000
63.5200 301.0000 1.0000
63.5600 277.0000 1.0000
63.6000 277.0000 1.0000
63.6400 266.0000 1.0000
63.6800 290.0000 1.0000
63.7200 288.0000 1.0000
63.7600 305.0000 1.0000
63.8000 307.0000 1.0000
63.8400 354.0000 1.0000
63.8800 385.0000 1.0000
63.9200 449.0000 1.0000
63.9600 442.0000 1.0000
64.0000 406.0000 1.0000
64.0400 359.0000 1.0000
64.0800 368.0000 1.0000
64.1200 362.0000 1.0000
64.1600 337.0000 1.0000
64.2000 332.0000 1.0000
64.2400 329.0000 1.0000
64.2800 300.0000 1.0000
64.3200 289.0000 1.0000
64.3600 295.0000 1.0000
64.4000 299.0000 1.0000
64.4400 277.0000 1.0000
64.4800 295.0000 1.0000
64.5200 287.0000 1.0000
64.5600 303.0000 1.0000
64.6000 274.0000 1.0000
64.6400 287.0000 1.0000
64.6800 258.0000 1.0000
64.7200 279.0000 1.0000
64.7600 293.0000 1.0000
64.8000 285.0000 1.0000
64.8400 285.0000 1.0000
64.8800 256.0000 1.0000
64.9200 291.0000 1.0000
64.9600 265.0000 1.0000
65.0000 292.0000 1.0000
65.0400 311.0000 1.0000
65.0800 322.0000 1.0000
65.1200 300.0000 1.0000
65.1600 357.0000 1.0000
65.2000 370.0000 1.0000
65.2400 369.0000 1.0000
65.2800 388.0000 1.0000
65.3200 444.0000 1.0000
65.3600 552.0000 1.0000
65.4000 634.0000 1.0000
65.4400 748.0000 1.0000
65.4800 926.0000 1.0000
65.5200 1058.0000 1.0000
65.5600 1085.0000 1.0000
65.6000 1029.0000 1.0000
65.6400 983.0000 1.0000
65.6800 867.0000 1.0000
65.7200 825.0000 1.0000
65.7600 758.0000 1.0000
65.8000 660.0000 1.0000
65.8400 555.0000 1.0000
65.8800 465.0000 1.0000
65.9200 416.0000 1.0000
65.9600 369.0000 1.0000
66.0000 364.0000 1.0000
66.0400 345.0000 1.0000
66.0800 326.0000 1.0000
66.1200 306.0000 1.0000
66.1600 288.0000 1.0000
66.2000 284.0000 1.0000
66.2400 276.0000 1.0000
66.2800 285.0000 1.0000
66.3200 286.0000 1.0000
66.3600 265.0000 1.0000
66.4000 270.0000 1.0000
66.4400 283.0000 1.0000
66.4800 280.0000 1.0000
66.5200 284.0000 1.0000
66.5600 255.0000 1.0000
66.6000 244.0000 1.0000
66.6400 264.0000 1.0000
66.6800 259.0000 1.0000
66.7200 283.0000 1.0000
66.7600 246.0000 1.0000
66.8000 228.0000 1.0000
66.8400 241.0000 1.0000
66.8800 267.0000 1.0000
66.9200 256.0000 1.0000
66.9600 263.0000 1.0000
67.0000 265.0000 1.0000
67.0400 263.0000 1.0000
67.0800 263.0000 1.0000
67.1200 274.0000 1.0000
67.1600 231.0000 1.0000
67.2000 245.0000 1.0000
67.2400 263.0000 1.0000
67.2800 258.0000 1.0000
67.3200 257.0000 1.0000
67.3600 277.0000 1.0000
67.4000 233.0000 1.0000
67.4400 269.0000 1.0000
67.4800 256.0000 1.0000
67.5200 245.0000 1.0000
67.5600 225.0000 1.0000
67.6000 251.0000 1.0000
67.6400 258.0000 1.0000
67.6800 264.0000 1.0000
67.7200 253.0000 1.0000
67.7600 229.0000 1.0000
67.8000 262.0000 1.0000
67.8400 247.0000 1.0000
67.8800 234.0000 1.0000
67.9200 235.0000 1.0000
67.9600 245.0000 1.0000
68.0000 246.0000 1.0000
68.0400 248.0000 1.0000
68.0800 262.0000 1.0000
68.1200 240.0000 1.0000
68.1600 237.0000 1.0000
68.2000 265.0000 1.0000
68.2400 246.0000 1.0000
68.2800 244.0000 1.0000
68.3200 226.0000 1.0000
68.3600 246.0000 1.0000
68.4000 264.0000 1.0000
68.4400 230.0000 1.0000
68.4800 270.0000 1.0000
68.5200 237.0000 1.0000
68.5600 246.0000 1.0000
68.6000 225.0000 1.0000
68.6400 239.0000 1.0000
68.6800 254.0000 1.0000
68.7200 248.0000 1.0000
68.7600 260.0000 1.0000
68.8000 245.0000 1.0000
68.8400 245.0000 1.0000
68.8800 247.0000 1.0000
68.9200 231.0000 1.0000
68.9600 233.0000 1.0000
69.0000 227.0000 1.0000
69.0400 228.0000 1.0000
69.0800 215.0000 1.0000
69.1200 243.0000 1.0000
69.1600 250.0000 1.0000
69.2000 225.0000 1.0000
69.2400 246.0000 1.0000
69.2800 266.0000 1.0000
69.3200 256.0000 1.0000
69.3600 235.0000 1.0000
69.4000 244.0000 1.0000
69.4400 194.0000 1.0000
69.4800 224.0000 1.0000
69.5200 253.0000 1.0000
69.5600 253.0000 1.0000
69.6000 254.0000 1.0000
69.6400 242.0000 1.0000
69.6800 271.0000 1.0000
69.7200 227.0000 1.0000
69.7600 224.0000 1.0000
69.8000 210.0000 1.0000
69.8400 238.0000 1.0000
69.8800 264.0000 1.0000
69.9200 240.0000 1.0000
69.9600 217.0000 1.0000
70.0000 246.0000 1.0000
*RAS_INT_END
*RAS_TEMPERATURE_START
*RAS_TEMPERATURE_END
*RAS_DATA_END