File: Data/Dataset2_Water_Organic/4_XRD/No_47_2312020240119_2-Ethyl-1-Butanol_5.ras
*RAS_DATA_START
*RAS_HEADER_START
*DISP_FMT_X "%.2f"
*DISP_FMT_Y "%.0f"
*DISP_FULLSCALE "16065.0000000000"
*DISP_LINE_COLOR "255.0000000000"
*DISP_LINE_STYLE "0.0000000000"
*DISP_LINE_WIDTH "0.2500000000"
*DISP_NOTE "測定データ-13"
*DISP_OFFSET_Y "0.0000000000"
*DISP_PEAKSEARCH_UNIT_Y "cps"
*DISP_RANGE_BOTTOM "0.0000000000"
*DISP_RANGE_LEFT "20.0000000000"
*DISP_RANGE_LOGCUTOFF "0.0100000000"
*DISP_RANGE_RIGHT "70.0000000000"
*DISP_RANGE_TOP "16065.0000000000"
*DISP_SCALE_MODE_Y "0.0000000000"
*DISP_TAB_NAME "2θ/θ"
*DISP_TITLE_Y "強度"
*DISP_UNIT_Y "cps"
*DISP_WINDOW_NAME "MSG_MACROENGINE"
*FILE_COMMENT " "
*FILE_MD5 ""
*FILE_MEMO " "
*FILE_OPERATOR "Administrator"
*FILE_SAMPLE " "
*FILE_TYPE "RAS_RAW"
*FILE_USERGROUP "システムマネージャ"
*FILE_VERSION "1.0000000000"
*HW_ATTACHMENT_ID "ATT0025"
*HW_ATTACHMENT_NAME "標準|Standard"
*HW_COUNTER_ID-0 "CUT0025"
*HW_COUNTER_ID-1 "CUT0020"
*HW_COUNTER_ID-2 "CUT0020"
*HW_COUNTER_ID-3 "CSL0021"
*HW_COUNTER_ID-4 "CMC0021"
*HW_COUNTER_NAME-0 "D/teX Ultra|D/teX Ultra"
*HW_COUNTER_NAME-1 "None|None"
*HW_COUNTER_NAME-2 "None|None"
*HW_COUNTER_NAME-3 "BBM|BBM"
*HW_COUNTER_NAME-4 "検出器モノクロメータ|Detector monochromator"
*HW_COUNTER_SELECT_NAME "D/teX Ultra|D/teX Ultra"
*HW_GONIOMETER_ID "GON0023"
*HW_GONIOMETER_NAME "SmartLab|SmartLab"
*HW_GONIOMETER_RADIUS-0 "90.0"
*HW_GONIOMETER_RADIUS-1 "114.0"
*HW_GONIOMETER_RADIUS-2 "190.0"
*HW_GONIOMETER_RADIUS-3 "300.0"
*HW_GONIOMETER_RADIUS-4 "187.0"
*HW_GONIOMETER_RADIUS-5 "300.0"
*HW_GONIOMETER_RADIUS-6 "113.0"
*HW_GONIOMETER_RADIUS-7 "331.0"
*HW_I_OPT_ID-0 "CBO0021"
*HW_I_OPT_ID-1 "ICR0023"
*HW_I_OPT_ID-2 "ISL0021"
*HW_I_OPT_ID-3 "ISO0021"
*HW_I_OPT_ID-4 "IAD0021"
*HW_I_OPT_ID-5 "IPR0001"
*HW_I_OPT_NAME-0 "CBOユニット|CBO unit"
*HW_I_OPT_NAME-1 "標準入射光学ユニット|Standard incident optical unit"
*HW_I_OPT_NAME-2 "標準入射スリットボックス|Standard incident slit box"
*HW_I_OPT_NAME-3 "入射平行スリット|Incident parallel slit"
*HW_I_OPT_NAME-4 "長手制限スリット|Length limiting slit"
*HW_I_OPT_NAME-5 "None|None"
*HW_R_ATTENUATER_AUTOMODE "0"
*HW_R_OPT_ID-0 "RSS0021"
*HW_R_OPT_ID-1 "RCR0023"
*HW_R_OPT_ID-2 "RSO0021"
*HW_R_OPT_ID-3 "RRS0021"
*HW_R_OPT_ID-4 "ATN0021"
*HW_R_OPT_ID-5 "RFL0021"
*HW_R_OPT_ID-6 "RAD0021"
*HW_R_OPT_NAME-0 "標準受光スリットボックス1|Standard receiving slit box # 1"
*HW_R_OPT_NAME-1 "標準受光光学ユニット1|Standard receiving unit # 1"
*HW_R_OPT_NAME-2 "標準受光光学ユニット2|Standard receiving optical unit # 2"
*HW_R_OPT_NAME-3 "標準受光スリットボックス2|Standard receiving slit box # 2"
*HW_R_OPT_NAME-4 "標準アッテネータ|Standard Attenuator"
*HW_R_OPT_NAME-5 "Cu Kβ|Cu K-beta"
*HW_R_OPT_NAME-6 "調整用受光スリット|Alignment receiving slit"
*HW_SAMPLE_HOLDER_ID "SMP0023"
*HW_SAMPLE_HOLDER_NAME "標準Zステージ|Standard Z stage"
*HW_XG_CURRENT_MAX "50"
*HW_XG_CURRENT_MIN "2"
*HW_XG_CURRENT_RESOLUTION "1"
*HW_XG_CURRENT_UNIT "mA"
*HW_XG_FOCUS "1mm x 10mm"
*HW_XG_FOCUS_TYPE "Normal"
*HW_XG_ID ""
*HW_XG_NAME "3kW 封入管(ID:1200)|3kW Sealed tube(ID:1200)"
*HW_XG_TARGET_ATOMIC_NUMBER "29.0000000000"
*HW_XG_TARGET_NAME "Cu"
*HW_XG_TYPE "Hermetic"
*HW_XG_VOLTAGE_MAX "60"
*HW_XG_VOLTAGE_MIN "20"
*HW_XG_VOLTAGE_RESOLUTION "1"
*HW_XG_VOLTAGE_UNIT "kV"
*HW_XG_WATT_MAX "1.500"
*HW_XG_WATT_UNIT "kW"
*HW_XG_WAVE_LENGTH_ALPHA1 "1.540593"
*HW_XG_WAVE_LENGTH_ALPHA2 "1.544414"
*HW_XG_WAVE_LENGTH_BETA "1.392250"
*MEAS_COND_AXIS_NAME-0 "2θ/θ"
*MEAS_COND_AXIS_NAME-1 "2θ"
*MEAS_COND_AXIS_NAME-2 "ω"
*MEAS_COND_AXIS_NAME-3 "Z"
*MEAS_COND_AXIS_NAME-4 "2θ/ω"
*MEAS_COND_AXIS_NAME-5 "θs"
*MEAS_COND_AXIS_NAME-6 "θd"
*MEAS_COND_AXIS_NAME-7 "Ts"
*MEAS_COND_AXIS_NAME-8 "CBO選択スリット"
*MEAS_COND_AXIS_NAME-9 "M"
*MEAS_COND_AXIS_NAME-10 "入射平行スリット"
*MEAS_COND_AXIS_NAME-11 "入射スリット"
*MEAS_COND_AXIS_NAME-12 ""
*MEAS_COND_AXIS_NAME-13 "Zs"
*MEAS_COND_AXIS_NAME-14 "入射光学素子"
*MEAS_COND_AXIS_NAME-15 "長手制限スリット"
*MEAS_COND_AXIS_NAME-16 "センタースリット"
*MEAS_COND_AXIS_NAME-17 "フィルター"
*MEAS_COND_AXIS_NAME-18 "受光スリット1"
*MEAS_COND_AXIS_NAME-19 "受光スリット2"
*MEAS_COND_AXIS_NAME-20 "受光光学素子"
*MEAS_COND_AXIS_NAME-21 "受光平行スリット"
*MEAS_COND_AXIS_NAME-22 "調整用受光スリット"
*MEAS_COND_AXIS_NAME-23 ""
*MEAS_COND_AXIS_NAME-24 ""
*MEAS_COND_AXIS_NAME-25 "Zd"
*MEAS_COND_AXIS_NAME-26 "アッテネータ"
*MEAS_COND_AXIS_NAME-27 "検出器モノクロメータ"
*MEAS_COND_AXIS_NAME-28 "モノクロメータスリット"
*MEAS_COND_AXIS_NAME-29 "プライマリビーム"
*MEAS_COND_AXIS_NAME-30 "PHA"
*MEAS_COND_AXIS_NAME_INTERNAL-0 "TwoThetaTheta"
*MEAS_COND_AXIS_NAME_INTERNAL-1 "TwoTheta"
*MEAS_COND_AXIS_NAME_INTERNAL-2 "Omega"
*MEAS_COND_AXIS_NAME_INTERNAL-3 "Z"
*MEAS_COND_AXIS_NAME_INTERNAL-4 "TwoThetaOmega"
*MEAS_COND_AXIS_NAME_INTERNAL-5 "ThetaS"
*MEAS_COND_AXIS_NAME_INTERNAL-6 "ThetaD"
*MEAS_COND_AXIS_NAME_INTERNAL-7 "Ts"
*MEAS_COND_AXIS_NAME_INTERNAL-8 "CBO"
*MEAS_COND_AXIS_NAME_INTERNAL-9 "CBO-M"
*MEAS_COND_AXIS_NAME_INTERNAL-10 "IncidentSollerSlit"
*MEAS_COND_AXIS_NAME_INTERNAL-11 "IncidentSlitBox"
*MEAS_COND_AXIS_NAME_INTERNAL-12 "IncidentSlitBox-_Axis"
*MEAS_COND_AXIS_NAME_INTERNAL-13 "Zs"
*MEAS_COND_AXIS_NAME_INTERNAL-14 "IncidentMonochromator"
*MEAS_COND_AXIS_NAME_INTERNAL-15 "IncidentAxdSlit"
*MEAS_COND_AXIS_NAME_INTERNAL-16 "CenterSlit"
*MEAS_COND_AXIS_NAME_INTERNAL-17 "Filter"
*MEAS_COND_AXIS_NAME_INTERNAL-18 "ReceivingSlitBox1"
*MEAS_COND_AXIS_NAME_INTERNAL-19 "ReceivingSlitBox2"
*MEAS_COND_AXIS_NAME_INTERNAL-20 "ReceivingOptics"
*MEAS_COND_AXIS_NAME_INTERNAL-21 "ReceivingSollerSlit"
*MEAS_COND_AXIS_NAME_INTERNAL-22 "ReceivingAxdSlit"
*MEAS_COND_AXIS_NAME_INTERNAL-23 "ReceivingSlitBox1-_Axis"
*MEAS_COND_AXIS_NAME_INTERNAL-24 "ReceivingSlitBox2-_Axis"
*MEAS_COND_AXIS_NAME_INTERNAL-25 "ReceivingSlitBox2-Zd"
*MEAS_COND_AXIS_NAME_INTERNAL-26 "Attenuator"
*MEAS_COND_AXIS_NAME_INTERNAL-27 "CounterMonochromator"
*MEAS_COND_AXIS_NAME_INTERNAL-28 "CounterSlit"
*MEAS_COND_AXIS_NAME_INTERNAL-29 "IncidentPrimary"
*MEAS_COND_AXIS_NAME_INTERNAL-30 "PHA"
*MEAS_COND_AXIS_NAME_MAGICNO-0 "83951616.0000000000"
*MEAS_COND_AXIS_NAME_MAGICNO-1 "268632064.0000000000"
*MEAS_COND_AXIS_NAME_MAGICNO-2 "268500992.0000000000"
*MEAS_COND_AXIS_NAME_MAGICNO-3 "285278208.0000000000"
*MEAS_COND_AXIS_NAME_MAGICNO-4 "83951616.0000000000"
*MEAS_COND_AXIS_NAME_MAGICNO-5 "131072.0000000000"
*MEAS_COND_AXIS_NAME_MAGICNO-6 "131072.0000000000"
*MEAS_COND_AXIS_NAME_MAGICNO-7 "318898176.0000000000"
*MEAS_COND_AXIS_NAME_MAGICNO-8 "20971521.0000000000"
*MEAS_COND_AXIS_NAME_MAGICNO-9 "285343744.0000000000"
*MEAS_COND_AXIS_NAME_MAGICNO-10 "20971521.0000000000"
*MEAS_COND_AXIS_NAME_MAGICNO-11 "22020097.0000000000"
*MEAS_COND_AXIS_NAME_MAGICNO-12 "25165824.0000000000"
*MEAS_COND_AXIS_NAME_MAGICNO-13 "318898176.0000000000"
*MEAS_COND_AXIS_NAME_MAGICNO-14 "1.0000000000"
*MEAS_COND_AXIS_NAME_MAGICNO-15 "20971521.0000000000"
*MEAS_COND_AXIS_NAME_MAGICNO-16 "20971521.0000000000"
*MEAS_COND_AXIS_NAME_MAGICNO-17 "20971521.0000000000"
*MEAS_COND_AXIS_NAME_MAGICNO-18 "23068673.0000000000"
*MEAS_COND_AXIS_NAME_MAGICNO-19 "23068673.0000000000"
*MEAS_COND_AXIS_NAME_MAGICNO-20 "20971521.0000000000"
*MEAS_COND_AXIS_NAME_MAGICNO-21 "20971521.0000000000"
*MEAS_COND_AXIS_NAME_MAGICNO-22 "20971521.0000000000"
*MEAS_COND_AXIS_NAME_MAGICNO-23 "25165824.0000000000"
*MEAS_COND_AXIS_NAME_MAGICNO-24 "25165824.0000000000"
*MEAS_COND_AXIS_NAME_MAGICNO-25 "285343744.0000000000"
*MEAS_COND_AXIS_NAME_MAGICNO-26 "17301505.0000000000"
*MEAS_COND_AXIS_NAME_MAGICNO-27 "20971521.0000000000"
*MEAS_COND_AXIS_NAME_MAGICNO-28 "20971521.0000000000"
*MEAS_COND_AXIS_NAME_MAGICNO-29 "20971521.0000000000"
*MEAS_COND_AXIS_NAME_MAGICNO-30 "0.0000000000"
*MEAS_COND_AXIS_OFFSET-0 "-"
*MEAS_COND_AXIS_OFFSET-1 "-0.0310000000"
*MEAS_COND_AXIS_OFFSET-2 "0.3957000000"
*MEAS_COND_AXIS_OFFSET-3 "-"
*MEAS_COND_AXIS_OFFSET-4 "-"
*MEAS_COND_AXIS_OFFSET-5 "0.3957000000"
*MEAS_COND_AXIS_OFFSET-6 "-0.4267000000"
*MEAS_COND_AXIS_OFFSET-7 "-"
*MEAS_COND_AXIS_OFFSET-8 "-"
*MEAS_COND_AXIS_OFFSET-9 "-"
*MEAS_COND_AXIS_OFFSET-10 "-"
*MEAS_COND_AXIS_OFFSET-11 "-"
*MEAS_COND_AXIS_OFFSET-12 "-"
*MEAS_COND_AXIS_OFFSET-13 "-"
*MEAS_COND_AXIS_OFFSET-14 "-"
*MEAS_COND_AXIS_OFFSET-15 "-"
*MEAS_COND_AXIS_OFFSET-16 "-"
*MEAS_COND_AXIS_OFFSET-17 "-"
*MEAS_COND_AXIS_OFFSET-18 "-"
*MEAS_COND_AXIS_OFFSET-19 "-"
*MEAS_COND_AXIS_OFFSET-20 "-"
*MEAS_COND_AXIS_OFFSET-21 "-"
*MEAS_COND_AXIS_OFFSET-22 "-"
*MEAS_COND_AXIS_OFFSET-23 "-"
*MEAS_COND_AXIS_OFFSET-24 "-"
*MEAS_COND_AXIS_OFFSET-25 "-"
*MEAS_COND_AXIS_OFFSET-26 "-"
*MEAS_COND_AXIS_OFFSET-27 "-"
*MEAS_COND_AXIS_OFFSET-28 "-"
*MEAS_COND_AXIS_OFFSET-29 "-"
*MEAS_COND_AXIS_OFFSET-30 "-"
*MEAS_COND_AXIS_POSITION-0 "0.0000000000"
*MEAS_COND_AXIS_POSITION-1 "0.0000000000"
*MEAS_COND_AXIS_POSITION-2 "0.0000000000"
*MEAS_COND_AXIS_POSITION-3 "-2.9037400000"
*MEAS_COND_AXIS_POSITION-4 "0.0000000000"
*MEAS_COND_AXIS_POSITION-5 "0.0000000000"
*MEAS_COND_AXIS_POSITION-6 "0.0000000000"
*MEAS_COND_AXIS_POSITION-7 "-0.7498700000"
*MEAS_COND_AXIS_POSITION-8 "BB"
*MEAS_COND_AXIS_POSITION-9 "0.0000000000"
*MEAS_COND_AXIS_POSITION-10 "Soller_slit_5.0deg"
*MEAS_COND_AXIS_POSITION-11 "2/3deg"
*MEAS_COND_AXIS_POSITION-12 "2.2088000000"
*MEAS_COND_AXIS_POSITION-13 "-0.6412500000"
*MEAS_COND_AXIS_POSITION-14 "0.0000000000"
*MEAS_COND_AXIS_POSITION-15 "10.0mm"
*MEAS_COND_AXIS_POSITION-16 "None"
*MEAS_COND_AXIS_POSITION-17 "Cu_K-beta"
*MEAS_COND_AXIS_POSITION-18 "13.000mm"
*MEAS_COND_AXIS_POSITION-19 "13.000mm"
*MEAS_COND_AXIS_POSITION-20 "No_unit"
*MEAS_COND_AXIS_POSITION-21 "Soller_slit_5.0deg"
*MEAS_COND_AXIS_POSITION-22 "None"
*MEAS_COND_AXIS_POSITION-23 "13.0000000000"
*MEAS_COND_AXIS_POSITION-24 "13.0000000000"
*MEAS_COND_AXIS_POSITION-25 "0.0281300000"
*MEAS_COND_AXIS_POSITION-26 "Open"
*MEAS_COND_AXIS_POSITION-27 "None"
*MEAS_COND_AXIS_POSITION-28 "None"
*MEAS_COND_AXIS_POSITION-29 "None"
*MEAS_COND_AXIS_POSITION-30 "38.0000000000"
*MEAS_COND_AXIS_UNIT-0 "deg"
*MEAS_COND_AXIS_UNIT-1 "deg"
*MEAS_COND_AXIS_UNIT-2 "deg"
*MEAS_COND_AXIS_UNIT-3 "mm"
*MEAS_COND_AXIS_UNIT-4 "deg"
*MEAS_COND_AXIS_UNIT-5 "deg"
*MEAS_COND_AXIS_UNIT-6 "deg"
*MEAS_COND_AXIS_UNIT-7 "mm"
*MEAS_COND_AXIS_UNIT-8 ""
*MEAS_COND_AXIS_UNIT-9 "pulse"
*MEAS_COND_AXIS_UNIT-10 ""
*MEAS_COND_AXIS_UNIT-11 ""
*MEAS_COND_AXIS_UNIT-12 "mm"
*MEAS_COND_AXIS_UNIT-13 "mm"
*MEAS_COND_AXIS_UNIT-14 ""
*MEAS_COND_AXIS_UNIT-15 ""
*MEAS_COND_AXIS_UNIT-16 ""
*MEAS_COND_AXIS_UNIT-17 ""
*MEAS_COND_AXIS_UNIT-18 ""
*MEAS_COND_AXIS_UNIT-19 ""
*MEAS_COND_AXIS_UNIT-20 ""
*MEAS_COND_AXIS_UNIT-21 ""
*MEAS_COND_AXIS_UNIT-22 ""
*MEAS_COND_AXIS_UNIT-23 "mm"
*MEAS_COND_AXIS_UNIT-24 "mm"
*MEAS_COND_AXIS_UNIT-25 "mm"
*MEAS_COND_AXIS_UNIT-26 ""
*MEAS_COND_AXIS_UNIT-27 ""
*MEAS_COND_AXIS_UNIT-28 ""
*MEAS_COND_AXIS_UNIT-29 ""
*MEAS_COND_AXIS_UNIT-30 "div"
*MEAS_COND_COUNTER_CNTLOSS_CORR "0.0000000000"
*MEAS_COND_COUNTER_PHABASE "38.0000000000"
*MEAS_COND_COUNTER_PHAWINDOW "16.0000000000"
*MEAS_COND_COUNTER_PHA_UNIT "div"
*MEAS_COND_COUNTER_TAUDIFF "30.0000000000"
*MEAS_COND_COUNTER_TAUINT "0.0000000000"
*MEAS_COND_IRRADIATION_MODE "OFF"
*MEAS_COND_IRRADIATION_WIDTH ""
*MEAS_COND_OPT_ATTR "集中法"
*MEAS_COND_OPT_NAME "@集中法"
*MEAS_COND_UNSYMMETRIC_MODE "OFF"
*MEAS_COND_XG_CURRENT "30.0000000000"
*MEAS_COND_XG_VOLTAGE "40.0000000000"
*MEAS_COND_XG_WAVE_TYPE "Ka"
*MEAS_DATA_COUNT "5001.0000000000"
*MEAS_SCAN_AXIS_X "2θ/θ"
*MEAS_SCAN_AXIS_X_INTERNAL "TwoThetaTheta"
*MEAS_SCAN_END_TIME "02/15/24 21:35:05"
*MEAS_SCAN_MODE "CONTINUOUS"
*MEAS_SCAN_MONITOR "0"
*MEAS_SCAN_RESOLUTION_X "0.0002"
*MEAS_SCAN_SPEED "2.5"
*MEAS_SCAN_SPEED_UNIT "deg/min"
*MEAS_SCAN_START "20.0000000000"
*MEAS_SCAN_START_TIME "02/15/24 21:13:40"
*MEAS_SCAN_STEP "0.0100000000"
*MEAS_SCAN_STOP "70.0000000000"
*MEAS_SCAN_UNIT_X "deg"
*MEAS_SCAN_UNIT_Y "counts"
*RAS_HEADER_END
*RAS_INT_START
20.0000 938.0000 1.0000
20.0400 876.0000 1.0000
20.0800 955.0000 1.0000
20.1200 954.0000 1.0000
20.1600 878.0000 1.0000
20.2000 889.0000 1.0000
20.2400 884.0000 1.0000
20.2800 903.0000 1.0000
20.3200 880.0000 1.0000
20.3600 931.0000 1.0000
20.4000 882.0000 1.0000
20.4400 870.0000 1.0000
20.4800 890.0000 1.0000
20.5200 924.0000 1.0000
20.5600 931.0000 1.0000
20.6000 878.0000 1.0000
20.6400 923.0000 1.0000
20.6800 897.0000 1.0000
20.7200 897.0000 1.0000
20.7600 863.0000 1.0000
20.8000 935.0000 1.0000
20.8400 902.0000 1.0000
20.8800 912.0000 1.0000
20.9200 882.0000 1.0000
20.9600 850.0000 1.0000
21.0000 933.0000 1.0000
21.0400 915.0000 1.0000
21.0800 922.0000 1.0000
21.1200 864.0000 1.0000
21.1600 909.0000 1.0000
21.2000 928.0000 1.0000
21.2400 925.0000 1.0000
21.2800 918.0000 1.0000
21.3200 898.0000 1.0000
21.3600 844.0000 1.0000
21.4000 883.0000 1.0000
21.4400 914.0000 1.0000
21.4800 854.0000 1.0000
21.5200 875.0000 1.0000
21.5600 850.0000 1.0000
21.6000 918.0000 1.0000
21.6400 959.0000 1.0000
21.6800 928.0000 1.0000
21.7200 866.0000 1.0000
21.7600 893.0000 1.0000
21.8000 860.0000 1.0000
21.8400 882.0000 1.0000
21.8800 874.0000 1.0000
21.9200 856.0000 1.0000
21.9600 901.0000 1.0000
22.0000 888.0000 1.0000
22.0400 882.0000 1.0000
22.0800 866.0000 1.0000
22.1200 849.0000 1.0000
22.1600 887.0000 1.0000
22.2000 889.0000 1.0000
22.2400 876.0000 1.0000
22.2800 838.0000 1.0000
22.3200 887.0000 1.0000
22.3600 836.0000 1.0000
22.4000 879.0000 1.0000
22.4400 899.0000 1.0000
22.4800 877.0000 1.0000
22.5200 822.0000 1.0000
22.5600 879.0000 1.0000
22.6000 875.0000 1.0000
22.6400 838.0000 1.0000
22.6800 854.0000 1.0000
22.7200 864.0000 1.0000
22.7600 877.0000 1.0000
22.8000 877.0000 1.0000
22.8400 832.0000 1.0000
22.8800 862.0000 1.0000
22.9200 846.0000 1.0000
22.9600 846.0000 1.0000
23.0000 893.0000 1.0000
23.0400 880.0000 1.0000
23.0800 867.0000 1.0000
23.1200 892.0000 1.0000
23.1600 834.0000 1.0000
23.2000 853.0000 1.0000
23.2400 865.0000 1.0000
23.2800 888.0000 1.0000
23.3200 857.0000 1.0000
23.3600 868.0000 1.0000
23.4000 828.0000 1.0000
23.4400 886.0000 1.0000
23.4800 877.0000 1.0000
23.5200 815.0000 1.0000
23.5600 875.0000 1.0000
23.6000 847.0000 1.0000
23.6400 872.0000 1.0000
23.6800 906.0000 1.0000
23.7200 836.0000 1.0000
23.7600 814.0000 1.0000
23.8000 834.0000 1.0000
23.8400 856.0000 1.0000
23.8800 833.0000 1.0000
23.9200 910.0000 1.0000
23.9600 940.0000 1.0000
24.0000 958.0000 1.0000
24.0400 1025.0000 1.0000
24.0800 994.0000 1.0000
24.1200 1062.0000 1.0000
24.1600 952.0000 1.0000
24.2000 962.0000 1.0000
24.2400 938.0000 1.0000
24.2800 873.0000 1.0000
24.3200 863.0000 1.0000
24.3600 871.0000 1.0000
24.4000 844.0000 1.0000
24.4400 820.0000 1.0000
24.4800 891.0000 1.0000
24.5200 824.0000 1.0000
24.5600 810.0000 1.0000
24.6000 808.0000 1.0000
24.6400 855.0000 1.0000
24.6800 800.0000 1.0000
24.7200 806.0000 1.0000
24.7600 841.0000 1.0000
24.8000 865.0000 1.0000
24.8400 839.0000 1.0000
24.8800 840.0000 1.0000
24.9200 820.0000 1.0000
24.9600 840.0000 1.0000
25.0000 856.0000 1.0000
25.0400 831.0000 1.0000
25.0800 827.0000 1.0000
25.1200 832.0000 1.0000
25.1600 823.0000 1.0000
25.2000 809.0000 1.0000
25.2400 823.0000 1.0000
25.2800 818.0000 1.0000
25.3200 805.0000 1.0000
25.3600 866.0000 1.0000
25.4000 838.0000 1.0000
25.4400 836.0000 1.0000
25.4800 881.0000 1.0000
25.5200 821.0000 1.0000
25.5600 839.0000 1.0000
25.6000 831.0000 1.0000
25.6400 767.0000 1.0000
25.6800 860.0000 1.0000
25.7200 794.0000 1.0000
25.7600 859.0000 1.0000
25.8000 871.0000 1.0000
25.8400 841.0000 1.0000
25.8800 797.0000 1.0000
25.9200 870.0000 1.0000
25.9600 848.0000 1.0000
26.0000 890.0000 1.0000
26.0400 855.0000 1.0000
26.0800 890.0000 1.0000
26.1200 875.0000 1.0000
26.1600 977.0000 1.0000
26.2000 977.0000 1.0000
26.2400 1019.0000 1.0000
26.2800 1135.0000 1.0000
26.3200 1204.0000 1.0000
26.3600 1340.0000 1.0000
26.4000 1404.0000 1.0000
26.4400 1510.0000 1.0000
26.4800 1494.0000 1.0000
26.5200 1440.0000 1.0000
26.5600 1240.0000 1.0000
26.6000 1230.0000 1.0000
26.6400 1139.0000 1.0000
26.6800 1029.0000 1.0000
26.7200 952.0000 1.0000
26.7600 954.0000 1.0000
26.8000 894.0000 1.0000
26.8400 914.0000 1.0000
26.8800 857.0000 1.0000
26.9200 855.0000 1.0000
26.9600 808.0000 1.0000
27.0000 845.0000 1.0000
27.0400 822.0000 1.0000
27.0800 794.0000 1.0000
27.1200 827.0000 1.0000
27.1600 803.0000 1.0000
27.2000 764.0000 1.0000
27.2400 778.0000 1.0000
27.2800 740.0000 1.0000
27.3200 748.0000 1.0000
27.3600 761.0000 1.0000
27.4000 758.0000 1.0000
27.4400 715.0000 1.0000
27.4800 761.0000 1.0000
27.5200 742.0000 1.0000
27.5600 728.0000 1.0000
27.6000 728.0000 1.0000
27.6400 754.0000 1.0000
27.6800 754.0000 1.0000
27.7200 782.0000 1.0000
27.7600 771.0000 1.0000
27.8000 759.0000 1.0000
27.8400 753.0000 1.0000
27.8800 759.0000 1.0000
27.9200 721.0000 1.0000
27.9600 684.0000 1.0000
28.0000 783.0000 1.0000
28.0400 732.0000 1.0000
28.0800 716.0000 1.0000
28.1200 741.0000 1.0000
28.1600 776.0000 1.0000
28.2000 742.0000 1.0000
28.2400 720.0000 1.0000
28.2800 733.0000 1.0000
28.3200 742.0000 1.0000
28.3600 734.0000 1.0000
28.4000 719.0000 1.0000
28.4400 680.0000 1.0000
28.4800 766.0000 1.0000
28.5200 706.0000 1.0000
28.5600 734.0000 1.0000
28.6000 680.0000 1.0000
28.6400 762.0000 1.0000
28.6800 707.0000 1.0000
28.7200 731.0000 1.0000
28.7600 694.0000 1.0000
28.8000 706.0000 1.0000
28.8400 727.0000 1.0000
28.8800 809.0000 1.0000
28.9200 708.0000 1.0000
28.9600 751.0000 1.0000
29.0000 687.0000 1.0000
29.0400 746.0000 1.0000
29.0800 740.0000 1.0000
29.1200 715.0000 1.0000
29.1600 701.0000 1.0000
29.2000 690.0000 1.0000
29.2400 734.0000 1.0000
29.2800 725.0000 1.0000
29.3200 670.0000 1.0000
29.3600 721.0000 1.0000
29.4000 720.0000 1.0000
29.4400 708.0000 1.0000
29.4800 684.0000 1.0000
29.5200 711.0000 1.0000
29.5600 682.0000 1.0000
29.6000 701.0000 1.0000
29.6400 656.0000 1.0000
29.6800 675.0000 1.0000
29.7200 695.0000 1.0000
29.7600 661.0000 1.0000
29.8000 694.0000 1.0000
29.8400 672.0000 1.0000
29.8800 690.0000 1.0000
29.9200 709.0000 1.0000
29.9600 645.0000 1.0000
30.0000 654.0000 1.0000
30.0400 700.0000 1.0000
30.0800 705.0000 1.0000
30.1200 655.0000 1.0000
30.1600 665.0000 1.0000
30.2000 650.0000 1.0000
30.2400 691.0000 1.0000
30.2800 765.0000 1.0000
30.3200 663.0000 1.0000
30.3600 680.0000 1.0000
30.4000 648.0000 1.0000
30.4400 641.0000 1.0000
30.4800 755.0000 1.0000
30.5200 664.0000 1.0000
30.5600 655.0000 1.0000
30.6000 632.0000 1.0000
30.6400 654.0000 1.0000
30.6800 676.0000 1.0000
30.7200 676.0000 1.0000
30.7600 631.0000 1.0000
30.8000 661.0000 1.0000
30.8400 641.0000 1.0000
30.8800 674.0000 1.0000
30.9200 656.0000 1.0000
30.9600 622.0000 1.0000
31.0000 662.0000 1.0000
31.0400 654.0000 1.0000
31.0800 650.0000 1.0000
31.1200 698.0000 1.0000
31.1600 652.0000 1.0000
31.2000 696.0000 1.0000
31.2400 641.0000 1.0000
31.2800 645.0000 1.0000
31.3200 601.0000 1.0000
31.3600 638.0000 1.0000
31.4000 629.0000 1.0000
31.4400 659.0000 1.0000
31.4800 653.0000 1.0000
31.5200 650.0000 1.0000
31.5600 634.0000 1.0000
31.6000 624.0000 1.0000
31.6400 653.0000 1.0000
31.6800 607.0000 1.0000
31.7200 654.0000 1.0000
31.7600 613.0000 1.0000
31.8000 654.0000 1.0000
31.8400 624.0000 1.0000
31.8800 627.0000 1.0000
31.9200 598.0000 1.0000
31.9600 611.0000 1.0000
32.0000 623.0000 1.0000
32.0400 643.0000 1.0000
32.0800 627.0000 1.0000
32.1200 596.0000 1.0000
32.1600 623.0000 1.0000
32.2000 608.0000 1.0000
32.2400 597.0000 1.0000
32.2800 639.0000 1.0000
32.3200 588.0000 1.0000
32.3600 612.0000 1.0000
32.4000 641.0000 1.0000
32.4400 585.0000 1.0000
32.4800 629.0000 1.0000
32.5200 618.0000 1.0000
32.5600 632.0000 1.0000
32.6000 661.0000 1.0000
32.6400 629.0000 1.0000
32.6800 629.0000 1.0000
32.7200 591.0000 1.0000
32.7600 621.0000 1.0000
32.8000 608.0000 1.0000
32.8400 586.0000 1.0000
32.8800 687.0000 1.0000
32.9200 699.0000 1.0000
32.9600 695.0000 1.0000
33.0000 708.0000 1.0000
33.0400 781.0000 1.0000
33.0800 868.0000 1.0000
33.1200 877.0000 1.0000
33.1600 840.0000 1.0000
33.2000 799.0000 1.0000
33.2400 722.0000 1.0000
33.2800 651.0000 1.0000
33.3200 661.0000 1.0000
33.3600 704.0000 1.0000
33.4000 648.0000 1.0000
33.4400 694.0000 1.0000
33.4800 725.0000 1.0000
33.5200 729.0000 1.0000
33.5600 698.0000 1.0000
33.6000 748.0000 1.0000
33.6400 775.0000 1.0000
33.6800 801.0000 1.0000
33.7200 780.0000 1.0000
33.7600 732.0000 1.0000
33.8000 727.0000 1.0000
33.8400 722.0000 1.0000
33.8800 685.0000 1.0000
33.9200 672.0000 1.0000
33.9600 632.0000 1.0000
34.0000 638.0000 1.0000
34.0400 628.0000 1.0000
34.0800 613.0000 1.0000
34.1200 595.0000 1.0000
34.1600 612.0000 1.0000
34.2000 556.0000 1.0000
34.2400 602.0000 1.0000
34.2800 594.0000 1.0000
34.3200 551.0000 1.0000
34.3600 559.0000 1.0000
34.4000 543.0000 1.0000
34.4400 569.0000 1.0000
34.4800 568.0000 1.0000
34.5200 533.0000 1.0000
34.5600 578.0000 1.0000
34.6000 576.0000 1.0000
34.6400 567.0000 1.0000
34.6800 546.0000 1.0000
34.7200 590.0000 1.0000
34.7600 563.0000 1.0000
34.8000 571.0000 1.0000
34.8400 585.0000 1.0000
34.8800 577.0000 1.0000
34.9200 519.0000 1.0000
34.9600 542.0000 1.0000
35.0000 558.0000 1.0000
35.0400 548.0000 1.0000
35.0800 581.0000 1.0000
35.1200 541.0000 1.0000
35.1600 570.0000 1.0000
35.2000 530.0000 1.0000
35.2400 589.0000 1.0000
35.2800 593.0000 1.0000
35.3200 627.0000 1.0000
35.3600 658.0000 1.0000
35.4000 733.0000 1.0000
35.4400 761.0000 1.0000
35.4800 909.0000 1.0000
35.5200 1133.0000 1.0000
35.5600 1329.0000 1.0000
35.6000 1330.0000 1.0000
35.6400 1244.0000 1.0000
35.6800 1128.0000 1.0000
35.7200 957.0000 1.0000
35.7600 736.0000 1.0000
35.8000 668.0000 1.0000
35.8400 571.0000 1.0000
35.8800 555.0000 1.0000
35.9200 540.0000 1.0000
35.9600 524.0000 1.0000
36.0000 545.0000 1.0000
36.0400 533.0000 1.0000
36.0800 499.0000 1.0000
36.1200 521.0000 1.0000
36.1600 521.0000 1.0000
36.2000 504.0000 1.0000
36.2400 539.0000 1.0000
36.2800 532.0000 1.0000
36.3200 493.0000 1.0000
36.3600 529.0000 1.0000
36.4000 515.0000 1.0000
36.4400 530.0000 1.0000
36.4800 517.0000 1.0000
36.5200 516.0000 1.0000
36.5600 512.0000 1.0000
36.6000 552.0000 1.0000
36.6400 520.0000 1.0000
36.6800 520.0000 1.0000
36.7200 532.0000 1.0000
36.7600 501.0000 1.0000
36.8000 536.0000 1.0000
36.8400 473.0000 1.0000
36.8800 507.0000 1.0000
36.9200 571.0000 1.0000
36.9600 528.0000 1.0000
37.0000 523.0000 1.0000
37.0400 536.0000 1.0000
37.0800 548.0000 1.0000
37.1200 559.0000 1.0000
37.1600 571.0000 1.0000
37.2000 569.0000 1.0000
37.2400 572.0000 1.0000
37.2800 598.0000 1.0000
37.3200 669.0000 1.0000
37.3600 641.0000 1.0000
37.4000 737.0000 1.0000
37.4400 833.0000 1.0000
37.4800 1012.0000 1.0000
37.5200 1172.0000 1.0000
37.5600 1430.0000 1.0000
37.6000 1729.0000 1.0000
37.6400 2192.0000 1.0000
37.6800 2751.0000 1.0000
37.7200 3077.0000 1.0000
37.7600 3104.0000 1.0000
37.8000 2848.0000 1.0000
37.8400 2372.0000 1.0000
37.8800 1961.0000 1.0000
37.9200 1527.0000 1.0000
37.9600 1184.0000 1.0000
38.0000 951.0000 1.0000
38.0400 814.0000 1.0000
38.0800 740.0000 1.0000
38.1200 644.0000 1.0000
38.1600 624.0000 1.0000
38.2000 603.0000 1.0000
38.2400 572.0000 1.0000
38.2800 541.0000 1.0000
38.3200 536.0000 1.0000
38.3600 512.0000 1.0000
38.4000 489.0000 1.0000
38.4400 506.0000 1.0000
38.4800 484.0000 1.0000
38.5200 504.0000 1.0000
38.5600 503.0000 1.0000
38.6000 523.0000 1.0000
38.6400 479.0000 1.0000
38.6800 430.0000 1.0000
38.7200 466.0000 1.0000
38.7600 488.0000 1.0000
38.8000 508.0000 1.0000
38.8400 461.0000 1.0000
38.8800 464.0000 1.0000
38.9200 446.0000 1.0000
38.9600 448.0000 1.0000
39.0000 440.0000 1.0000
39.0400 456.0000 1.0000
39.0800 439.0000 1.0000
39.1200 435.0000 1.0000
39.1600 428.0000 1.0000
39.2000 424.0000 1.0000
39.2400 475.0000 1.0000
39.2800 464.0000 1.0000
39.3200 467.0000 1.0000
39.3600 454.0000 1.0000
39.4000 414.0000 1.0000
39.4400 436.0000 1.0000
39.4800 467.0000 1.0000
39.5200 438.0000 1.0000
39.5600 453.0000 1.0000
39.6000 456.0000 1.0000
39.6400 440.0000 1.0000
39.6800 424.0000 1.0000
39.7200 430.0000 1.0000
39.7600 453.0000 1.0000
39.8000 421.0000 1.0000
39.8400 430.0000 1.0000
39.8800 430.0000 1.0000
39.9200 424.0000 1.0000
39.9600 455.0000 1.0000
40.0000 468.0000 1.0000
40.0400 441.0000 1.0000
40.0800 411.0000 1.0000
40.1200 423.0000 1.0000
40.1600 391.0000 1.0000
40.2000 435.0000 1.0000
40.2400 412.0000 1.0000
40.2800 433.0000 1.0000
40.3200 415.0000 1.0000
40.3600 460.0000 1.0000
40.4000 427.0000 1.0000
40.4400 418.0000 1.0000
40.4800 435.0000 1.0000
40.5200 453.0000 1.0000
40.5600 472.0000 1.0000
40.6000 434.0000 1.0000
40.6400 443.0000 1.0000
40.6800 454.0000 1.0000
40.7200 491.0000 1.0000
40.7600 517.0000 1.0000
40.8000 495.0000 1.0000
40.8400 495.0000 1.0000
40.8800 496.0000 1.0000
40.9200 467.0000 1.0000
40.9600 455.0000 1.0000
41.0000 427.0000 1.0000
41.0400 442.0000 1.0000
41.0800 427.0000 1.0000
41.1200 436.0000 1.0000
41.1600 458.0000 1.0000
41.2000 426.0000 1.0000
41.2400 416.0000 1.0000
41.2800 413.0000 1.0000
41.3200 407.0000 1.0000
41.3600 366.0000 1.0000
41.4000 385.0000 1.0000
41.4400 426.0000 1.0000
41.4800 382.0000 1.0000
41.5200 413.0000 1.0000
41.5600 403.0000 1.0000
41.6000 428.0000 1.0000
41.6400 411.0000 1.0000
41.6800 399.0000 1.0000
41.7200 412.0000 1.0000
41.7600 422.0000 1.0000
41.8000 417.0000 1.0000
41.8400 429.0000 1.0000
41.8800 425.0000 1.0000
41.9200 429.0000 1.0000
41.9600 415.0000 1.0000
42.0000 425.0000 1.0000
42.0400 401.0000 1.0000
42.0800 420.0000 1.0000
42.1200 411.0000 1.0000
42.1600 408.0000 1.0000
42.2000 377.0000 1.0000
42.2400 390.0000 1.0000
42.2800 417.0000 1.0000
42.3200 417.0000 1.0000
42.3600 393.0000 1.0000
42.4000 428.0000 1.0000
42.4400 414.0000 1.0000
42.4800 425.0000 1.0000
42.5200 408.0000 1.0000
42.5600 393.0000 1.0000
42.6000 393.0000 1.0000
42.6400 449.0000 1.0000
42.6800 401.0000 1.0000
42.7200 457.0000 1.0000
42.7600 416.0000 1.0000
42.8000 411.0000 1.0000
42.8400 423.0000 1.0000
42.8800 419.0000 1.0000
42.9200 431.0000 1.0000
42.9600 382.0000 1.0000
43.0000 420.0000 1.0000
43.0400 426.0000 1.0000
43.0800 380.0000 1.0000
43.1200 405.0000 1.0000
43.1600 405.0000 1.0000
43.2000 403.0000 1.0000
43.2400 358.0000 1.0000
43.2800 396.0000 1.0000
43.3200 414.0000 1.0000
43.3600 363.0000 1.0000
43.4000 425.0000 1.0000
43.4400 388.0000 1.0000
43.4800 411.0000 1.0000
43.5200 393.0000 1.0000
43.5600 376.0000 1.0000
43.6000 407.0000 1.0000
43.6400 376.0000 1.0000
43.6800 404.0000 1.0000
43.7200 386.0000 1.0000
43.7600 443.0000 1.0000
43.8000 404.0000 1.0000
43.8400 379.0000 1.0000
43.8800 389.0000 1.0000
43.9200 397.0000 1.0000
43.9600 382.0000 1.0000
44.0000 423.0000 1.0000
44.0400 378.0000 1.0000
44.0800 386.0000 1.0000
44.1200 397.0000 1.0000
44.1600 422.0000 1.0000
44.2000 406.0000 1.0000
44.2400 381.0000 1.0000
44.2800 393.0000 1.0000
44.3200 385.0000 1.0000
44.3600 386.0000 1.0000
44.4000 389.0000 1.0000
44.4400 396.0000 1.0000
44.4800 366.0000 1.0000
44.5200 392.0000 1.0000
44.5600 389.0000 1.0000
44.6000 414.0000 1.0000
44.6400 400.0000 1.0000
44.6800 365.0000 1.0000
44.7200 374.0000 1.0000
44.7600 398.0000 1.0000
44.8000 379.0000 1.0000
44.8400 381.0000 1.0000
44.8800 415.0000 1.0000
44.9200 413.0000 1.0000
44.9600 393.0000 1.0000
45.0000 375.0000 1.0000
45.0400 339.0000 1.0000
45.0800 365.0000 1.0000
45.1200 392.0000 1.0000
45.1600 369.0000 1.0000
45.2000 398.0000 1.0000
45.2400 370.0000 1.0000
45.2800 352.0000 1.0000
45.3200 380.0000 1.0000
45.3600 372.0000 1.0000
45.4000 365.0000 1.0000
45.4400 409.0000 1.0000
45.4800 383.0000 1.0000
45.5200 398.0000 1.0000
45.5600 379.0000 1.0000
45.6000 363.0000 1.0000
45.6400 317.0000 1.0000
45.6800 387.0000 1.0000
45.7200 346.0000 1.0000
45.7600 377.0000 1.0000
45.8000 351.0000 1.0000
45.8400 358.0000 1.0000
45.8800 364.0000 1.0000
45.9200 391.0000 1.0000
45.9600 347.0000 1.0000
46.0000 375.0000 1.0000
46.0400 373.0000 1.0000
46.0800 374.0000 1.0000
46.1200 355.0000 1.0000
46.1600 345.0000 1.0000
46.2000 389.0000 1.0000
46.2400 400.0000 1.0000
46.2800 381.0000 1.0000
46.3200 372.0000 1.0000
46.3600 384.0000 1.0000
46.4000 381.0000 1.0000
46.4400 393.0000 1.0000
46.4800 349.0000 1.0000
46.5200 367.0000 1.0000
46.5600 334.0000 1.0000
46.6000 371.0000 1.0000
46.6400 356.0000 1.0000
46.6800 385.0000 1.0000
46.7200 357.0000 1.0000
46.7600 390.0000 1.0000
46.8000 357.0000 1.0000
46.8400 384.0000 1.0000
46.8800 357.0000 1.0000
46.9200 371.0000 1.0000
46.9600 354.0000 1.0000
47.0000 346.0000 1.0000
47.0400 352.0000 1.0000
47.0800 381.0000 1.0000
47.1200 365.0000 1.0000
47.1600 331.0000 1.0000
47.2000 344.0000 1.0000
47.2400 372.0000 1.0000
47.2800 373.0000 1.0000
47.3200 365.0000 1.0000
47.3600 337.0000 1.0000
47.4000 394.0000 1.0000
47.4400 376.0000 1.0000
47.4800 389.0000 1.0000
47.5200 350.0000 1.0000
47.5600 340.0000 1.0000
47.6000 356.0000 1.0000
47.6400 359.0000 1.0000
47.6800 364.0000 1.0000
47.7200 353.0000 1.0000
47.7600 368.0000 1.0000
47.8000 355.0000 1.0000
47.8400 375.0000 1.0000
47.8800 344.0000 1.0000
47.9200 346.0000 1.0000
47.9600 357.0000 1.0000
48.0000 344.0000 1.0000
48.0400 361.0000 1.0000
48.0800 350.0000 1.0000
48.1200 334.0000 1.0000
48.1600 369.0000 1.0000
48.2000 344.0000 1.0000
48.2400 367.0000 1.0000
48.2800 372.0000 1.0000
48.3200 343.0000 1.0000
48.3600 349.0000 1.0000
48.4000 327.0000 1.0000
48.4400 342.0000 1.0000
48.4800 344.0000 1.0000
48.5200 363.0000 1.0000
48.5600 366.0000 1.0000
48.6000 353.0000 1.0000
48.6400 394.0000 1.0000
48.6800 346.0000 1.0000
48.7200 349.0000 1.0000
48.7600 363.0000 1.0000
48.8000 360.0000 1.0000
48.8400 347.0000 1.0000
48.8800 336.0000 1.0000
48.9200 340.0000 1.0000
48.9600 350.0000 1.0000
49.0000 335.0000 1.0000
49.0400 333.0000 1.0000
49.0800 350.0000 1.0000
49.1200 359.0000 1.0000
49.1600 373.0000 1.0000
49.2000 378.0000 1.0000
49.2400 350.0000 1.0000
49.2800 417.0000 1.0000
49.3200 388.0000 1.0000
49.3600 410.0000 1.0000
49.4000 440.0000 1.0000
49.4400 491.0000 1.0000
49.4800 415.0000 1.0000
49.5200 426.0000 1.0000
49.5600 419.0000 1.0000
49.6000 374.0000 1.0000
49.6400 354.0000 1.0000
49.6800 399.0000 1.0000
49.7200 336.0000 1.0000
49.7600 340.0000 1.0000
49.8000 366.0000 1.0000
49.8400 338.0000 1.0000
49.8800 352.0000 1.0000
49.9200 367.0000 1.0000
49.9600 346.0000 1.0000
50.0000 334.0000 1.0000
50.0400 335.0000 1.0000
50.0800 344.0000 1.0000
50.1200 349.0000 1.0000
50.1600 360.0000 1.0000
50.2000 317.0000 1.0000
50.2400 342.0000 1.0000
50.2800 355.0000 1.0000
50.3200 357.0000 1.0000
50.3600 339.0000 1.0000
50.4000 361.0000 1.0000
50.4400 331.0000 1.0000
50.4800 347.0000 1.0000
50.5200 338.0000 1.0000
50.5600 345.0000 1.0000
50.6000 336.0000 1.0000
50.6400 367.0000 1.0000
50.6800 343.0000 1.0000
50.7200 340.0000 1.0000
50.7600 358.0000 1.0000
50.8000 349.0000 1.0000
50.8400 362.0000 1.0000
50.8800 369.0000 1.0000
50.9200 398.0000 1.0000
50.9600 337.0000 1.0000
51.0000 403.0000 1.0000
51.0400 361.0000 1.0000
51.0800 358.0000 1.0000
51.1200 406.0000 1.0000
51.1600 410.0000 1.0000
51.2000 396.0000 1.0000
51.2400 447.0000 1.0000
51.2800 553.0000 1.0000
51.3200 569.0000 1.0000
51.3600 627.0000 1.0000
51.4000 806.0000 1.0000
51.4400 940.0000 1.0000
51.4800 997.0000 1.0000
51.5200 921.0000 1.0000
51.5600 917.0000 1.0000
51.6000 813.0000 1.0000
51.6400 762.0000 1.0000
51.6800 622.0000 1.0000
51.7200 521.0000 1.0000
51.7600 485.0000 1.0000
51.8000 463.0000 1.0000
51.8400 439.0000 1.0000
51.8800 410.0000 1.0000
51.9200 393.0000 1.0000
51.9600 395.0000 1.0000
52.0000 387.0000 1.0000
52.0400 397.0000 1.0000
52.0800 362.0000 1.0000
52.1200 351.0000 1.0000
52.1600 389.0000 1.0000
52.2000 374.0000 1.0000
52.2400 349.0000 1.0000
52.2800 321.0000 1.0000
52.3200 341.0000 1.0000
52.3600 330.0000 1.0000
52.4000 338.0000 1.0000
52.4400 341.0000 1.0000
52.4800 342.0000 1.0000
52.5200 357.0000 1.0000
52.5600 315.0000 1.0000
52.6000 332.0000 1.0000
52.6400 353.0000 1.0000
52.6800 347.0000 1.0000
52.7200 351.0000 1.0000
52.7600 310.0000 1.0000
52.8000 317.0000 1.0000
52.8400 329.0000 1.0000
52.8800 343.0000 1.0000
52.9200 320.0000 1.0000
52.9600 322.0000 1.0000
53.0000 328.0000 1.0000
53.0400 327.0000 1.0000
53.0800 324.0000 1.0000
53.1200 342.0000 1.0000
53.1600 326.0000 1.0000
53.2000 313.0000 1.0000
53.2400 345.0000 1.0000
53.2800 342.0000 1.0000
53.3200 319.0000 1.0000
53.3600 327.0000 1.0000
53.4000 343.0000 1.0000
53.4400 345.0000 1.0000
53.4800 339.0000 1.0000
53.5200 314.0000 1.0000
53.5600 349.0000 1.0000
53.6000 324.0000 1.0000
53.6400 328.0000 1.0000
53.6800 313.0000 1.0000
53.7200 347.0000 1.0000
53.7600 341.0000 1.0000
53.8000 308.0000 1.0000
53.8400 366.0000 1.0000
53.8800 350.0000 1.0000
53.9200 400.0000 1.0000
53.9600 373.0000 1.0000
54.0000 387.0000 1.0000
54.0400 382.0000 1.0000
54.0800 401.0000 1.0000
54.1200 391.0000 1.0000
54.1600 411.0000 1.0000
54.2000 362.0000 1.0000
54.2400 375.0000 1.0000
54.2800 353.0000 1.0000
54.3200 386.0000 1.0000
54.3600 344.0000 1.0000
54.4000 362.0000 1.0000
54.4400 373.0000 1.0000
54.4800 355.0000 1.0000
54.5200 388.0000 1.0000
54.5600 413.0000 1.0000
54.6000 355.0000 1.0000
54.6400 378.0000 1.0000
54.6800 384.0000 1.0000
54.7200 392.0000 1.0000
54.7600 370.0000 1.0000
54.8000 363.0000 1.0000
54.8400 336.0000 1.0000
54.8800 325.0000 1.0000
54.9200 352.0000 1.0000
54.9600 346.0000 1.0000
55.0000 360.0000 1.0000
55.0400 326.0000 1.0000
55.0800 329.0000 1.0000
55.1200 340.0000 1.0000
55.1600 373.0000 1.0000
55.2000 337.0000 1.0000
55.2400 322.0000 1.0000
55.2800 344.0000 1.0000
55.3200 331.0000 1.0000
55.3600 344.0000 1.0000
55.4000 321.0000 1.0000
55.4400 332.0000 1.0000
55.4800 308.0000 1.0000
55.5200 347.0000 1.0000
55.5600 315.0000 1.0000
55.6000 331.0000 1.0000
55.6400 350.0000 1.0000
55.6800 329.0000 1.0000
55.7200 326.0000 1.0000
55.7600 329.0000 1.0000
55.8000 320.0000 1.0000
55.8400 317.0000 1.0000
55.8800 305.0000 1.0000
55.9200 350.0000 1.0000
55.9600 358.0000 1.0000
56.0000 321.0000 1.0000
56.0400 318.0000 1.0000
56.0800 323.0000 1.0000
56.1200 328.0000 1.0000
56.1600 315.0000 1.0000
56.2000 306.0000 1.0000
56.2400 301.0000 1.0000
56.2800 323.0000 1.0000
56.3200 317.0000 1.0000
56.3600 295.0000 1.0000
56.4000 336.0000 1.0000
56.4400 336.0000 1.0000
56.4800 311.0000 1.0000
56.5200 319.0000 1.0000
56.5600 293.0000 1.0000
56.6000 334.0000 1.0000
56.6400 295.0000 1.0000
56.6800 311.0000 1.0000
56.7200 326.0000 1.0000
56.7600 321.0000 1.0000
56.8000 288.0000 1.0000
56.8400 319.0000 1.0000
56.8800 314.0000 1.0000
56.9200 325.0000 1.0000
56.9600 311.0000 1.0000
57.0000 313.0000 1.0000
57.0400 305.0000 1.0000
57.0800 310.0000 1.0000
57.1200 314.0000 1.0000
57.1600 348.0000 1.0000
57.2000 319.0000 1.0000
57.2400 327.0000 1.0000
57.2800 298.0000 1.0000
57.3200 342.0000 1.0000
57.3600 321.0000 1.0000
57.4000 319.0000 1.0000
57.4400 348.0000 1.0000
57.4800 333.0000 1.0000
57.5200 336.0000 1.0000
57.5600 325.0000 1.0000
57.6000 344.0000 1.0000
57.6400 332.0000 1.0000
57.6800 304.0000 1.0000
57.7200 303.0000 1.0000
57.7600 337.0000 1.0000
57.8000 334.0000 1.0000
57.8400 291.0000 1.0000
57.8800 323.0000 1.0000
57.9200 323.0000 1.0000
57.9600 323.0000 1.0000
58.0000 314.0000 1.0000
58.0400 329.0000 1.0000
58.0800 318.0000 1.0000
58.1200 301.0000 1.0000
58.1600 298.0000 1.0000
58.2000 293.0000 1.0000
58.2400 324.0000 1.0000
58.2800 330.0000 1.0000
58.3200 313.0000 1.0000
58.3600 313.0000 1.0000
58.4000 320.0000 1.0000
58.4400 341.0000 1.0000
58.4800 300.0000 1.0000
58.5200 328.0000 1.0000
58.5600 331.0000 1.0000
58.6000 337.0000 1.0000
58.6400 338.0000 1.0000
58.6800 301.0000 1.0000
58.7200 355.0000 1.0000
58.7600 285.0000 1.0000
58.8000 317.0000 1.0000
58.8400 314.0000 1.0000
58.8800 354.0000 1.0000
58.9200 316.0000 1.0000
58.9600 298.0000 1.0000
59.0000 315.0000 1.0000
59.0400 314.0000 1.0000
59.0800 335.0000 1.0000
59.1200 334.0000 1.0000
59.1600 311.0000 1.0000
59.2000 298.0000 1.0000
59.2400 323.0000 1.0000
59.2800 308.0000 1.0000
59.3200 318.0000 1.0000
59.3600 321.0000 1.0000
59.4000 340.0000 1.0000
59.4400 294.0000 1.0000
59.4800 296.0000 1.0000
59.5200 304.0000 1.0000
59.5600 292.0000 1.0000
59.6000 294.0000 1.0000
59.6400 319.0000 1.0000
59.6800 305.0000 1.0000
59.7200 278.0000 1.0000
59.7600 309.0000 1.0000
59.8000 302.0000 1.0000
59.8400 305.0000 1.0000
59.8800 311.0000 1.0000
59.9200 300.0000 1.0000
59.9600 326.0000 1.0000
60.0000 298.0000 1.0000
60.0400 308.0000 1.0000
60.0800 310.0000 1.0000
60.1200 317.0000 1.0000
60.1600 300.0000 1.0000
60.2000 306.0000 1.0000
60.2400 324.0000 1.0000
60.2800 318.0000 1.0000
60.3200 301.0000 1.0000
60.3600 320.0000 1.0000
60.4000 311.0000 1.0000
60.4400 339.0000 1.0000
60.4800 312.0000 1.0000
60.5200 354.0000 1.0000
60.5600 328.0000 1.0000
60.6000 304.0000 1.0000
60.6400 293.0000 1.0000
60.6800 302.0000 1.0000
60.7200 285.0000 1.0000
60.7600 323.0000 1.0000
60.8000 300.0000 1.0000
60.8400 327.0000 1.0000
60.8800 320.0000 1.0000
60.9200 335.0000 1.0000
60.9600 354.0000 1.0000
61.0000 330.0000 1.0000
61.0400 350.0000 1.0000
61.0800 355.0000 1.0000
61.1200 375.0000 1.0000
61.1600 367.0000 1.0000
61.2000 341.0000 1.0000
61.2400 361.0000 1.0000
61.2800 385.0000 1.0000
61.3200 406.0000 1.0000
61.3600 426.0000 1.0000
61.4000 500.0000 1.0000
61.4400 477.0000 1.0000
61.4800 534.0000 1.0000
61.5200 571.0000 1.0000
61.5600 579.0000 1.0000
61.6000 609.0000 1.0000
61.6400 591.0000 1.0000
61.6800 564.0000 1.0000
61.7200 544.0000 1.0000
61.7600 518.0000 1.0000
61.8000 501.0000 1.0000
61.8400 474.0000 1.0000
61.8800 442.0000 1.0000
61.9200 413.0000 1.0000
61.9600 424.0000 1.0000
62.0000 372.0000 1.0000
62.0400 369.0000 1.0000
62.0800 364.0000 1.0000
62.1200 373.0000 1.0000
62.1600 373.0000 1.0000
62.2000 372.0000 1.0000
62.2400 345.0000 1.0000
62.2800 394.0000 1.0000
62.3200 398.0000 1.0000
62.3600 425.0000 1.0000
62.4000 371.0000 1.0000
62.4400 393.0000 1.0000
62.4800 400.0000 1.0000
62.5200 369.0000 1.0000
62.5600 366.0000 1.0000
62.6000 372.0000 1.0000
62.6400 341.0000 1.0000
62.6800 353.0000 1.0000
62.7200 323.0000 1.0000
62.7600 318.0000 1.0000
62.8000 335.0000 1.0000
62.8400 326.0000 1.0000
62.8800 300.0000 1.0000
62.9200 288.0000 1.0000
62.9600 304.0000 1.0000
63.0000 306.0000 1.0000
63.0400 317.0000 1.0000
63.0800 322.0000 1.0000
63.1200 311.0000 1.0000
63.1600 314.0000 1.0000
63.2000 335.0000 1.0000
63.2400 331.0000 1.0000
63.2800 330.0000 1.0000
63.3200 300.0000 1.0000
63.3600 330.0000 1.0000
63.4000 328.0000 1.0000
63.4400 324.0000 1.0000
63.4800 317.0000 1.0000
63.5200 319.0000 1.0000
63.5600 312.0000 1.0000
63.6000 325.0000 1.0000
63.6400 295.0000 1.0000
63.6800 330.0000 1.0000
63.7200 353.0000 1.0000
63.7600 334.0000 1.0000
63.8000 321.0000 1.0000
63.8400 360.0000 1.0000
63.8800 386.0000 1.0000
63.9200 419.0000 1.0000
63.9600 449.0000 1.0000
64.0000 433.0000 1.0000
64.0400 432.0000 1.0000
64.0800 381.0000 1.0000
64.1200 419.0000 1.0000
64.1600 367.0000 1.0000
64.2000 371.0000 1.0000
64.2400 361.0000 1.0000
64.2800 305.0000 1.0000
64.3200 341.0000 1.0000
64.3600 346.0000 1.0000
64.4000 309.0000 1.0000
64.4400 360.0000 1.0000
64.4800 345.0000 1.0000
64.5200 303.0000 1.0000
64.5600 324.0000 1.0000
64.6000 323.0000 1.0000
64.6400 298.0000 1.0000
64.6800 320.0000 1.0000
64.7200 328.0000 1.0000
64.7600 343.0000 1.0000
64.8000 341.0000 1.0000
64.8400 323.0000 1.0000
64.8800 308.0000 1.0000
64.9200 341.0000 1.0000
64.9600 364.0000 1.0000
65.0000 336.0000 1.0000
65.0400 374.0000 1.0000
65.0800 364.0000 1.0000
65.1200 406.0000 1.0000
65.1600 378.0000 1.0000
65.2000 392.0000 1.0000
65.2400 405.0000 1.0000
65.2800 448.0000 1.0000
65.3200 498.0000 1.0000
65.3600 561.0000 1.0000
65.4000 706.0000 1.0000
65.4400 794.0000 1.0000
65.4800 851.0000 1.0000
65.5200 901.0000 1.0000
65.5600 843.0000 1.0000
65.6000 777.0000 1.0000
65.6400 701.0000 1.0000
65.6800 693.0000 1.0000
65.7200 685.0000 1.0000
65.7600 609.0000 1.0000
65.8000 546.0000 1.0000
65.8400 465.0000 1.0000
65.8800 448.0000 1.0000
65.9200 433.0000 1.0000
65.9600 382.0000 1.0000
66.0000 364.0000 1.0000
66.0400 358.0000 1.0000
66.0800 355.0000 1.0000
66.1200 345.0000 1.0000
66.1600 329.0000 1.0000
66.2000 334.0000 1.0000
66.2400 308.0000 1.0000
66.2800 334.0000 1.0000
66.3200 336.0000 1.0000
66.3600 346.0000 1.0000
66.4000 280.0000 1.0000
66.4400 297.0000 1.0000
66.4800 306.0000 1.0000
66.5200 306.0000 1.0000
66.5600 299.0000 1.0000
66.6000 295.0000 1.0000
66.6400 286.0000 1.0000
66.6800 297.0000 1.0000
66.7200 293.0000 1.0000
66.7600 300.0000 1.0000
66.8000 300.0000 1.0000
66.8400 308.0000 1.0000
66.8800 300.0000 1.0000
66.9200 303.0000 1.0000
66.9600 282.0000 1.0000
67.0000 281.0000 1.0000
67.0400 262.0000 1.0000
67.0800 285.0000 1.0000
67.1200 278.0000 1.0000
67.1600 277.0000 1.0000
67.2000 300.0000 1.0000
67.2400 275.0000 1.0000
67.2800 307.0000 1.0000
67.3200 270.0000 1.0000
67.3600 307.0000 1.0000
67.4000 280.0000 1.0000
67.4400 283.0000 1.0000
67.4800 291.0000 1.0000
67.5200 270.0000 1.0000
67.5600 287.0000 1.0000
67.6000 308.0000 1.0000
67.6400 267.0000 1.0000
67.6800 307.0000 1.0000
67.7200 291.0000 1.0000
67.7600 289.0000 1.0000
67.8000 287.0000 1.0000
67.8400 277.0000 1.0000
67.8800 302.0000 1.0000
67.9200 262.0000 1.0000
67.9600 266.0000 1.0000
68.0000 268.0000 1.0000
68.0400 273.0000 1.0000
68.0800 264.0000 1.0000
68.1200 275.0000 1.0000
68.1600 289.0000 1.0000
68.2000 303.0000 1.0000
68.2400 292.0000 1.0000
68.2800 273.0000 1.0000
68.3200 270.0000 1.0000
68.3600 284.0000 1.0000
68.4000 252.0000 1.0000
68.4400 271.0000 1.0000
68.4800 281.0000 1.0000
68.5200 276.0000 1.0000
68.5600 302.0000 1.0000
68.6000 264.0000 1.0000
68.6400 277.0000 1.0000
68.6800 279.0000 1.0000
68.7200 284.0000 1.0000
68.7600 293.0000 1.0000
68.8000 270.0000 1.0000
68.8400 296.0000 1.0000
68.8800 293.0000 1.0000
68.9200 278.0000 1.0000
68.9600 262.0000 1.0000
69.0000 262.0000 1.0000
69.0400 277.0000 1.0000
69.0800 287.0000 1.0000
69.1200 280.0000 1.0000
69.1600 278.0000 1.0000
69.2000 291.0000 1.0000
69.2400 275.0000 1.0000
69.2800 267.0000 1.0000
69.3200 280.0000 1.0000
69.3600 290.0000 1.0000
69.4000 262.0000 1.0000
69.4400 273.0000 1.0000
69.4800 289.0000 1.0000
69.5200 273.0000 1.0000
69.5600 274.0000 1.0000
69.6000 315.0000 1.0000
69.6400 273.0000 1.0000
69.6800 272.0000 1.0000
69.7200 289.0000 1.0000
69.7600 278.0000 1.0000
69.8000 285.0000 1.0000
69.8400 237.0000 1.0000
69.8800 260.0000 1.0000
69.9200 256.0000 1.0000
69.9600 263.0000 1.0000
70.0000 257.0000 1.0000
*RAS_INT_END
*RAS_TEMPERATURE_START
*RAS_TEMPERATURE_END
*RAS_DATA_END