File: Data/Dataset2_Water_Organic/4_XRD/No_59_2312020240119_MeOH_11.ras
*RAS_DATA_START
*RAS_HEADER_START
*DISP_FMT_X "%.2f"
*DISP_FMT_Y "%.0f"
*DISP_FULLSCALE "15070.0000000000"
*DISP_LINE_COLOR "255.0000000000"
*DISP_LINE_STYLE "0.0000000000"
*DISP_LINE_WIDTH "0.2500000000"
*DISP_NOTE "測定データ-14"
*DISP_OFFSET_Y "0.0000000000"
*DISP_PEAKSEARCH_UNIT_Y "cps"
*DISP_RANGE_BOTTOM "0.0000000000"
*DISP_RANGE_LEFT "20.0000000000"
*DISP_RANGE_LOGCUTOFF "0.0100000000"
*DISP_RANGE_RIGHT "70.0000000000"
*DISP_RANGE_TOP "15070.0000000000"
*DISP_SCALE_MODE_Y "0.0000000000"
*DISP_TAB_NAME "2θ/θ"
*DISP_TITLE_Y "強度"
*DISP_UNIT_Y "cps"
*DISP_WINDOW_NAME "MSG_MACROENGINE"
*FILE_COMMENT " "
*FILE_MD5 ""
*FILE_MEMO " "
*FILE_OPERATOR "Administrator"
*FILE_SAMPLE " "
*FILE_TYPE "RAS_RAW"
*FILE_USERGROUP "システムマネージャ"
*FILE_VERSION "1.0000000000"
*HW_ATTACHMENT_ID "ATT0025"
*HW_ATTACHMENT_NAME "標準|Standard"
*HW_COUNTER_ID-0 "CUT0025"
*HW_COUNTER_ID-1 "CUT0020"
*HW_COUNTER_ID-2 "CUT0020"
*HW_COUNTER_ID-3 "CSL0021"
*HW_COUNTER_ID-4 "CMC0021"
*HW_COUNTER_NAME-0 "D/teX Ultra|D/teX Ultra"
*HW_COUNTER_NAME-1 "None|None"
*HW_COUNTER_NAME-2 "None|None"
*HW_COUNTER_NAME-3 "BBM|BBM"
*HW_COUNTER_NAME-4 "検出器モノクロメータ|Detector monochromator"
*HW_COUNTER_SELECT_NAME "D/teX Ultra|D/teX Ultra"
*HW_GONIOMETER_ID "GON0023"
*HW_GONIOMETER_NAME "SmartLab|SmartLab"
*HW_GONIOMETER_RADIUS-0 "90.0"
*HW_GONIOMETER_RADIUS-1 "114.0"
*HW_GONIOMETER_RADIUS-2 "190.0"
*HW_GONIOMETER_RADIUS-3 "300.0"
*HW_GONIOMETER_RADIUS-4 "187.0"
*HW_GONIOMETER_RADIUS-5 "300.0"
*HW_GONIOMETER_RADIUS-6 "113.0"
*HW_GONIOMETER_RADIUS-7 "331.0"
*HW_I_OPT_ID-0 "CBO0021"
*HW_I_OPT_ID-1 "ICR0023"
*HW_I_OPT_ID-2 "ISL0021"
*HW_I_OPT_ID-3 "ISO0021"
*HW_I_OPT_ID-4 "IAD0021"
*HW_I_OPT_ID-5 "IPR0001"
*HW_I_OPT_NAME-0 "CBOユニット|CBO unit"
*HW_I_OPT_NAME-1 "標準入射光学ユニット|Standard incident optical unit"
*HW_I_OPT_NAME-2 "標準入射スリットボックス|Standard incident slit box"
*HW_I_OPT_NAME-3 "入射平行スリット|Incident parallel slit"
*HW_I_OPT_NAME-4 "長手制限スリット|Length limiting slit"
*HW_I_OPT_NAME-5 "None|None"
*HW_R_ATTENUATER_AUTOMODE "0"
*HW_R_OPT_ID-0 "RSS0021"
*HW_R_OPT_ID-1 "RCR0023"
*HW_R_OPT_ID-2 "RSO0021"
*HW_R_OPT_ID-3 "RRS0021"
*HW_R_OPT_ID-4 "ATN0021"
*HW_R_OPT_ID-5 "RFL0021"
*HW_R_OPT_ID-6 "RAD0021"
*HW_R_OPT_NAME-0 "標準受光スリットボックス1|Standard receiving slit box # 1"
*HW_R_OPT_NAME-1 "標準受光光学ユニット1|Standard receiving unit # 1"
*HW_R_OPT_NAME-2 "標準受光光学ユニット2|Standard receiving optical unit # 2"
*HW_R_OPT_NAME-3 "標準受光スリットボックス2|Standard receiving slit box # 2"
*HW_R_OPT_NAME-4 "標準アッテネータ|Standard Attenuator"
*HW_R_OPT_NAME-5 "Cu Kβ|Cu K-beta"
*HW_R_OPT_NAME-6 "調整用受光スリット|Alignment receiving slit"
*HW_SAMPLE_HOLDER_ID "SMP0023"
*HW_SAMPLE_HOLDER_NAME "標準Zステージ|Standard Z stage"
*HW_XG_CURRENT_MAX "50"
*HW_XG_CURRENT_MIN "2"
*HW_XG_CURRENT_RESOLUTION "1"
*HW_XG_CURRENT_UNIT "mA"
*HW_XG_FOCUS "1mm x 10mm"
*HW_XG_FOCUS_TYPE "Normal"
*HW_XG_ID ""
*HW_XG_NAME "3kW 封入管(ID:1200)|3kW Sealed tube(ID:1200)"
*HW_XG_TARGET_ATOMIC_NUMBER "29.0000000000"
*HW_XG_TARGET_NAME "Cu"
*HW_XG_TYPE "Hermetic"
*HW_XG_VOLTAGE_MAX "60"
*HW_XG_VOLTAGE_MIN "20"
*HW_XG_VOLTAGE_RESOLUTION "1"
*HW_XG_VOLTAGE_UNIT "kV"
*HW_XG_WATT_MAX "1.500"
*HW_XG_WATT_UNIT "kW"
*HW_XG_WAVE_LENGTH_ALPHA1 "1.540593"
*HW_XG_WAVE_LENGTH_ALPHA2 "1.544414"
*HW_XG_WAVE_LENGTH_BETA "1.392250"
*MEAS_COND_AXIS_NAME-0 "2θ/θ"
*MEAS_COND_AXIS_NAME-1 "2θ"
*MEAS_COND_AXIS_NAME-2 "ω"
*MEAS_COND_AXIS_NAME-3 "Z"
*MEAS_COND_AXIS_NAME-4 "2θ/ω"
*MEAS_COND_AXIS_NAME-5 "θs"
*MEAS_COND_AXIS_NAME-6 "θd"
*MEAS_COND_AXIS_NAME-7 "Ts"
*MEAS_COND_AXIS_NAME-8 "CBO選択スリット"
*MEAS_COND_AXIS_NAME-9 "M"
*MEAS_COND_AXIS_NAME-10 "入射平行スリット"
*MEAS_COND_AXIS_NAME-11 "入射スリット"
*MEAS_COND_AXIS_NAME-12 ""
*MEAS_COND_AXIS_NAME-13 "Zs"
*MEAS_COND_AXIS_NAME-14 "入射光学素子"
*MEAS_COND_AXIS_NAME-15 "長手制限スリット"
*MEAS_COND_AXIS_NAME-16 "センタースリット"
*MEAS_COND_AXIS_NAME-17 "フィルター"
*MEAS_COND_AXIS_NAME-18 "受光スリット1"
*MEAS_COND_AXIS_NAME-19 "受光スリット2"
*MEAS_COND_AXIS_NAME-20 "受光光学素子"
*MEAS_COND_AXIS_NAME-21 "受光平行スリット"
*MEAS_COND_AXIS_NAME-22 "調整用受光スリット"
*MEAS_COND_AXIS_NAME-23 ""
*MEAS_COND_AXIS_NAME-24 ""
*MEAS_COND_AXIS_NAME-25 "Zd"
*MEAS_COND_AXIS_NAME-26 "アッテネータ"
*MEAS_COND_AXIS_NAME-27 "検出器モノクロメータ"
*MEAS_COND_AXIS_NAME-28 "モノクロメータスリット"
*MEAS_COND_AXIS_NAME-29 "プライマリビーム"
*MEAS_COND_AXIS_NAME-30 "PHA"
*MEAS_COND_AXIS_NAME_INTERNAL-0 "TwoThetaTheta"
*MEAS_COND_AXIS_NAME_INTERNAL-1 "TwoTheta"
*MEAS_COND_AXIS_NAME_INTERNAL-2 "Omega"
*MEAS_COND_AXIS_NAME_INTERNAL-3 "Z"
*MEAS_COND_AXIS_NAME_INTERNAL-4 "TwoThetaOmega"
*MEAS_COND_AXIS_NAME_INTERNAL-5 "ThetaS"
*MEAS_COND_AXIS_NAME_INTERNAL-6 "ThetaD"
*MEAS_COND_AXIS_NAME_INTERNAL-7 "Ts"
*MEAS_COND_AXIS_NAME_INTERNAL-8 "CBO"
*MEAS_COND_AXIS_NAME_INTERNAL-9 "CBO-M"
*MEAS_COND_AXIS_NAME_INTERNAL-10 "IncidentSollerSlit"
*MEAS_COND_AXIS_NAME_INTERNAL-11 "IncidentSlitBox"
*MEAS_COND_AXIS_NAME_INTERNAL-12 "IncidentSlitBox-_Axis"
*MEAS_COND_AXIS_NAME_INTERNAL-13 "Zs"
*MEAS_COND_AXIS_NAME_INTERNAL-14 "IncidentMonochromator"
*MEAS_COND_AXIS_NAME_INTERNAL-15 "IncidentAxdSlit"
*MEAS_COND_AXIS_NAME_INTERNAL-16 "CenterSlit"
*MEAS_COND_AXIS_NAME_INTERNAL-17 "Filter"
*MEAS_COND_AXIS_NAME_INTERNAL-18 "ReceivingSlitBox1"
*MEAS_COND_AXIS_NAME_INTERNAL-19 "ReceivingSlitBox2"
*MEAS_COND_AXIS_NAME_INTERNAL-20 "ReceivingOptics"
*MEAS_COND_AXIS_NAME_INTERNAL-21 "ReceivingSollerSlit"
*MEAS_COND_AXIS_NAME_INTERNAL-22 "ReceivingAxdSlit"
*MEAS_COND_AXIS_NAME_INTERNAL-23 "ReceivingSlitBox1-_Axis"
*MEAS_COND_AXIS_NAME_INTERNAL-24 "ReceivingSlitBox2-_Axis"
*MEAS_COND_AXIS_NAME_INTERNAL-25 "ReceivingSlitBox2-Zd"
*MEAS_COND_AXIS_NAME_INTERNAL-26 "Attenuator"
*MEAS_COND_AXIS_NAME_INTERNAL-27 "CounterMonochromator"
*MEAS_COND_AXIS_NAME_INTERNAL-28 "CounterSlit"
*MEAS_COND_AXIS_NAME_INTERNAL-29 "IncidentPrimary"
*MEAS_COND_AXIS_NAME_INTERNAL-30 "PHA"
*MEAS_COND_AXIS_NAME_MAGICNO-0 "83951616.0000000000"
*MEAS_COND_AXIS_NAME_MAGICNO-1 "268632064.0000000000"
*MEAS_COND_AXIS_NAME_MAGICNO-2 "268500992.0000000000"
*MEAS_COND_AXIS_NAME_MAGICNO-3 "285278208.0000000000"
*MEAS_COND_AXIS_NAME_MAGICNO-4 "83951616.0000000000"
*MEAS_COND_AXIS_NAME_MAGICNO-5 "131072.0000000000"
*MEAS_COND_AXIS_NAME_MAGICNO-6 "131072.0000000000"
*MEAS_COND_AXIS_NAME_MAGICNO-7 "318898176.0000000000"
*MEAS_COND_AXIS_NAME_MAGICNO-8 "20971521.0000000000"
*MEAS_COND_AXIS_NAME_MAGICNO-9 "285343744.0000000000"
*MEAS_COND_AXIS_NAME_MAGICNO-10 "20971521.0000000000"
*MEAS_COND_AXIS_NAME_MAGICNO-11 "22020097.0000000000"
*MEAS_COND_AXIS_NAME_MAGICNO-12 "25165824.0000000000"
*MEAS_COND_AXIS_NAME_MAGICNO-13 "318898176.0000000000"
*MEAS_COND_AXIS_NAME_MAGICNO-14 "1.0000000000"
*MEAS_COND_AXIS_NAME_MAGICNO-15 "20971521.0000000000"
*MEAS_COND_AXIS_NAME_MAGICNO-16 "20971521.0000000000"
*MEAS_COND_AXIS_NAME_MAGICNO-17 "20971521.0000000000"
*MEAS_COND_AXIS_NAME_MAGICNO-18 "23068673.0000000000"
*MEAS_COND_AXIS_NAME_MAGICNO-19 "23068673.0000000000"
*MEAS_COND_AXIS_NAME_MAGICNO-20 "20971521.0000000000"
*MEAS_COND_AXIS_NAME_MAGICNO-21 "20971521.0000000000"
*MEAS_COND_AXIS_NAME_MAGICNO-22 "20971521.0000000000"
*MEAS_COND_AXIS_NAME_MAGICNO-23 "25165824.0000000000"
*MEAS_COND_AXIS_NAME_MAGICNO-24 "25165824.0000000000"
*MEAS_COND_AXIS_NAME_MAGICNO-25 "285343744.0000000000"
*MEAS_COND_AXIS_NAME_MAGICNO-26 "17301505.0000000000"
*MEAS_COND_AXIS_NAME_MAGICNO-27 "20971521.0000000000"
*MEAS_COND_AXIS_NAME_MAGICNO-28 "20971521.0000000000"
*MEAS_COND_AXIS_NAME_MAGICNO-29 "20971521.0000000000"
*MEAS_COND_AXIS_NAME_MAGICNO-30 "0.0000000000"
*MEAS_COND_AXIS_OFFSET-0 "-"
*MEAS_COND_AXIS_OFFSET-1 "-0.0310000000"
*MEAS_COND_AXIS_OFFSET-2 "0.3957000000"
*MEAS_COND_AXIS_OFFSET-3 "-"
*MEAS_COND_AXIS_OFFSET-4 "-"
*MEAS_COND_AXIS_OFFSET-5 "0.3957000000"
*MEAS_COND_AXIS_OFFSET-6 "-0.4267000000"
*MEAS_COND_AXIS_OFFSET-7 "-"
*MEAS_COND_AXIS_OFFSET-8 "-"
*MEAS_COND_AXIS_OFFSET-9 "-"
*MEAS_COND_AXIS_OFFSET-10 "-"
*MEAS_COND_AXIS_OFFSET-11 "-"
*MEAS_COND_AXIS_OFFSET-12 "-"
*MEAS_COND_AXIS_OFFSET-13 "-"
*MEAS_COND_AXIS_OFFSET-14 "-"
*MEAS_COND_AXIS_OFFSET-15 "-"
*MEAS_COND_AXIS_OFFSET-16 "-"
*MEAS_COND_AXIS_OFFSET-17 "-"
*MEAS_COND_AXIS_OFFSET-18 "-"
*MEAS_COND_AXIS_OFFSET-19 "-"
*MEAS_COND_AXIS_OFFSET-20 "-"
*MEAS_COND_AXIS_OFFSET-21 "-"
*MEAS_COND_AXIS_OFFSET-22 "-"
*MEAS_COND_AXIS_OFFSET-23 "-"
*MEAS_COND_AXIS_OFFSET-24 "-"
*MEAS_COND_AXIS_OFFSET-25 "-"
*MEAS_COND_AXIS_OFFSET-26 "-"
*MEAS_COND_AXIS_OFFSET-27 "-"
*MEAS_COND_AXIS_OFFSET-28 "-"
*MEAS_COND_AXIS_OFFSET-29 "-"
*MEAS_COND_AXIS_OFFSET-30 "-"
*MEAS_COND_AXIS_POSITION-0 "0.0000000000"
*MEAS_COND_AXIS_POSITION-1 "0.0000000000"
*MEAS_COND_AXIS_POSITION-2 "0.0000000000"
*MEAS_COND_AXIS_POSITION-3 "-2.9656400000"
*MEAS_COND_AXIS_POSITION-4 "0.0000000000"
*MEAS_COND_AXIS_POSITION-5 "0.0000000000"
*MEAS_COND_AXIS_POSITION-6 "0.0000000000"
*MEAS_COND_AXIS_POSITION-7 "-0.7498700000"
*MEAS_COND_AXIS_POSITION-8 "BB"
*MEAS_COND_AXIS_POSITION-9 "0.0000000000"
*MEAS_COND_AXIS_POSITION-10 "Soller_slit_5.0deg"
*MEAS_COND_AXIS_POSITION-11 "2/3deg"
*MEAS_COND_AXIS_POSITION-12 "2.2088000000"
*MEAS_COND_AXIS_POSITION-13 "-0.6412500000"
*MEAS_COND_AXIS_POSITION-14 "0.0000000000"
*MEAS_COND_AXIS_POSITION-15 "10.0mm"
*MEAS_COND_AXIS_POSITION-16 "None"
*MEAS_COND_AXIS_POSITION-17 "Cu_K-beta"
*MEAS_COND_AXIS_POSITION-18 "13.000mm"
*MEAS_COND_AXIS_POSITION-19 "13.000mm"
*MEAS_COND_AXIS_POSITION-20 "No_unit"
*MEAS_COND_AXIS_POSITION-21 "Soller_slit_5.0deg"
*MEAS_COND_AXIS_POSITION-22 "None"
*MEAS_COND_AXIS_POSITION-23 "13.0000000000"
*MEAS_COND_AXIS_POSITION-24 "13.0000000000"
*MEAS_COND_AXIS_POSITION-25 "0.0281300000"
*MEAS_COND_AXIS_POSITION-26 "Open"
*MEAS_COND_AXIS_POSITION-27 "None"
*MEAS_COND_AXIS_POSITION-28 "None"
*MEAS_COND_AXIS_POSITION-29 "None"
*MEAS_COND_AXIS_POSITION-30 "38.0000000000"
*MEAS_COND_AXIS_UNIT-0 "deg"
*MEAS_COND_AXIS_UNIT-1 "deg"
*MEAS_COND_AXIS_UNIT-2 "deg"
*MEAS_COND_AXIS_UNIT-3 "mm"
*MEAS_COND_AXIS_UNIT-4 "deg"
*MEAS_COND_AXIS_UNIT-5 "deg"
*MEAS_COND_AXIS_UNIT-6 "deg"
*MEAS_COND_AXIS_UNIT-7 "mm"
*MEAS_COND_AXIS_UNIT-8 ""
*MEAS_COND_AXIS_UNIT-9 "pulse"
*MEAS_COND_AXIS_UNIT-10 ""
*MEAS_COND_AXIS_UNIT-11 ""
*MEAS_COND_AXIS_UNIT-12 "mm"
*MEAS_COND_AXIS_UNIT-13 "mm"
*MEAS_COND_AXIS_UNIT-14 ""
*MEAS_COND_AXIS_UNIT-15 ""
*MEAS_COND_AXIS_UNIT-16 ""
*MEAS_COND_AXIS_UNIT-17 ""
*MEAS_COND_AXIS_UNIT-18 ""
*MEAS_COND_AXIS_UNIT-19 ""
*MEAS_COND_AXIS_UNIT-20 ""
*MEAS_COND_AXIS_UNIT-21 ""
*MEAS_COND_AXIS_UNIT-22 ""
*MEAS_COND_AXIS_UNIT-23 "mm"
*MEAS_COND_AXIS_UNIT-24 "mm"
*MEAS_COND_AXIS_UNIT-25 "mm"
*MEAS_COND_AXIS_UNIT-26 ""
*MEAS_COND_AXIS_UNIT-27 ""
*MEAS_COND_AXIS_UNIT-28 ""
*MEAS_COND_AXIS_UNIT-29 ""
*MEAS_COND_AXIS_UNIT-30 "div"
*MEAS_COND_COUNTER_CNTLOSS_CORR "0.0000000000"
*MEAS_COND_COUNTER_PHABASE "38.0000000000"
*MEAS_COND_COUNTER_PHAWINDOW "16.0000000000"
*MEAS_COND_COUNTER_PHA_UNIT "div"
*MEAS_COND_COUNTER_TAUDIFF "30.0000000000"
*MEAS_COND_COUNTER_TAUINT "0.0000000000"
*MEAS_COND_IRRADIATION_MODE "OFF"
*MEAS_COND_IRRADIATION_WIDTH ""
*MEAS_COND_OPT_ATTR "集中法"
*MEAS_COND_OPT_NAME "@集中法"
*MEAS_COND_UNSYMMETRIC_MODE "OFF"
*MEAS_COND_XG_CURRENT "30.0000000000"
*MEAS_COND_XG_VOLTAGE "40.0000000000"
*MEAS_COND_XG_WAVE_TYPE "Ka"
*MEAS_DATA_COUNT "5001.0000000000"
*MEAS_SCAN_AXIS_X "2θ/θ"
*MEAS_SCAN_AXIS_X_INTERNAL "TwoThetaTheta"
*MEAS_SCAN_END_TIME "02/14/24 22:18:29"
*MEAS_SCAN_MODE "CONTINUOUS"
*MEAS_SCAN_MONITOR "0"
*MEAS_SCAN_RESOLUTION_X "0.0002"
*MEAS_SCAN_SPEED "2.5"
*MEAS_SCAN_SPEED_UNIT "deg/min"
*MEAS_SCAN_START "20.0000000000"
*MEAS_SCAN_START_TIME "02/14/24 21:57:06"
*MEAS_SCAN_STEP "0.0100000000"
*MEAS_SCAN_STOP "70.0000000000"
*MEAS_SCAN_UNIT_X "deg"
*MEAS_SCAN_UNIT_Y "counts"
*RAS_HEADER_END
*RAS_INT_START
20.0000 734.0000 1.0000
20.0400 760.0000 1.0000
20.0800 767.0000 1.0000
20.1200 744.0000 1.0000
20.1600 741.0000 1.0000
20.2000 731.0000 1.0000
20.2400 733.0000 1.0000
20.2800 746.0000 1.0000
20.3200 749.0000 1.0000
20.3600 721.0000 1.0000
20.4000 740.0000 1.0000
20.4400 731.0000 1.0000
20.4800 774.0000 1.0000
20.5200 799.0000 1.0000
20.5600 762.0000 1.0000
20.6000 736.0000 1.0000
20.6400 712.0000 1.0000
20.6800 754.0000 1.0000
20.7200 721.0000 1.0000
20.7600 732.0000 1.0000
20.8000 739.0000 1.0000
20.8400 754.0000 1.0000
20.8800 759.0000 1.0000
20.9200 780.0000 1.0000
20.9600 744.0000 1.0000
21.0000 748.0000 1.0000
21.0400 756.0000 1.0000
21.0800 780.0000 1.0000
21.1200 812.0000 1.0000
21.1600 742.0000 1.0000
21.2000 689.0000 1.0000
21.2400 774.0000 1.0000
21.2800 712.0000 1.0000
21.3200 718.0000 1.0000
21.3600 739.0000 1.0000
21.4000 784.0000 1.0000
21.4400 758.0000 1.0000
21.4800 791.0000 1.0000
21.5200 730.0000 1.0000
21.5600 751.0000 1.0000
21.6000 738.0000 1.0000
21.6400 728.0000 1.0000
21.6800 739.0000 1.0000
21.7200 786.0000 1.0000
21.7600 733.0000 1.0000
21.8000 731.0000 1.0000
21.8400 762.0000 1.0000
21.8800 713.0000 1.0000
21.9200 720.0000 1.0000
21.9600 771.0000 1.0000
22.0000 771.0000 1.0000
22.0400 710.0000 1.0000
22.0800 762.0000 1.0000
22.1200 747.0000 1.0000
22.1600 726.0000 1.0000
22.2000 762.0000 1.0000
22.2400 684.0000 1.0000
22.2800 745.0000 1.0000
22.3200 721.0000 1.0000
22.3600 700.0000 1.0000
22.4000 737.0000 1.0000
22.4400 708.0000 1.0000
22.4800 724.0000 1.0000
22.5200 727.0000 1.0000
22.5600 744.0000 1.0000
22.6000 718.0000 1.0000
22.6400 744.0000 1.0000
22.6800 703.0000 1.0000
22.7200 725.0000 1.0000
22.7600 729.0000 1.0000
22.8000 754.0000 1.0000
22.8400 741.0000 1.0000
22.8800 733.0000 1.0000
22.9200 749.0000 1.0000
22.9600 737.0000 1.0000
23.0000 767.0000 1.0000
23.0400 727.0000 1.0000
23.0800 756.0000 1.0000
23.1200 704.0000 1.0000
23.1600 760.0000 1.0000
23.2000 675.0000 1.0000
23.2400 752.0000 1.0000
23.2800 712.0000 1.0000
23.3200 722.0000 1.0000
23.3600 734.0000 1.0000
23.4000 737.0000 1.0000
23.4400 748.0000 1.0000
23.4800 714.0000 1.0000
23.5200 753.0000 1.0000
23.5600 750.0000 1.0000
23.6000 753.0000 1.0000
23.6400 729.0000 1.0000
23.6800 757.0000 1.0000
23.7200 748.0000 1.0000
23.7600 722.0000 1.0000
23.8000 726.0000 1.0000
23.8400 746.0000 1.0000
23.8800 755.0000 1.0000
23.9200 731.0000 1.0000
23.9600 782.0000 1.0000
24.0000 760.0000 1.0000
24.0400 809.0000 1.0000
24.0800 826.0000 1.0000
24.1200 762.0000 1.0000
24.1600 760.0000 1.0000
24.2000 764.0000 1.0000
24.2400 704.0000 1.0000
24.2800 772.0000 1.0000
24.3200 736.0000 1.0000
24.3600 771.0000 1.0000
24.4000 727.0000 1.0000
24.4400 704.0000 1.0000
24.4800 737.0000 1.0000
24.5200 757.0000 1.0000
24.5600 752.0000 1.0000
24.6000 747.0000 1.0000
24.6400 748.0000 1.0000
24.6800 693.0000 1.0000
24.7200 732.0000 1.0000
24.7600 709.0000 1.0000
24.8000 679.0000 1.0000
24.8400 692.0000 1.0000
24.8800 697.0000 1.0000
24.9200 633.0000 1.0000
24.9600 708.0000 1.0000
25.0000 699.0000 1.0000
25.0400 651.0000 1.0000
25.0800 677.0000 1.0000
25.1200 689.0000 1.0000
25.1600 722.0000 1.0000
25.2000 681.0000 1.0000
25.2400 658.0000 1.0000
25.2800 725.0000 1.0000
25.3200 732.0000 1.0000
25.3600 735.0000 1.0000
25.4000 718.0000 1.0000
25.4400 756.0000 1.0000
25.4800 696.0000 1.0000
25.5200 672.0000 1.0000
25.5600 721.0000 1.0000
25.6000 690.0000 1.0000
25.6400 729.0000 1.0000
25.6800 738.0000 1.0000
25.7200 702.0000 1.0000
25.7600 692.0000 1.0000
25.8000 758.0000 1.0000
25.8400 707.0000 1.0000
25.8800 734.0000 1.0000
25.9200 771.0000 1.0000
25.9600 779.0000 1.0000
26.0000 771.0000 1.0000
26.0400 758.0000 1.0000
26.0800 808.0000 1.0000
26.1200 808.0000 1.0000
26.1600 835.0000 1.0000
26.2000 881.0000 1.0000
26.2400 926.0000 1.0000
26.2800 1027.0000 1.0000
26.3200 1109.0000 1.0000
26.3600 1247.0000 1.0000
26.4000 1378.0000 1.0000
26.4400 1410.0000 1.0000
26.4800 1432.0000 1.0000
26.5200 1239.0000 1.0000
26.5600 1208.0000 1.0000
26.6000 1054.0000 1.0000
26.6400 929.0000 1.0000
26.6800 891.0000 1.0000
26.7200 874.0000 1.0000
26.7600 789.0000 1.0000
26.8000 791.0000 1.0000
26.8400 746.0000 1.0000
26.8800 727.0000 1.0000
26.9200 724.0000 1.0000
26.9600 680.0000 1.0000
27.0000 697.0000 1.0000
27.0400 740.0000 1.0000
27.0800 670.0000 1.0000
27.1200 726.0000 1.0000
27.1600 671.0000 1.0000
27.2000 671.0000 1.0000
27.2400 656.0000 1.0000
27.2800 695.0000 1.0000
27.3200 650.0000 1.0000
27.3600 620.0000 1.0000
27.4000 654.0000 1.0000
27.4400 653.0000 1.0000
27.4800 651.0000 1.0000
27.5200 627.0000 1.0000
27.5600 630.0000 1.0000
27.6000 652.0000 1.0000
27.6400 625.0000 1.0000
27.6800 616.0000 1.0000
27.7200 637.0000 1.0000
27.7600 637.0000 1.0000
27.8000 641.0000 1.0000
27.8400 590.0000 1.0000
27.8800 641.0000 1.0000
27.9200 613.0000 1.0000
27.9600 641.0000 1.0000
28.0000 643.0000 1.0000
28.0400 622.0000 1.0000
28.0800 625.0000 1.0000
28.1200 609.0000 1.0000
28.1600 600.0000 1.0000
28.2000 588.0000 1.0000
28.2400 585.0000 1.0000
28.2800 613.0000 1.0000
28.3200 570.0000 1.0000
28.3600 637.0000 1.0000
28.4000 624.0000 1.0000
28.4400 636.0000 1.0000
28.4800 568.0000 1.0000
28.5200 639.0000 1.0000
28.5600 564.0000 1.0000
28.6000 651.0000 1.0000
28.6400 582.0000 1.0000
28.6800 589.0000 1.0000
28.7200 610.0000 1.0000
28.7600 568.0000 1.0000
28.8000 640.0000 1.0000
28.8400 583.0000 1.0000
28.8800 613.0000 1.0000
28.9200 558.0000 1.0000
28.9600 568.0000 1.0000
29.0000 562.0000 1.0000
29.0400 574.0000 1.0000
29.0800 538.0000 1.0000
29.1200 560.0000 1.0000
29.1600 571.0000 1.0000
29.2000 565.0000 1.0000
29.2400 562.0000 1.0000
29.2800 596.0000 1.0000
29.3200 576.0000 1.0000
29.3600 596.0000 1.0000
29.4000 554.0000 1.0000
29.4400 590.0000 1.0000
29.4800 613.0000 1.0000
29.5200 572.0000 1.0000
29.5600 559.0000 1.0000
29.6000 570.0000 1.0000
29.6400 534.0000 1.0000
29.6800 568.0000 1.0000
29.7200 555.0000 1.0000
29.7600 567.0000 1.0000
29.8000 607.0000 1.0000
29.8400 553.0000 1.0000
29.8800 541.0000 1.0000
29.9200 550.0000 1.0000
29.9600 521.0000 1.0000
30.0000 544.0000 1.0000
30.0400 565.0000 1.0000
30.0800 521.0000 1.0000
30.1200 600.0000 1.0000
30.1600 592.0000 1.0000
30.2000 570.0000 1.0000
30.2400 591.0000 1.0000
30.2800 530.0000 1.0000
30.3200 531.0000 1.0000
30.3600 519.0000 1.0000
30.4000 531.0000 1.0000
30.4400 538.0000 1.0000
30.4800 548.0000 1.0000
30.5200 574.0000 1.0000
30.5600 563.0000 1.0000
30.6000 561.0000 1.0000
30.6400 531.0000 1.0000
30.6800 526.0000 1.0000
30.7200 568.0000 1.0000
30.7600 557.0000 1.0000
30.8000 531.0000 1.0000
30.8400 560.0000 1.0000
30.8800 517.0000 1.0000
30.9200 540.0000 1.0000
30.9600 562.0000 1.0000
31.0000 559.0000 1.0000
31.0400 592.0000 1.0000
31.0800 567.0000 1.0000
31.1200 560.0000 1.0000
31.1600 558.0000 1.0000
31.2000 523.0000 1.0000
31.2400 578.0000 1.0000
31.2800 608.0000 1.0000
31.3200 567.0000 1.0000
31.3600 576.0000 1.0000
31.4000 577.0000 1.0000
31.4400 600.0000 1.0000
31.4800 643.0000 1.0000
31.5200 596.0000 1.0000
31.5600 619.0000 1.0000
31.6000 640.0000 1.0000
31.6400 681.0000 1.0000
31.6800 598.0000 1.0000
31.7200 565.0000 1.0000
31.7600 570.0000 1.0000
31.8000 544.0000 1.0000
31.8400 550.0000 1.0000
31.8800 549.0000 1.0000
31.9200 513.0000 1.0000
31.9600 522.0000 1.0000
32.0000 519.0000 1.0000
32.0400 523.0000 1.0000
32.0800 519.0000 1.0000
32.1200 518.0000 1.0000
32.1600 522.0000 1.0000
32.2000 512.0000 1.0000
32.2400 514.0000 1.0000
32.2800 503.0000 1.0000
32.3200 488.0000 1.0000
32.3600 504.0000 1.0000
32.4000 514.0000 1.0000
32.4400 508.0000 1.0000
32.4800 496.0000 1.0000
32.5200 521.0000 1.0000
32.5600 499.0000 1.0000
32.6000 474.0000 1.0000
32.6400 509.0000 1.0000
32.6800 542.0000 1.0000
32.7200 499.0000 1.0000
32.7600 506.0000 1.0000
32.8000 505.0000 1.0000
32.8400 509.0000 1.0000
32.8800 518.0000 1.0000
32.9200 506.0000 1.0000
32.9600 566.0000 1.0000
33.0000 574.0000 1.0000
33.0400 584.0000 1.0000
33.0800 606.0000 1.0000
33.1200 619.0000 1.0000
33.1600 586.0000 1.0000
33.2000 555.0000 1.0000
33.2400 564.0000 1.0000
33.2800 540.0000 1.0000
33.3200 526.0000 1.0000
33.3600 535.0000 1.0000
33.4000 554.0000 1.0000
33.4400 579.0000 1.0000
33.4800 613.0000 1.0000
33.5200 625.0000 1.0000
33.5600 671.0000 1.0000
33.6000 686.0000 1.0000
33.6400 707.0000 1.0000
33.6800 687.0000 1.0000
33.7200 660.0000 1.0000
33.7600 654.0000 1.0000
33.8000 586.0000 1.0000
33.8400 624.0000 1.0000
33.8800 567.0000 1.0000
33.9200 586.0000 1.0000
33.9600 504.0000 1.0000
34.0000 535.0000 1.0000
34.0400 502.0000 1.0000
34.0800 510.0000 1.0000
34.1200 515.0000 1.0000
34.1600 504.0000 1.0000
34.2000 468.0000 1.0000
34.2400 493.0000 1.0000
34.2800 474.0000 1.0000
34.3200 474.0000 1.0000
34.3600 461.0000 1.0000
34.4000 479.0000 1.0000
34.4400 440.0000 1.0000
34.4800 440.0000 1.0000
34.5200 469.0000 1.0000
34.5600 491.0000 1.0000
34.6000 473.0000 1.0000
34.6400 474.0000 1.0000
34.6800 451.0000 1.0000
34.7200 432.0000 1.0000
34.7600 480.0000 1.0000
34.8000 402.0000 1.0000
34.8400 442.0000 1.0000
34.8800 404.0000 1.0000
34.9200 475.0000 1.0000
34.9600 421.0000 1.0000
35.0000 441.0000 1.0000
35.0400 448.0000 1.0000
35.0800 428.0000 1.0000
35.1200 472.0000 1.0000
35.1600 446.0000 1.0000
35.2000 472.0000 1.0000
35.2400 471.0000 1.0000
35.2800 468.0000 1.0000
35.3200 496.0000 1.0000
35.3600 503.0000 1.0000
35.4000 553.0000 1.0000
35.4400 598.0000 1.0000
35.4800 668.0000 1.0000
35.5200 866.0000 1.0000
35.5600 877.0000 1.0000
35.6000 895.0000 1.0000
35.6400 855.0000 1.0000
35.6800 788.0000 1.0000
35.7200 656.0000 1.0000
35.7600 584.0000 1.0000
35.8000 520.0000 1.0000
35.8400 453.0000 1.0000
35.8800 436.0000 1.0000
35.9200 440.0000 1.0000
35.9600 427.0000 1.0000
36.0000 457.0000 1.0000
36.0400 411.0000 1.0000
36.0800 415.0000 1.0000
36.1200 393.0000 1.0000
36.1600 409.0000 1.0000
36.2000 386.0000 1.0000
36.2400 417.0000 1.0000
36.2800 425.0000 1.0000
36.3200 403.0000 1.0000
36.3600 408.0000 1.0000
36.4000 411.0000 1.0000
36.4400 402.0000 1.0000
36.4800 431.0000 1.0000
36.5200 420.0000 1.0000
36.5600 406.0000 1.0000
36.6000 427.0000 1.0000
36.6400 416.0000 1.0000
36.6800 386.0000 1.0000
36.7200 393.0000 1.0000
36.7600 426.0000 1.0000
36.8000 390.0000 1.0000
36.8400 453.0000 1.0000
36.8800 424.0000 1.0000
36.9200 457.0000 1.0000
36.9600 422.0000 1.0000
37.0000 437.0000 1.0000
37.0400 447.0000 1.0000
37.0800 438.0000 1.0000
37.1200 439.0000 1.0000
37.1600 468.0000 1.0000
37.2000 462.0000 1.0000
37.2400 482.0000 1.0000
37.2800 518.0000 1.0000
37.3200 536.0000 1.0000
37.3600 592.0000 1.0000
37.4000 683.0000 1.0000
37.4400 771.0000 1.0000
37.4800 877.0000 1.0000
37.5200 1043.0000 1.0000
37.5600 1336.0000 1.0000
37.6000 1715.0000 1.0000
37.6400 2223.0000 1.0000
37.6800 2713.0000 1.0000
37.7200 2986.0000 1.0000
37.7600 2925.0000 1.0000
37.8000 2566.0000 1.0000
37.8400 2122.0000 1.0000
37.8800 1714.0000 1.0000
37.9200 1281.0000 1.0000
37.9600 976.0000 1.0000
38.0000 818.0000 1.0000
38.0400 653.0000 1.0000
38.0800 621.0000 1.0000
38.1200 525.0000 1.0000
38.1600 524.0000 1.0000
38.2000 473.0000 1.0000
38.2400 447.0000 1.0000
38.2800 432.0000 1.0000
38.3200 428.0000 1.0000
38.3600 427.0000 1.0000
38.4000 415.0000 1.0000
38.4400 415.0000 1.0000
38.4800 358.0000 1.0000
38.5200 390.0000 1.0000
38.5600 365.0000 1.0000
38.6000 418.0000 1.0000
38.6400 363.0000 1.0000
38.6800 384.0000 1.0000
38.7200 389.0000 1.0000
38.7600 388.0000 1.0000
38.8000 377.0000 1.0000
38.8400 355.0000 1.0000
38.8800 358.0000 1.0000
38.9200 388.0000 1.0000
38.9600 383.0000 1.0000
39.0000 351.0000 1.0000
39.0400 351.0000 1.0000
39.0800 345.0000 1.0000
39.1200 383.0000 1.0000
39.1600 364.0000 1.0000
39.2000 377.0000 1.0000
39.2400 379.0000 1.0000
39.2800 343.0000 1.0000
39.3200 360.0000 1.0000
39.3600 387.0000 1.0000
39.4000 366.0000 1.0000
39.4400 346.0000 1.0000
39.4800 339.0000 1.0000
39.5200 300.0000 1.0000
39.5600 339.0000 1.0000
39.6000 359.0000 1.0000
39.6400 373.0000 1.0000
39.6800 358.0000 1.0000
39.7200 352.0000 1.0000
39.7600 349.0000 1.0000
39.8000 371.0000 1.0000
39.8400 327.0000 1.0000
39.8800 355.0000 1.0000
39.9200 357.0000 1.0000
39.9600 324.0000 1.0000
40.0000 307.0000 1.0000
40.0400 346.0000 1.0000
40.0800 330.0000 1.0000
40.1200 322.0000 1.0000
40.1600 337.0000 1.0000
40.2000 293.0000 1.0000
40.2400 357.0000 1.0000
40.2800 346.0000 1.0000
40.3200 376.0000 1.0000
40.3600 388.0000 1.0000
40.4000 371.0000 1.0000
40.4400 382.0000 1.0000
40.4800 426.0000 1.0000
40.5200 428.0000 1.0000
40.5600 411.0000 1.0000
40.6000 435.0000 1.0000
40.6400 399.0000 1.0000
40.6800 412.0000 1.0000
40.7200 397.0000 1.0000
40.7600 382.0000 1.0000
40.8000 400.0000 1.0000
40.8400 382.0000 1.0000
40.8800 388.0000 1.0000
40.9200 386.0000 1.0000
40.9600 358.0000 1.0000
41.0000 358.0000 1.0000
41.0400 367.0000 1.0000
41.0800 328.0000 1.0000
41.1200 321.0000 1.0000
41.1600 338.0000 1.0000
41.2000 318.0000 1.0000
41.2400 339.0000 1.0000
41.2800 322.0000 1.0000
41.3200 343.0000 1.0000
41.3600 359.0000 1.0000
41.4000 303.0000 1.0000
41.4400 329.0000 1.0000
41.4800 304.0000 1.0000
41.5200 311.0000 1.0000
41.5600 335.0000 1.0000
41.6000 332.0000 1.0000
41.6400 314.0000 1.0000
41.6800 339.0000 1.0000
41.7200 325.0000 1.0000
41.7600 341.0000 1.0000
41.8000 302.0000 1.0000
41.8400 338.0000 1.0000
41.8800 288.0000 1.0000
41.9200 305.0000 1.0000
41.9600 307.0000 1.0000
42.0000 326.0000 1.0000
42.0400 326.0000 1.0000
42.0800 319.0000 1.0000
42.1200 311.0000 1.0000
42.1600 312.0000 1.0000
42.2000 353.0000 1.0000
42.2400 354.0000 1.0000
42.2800 352.0000 1.0000
42.3200 327.0000 1.0000
42.3600 326.0000 1.0000
42.4000 316.0000 1.0000
42.4400 346.0000 1.0000
42.4800 329.0000 1.0000
42.5200 345.0000 1.0000
42.5600 347.0000 1.0000
42.6000 320.0000 1.0000
42.6400 326.0000 1.0000
42.6800 319.0000 1.0000
42.7200 332.0000 1.0000
42.7600 298.0000 1.0000
42.8000 303.0000 1.0000
42.8400 308.0000 1.0000
42.8800 326.0000 1.0000
42.9200 311.0000 1.0000
42.9600 315.0000 1.0000
43.0000 313.0000 1.0000
43.0400 307.0000 1.0000
43.0800 329.0000 1.0000
43.1200 334.0000 1.0000
43.1600 276.0000 1.0000
43.2000 320.0000 1.0000
43.2400 312.0000 1.0000
43.2800 295.0000 1.0000
43.3200 312.0000 1.0000
43.3600 312.0000 1.0000
43.4000 314.0000 1.0000
43.4400 297.0000 1.0000
43.4800 288.0000 1.0000
43.5200 320.0000 1.0000
43.5600 319.0000 1.0000
43.6000 316.0000 1.0000
43.6400 339.0000 1.0000
43.6800 318.0000 1.0000
43.7200 296.0000 1.0000
43.7600 300.0000 1.0000
43.8000 293.0000 1.0000
43.8400 286.0000 1.0000
43.8800 297.0000 1.0000
43.9200 292.0000 1.0000
43.9600 304.0000 1.0000
44.0000 307.0000 1.0000
44.0400 312.0000 1.0000
44.0800 307.0000 1.0000
44.1200 304.0000 1.0000
44.1600 324.0000 1.0000
44.2000 319.0000 1.0000
44.2400 286.0000 1.0000
44.2800 342.0000 1.0000
44.3200 317.0000 1.0000
44.3600 294.0000 1.0000
44.4000 303.0000 1.0000
44.4400 313.0000 1.0000
44.4800 308.0000 1.0000
44.5200 321.0000 1.0000
44.5600 317.0000 1.0000
44.6000 285.0000 1.0000
44.6400 295.0000 1.0000
44.6800 273.0000 1.0000
44.7200 316.0000 1.0000
44.7600 255.0000 1.0000
44.8000 296.0000 1.0000
44.8400 311.0000 1.0000
44.8800 276.0000 1.0000
44.9200 306.0000 1.0000
44.9600 316.0000 1.0000
45.0000 298.0000 1.0000
45.0400 325.0000 1.0000
45.0800 275.0000 1.0000
45.1200 280.0000 1.0000
45.1600 265.0000 1.0000
45.2000 336.0000 1.0000
45.2400 313.0000 1.0000
45.2800 327.0000 1.0000
45.3200 288.0000 1.0000
45.3600 315.0000 1.0000
45.4000 326.0000 1.0000
45.4400 322.0000 1.0000
45.4800 309.0000 1.0000
45.5200 253.0000 1.0000
45.5600 294.0000 1.0000
45.6000 306.0000 1.0000
45.6400 294.0000 1.0000
45.6800 289.0000 1.0000
45.7200 270.0000 1.0000
45.7600 295.0000 1.0000
45.8000 275.0000 1.0000
45.8400 279.0000 1.0000
45.8800 274.0000 1.0000
45.9200 313.0000 1.0000
45.9600 281.0000 1.0000
46.0000 285.0000 1.0000
46.0400 292.0000 1.0000
46.0800 269.0000 1.0000
46.1200 299.0000 1.0000
46.1600 281.0000 1.0000
46.2000 244.0000 1.0000
46.2400 302.0000 1.0000
46.2800 300.0000 1.0000
46.3200 274.0000 1.0000
46.3600 301.0000 1.0000
46.4000 291.0000 1.0000
46.4400 276.0000 1.0000
46.4800 288.0000 1.0000
46.5200 284.0000 1.0000
46.5600 264.0000 1.0000
46.6000 280.0000 1.0000
46.6400 278.0000 1.0000
46.6800 280.0000 1.0000
46.7200 304.0000 1.0000
46.7600 251.0000 1.0000
46.8000 263.0000 1.0000
46.8400 274.0000 1.0000
46.8800 278.0000 1.0000
46.9200 281.0000 1.0000
46.9600 272.0000 1.0000
47.0000 254.0000 1.0000
47.0400 263.0000 1.0000
47.0800 264.0000 1.0000
47.1200 292.0000 1.0000
47.1600 250.0000 1.0000
47.2000 272.0000 1.0000
47.2400 285.0000 1.0000
47.2800 275.0000 1.0000
47.3200 247.0000 1.0000
47.3600 299.0000 1.0000
47.4000 282.0000 1.0000
47.4400 290.0000 1.0000
47.4800 256.0000 1.0000
47.5200 290.0000 1.0000
47.5600 288.0000 1.0000
47.6000 254.0000 1.0000
47.6400 308.0000 1.0000
47.6800 266.0000 1.0000
47.7200 263.0000 1.0000
47.7600 279.0000 1.0000
47.8000 272.0000 1.0000
47.8400 247.0000 1.0000
47.8800 263.0000 1.0000
47.9200 268.0000 1.0000
47.9600 265.0000 1.0000
48.0000 275.0000 1.0000
48.0400 294.0000 1.0000
48.0800 243.0000 1.0000
48.1200 278.0000 1.0000
48.1600 267.0000 1.0000
48.2000 241.0000 1.0000
48.2400 279.0000 1.0000
48.2800 277.0000 1.0000
48.3200 286.0000 1.0000
48.3600 288.0000 1.0000
48.4000 295.0000 1.0000
48.4400 256.0000 1.0000
48.4800 265.0000 1.0000
48.5200 279.0000 1.0000
48.5600 274.0000 1.0000
48.6000 255.0000 1.0000
48.6400 256.0000 1.0000
48.6800 267.0000 1.0000
48.7200 282.0000 1.0000
48.7600 256.0000 1.0000
48.8000 271.0000 1.0000
48.8400 280.0000 1.0000
48.8800 263.0000 1.0000
48.9200 278.0000 1.0000
48.9600 284.0000 1.0000
49.0000 270.0000 1.0000
49.0400 303.0000 1.0000
49.0800 259.0000 1.0000
49.1200 273.0000 1.0000
49.1600 287.0000 1.0000
49.2000 299.0000 1.0000
49.2400 259.0000 1.0000
49.2800 313.0000 1.0000
49.3200 327.0000 1.0000
49.3600 299.0000 1.0000
49.4000 313.0000 1.0000
49.4400 298.0000 1.0000
49.4800 312.0000 1.0000
49.5200 294.0000 1.0000
49.5600 274.0000 1.0000
49.6000 279.0000 1.0000
49.6400 272.0000 1.0000
49.6800 292.0000 1.0000
49.7200 268.0000 1.0000
49.7600 292.0000 1.0000
49.8000 258.0000 1.0000
49.8400 277.0000 1.0000
49.8800 295.0000 1.0000
49.9200 263.0000 1.0000
49.9600 275.0000 1.0000
50.0000 286.0000 1.0000
50.0400 240.0000 1.0000
50.0800 269.0000 1.0000
50.1200 269.0000 1.0000
50.1600 257.0000 1.0000
50.2000 250.0000 1.0000
50.2400 256.0000 1.0000
50.2800 272.0000 1.0000
50.3200 274.0000 1.0000
50.3600 273.0000 1.0000
50.4000 267.0000 1.0000
50.4400 280.0000 1.0000
50.4800 283.0000 1.0000
50.5200 250.0000 1.0000
50.5600 266.0000 1.0000
50.6000 266.0000 1.0000
50.6400 265.0000 1.0000
50.6800 259.0000 1.0000
50.7200 261.0000 1.0000
50.7600 263.0000 1.0000
50.8000 286.0000 1.0000
50.8400 294.0000 1.0000
50.8800 290.0000 1.0000
50.9200 256.0000 1.0000
50.9600 286.0000 1.0000
51.0000 303.0000 1.0000
51.0400 275.0000 1.0000
51.0800 293.0000 1.0000
51.1200 321.0000 1.0000
51.1600 313.0000 1.0000
51.2000 362.0000 1.0000
51.2400 364.0000 1.0000
51.2800 448.0000 1.0000
51.3200 502.0000 1.0000
51.3600 584.0000 1.0000
51.4000 796.0000 1.0000
51.4400 887.0000 1.0000
51.4800 976.0000 1.0000
51.5200 924.0000 1.0000
51.5600 851.0000 1.0000
51.6000 825.0000 1.0000
51.6400 641.0000 1.0000
51.6800 604.0000 1.0000
51.7200 467.0000 1.0000
51.7600 427.0000 1.0000
51.8000 378.0000 1.0000
51.8400 395.0000 1.0000
51.8800 324.0000 1.0000
51.9200 295.0000 1.0000
51.9600 332.0000 1.0000
52.0000 293.0000 1.0000
52.0400 287.0000 1.0000
52.0800 295.0000 1.0000
52.1200 281.0000 1.0000
52.1600 279.0000 1.0000
52.2000 255.0000 1.0000
52.2400 270.0000 1.0000
52.2800 275.0000 1.0000
52.3200 268.0000 1.0000
52.3600 269.0000 1.0000
52.4000 259.0000 1.0000
52.4400 248.0000 1.0000
52.4800 272.0000 1.0000
52.5200 234.0000 1.0000
52.5600 252.0000 1.0000
52.6000 247.0000 1.0000
52.6400 262.0000 1.0000
52.6800 275.0000 1.0000
52.7200 275.0000 1.0000
52.7600 269.0000 1.0000
52.8000 272.0000 1.0000
52.8400 263.0000 1.0000
52.8800 246.0000 1.0000
52.9200 251.0000 1.0000
52.9600 280.0000 1.0000
53.0000 251.0000 1.0000
53.0400 249.0000 1.0000
53.0800 276.0000 1.0000
53.1200 262.0000 1.0000
53.1600 279.0000 1.0000
53.2000 278.0000 1.0000
53.2400 255.0000 1.0000
53.2800 252.0000 1.0000
53.3200 246.0000 1.0000
53.3600 247.0000 1.0000
53.4000 259.0000 1.0000
53.4400 262.0000 1.0000
53.4800 247.0000 1.0000
53.5200 248.0000 1.0000
53.5600 281.0000 1.0000
53.6000 280.0000 1.0000
53.6400 265.0000 1.0000
53.6800 254.0000 1.0000
53.7200 254.0000 1.0000
53.7600 253.0000 1.0000
53.8000 263.0000 1.0000
53.8400 269.0000 1.0000
53.8800 288.0000 1.0000
53.9200 268.0000 1.0000
53.9600 280.0000 1.0000
54.0000 270.0000 1.0000
54.0400 298.0000 1.0000
54.0800 296.0000 1.0000
54.1200 301.0000 1.0000
54.1600 275.0000 1.0000
54.2000 259.0000 1.0000
54.2400 282.0000 1.0000
54.2800 275.0000 1.0000
54.3200 260.0000 1.0000
54.3600 310.0000 1.0000
54.4000 298.0000 1.0000
54.4400 307.0000 1.0000
54.4800 301.0000 1.0000
54.5200 303.0000 1.0000
54.5600 318.0000 1.0000
54.6000 303.0000 1.0000
54.6400 300.0000 1.0000
54.6800 300.0000 1.0000
54.7200 253.0000 1.0000
54.7600 272.0000 1.0000
54.8000 279.0000 1.0000
54.8400 281.0000 1.0000
54.8800 285.0000 1.0000
54.9200 263.0000 1.0000
54.9600 249.0000 1.0000
55.0000 277.0000 1.0000
55.0400 274.0000 1.0000
55.0800 233.0000 1.0000
55.1200 255.0000 1.0000
55.1600 240.0000 1.0000
55.2000 277.0000 1.0000
55.2400 244.0000 1.0000
55.2800 246.0000 1.0000
55.3200 233.0000 1.0000
55.3600 277.0000 1.0000
55.4000 257.0000 1.0000
55.4400 256.0000 1.0000
55.4800 264.0000 1.0000
55.5200 279.0000 1.0000
55.5600 259.0000 1.0000
55.6000 253.0000 1.0000
55.6400 250.0000 1.0000
55.6800 260.0000 1.0000
55.7200 264.0000 1.0000
55.7600 246.0000 1.0000
55.8000 243.0000 1.0000
55.8400 249.0000 1.0000
55.8800 258.0000 1.0000
55.9200 276.0000 1.0000
55.9600 265.0000 1.0000
56.0000 226.0000 1.0000
56.0400 251.0000 1.0000
56.0800 258.0000 1.0000
56.1200 260.0000 1.0000
56.1600 266.0000 1.0000
56.2000 265.0000 1.0000
56.2400 294.0000 1.0000
56.2800 244.0000 1.0000
56.3200 247.0000 1.0000
56.3600 218.0000 1.0000
56.4000 242.0000 1.0000
56.4400 236.0000 1.0000
56.4800 244.0000 1.0000
56.5200 266.0000 1.0000
56.5600 240.0000 1.0000
56.6000 240.0000 1.0000
56.6400 250.0000 1.0000
56.6800 246.0000 1.0000
56.7200 239.0000 1.0000
56.7600 221.0000 1.0000
56.8000 257.0000 1.0000
56.8400 258.0000 1.0000
56.8800 236.0000 1.0000
56.9200 236.0000 1.0000
56.9600 263.0000 1.0000
57.0000 237.0000 1.0000
57.0400 227.0000 1.0000
57.0800 246.0000 1.0000
57.1200 233.0000 1.0000
57.1600 243.0000 1.0000
57.2000 267.0000 1.0000
57.2400 265.0000 1.0000
57.2800 255.0000 1.0000
57.3200 252.0000 1.0000
57.3600 231.0000 1.0000
57.4000 247.0000 1.0000
57.4400 252.0000 1.0000
57.4800 262.0000 1.0000
57.5200 274.0000 1.0000
57.5600 246.0000 1.0000
57.6000 257.0000 1.0000
57.6400 264.0000 1.0000
57.6800 267.0000 1.0000
57.7200 231.0000 1.0000
57.7600 248.0000 1.0000
57.8000 248.0000 1.0000
57.8400 232.0000 1.0000
57.8800 240.0000 1.0000
57.9200 280.0000 1.0000
57.9600 235.0000 1.0000
58.0000 249.0000 1.0000
58.0400 254.0000 1.0000
58.0800 235.0000 1.0000
58.1200 232.0000 1.0000
58.1600 250.0000 1.0000
58.2000 243.0000 1.0000
58.2400 234.0000 1.0000
58.2800 250.0000 1.0000
58.3200 271.0000 1.0000
58.3600 253.0000 1.0000
58.4000 240.0000 1.0000
58.4400 257.0000 1.0000
58.4800 230.0000 1.0000
58.5200 217.0000 1.0000
58.5600 240.0000 1.0000
58.6000 226.0000 1.0000
58.6400 238.0000 1.0000
58.6800 278.0000 1.0000
58.7200 236.0000 1.0000
58.7600 252.0000 1.0000
58.8000 256.0000 1.0000
58.8400 244.0000 1.0000
58.8800 258.0000 1.0000
58.9200 219.0000 1.0000
58.9600 256.0000 1.0000
59.0000 257.0000 1.0000
59.0400 253.0000 1.0000
59.0800 255.0000 1.0000
59.1200 249.0000 1.0000
59.1600 221.0000 1.0000
59.2000 253.0000 1.0000
59.2400 235.0000 1.0000
59.2800 250.0000 1.0000
59.3200 248.0000 1.0000
59.3600 231.0000 1.0000
59.4000 248.0000 1.0000
59.4400 242.0000 1.0000
59.4800 245.0000 1.0000
59.5200 267.0000 1.0000
59.5600 248.0000 1.0000
59.6000 273.0000 1.0000
59.6400 258.0000 1.0000
59.6800 245.0000 1.0000
59.7200 234.0000 1.0000
59.7600 260.0000 1.0000
59.8000 246.0000 1.0000
59.8400 251.0000 1.0000
59.8800 238.0000 1.0000
59.9200 252.0000 1.0000
59.9600 264.0000 1.0000
60.0000 254.0000 1.0000
60.0400 246.0000 1.0000
60.0800 249.0000 1.0000
60.1200 264.0000 1.0000
60.1600 264.0000 1.0000
60.2000 238.0000 1.0000
60.2400 258.0000 1.0000
60.2800 240.0000 1.0000
60.3200 247.0000 1.0000
60.3600 234.0000 1.0000
60.4000 253.0000 1.0000
60.4400 247.0000 1.0000
60.4800 239.0000 1.0000
60.5200 232.0000 1.0000
60.5600 261.0000 1.0000
60.6000 229.0000 1.0000
60.6400 253.0000 1.0000
60.6800 239.0000 1.0000
60.7200 241.0000 1.0000
60.7600 270.0000 1.0000
60.8000 239.0000 1.0000
60.8400 271.0000 1.0000
60.8800 290.0000 1.0000
60.9200 290.0000 1.0000
60.9600 247.0000 1.0000
61.0000 277.0000 1.0000
61.0400 285.0000 1.0000
61.0800 266.0000 1.0000
61.1200 268.0000 1.0000
61.1600 292.0000 1.0000
61.2000 321.0000 1.0000
61.2400 323.0000 1.0000
61.2800 349.0000 1.0000
61.3200 373.0000 1.0000
61.3600 393.0000 1.0000
61.4000 423.0000 1.0000
61.4400 441.0000 1.0000
61.4800 486.0000 1.0000
61.5200 509.0000 1.0000
61.5600 488.0000 1.0000
61.6000 530.0000 1.0000
61.6400 539.0000 1.0000
61.6800 495.0000 1.0000
61.7200 457.0000 1.0000
61.7600 456.0000 1.0000
61.8000 445.0000 1.0000
61.8400 422.0000 1.0000
61.8800 375.0000 1.0000
61.9200 400.0000 1.0000
61.9600 354.0000 1.0000
62.0000 302.0000 1.0000
62.0400 296.0000 1.0000
62.0800 319.0000 1.0000
62.1200 291.0000 1.0000
62.1600 259.0000 1.0000
62.2000 300.0000 1.0000
62.2400 282.0000 1.0000
62.2800 302.0000 1.0000
62.3200 291.0000 1.0000
62.3600 273.0000 1.0000
62.4000 287.0000 1.0000
62.4400 290.0000 1.0000
62.4800 305.0000 1.0000
62.5200 266.0000 1.0000
62.5600 266.0000 1.0000
62.6000 289.0000 1.0000
62.6400 256.0000 1.0000
62.6800 288.0000 1.0000
62.7200 268.0000 1.0000
62.7600 257.0000 1.0000
62.8000 248.0000 1.0000
62.8400 237.0000 1.0000
62.8800 244.0000 1.0000
62.9200 253.0000 1.0000
62.9600 251.0000 1.0000
63.0000 255.0000 1.0000
63.0400 248.0000 1.0000
63.0800 264.0000 1.0000
63.1200 234.0000 1.0000
63.1600 240.0000 1.0000
63.2000 228.0000 1.0000
63.2400 257.0000 1.0000
63.2800 245.0000 1.0000
63.3200 269.0000 1.0000
63.3600 257.0000 1.0000
63.4000 262.0000 1.0000
63.4400 235.0000 1.0000
63.4800 242.0000 1.0000
63.5200 260.0000 1.0000
63.5600 261.0000 1.0000
63.6000 226.0000 1.0000
63.6400 257.0000 1.0000
63.6800 238.0000 1.0000
63.7200 235.0000 1.0000
63.7600 267.0000 1.0000
63.8000 292.0000 1.0000
63.8400 274.0000 1.0000
63.8800 282.0000 1.0000
63.9200 306.0000 1.0000
63.9600 302.0000 1.0000
64.0000 299.0000 1.0000
64.0400 265.0000 1.0000
64.0800 293.0000 1.0000
64.1200 299.0000 1.0000
64.1600 291.0000 1.0000
64.2000 263.0000 1.0000
64.2400 242.0000 1.0000
64.2800 242.0000 1.0000
64.3200 256.0000 1.0000
64.3600 254.0000 1.0000
64.4000 261.0000 1.0000
64.4400 235.0000 1.0000
64.4800 257.0000 1.0000
64.5200 267.0000 1.0000
64.5600 271.0000 1.0000
64.6000 251.0000 1.0000
64.6400 250.0000 1.0000
64.6800 257.0000 1.0000
64.7200 258.0000 1.0000
64.7600 257.0000 1.0000
64.8000 276.0000 1.0000
64.8400 259.0000 1.0000
64.8800 262.0000 1.0000
64.9200 268.0000 1.0000
64.9600 307.0000 1.0000
65.0000 302.0000 1.0000
65.0400 285.0000 1.0000
65.0800 300.0000 1.0000
65.1200 323.0000 1.0000
65.1600 325.0000 1.0000
65.2000 344.0000 1.0000
65.2400 348.0000 1.0000
65.2800 412.0000 1.0000
65.3200 492.0000 1.0000
65.3600 531.0000 1.0000
65.4000 644.0000 1.0000
65.4400 758.0000 1.0000
65.4800 807.0000 1.0000
65.5200 840.0000 1.0000
65.5600 756.0000 1.0000
65.6000 770.0000 1.0000
65.6400 708.0000 1.0000
65.6800 676.0000 1.0000
65.7200 583.0000 1.0000
65.7600 528.0000 1.0000
65.8000 431.0000 1.0000
65.8400 398.0000 1.0000
65.8800 365.0000 1.0000
65.9200 316.0000 1.0000
65.9600 315.0000 1.0000
66.0000 313.0000 1.0000
66.0400 297.0000 1.0000
66.0800 299.0000 1.0000
66.1200 262.0000 1.0000
66.1600 267.0000 1.0000
66.2000 259.0000 1.0000
66.2400 280.0000 1.0000
66.2800 244.0000 1.0000
66.3200 229.0000 1.0000
66.3600 237.0000 1.0000
66.4000 263.0000 1.0000
66.4400 229.0000 1.0000
66.4800 234.0000 1.0000
66.5200 240.0000 1.0000
66.5600 243.0000 1.0000
66.6000 234.0000 1.0000
66.6400 216.0000 1.0000
66.6800 225.0000 1.0000
66.7200 246.0000 1.0000
66.7600 233.0000 1.0000
66.8000 229.0000 1.0000
66.8400 250.0000 1.0000
66.8800 230.0000 1.0000
66.9200 237.0000 1.0000
66.9600 257.0000 1.0000
67.0000 233.0000 1.0000
67.0400 243.0000 1.0000
67.0800 249.0000 1.0000
67.1200 239.0000 1.0000
67.1600 238.0000 1.0000
67.2000 232.0000 1.0000
67.2400 255.0000 1.0000
67.2800 219.0000 1.0000
67.3200 199.0000 1.0000
67.3600 238.0000 1.0000
67.4000 212.0000 1.0000
67.4400 211.0000 1.0000
67.4800 221.0000 1.0000
67.5200 234.0000 1.0000
67.5600 229.0000 1.0000
67.6000 226.0000 1.0000
67.6400 220.0000 1.0000
67.6800 236.0000 1.0000
67.7200 212.0000 1.0000
67.7600 217.0000 1.0000
67.8000 227.0000 1.0000
67.8400 247.0000 1.0000
67.8800 242.0000 1.0000
67.9200 212.0000 1.0000
67.9600 218.0000 1.0000
68.0000 218.0000 1.0000
68.0400 227.0000 1.0000
68.0800 224.0000 1.0000
68.1200 214.0000 1.0000
68.1600 218.0000 1.0000
68.2000 210.0000 1.0000
68.2400 219.0000 1.0000
68.2800 224.0000 1.0000
68.3200 223.0000 1.0000
68.3600 209.0000 1.0000
68.4000 211.0000 1.0000
68.4400 219.0000 1.0000
68.4800 199.0000 1.0000
68.5200 204.0000 1.0000
68.5600 209.0000 1.0000
68.6000 212.0000 1.0000
68.6400 222.0000 1.0000
68.6800 230.0000 1.0000
68.7200 211.0000 1.0000
68.7600 226.0000 1.0000
68.8000 202.0000 1.0000
68.8400 190.0000 1.0000
68.8800 221.0000 1.0000
68.9200 203.0000 1.0000
68.9600 220.0000 1.0000
69.0000 207.0000 1.0000
69.0400 230.0000 1.0000
69.0800 219.0000 1.0000
69.1200 197.0000 1.0000
69.1600 223.0000 1.0000
69.2000 217.0000 1.0000
69.2400 202.0000 1.0000
69.2800 223.0000 1.0000
69.3200 216.0000 1.0000
69.3600 204.0000 1.0000
69.4000 214.0000 1.0000
69.4400 191.0000 1.0000
69.4800 218.0000 1.0000
69.5200 211.0000 1.0000
69.5600 223.0000 1.0000
69.6000 221.0000 1.0000
69.6400 227.0000 1.0000
69.6800 221.0000 1.0000
69.7200 201.0000 1.0000
69.7600 204.0000 1.0000
69.8000 202.0000 1.0000
69.8400 219.0000 1.0000
69.8800 221.0000 1.0000
69.9200 220.0000 1.0000
69.9600 224.0000 1.0000
70.0000 212.0000 1.0000
*RAS_INT_END
*RAS_TEMPERATURE_START
*RAS_TEMPERATURE_END
*RAS_DATA_END