File: Data/Dataset2_Water_Organic/4_XRD/No_51_2312020240118_MeOH_3.ras
*RAS_DATA_START
*RAS_HEADER_START
*DISP_FMT_X "%.2f"
*DISP_FMT_Y "%.0f"
*DISP_FULLSCALE "15485.0000000000"
*DISP_LINE_COLOR "255.0000000000"
*DISP_LINE_STYLE "0.0000000000"
*DISP_LINE_WIDTH "0.2500000000"
*DISP_NOTE "測定データ-3"
*DISP_OFFSET_Y "0.0000000000"
*DISP_PEAKSEARCH_UNIT_Y "cps"
*DISP_RANGE_BOTTOM "0.0000000000"
*DISP_RANGE_LEFT "20.0000000000"
*DISP_RANGE_LOGCUTOFF "0.0100000000"
*DISP_RANGE_RIGHT "70.0000000000"
*DISP_RANGE_TOP "15485.0000000000"
*DISP_SCALE_MODE_Y "0.0000000000"
*DISP_TAB_NAME "2θ/θ"
*DISP_TITLE_Y "強度"
*DISP_UNIT_Y "cps"
*DISP_WINDOW_NAME "MSG_MACROENGINE"
*FILE_COMMENT " "
*FILE_MD5 ""
*FILE_MEMO " "
*FILE_OPERATOR "Administrator"
*FILE_SAMPLE " "
*FILE_TYPE "RAS_RAW"
*FILE_USERGROUP "システムマネージャ"
*FILE_VERSION "1.0000000000"
*HW_ATTACHMENT_ID "ATT0025"
*HW_ATTACHMENT_NAME "標準|Standard"
*HW_COUNTER_ID-0 "CUT0025"
*HW_COUNTER_ID-1 "CUT0020"
*HW_COUNTER_ID-2 "CUT0020"
*HW_COUNTER_ID-3 "CSL0021"
*HW_COUNTER_ID-4 "CMC0021"
*HW_COUNTER_NAME-0 "D/teX Ultra|D/teX Ultra"
*HW_COUNTER_NAME-1 "None|None"
*HW_COUNTER_NAME-2 "None|None"
*HW_COUNTER_NAME-3 "BBM|BBM"
*HW_COUNTER_NAME-4 "検出器モノクロメータ|Detector monochromator"
*HW_COUNTER_SELECT_NAME "D/teX Ultra|D/teX Ultra"
*HW_GONIOMETER_ID "GON0023"
*HW_GONIOMETER_NAME "SmartLab|SmartLab"
*HW_GONIOMETER_RADIUS-0 "90.0"
*HW_GONIOMETER_RADIUS-1 "114.0"
*HW_GONIOMETER_RADIUS-2 "190.0"
*HW_GONIOMETER_RADIUS-3 "300.0"
*HW_GONIOMETER_RADIUS-4 "187.0"
*HW_GONIOMETER_RADIUS-5 "300.0"
*HW_GONIOMETER_RADIUS-6 "113.0"
*HW_GONIOMETER_RADIUS-7 "331.0"
*HW_I_OPT_ID-0 "CBO0021"
*HW_I_OPT_ID-1 "ICR0023"
*HW_I_OPT_ID-2 "ISL0021"
*HW_I_OPT_ID-3 "ISO0021"
*HW_I_OPT_ID-4 "IAD0021"
*HW_I_OPT_ID-5 "IPR0001"
*HW_I_OPT_NAME-0 "CBOユニット|CBO unit"
*HW_I_OPT_NAME-1 "標準入射光学ユニット|Standard incident optical unit"
*HW_I_OPT_NAME-2 "標準入射スリットボックス|Standard incident slit box"
*HW_I_OPT_NAME-3 "入射平行スリット|Incident parallel slit"
*HW_I_OPT_NAME-4 "長手制限スリット|Length limiting slit"
*HW_I_OPT_NAME-5 "None|None"
*HW_R_ATTENUATER_AUTOMODE "0"
*HW_R_OPT_ID-0 "RSS0021"
*HW_R_OPT_ID-1 "RCR0023"
*HW_R_OPT_ID-2 "RSO0021"
*HW_R_OPT_ID-3 "RRS0021"
*HW_R_OPT_ID-4 "ATN0021"
*HW_R_OPT_ID-5 "RFL0021"
*HW_R_OPT_ID-6 "RAD0021"
*HW_R_OPT_NAME-0 "標準受光スリットボックス1|Standard receiving slit box # 1"
*HW_R_OPT_NAME-1 "標準受光光学ユニット1|Standard receiving unit # 1"
*HW_R_OPT_NAME-2 "標準受光光学ユニット2|Standard receiving optical unit # 2"
*HW_R_OPT_NAME-3 "標準受光スリットボックス2|Standard receiving slit box # 2"
*HW_R_OPT_NAME-4 "標準アッテネータ|Standard Attenuator"
*HW_R_OPT_NAME-5 "Cu Kβ|Cu K-beta"
*HW_R_OPT_NAME-6 "調整用受光スリット|Alignment receiving slit"
*HW_SAMPLE_HOLDER_ID "SMP0023"
*HW_SAMPLE_HOLDER_NAME "標準Zステージ|Standard Z stage"
*HW_XG_CURRENT_MAX "50"
*HW_XG_CURRENT_MIN "2"
*HW_XG_CURRENT_RESOLUTION "1"
*HW_XG_CURRENT_UNIT "mA"
*HW_XG_FOCUS "1mm x 10mm"
*HW_XG_FOCUS_TYPE "Normal"
*HW_XG_ID ""
*HW_XG_NAME "3kW 封入管(ID:1200)|3kW Sealed tube(ID:1200)"
*HW_XG_TARGET_ATOMIC_NUMBER "29.0000000000"
*HW_XG_TARGET_NAME "Cu"
*HW_XG_TYPE "Hermetic"
*HW_XG_VOLTAGE_MAX "60"
*HW_XG_VOLTAGE_MIN "20"
*HW_XG_VOLTAGE_RESOLUTION "1"
*HW_XG_VOLTAGE_UNIT "kV"
*HW_XG_WATT_MAX "1.500"
*HW_XG_WATT_UNIT "kW"
*HW_XG_WAVE_LENGTH_ALPHA1 "1.540593"
*HW_XG_WAVE_LENGTH_ALPHA2 "1.544414"
*HW_XG_WAVE_LENGTH_BETA "1.392250"
*MEAS_COND_AXIS_NAME-0 "2θ/θ"
*MEAS_COND_AXIS_NAME-1 "2θ"
*MEAS_COND_AXIS_NAME-2 "ω"
*MEAS_COND_AXIS_NAME-3 "Z"
*MEAS_COND_AXIS_NAME-4 "2θ/ω"
*MEAS_COND_AXIS_NAME-5 "θs"
*MEAS_COND_AXIS_NAME-6 "θd"
*MEAS_COND_AXIS_NAME-7 "Ts"
*MEAS_COND_AXIS_NAME-8 "CBO選択スリット"
*MEAS_COND_AXIS_NAME-9 "M"
*MEAS_COND_AXIS_NAME-10 "入射平行スリット"
*MEAS_COND_AXIS_NAME-11 "入射スリット"
*MEAS_COND_AXIS_NAME-12 ""
*MEAS_COND_AXIS_NAME-13 "Zs"
*MEAS_COND_AXIS_NAME-14 "入射光学素子"
*MEAS_COND_AXIS_NAME-15 "長手制限スリット"
*MEAS_COND_AXIS_NAME-16 "センタースリット"
*MEAS_COND_AXIS_NAME-17 "フィルター"
*MEAS_COND_AXIS_NAME-18 "受光スリット1"
*MEAS_COND_AXIS_NAME-19 "受光スリット2"
*MEAS_COND_AXIS_NAME-20 "受光光学素子"
*MEAS_COND_AXIS_NAME-21 "受光平行スリット"
*MEAS_COND_AXIS_NAME-22 "調整用受光スリット"
*MEAS_COND_AXIS_NAME-23 ""
*MEAS_COND_AXIS_NAME-24 ""
*MEAS_COND_AXIS_NAME-25 "Zd"
*MEAS_COND_AXIS_NAME-26 "アッテネータ"
*MEAS_COND_AXIS_NAME-27 "検出器モノクロメータ"
*MEAS_COND_AXIS_NAME-28 "モノクロメータスリット"
*MEAS_COND_AXIS_NAME-29 "プライマリビーム"
*MEAS_COND_AXIS_NAME-30 "PHA"
*MEAS_COND_AXIS_NAME_INTERNAL-0 "TwoThetaTheta"
*MEAS_COND_AXIS_NAME_INTERNAL-1 "TwoTheta"
*MEAS_COND_AXIS_NAME_INTERNAL-2 "Omega"
*MEAS_COND_AXIS_NAME_INTERNAL-3 "Z"
*MEAS_COND_AXIS_NAME_INTERNAL-4 "TwoThetaOmega"
*MEAS_COND_AXIS_NAME_INTERNAL-5 "ThetaS"
*MEAS_COND_AXIS_NAME_INTERNAL-6 "ThetaD"
*MEAS_COND_AXIS_NAME_INTERNAL-7 "Ts"
*MEAS_COND_AXIS_NAME_INTERNAL-8 "CBO"
*MEAS_COND_AXIS_NAME_INTERNAL-9 "CBO-M"
*MEAS_COND_AXIS_NAME_INTERNAL-10 "IncidentSollerSlit"
*MEAS_COND_AXIS_NAME_INTERNAL-11 "IncidentSlitBox"
*MEAS_COND_AXIS_NAME_INTERNAL-12 "IncidentSlitBox-_Axis"
*MEAS_COND_AXIS_NAME_INTERNAL-13 "Zs"
*MEAS_COND_AXIS_NAME_INTERNAL-14 "IncidentMonochromator"
*MEAS_COND_AXIS_NAME_INTERNAL-15 "IncidentAxdSlit"
*MEAS_COND_AXIS_NAME_INTERNAL-16 "CenterSlit"
*MEAS_COND_AXIS_NAME_INTERNAL-17 "Filter"
*MEAS_COND_AXIS_NAME_INTERNAL-18 "ReceivingSlitBox1"
*MEAS_COND_AXIS_NAME_INTERNAL-19 "ReceivingSlitBox2"
*MEAS_COND_AXIS_NAME_INTERNAL-20 "ReceivingOptics"
*MEAS_COND_AXIS_NAME_INTERNAL-21 "ReceivingSollerSlit"
*MEAS_COND_AXIS_NAME_INTERNAL-22 "ReceivingAxdSlit"
*MEAS_COND_AXIS_NAME_INTERNAL-23 "ReceivingSlitBox1-_Axis"
*MEAS_COND_AXIS_NAME_INTERNAL-24 "ReceivingSlitBox2-_Axis"
*MEAS_COND_AXIS_NAME_INTERNAL-25 "ReceivingSlitBox2-Zd"
*MEAS_COND_AXIS_NAME_INTERNAL-26 "Attenuator"
*MEAS_COND_AXIS_NAME_INTERNAL-27 "CounterMonochromator"
*MEAS_COND_AXIS_NAME_INTERNAL-28 "CounterSlit"
*MEAS_COND_AXIS_NAME_INTERNAL-29 "IncidentPrimary"
*MEAS_COND_AXIS_NAME_INTERNAL-30 "PHA"
*MEAS_COND_AXIS_NAME_MAGICNO-0 "83951616.0000000000"
*MEAS_COND_AXIS_NAME_MAGICNO-1 "268632064.0000000000"
*MEAS_COND_AXIS_NAME_MAGICNO-2 "268500992.0000000000"
*MEAS_COND_AXIS_NAME_MAGICNO-3 "285278208.0000000000"
*MEAS_COND_AXIS_NAME_MAGICNO-4 "83951616.0000000000"
*MEAS_COND_AXIS_NAME_MAGICNO-5 "131072.0000000000"
*MEAS_COND_AXIS_NAME_MAGICNO-6 "131072.0000000000"
*MEAS_COND_AXIS_NAME_MAGICNO-7 "318898176.0000000000"
*MEAS_COND_AXIS_NAME_MAGICNO-8 "20971521.0000000000"
*MEAS_COND_AXIS_NAME_MAGICNO-9 "285343744.0000000000"
*MEAS_COND_AXIS_NAME_MAGICNO-10 "20971521.0000000000"
*MEAS_COND_AXIS_NAME_MAGICNO-11 "22020097.0000000000"
*MEAS_COND_AXIS_NAME_MAGICNO-12 "25165824.0000000000"
*MEAS_COND_AXIS_NAME_MAGICNO-13 "318898176.0000000000"
*MEAS_COND_AXIS_NAME_MAGICNO-14 "1.0000000000"
*MEAS_COND_AXIS_NAME_MAGICNO-15 "20971521.0000000000"
*MEAS_COND_AXIS_NAME_MAGICNO-16 "20971521.0000000000"
*MEAS_COND_AXIS_NAME_MAGICNO-17 "20971521.0000000000"
*MEAS_COND_AXIS_NAME_MAGICNO-18 "23068673.0000000000"
*MEAS_COND_AXIS_NAME_MAGICNO-19 "23068673.0000000000"
*MEAS_COND_AXIS_NAME_MAGICNO-20 "20971521.0000000000"
*MEAS_COND_AXIS_NAME_MAGICNO-21 "20971521.0000000000"
*MEAS_COND_AXIS_NAME_MAGICNO-22 "20971521.0000000000"
*MEAS_COND_AXIS_NAME_MAGICNO-23 "25165824.0000000000"
*MEAS_COND_AXIS_NAME_MAGICNO-24 "25165824.0000000000"
*MEAS_COND_AXIS_NAME_MAGICNO-25 "285343744.0000000000"
*MEAS_COND_AXIS_NAME_MAGICNO-26 "17301505.0000000000"
*MEAS_COND_AXIS_NAME_MAGICNO-27 "20971521.0000000000"
*MEAS_COND_AXIS_NAME_MAGICNO-28 "20971521.0000000000"
*MEAS_COND_AXIS_NAME_MAGICNO-29 "20971521.0000000000"
*MEAS_COND_AXIS_NAME_MAGICNO-30 "0.0000000000"
*MEAS_COND_AXIS_OFFSET-0 "-"
*MEAS_COND_AXIS_OFFSET-1 "-0.0310000000"
*MEAS_COND_AXIS_OFFSET-2 "0.3957000000"
*MEAS_COND_AXIS_OFFSET-3 "-"
*MEAS_COND_AXIS_OFFSET-4 "-"
*MEAS_COND_AXIS_OFFSET-5 "0.3957000000"
*MEAS_COND_AXIS_OFFSET-6 "-0.4267000000"
*MEAS_COND_AXIS_OFFSET-7 "-"
*MEAS_COND_AXIS_OFFSET-8 "-"
*MEAS_COND_AXIS_OFFSET-9 "-"
*MEAS_COND_AXIS_OFFSET-10 "-"
*MEAS_COND_AXIS_OFFSET-11 "-"
*MEAS_COND_AXIS_OFFSET-12 "-"
*MEAS_COND_AXIS_OFFSET-13 "-"
*MEAS_COND_AXIS_OFFSET-14 "-"
*MEAS_COND_AXIS_OFFSET-15 "-"
*MEAS_COND_AXIS_OFFSET-16 "-"
*MEAS_COND_AXIS_OFFSET-17 "-"
*MEAS_COND_AXIS_OFFSET-18 "-"
*MEAS_COND_AXIS_OFFSET-19 "-"
*MEAS_COND_AXIS_OFFSET-20 "-"
*MEAS_COND_AXIS_OFFSET-21 "-"
*MEAS_COND_AXIS_OFFSET-22 "-"
*MEAS_COND_AXIS_OFFSET-23 "-"
*MEAS_COND_AXIS_OFFSET-24 "-"
*MEAS_COND_AXIS_OFFSET-25 "-"
*MEAS_COND_AXIS_OFFSET-26 "-"
*MEAS_COND_AXIS_OFFSET-27 "-"
*MEAS_COND_AXIS_OFFSET-28 "-"
*MEAS_COND_AXIS_OFFSET-29 "-"
*MEAS_COND_AXIS_OFFSET-30 "-"
*MEAS_COND_AXIS_POSITION-0 "0.0000000000"
*MEAS_COND_AXIS_POSITION-1 "0.0000000000"
*MEAS_COND_AXIS_POSITION-2 "0.0000000000"
*MEAS_COND_AXIS_POSITION-3 "-2.8588600000"
*MEAS_COND_AXIS_POSITION-4 "0.0000000000"
*MEAS_COND_AXIS_POSITION-5 "0.0000000000"
*MEAS_COND_AXIS_POSITION-6 "0.0000000000"
*MEAS_COND_AXIS_POSITION-7 "-0.7498700000"
*MEAS_COND_AXIS_POSITION-8 "BB"
*MEAS_COND_AXIS_POSITION-9 "0.0000000000"
*MEAS_COND_AXIS_POSITION-10 "Soller_slit_5.0deg"
*MEAS_COND_AXIS_POSITION-11 "2/3deg"
*MEAS_COND_AXIS_POSITION-12 "2.2088000000"
*MEAS_COND_AXIS_POSITION-13 "-0.6412500000"
*MEAS_COND_AXIS_POSITION-14 "0.0000000000"
*MEAS_COND_AXIS_POSITION-15 "10.0mm"
*MEAS_COND_AXIS_POSITION-16 "None"
*MEAS_COND_AXIS_POSITION-17 "Cu_K-beta"
*MEAS_COND_AXIS_POSITION-18 "13.000mm"
*MEAS_COND_AXIS_POSITION-19 "13.000mm"
*MEAS_COND_AXIS_POSITION-20 "No_unit"
*MEAS_COND_AXIS_POSITION-21 "Soller_slit_5.0deg"
*MEAS_COND_AXIS_POSITION-22 "None"
*MEAS_COND_AXIS_POSITION-23 "13.0000000000"
*MEAS_COND_AXIS_POSITION-24 "13.0000000000"
*MEAS_COND_AXIS_POSITION-25 "0.0281300000"
*MEAS_COND_AXIS_POSITION-26 "Open"
*MEAS_COND_AXIS_POSITION-27 "None"
*MEAS_COND_AXIS_POSITION-28 "None"
*MEAS_COND_AXIS_POSITION-29 "None"
*MEAS_COND_AXIS_POSITION-30 "38.0000000000"
*MEAS_COND_AXIS_UNIT-0 "deg"
*MEAS_COND_AXIS_UNIT-1 "deg"
*MEAS_COND_AXIS_UNIT-2 "deg"
*MEAS_COND_AXIS_UNIT-3 "mm"
*MEAS_COND_AXIS_UNIT-4 "deg"
*MEAS_COND_AXIS_UNIT-5 "deg"
*MEAS_COND_AXIS_UNIT-6 "deg"
*MEAS_COND_AXIS_UNIT-7 "mm"
*MEAS_COND_AXIS_UNIT-8 ""
*MEAS_COND_AXIS_UNIT-9 "pulse"
*MEAS_COND_AXIS_UNIT-10 ""
*MEAS_COND_AXIS_UNIT-11 ""
*MEAS_COND_AXIS_UNIT-12 "mm"
*MEAS_COND_AXIS_UNIT-13 "mm"
*MEAS_COND_AXIS_UNIT-14 ""
*MEAS_COND_AXIS_UNIT-15 ""
*MEAS_COND_AXIS_UNIT-16 ""
*MEAS_COND_AXIS_UNIT-17 ""
*MEAS_COND_AXIS_UNIT-18 ""
*MEAS_COND_AXIS_UNIT-19 ""
*MEAS_COND_AXIS_UNIT-20 ""
*MEAS_COND_AXIS_UNIT-21 ""
*MEAS_COND_AXIS_UNIT-22 ""
*MEAS_COND_AXIS_UNIT-23 "mm"
*MEAS_COND_AXIS_UNIT-24 "mm"
*MEAS_COND_AXIS_UNIT-25 "mm"
*MEAS_COND_AXIS_UNIT-26 ""
*MEAS_COND_AXIS_UNIT-27 ""
*MEAS_COND_AXIS_UNIT-28 ""
*MEAS_COND_AXIS_UNIT-29 ""
*MEAS_COND_AXIS_UNIT-30 "div"
*MEAS_COND_COUNTER_CNTLOSS_CORR "0.0000000000"
*MEAS_COND_COUNTER_PHABASE "38.0000000000"
*MEAS_COND_COUNTER_PHAWINDOW "16.0000000000"
*MEAS_COND_COUNTER_PHA_UNIT "div"
*MEAS_COND_COUNTER_TAUDIFF "30.0000000000"
*MEAS_COND_COUNTER_TAUINT "0.0000000000"
*MEAS_COND_IRRADIATION_MODE "OFF"
*MEAS_COND_IRRADIATION_WIDTH ""
*MEAS_COND_OPT_ATTR "集中法"
*MEAS_COND_OPT_NAME "@集中法"
*MEAS_COND_UNSYMMETRIC_MODE "OFF"
*MEAS_COND_XG_CURRENT "30.0000000000"
*MEAS_COND_XG_VOLTAGE "40.0000000000"
*MEAS_COND_XG_WAVE_TYPE "Ka"
*MEAS_DATA_COUNT "5001.0000000000"
*MEAS_SCAN_AXIS_X "2θ/θ"
*MEAS_SCAN_AXIS_X_INTERNAL "TwoThetaTheta"
*MEAS_SCAN_END_TIME "01/29/24 11:41:37"
*MEAS_SCAN_MODE "CONTINUOUS"
*MEAS_SCAN_MONITOR "0"
*MEAS_SCAN_RESOLUTION_X "0.0002"
*MEAS_SCAN_SPEED "2.5"
*MEAS_SCAN_SPEED_UNIT "deg/min"
*MEAS_SCAN_START "20.0000000000"
*MEAS_SCAN_START_TIME "01/29/24 11:20:13"
*MEAS_SCAN_STEP "0.0100000000"
*MEAS_SCAN_STOP "70.0000000000"
*MEAS_SCAN_UNIT_X "deg"
*MEAS_SCAN_UNIT_Y "counts"
*RAS_HEADER_END
*RAS_INT_START
20.0000 721.0000 1.0000
20.0400 728.0000 1.0000
20.0800 739.0000 1.0000
20.1200 723.0000 1.0000
20.1600 774.0000 1.0000
20.2000 753.0000 1.0000
20.2400 738.0000 1.0000
20.2800 710.0000 1.0000
20.3200 702.0000 1.0000
20.3600 717.0000 1.0000
20.4000 721.0000 1.0000
20.4400 778.0000 1.0000
20.4800 731.0000 1.0000
20.5200 721.0000 1.0000
20.5600 721.0000 1.0000
20.6000 719.0000 1.0000
20.6400 730.0000 1.0000
20.6800 760.0000 1.0000
20.7200 749.0000 1.0000
20.7600 730.0000 1.0000
20.8000 688.0000 1.0000
20.8400 724.0000 1.0000
20.8800 705.0000 1.0000
20.9200 675.0000 1.0000
20.9600 692.0000 1.0000
21.0000 699.0000 1.0000
21.0400 705.0000 1.0000
21.0800 701.0000 1.0000
21.1200 765.0000 1.0000
21.1600 728.0000 1.0000
21.2000 679.0000 1.0000
21.2400 716.0000 1.0000
21.2800 710.0000 1.0000
21.3200 746.0000 1.0000
21.3600 750.0000 1.0000
21.4000 751.0000 1.0000
21.4400 705.0000 1.0000
21.4800 714.0000 1.0000
21.5200 724.0000 1.0000
21.5600 745.0000 1.0000
21.6000 717.0000 1.0000
21.6400 763.0000 1.0000
21.6800 738.0000 1.0000
21.7200 752.0000 1.0000
21.7600 747.0000 1.0000
21.8000 710.0000 1.0000
21.8400 730.0000 1.0000
21.8800 744.0000 1.0000
21.9200 713.0000 1.0000
21.9600 707.0000 1.0000
22.0000 699.0000 1.0000
22.0400 734.0000 1.0000
22.0800 739.0000 1.0000
22.1200 698.0000 1.0000
22.1600 701.0000 1.0000
22.2000 765.0000 1.0000
22.2400 727.0000 1.0000
22.2800 760.0000 1.0000
22.3200 720.0000 1.0000
22.3600 704.0000 1.0000
22.4000 747.0000 1.0000
22.4400 716.0000 1.0000
22.4800 741.0000 1.0000
22.5200 714.0000 1.0000
22.5600 747.0000 1.0000
22.6000 708.0000 1.0000
22.6400 698.0000 1.0000
22.6800 732.0000 1.0000
22.7200 729.0000 1.0000
22.7600 711.0000 1.0000
22.8000 728.0000 1.0000
22.8400 696.0000 1.0000
22.8800 713.0000 1.0000
22.9200 700.0000 1.0000
22.9600 731.0000 1.0000
23.0000 724.0000 1.0000
23.0400 709.0000 1.0000
23.0800 728.0000 1.0000
23.1200 643.0000 1.0000
23.1600 717.0000 1.0000
23.2000 735.0000 1.0000
23.2400 713.0000 1.0000
23.2800 739.0000 1.0000
23.3200 715.0000 1.0000
23.3600 721.0000 1.0000
23.4000 690.0000 1.0000
23.4400 707.0000 1.0000
23.4800 695.0000 1.0000
23.5200 686.0000 1.0000
23.5600 732.0000 1.0000
23.6000 715.0000 1.0000
23.6400 741.0000 1.0000
23.6800 689.0000 1.0000
23.7200 733.0000 1.0000
23.7600 692.0000 1.0000
23.8000 694.0000 1.0000
23.8400 728.0000 1.0000
23.8800 690.0000 1.0000
23.9200 712.0000 1.0000
23.9600 701.0000 1.0000
24.0000 748.0000 1.0000
24.0400 747.0000 1.0000
24.0800 784.0000 1.0000
24.1200 766.0000 1.0000
24.1600 783.0000 1.0000
24.2000 776.0000 1.0000
24.2400 706.0000 1.0000
24.2800 724.0000 1.0000
24.3200 712.0000 1.0000
24.3600 687.0000 1.0000
24.4000 679.0000 1.0000
24.4400 714.0000 1.0000
24.4800 724.0000 1.0000
24.5200 697.0000 1.0000
24.5600 664.0000 1.0000
24.6000 657.0000 1.0000
24.6400 656.0000 1.0000
24.6800 726.0000 1.0000
24.7200 706.0000 1.0000
24.7600 644.0000 1.0000
24.8000 673.0000 1.0000
24.8400 721.0000 1.0000
24.8800 690.0000 1.0000
24.9200 679.0000 1.0000
24.9600 700.0000 1.0000
25.0000 702.0000 1.0000
25.0400 697.0000 1.0000
25.0800 693.0000 1.0000
25.1200 684.0000 1.0000
25.1600 683.0000 1.0000
25.2000 665.0000 1.0000
25.2400 701.0000 1.0000
25.2800 705.0000 1.0000
25.3200 701.0000 1.0000
25.3600 689.0000 1.0000
25.4000 670.0000 1.0000
25.4400 683.0000 1.0000
25.4800 697.0000 1.0000
25.5200 706.0000 1.0000
25.5600 656.0000 1.0000
25.6000 647.0000 1.0000
25.6400 750.0000 1.0000
25.6800 696.0000 1.0000
25.7200 709.0000 1.0000
25.7600 705.0000 1.0000
25.8000 725.0000 1.0000
25.8400 692.0000 1.0000
25.8800 695.0000 1.0000
25.9200 752.0000 1.0000
25.9600 730.0000 1.0000
26.0000 747.0000 1.0000
26.0400 703.0000 1.0000
26.0800 789.0000 1.0000
26.1200 833.0000 1.0000
26.1600 892.0000 1.0000
26.2000 909.0000 1.0000
26.2400 945.0000 1.0000
26.2800 995.0000 1.0000
26.3200 1094.0000 1.0000
26.3600 1234.0000 1.0000
26.4000 1328.0000 1.0000
26.4400 1429.0000 1.0000
26.4800 1347.0000 1.0000
26.5200 1345.0000 1.0000
26.5600 1170.0000 1.0000
26.6000 1070.0000 1.0000
26.6400 977.0000 1.0000
26.6800 916.0000 1.0000
26.7200 815.0000 1.0000
26.7600 805.0000 1.0000
26.8000 830.0000 1.0000
26.8400 726.0000 1.0000
26.8800 722.0000 1.0000
26.9200 728.0000 1.0000
26.9600 681.0000 1.0000
27.0000 683.0000 1.0000
27.0400 640.0000 1.0000
27.0800 668.0000 1.0000
27.1200 660.0000 1.0000
27.1600 633.0000 1.0000
27.2000 658.0000 1.0000
27.2400 634.0000 1.0000
27.2800 672.0000 1.0000
27.3200 655.0000 1.0000
27.3600 608.0000 1.0000
27.4000 618.0000 1.0000
27.4400 660.0000 1.0000
27.4800 612.0000 1.0000
27.5200 580.0000 1.0000
27.5600 648.0000 1.0000
27.6000 606.0000 1.0000
27.6400 637.0000 1.0000
27.6800 598.0000 1.0000
27.7200 577.0000 1.0000
27.7600 638.0000 1.0000
27.8000 609.0000 1.0000
27.8400 604.0000 1.0000
27.8800 591.0000 1.0000
27.9200 659.0000 1.0000
27.9600 590.0000 1.0000
28.0000 586.0000 1.0000
28.0400 599.0000 1.0000
28.0800 577.0000 1.0000
28.1200 590.0000 1.0000
28.1600 613.0000 1.0000
28.2000 608.0000 1.0000
28.2400 633.0000 1.0000
28.2800 641.0000 1.0000
28.3200 568.0000 1.0000
28.3600 548.0000 1.0000
28.4000 605.0000 1.0000
28.4400 611.0000 1.0000
28.4800 595.0000 1.0000
28.5200 576.0000 1.0000
28.5600 569.0000 1.0000
28.6000 593.0000 1.0000
28.6400 552.0000 1.0000
28.6800 607.0000 1.0000
28.7200 560.0000 1.0000
28.7600 554.0000 1.0000
28.8000 539.0000 1.0000
28.8400 561.0000 1.0000
28.8800 555.0000 1.0000
28.9200 553.0000 1.0000
28.9600 602.0000 1.0000
29.0000 554.0000 1.0000
29.0400 586.0000 1.0000
29.0800 574.0000 1.0000
29.1200 606.0000 1.0000
29.1600 598.0000 1.0000
29.2000 571.0000 1.0000
29.2400 551.0000 1.0000
29.2800 586.0000 1.0000
29.3200 571.0000 1.0000
29.3600 558.0000 1.0000
29.4000 518.0000 1.0000
29.4400 578.0000 1.0000
29.4800 625.0000 1.0000
29.5200 508.0000 1.0000
29.5600 535.0000 1.0000
29.6000 564.0000 1.0000
29.6400 546.0000 1.0000
29.6800 547.0000 1.0000
29.7200 558.0000 1.0000
29.7600 560.0000 1.0000
29.8000 552.0000 1.0000
29.8400 569.0000 1.0000
29.8800 561.0000 1.0000
29.9200 554.0000 1.0000
29.9600 559.0000 1.0000
30.0000 563.0000 1.0000
30.0400 558.0000 1.0000
30.0800 563.0000 1.0000
30.1200 517.0000 1.0000
30.1600 543.0000 1.0000
30.2000 532.0000 1.0000
30.2400 547.0000 1.0000
30.2800 525.0000 1.0000
30.3200 538.0000 1.0000
30.3600 556.0000 1.0000
30.4000 541.0000 1.0000
30.4400 520.0000 1.0000
30.4800 550.0000 1.0000
30.5200 527.0000 1.0000
30.5600 555.0000 1.0000
30.6000 555.0000 1.0000
30.6400 551.0000 1.0000
30.6800 531.0000 1.0000
30.7200 519.0000 1.0000
30.7600 518.0000 1.0000
30.8000 518.0000 1.0000
30.8400 511.0000 1.0000
30.8800 539.0000 1.0000
30.9200 518.0000 1.0000
30.9600 533.0000 1.0000
31.0000 563.0000 1.0000
31.0400 580.0000 1.0000
31.0800 592.0000 1.0000
31.1200 551.0000 1.0000
31.1600 542.0000 1.0000
31.2000 584.0000 1.0000
31.2400 517.0000 1.0000
31.2800 537.0000 1.0000
31.3200 508.0000 1.0000
31.3600 499.0000 1.0000
31.4000 527.0000 1.0000
31.4400 527.0000 1.0000
31.4800 531.0000 1.0000
31.5200 508.0000 1.0000
31.5600 477.0000 1.0000
31.6000 496.0000 1.0000
31.6400 527.0000 1.0000
31.6800 536.0000 1.0000
31.7200 503.0000 1.0000
31.7600 516.0000 1.0000
31.8000 519.0000 1.0000
31.8400 480.0000 1.0000
31.8800 535.0000 1.0000
31.9200 498.0000 1.0000
31.9600 539.0000 1.0000
32.0000 502.0000 1.0000
32.0400 527.0000 1.0000
32.0800 538.0000 1.0000
32.1200 483.0000 1.0000
32.1600 525.0000 1.0000
32.2000 521.0000 1.0000
32.2400 501.0000 1.0000
32.2800 546.0000 1.0000
32.3200 492.0000 1.0000
32.3600 499.0000 1.0000
32.4000 467.0000 1.0000
32.4400 510.0000 1.0000
32.4800 481.0000 1.0000
32.5200 494.0000 1.0000
32.5600 478.0000 1.0000
32.6000 530.0000 1.0000
32.6400 492.0000 1.0000
32.6800 469.0000 1.0000
32.7200 509.0000 1.0000
32.7600 522.0000 1.0000
32.8000 519.0000 1.0000
32.8400 545.0000 1.0000
32.8800 515.0000 1.0000
32.9200 501.0000 1.0000
32.9600 533.0000 1.0000
33.0000 538.0000 1.0000
33.0400 559.0000 1.0000
33.0800 551.0000 1.0000
33.1200 579.0000 1.0000
33.1600 600.0000 1.0000
33.2000 568.0000 1.0000
33.2400 597.0000 1.0000
33.2800 534.0000 1.0000
33.3200 520.0000 1.0000
33.3600 549.0000 1.0000
33.4000 581.0000 1.0000
33.4400 559.0000 1.0000
33.4800 569.0000 1.0000
33.5200 607.0000 1.0000
33.5600 643.0000 1.0000
33.6000 661.0000 1.0000
33.6400 662.0000 1.0000
33.6800 671.0000 1.0000
33.7200 658.0000 1.0000
33.7600 630.0000 1.0000
33.8000 619.0000 1.0000
33.8400 592.0000 1.0000
33.8800 579.0000 1.0000
33.9200 544.0000 1.0000
33.9600 551.0000 1.0000
34.0000 508.0000 1.0000
34.0400 478.0000 1.0000
34.0800 490.0000 1.0000
34.1200 457.0000 1.0000
34.1600 486.0000 1.0000
34.2000 476.0000 1.0000
34.2400 473.0000 1.0000
34.2800 488.0000 1.0000
34.3200 454.0000 1.0000
34.3600 463.0000 1.0000
34.4000 475.0000 1.0000
34.4400 422.0000 1.0000
34.4800 475.0000 1.0000
34.5200 455.0000 1.0000
34.5600 467.0000 1.0000
34.6000 438.0000 1.0000
34.6400 503.0000 1.0000
34.6800 443.0000 1.0000
34.7200 434.0000 1.0000
34.7600 432.0000 1.0000
34.8000 446.0000 1.0000
34.8400 428.0000 1.0000
34.8800 438.0000 1.0000
34.9200 438.0000 1.0000
34.9600 439.0000 1.0000
35.0000 430.0000 1.0000
35.0400 429.0000 1.0000
35.0800 455.0000 1.0000
35.1200 426.0000 1.0000
35.1600 422.0000 1.0000
35.2000 431.0000 1.0000
35.2400 461.0000 1.0000
35.2800 453.0000 1.0000
35.3200 469.0000 1.0000
35.3600 479.0000 1.0000
35.4000 520.0000 1.0000
35.4400 568.0000 1.0000
35.4800 675.0000 1.0000
35.5200 798.0000 1.0000
35.5600 865.0000 1.0000
35.6000 918.0000 1.0000
35.6400 805.0000 1.0000
35.6800 736.0000 1.0000
35.7200 609.0000 1.0000
35.7600 549.0000 1.0000
35.8000 478.0000 1.0000
35.8400 460.0000 1.0000
35.8800 448.0000 1.0000
35.9200 436.0000 1.0000
35.9600 413.0000 1.0000
36.0000 377.0000 1.0000
36.0400 438.0000 1.0000
36.0800 448.0000 1.0000
36.1200 384.0000 1.0000
36.1600 412.0000 1.0000
36.2000 418.0000 1.0000
36.2400 416.0000 1.0000
36.2800 388.0000 1.0000
36.3200 414.0000 1.0000
36.3600 403.0000 1.0000
36.4000 413.0000 1.0000
36.4400 399.0000 1.0000
36.4800 438.0000 1.0000
36.5200 433.0000 1.0000
36.5600 425.0000 1.0000
36.6000 433.0000 1.0000
36.6400 388.0000 1.0000
36.6800 411.0000 1.0000
36.7200 381.0000 1.0000
36.7600 419.0000 1.0000
36.8000 397.0000 1.0000
36.8400 397.0000 1.0000
36.8800 409.0000 1.0000
36.9200 428.0000 1.0000
36.9600 422.0000 1.0000
37.0000 443.0000 1.0000
37.0400 445.0000 1.0000
37.0800 446.0000 1.0000
37.1200 431.0000 1.0000
37.1600 477.0000 1.0000
37.2000 491.0000 1.0000
37.2400 473.0000 1.0000
37.2800 474.0000 1.0000
37.3200 524.0000 1.0000
37.3600 582.0000 1.0000
37.4000 654.0000 1.0000
37.4400 816.0000 1.0000
37.4800 828.0000 1.0000
37.5200 1062.0000 1.0000
37.5600 1422.0000 1.0000
37.6000 1682.0000 1.0000
37.6400 2208.0000 1.0000
37.6800 2868.0000 1.0000
37.7200 3066.0000 1.0000
37.7600 3005.0000 1.0000
37.8000 2515.0000 1.0000
37.8400 2156.0000 1.0000
37.8800 1610.0000 1.0000
37.9200 1245.0000 1.0000
37.9600 1031.0000 1.0000
38.0000 818.0000 1.0000
38.0400 676.0000 1.0000
38.0800 599.0000 1.0000
38.1200 554.0000 1.0000
38.1600 466.0000 1.0000
38.2000 488.0000 1.0000
38.2400 443.0000 1.0000
38.2800 423.0000 1.0000
38.3200 399.0000 1.0000
38.3600 419.0000 1.0000
38.4000 400.0000 1.0000
38.4400 369.0000 1.0000
38.4800 366.0000 1.0000
38.5200 395.0000 1.0000
38.5600 366.0000 1.0000
38.6000 372.0000 1.0000
38.6400 342.0000 1.0000
38.6800 344.0000 1.0000
38.7200 374.0000 1.0000
38.7600 353.0000 1.0000
38.8000 357.0000 1.0000
38.8400 357.0000 1.0000
38.8800 350.0000 1.0000
38.9200 365.0000 1.0000
38.9600 374.0000 1.0000
39.0000 346.0000 1.0000
39.0400 336.0000 1.0000
39.0800 400.0000 1.0000
39.1200 348.0000 1.0000
39.1600 367.0000 1.0000
39.2000 369.0000 1.0000
39.2400 341.0000 1.0000
39.2800 345.0000 1.0000
39.3200 363.0000 1.0000
39.3600 350.0000 1.0000
39.4000 368.0000 1.0000
39.4400 349.0000 1.0000
39.4800 349.0000 1.0000
39.5200 337.0000 1.0000
39.5600 332.0000 1.0000
39.6000 305.0000 1.0000
39.6400 337.0000 1.0000
39.6800 326.0000 1.0000
39.7200 339.0000 1.0000
39.7600 340.0000 1.0000
39.8000 326.0000 1.0000
39.8400 318.0000 1.0000
39.8800 329.0000 1.0000
39.9200 364.0000 1.0000
39.9600 323.0000 1.0000
40.0000 330.0000 1.0000
40.0400 380.0000 1.0000
40.0800 334.0000 1.0000
40.1200 316.0000 1.0000
40.1600 311.0000 1.0000
40.2000 313.0000 1.0000
40.2400 339.0000 1.0000
40.2800 292.0000 1.0000
40.3200 346.0000 1.0000
40.3600 347.0000 1.0000
40.4000 302.0000 1.0000
40.4400 321.0000 1.0000
40.4800 318.0000 1.0000
40.5200 321.0000 1.0000
40.5600 328.0000 1.0000
40.6000 353.0000 1.0000
40.6400 348.0000 1.0000
40.6800 351.0000 1.0000
40.7200 357.0000 1.0000
40.7600 408.0000 1.0000
40.8000 360.0000 1.0000
40.8400 348.0000 1.0000
40.8800 354.0000 1.0000
40.9200 345.0000 1.0000
40.9600 372.0000 1.0000
41.0000 311.0000 1.0000
41.0400 313.0000 1.0000
41.0800 351.0000 1.0000
41.1200 317.0000 1.0000
41.1600 320.0000 1.0000
41.2000 314.0000 1.0000
41.2400 321.0000 1.0000
41.2800 331.0000 1.0000
41.3200 318.0000 1.0000
41.3600 331.0000 1.0000
41.4000 327.0000 1.0000
41.4400 310.0000 1.0000
41.4800 332.0000 1.0000
41.5200 308.0000 1.0000
41.5600 291.0000 1.0000
41.6000 329.0000 1.0000
41.6400 307.0000 1.0000
41.6800 329.0000 1.0000
41.7200 336.0000 1.0000
41.7600 326.0000 1.0000
41.8000 320.0000 1.0000
41.8400 307.0000 1.0000
41.8800 311.0000 1.0000
41.9200 315.0000 1.0000
41.9600 303.0000 1.0000
42.0000 303.0000 1.0000
42.0400 309.0000 1.0000
42.0800 313.0000 1.0000
42.1200 327.0000 1.0000
42.1600 325.0000 1.0000
42.2000 352.0000 1.0000
42.2400 322.0000 1.0000
42.2800 339.0000 1.0000
42.3200 339.0000 1.0000
42.3600 350.0000 1.0000
42.4000 319.0000 1.0000
42.4400 329.0000 1.0000
42.4800 326.0000 1.0000
42.5200 327.0000 1.0000
42.5600 310.0000 1.0000
42.6000 345.0000 1.0000
42.6400 310.0000 1.0000
42.6800 340.0000 1.0000
42.7200 302.0000 1.0000
42.7600 335.0000 1.0000
42.8000 317.0000 1.0000
42.8400 318.0000 1.0000
42.8800 325.0000 1.0000
42.9200 297.0000 1.0000
42.9600 320.0000 1.0000
43.0000 276.0000 1.0000
43.0400 324.0000 1.0000
43.0800 315.0000 1.0000
43.1200 322.0000 1.0000
43.1600 286.0000 1.0000
43.2000 288.0000 1.0000
43.2400 307.0000 1.0000
43.2800 282.0000 1.0000
43.3200 304.0000 1.0000
43.3600 299.0000 1.0000
43.4000 343.0000 1.0000
43.4400 289.0000 1.0000
43.4800 319.0000 1.0000
43.5200 276.0000 1.0000
43.5600 324.0000 1.0000
43.6000 291.0000 1.0000
43.6400 295.0000 1.0000
43.6800 317.0000 1.0000
43.7200 327.0000 1.0000
43.7600 324.0000 1.0000
43.8000 303.0000 1.0000
43.8400 305.0000 1.0000
43.8800 300.0000 1.0000
43.9200 311.0000 1.0000
43.9600 293.0000 1.0000
44.0000 325.0000 1.0000
44.0400 330.0000 1.0000
44.0800 316.0000 1.0000
44.1200 306.0000 1.0000
44.1600 322.0000 1.0000
44.2000 272.0000 1.0000
44.2400 321.0000 1.0000
44.2800 263.0000 1.0000
44.3200 289.0000 1.0000
44.3600 318.0000 1.0000
44.4000 284.0000 1.0000
44.4400 312.0000 1.0000
44.4800 280.0000 1.0000
44.5200 293.0000 1.0000
44.5600 312.0000 1.0000
44.6000 295.0000 1.0000
44.6400 300.0000 1.0000
44.6800 275.0000 1.0000
44.7200 285.0000 1.0000
44.7600 289.0000 1.0000
44.8000 279.0000 1.0000
44.8400 267.0000 1.0000
44.8800 294.0000 1.0000
44.9200 296.0000 1.0000
44.9600 299.0000 1.0000
45.0000 272.0000 1.0000
45.0400 335.0000 1.0000
45.0800 287.0000 1.0000
45.1200 309.0000 1.0000
45.1600 294.0000 1.0000
45.2000 301.0000 1.0000
45.2400 287.0000 1.0000
45.2800 264.0000 1.0000
45.3200 302.0000 1.0000
45.3600 285.0000 1.0000
45.4000 273.0000 1.0000
45.4400 272.0000 1.0000
45.4800 264.0000 1.0000
45.5200 285.0000 1.0000
45.5600 293.0000 1.0000
45.6000 297.0000 1.0000
45.6400 272.0000 1.0000
45.6800 293.0000 1.0000
45.7200 288.0000 1.0000
45.7600 287.0000 1.0000
45.8000 282.0000 1.0000
45.8400 280.0000 1.0000
45.8800 302.0000 1.0000
45.9200 282.0000 1.0000
45.9600 269.0000 1.0000
46.0000 311.0000 1.0000
46.0400 278.0000 1.0000
46.0800 313.0000 1.0000
46.1200 294.0000 1.0000
46.1600 300.0000 1.0000
46.2000 282.0000 1.0000
46.2400 294.0000 1.0000
46.2800 281.0000 1.0000
46.3200 260.0000 1.0000
46.3600 308.0000 1.0000
46.4000 245.0000 1.0000
46.4400 291.0000 1.0000
46.4800 275.0000 1.0000
46.5200 287.0000 1.0000
46.5600 281.0000 1.0000
46.6000 272.0000 1.0000
46.6400 283.0000 1.0000
46.6800 256.0000 1.0000
46.7200 250.0000 1.0000
46.7600 273.0000 1.0000
46.8000 288.0000 1.0000
46.8400 262.0000 1.0000
46.8800 302.0000 1.0000
46.9200 258.0000 1.0000
46.9600 268.0000 1.0000
47.0000 274.0000 1.0000
47.0400 260.0000 1.0000
47.0800 294.0000 1.0000
47.1200 266.0000 1.0000
47.1600 278.0000 1.0000
47.2000 255.0000 1.0000
47.2400 271.0000 1.0000
47.2800 280.0000 1.0000
47.3200 274.0000 1.0000
47.3600 262.0000 1.0000
47.4000 278.0000 1.0000
47.4400 268.0000 1.0000
47.4800 263.0000 1.0000
47.5200 281.0000 1.0000
47.5600 261.0000 1.0000
47.6000 256.0000 1.0000
47.6400 276.0000 1.0000
47.6800 287.0000 1.0000
47.7200 294.0000 1.0000
47.7600 263.0000 1.0000
47.8000 244.0000 1.0000
47.8400 292.0000 1.0000
47.8800 246.0000 1.0000
47.9200 283.0000 1.0000
47.9600 274.0000 1.0000
48.0000 277.0000 1.0000
48.0400 275.0000 1.0000
48.0800 276.0000 1.0000
48.1200 257.0000 1.0000
48.1600 252.0000 1.0000
48.2000 280.0000 1.0000
48.2400 255.0000 1.0000
48.2800 277.0000 1.0000
48.3200 265.0000 1.0000
48.3600 280.0000 1.0000
48.4000 275.0000 1.0000
48.4400 254.0000 1.0000
48.4800 235.0000 1.0000
48.5200 268.0000 1.0000
48.5600 230.0000 1.0000
48.6000 264.0000 1.0000
48.6400 263.0000 1.0000
48.6800 244.0000 1.0000
48.7200 257.0000 1.0000
48.7600 254.0000 1.0000
48.8000 256.0000 1.0000
48.8400 273.0000 1.0000
48.8800 260.0000 1.0000
48.9200 279.0000 1.0000
48.9600 279.0000 1.0000
49.0000 278.0000 1.0000
49.0400 274.0000 1.0000
49.0800 257.0000 1.0000
49.1200 272.0000 1.0000
49.1600 265.0000 1.0000
49.2000 284.0000 1.0000
49.2400 275.0000 1.0000
49.2800 286.0000 1.0000
49.3200 297.0000 1.0000
49.3600 289.0000 1.0000
49.4000 304.0000 1.0000
49.4400 331.0000 1.0000
49.4800 309.0000 1.0000
49.5200 302.0000 1.0000
49.5600 297.0000 1.0000
49.6000 280.0000 1.0000
49.6400 290.0000 1.0000
49.6800 267.0000 1.0000
49.7200 251.0000 1.0000
49.7600 266.0000 1.0000
49.8000 265.0000 1.0000
49.8400 266.0000 1.0000
49.8800 263.0000 1.0000
49.9200 274.0000 1.0000
49.9600 238.0000 1.0000
50.0000 262.0000 1.0000
50.0400 259.0000 1.0000
50.0800 267.0000 1.0000
50.1200 271.0000 1.0000
50.1600 279.0000 1.0000
50.2000 248.0000 1.0000
50.2400 268.0000 1.0000
50.2800 275.0000 1.0000
50.3200 246.0000 1.0000
50.3600 245.0000 1.0000
50.4000 258.0000 1.0000
50.4400 252.0000 1.0000
50.4800 278.0000 1.0000
50.5200 266.0000 1.0000
50.5600 276.0000 1.0000
50.6000 284.0000 1.0000
50.6400 242.0000 1.0000
50.6800 261.0000 1.0000
50.7200 265.0000 1.0000
50.7600 256.0000 1.0000
50.8000 254.0000 1.0000
50.8400 275.0000 1.0000
50.8800 279.0000 1.0000
50.9200 279.0000 1.0000
50.9600 286.0000 1.0000
51.0000 256.0000 1.0000
51.0400 311.0000 1.0000
51.0800 302.0000 1.0000
51.1200 293.0000 1.0000
51.1600 331.0000 1.0000
51.2000 355.0000 1.0000
51.2400 376.0000 1.0000
51.2800 423.0000 1.0000
51.3200 467.0000 1.0000
51.3600 559.0000 1.0000
51.4000 770.0000 1.0000
51.4400 784.0000 1.0000
51.4800 865.0000 1.0000
51.5200 869.0000 1.0000
51.5600 752.0000 1.0000
51.6000 737.0000 1.0000
51.6400 637.0000 1.0000
51.6800 515.0000 1.0000
51.7200 456.0000 1.0000
51.7600 398.0000 1.0000
51.8000 350.0000 1.0000
51.8400 353.0000 1.0000
51.8800 328.0000 1.0000
51.9200 283.0000 1.0000
51.9600 299.0000 1.0000
52.0000 285.0000 1.0000
52.0400 283.0000 1.0000
52.0800 309.0000 1.0000
52.1200 270.0000 1.0000
52.1600 290.0000 1.0000
52.2000 286.0000 1.0000
52.2400 273.0000 1.0000
52.2800 285.0000 1.0000
52.3200 292.0000 1.0000
52.3600 280.0000 1.0000
52.4000 237.0000 1.0000
52.4400 261.0000 1.0000
52.4800 264.0000 1.0000
52.5200 276.0000 1.0000
52.5600 242.0000 1.0000
52.6000 228.0000 1.0000
52.6400 240.0000 1.0000
52.6800 252.0000 1.0000
52.7200 258.0000 1.0000
52.7600 241.0000 1.0000
52.8000 253.0000 1.0000
52.8400 262.0000 1.0000
52.8800 264.0000 1.0000
52.9200 254.0000 1.0000
52.9600 245.0000 1.0000
53.0000 260.0000 1.0000
53.0400 263.0000 1.0000
53.0800 268.0000 1.0000
53.1200 247.0000 1.0000
53.1600 242.0000 1.0000
53.2000 249.0000 1.0000
53.2400 253.0000 1.0000
53.2800 243.0000 1.0000
53.3200 235.0000 1.0000
53.3600 254.0000 1.0000
53.4000 262.0000 1.0000
53.4400 255.0000 1.0000
53.4800 252.0000 1.0000
53.5200 228.0000 1.0000
53.5600 254.0000 1.0000
53.6000 249.0000 1.0000
53.6400 239.0000 1.0000
53.6800 218.0000 1.0000
53.7200 277.0000 1.0000
53.7600 259.0000 1.0000
53.8000 270.0000 1.0000
53.8400 299.0000 1.0000
53.8800 253.0000 1.0000
53.9200 288.0000 1.0000
53.9600 261.0000 1.0000
54.0000 279.0000 1.0000
54.0400 270.0000 1.0000
54.0800 279.0000 1.0000
54.1200 288.0000 1.0000
54.1600 275.0000 1.0000
54.2000 297.0000 1.0000
54.2400 257.0000 1.0000
54.2800 285.0000 1.0000
54.3200 279.0000 1.0000
54.3600 284.0000 1.0000
54.4000 286.0000 1.0000
54.4400 307.0000 1.0000
54.4800 296.0000 1.0000
54.5200 299.0000 1.0000
54.5600 342.0000 1.0000
54.6000 306.0000 1.0000
54.6400 327.0000 1.0000
54.6800 267.0000 1.0000
54.7200 296.0000 1.0000
54.7600 283.0000 1.0000
54.8000 259.0000 1.0000
54.8400 276.0000 1.0000
54.8800 247.0000 1.0000
54.9200 268.0000 1.0000
54.9600 270.0000 1.0000
55.0000 275.0000 1.0000
55.0400 251.0000 1.0000
55.0800 236.0000 1.0000
55.1200 223.0000 1.0000
55.1600 238.0000 1.0000
55.2000 248.0000 1.0000
55.2400 224.0000 1.0000
55.2800 260.0000 1.0000
55.3200 259.0000 1.0000
55.3600 250.0000 1.0000
55.4000 237.0000 1.0000
55.4400 252.0000 1.0000
55.4800 229.0000 1.0000
55.5200 239.0000 1.0000
55.5600 214.0000 1.0000
55.6000 247.0000 1.0000
55.6400 246.0000 1.0000
55.6800 266.0000 1.0000
55.7200 241.0000 1.0000
55.7600 245.0000 1.0000
55.8000 233.0000 1.0000
55.8400 264.0000 1.0000
55.8800 255.0000 1.0000
55.9200 225.0000 1.0000
55.9600 256.0000 1.0000
56.0000 271.0000 1.0000
56.0400 230.0000 1.0000
56.0800 238.0000 1.0000
56.1200 240.0000 1.0000
56.1600 267.0000 1.0000
56.2000 250.0000 1.0000
56.2400 214.0000 1.0000
56.2800 239.0000 1.0000
56.3200 230.0000 1.0000
56.3600 226.0000 1.0000
56.4000 233.0000 1.0000
56.4400 238.0000 1.0000
56.4800 244.0000 1.0000
56.5200 258.0000 1.0000
56.5600 242.0000 1.0000
56.6000 238.0000 1.0000
56.6400 257.0000 1.0000
56.6800 225.0000 1.0000
56.7200 251.0000 1.0000
56.7600 250.0000 1.0000
56.8000 220.0000 1.0000
56.8400 236.0000 1.0000
56.8800 231.0000 1.0000
56.9200 235.0000 1.0000
56.9600 236.0000 1.0000
57.0000 232.0000 1.0000
57.0400 229.0000 1.0000
57.0800 235.0000 1.0000
57.1200 249.0000 1.0000
57.1600 246.0000 1.0000
57.2000 252.0000 1.0000
57.2400 231.0000 1.0000
57.2800 274.0000 1.0000
57.3200 272.0000 1.0000
57.3600 240.0000 1.0000
57.4000 252.0000 1.0000
57.4400 271.0000 1.0000
57.4800 253.0000 1.0000
57.5200 256.0000 1.0000
57.5600 242.0000 1.0000
57.6000 254.0000 1.0000
57.6400 217.0000 1.0000
57.6800 250.0000 1.0000
57.7200 250.0000 1.0000
57.7600 234.0000 1.0000
57.8000 251.0000 1.0000
57.8400 243.0000 1.0000
57.8800 234.0000 1.0000
57.9200 250.0000 1.0000
57.9600 238.0000 1.0000
58.0000 251.0000 1.0000
58.0400 235.0000 1.0000
58.0800 244.0000 1.0000
58.1200 238.0000 1.0000
58.1600 229.0000 1.0000
58.2000 252.0000 1.0000
58.2400 233.0000 1.0000
58.2800 229.0000 1.0000
58.3200 222.0000 1.0000
58.3600 257.0000 1.0000
58.4000 256.0000 1.0000
58.4400 238.0000 1.0000
58.4800 228.0000 1.0000
58.5200 273.0000 1.0000
58.5600 249.0000 1.0000
58.6000 232.0000 1.0000
58.6400 238.0000 1.0000
58.6800 261.0000 1.0000
58.7200 234.0000 1.0000
58.7600 244.0000 1.0000
58.8000 247.0000 1.0000
58.8400 225.0000 1.0000
58.8800 229.0000 1.0000
58.9200 237.0000 1.0000
58.9600 226.0000 1.0000
59.0000 238.0000 1.0000
59.0400 247.0000 1.0000
59.0800 221.0000 1.0000
59.1200 255.0000 1.0000
59.1600 239.0000 1.0000
59.2000 232.0000 1.0000
59.2400 254.0000 1.0000
59.2800 211.0000 1.0000
59.3200 263.0000 1.0000
59.3600 237.0000 1.0000
59.4000 247.0000 1.0000
59.4400 206.0000 1.0000
59.4800 255.0000 1.0000
59.5200 235.0000 1.0000
59.5600 244.0000 1.0000
59.6000 218.0000 1.0000
59.6400 243.0000 1.0000
59.6800 249.0000 1.0000
59.7200 237.0000 1.0000
59.7600 261.0000 1.0000
59.8000 224.0000 1.0000
59.8400 229.0000 1.0000
59.8800 233.0000 1.0000
59.9200 229.0000 1.0000
59.9600 212.0000 1.0000
60.0000 246.0000 1.0000
60.0400 233.0000 1.0000
60.0800 232.0000 1.0000
60.1200 214.0000 1.0000
60.1600 241.0000 1.0000
60.2000 245.0000 1.0000
60.2400 249.0000 1.0000
60.2800 237.0000 1.0000
60.3200 238.0000 1.0000
60.3600 220.0000 1.0000
60.4000 270.0000 1.0000
60.4400 241.0000 1.0000
60.4800 244.0000 1.0000
60.5200 238.0000 1.0000
60.5600 240.0000 1.0000
60.6000 234.0000 1.0000
60.6400 254.0000 1.0000
60.6800 241.0000 1.0000
60.7200 236.0000 1.0000
60.7600 269.0000 1.0000
60.8000 234.0000 1.0000
60.8400 239.0000 1.0000
60.8800 230.0000 1.0000
60.9200 235.0000 1.0000
60.9600 247.0000 1.0000
61.0000 250.0000 1.0000
61.0400 262.0000 1.0000
61.0800 261.0000 1.0000
61.1200 287.0000 1.0000
61.1600 258.0000 1.0000
61.2000 301.0000 1.0000
61.2400 322.0000 1.0000
61.2800 328.0000 1.0000
61.3200 387.0000 1.0000
61.3600 403.0000 1.0000
61.4000 419.0000 1.0000
61.4400 457.0000 1.0000
61.4800 432.0000 1.0000
61.5200 477.0000 1.0000
61.5600 558.0000 1.0000
61.6000 491.0000 1.0000
61.6400 483.0000 1.0000
61.6800 489.0000 1.0000
61.7200 502.0000 1.0000
61.7600 445.0000 1.0000
61.8000 443.0000 1.0000
61.8400 401.0000 1.0000
61.8800 381.0000 1.0000
61.9200 328.0000 1.0000
61.9600 320.0000 1.0000
62.0000 314.0000 1.0000
62.0400 291.0000 1.0000
62.0800 295.0000 1.0000
62.1200 266.0000 1.0000
62.1600 288.0000 1.0000
62.2000 263.0000 1.0000
62.2400 282.0000 1.0000
62.2800 259.0000 1.0000
62.3200 291.0000 1.0000
62.3600 278.0000 1.0000
62.4000 304.0000 1.0000
62.4400 279.0000 1.0000
62.4800 257.0000 1.0000
62.5200 301.0000 1.0000
62.5600 265.0000 1.0000
62.6000 261.0000 1.0000
62.6400 254.0000 1.0000
62.6800 292.0000 1.0000
62.7200 263.0000 1.0000
62.7600 257.0000 1.0000
62.8000 239.0000 1.0000
62.8400 232.0000 1.0000
62.8800 228.0000 1.0000
62.9200 242.0000 1.0000
62.9600 252.0000 1.0000
63.0000 240.0000 1.0000
63.0400 249.0000 1.0000
63.0800 231.0000 1.0000
63.1200 259.0000 1.0000
63.1600 227.0000 1.0000
63.2000 239.0000 1.0000
63.2400 225.0000 1.0000
63.2800 244.0000 1.0000
63.3200 240.0000 1.0000
63.3600 268.0000 1.0000
63.4000 220.0000 1.0000
63.4400 244.0000 1.0000
63.4800 253.0000 1.0000
63.5200 258.0000 1.0000
63.5600 233.0000 1.0000
63.6000 235.0000 1.0000
63.6400 246.0000 1.0000
63.6800 251.0000 1.0000
63.7200 251.0000 1.0000
63.7600 267.0000 1.0000
63.8000 280.0000 1.0000
63.8400 259.0000 1.0000
63.8800 306.0000 1.0000
63.9200 298.0000 1.0000
63.9600 289.0000 1.0000
64.0000 263.0000 1.0000
64.0400 300.0000 1.0000
64.0800 291.0000 1.0000
64.1200 274.0000 1.0000
64.1600 274.0000 1.0000
64.2000 261.0000 1.0000
64.2400 255.0000 1.0000
64.2800 221.0000 1.0000
64.3200 258.0000 1.0000
64.3600 240.0000 1.0000
64.4000 266.0000 1.0000
64.4400 247.0000 1.0000
64.4800 245.0000 1.0000
64.5200 227.0000 1.0000
64.5600 252.0000 1.0000
64.6000 232.0000 1.0000
64.6400 266.0000 1.0000
64.6800 255.0000 1.0000
64.7200 273.0000 1.0000
64.7600 248.0000 1.0000
64.8000 254.0000 1.0000
64.8400 259.0000 1.0000
64.8800 261.0000 1.0000
64.9200 279.0000 1.0000
64.9600 274.0000 1.0000
65.0000 261.0000 1.0000
65.0400 282.0000 1.0000
65.0800 282.0000 1.0000
65.1200 314.0000 1.0000
65.1600 290.0000 1.0000
65.2000 347.0000 1.0000
65.2400 330.0000 1.0000
65.2800 389.0000 1.0000
65.3200 419.0000 1.0000
65.3600 539.0000 1.0000
65.4000 613.0000 1.0000
65.4400 693.0000 1.0000
65.4800 770.0000 1.0000
65.5200 746.0000 1.0000
65.5600 731.0000 1.0000
65.6000 715.0000 1.0000
65.6400 621.0000 1.0000
65.6800 618.0000 1.0000
65.7200 531.0000 1.0000
65.7600 468.0000 1.0000
65.8000 435.0000 1.0000
65.8400 397.0000 1.0000
65.8800 340.0000 1.0000
65.9200 314.0000 1.0000
65.9600 318.0000 1.0000
66.0000 280.0000 1.0000
66.0400 278.0000 1.0000
66.0800 273.0000 1.0000
66.1200 274.0000 1.0000
66.1600 256.0000 1.0000
66.2000 277.0000 1.0000
66.2400 254.0000 1.0000
66.2800 249.0000 1.0000
66.3200 222.0000 1.0000
66.3600 263.0000 1.0000
66.4000 259.0000 1.0000
66.4400 241.0000 1.0000
66.4800 247.0000 1.0000
66.5200 212.0000 1.0000
66.5600 234.0000 1.0000
66.6000 245.0000 1.0000
66.6400 194.0000 1.0000
66.6800 221.0000 1.0000
66.7200 196.0000 1.0000
66.7600 229.0000 1.0000
66.8000 221.0000 1.0000
66.8400 234.0000 1.0000
66.8800 212.0000 1.0000
66.9200 206.0000 1.0000
66.9600 221.0000 1.0000
67.0000 221.0000 1.0000
67.0400 223.0000 1.0000
67.0800 206.0000 1.0000
67.1200 228.0000 1.0000
67.1600 223.0000 1.0000
67.2000 212.0000 1.0000
67.2400 226.0000 1.0000
67.2800 231.0000 1.0000
67.3200 206.0000 1.0000
67.3600 213.0000 1.0000
67.4000 233.0000 1.0000
67.4400 250.0000 1.0000
67.4800 211.0000 1.0000
67.5200 220.0000 1.0000
67.5600 220.0000 1.0000
67.6000 234.0000 1.0000
67.6400 217.0000 1.0000
67.6800 219.0000 1.0000
67.7200 213.0000 1.0000
67.7600 206.0000 1.0000
67.8000 201.0000 1.0000
67.8400 204.0000 1.0000
67.8800 220.0000 1.0000
67.9200 210.0000 1.0000
67.9600 223.0000 1.0000
68.0000 222.0000 1.0000
68.0400 231.0000 1.0000
68.0800 209.0000 1.0000
68.1200 207.0000 1.0000
68.1600 230.0000 1.0000
68.2000 220.0000 1.0000
68.2400 210.0000 1.0000
68.2800 206.0000 1.0000
68.3200 225.0000 1.0000
68.3600 204.0000 1.0000
68.4000 210.0000 1.0000
68.4400 217.0000 1.0000
68.4800 227.0000 1.0000
68.5200 205.0000 1.0000
68.5600 200.0000 1.0000
68.6000 214.0000 1.0000
68.6400 201.0000 1.0000
68.6800 202.0000 1.0000
68.7200 231.0000 1.0000
68.7600 200.0000 1.0000
68.8000 204.0000 1.0000
68.8400 196.0000 1.0000
68.8800 207.0000 1.0000
68.9200 213.0000 1.0000
68.9600 215.0000 1.0000
69.0000 212.0000 1.0000
69.0400 193.0000 1.0000
69.0800 198.0000 1.0000
69.1200 208.0000 1.0000
69.1600 234.0000 1.0000
69.2000 203.0000 1.0000
69.2400 201.0000 1.0000
69.2800 200.0000 1.0000
69.3200 211.0000 1.0000
69.3600 199.0000 1.0000
69.4000 200.0000 1.0000
69.4400 228.0000 1.0000
69.4800 193.0000 1.0000
69.5200 206.0000 1.0000
69.5600 200.0000 1.0000
69.6000 207.0000 1.0000
69.6400 209.0000 1.0000
69.6800 212.0000 1.0000
69.7200 210.0000 1.0000
69.7600 215.0000 1.0000
69.8000 216.0000 1.0000
69.8400 207.0000 1.0000
69.8800 214.0000 1.0000
69.9200 196.0000 1.0000
69.9600 206.0000 1.0000
70.0000 200.0000 1.0000
*RAS_INT_END
*RAS_TEMPERATURE_START
*RAS_TEMPERATURE_END
*RAS_DATA_END