File: Data/Dataset1_Only_water/5_XRD/No_015_FS4-3.ras
*RAS_DATA_START
*RAS_HEADER_START
*DISP_FMT_X "%.2f"
*DISP_FMT_Y "%.0f"
*DISP_FULLSCALE "14850.0000000000"
*DISP_LINE_COLOR "255.0000000000"
*DISP_LINE_STYLE "0.0000000000"
*DISP_LINE_WIDTH "0.2500000000"
*DISP_NOTE "測定データ-6"
*DISP_OFFSET_Y "0.0000000000"
*DISP_PEAKSEARCH_UNIT_Y "cps"
*DISP_RANGE_BOTTOM "0.0000000000"
*DISP_RANGE_LEFT "20.0000000000"
*DISP_RANGE_LOGCUTOFF "0.0100000000"
*DISP_RANGE_RIGHT "70.0000000000"
*DISP_RANGE_TOP "14850.0000000000"
*DISP_SCALE_MODE_Y "0.0000000000"
*DISP_TAB_NAME "2θ/θ"
*DISP_TITLE_Y "強度"
*DISP_UNIT_Y "cps"
*DISP_WINDOW_NAME "MSG_MACROENGINE"
*FILE_COMMENT " "
*FILE_MD5 ""
*FILE_MEMO " "
*FILE_OPERATOR "Administrator"
*FILE_SAMPLE " "
*FILE_TYPE "RAS_RAW"
*FILE_USERGROUP "システムマネージャ"
*FILE_VERSION "1.0000000000"
*HW_ATTACHMENT_ID "ATT0025"
*HW_ATTACHMENT_NAME "標準|Standard"
*HW_COUNTER_ID-0 "CUT0025"
*HW_COUNTER_ID-1 "CUT0020"
*HW_COUNTER_ID-2 "CUT0020"
*HW_COUNTER_ID-3 "CSL0021"
*HW_COUNTER_ID-4 "CMC0021"
*HW_COUNTER_NAME-0 "D/teX Ultra|D/teX Ultra"
*HW_COUNTER_NAME-1 "None|None"
*HW_COUNTER_NAME-2 "None|None"
*HW_COUNTER_NAME-3 "BBM|BBM"
*HW_COUNTER_NAME-4 "検出器モノクロメータ|Detector monochromator"
*HW_COUNTER_SELECT_NAME "D/teX Ultra|D/teX Ultra"
*HW_GONIOMETER_ID "GON0023"
*HW_GONIOMETER_NAME "SmartLab|SmartLab"
*HW_GONIOMETER_RADIUS-0 "90.0"
*HW_GONIOMETER_RADIUS-1 "114.0"
*HW_GONIOMETER_RADIUS-2 "190.0"
*HW_GONIOMETER_RADIUS-3 "300.0"
*HW_GONIOMETER_RADIUS-4 "187.0"
*HW_GONIOMETER_RADIUS-5 "300.0"
*HW_GONIOMETER_RADIUS-6 "113.0"
*HW_GONIOMETER_RADIUS-7 "331.0"
*HW_I_OPT_ID-0 "CBO0021"
*HW_I_OPT_ID-1 "ICR0023"
*HW_I_OPT_ID-2 "ISL0021"
*HW_I_OPT_ID-3 "ISO0021"
*HW_I_OPT_ID-4 "IAD0021"
*HW_I_OPT_ID-5 "IPR0001"
*HW_I_OPT_NAME-0 "CBOユニット|CBO unit"
*HW_I_OPT_NAME-1 "標準入射光学ユニット|Standard incident optical unit"
*HW_I_OPT_NAME-2 "標準入射スリットボックス|Standard incident slit box"
*HW_I_OPT_NAME-3 "入射平行スリット|Incident parallel slit"
*HW_I_OPT_NAME-4 "長手制限スリット|Length limiting slit"
*HW_I_OPT_NAME-5 "None|None"
*HW_R_ATTENUATER_AUTOMODE "0"
*HW_R_OPT_ID-0 "RSS0021"
*HW_R_OPT_ID-1 "RCR0023"
*HW_R_OPT_ID-2 "RSO0021"
*HW_R_OPT_ID-3 "RRS0021"
*HW_R_OPT_ID-4 "ATN0021"
*HW_R_OPT_ID-5 "RFL0021"
*HW_R_OPT_ID-6 "RAD0021"
*HW_R_OPT_NAME-0 "標準受光スリットボックス1|Standard receiving slit box # 1"
*HW_R_OPT_NAME-1 "標準受光光学ユニット1|Standard receiving unit # 1"
*HW_R_OPT_NAME-2 "標準受光光学ユニット2|Standard receiving optical unit # 2"
*HW_R_OPT_NAME-3 "標準受光スリットボックス2|Standard receiving slit box # 2"
*HW_R_OPT_NAME-4 "標準アッテネータ|Standard Attenuator"
*HW_R_OPT_NAME-5 "Cu Kβ|Cu K-beta"
*HW_R_OPT_NAME-6 "調整用受光スリット|Alignment receiving slit"
*HW_SAMPLE_HOLDER_ID "SMP0023"
*HW_SAMPLE_HOLDER_NAME "標準Zステージ|Standard Z stage"
*HW_XG_CURRENT_MAX "50"
*HW_XG_CURRENT_MIN "2"
*HW_XG_CURRENT_RESOLUTION "1"
*HW_XG_CURRENT_UNIT "mA"
*HW_XG_FOCUS "1mm x 10mm"
*HW_XG_FOCUS_TYPE "Normal"
*HW_XG_ID ""
*HW_XG_NAME "3kW 封入管(ID:1200)|3kW Sealed tube(ID:1200)"
*HW_XG_TARGET_ATOMIC_NUMBER "29.0000000000"
*HW_XG_TARGET_NAME "Cu"
*HW_XG_TYPE "Hermetic"
*HW_XG_VOLTAGE_MAX "60"
*HW_XG_VOLTAGE_MIN "20"
*HW_XG_VOLTAGE_RESOLUTION "1"
*HW_XG_VOLTAGE_UNIT "kV"
*HW_XG_WATT_MAX "1.500"
*HW_XG_WATT_UNIT "kW"
*HW_XG_WAVE_LENGTH_ALPHA1 "1.540593"
*HW_XG_WAVE_LENGTH_ALPHA2 "1.544414"
*HW_XG_WAVE_LENGTH_BETA "1.392250"
*MEAS_COND_AXIS_NAME-0 "2θ/θ"
*MEAS_COND_AXIS_NAME-1 "2θ"
*MEAS_COND_AXIS_NAME-2 "ω"
*MEAS_COND_AXIS_NAME-3 "Z"
*MEAS_COND_AXIS_NAME-4 "2θ/ω"
*MEAS_COND_AXIS_NAME-5 "θs"
*MEAS_COND_AXIS_NAME-6 "θd"
*MEAS_COND_AXIS_NAME-7 "Ts"
*MEAS_COND_AXIS_NAME-8 "CBO選択スリット"
*MEAS_COND_AXIS_NAME-9 "M"
*MEAS_COND_AXIS_NAME-10 "入射平行スリット"
*MEAS_COND_AXIS_NAME-11 "入射スリット"
*MEAS_COND_AXIS_NAME-12 ""
*MEAS_COND_AXIS_NAME-13 "Zs"
*MEAS_COND_AXIS_NAME-14 "入射光学素子"
*MEAS_COND_AXIS_NAME-15 "長手制限スリット"
*MEAS_COND_AXIS_NAME-16 "センタースリット"
*MEAS_COND_AXIS_NAME-17 "フィルター"
*MEAS_COND_AXIS_NAME-18 "受光スリット1"
*MEAS_COND_AXIS_NAME-19 "受光スリット2"
*MEAS_COND_AXIS_NAME-20 "受光光学素子"
*MEAS_COND_AXIS_NAME-21 "受光平行スリット"
*MEAS_COND_AXIS_NAME-22 "調整用受光スリット"
*MEAS_COND_AXIS_NAME-23 ""
*MEAS_COND_AXIS_NAME-24 ""
*MEAS_COND_AXIS_NAME-25 "Zd"
*MEAS_COND_AXIS_NAME-26 "アッテネータ"
*MEAS_COND_AXIS_NAME-27 "検出器モノクロメータ"
*MEAS_COND_AXIS_NAME-28 "モノクロメータスリット"
*MEAS_COND_AXIS_NAME-29 "プライマリビーム"
*MEAS_COND_AXIS_NAME-30 "PHA"
*MEAS_COND_AXIS_NAME_INTERNAL-0 "TwoThetaTheta"
*MEAS_COND_AXIS_NAME_INTERNAL-1 "TwoTheta"
*MEAS_COND_AXIS_NAME_INTERNAL-2 "Omega"
*MEAS_COND_AXIS_NAME_INTERNAL-3 "Z"
*MEAS_COND_AXIS_NAME_INTERNAL-4 "TwoThetaOmega"
*MEAS_COND_AXIS_NAME_INTERNAL-5 "ThetaS"
*MEAS_COND_AXIS_NAME_INTERNAL-6 "ThetaD"
*MEAS_COND_AXIS_NAME_INTERNAL-7 "Ts"
*MEAS_COND_AXIS_NAME_INTERNAL-8 "CBO"
*MEAS_COND_AXIS_NAME_INTERNAL-9 "CBO-M"
*MEAS_COND_AXIS_NAME_INTERNAL-10 "IncidentSollerSlit"
*MEAS_COND_AXIS_NAME_INTERNAL-11 "IncidentSlitBox"
*MEAS_COND_AXIS_NAME_INTERNAL-12 "IncidentSlitBox-_Axis"
*MEAS_COND_AXIS_NAME_INTERNAL-13 "Zs"
*MEAS_COND_AXIS_NAME_INTERNAL-14 "IncidentMonochromator"
*MEAS_COND_AXIS_NAME_INTERNAL-15 "IncidentAxdSlit"
*MEAS_COND_AXIS_NAME_INTERNAL-16 "CenterSlit"
*MEAS_COND_AXIS_NAME_INTERNAL-17 "Filter"
*MEAS_COND_AXIS_NAME_INTERNAL-18 "ReceivingSlitBox1"
*MEAS_COND_AXIS_NAME_INTERNAL-19 "ReceivingSlitBox2"
*MEAS_COND_AXIS_NAME_INTERNAL-20 "ReceivingOptics"
*MEAS_COND_AXIS_NAME_INTERNAL-21 "ReceivingSollerSlit"
*MEAS_COND_AXIS_NAME_INTERNAL-22 "ReceivingAxdSlit"
*MEAS_COND_AXIS_NAME_INTERNAL-23 "ReceivingSlitBox1-_Axis"
*MEAS_COND_AXIS_NAME_INTERNAL-24 "ReceivingSlitBox2-_Axis"
*MEAS_COND_AXIS_NAME_INTERNAL-25 "ReceivingSlitBox2-Zd"
*MEAS_COND_AXIS_NAME_INTERNAL-26 "Attenuator"
*MEAS_COND_AXIS_NAME_INTERNAL-27 "CounterMonochromator"
*MEAS_COND_AXIS_NAME_INTERNAL-28 "CounterSlit"
*MEAS_COND_AXIS_NAME_INTERNAL-29 "IncidentPrimary"
*MEAS_COND_AXIS_NAME_INTERNAL-30 "PHA"
*MEAS_COND_AXIS_NAME_MAGICNO-0 "83951616.0000000000"
*MEAS_COND_AXIS_NAME_MAGICNO-1 "268632064.0000000000"
*MEAS_COND_AXIS_NAME_MAGICNO-2 "268500992.0000000000"
*MEAS_COND_AXIS_NAME_MAGICNO-3 "285278208.0000000000"
*MEAS_COND_AXIS_NAME_MAGICNO-4 "83951616.0000000000"
*MEAS_COND_AXIS_NAME_MAGICNO-5 "131072.0000000000"
*MEAS_COND_AXIS_NAME_MAGICNO-6 "131072.0000000000"
*MEAS_COND_AXIS_NAME_MAGICNO-7 "318898176.0000000000"
*MEAS_COND_AXIS_NAME_MAGICNO-8 "20971521.0000000000"
*MEAS_COND_AXIS_NAME_MAGICNO-9 "285343744.0000000000"
*MEAS_COND_AXIS_NAME_MAGICNO-10 "20971521.0000000000"
*MEAS_COND_AXIS_NAME_MAGICNO-11 "22020097.0000000000"
*MEAS_COND_AXIS_NAME_MAGICNO-12 "25165824.0000000000"
*MEAS_COND_AXIS_NAME_MAGICNO-13 "318898176.0000000000"
*MEAS_COND_AXIS_NAME_MAGICNO-14 "1.0000000000"
*MEAS_COND_AXIS_NAME_MAGICNO-15 "20971521.0000000000"
*MEAS_COND_AXIS_NAME_MAGICNO-16 "20971521.0000000000"
*MEAS_COND_AXIS_NAME_MAGICNO-17 "20971521.0000000000"
*MEAS_COND_AXIS_NAME_MAGICNO-18 "23068673.0000000000"
*MEAS_COND_AXIS_NAME_MAGICNO-19 "23068673.0000000000"
*MEAS_COND_AXIS_NAME_MAGICNO-20 "20971521.0000000000"
*MEAS_COND_AXIS_NAME_MAGICNO-21 "20971521.0000000000"
*MEAS_COND_AXIS_NAME_MAGICNO-22 "20971521.0000000000"
*MEAS_COND_AXIS_NAME_MAGICNO-23 "25165824.0000000000"
*MEAS_COND_AXIS_NAME_MAGICNO-24 "25165824.0000000000"
*MEAS_COND_AXIS_NAME_MAGICNO-25 "285343744.0000000000"
*MEAS_COND_AXIS_NAME_MAGICNO-26 "17301505.0000000000"
*MEAS_COND_AXIS_NAME_MAGICNO-27 "20971521.0000000000"
*MEAS_COND_AXIS_NAME_MAGICNO-28 "20971521.0000000000"
*MEAS_COND_AXIS_NAME_MAGICNO-29 "20971521.0000000000"
*MEAS_COND_AXIS_NAME_MAGICNO-30 "0.0000000000"
*MEAS_COND_AXIS_OFFSET-0 "-"
*MEAS_COND_AXIS_OFFSET-1 "-0.1081000000"
*MEAS_COND_AXIS_OFFSET-2 "0.3758000000"
*MEAS_COND_AXIS_OFFSET-3 "-"
*MEAS_COND_AXIS_OFFSET-4 "-"
*MEAS_COND_AXIS_OFFSET-5 "0.3758000000"
*MEAS_COND_AXIS_OFFSET-6 "-0.4839000000"
*MEAS_COND_AXIS_OFFSET-7 "-"
*MEAS_COND_AXIS_OFFSET-8 "-"
*MEAS_COND_AXIS_OFFSET-9 "-"
*MEAS_COND_AXIS_OFFSET-10 "-"
*MEAS_COND_AXIS_OFFSET-11 "-"
*MEAS_COND_AXIS_OFFSET-12 "-"
*MEAS_COND_AXIS_OFFSET-13 "-"
*MEAS_COND_AXIS_OFFSET-14 "-"
*MEAS_COND_AXIS_OFFSET-15 "-"
*MEAS_COND_AXIS_OFFSET-16 "-"
*MEAS_COND_AXIS_OFFSET-17 "-"
*MEAS_COND_AXIS_OFFSET-18 "-"
*MEAS_COND_AXIS_OFFSET-19 "-"
*MEAS_COND_AXIS_OFFSET-20 "-"
*MEAS_COND_AXIS_OFFSET-21 "-"
*MEAS_COND_AXIS_OFFSET-22 "-"
*MEAS_COND_AXIS_OFFSET-23 "-"
*MEAS_COND_AXIS_OFFSET-24 "-"
*MEAS_COND_AXIS_OFFSET-25 "-"
*MEAS_COND_AXIS_OFFSET-26 "-"
*MEAS_COND_AXIS_OFFSET-27 "-"
*MEAS_COND_AXIS_OFFSET-28 "-"
*MEAS_COND_AXIS_OFFSET-29 "-"
*MEAS_COND_AXIS_OFFSET-30 "-"
*MEAS_COND_AXIS_POSITION-0 "0.0000000000"
*MEAS_COND_AXIS_POSITION-1 "0.0000000000"
*MEAS_COND_AXIS_POSITION-2 "0.0000000000"
*MEAS_COND_AXIS_POSITION-3 "-0.5500000000"
*MEAS_COND_AXIS_POSITION-4 "0.0000000000"
*MEAS_COND_AXIS_POSITION-5 "0.0000000000"
*MEAS_COND_AXIS_POSITION-6 "0.0000000000"
*MEAS_COND_AXIS_POSITION-7 "-0.4278800000"
*MEAS_COND_AXIS_POSITION-8 "BB"
*MEAS_COND_AXIS_POSITION-9 "0.0000000000"
*MEAS_COND_AXIS_POSITION-10 "Soller_slit_5.0deg"
*MEAS_COND_AXIS_POSITION-11 "2/3deg"
*MEAS_COND_AXIS_POSITION-12 "2.2088000000"
*MEAS_COND_AXIS_POSITION-13 "-0.4140600000"
*MEAS_COND_AXIS_POSITION-14 "0.0000000000"
*MEAS_COND_AXIS_POSITION-15 "10.0mm"
*MEAS_COND_AXIS_POSITION-16 "None"
*MEAS_COND_AXIS_POSITION-17 "Cu_K-beta"
*MEAS_COND_AXIS_POSITION-18 "13.000mm"
*MEAS_COND_AXIS_POSITION-19 "13.000mm"
*MEAS_COND_AXIS_POSITION-20 "No_unit"
*MEAS_COND_AXIS_POSITION-21 "Soller_slit_5.0deg"
*MEAS_COND_AXIS_POSITION-22 "None"
*MEAS_COND_AXIS_POSITION-23 "13.0000000000"
*MEAS_COND_AXIS_POSITION-24 "13.0000000000"
*MEAS_COND_AXIS_POSITION-25 "0.0109400000"
*MEAS_COND_AXIS_POSITION-26 "Open"
*MEAS_COND_AXIS_POSITION-27 "None"
*MEAS_COND_AXIS_POSITION-28 "None"
*MEAS_COND_AXIS_POSITION-29 "None"
*MEAS_COND_AXIS_POSITION-30 "38.0000000000"
*MEAS_COND_AXIS_UNIT-0 "deg"
*MEAS_COND_AXIS_UNIT-1 "deg"
*MEAS_COND_AXIS_UNIT-2 "deg"
*MEAS_COND_AXIS_UNIT-3 "mm"
*MEAS_COND_AXIS_UNIT-4 "deg"
*MEAS_COND_AXIS_UNIT-5 "deg"
*MEAS_COND_AXIS_UNIT-6 "deg"
*MEAS_COND_AXIS_UNIT-7 "mm"
*MEAS_COND_AXIS_UNIT-8 ""
*MEAS_COND_AXIS_UNIT-9 "pulse"
*MEAS_COND_AXIS_UNIT-10 ""
*MEAS_COND_AXIS_UNIT-11 ""
*MEAS_COND_AXIS_UNIT-12 "mm"
*MEAS_COND_AXIS_UNIT-13 "mm"
*MEAS_COND_AXIS_UNIT-14 ""
*MEAS_COND_AXIS_UNIT-15 ""
*MEAS_COND_AXIS_UNIT-16 ""
*MEAS_COND_AXIS_UNIT-17 ""
*MEAS_COND_AXIS_UNIT-18 ""
*MEAS_COND_AXIS_UNIT-19 ""
*MEAS_COND_AXIS_UNIT-20 ""
*MEAS_COND_AXIS_UNIT-21 ""
*MEAS_COND_AXIS_UNIT-22 ""
*MEAS_COND_AXIS_UNIT-23 "mm"
*MEAS_COND_AXIS_UNIT-24 "mm"
*MEAS_COND_AXIS_UNIT-25 "mm"
*MEAS_COND_AXIS_UNIT-26 ""
*MEAS_COND_AXIS_UNIT-27 ""
*MEAS_COND_AXIS_UNIT-28 ""
*MEAS_COND_AXIS_UNIT-29 ""
*MEAS_COND_AXIS_UNIT-30 "div"
*MEAS_COND_COUNTER_CNTLOSS_CORR "0.0000000000"
*MEAS_COND_COUNTER_PHABASE "38.0000000000"
*MEAS_COND_COUNTER_PHAWINDOW "16.0000000000"
*MEAS_COND_COUNTER_PHA_UNIT "div"
*MEAS_COND_COUNTER_TAUDIFF "30.0000000000"
*MEAS_COND_COUNTER_TAUINT "0.0000000000"
*MEAS_COND_IRRADIATION_MODE "OFF"
*MEAS_COND_IRRADIATION_WIDTH ""
*MEAS_COND_OPT_ATTR "集中法"
*MEAS_COND_OPT_NAME "@集中法"
*MEAS_COND_UNSYMMETRIC_MODE "OFF"
*MEAS_COND_XG_CURRENT "30.0000000000"
*MEAS_COND_XG_VOLTAGE "40.0000000000"
*MEAS_COND_XG_WAVE_TYPE "Ka"
*MEAS_DATA_COUNT "5001.0000000000"
*MEAS_SCAN_AXIS_X "2θ/θ"
*MEAS_SCAN_AXIS_X_INTERNAL "TwoThetaTheta"
*MEAS_SCAN_END_TIME "07/06/21 18:47:57"
*MEAS_SCAN_MODE "CONTINUOUS"
*MEAS_SCAN_MONITOR "0"
*MEAS_SCAN_RESOLUTION_X "0.0002"
*MEAS_SCAN_SPEED "1.0"
*MEAS_SCAN_SPEED_UNIT "deg/min"
*MEAS_SCAN_START "20.0000000000"
*MEAS_SCAN_START_TIME "07/06/21 17:55:04"
*MEAS_SCAN_STEP "0.0100000000"
*MEAS_SCAN_STOP "70.0000000000"
*MEAS_SCAN_UNIT_X "deg"
*MEAS_SCAN_UNIT_Y "counts"
*RAS_HEADER_END
*RAS_INT_START
20.0000 1701.0000 1.0000
20.0400 1596.0000 1.0000
20.0800 1570.0000 1.0000
20.1200 1596.0000 1.0000
20.1600 1514.0000 1.0000
20.2000 1630.0000 1.0000
20.2400 1663.0000 1.0000
20.2800 1564.0000 1.0000
20.3200 1643.0000 1.0000
20.3600 1575.0000 1.0000
20.4000 1585.0000 1.0000
20.4400 1605.0000 1.0000
20.4800 1581.0000 1.0000
20.5200 1619.0000 1.0000
20.5600 1606.0000 1.0000
20.6000 1628.0000 1.0000
20.6400 1639.0000 1.0000
20.6800 1616.0000 1.0000
20.7200 1630.0000 1.0000
20.7600 1590.0000 1.0000
20.8000 1606.0000 1.0000
20.8400 1587.0000 1.0000
20.8800 1637.0000 1.0000
20.9200 1623.0000 1.0000
20.9600 1549.0000 1.0000
21.0000 1587.0000 1.0000
21.0400 1633.0000 1.0000
21.0800 1599.0000 1.0000
21.1200 1692.0000 1.0000
21.1600 1592.0000 1.0000
21.2000 1569.0000 1.0000
21.2400 1606.0000 1.0000
21.2800 1601.0000 1.0000
21.3200 1604.0000 1.0000
21.3600 1613.0000 1.0000
21.4000 1599.0000 1.0000
21.4400 1578.0000 1.0000
21.4800 1682.0000 1.0000
21.5200 1626.0000 1.0000
21.5600 1613.0000 1.0000
21.6000 1695.0000 1.0000
21.6400 1616.0000 1.0000
21.6800 1607.0000 1.0000
21.7200 1670.0000 1.0000
21.7600 1560.0000 1.0000
21.8000 1583.0000 1.0000
21.8400 1590.0000 1.0000
21.8800 1653.0000 1.0000
21.9200 1672.0000 1.0000
21.9600 1664.0000 1.0000
22.0000 1585.0000 1.0000
22.0400 1630.0000 1.0000
22.0800 1612.0000 1.0000
22.1200 1632.0000 1.0000
22.1600 1604.0000 1.0000
22.2000 1635.0000 1.0000
22.2400 1644.0000 1.0000
22.2800 1598.0000 1.0000
22.3200 1632.0000 1.0000
22.3600 1610.0000 1.0000
22.4000 1572.0000 1.0000
22.4400 1671.0000 1.0000
22.4800 1636.0000 1.0000
22.5200 1607.0000 1.0000
22.5600 1641.0000 1.0000
22.6000 1626.0000 1.0000
22.6400 1640.0000 1.0000
22.6800 1636.0000 1.0000
22.7200 1611.0000 1.0000
22.7600 1714.0000 1.0000
22.8000 1671.0000 1.0000
22.8400 1719.0000 1.0000
22.8800 1672.0000 1.0000
22.9200 1641.0000 1.0000
22.9600 1692.0000 1.0000
23.0000 1659.0000 1.0000
23.0400 1709.0000 1.0000
23.0800 1641.0000 1.0000
23.1200 1603.0000 1.0000
23.1600 1601.0000 1.0000
23.2000 1648.0000 1.0000
23.2400 1644.0000 1.0000
23.2800 1724.0000 1.0000
23.3200 1695.0000 1.0000
23.3600 1620.0000 1.0000
23.4000 1664.0000 1.0000
23.4400 1672.0000 1.0000
23.4800 1612.0000 1.0000
23.5200 1597.0000 1.0000
23.5600 1697.0000 1.0000
23.6000 1688.0000 1.0000
23.6400 1703.0000 1.0000
23.6800 1671.0000 1.0000
23.7200 1663.0000 1.0000
23.7600 1685.0000 1.0000
23.8000 1721.0000 1.0000
23.8400 1649.0000 1.0000
23.8800 1702.0000 1.0000
23.9200 1689.0000 1.0000
23.9600 1671.0000 1.0000
24.0000 1677.0000 1.0000
24.0400 1675.0000 1.0000
24.0800 1683.0000 1.0000
24.1200 1698.0000 1.0000
24.1600 1606.0000 1.0000
24.2000 1728.0000 1.0000
24.2400 1757.0000 1.0000
24.2800 1618.0000 1.0000
24.3200 1720.0000 1.0000
24.3600 1696.0000 1.0000
24.4000 1714.0000 1.0000
24.4400 1652.0000 1.0000
24.4800 1743.0000 1.0000
24.5200 1657.0000 1.0000
24.5600 1680.0000 1.0000
24.6000 1713.0000 1.0000
24.6400 1774.0000 1.0000
24.6800 1753.0000 1.0000
24.7200 1757.0000 1.0000
24.7600 1715.0000 1.0000
24.8000 1735.0000 1.0000
24.8400 1735.0000 1.0000
24.8800 1760.0000 1.0000
24.9200 1751.0000 1.0000
24.9600 1765.0000 1.0000
25.0000 1757.0000 1.0000
25.0400 1724.0000 1.0000
25.0800 1759.0000 1.0000
25.1200 1774.0000 1.0000
25.1600 1800.0000 1.0000
25.2000 1733.0000 1.0000
25.2400 1755.0000 1.0000
25.2800 1740.0000 1.0000
25.3200 1713.0000 1.0000
25.3600 1802.0000 1.0000
25.4000 1699.0000 1.0000
25.4400 1666.0000 1.0000
25.4800 1705.0000 1.0000
25.5200 1719.0000 1.0000
25.5600 1786.0000 1.0000
25.6000 1814.0000 1.0000
25.6400 1782.0000 1.0000
25.6800 1746.0000 1.0000
25.7200 1707.0000 1.0000
25.7600 1710.0000 1.0000
25.8000 1805.0000 1.0000
25.8400 1728.0000 1.0000
25.8800 1703.0000 1.0000
25.9200 1686.0000 1.0000
25.9600 1818.0000 1.0000
26.0000 1760.0000 1.0000
26.0400 1756.0000 1.0000
26.0800 1769.0000 1.0000
26.1200 1768.0000 1.0000
26.1600 1737.0000 1.0000
26.2000 1795.0000 1.0000
26.2400 1759.0000 1.0000
26.2800 1809.0000 1.0000
26.3200 1816.0000 1.0000
26.3600 1662.0000 1.0000
26.4000 1743.0000 1.0000
26.4400 1762.0000 1.0000
26.4800 1848.0000 1.0000
26.5200 1789.0000 1.0000
26.5600 1756.0000 1.0000
26.6000 1889.0000 1.0000
26.6400 1868.0000 1.0000
26.6800 1852.0000 1.0000
26.7200 1848.0000 1.0000
26.7600 1852.0000 1.0000
26.8000 1967.0000 1.0000
26.8400 1961.0000 1.0000
26.8800 1988.0000 1.0000
26.9200 2048.0000 1.0000
26.9600 2170.0000 1.0000
27.0000 2387.0000 1.0000
27.0400 2559.0000 1.0000
27.0800 2782.0000 1.0000
27.1200 3256.0000 1.0000
27.1600 3775.0000 1.0000
27.2000 4608.0000 1.0000
27.2400 5712.0000 1.0000
27.2800 6511.0000 1.0000
27.3200 6687.0000 1.0000
27.3600 5802.0000 1.0000
27.4000 4833.0000 1.0000
27.4400 3944.0000 1.0000
27.4800 3378.0000 1.0000
27.5200 2952.0000 1.0000
27.5600 2568.0000 1.0000
27.6000 2444.0000 1.0000
27.6400 2169.0000 1.0000
27.6800 2065.0000 1.0000
27.7200 2016.0000 1.0000
27.7600 1938.0000 1.0000
27.8000 1879.0000 1.0000
27.8400 1861.0000 1.0000
27.8800 1870.0000 1.0000
27.9200 1831.0000 1.0000
27.9600 1742.0000 1.0000
28.0000 1792.0000 1.0000
28.0400 1740.0000 1.0000
28.0800 1792.0000 1.0000
28.1200 1708.0000 1.0000
28.1600 1719.0000 1.0000
28.2000 1702.0000 1.0000
28.2400 1623.0000 1.0000
28.2800 1699.0000 1.0000
28.3200 1652.0000 1.0000
28.3600 1700.0000 1.0000
28.4000 1662.0000 1.0000
28.4400 1683.0000 1.0000
28.4800 1693.0000 1.0000
28.5200 1685.0000 1.0000
28.5600 1643.0000 1.0000
28.6000 1628.0000 1.0000
28.6400 1637.0000 1.0000
28.6800 1596.0000 1.0000
28.7200 1597.0000 1.0000
28.7600 1588.0000 1.0000
28.8000 1661.0000 1.0000
28.8400 1638.0000 1.0000
28.8800 1621.0000 1.0000
28.9200 1615.0000 1.0000
28.9600 1709.0000 1.0000
29.0000 1589.0000 1.0000
29.0400 1578.0000 1.0000
29.0800 1596.0000 1.0000
29.1200 1518.0000 1.0000
29.1600 1651.0000 1.0000
29.2000 1589.0000 1.0000
29.2400 1589.0000 1.0000
29.2800 1578.0000 1.0000
29.3200 1548.0000 1.0000
29.3600 1570.0000 1.0000
29.4000 1617.0000 1.0000
29.4400 1639.0000 1.0000
29.4800 1554.0000 1.0000
29.5200 1518.0000 1.0000
29.5600 1542.0000 1.0000
29.6000 1528.0000 1.0000
29.6400 1525.0000 1.0000
29.6800 1537.0000 1.0000
29.7200 1543.0000 1.0000
29.7600 1553.0000 1.0000
29.8000 1542.0000 1.0000
29.8400 1523.0000 1.0000
29.8800 1478.0000 1.0000
29.9200 1578.0000 1.0000
29.9600 1544.0000 1.0000
30.0000 1526.0000 1.0000
30.0400 1543.0000 1.0000
30.0800 1516.0000 1.0000
30.1200 1596.0000 1.0000
30.1600 1469.0000 1.0000
30.2000 1525.0000 1.0000
30.2400 1575.0000 1.0000
30.2800 1479.0000 1.0000
30.3200 1515.0000 1.0000
30.3600 1479.0000 1.0000
30.4000 1492.0000 1.0000
30.4400 1510.0000 1.0000
30.4800 1446.0000 1.0000
30.5200 1486.0000 1.0000
30.5600 1512.0000 1.0000
30.6000 1480.0000 1.0000
30.6400 1455.0000 1.0000
30.6800 1478.0000 1.0000
30.7200 1497.0000 1.0000
30.7600 1512.0000 1.0000
30.8000 1457.0000 1.0000
30.8400 1444.0000 1.0000
30.8800 1427.0000 1.0000
30.9200 1477.0000 1.0000
30.9600 1464.0000 1.0000
31.0000 1533.0000 1.0000
31.0400 1459.0000 1.0000
31.0800 1500.0000 1.0000
31.1200 1485.0000 1.0000
31.1600 1411.0000 1.0000
31.2000 1443.0000 1.0000
31.2400 1461.0000 1.0000
31.2800 1421.0000 1.0000
31.3200 1397.0000 1.0000
31.3600 1454.0000 1.0000
31.4000 1414.0000 1.0000
31.4400 1416.0000 1.0000
31.4800 1444.0000 1.0000
31.5200 1414.0000 1.0000
31.5600 1466.0000 1.0000
31.6000 1427.0000 1.0000
31.6400 1401.0000 1.0000
31.6800 1387.0000 1.0000
31.7200 1465.0000 1.0000
31.7600 1493.0000 1.0000
31.8000 1443.0000 1.0000
31.8400 1393.0000 1.0000
31.8800 1489.0000 1.0000
31.9200 1418.0000 1.0000
31.9600 1451.0000 1.0000
32.0000 1436.0000 1.0000
32.0400 1440.0000 1.0000
32.0800 1380.0000 1.0000
32.1200 1420.0000 1.0000
32.1600 1442.0000 1.0000
32.2000 1469.0000 1.0000
32.2400 1434.0000 1.0000
32.2800 1420.0000 1.0000
32.3200 1417.0000 1.0000
32.3600 1396.0000 1.0000
32.4000 1424.0000 1.0000
32.4400 1403.0000 1.0000
32.4800 1412.0000 1.0000
32.5200 1371.0000 1.0000
32.5600 1420.0000 1.0000
32.6000 1353.0000 1.0000
32.6400 1313.0000 1.0000
32.6800 1343.0000 1.0000
32.7200 1471.0000 1.0000
32.7600 1400.0000 1.0000
32.8000 1395.0000 1.0000
32.8400 1372.0000 1.0000
32.8800 1387.0000 1.0000
32.9200 1337.0000 1.0000
32.9600 1394.0000 1.0000
33.0000 1387.0000 1.0000
33.0400 1348.0000 1.0000
33.0800 1420.0000 1.0000
33.1200 1346.0000 1.0000
33.1600 1374.0000 1.0000
33.2000 1364.0000 1.0000
33.2400 1361.0000 1.0000
33.2800 1397.0000 1.0000
33.3200 1311.0000 1.0000
33.3600 1345.0000 1.0000
33.4000 1368.0000 1.0000
33.4400 1326.0000 1.0000
33.4800 1369.0000 1.0000
33.5200 1329.0000 1.0000
33.5600 1390.0000 1.0000
33.6000 1315.0000 1.0000
33.6400 1339.0000 1.0000
33.6800 1334.0000 1.0000
33.7200 1306.0000 1.0000
33.7600 1444.0000 1.0000
33.8000 1439.0000 1.0000
33.8400 1445.0000 1.0000
33.8800 1501.0000 1.0000
33.9200 1501.0000 1.0000
33.9600 1457.0000 1.0000
34.0000 1518.0000 1.0000
34.0400 1504.0000 1.0000
34.0800 1428.0000 1.0000
34.1200 1514.0000 1.0000
34.1600 1470.0000 1.0000
34.2000 1549.0000 1.0000
34.2400 1594.0000 1.0000
34.2800 1698.0000 1.0000
34.3200 1883.0000 1.0000
34.3600 2131.0000 1.0000
34.4000 2320.0000 1.0000
34.4400 2761.0000 1.0000
34.4800 2945.0000 1.0000
34.5200 2984.0000 1.0000
34.5600 2884.0000 1.0000
34.6000 2585.0000 1.0000
34.6400 2209.0000 1.0000
34.6800 1896.0000 1.0000
34.7200 1798.0000 1.0000
34.7600 1703.0000 1.0000
34.8000 1684.0000 1.0000
34.8400 1446.0000 1.0000
34.8800 1431.0000 1.0000
34.9200 1323.0000 1.0000
34.9600 1373.0000 1.0000
35.0000 1344.0000 1.0000
35.0400 1292.0000 1.0000
35.0800 1297.0000 1.0000
35.1200 1297.0000 1.0000
35.1600 1293.0000 1.0000
35.2000 1229.0000 1.0000
35.2400 1231.0000 1.0000
35.2800 1263.0000 1.0000
35.3200 1222.0000 1.0000
35.3600 1189.0000 1.0000
35.4000 1216.0000 1.0000
35.4400 1199.0000 1.0000
35.4800 1183.0000 1.0000
35.5200 1143.0000 1.0000
35.5600 1156.0000 1.0000
35.6000 1158.0000 1.0000
35.6400 1226.0000 1.0000
35.6800 1127.0000 1.0000
35.7200 1160.0000 1.0000
35.7600 1148.0000 1.0000
35.8000 1136.0000 1.0000
35.8400 1095.0000 1.0000
35.8800 1143.0000 1.0000
35.9200 1156.0000 1.0000
35.9600 1088.0000 1.0000
36.0000 1144.0000 1.0000
36.0400 1154.0000 1.0000
36.0800 1136.0000 1.0000
36.1200 1164.0000 1.0000
36.1600 1261.0000 1.0000
36.2000 1237.0000 1.0000
36.2400 1316.0000 1.0000
36.2800 1395.0000 1.0000
36.3200 1664.0000 1.0000
36.3600 1946.0000 1.0000
36.4000 2072.0000 1.0000
36.4400 2150.0000 1.0000
36.4800 1920.0000 1.0000
36.5200 1679.0000 1.0000
36.5600 1473.0000 1.0000
36.6000 1256.0000 1.0000
36.6400 1237.0000 1.0000
36.6800 1127.0000 1.0000
36.7200 1100.0000 1.0000
36.7600 1141.0000 1.0000
36.8000 1115.0000 1.0000
36.8400 999.0000 1.0000
36.8800 1053.0000 1.0000
36.9200 1095.0000 1.0000
36.9600 1105.0000 1.0000
37.0000 1096.0000 1.0000
37.0400 1030.0000 1.0000
37.0800 1092.0000 1.0000
37.1200 1032.0000 1.0000
37.1600 1077.0000 1.0000
37.2000 1067.0000 1.0000
37.2400 1039.0000 1.0000
37.2800 1047.0000 1.0000
37.3200 1052.0000 1.0000
37.3600 1060.0000 1.0000
37.4000 1068.0000 1.0000
37.4400 1053.0000 1.0000
37.4800 1012.0000 1.0000
37.5200 1072.0000 1.0000
37.5600 1037.0000 1.0000
37.6000 1051.0000 1.0000
37.6400 1050.0000 1.0000
37.6800 1055.0000 1.0000
37.7200 1046.0000 1.0000
37.7600 1074.0000 1.0000
37.8000 1046.0000 1.0000
37.8400 1084.0000 1.0000
37.8800 1081.0000 1.0000
37.9200 1070.0000 1.0000
37.9600 1102.0000 1.0000
38.0000 1189.0000 1.0000
38.0400 1136.0000 1.0000
38.0800 1224.0000 1.0000
38.1200 1262.0000 1.0000
38.1600 1385.0000 1.0000
38.2000 1425.0000 1.0000
38.2400 1617.0000 1.0000
38.2800 1854.0000 1.0000
38.3200 2127.0000 1.0000
38.3600 2671.0000 1.0000
38.4000 3340.0000 1.0000
38.4400 4427.0000 1.0000
38.4800 5728.0000 1.0000
38.5200 6932.0000 1.0000
38.5600 7425.0000 1.0000
38.6000 6910.0000 1.0000
38.6400 5999.0000 1.0000
38.6800 4745.0000 1.0000
38.7200 3577.0000 1.0000
38.7600 2761.0000 1.0000
38.8000 2211.0000 1.0000
38.8400 1794.0000 1.0000
38.8800 1548.0000 1.0000
38.9200 1363.0000 1.0000
38.9600 1275.0000 1.0000
39.0000 1186.0000 1.0000
39.0400 1143.0000 1.0000
39.0800 1078.0000 1.0000
39.1200 1057.0000 1.0000
39.1600 1044.0000 1.0000
39.2000 1015.0000 1.0000
39.2400 969.0000 1.0000
39.2800 1006.0000 1.0000
39.3200 986.0000 1.0000
39.3600 943.0000 1.0000
39.4000 966.0000 1.0000
39.4400 958.0000 1.0000
39.4800 988.0000 1.0000
39.5200 967.0000 1.0000
39.5600 1013.0000 1.0000
39.6000 1012.0000 1.0000
39.6400 977.0000 1.0000
39.6800 1010.0000 1.0000
39.7200 955.0000 1.0000
39.7600 985.0000 1.0000
39.8000 924.0000 1.0000
39.8400 894.0000 1.0000
39.8800 961.0000 1.0000
39.9200 965.0000 1.0000
39.9600 919.0000 1.0000
40.0000 907.0000 1.0000
40.0400 904.0000 1.0000
40.0800 886.0000 1.0000
40.1200 917.0000 1.0000
40.1600 891.0000 1.0000
40.2000 882.0000 1.0000
40.2400 861.0000 1.0000
40.2800 923.0000 1.0000
40.3200 930.0000 1.0000
40.3600 893.0000 1.0000
40.4000 884.0000 1.0000
40.4400 873.0000 1.0000
40.4800 877.0000 1.0000
40.5200 814.0000 1.0000
40.5600 845.0000 1.0000
40.6000 902.0000 1.0000
40.6400 861.0000 1.0000
40.6800 880.0000 1.0000
40.7200 882.0000 1.0000
40.7600 913.0000 1.0000
40.8000 868.0000 1.0000
40.8400 883.0000 1.0000
40.8800 850.0000 1.0000
40.9200 865.0000 1.0000
40.9600 869.0000 1.0000
41.0000 876.0000 1.0000
41.0400 848.0000 1.0000
41.0800 865.0000 1.0000
41.1200 866.0000 1.0000
41.1600 840.0000 1.0000
41.2000 909.0000 1.0000
41.2400 845.0000 1.0000
41.2800 854.0000 1.0000
41.3200 851.0000 1.0000
41.3600 866.0000 1.0000
41.4000 843.0000 1.0000
41.4400 858.0000 1.0000
41.4800 873.0000 1.0000
41.5200 888.0000 1.0000
41.5600 872.0000 1.0000
41.6000 883.0000 1.0000
41.6400 888.0000 1.0000
41.6800 889.0000 1.0000
41.7200 864.0000 1.0000
41.7600 830.0000 1.0000
41.8000 927.0000 1.0000
41.8400 844.0000 1.0000
41.8800 845.0000 1.0000
41.9200 821.0000 1.0000
41.9600 872.0000 1.0000
42.0000 883.0000 1.0000
42.0400 876.0000 1.0000
42.0800 855.0000 1.0000
42.1200 805.0000 1.0000
42.1600 822.0000 1.0000
42.2000 857.0000 1.0000
42.2400 891.0000 1.0000
42.2800 865.0000 1.0000
42.3200 826.0000 1.0000
42.3600 868.0000 1.0000
42.4000 822.0000 1.0000
42.4400 853.0000 1.0000
42.4800 840.0000 1.0000
42.5200 869.0000 1.0000
42.5600 856.0000 1.0000
42.6000 814.0000 1.0000
42.6400 859.0000 1.0000
42.6800 894.0000 1.0000
42.7200 821.0000 1.0000
42.7600 809.0000 1.0000
42.8000 856.0000 1.0000
42.8400 819.0000 1.0000
42.8800 830.0000 1.0000
42.9200 865.0000 1.0000
42.9600 854.0000 1.0000
43.0000 875.0000 1.0000
43.0400 859.0000 1.0000
43.0800 856.0000 1.0000
43.1200 851.0000 1.0000
43.1600 907.0000 1.0000
43.2000 936.0000 1.0000
43.2400 902.0000 1.0000
43.2800 950.0000 1.0000
43.3200 921.0000 1.0000
43.3600 942.0000 1.0000
43.4000 880.0000 1.0000
43.4400 849.0000 1.0000
43.4800 862.0000 1.0000
43.5200 819.0000 1.0000
43.5600 835.0000 1.0000
43.6000 855.0000 1.0000
43.6400 791.0000 1.0000
43.6800 838.0000 1.0000
43.7200 827.0000 1.0000
43.7600 840.0000 1.0000
43.8000 836.0000 1.0000
43.8400 794.0000 1.0000
43.8800 802.0000 1.0000
43.9200 810.0000 1.0000
43.9600 780.0000 1.0000
44.0000 867.0000 1.0000
44.0400 813.0000 1.0000
44.0800 808.0000 1.0000
44.1200 817.0000 1.0000
44.1600 801.0000 1.0000
44.2000 798.0000 1.0000
44.2400 823.0000 1.0000
44.2800 845.0000 1.0000
44.3200 823.0000 1.0000
44.3600 891.0000 1.0000
44.4000 834.0000 1.0000
44.4400 819.0000 1.0000
44.4800 816.0000 1.0000
44.5200 810.0000 1.0000
44.5600 843.0000 1.0000
44.6000 787.0000 1.0000
44.6400 829.0000 1.0000
44.6800 810.0000 1.0000
44.7200 812.0000 1.0000
44.7600 791.0000 1.0000
44.8000 820.0000 1.0000
44.8400 780.0000 1.0000
44.8800 777.0000 1.0000
44.9200 797.0000 1.0000
44.9600 788.0000 1.0000
45.0000 780.0000 1.0000
45.0400 819.0000 1.0000
45.0800 770.0000 1.0000
45.1200 780.0000 1.0000
45.1600 800.0000 1.0000
45.2000 785.0000 1.0000
45.2400 792.0000 1.0000
45.2800 766.0000 1.0000
45.3200 814.0000 1.0000
45.3600 788.0000 1.0000
45.4000 805.0000 1.0000
45.4400 739.0000 1.0000
45.4800 796.0000 1.0000
45.5200 786.0000 1.0000
45.5600 783.0000 1.0000
45.6000 814.0000 1.0000
45.6400 755.0000 1.0000
45.6800 740.0000 1.0000
45.7200 766.0000 1.0000
45.7600 752.0000 1.0000
45.8000 740.0000 1.0000
45.8400 775.0000 1.0000
45.8800 747.0000 1.0000
45.9200 809.0000 1.0000
45.9600 769.0000 1.0000
46.0000 772.0000 1.0000
46.0400 785.0000 1.0000
46.0800 779.0000 1.0000
46.1200 750.0000 1.0000
46.1600 775.0000 1.0000
46.2000 761.0000 1.0000
46.2400 769.0000 1.0000
46.2800 728.0000 1.0000
46.3200 783.0000 1.0000
46.3600 792.0000 1.0000
46.4000 767.0000 1.0000
46.4400 785.0000 1.0000
46.4800 751.0000 1.0000
46.5200 748.0000 1.0000
46.5600 784.0000 1.0000
46.6000 796.0000 1.0000
46.6400 808.0000 1.0000
46.6800 764.0000 1.0000
46.7200 752.0000 1.0000
46.7600 732.0000 1.0000
46.8000 741.0000 1.0000
46.8400 781.0000 1.0000
46.8800 799.0000 1.0000
46.9200 810.0000 1.0000
46.9600 781.0000 1.0000
47.0000 723.0000 1.0000
47.0400 818.0000 1.0000
47.0800 787.0000 1.0000
47.1200 738.0000 1.0000
47.1600 745.0000 1.0000
47.2000 754.0000 1.0000
47.2400 782.0000 1.0000
47.2800 728.0000 1.0000
47.3200 740.0000 1.0000
47.3600 761.0000 1.0000
47.4000 742.0000 1.0000
47.4400 758.0000 1.0000
47.4800 697.0000 1.0000
47.5200 766.0000 1.0000
47.5600 741.0000 1.0000
47.6000 738.0000 1.0000
47.6400 706.0000 1.0000
47.6800 730.0000 1.0000
47.7200 782.0000 1.0000
47.7600 723.0000 1.0000
47.8000 738.0000 1.0000
47.8400 737.0000 1.0000
47.8800 740.0000 1.0000
47.9200 744.0000 1.0000
47.9600 730.0000 1.0000
48.0000 724.0000 1.0000
48.0400 770.0000 1.0000
48.0800 758.0000 1.0000
48.1200 783.0000 1.0000
48.1600 729.0000 1.0000
48.2000 720.0000 1.0000
48.2400 744.0000 1.0000
48.2800 724.0000 1.0000
48.3200 718.0000 1.0000
48.3600 720.0000 1.0000
48.4000 749.0000 1.0000
48.4400 711.0000 1.0000
48.4800 697.0000 1.0000
48.5200 708.0000 1.0000
48.5600 720.0000 1.0000
48.6000 721.0000 1.0000
48.6400 712.0000 1.0000
48.6800 710.0000 1.0000
48.7200 720.0000 1.0000
48.7600 715.0000 1.0000
48.8000 751.0000 1.0000
48.8400 735.0000 1.0000
48.8800 708.0000 1.0000
48.9200 707.0000 1.0000
48.9600 716.0000 1.0000
49.0000 702.0000 1.0000
49.0400 698.0000 1.0000
49.0800 697.0000 1.0000
49.1200 693.0000 1.0000
49.1600 677.0000 1.0000
49.2000 727.0000 1.0000
49.2400 749.0000 1.0000
49.2800 731.0000 1.0000
49.3200 712.0000 1.0000
49.3600 736.0000 1.0000
49.4000 752.0000 1.0000
49.4400 732.0000 1.0000
49.4800 730.0000 1.0000
49.5200 714.0000 1.0000
49.5600 714.0000 1.0000
49.6000 715.0000 1.0000
49.6400 759.0000 1.0000
49.6800 711.0000 1.0000
49.7200 683.0000 1.0000
49.7600 697.0000 1.0000
49.8000 693.0000 1.0000
49.8400 726.0000 1.0000
49.8800 727.0000 1.0000
49.9200 709.0000 1.0000
49.9600 751.0000 1.0000
50.0000 726.0000 1.0000
50.0400 752.0000 1.0000
50.0800 711.0000 1.0000
50.1200 768.0000 1.0000
50.1600 745.0000 1.0000
50.2000 755.0000 1.0000
50.2400 805.0000 1.0000
50.2800 764.0000 1.0000
50.3200 734.0000 1.0000
50.3600 744.0000 1.0000
50.4000 728.0000 1.0000
50.4400 733.0000 1.0000
50.4800 700.0000 1.0000
50.5200 776.0000 1.0000
50.5600 763.0000 1.0000
50.6000 765.0000 1.0000
50.6400 731.0000 1.0000
50.6800 675.0000 1.0000
50.7200 691.0000 1.0000
50.7600 743.0000 1.0000
50.8000 720.0000 1.0000
50.8400 732.0000 1.0000
50.8800 715.0000 1.0000
50.9200 730.0000 1.0000
50.9600 742.0000 1.0000
51.0000 732.0000 1.0000
51.0400 712.0000 1.0000
51.0800 689.0000 1.0000
51.1200 719.0000 1.0000
51.1600 785.0000 1.0000
51.2000 741.0000 1.0000
51.2400 729.0000 1.0000
51.2800 727.0000 1.0000
51.3200 755.0000 1.0000
51.3600 712.0000 1.0000
51.4000 742.0000 1.0000
51.4400 754.0000 1.0000
51.4800 719.0000 1.0000
51.5200 725.0000 1.0000
51.5600 790.0000 1.0000
51.6000 691.0000 1.0000
51.6400 763.0000 1.0000
51.6800 754.0000 1.0000
51.7200 773.0000 1.0000
51.7600 781.0000 1.0000
51.8000 789.0000 1.0000
51.8400 833.0000 1.0000
51.8800 825.0000 1.0000
51.9200 916.0000 1.0000
51.9600 1066.0000 1.0000
52.0000 1133.0000 1.0000
52.0400 1253.0000 1.0000
52.0800 1457.0000 1.0000
52.1200 1800.0000 1.0000
52.1600 2416.0000 1.0000
52.2000 3367.0000 1.0000
52.2400 4368.0000 1.0000
52.2800 4873.0000 1.0000
52.3200 4660.0000 1.0000
52.3600 4142.0000 1.0000
52.4000 3649.0000 1.0000
52.4400 3273.0000 1.0000
52.4800 2473.0000 1.0000
52.5200 1844.0000 1.0000
52.5600 1540.0000 1.0000
52.6000 1295.0000 1.0000
52.6400 1090.0000 1.0000
52.6800 1026.0000 1.0000
52.7200 937.0000 1.0000
52.7600 872.0000 1.0000
52.8000 861.0000 1.0000
52.8400 825.0000 1.0000
52.8800 828.0000 1.0000
52.9200 798.0000 1.0000
52.9600 766.0000 1.0000
53.0000 716.0000 1.0000
53.0400 759.0000 1.0000
53.0800 749.0000 1.0000
53.1200 688.0000 1.0000
53.1600 727.0000 1.0000
53.2000 732.0000 1.0000
53.2400 806.0000 1.0000
53.2800 730.0000 1.0000
53.3200 736.0000 1.0000
53.3600 721.0000 1.0000
53.4000 702.0000 1.0000
53.4400 710.0000 1.0000
53.4800 710.0000 1.0000
53.5200 744.0000 1.0000
53.5600 711.0000 1.0000
53.6000 676.0000 1.0000
53.6400 719.0000 1.0000
53.6800 691.0000 1.0000
53.7200 688.0000 1.0000
53.7600 684.0000 1.0000
53.8000 676.0000 1.0000
53.8400 705.0000 1.0000
53.8800 698.0000 1.0000
53.9200 693.0000 1.0000
53.9600 703.0000 1.0000
54.0000 709.0000 1.0000
54.0400 682.0000 1.0000
54.0800 672.0000 1.0000
54.1200 682.0000 1.0000
54.1600 678.0000 1.0000
54.2000 659.0000 1.0000
54.2400 682.0000 1.0000
54.2800 735.0000 1.0000
54.3200 686.0000 1.0000
54.3600 728.0000 1.0000
54.4000 698.0000 1.0000
54.4400 682.0000 1.0000
54.4800 679.0000 1.0000
54.5200 715.0000 1.0000
54.5600 705.0000 1.0000
54.6000 703.0000 1.0000
54.6400 759.0000 1.0000
54.6800 734.0000 1.0000
54.7200 728.0000 1.0000
54.7600 725.0000 1.0000
54.8000 750.0000 1.0000
54.8400 745.0000 1.0000
54.8800 764.0000 1.0000
54.9200 726.0000 1.0000
54.9600 768.0000 1.0000
55.0000 765.0000 1.0000
55.0400 794.0000 1.0000
55.0800 779.0000 1.0000
55.1200 813.0000 1.0000
55.1600 904.0000 1.0000
55.2000 989.0000 1.0000
55.2400 1018.0000 1.0000
55.2800 1097.0000 1.0000
55.3200 1060.0000 1.0000
55.3600 963.0000 1.0000
55.4000 993.0000 1.0000
55.4400 1005.0000 1.0000
55.4800 945.0000 1.0000
55.5200 866.0000 1.0000
55.5600 791.0000 1.0000
55.6000 817.0000 1.0000
55.6400 750.0000 1.0000
55.6800 748.0000 1.0000
55.7200 729.0000 1.0000
55.7600 692.0000 1.0000
55.8000 719.0000 1.0000
55.8400 657.0000 1.0000
55.8800 728.0000 1.0000
55.9200 663.0000 1.0000
55.9600 681.0000 1.0000
56.0000 710.0000 1.0000
56.0400 683.0000 1.0000
56.0800 695.0000 1.0000
56.1200 681.0000 1.0000
56.1600 730.0000 1.0000
56.2000 667.0000 1.0000
56.2400 642.0000 1.0000
56.2800 653.0000 1.0000
56.3200 676.0000 1.0000
56.3600 688.0000 1.0000
56.4000 649.0000 1.0000
56.4400 676.0000 1.0000
56.4800 660.0000 1.0000
56.5200 695.0000 1.0000
56.5600 639.0000 1.0000
56.6000 653.0000 1.0000
56.6400 655.0000 1.0000
56.6800 703.0000 1.0000
56.7200 633.0000 1.0000
56.7600 724.0000 1.0000
56.8000 705.0000 1.0000
56.8400 707.0000 1.0000
56.8800 648.0000 1.0000
56.9200 668.0000 1.0000
56.9600 664.0000 1.0000
57.0000 661.0000 1.0000
57.0400 682.0000 1.0000
57.0800 680.0000 1.0000
57.1200 673.0000 1.0000
57.1600 649.0000 1.0000
57.2000 674.0000 1.0000
57.2400 675.0000 1.0000
57.2800 656.0000 1.0000
57.3200 654.0000 1.0000
57.3600 661.0000 1.0000
57.4000 675.0000 1.0000
57.4400 675.0000 1.0000
57.4800 694.0000 1.0000
57.5200 668.0000 1.0000
57.5600 679.0000 1.0000
57.6000 654.0000 1.0000
57.6400 677.0000 1.0000
57.6800 674.0000 1.0000
57.7200 698.0000 1.0000
57.7600 664.0000 1.0000
57.8000 674.0000 1.0000
57.8400 684.0000 1.0000
57.8800 729.0000 1.0000
57.9200 684.0000 1.0000
57.9600 715.0000 1.0000
58.0000 674.0000 1.0000
58.0400 679.0000 1.0000
58.0800 698.0000 1.0000
58.1200 703.0000 1.0000
58.1600 658.0000 1.0000
58.2000 650.0000 1.0000
58.2400 730.0000 1.0000
58.2800 699.0000 1.0000
58.3200 660.0000 1.0000
58.3600 680.0000 1.0000
58.4000 667.0000 1.0000
58.4400 684.0000 1.0000
58.4800 683.0000 1.0000
58.5200 640.0000 1.0000
58.5600 650.0000 1.0000
58.6000 678.0000 1.0000
58.6400 674.0000 1.0000
58.6800 660.0000 1.0000
58.7200 651.0000 1.0000
58.7600 652.0000 1.0000
58.8000 676.0000 1.0000
58.8400 622.0000 1.0000
58.8800 656.0000 1.0000
58.9200 658.0000 1.0000
58.9600 695.0000 1.0000
59.0000 656.0000 1.0000
59.0400 691.0000 1.0000
59.0800 690.0000 1.0000
59.1200 640.0000 1.0000
59.1600 694.0000 1.0000
59.2000 638.0000 1.0000
59.2400 655.0000 1.0000
59.2800 670.0000 1.0000
59.3200 678.0000 1.0000
59.3600 677.0000 1.0000
59.4000 713.0000 1.0000
59.4400 658.0000 1.0000
59.4800 673.0000 1.0000
59.5200 673.0000 1.0000
59.5600 636.0000 1.0000
59.6000 676.0000 1.0000
59.6400 674.0000 1.0000
59.6800 624.0000 1.0000
59.7200 700.0000 1.0000
59.7600 630.0000 1.0000
59.8000 655.0000 1.0000
59.8400 670.0000 1.0000
59.8800 648.0000 1.0000
59.9200 648.0000 1.0000
59.9600 688.0000 1.0000
60.0000 676.0000 1.0000
60.0400 640.0000 1.0000
60.0800 654.0000 1.0000
60.1200 604.0000 1.0000
60.1600 636.0000 1.0000
60.2000 681.0000 1.0000
60.2400 674.0000 1.0000
60.2800 634.0000 1.0000
60.3200 666.0000 1.0000
60.3600 682.0000 1.0000
60.4000 675.0000 1.0000
60.4400 674.0000 1.0000
60.4800 674.0000 1.0000
60.5200 669.0000 1.0000
60.5600 665.0000 1.0000
60.6000 681.0000 1.0000
60.6400 693.0000 1.0000
60.6800 643.0000 1.0000
60.7200 642.0000 1.0000
60.7600 679.0000 1.0000
60.8000 663.0000 1.0000
60.8400 681.0000 1.0000
60.8800 669.0000 1.0000
60.9200 643.0000 1.0000
60.9600 608.0000 1.0000
61.0000 634.0000 1.0000
61.0400 670.0000 1.0000
61.0800 645.0000 1.0000
61.1200 658.0000 1.0000
61.1600 664.0000 1.0000
61.2000 706.0000 1.0000
61.2400 663.0000 1.0000
61.2800 692.0000 1.0000
61.3200 662.0000 1.0000
61.3600 666.0000 1.0000
61.4000 688.0000 1.0000
61.4400 663.0000 1.0000
61.4800 690.0000 1.0000
61.5200 697.0000 1.0000
61.5600 708.0000 1.0000
61.6000 702.0000 1.0000
61.6400 696.0000 1.0000
61.6800 649.0000 1.0000
61.7200 711.0000 1.0000
61.7600 701.0000 1.0000
61.8000 722.0000 1.0000
61.8400 736.0000 1.0000
61.8800 725.0000 1.0000
61.9200 767.0000 1.0000
61.9600 799.0000 1.0000
62.0000 830.0000 1.0000
62.0400 921.0000 1.0000
62.0800 1029.0000 1.0000
62.1200 1038.0000 1.0000
62.1600 1152.0000 1.0000
62.2000 1310.0000 1.0000
62.2400 1508.0000 1.0000
62.2800 1525.0000 1.0000
62.3200 1591.0000 1.0000
62.3600 1586.0000 1.0000
62.4000 1568.0000 1.0000
62.4400 1467.0000 1.0000
62.4800 1376.0000 1.0000
62.5200 1315.0000 1.0000
62.5600 1189.0000 1.0000
62.6000 1063.0000 1.0000
62.6400 962.0000 1.0000
62.6800 918.0000 1.0000
62.7200 906.0000 1.0000
62.7600 809.0000 1.0000
62.8000 818.0000 1.0000
62.8400 742.0000 1.0000
62.8800 765.0000 1.0000
62.9200 759.0000 1.0000
62.9600 762.0000 1.0000
63.0000 726.0000 1.0000
63.0400 759.0000 1.0000
63.0800 736.0000 1.0000
63.1200 713.0000 1.0000
63.1600 699.0000 1.0000
63.2000 734.0000 1.0000
63.2400 721.0000 1.0000
63.2800 689.0000 1.0000
63.3200 709.0000 1.0000
63.3600 693.0000 1.0000
63.4000 664.0000 1.0000
63.4400 676.0000 1.0000
63.4800 622.0000 1.0000
63.5200 673.0000 1.0000
63.5600 667.0000 1.0000
63.6000 673.0000 1.0000
63.6400 664.0000 1.0000
63.6800 676.0000 1.0000
63.7200 702.0000 1.0000
63.7600 636.0000 1.0000
63.8000 717.0000 1.0000
63.8400 669.0000 1.0000
63.8800 684.0000 1.0000
63.9200 642.0000 1.0000
63.9600 729.0000 1.0000
64.0000 626.0000 1.0000
64.0400 706.0000 1.0000
64.0800 663.0000 1.0000
64.1200 654.0000 1.0000
64.1600 628.0000 1.0000
64.2000 656.0000 1.0000
64.2400 679.0000 1.0000
64.2800 705.0000 1.0000
64.3200 647.0000 1.0000
64.3600 676.0000 1.0000
64.4000 697.0000 1.0000
64.4400 685.0000 1.0000
64.4800 691.0000 1.0000
64.5200 744.0000 1.0000
64.5600 738.0000 1.0000
64.6000 776.0000 1.0000
64.6400 835.0000 1.0000
64.6800 925.0000 1.0000
64.7200 863.0000 1.0000
64.7600 825.0000 1.0000
64.8000 817.0000 1.0000
64.8400 760.0000 1.0000
64.8800 850.0000 1.0000
64.9200 807.0000 1.0000
64.9600 753.0000 1.0000
65.0000 700.0000 1.0000
65.0400 699.0000 1.0000
65.0800 681.0000 1.0000
65.1200 691.0000 1.0000
65.1600 712.0000 1.0000
65.2000 691.0000 1.0000
65.2400 727.0000 1.0000
65.2800 654.0000 1.0000
65.3200 721.0000 1.0000
65.3600 681.0000 1.0000
65.4000 677.0000 1.0000
65.4400 662.0000 1.0000
65.4800 708.0000 1.0000
65.5200 699.0000 1.0000
65.5600 648.0000 1.0000
65.6000 672.0000 1.0000
65.6400 680.0000 1.0000
65.6800 681.0000 1.0000
65.7200 730.0000 1.0000
65.7600 755.0000 1.0000
65.8000 745.0000 1.0000
65.8400 786.0000 1.0000
65.8800 765.0000 1.0000
65.9200 905.0000 1.0000
65.9600 887.0000 1.0000
66.0000 1015.0000 1.0000
66.0400 1145.0000 1.0000
66.0800 1236.0000 1.0000
66.1200 1458.0000 1.0000
66.1600 1765.0000 1.0000
66.2000 2153.0000 1.0000
66.2400 2492.0000 1.0000
66.2800 2764.0000 1.0000
66.3200 2604.0000 1.0000
66.3600 2382.0000 1.0000
66.4000 2246.0000 1.0000
66.4400 2103.0000 1.0000
66.4800 1918.0000 1.0000
66.5200 1711.0000 1.0000
66.5600 1437.0000 1.0000
66.6000 1248.0000 1.0000
66.6400 1082.0000 1.0000
66.6800 944.0000 1.0000
66.7200 866.0000 1.0000
66.7600 826.0000 1.0000
66.8000 808.0000 1.0000
66.8400 803.0000 1.0000
66.8800 750.0000 1.0000
66.9200 708.0000 1.0000
66.9600 659.0000 1.0000
67.0000 647.0000 1.0000
67.0400 663.0000 1.0000
67.0800 660.0000 1.0000
67.1200 657.0000 1.0000
67.1600 666.0000 1.0000
67.2000 661.0000 1.0000
67.2400 614.0000 1.0000
67.2800 625.0000 1.0000
67.3200 649.0000 1.0000
67.3600 629.0000 1.0000
67.4000 627.0000 1.0000
67.4400 595.0000 1.0000
67.4800 610.0000 1.0000
67.5200 673.0000 1.0000
67.5600 614.0000 1.0000
67.6000 623.0000 1.0000
67.6400 649.0000 1.0000
67.6800 626.0000 1.0000
67.7200 634.0000 1.0000
67.7600 604.0000 1.0000
67.8000 597.0000 1.0000
67.8400 615.0000 1.0000
67.8800 609.0000 1.0000
67.9200 597.0000 1.0000
67.9600 581.0000 1.0000
68.0000 624.0000 1.0000
68.0400 582.0000 1.0000
68.0800 578.0000 1.0000
68.1200 619.0000 1.0000
68.1600 596.0000 1.0000
68.2000 613.0000 1.0000
68.2400 597.0000 1.0000
68.2800 592.0000 1.0000
68.3200 623.0000 1.0000
68.3600 564.0000 1.0000
68.4000 622.0000 1.0000
68.4400 583.0000 1.0000
68.4800 538.0000 1.0000
68.5200 578.0000 1.0000
68.5600 611.0000 1.0000
68.6000 602.0000 1.0000
68.6400 573.0000 1.0000
68.6800 586.0000 1.0000
68.7200 596.0000 1.0000
68.7600 593.0000 1.0000
68.8000 580.0000 1.0000
68.8400 610.0000 1.0000
68.8800 553.0000 1.0000
68.9200 657.0000 1.0000
68.9600 593.0000 1.0000
69.0000 592.0000 1.0000
69.0400 608.0000 1.0000
69.0800 559.0000 1.0000
69.1200 623.0000 1.0000
69.1600 547.0000 1.0000
69.2000 593.0000 1.0000
69.2400 553.0000 1.0000
69.2800 599.0000 1.0000
69.3200 586.0000 1.0000
69.3600 527.0000 1.0000
69.4000 557.0000 1.0000
69.4400 595.0000 1.0000
69.4800 614.0000 1.0000
69.5200 582.0000 1.0000
69.5600 594.0000 1.0000
69.6000 591.0000 1.0000
69.6400 618.0000 1.0000
69.6800 577.0000 1.0000
69.7200 600.0000 1.0000
69.7600 552.0000 1.0000
69.8000 601.0000 1.0000
69.8400 633.0000 1.0000
69.8800 545.0000 1.0000
69.9200 562.0000 1.0000
69.9600 559.0000 1.0000
70.0000 556.0000 1.0000
*RAS_INT_END
*RAS_TEMPERATURE_START
*RAS_TEMPERATURE_END
*RAS_DATA_END