File: Data/Dataset1_Only_water/5_XRD/No_073_deposition_3h_TiO2_21.ras
*RAS_DATA_START
*RAS_HEADER_START
*DISP_FMT_X "%.2f"
*DISP_FMT_Y "%.0f"
*DISP_FULLSCALE "16470.0000000000"
*DISP_LINE_COLOR "255.0000000000"
*DISP_LINE_STYLE "0.0000000000"
*DISP_LINE_WIDTH "0.2500000000"
*DISP_NOTE "測定データ-5"
*DISP_OFFSET_Y "0.0000000000"
*DISP_PEAKSEARCH_UNIT_Y "cps"
*DISP_RANGE_BOTTOM "0.0000000000"
*DISP_RANGE_LEFT "20.0000000000"
*DISP_RANGE_LOGCUTOFF "0.0100000000"
*DISP_RANGE_RIGHT "70.0000000000"
*DISP_RANGE_TOP "16470.0000000000"
*DISP_SCALE_MODE_Y "0.0000000000"
*DISP_TAB_NAME "2θ/θ"
*DISP_TITLE_Y "強度"
*DISP_UNIT_Y "cps"
*DISP_WINDOW_NAME "MSG_MACROENGINE"
*FILE_COMMENT " "
*FILE_MD5 ""
*FILE_MEMO " "
*FILE_OPERATOR "Administrator"
*FILE_SAMPLE " "
*FILE_TYPE "RAS_RAW"
*FILE_USERGROUP "システムマネージャ"
*FILE_VERSION "1.0000000000"
*HW_ATTACHMENT_ID "ATT0025"
*HW_ATTACHMENT_NAME "標準|Standard"
*HW_COUNTER_ID-0 "CUT0025"
*HW_COUNTER_ID-1 "CUT0020"
*HW_COUNTER_ID-2 "CUT0020"
*HW_COUNTER_ID-3 "CSL0021"
*HW_COUNTER_ID-4 "CMC0021"
*HW_COUNTER_NAME-0 "D/teX Ultra|D/teX Ultra"
*HW_COUNTER_NAME-1 "None|None"
*HW_COUNTER_NAME-2 "None|None"
*HW_COUNTER_NAME-3 "BBM|BBM"
*HW_COUNTER_NAME-4 "検出器モノクロメータ|Detector monochromator"
*HW_COUNTER_SELECT_NAME "D/teX Ultra|D/teX Ultra"
*HW_GONIOMETER_ID "GON0023"
*HW_GONIOMETER_NAME "SmartLab|SmartLab"
*HW_GONIOMETER_RADIUS-0 "90.0"
*HW_GONIOMETER_RADIUS-1 "114.0"
*HW_GONIOMETER_RADIUS-2 "190.0"
*HW_GONIOMETER_RADIUS-3 "300.0"
*HW_GONIOMETER_RADIUS-4 "187.0"
*HW_GONIOMETER_RADIUS-5 "300.0"
*HW_GONIOMETER_RADIUS-6 "113.0"
*HW_GONIOMETER_RADIUS-7 "331.0"
*HW_I_OPT_ID-0 "CBO0021"
*HW_I_OPT_ID-1 "ICR0023"
*HW_I_OPT_ID-2 "ISL0021"
*HW_I_OPT_ID-3 "ISO0021"
*HW_I_OPT_ID-4 "IAD0021"
*HW_I_OPT_ID-5 "IPR0001"
*HW_I_OPT_NAME-0 "CBOユニット|CBO unit"
*HW_I_OPT_NAME-1 "標準入射光学ユニット|Standard incident optical unit"
*HW_I_OPT_NAME-2 "標準入射スリットボックス|Standard incident slit box"
*HW_I_OPT_NAME-3 "入射平行スリット|Incident parallel slit"
*HW_I_OPT_NAME-4 "長手制限スリット|Length limiting slit"
*HW_I_OPT_NAME-5 "None|None"
*HW_R_ATTENUATER_AUTOMODE "0"
*HW_R_OPT_ID-0 "RSS0021"
*HW_R_OPT_ID-1 "RCR0023"
*HW_R_OPT_ID-2 "RSO0021"
*HW_R_OPT_ID-3 "RRS0021"
*HW_R_OPT_ID-4 "ATN0021"
*HW_R_OPT_ID-5 "RFL0021"
*HW_R_OPT_ID-6 "RAD0021"
*HW_R_OPT_NAME-0 "標準受光スリットボックス1|Standard receiving slit box # 1"
*HW_R_OPT_NAME-1 "標準受光光学ユニット1|Standard receiving unit # 1"
*HW_R_OPT_NAME-2 "標準受光光学ユニット2|Standard receiving optical unit # 2"
*HW_R_OPT_NAME-3 "標準受光スリットボックス2|Standard receiving slit box # 2"
*HW_R_OPT_NAME-4 "標準アッテネータ|Standard Attenuator"
*HW_R_OPT_NAME-5 "Cu Kβ|Cu K-beta"
*HW_R_OPT_NAME-6 "調整用受光スリット|Alignment receiving slit"
*HW_SAMPLE_HOLDER_ID "SMP0023"
*HW_SAMPLE_HOLDER_NAME "標準Zステージ|Standard Z stage"
*HW_XG_CURRENT_MAX "50"
*HW_XG_CURRENT_MIN "2"
*HW_XG_CURRENT_RESOLUTION "1"
*HW_XG_CURRENT_UNIT "mA"
*HW_XG_FOCUS "1mm x 10mm"
*HW_XG_FOCUS_TYPE "Normal"
*HW_XG_ID ""
*HW_XG_NAME "3kW 封入管(ID:1200)|3kW Sealed tube(ID:1200)"
*HW_XG_TARGET_ATOMIC_NUMBER "29.0000000000"
*HW_XG_TARGET_NAME "Cu"
*HW_XG_TYPE "Hermetic"
*HW_XG_VOLTAGE_MAX "60"
*HW_XG_VOLTAGE_MIN "20"
*HW_XG_VOLTAGE_RESOLUTION "1"
*HW_XG_VOLTAGE_UNIT "kV"
*HW_XG_WATT_MAX "1.500"
*HW_XG_WATT_UNIT "kW"
*HW_XG_WAVE_LENGTH_ALPHA1 "1.540593"
*HW_XG_WAVE_LENGTH_ALPHA2 "1.544414"
*HW_XG_WAVE_LENGTH_BETA "1.392250"
*MEAS_COND_AXIS_NAME-0 "2θ/θ"
*MEAS_COND_AXIS_NAME-1 "2θ"
*MEAS_COND_AXIS_NAME-2 "ω"
*MEAS_COND_AXIS_NAME-3 "Z"
*MEAS_COND_AXIS_NAME-4 "2θ/ω"
*MEAS_COND_AXIS_NAME-5 "θs"
*MEAS_COND_AXIS_NAME-6 "θd"
*MEAS_COND_AXIS_NAME-7 "Ts"
*MEAS_COND_AXIS_NAME-8 "CBO選択スリット"
*MEAS_COND_AXIS_NAME-9 "M"
*MEAS_COND_AXIS_NAME-10 "入射平行スリット"
*MEAS_COND_AXIS_NAME-11 "入射スリット"
*MEAS_COND_AXIS_NAME-12 ""
*MEAS_COND_AXIS_NAME-13 "Zs"
*MEAS_COND_AXIS_NAME-14 "入射光学素子"
*MEAS_COND_AXIS_NAME-15 "長手制限スリット"
*MEAS_COND_AXIS_NAME-16 "センタースリット"
*MEAS_COND_AXIS_NAME-17 "フィルター"
*MEAS_COND_AXIS_NAME-18 "受光スリット1"
*MEAS_COND_AXIS_NAME-19 "受光スリット2"
*MEAS_COND_AXIS_NAME-20 "受光光学素子"
*MEAS_COND_AXIS_NAME-21 "受光平行スリット"
*MEAS_COND_AXIS_NAME-22 "調整用受光スリット"
*MEAS_COND_AXIS_NAME-23 ""
*MEAS_COND_AXIS_NAME-24 ""
*MEAS_COND_AXIS_NAME-25 "Zd"
*MEAS_COND_AXIS_NAME-26 "アッテネータ"
*MEAS_COND_AXIS_NAME-27 "検出器モノクロメータ"
*MEAS_COND_AXIS_NAME-28 "モノクロメータスリット"
*MEAS_COND_AXIS_NAME-29 "プライマリビーム"
*MEAS_COND_AXIS_NAME-30 "PHA"
*MEAS_COND_AXIS_NAME_INTERNAL-0 "TwoThetaTheta"
*MEAS_COND_AXIS_NAME_INTERNAL-1 "TwoTheta"
*MEAS_COND_AXIS_NAME_INTERNAL-2 "Omega"
*MEAS_COND_AXIS_NAME_INTERNAL-3 "Z"
*MEAS_COND_AXIS_NAME_INTERNAL-4 "TwoThetaOmega"
*MEAS_COND_AXIS_NAME_INTERNAL-5 "ThetaS"
*MEAS_COND_AXIS_NAME_INTERNAL-6 "ThetaD"
*MEAS_COND_AXIS_NAME_INTERNAL-7 "Ts"
*MEAS_COND_AXIS_NAME_INTERNAL-8 "CBO"
*MEAS_COND_AXIS_NAME_INTERNAL-9 "CBO-M"
*MEAS_COND_AXIS_NAME_INTERNAL-10 "IncidentSollerSlit"
*MEAS_COND_AXIS_NAME_INTERNAL-11 "IncidentSlitBox"
*MEAS_COND_AXIS_NAME_INTERNAL-12 "IncidentSlitBox-_Axis"
*MEAS_COND_AXIS_NAME_INTERNAL-13 "Zs"
*MEAS_COND_AXIS_NAME_INTERNAL-14 "IncidentMonochromator"
*MEAS_COND_AXIS_NAME_INTERNAL-15 "IncidentAxdSlit"
*MEAS_COND_AXIS_NAME_INTERNAL-16 "CenterSlit"
*MEAS_COND_AXIS_NAME_INTERNAL-17 "Filter"
*MEAS_COND_AXIS_NAME_INTERNAL-18 "ReceivingSlitBox1"
*MEAS_COND_AXIS_NAME_INTERNAL-19 "ReceivingSlitBox2"
*MEAS_COND_AXIS_NAME_INTERNAL-20 "ReceivingOptics"
*MEAS_COND_AXIS_NAME_INTERNAL-21 "ReceivingSollerSlit"
*MEAS_COND_AXIS_NAME_INTERNAL-22 "ReceivingAxdSlit"
*MEAS_COND_AXIS_NAME_INTERNAL-23 "ReceivingSlitBox1-_Axis"
*MEAS_COND_AXIS_NAME_INTERNAL-24 "ReceivingSlitBox2-_Axis"
*MEAS_COND_AXIS_NAME_INTERNAL-25 "ReceivingSlitBox2-Zd"
*MEAS_COND_AXIS_NAME_INTERNAL-26 "Attenuator"
*MEAS_COND_AXIS_NAME_INTERNAL-27 "CounterMonochromator"
*MEAS_COND_AXIS_NAME_INTERNAL-28 "CounterSlit"
*MEAS_COND_AXIS_NAME_INTERNAL-29 "IncidentPrimary"
*MEAS_COND_AXIS_NAME_INTERNAL-30 "PHA"
*MEAS_COND_AXIS_NAME_MAGICNO-0 "83951616.0000000000"
*MEAS_COND_AXIS_NAME_MAGICNO-1 "268632064.0000000000"
*MEAS_COND_AXIS_NAME_MAGICNO-2 "268500992.0000000000"
*MEAS_COND_AXIS_NAME_MAGICNO-3 "285278208.0000000000"
*MEAS_COND_AXIS_NAME_MAGICNO-4 "83951616.0000000000"
*MEAS_COND_AXIS_NAME_MAGICNO-5 "131072.0000000000"
*MEAS_COND_AXIS_NAME_MAGICNO-6 "131072.0000000000"
*MEAS_COND_AXIS_NAME_MAGICNO-7 "318898176.0000000000"
*MEAS_COND_AXIS_NAME_MAGICNO-8 "20971521.0000000000"
*MEAS_COND_AXIS_NAME_MAGICNO-9 "285343744.0000000000"
*MEAS_COND_AXIS_NAME_MAGICNO-10 "20971521.0000000000"
*MEAS_COND_AXIS_NAME_MAGICNO-11 "22020097.0000000000"
*MEAS_COND_AXIS_NAME_MAGICNO-12 "25165824.0000000000"
*MEAS_COND_AXIS_NAME_MAGICNO-13 "318898176.0000000000"
*MEAS_COND_AXIS_NAME_MAGICNO-14 "1.0000000000"
*MEAS_COND_AXIS_NAME_MAGICNO-15 "20971521.0000000000"
*MEAS_COND_AXIS_NAME_MAGICNO-16 "20971521.0000000000"
*MEAS_COND_AXIS_NAME_MAGICNO-17 "20971521.0000000000"
*MEAS_COND_AXIS_NAME_MAGICNO-18 "23068673.0000000000"
*MEAS_COND_AXIS_NAME_MAGICNO-19 "23068673.0000000000"
*MEAS_COND_AXIS_NAME_MAGICNO-20 "20971521.0000000000"
*MEAS_COND_AXIS_NAME_MAGICNO-21 "20971521.0000000000"
*MEAS_COND_AXIS_NAME_MAGICNO-22 "20971521.0000000000"
*MEAS_COND_AXIS_NAME_MAGICNO-23 "25165824.0000000000"
*MEAS_COND_AXIS_NAME_MAGICNO-24 "25165824.0000000000"
*MEAS_COND_AXIS_NAME_MAGICNO-25 "285343744.0000000000"
*MEAS_COND_AXIS_NAME_MAGICNO-26 "17301505.0000000000"
*MEAS_COND_AXIS_NAME_MAGICNO-27 "20971521.0000000000"
*MEAS_COND_AXIS_NAME_MAGICNO-28 "20971521.0000000000"
*MEAS_COND_AXIS_NAME_MAGICNO-29 "20971521.0000000000"
*MEAS_COND_AXIS_NAME_MAGICNO-30 "0.0000000000"
*MEAS_COND_AXIS_OFFSET-0 "-"
*MEAS_COND_AXIS_OFFSET-1 "-0.0801000000"
*MEAS_COND_AXIS_OFFSET-2 "0.2338000000"
*MEAS_COND_AXIS_OFFSET-3 "-"
*MEAS_COND_AXIS_OFFSET-4 "-"
*MEAS_COND_AXIS_OFFSET-5 "0.2338000000"
*MEAS_COND_AXIS_OFFSET-6 "-0.3139000000"
*MEAS_COND_AXIS_OFFSET-7 "-"
*MEAS_COND_AXIS_OFFSET-8 "-"
*MEAS_COND_AXIS_OFFSET-9 "-"
*MEAS_COND_AXIS_OFFSET-10 "-"
*MEAS_COND_AXIS_OFFSET-11 "-"
*MEAS_COND_AXIS_OFFSET-12 "-"
*MEAS_COND_AXIS_OFFSET-13 "-"
*MEAS_COND_AXIS_OFFSET-14 "-"
*MEAS_COND_AXIS_OFFSET-15 "-"
*MEAS_COND_AXIS_OFFSET-16 "-"
*MEAS_COND_AXIS_OFFSET-17 "-"
*MEAS_COND_AXIS_OFFSET-18 "-"
*MEAS_COND_AXIS_OFFSET-19 "-"
*MEAS_COND_AXIS_OFFSET-20 "-"
*MEAS_COND_AXIS_OFFSET-21 "-"
*MEAS_COND_AXIS_OFFSET-22 "-"
*MEAS_COND_AXIS_OFFSET-23 "-"
*MEAS_COND_AXIS_OFFSET-24 "-"
*MEAS_COND_AXIS_OFFSET-25 "-"
*MEAS_COND_AXIS_OFFSET-26 "-"
*MEAS_COND_AXIS_OFFSET-27 "-"
*MEAS_COND_AXIS_OFFSET-28 "-"
*MEAS_COND_AXIS_OFFSET-29 "-"
*MEAS_COND_AXIS_OFFSET-30 "-"
*MEAS_COND_AXIS_POSITION-0 "0.0000000000"
*MEAS_COND_AXIS_POSITION-1 "0.0000000000"
*MEAS_COND_AXIS_POSITION-2 "0.0000000000"
*MEAS_COND_AXIS_POSITION-3 "-2.9583600000"
*MEAS_COND_AXIS_POSITION-4 "0.0000000000"
*MEAS_COND_AXIS_POSITION-5 "0.0000000000"
*MEAS_COND_AXIS_POSITION-6 "0.0000000000"
*MEAS_COND_AXIS_POSITION-7 "-0.4278800000"
*MEAS_COND_AXIS_POSITION-8 "BB"
*MEAS_COND_AXIS_POSITION-9 "0.0000000000"
*MEAS_COND_AXIS_POSITION-10 "Soller_slit_5.0deg"
*MEAS_COND_AXIS_POSITION-11 "2/3deg"
*MEAS_COND_AXIS_POSITION-12 "2.2088000000"
*MEAS_COND_AXIS_POSITION-13 "-1.0609400000"
*MEAS_COND_AXIS_POSITION-14 "0.0000000000"
*MEAS_COND_AXIS_POSITION-15 "10.0mm"
*MEAS_COND_AXIS_POSITION-16 "None"
*MEAS_COND_AXIS_POSITION-17 "Cu_K-beta"
*MEAS_COND_AXIS_POSITION-18 "13.000mm"
*MEAS_COND_AXIS_POSITION-19 "13.000mm"
*MEAS_COND_AXIS_POSITION-20 "No_unit"
*MEAS_COND_AXIS_POSITION-21 "Soller_slit_5.0deg"
*MEAS_COND_AXIS_POSITION-22 "None"
*MEAS_COND_AXIS_POSITION-23 "13.0000000000"
*MEAS_COND_AXIS_POSITION-24 "13.0000000000"
*MEAS_COND_AXIS_POSITION-25 "0.0081300000"
*MEAS_COND_AXIS_POSITION-26 "Open"
*MEAS_COND_AXIS_POSITION-27 "None"
*MEAS_COND_AXIS_POSITION-28 "None"
*MEAS_COND_AXIS_POSITION-29 "None"
*MEAS_COND_AXIS_POSITION-30 "38.0000000000"
*MEAS_COND_AXIS_UNIT-0 "deg"
*MEAS_COND_AXIS_UNIT-1 "deg"
*MEAS_COND_AXIS_UNIT-2 "deg"
*MEAS_COND_AXIS_UNIT-3 "mm"
*MEAS_COND_AXIS_UNIT-4 "deg"
*MEAS_COND_AXIS_UNIT-5 "deg"
*MEAS_COND_AXIS_UNIT-6 "deg"
*MEAS_COND_AXIS_UNIT-7 "mm"
*MEAS_COND_AXIS_UNIT-8 ""
*MEAS_COND_AXIS_UNIT-9 "pulse"
*MEAS_COND_AXIS_UNIT-10 ""
*MEAS_COND_AXIS_UNIT-11 ""
*MEAS_COND_AXIS_UNIT-12 "mm"
*MEAS_COND_AXIS_UNIT-13 "mm"
*MEAS_COND_AXIS_UNIT-14 ""
*MEAS_COND_AXIS_UNIT-15 ""
*MEAS_COND_AXIS_UNIT-16 ""
*MEAS_COND_AXIS_UNIT-17 ""
*MEAS_COND_AXIS_UNIT-18 ""
*MEAS_COND_AXIS_UNIT-19 ""
*MEAS_COND_AXIS_UNIT-20 ""
*MEAS_COND_AXIS_UNIT-21 ""
*MEAS_COND_AXIS_UNIT-22 ""
*MEAS_COND_AXIS_UNIT-23 "mm"
*MEAS_COND_AXIS_UNIT-24 "mm"
*MEAS_COND_AXIS_UNIT-25 "mm"
*MEAS_COND_AXIS_UNIT-26 ""
*MEAS_COND_AXIS_UNIT-27 ""
*MEAS_COND_AXIS_UNIT-28 ""
*MEAS_COND_AXIS_UNIT-29 ""
*MEAS_COND_AXIS_UNIT-30 "div"
*MEAS_COND_COUNTER_CNTLOSS_CORR "0.0000000000"
*MEAS_COND_COUNTER_PHABASE "38.0000000000"
*MEAS_COND_COUNTER_PHAWINDOW "16.0000000000"
*MEAS_COND_COUNTER_PHA_UNIT "div"
*MEAS_COND_COUNTER_TAUDIFF "30.0000000000"
*MEAS_COND_COUNTER_TAUINT "0.0000000000"
*MEAS_COND_IRRADIATION_MODE "OFF"
*MEAS_COND_IRRADIATION_WIDTH ""
*MEAS_COND_OPT_ATTR "集中法"
*MEAS_COND_OPT_NAME "@集中法"
*MEAS_COND_UNSYMMETRIC_MODE "OFF"
*MEAS_COND_XG_CURRENT "30.0000000000"
*MEAS_COND_XG_VOLTAGE "40.0000000000"
*MEAS_COND_XG_WAVE_TYPE "Ka"
*MEAS_DATA_COUNT "5001.0000000000"
*MEAS_SCAN_AXIS_X "2θ/θ"
*MEAS_SCAN_AXIS_X_INTERNAL "TwoThetaTheta"
*MEAS_SCAN_END_TIME "08/06/22 14:57:20"
*MEAS_SCAN_MODE "CONTINUOUS"
*MEAS_SCAN_MONITOR "0"
*MEAS_SCAN_RESOLUTION_X "0.0002"
*MEAS_SCAN_SPEED "2.5"
*MEAS_SCAN_SPEED_UNIT "deg/min"
*MEAS_SCAN_START "20.0000000000"
*MEAS_SCAN_START_TIME "08/06/22 14:35:56"
*MEAS_SCAN_STEP "0.0100000000"
*MEAS_SCAN_STOP "70.0000000000"
*MEAS_SCAN_UNIT_X "deg"
*MEAS_SCAN_UNIT_Y "counts"
*RAS_HEADER_END
*RAS_INT_START
20.0000 942.0000 1.0000
20.0400 959.0000 1.0000
20.0800 899.0000 1.0000
20.1200 900.0000 1.0000
20.1600 961.0000 1.0000
20.2000 925.0000 1.0000
20.2400 976.0000 1.0000
20.2800 931.0000 1.0000
20.3200 893.0000 1.0000
20.3600 953.0000 1.0000
20.4000 931.0000 1.0000
20.4400 917.0000 1.0000
20.4800 909.0000 1.0000
20.5200 928.0000 1.0000
20.5600 885.0000 1.0000
20.6000 864.0000 1.0000
20.6400 952.0000 1.0000
20.6800 929.0000 1.0000
20.7200 898.0000 1.0000
20.7600 929.0000 1.0000
20.8000 897.0000 1.0000
20.8400 945.0000 1.0000
20.8800 895.0000 1.0000
20.9200 955.0000 1.0000
20.9600 973.0000 1.0000
21.0000 920.0000 1.0000
21.0400 946.0000 1.0000
21.0800 928.0000 1.0000
21.1200 916.0000 1.0000
21.1600 908.0000 1.0000
21.2000 968.0000 1.0000
21.2400 927.0000 1.0000
21.2800 952.0000 1.0000
21.3200 872.0000 1.0000
21.3600 911.0000 1.0000
21.4000 940.0000 1.0000
21.4400 924.0000 1.0000
21.4800 867.0000 1.0000
21.5200 985.0000 1.0000
21.5600 908.0000 1.0000
21.6000 946.0000 1.0000
21.6400 879.0000 1.0000
21.6800 876.0000 1.0000
21.7200 904.0000 1.0000
21.7600 910.0000 1.0000
21.8000 896.0000 1.0000
21.8400 908.0000 1.0000
21.8800 925.0000 1.0000
21.9200 888.0000 1.0000
21.9600 890.0000 1.0000
22.0000 946.0000 1.0000
22.0400 853.0000 1.0000
22.0800 923.0000 1.0000
22.1200 946.0000 1.0000
22.1600 892.0000 1.0000
22.2000 854.0000 1.0000
22.2400 943.0000 1.0000
22.2800 889.0000 1.0000
22.3200 885.0000 1.0000
22.3600 876.0000 1.0000
22.4000 905.0000 1.0000
22.4400 895.0000 1.0000
22.4800 863.0000 1.0000
22.5200 906.0000 1.0000
22.5600 874.0000 1.0000
22.6000 927.0000 1.0000
22.6400 895.0000 1.0000
22.6800 873.0000 1.0000
22.7200 877.0000 1.0000
22.7600 907.0000 1.0000
22.8000 861.0000 1.0000
22.8400 872.0000 1.0000
22.8800 889.0000 1.0000
22.9200 872.0000 1.0000
22.9600 935.0000 1.0000
23.0000 890.0000 1.0000
23.0400 902.0000 1.0000
23.0800 883.0000 1.0000
23.1200 881.0000 1.0000
23.1600 909.0000 1.0000
23.2000 919.0000 1.0000
23.2400 899.0000 1.0000
23.2800 880.0000 1.0000
23.3200 893.0000 1.0000
23.3600 903.0000 1.0000
23.4000 891.0000 1.0000
23.4400 899.0000 1.0000
23.4800 884.0000 1.0000
23.5200 835.0000 1.0000
23.5600 869.0000 1.0000
23.6000 875.0000 1.0000
23.6400 939.0000 1.0000
23.6800 869.0000 1.0000
23.7200 927.0000 1.0000
23.7600 923.0000 1.0000
23.8000 909.0000 1.0000
23.8400 928.0000 1.0000
23.8800 913.0000 1.0000
23.9200 885.0000 1.0000
23.9600 946.0000 1.0000
24.0000 922.0000 1.0000
24.0400 964.0000 1.0000
24.0800 926.0000 1.0000
24.1200 932.0000 1.0000
24.1600 922.0000 1.0000
24.2000 933.0000 1.0000
24.2400 903.0000 1.0000
24.2800 866.0000 1.0000
24.3200 880.0000 1.0000
24.3600 838.0000 1.0000
24.4000 900.0000 1.0000
24.4400 856.0000 1.0000
24.4800 898.0000 1.0000
24.5200 894.0000 1.0000
24.5600 872.0000 1.0000
24.6000 851.0000 1.0000
24.6400 854.0000 1.0000
24.6800 871.0000 1.0000
24.7200 880.0000 1.0000
24.7600 866.0000 1.0000
24.8000 881.0000 1.0000
24.8400 883.0000 1.0000
24.8800 864.0000 1.0000
24.9200 856.0000 1.0000
24.9600 823.0000 1.0000
25.0000 881.0000 1.0000
25.0400 832.0000 1.0000
25.0800 873.0000 1.0000
25.1200 868.0000 1.0000
25.1600 874.0000 1.0000
25.2000 899.0000 1.0000
25.2400 869.0000 1.0000
25.2800 853.0000 1.0000
25.3200 856.0000 1.0000
25.3600 855.0000 1.0000
25.4000 836.0000 1.0000
25.4400 858.0000 1.0000
25.4800 871.0000 1.0000
25.5200 863.0000 1.0000
25.5600 874.0000 1.0000
25.6000 890.0000 1.0000
25.6400 870.0000 1.0000
25.6800 841.0000 1.0000
25.7200 836.0000 1.0000
25.7600 920.0000 1.0000
25.8000 879.0000 1.0000
25.8400 909.0000 1.0000
25.8800 880.0000 1.0000
25.9200 886.0000 1.0000
25.9600 918.0000 1.0000
26.0000 1020.0000 1.0000
26.0400 964.0000 1.0000
26.0800 1009.0000 1.0000
26.1200 1133.0000 1.0000
26.1600 1176.0000 1.0000
26.2000 1276.0000 1.0000
26.2400 1463.0000 1.0000
26.2800 1635.0000 1.0000
26.3200 2019.0000 1.0000
26.3600 2502.0000 1.0000
26.4000 3032.0000 1.0000
26.4400 3210.0000 1.0000
26.4800 2834.0000 1.0000
26.5200 2411.0000 1.0000
26.5600 1890.0000 1.0000
26.6000 1518.0000 1.0000
26.6400 1363.0000 1.0000
26.6800 1181.0000 1.0000
26.7200 1074.0000 1.0000
26.7600 1057.0000 1.0000
26.8000 1021.0000 1.0000
26.8400 944.0000 1.0000
26.8800 944.0000 1.0000
26.9200 949.0000 1.0000
26.9600 901.0000 1.0000
27.0000 820.0000 1.0000
27.0400 852.0000 1.0000
27.0800 813.0000 1.0000
27.1200 880.0000 1.0000
27.1600 821.0000 1.0000
27.2000 836.0000 1.0000
27.2400 814.0000 1.0000
27.2800 805.0000 1.0000
27.3200 818.0000 1.0000
27.3600 770.0000 1.0000
27.4000 791.0000 1.0000
27.4400 837.0000 1.0000
27.4800 837.0000 1.0000
27.5200 778.0000 1.0000
27.5600 734.0000 1.0000
27.6000 760.0000 1.0000
27.6400 768.0000 1.0000
27.6800 823.0000 1.0000
27.7200 780.0000 1.0000
27.7600 711.0000 1.0000
27.8000 760.0000 1.0000
27.8400 784.0000 1.0000
27.8800 783.0000 1.0000
27.9200 737.0000 1.0000
27.9600 823.0000 1.0000
28.0000 776.0000 1.0000
28.0400 756.0000 1.0000
28.0800 761.0000 1.0000
28.1200 781.0000 1.0000
28.1600 742.0000 1.0000
28.2000 720.0000 1.0000
28.2400 790.0000 1.0000
28.2800 726.0000 1.0000
28.3200 765.0000 1.0000
28.3600 734.0000 1.0000
28.4000 747.0000 1.0000
28.4400 754.0000 1.0000
28.4800 728.0000 1.0000
28.5200 766.0000 1.0000
28.5600 737.0000 1.0000
28.6000 726.0000 1.0000
28.6400 772.0000 1.0000
28.6800 741.0000 1.0000
28.7200 716.0000 1.0000
28.7600 718.0000 1.0000
28.8000 718.0000 1.0000
28.8400 744.0000 1.0000
28.8800 745.0000 1.0000
28.9200 731.0000 1.0000
28.9600 745.0000 1.0000
29.0000 725.0000 1.0000
29.0400 771.0000 1.0000
29.0800 712.0000 1.0000
29.1200 707.0000 1.0000
29.1600 713.0000 1.0000
29.2000 726.0000 1.0000
29.2400 687.0000 1.0000
29.2800 715.0000 1.0000
29.3200 747.0000 1.0000
29.3600 753.0000 1.0000
29.4000 716.0000 1.0000
29.4400 708.0000 1.0000
29.4800 693.0000 1.0000
29.5200 682.0000 1.0000
29.5600 697.0000 1.0000
29.6000 684.0000 1.0000
29.6400 748.0000 1.0000
29.6800 727.0000 1.0000
29.7200 716.0000 1.0000
29.7600 699.0000 1.0000
29.8000 738.0000 1.0000
29.8400 694.0000 1.0000
29.8800 663.0000 1.0000
29.9200 711.0000 1.0000
29.9600 688.0000 1.0000
30.0000 719.0000 1.0000
30.0400 688.0000 1.0000
30.0800 721.0000 1.0000
30.1200 706.0000 1.0000
30.1600 710.0000 1.0000
30.2000 719.0000 1.0000
30.2400 686.0000 1.0000
30.2800 702.0000 1.0000
30.3200 720.0000 1.0000
30.3600 639.0000 1.0000
30.4000 662.0000 1.0000
30.4400 699.0000 1.0000
30.4800 684.0000 1.0000
30.5200 704.0000 1.0000
30.5600 662.0000 1.0000
30.6000 700.0000 1.0000
30.6400 702.0000 1.0000
30.6800 670.0000 1.0000
30.7200 659.0000 1.0000
30.7600 717.0000 1.0000
30.8000 676.0000 1.0000
30.8400 656.0000 1.0000
30.8800 685.0000 1.0000
30.9200 679.0000 1.0000
30.9600 664.0000 1.0000
31.0000 717.0000 1.0000
31.0400 730.0000 1.0000
31.0800 681.0000 1.0000
31.1200 688.0000 1.0000
31.1600 673.0000 1.0000
31.2000 680.0000 1.0000
31.2400 686.0000 1.0000
31.2800 652.0000 1.0000
31.3200 637.0000 1.0000
31.3600 663.0000 1.0000
31.4000 660.0000 1.0000
31.4400 618.0000 1.0000
31.4800 698.0000 1.0000
31.5200 677.0000 1.0000
31.5600 670.0000 1.0000
31.6000 658.0000 1.0000
31.6400 647.0000 1.0000
31.6800 627.0000 1.0000
31.7200 649.0000 1.0000
31.7600 667.0000 1.0000
31.8000 686.0000 1.0000
31.8400 681.0000 1.0000
31.8800 637.0000 1.0000
31.9200 639.0000 1.0000
31.9600 622.0000 1.0000
32.0000 662.0000 1.0000
32.0400 640.0000 1.0000
32.0800 634.0000 1.0000
32.1200 640.0000 1.0000
32.1600 627.0000 1.0000
32.2000 602.0000 1.0000
32.2400 624.0000 1.0000
32.2800 614.0000 1.0000
32.3200 639.0000 1.0000
32.3600 637.0000 1.0000
32.4000 620.0000 1.0000
32.4400 637.0000 1.0000
32.4800 622.0000 1.0000
32.5200 610.0000 1.0000
32.5600 637.0000 1.0000
32.6000 652.0000 1.0000
32.6400 662.0000 1.0000
32.6800 663.0000 1.0000
32.7200 695.0000 1.0000
32.7600 666.0000 1.0000
32.8000 671.0000 1.0000
32.8400 692.0000 1.0000
32.8800 623.0000 1.0000
32.9200 717.0000 1.0000
32.9600 685.0000 1.0000
33.0000 770.0000 1.0000
33.0400 773.0000 1.0000
33.0800 787.0000 1.0000
33.1200 825.0000 1.0000
33.1600 773.0000 1.0000
33.2000 764.0000 1.0000
33.2400 755.0000 1.0000
33.2800 728.0000 1.0000
33.3200 721.0000 1.0000
33.3600 760.0000 1.0000
33.4000 809.0000 1.0000
33.4400 850.0000 1.0000
33.4800 941.0000 1.0000
33.5200 1032.0000 1.0000
33.5600 1189.0000 1.0000
33.6000 1468.0000 1.0000
33.6400 1512.0000 1.0000
33.6800 1424.0000 1.0000
33.7200 1247.0000 1.0000
33.7600 1128.0000 1.0000
33.8000 949.0000 1.0000
33.8400 784.0000 1.0000
33.8800 838.0000 1.0000
33.9200 741.0000 1.0000
33.9600 739.0000 1.0000
34.0000 661.0000 1.0000
34.0400 645.0000 1.0000
34.0800 635.0000 1.0000
34.1200 664.0000 1.0000
34.1600 637.0000 1.0000
34.2000 662.0000 1.0000
34.2400 568.0000 1.0000
34.2800 567.0000 1.0000
34.3200 600.0000 1.0000
34.3600 608.0000 1.0000
34.4000 585.0000 1.0000
34.4400 568.0000 1.0000
34.4800 564.0000 1.0000
34.5200 546.0000 1.0000
34.5600 562.0000 1.0000
34.6000 546.0000 1.0000
34.6400 548.0000 1.0000
34.6800 572.0000 1.0000
34.7200 533.0000 1.0000
34.7600 566.0000 1.0000
34.8000 552.0000 1.0000
34.8400 549.0000 1.0000
34.8800 569.0000 1.0000
34.9200 543.0000 1.0000
34.9600 544.0000 1.0000
35.0000 548.0000 1.0000
35.0400 543.0000 1.0000
35.0800 553.0000 1.0000
35.1200 545.0000 1.0000
35.1600 522.0000 1.0000
35.2000 554.0000 1.0000
35.2400 570.0000 1.0000
35.2800 606.0000 1.0000
35.3200 564.0000 1.0000
35.3600 599.0000 1.0000
35.4000 668.0000 1.0000
35.4400 668.0000 1.0000
35.4800 739.0000 1.0000
35.5200 831.0000 1.0000
35.5600 811.0000 1.0000
35.6000 831.0000 1.0000
35.6400 746.0000 1.0000
35.6800 648.0000 1.0000
35.7200 649.0000 1.0000
35.7600 591.0000 1.0000
35.8000 558.0000 1.0000
35.8400 522.0000 1.0000
35.8800 510.0000 1.0000
35.9200 524.0000 1.0000
35.9600 532.0000 1.0000
36.0000 540.0000 1.0000
36.0400 525.0000 1.0000
36.0800 527.0000 1.0000
36.1200 508.0000 1.0000
36.1600 484.0000 1.0000
36.2000 521.0000 1.0000
36.2400 481.0000 1.0000
36.2800 497.0000 1.0000
36.3200 538.0000 1.0000
36.3600 499.0000 1.0000
36.4000 514.0000 1.0000
36.4400 507.0000 1.0000
36.4800 502.0000 1.0000
36.5200 498.0000 1.0000
36.5600 524.0000 1.0000
36.6000 493.0000 1.0000
36.6400 522.0000 1.0000
36.6800 535.0000 1.0000
36.7200 494.0000 1.0000
36.7600 501.0000 1.0000
36.8000 485.0000 1.0000
36.8400 510.0000 1.0000
36.8800 526.0000 1.0000
36.9200 521.0000 1.0000
36.9600 495.0000 1.0000
37.0000 514.0000 1.0000
37.0400 461.0000 1.0000
37.0800 516.0000 1.0000
37.1200 499.0000 1.0000
37.1600 499.0000 1.0000
37.2000 523.0000 1.0000
37.2400 544.0000 1.0000
37.2800 586.0000 1.0000
37.3200 577.0000 1.0000
37.3600 638.0000 1.0000
37.4000 700.0000 1.0000
37.4400 756.0000 1.0000
37.4800 918.0000 1.0000
37.5200 1096.0000 1.0000
37.5600 1369.0000 1.0000
37.6000 1781.0000 1.0000
37.6400 2212.0000 1.0000
37.6800 2520.0000 1.0000
37.7200 2559.0000 1.0000
37.7600 2298.0000 1.0000
37.8000 1913.0000 1.0000
37.8400 1511.0000 1.0000
37.8800 1203.0000 1.0000
37.9200 910.0000 1.0000
37.9600 795.0000 1.0000
38.0000 724.0000 1.0000
38.0400 591.0000 1.0000
38.0800 599.0000 1.0000
38.1200 532.0000 1.0000
38.1600 489.0000 1.0000
38.2000 502.0000 1.0000
38.2400 493.0000 1.0000
38.2800 477.0000 1.0000
38.3200 501.0000 1.0000
38.3600 481.0000 1.0000
38.4000 475.0000 1.0000
38.4400 490.0000 1.0000
38.4800 460.0000 1.0000
38.5200 431.0000 1.0000
38.5600 430.0000 1.0000
38.6000 474.0000 1.0000
38.6400 439.0000 1.0000
38.6800 458.0000 1.0000
38.7200 504.0000 1.0000
38.7600 500.0000 1.0000
38.8000 463.0000 1.0000
38.8400 448.0000 1.0000
38.8800 489.0000 1.0000
38.9200 454.0000 1.0000
38.9600 458.0000 1.0000
39.0000 448.0000 1.0000
39.0400 459.0000 1.0000
39.0800 456.0000 1.0000
39.1200 440.0000 1.0000
39.1600 453.0000 1.0000
39.2000 423.0000 1.0000
39.2400 442.0000 1.0000
39.2800 446.0000 1.0000
39.3200 440.0000 1.0000
39.3600 435.0000 1.0000
39.4000 441.0000 1.0000
39.4400 420.0000 1.0000
39.4800 435.0000 1.0000
39.5200 416.0000 1.0000
39.5600 436.0000 1.0000
39.6000 436.0000 1.0000
39.6400 414.0000 1.0000
39.6800 441.0000 1.0000
39.7200 426.0000 1.0000
39.7600 457.0000 1.0000
39.8000 397.0000 1.0000
39.8400 399.0000 1.0000
39.8800 418.0000 1.0000
39.9200 404.0000 1.0000
39.9600 420.0000 1.0000
40.0000 394.0000 1.0000
40.0400 381.0000 1.0000
40.0800 437.0000 1.0000
40.1200 433.0000 1.0000
40.1600 413.0000 1.0000
40.2000 465.0000 1.0000
40.2400 387.0000 1.0000
40.2800 391.0000 1.0000
40.3200 418.0000 1.0000
40.3600 405.0000 1.0000
40.4000 405.0000 1.0000
40.4400 399.0000 1.0000
40.4800 398.0000 1.0000
40.5200 414.0000 1.0000
40.5600 387.0000 1.0000
40.6000 381.0000 1.0000
40.6400 395.0000 1.0000
40.6800 440.0000 1.0000
40.7200 456.0000 1.0000
40.7600 470.0000 1.0000
40.8000 450.0000 1.0000
40.8400 450.0000 1.0000
40.8800 424.0000 1.0000
40.9200 438.0000 1.0000
40.9600 426.0000 1.0000
41.0000 418.0000 1.0000
41.0400 443.0000 1.0000
41.0800 422.0000 1.0000
41.1200 420.0000 1.0000
41.1600 394.0000 1.0000
41.2000 431.0000 1.0000
41.2400 409.0000 1.0000
41.2800 390.0000 1.0000
41.3200 395.0000 1.0000
41.3600 413.0000 1.0000
41.4000 411.0000 1.0000
41.4400 418.0000 1.0000
41.4800 393.0000 1.0000
41.5200 410.0000 1.0000
41.5600 419.0000 1.0000
41.6000 373.0000 1.0000
41.6400 388.0000 1.0000
41.6800 388.0000 1.0000
41.7200 390.0000 1.0000
41.7600 406.0000 1.0000
41.8000 359.0000 1.0000
41.8400 398.0000 1.0000
41.8800 407.0000 1.0000
41.9200 401.0000 1.0000
41.9600 444.0000 1.0000
42.0000 398.0000 1.0000
42.0400 413.0000 1.0000
42.0800 382.0000 1.0000
42.1200 387.0000 1.0000
42.1600 397.0000 1.0000
42.2000 403.0000 1.0000
42.2400 367.0000 1.0000
42.2800 400.0000 1.0000
42.3200 429.0000 1.0000
42.3600 447.0000 1.0000
42.4000 434.0000 1.0000
42.4400 460.0000 1.0000
42.4800 440.0000 1.0000
42.5200 439.0000 1.0000
42.5600 386.0000 1.0000
42.6000 449.0000 1.0000
42.6400 391.0000 1.0000
42.6800 411.0000 1.0000
42.7200 394.0000 1.0000
42.7600 408.0000 1.0000
42.8000 403.0000 1.0000
42.8400 395.0000 1.0000
42.8800 388.0000 1.0000
42.9200 376.0000 1.0000
42.9600 394.0000 1.0000
43.0000 378.0000 1.0000
43.0400 368.0000 1.0000
43.0800 397.0000 1.0000
43.1200 382.0000 1.0000
43.1600 394.0000 1.0000
43.2000 402.0000 1.0000
43.2400 374.0000 1.0000
43.2800 441.0000 1.0000
43.3200 389.0000 1.0000
43.3600 409.0000 1.0000
43.4000 401.0000 1.0000
43.4400 400.0000 1.0000
43.4800 390.0000 1.0000
43.5200 393.0000 1.0000
43.5600 410.0000 1.0000
43.6000 393.0000 1.0000
43.6400 350.0000 1.0000
43.6800 372.0000 1.0000
43.7200 421.0000 1.0000
43.7600 395.0000 1.0000
43.8000 344.0000 1.0000
43.8400 367.0000 1.0000
43.8800 373.0000 1.0000
43.9200 386.0000 1.0000
43.9600 413.0000 1.0000
44.0000 389.0000 1.0000
44.0400 386.0000 1.0000
44.0800 409.0000 1.0000
44.1200 383.0000 1.0000
44.1600 374.0000 1.0000
44.2000 377.0000 1.0000
44.2400 384.0000 1.0000
44.2800 397.0000 1.0000
44.3200 385.0000 1.0000
44.3600 375.0000 1.0000
44.4000 380.0000 1.0000
44.4400 384.0000 1.0000
44.4800 382.0000 1.0000
44.5200 393.0000 1.0000
44.5600 360.0000 1.0000
44.6000 399.0000 1.0000
44.6400 351.0000 1.0000
44.6800 357.0000 1.0000
44.7200 377.0000 1.0000
44.7600 396.0000 1.0000
44.8000 382.0000 1.0000
44.8400 392.0000 1.0000
44.8800 388.0000 1.0000
44.9200 389.0000 1.0000
44.9600 397.0000 1.0000
45.0000 386.0000 1.0000
45.0400 359.0000 1.0000
45.0800 385.0000 1.0000
45.1200 366.0000 1.0000
45.1600 358.0000 1.0000
45.2000 380.0000 1.0000
45.2400 350.0000 1.0000
45.2800 363.0000 1.0000
45.3200 391.0000 1.0000
45.3600 368.0000 1.0000
45.4000 361.0000 1.0000
45.4400 370.0000 1.0000
45.4800 368.0000 1.0000
45.5200 377.0000 1.0000
45.5600 362.0000 1.0000
45.6000 340.0000 1.0000
45.6400 351.0000 1.0000
45.6800 357.0000 1.0000
45.7200 372.0000 1.0000
45.7600 328.0000 1.0000
45.8000 389.0000 1.0000
45.8400 372.0000 1.0000
45.8800 337.0000 1.0000
45.9200 376.0000 1.0000
45.9600 339.0000 1.0000
46.0000 349.0000 1.0000
46.0400 352.0000 1.0000
46.0800 379.0000 1.0000
46.1200 360.0000 1.0000
46.1600 386.0000 1.0000
46.2000 342.0000 1.0000
46.2400 380.0000 1.0000
46.2800 354.0000 1.0000
46.3200 371.0000 1.0000
46.3600 364.0000 1.0000
46.4000 351.0000 1.0000
46.4400 393.0000 1.0000
46.4800 345.0000 1.0000
46.5200 373.0000 1.0000
46.5600 369.0000 1.0000
46.6000 358.0000 1.0000
46.6400 353.0000 1.0000
46.6800 366.0000 1.0000
46.7200 358.0000 1.0000
46.7600 354.0000 1.0000
46.8000 338.0000 1.0000
46.8400 353.0000 1.0000
46.8800 347.0000 1.0000
46.9200 337.0000 1.0000
46.9600 357.0000 1.0000
47.0000 341.0000 1.0000
47.0400 343.0000 1.0000
47.0800 340.0000 1.0000
47.1200 343.0000 1.0000
47.1600 371.0000 1.0000
47.2000 374.0000 1.0000
47.2400 329.0000 1.0000
47.2800 346.0000 1.0000
47.3200 367.0000 1.0000
47.3600 366.0000 1.0000
47.4000 338.0000 1.0000
47.4400 366.0000 1.0000
47.4800 351.0000 1.0000
47.5200 385.0000 1.0000
47.5600 351.0000 1.0000
47.6000 357.0000 1.0000
47.6400 365.0000 1.0000
47.6800 365.0000 1.0000
47.7200 338.0000 1.0000
47.7600 322.0000 1.0000
47.8000 349.0000 1.0000
47.8400 334.0000 1.0000
47.8800 352.0000 1.0000
47.9200 303.0000 1.0000
47.9600 360.0000 1.0000
48.0000 357.0000 1.0000
48.0400 352.0000 1.0000
48.0800 341.0000 1.0000
48.1200 345.0000 1.0000
48.1600 319.0000 1.0000
48.2000 378.0000 1.0000
48.2400 322.0000 1.0000
48.2800 333.0000 1.0000
48.3200 327.0000 1.0000
48.3600 350.0000 1.0000
48.4000 356.0000 1.0000
48.4400 333.0000 1.0000
48.4800 381.0000 1.0000
48.5200 301.0000 1.0000
48.5600 353.0000 1.0000
48.6000 325.0000 1.0000
48.6400 339.0000 1.0000
48.6800 329.0000 1.0000
48.7200 343.0000 1.0000
48.7600 325.0000 1.0000
48.8000 339.0000 1.0000
48.8400 333.0000 1.0000
48.8800 312.0000 1.0000
48.9200 309.0000 1.0000
48.9600 357.0000 1.0000
49.0000 355.0000 1.0000
49.0400 332.0000 1.0000
49.0800 356.0000 1.0000
49.1200 347.0000 1.0000
49.1600 370.0000 1.0000
49.2000 383.0000 1.0000
49.2400 390.0000 1.0000
49.2800 363.0000 1.0000
49.3200 353.0000 1.0000
49.3600 349.0000 1.0000
49.4000 413.0000 1.0000
49.4400 394.0000 1.0000
49.4800 375.0000 1.0000
49.5200 365.0000 1.0000
49.5600 367.0000 1.0000
49.6000 368.0000 1.0000
49.6400 380.0000 1.0000
49.6800 356.0000 1.0000
49.7200 356.0000 1.0000
49.7600 346.0000 1.0000
49.8000 365.0000 1.0000
49.8400 357.0000 1.0000
49.8800 355.0000 1.0000
49.9200 346.0000 1.0000
49.9600 372.0000 1.0000
50.0000 382.0000 1.0000
50.0400 355.0000 1.0000
50.0800 367.0000 1.0000
50.1200 351.0000 1.0000
50.1600 344.0000 1.0000
50.2000 348.0000 1.0000
50.2400 325.0000 1.0000
50.2800 346.0000 1.0000
50.3200 348.0000 1.0000
50.3600 365.0000 1.0000
50.4000 375.0000 1.0000
50.4400 344.0000 1.0000
50.4800 337.0000 1.0000
50.5200 350.0000 1.0000
50.5600 342.0000 1.0000
50.6000 344.0000 1.0000
50.6400 339.0000 1.0000
50.6800 370.0000 1.0000
50.7200 357.0000 1.0000
50.7600 360.0000 1.0000
50.8000 346.0000 1.0000
50.8400 368.0000 1.0000
50.8800 356.0000 1.0000
50.9200 361.0000 1.0000
50.9600 377.0000 1.0000
51.0000 391.0000 1.0000
51.0400 374.0000 1.0000
51.0800 421.0000 1.0000
51.1200 430.0000 1.0000
51.1600 484.0000 1.0000
51.2000 538.0000 1.0000
51.2400 588.0000 1.0000
51.2800 725.0000 1.0000
51.3200 893.0000 1.0000
51.3600 1210.0000 1.0000
51.4000 1662.0000 1.0000
51.4400 2076.0000 1.0000
51.4800 2229.0000 1.0000
51.5200 2057.0000 1.0000
51.5600 1789.0000 1.0000
51.6000 1646.0000 1.0000
51.6400 1329.0000 1.0000
51.6800 1063.0000 1.0000
51.7200 791.0000 1.0000
51.7600 659.0000 1.0000
51.8000 570.0000 1.0000
51.8400 502.0000 1.0000
51.8800 479.0000 1.0000
51.9200 458.0000 1.0000
51.9600 374.0000 1.0000
52.0000 422.0000 1.0000
52.0400 356.0000 1.0000
52.0800 369.0000 1.0000
52.1200 398.0000 1.0000
52.1600 391.0000 1.0000
52.2000 360.0000 1.0000
52.2400 368.0000 1.0000
52.2800 359.0000 1.0000
52.3200 346.0000 1.0000
52.3600 339.0000 1.0000
52.4000 327.0000 1.0000
52.4400 354.0000 1.0000
52.4800 337.0000 1.0000
52.5200 369.0000 1.0000
52.5600 330.0000 1.0000
52.6000 362.0000 1.0000
52.6400 361.0000 1.0000
52.6800 348.0000 1.0000
52.7200 359.0000 1.0000
52.7600 330.0000 1.0000
52.8000 341.0000 1.0000
52.8400 326.0000 1.0000
52.8800 320.0000 1.0000
52.9200 334.0000 1.0000
52.9600 314.0000 1.0000
53.0000 383.0000 1.0000
53.0400 313.0000 1.0000
53.0800 332.0000 1.0000
53.1200 349.0000 1.0000
53.1600 311.0000 1.0000
53.2000 338.0000 1.0000
53.2400 352.0000 1.0000
53.2800 362.0000 1.0000
53.3200 308.0000 1.0000
53.3600 332.0000 1.0000
53.4000 346.0000 1.0000
53.4400 331.0000 1.0000
53.4800 330.0000 1.0000
53.5200 339.0000 1.0000
53.5600 326.0000 1.0000
53.6000 319.0000 1.0000
53.6400 330.0000 1.0000
53.6800 342.0000 1.0000
53.7200 327.0000 1.0000
53.7600 334.0000 1.0000
53.8000 311.0000 1.0000
53.8400 339.0000 1.0000
53.8800 393.0000 1.0000
53.9200 361.0000 1.0000
53.9600 371.0000 1.0000
54.0000 386.0000 1.0000
54.0400 378.0000 1.0000
54.0800 383.0000 1.0000
54.1200 378.0000 1.0000
54.1600 386.0000 1.0000
54.2000 387.0000 1.0000
54.2400 355.0000 1.0000
54.2800 395.0000 1.0000
54.3200 413.0000 1.0000
54.3600 394.0000 1.0000
54.4000 452.0000 1.0000
54.4400 492.0000 1.0000
54.4800 490.0000 1.0000
54.5200 458.0000 1.0000
54.5600 482.0000 1.0000
54.6000 431.0000 1.0000
54.6400 489.0000 1.0000
54.6800 428.0000 1.0000
54.7200 387.0000 1.0000
54.7600 386.0000 1.0000
54.8000 355.0000 1.0000
54.8400 348.0000 1.0000
54.8800 375.0000 1.0000
54.9200 333.0000 1.0000
54.9600 370.0000 1.0000
55.0000 328.0000 1.0000
55.0400 318.0000 1.0000
55.0800 339.0000 1.0000
55.1200 321.0000 1.0000
55.1600 341.0000 1.0000
55.2000 292.0000 1.0000
55.2400 302.0000 1.0000
55.2800 341.0000 1.0000
55.3200 309.0000 1.0000
55.3600 331.0000 1.0000
55.4000 334.0000 1.0000
55.4400 308.0000 1.0000
55.4800 323.0000 1.0000
55.5200 310.0000 1.0000
55.5600 296.0000 1.0000
55.6000 337.0000 1.0000
55.6400 315.0000 1.0000
55.6800 329.0000 1.0000
55.7200 311.0000 1.0000
55.7600 326.0000 1.0000
55.8000 317.0000 1.0000
55.8400 316.0000 1.0000
55.8800 311.0000 1.0000
55.9200 321.0000 1.0000
55.9600 300.0000 1.0000
56.0000 348.0000 1.0000
56.0400 327.0000 1.0000
56.0800 334.0000 1.0000
56.1200 316.0000 1.0000
56.1600 321.0000 1.0000
56.2000 302.0000 1.0000
56.2400 323.0000 1.0000
56.2800 306.0000 1.0000
56.3200 334.0000 1.0000
56.3600 330.0000 1.0000
56.4000 298.0000 1.0000
56.4400 324.0000 1.0000
56.4800 306.0000 1.0000
56.5200 298.0000 1.0000
56.5600 307.0000 1.0000
56.6000 314.0000 1.0000
56.6400 324.0000 1.0000
56.6800 346.0000 1.0000
56.7200 278.0000 1.0000
56.7600 325.0000 1.0000
56.8000 303.0000 1.0000
56.8400 297.0000 1.0000
56.8800 292.0000 1.0000
56.9200 309.0000 1.0000
56.9600 309.0000 1.0000
57.0000 281.0000 1.0000
57.0400 303.0000 1.0000
57.0800 303.0000 1.0000
57.1200 311.0000 1.0000
57.1600 319.0000 1.0000
57.2000 316.0000 1.0000
57.2400 307.0000 1.0000
57.2800 331.0000 1.0000
57.3200 319.0000 1.0000
57.3600 319.0000 1.0000
57.4000 331.0000 1.0000
57.4400 349.0000 1.0000
57.4800 304.0000 1.0000
57.5200 351.0000 1.0000
57.5600 312.0000 1.0000
57.6000 342.0000 1.0000
57.6400 347.0000 1.0000
57.6800 346.0000 1.0000
57.7200 320.0000 1.0000
57.7600 329.0000 1.0000
57.8000 327.0000 1.0000
57.8400 311.0000 1.0000
57.8800 290.0000 1.0000
57.9200 338.0000 1.0000
57.9600 334.0000 1.0000
58.0000 319.0000 1.0000
58.0400 311.0000 1.0000
58.0800 339.0000 1.0000
58.1200 295.0000 1.0000
58.1600 333.0000 1.0000
58.2000 294.0000 1.0000
58.2400 347.0000 1.0000
58.2800 336.0000 1.0000
58.3200 313.0000 1.0000
58.3600 318.0000 1.0000
58.4000 303.0000 1.0000
58.4400 313.0000 1.0000
58.4800 312.0000 1.0000
58.5200 292.0000 1.0000
58.5600 315.0000 1.0000
58.6000 289.0000 1.0000
58.6400 332.0000 1.0000
58.6800 325.0000 1.0000
58.7200 313.0000 1.0000
58.7600 338.0000 1.0000
58.8000 275.0000 1.0000
58.8400 286.0000 1.0000
58.8800 290.0000 1.0000
58.9200 365.0000 1.0000
58.9600 331.0000 1.0000
59.0000 308.0000 1.0000
59.0400 314.0000 1.0000
59.0800 270.0000 1.0000
59.1200 300.0000 1.0000
59.1600 286.0000 1.0000
59.2000 297.0000 1.0000
59.2400 343.0000 1.0000
59.2800 322.0000 1.0000
59.3200 306.0000 1.0000
59.3600 314.0000 1.0000
59.4000 301.0000 1.0000
59.4400 295.0000 1.0000
59.4800 313.0000 1.0000
59.5200 313.0000 1.0000
59.5600 333.0000 1.0000
59.6000 326.0000 1.0000
59.6400 286.0000 1.0000
59.6800 276.0000 1.0000
59.7200 304.0000 1.0000
59.7600 312.0000 1.0000
59.8000 337.0000 1.0000
59.8400 323.0000 1.0000
59.8800 327.0000 1.0000
59.9200 309.0000 1.0000
59.9600 308.0000 1.0000
60.0000 317.0000 1.0000
60.0400 289.0000 1.0000
60.0800 320.0000 1.0000
60.1200 312.0000 1.0000
60.1600 313.0000 1.0000
60.2000 303.0000 1.0000
60.2400 291.0000 1.0000
60.2800 307.0000 1.0000
60.3200 265.0000 1.0000
60.3600 308.0000 1.0000
60.4000 303.0000 1.0000
60.4400 326.0000 1.0000
60.4800 333.0000 1.0000
60.5200 340.0000 1.0000
60.5600 292.0000 1.0000
60.6000 315.0000 1.0000
60.6400 319.0000 1.0000
60.6800 309.0000 1.0000
60.7200 297.0000 1.0000
60.7600 310.0000 1.0000
60.8000 317.0000 1.0000
60.8400 331.0000 1.0000
60.8800 303.0000 1.0000
60.9200 305.0000 1.0000
60.9600 319.0000 1.0000
61.0000 328.0000 1.0000
61.0400 322.0000 1.0000
61.0800 338.0000 1.0000
61.1200 354.0000 1.0000
61.1600 358.0000 1.0000
61.2000 403.0000 1.0000
61.2400 395.0000 1.0000
61.2800 418.0000 1.0000
61.3200 468.0000 1.0000
61.3600 504.0000 1.0000
61.4000 532.0000 1.0000
61.4400 601.0000 1.0000
61.4800 656.0000 1.0000
61.5200 657.0000 1.0000
61.5600 641.0000 1.0000
61.6000 648.0000 1.0000
61.6400 620.0000 1.0000
61.6800 627.0000 1.0000
61.7200 531.0000 1.0000
61.7600 547.0000 1.0000
61.8000 480.0000 1.0000
61.8400 450.0000 1.0000
61.8800 400.0000 1.0000
61.9200 393.0000 1.0000
61.9600 369.0000 1.0000
62.0000 394.0000 1.0000
62.0400 358.0000 1.0000
62.0800 343.0000 1.0000
62.1200 342.0000 1.0000
62.1600 371.0000 1.0000
62.2000 357.0000 1.0000
62.2400 327.0000 1.0000
62.2800 355.0000 1.0000
62.3200 332.0000 1.0000
62.3600 344.0000 1.0000
62.4000 364.0000 1.0000
62.4400 332.0000 1.0000
62.4800 337.0000 1.0000
62.5200 308.0000 1.0000
62.5600 348.0000 1.0000
62.6000 332.0000 1.0000
62.6400 330.0000 1.0000
62.6800 346.0000 1.0000
62.7200 314.0000 1.0000
62.7600 313.0000 1.0000
62.8000 332.0000 1.0000
62.8400 329.0000 1.0000
62.8800 339.0000 1.0000
62.9200 314.0000 1.0000
62.9600 338.0000 1.0000
63.0000 310.0000 1.0000
63.0400 325.0000 1.0000
63.0800 298.0000 1.0000
63.1200 331.0000 1.0000
63.1600 329.0000 1.0000
63.2000 311.0000 1.0000
63.2400 332.0000 1.0000
63.2800 306.0000 1.0000
63.3200 326.0000 1.0000
63.3600 348.0000 1.0000
63.4000 348.0000 1.0000
63.4400 323.0000 1.0000
63.4800 304.0000 1.0000
63.5200 301.0000 1.0000
63.5600 329.0000 1.0000
63.6000 328.0000 1.0000
63.6400 336.0000 1.0000
63.6800 323.0000 1.0000
63.7200 342.0000 1.0000
63.7600 332.0000 1.0000
63.8000 355.0000 1.0000
63.8400 337.0000 1.0000
63.8800 352.0000 1.0000
63.9200 420.0000 1.0000
63.9600 410.0000 1.0000
64.0000 384.0000 1.0000
64.0400 410.0000 1.0000
64.0800 365.0000 1.0000
64.1200 399.0000 1.0000
64.1600 358.0000 1.0000
64.2000 334.0000 1.0000
64.2400 363.0000 1.0000
64.2800 344.0000 1.0000
64.3200 327.0000 1.0000
64.3600 365.0000 1.0000
64.4000 308.0000 1.0000
64.4400 320.0000 1.0000
64.4800 335.0000 1.0000
64.5200 337.0000 1.0000
64.5600 331.0000 1.0000
64.6000 322.0000 1.0000
64.6400 338.0000 1.0000
64.6800 307.0000 1.0000
64.7200 322.0000 1.0000
64.7600 312.0000 1.0000
64.8000 331.0000 1.0000
64.8400 311.0000 1.0000
64.8800 307.0000 1.0000
64.9200 324.0000 1.0000
64.9600 340.0000 1.0000
65.0000 351.0000 1.0000
65.0400 363.0000 1.0000
65.0800 359.0000 1.0000
65.1200 341.0000 1.0000
65.1600 370.0000 1.0000
65.2000 390.0000 1.0000
65.2400 438.0000 1.0000
65.2800 503.0000 1.0000
65.3200 590.0000 1.0000
65.3600 648.0000 1.0000
65.4000 762.0000 1.0000
65.4400 938.0000 1.0000
65.4800 1046.0000 1.0000
65.5200 1134.0000 1.0000
65.5600 1128.0000 1.0000
65.6000 1037.0000 1.0000
65.6400 917.0000 1.0000
65.6800 951.0000 1.0000
65.7200 845.0000 1.0000
65.7600 694.0000 1.0000
65.8000 616.0000 1.0000
65.8400 509.0000 1.0000
65.8800 448.0000 1.0000
65.9200 437.0000 1.0000
65.9600 420.0000 1.0000
66.0000 364.0000 1.0000
66.0400 338.0000 1.0000
66.0800 374.0000 1.0000
66.1200 322.0000 1.0000
66.1600 299.0000 1.0000
66.2000 338.0000 1.0000
66.2400 332.0000 1.0000
66.2800 304.0000 1.0000
66.3200 294.0000 1.0000
66.3600 302.0000 1.0000
66.4000 308.0000 1.0000
66.4400 313.0000 1.0000
66.4800 311.0000 1.0000
66.5200 309.0000 1.0000
66.5600 279.0000 1.0000
66.6000 285.0000 1.0000
66.6400 321.0000 1.0000
66.6800 278.0000 1.0000
66.7200 287.0000 1.0000
66.7600 285.0000 1.0000
66.8000 313.0000 1.0000
66.8400 308.0000 1.0000
66.8800 290.0000 1.0000
66.9200 313.0000 1.0000
66.9600 292.0000 1.0000
67.0000 305.0000 1.0000
67.0400 253.0000 1.0000
67.0800 294.0000 1.0000
67.1200 257.0000 1.0000
67.1600 319.0000 1.0000
67.2000 282.0000 1.0000
67.2400 288.0000 1.0000
67.2800 291.0000 1.0000
67.3200 290.0000 1.0000
67.3600 279.0000 1.0000
67.4000 288.0000 1.0000
67.4400 286.0000 1.0000
67.4800 285.0000 1.0000
67.5200 265.0000 1.0000
67.5600 275.0000 1.0000
67.6000 288.0000 1.0000
67.6400 269.0000 1.0000
67.6800 311.0000 1.0000
67.7200 278.0000 1.0000
67.7600 284.0000 1.0000
67.8000 290.0000 1.0000
67.8400 272.0000 1.0000
67.8800 273.0000 1.0000
67.9200 257.0000 1.0000
67.9600 269.0000 1.0000
68.0000 305.0000 1.0000
68.0400 274.0000 1.0000
68.0800 303.0000 1.0000
68.1200 263.0000 1.0000
68.1600 272.0000 1.0000
68.2000 290.0000 1.0000
68.2400 305.0000 1.0000
68.2800 272.0000 1.0000
68.3200 301.0000 1.0000
68.3600 283.0000 1.0000
68.4000 301.0000 1.0000
68.4400 266.0000 1.0000
68.4800 264.0000 1.0000
68.5200 274.0000 1.0000
68.5600 288.0000 1.0000
68.6000 282.0000 1.0000
68.6400 258.0000 1.0000
68.6800 281.0000 1.0000
68.7200 268.0000 1.0000
68.7600 264.0000 1.0000
68.8000 290.0000 1.0000
68.8400 248.0000 1.0000
68.8800 294.0000 1.0000
68.9200 245.0000 1.0000
68.9600 298.0000 1.0000
69.0000 289.0000 1.0000
69.0400 263.0000 1.0000
69.0800 293.0000 1.0000
69.1200 296.0000 1.0000
69.1600 285.0000 1.0000
69.2000 257.0000 1.0000
69.2400 262.0000 1.0000
69.2800 263.0000 1.0000
69.3200 280.0000 1.0000
69.3600 250.0000 1.0000
69.4000 260.0000 1.0000
69.4400 261.0000 1.0000
69.4800 272.0000 1.0000
69.5200 283.0000 1.0000
69.5600 284.0000 1.0000
69.6000 266.0000 1.0000
69.6400 266.0000 1.0000
69.6800 254.0000 1.0000
69.7200 261.0000 1.0000
69.7600 269.0000 1.0000
69.8000 296.0000 1.0000
69.8400 270.0000 1.0000
69.8800 270.0000 1.0000
69.9200 275.0000 1.0000
69.9600 247.0000 1.0000
70.0000 261.0000 1.0000
*RAS_INT_END
*RAS_TEMPERATURE_START
*RAS_TEMPERATURE_END
*RAS_DATA_END