File: Data/Dataset1_Only_water/5_XRD/No_014_FS4_2.ras
*RAS_DATA_START
*RAS_HEADER_START
*DISP_FMT_X "%.2f"
*DISP_FMT_Y "%.0f"
*DISP_FULLSCALE "15380.0000000000"
*DISP_LINE_COLOR "255.0000000000"
*DISP_LINE_STYLE "0.0000000000"
*DISP_LINE_WIDTH "0.2500000000"
*DISP_NOTE "測定データ-5"
*DISP_OFFSET_Y "0.0000000000"
*DISP_PEAKSEARCH_UNIT_Y "cps"
*DISP_RANGE_BOTTOM "0.0000000000"
*DISP_RANGE_LEFT "20.0000000000"
*DISP_RANGE_LOGCUTOFF "0.0100000000"
*DISP_RANGE_RIGHT "70.0000000000"
*DISP_RANGE_TOP "15380.0000000000"
*DISP_SCALE_MODE_Y "0.0000000000"
*DISP_TAB_NAME "2θ/θ"
*DISP_TITLE_Y "強度"
*DISP_UNIT_Y "cps"
*DISP_WINDOW_NAME "MSG_MACROENGINE"
*FILE_COMMENT " "
*FILE_MD5 ""
*FILE_MEMO " "
*FILE_OPERATOR "Administrator"
*FILE_SAMPLE " "
*FILE_TYPE "RAS_RAW"
*FILE_USERGROUP "システムマネージャ"
*FILE_VERSION "1.0000000000"
*HW_ATTACHMENT_ID "ATT0025"
*HW_ATTACHMENT_NAME "標準|Standard"
*HW_COUNTER_ID-0 "CUT0025"
*HW_COUNTER_ID-1 "CUT0020"
*HW_COUNTER_ID-2 "CUT0020"
*HW_COUNTER_ID-3 "CSL0021"
*HW_COUNTER_ID-4 "CMC0021"
*HW_COUNTER_NAME-0 "D/teX Ultra|D/teX Ultra"
*HW_COUNTER_NAME-1 "None|None"
*HW_COUNTER_NAME-2 "None|None"
*HW_COUNTER_NAME-3 "BBM|BBM"
*HW_COUNTER_NAME-4 "検出器モノクロメータ|Detector monochromator"
*HW_COUNTER_SELECT_NAME "D/teX Ultra|D/teX Ultra"
*HW_GONIOMETER_ID "GON0023"
*HW_GONIOMETER_NAME "SmartLab|SmartLab"
*HW_GONIOMETER_RADIUS-0 "90.0"
*HW_GONIOMETER_RADIUS-1 "114.0"
*HW_GONIOMETER_RADIUS-2 "190.0"
*HW_GONIOMETER_RADIUS-3 "300.0"
*HW_GONIOMETER_RADIUS-4 "187.0"
*HW_GONIOMETER_RADIUS-5 "300.0"
*HW_GONIOMETER_RADIUS-6 "113.0"
*HW_GONIOMETER_RADIUS-7 "331.0"
*HW_I_OPT_ID-0 "CBO0021"
*HW_I_OPT_ID-1 "ICR0023"
*HW_I_OPT_ID-2 "ISL0021"
*HW_I_OPT_ID-3 "ISO0021"
*HW_I_OPT_ID-4 "IAD0021"
*HW_I_OPT_ID-5 "IPR0001"
*HW_I_OPT_NAME-0 "CBOユニット|CBO unit"
*HW_I_OPT_NAME-1 "標準入射光学ユニット|Standard incident optical unit"
*HW_I_OPT_NAME-2 "標準入射スリットボックス|Standard incident slit box"
*HW_I_OPT_NAME-3 "入射平行スリット|Incident parallel slit"
*HW_I_OPT_NAME-4 "長手制限スリット|Length limiting slit"
*HW_I_OPT_NAME-5 "None|None"
*HW_R_ATTENUATER_AUTOMODE "0"
*HW_R_OPT_ID-0 "RSS0021"
*HW_R_OPT_ID-1 "RCR0023"
*HW_R_OPT_ID-2 "RSO0021"
*HW_R_OPT_ID-3 "RRS0021"
*HW_R_OPT_ID-4 "ATN0021"
*HW_R_OPT_ID-5 "RFL0021"
*HW_R_OPT_ID-6 "RAD0021"
*HW_R_OPT_NAME-0 "標準受光スリットボックス1|Standard receiving slit box # 1"
*HW_R_OPT_NAME-1 "標準受光光学ユニット1|Standard receiving unit # 1"
*HW_R_OPT_NAME-2 "標準受光光学ユニット2|Standard receiving optical unit # 2"
*HW_R_OPT_NAME-3 "標準受光スリットボックス2|Standard receiving slit box # 2"
*HW_R_OPT_NAME-4 "標準アッテネータ|Standard Attenuator"
*HW_R_OPT_NAME-5 "Cu Kβ|Cu K-beta"
*HW_R_OPT_NAME-6 "調整用受光スリット|Alignment receiving slit"
*HW_SAMPLE_HOLDER_ID "SMP0023"
*HW_SAMPLE_HOLDER_NAME "標準Zステージ|Standard Z stage"
*HW_XG_CURRENT_MAX "50"
*HW_XG_CURRENT_MIN "2"
*HW_XG_CURRENT_RESOLUTION "1"
*HW_XG_CURRENT_UNIT "mA"
*HW_XG_FOCUS "1mm x 10mm"
*HW_XG_FOCUS_TYPE "Normal"
*HW_XG_ID ""
*HW_XG_NAME "3kW 封入管(ID:1200)|3kW Sealed tube(ID:1200)"
*HW_XG_TARGET_ATOMIC_NUMBER "29.0000000000"
*HW_XG_TARGET_NAME "Cu"
*HW_XG_TYPE "Hermetic"
*HW_XG_VOLTAGE_MAX "60"
*HW_XG_VOLTAGE_MIN "20"
*HW_XG_VOLTAGE_RESOLUTION "1"
*HW_XG_VOLTAGE_UNIT "kV"
*HW_XG_WATT_MAX "1.500"
*HW_XG_WATT_UNIT "kW"
*HW_XG_WAVE_LENGTH_ALPHA1 "1.540593"
*HW_XG_WAVE_LENGTH_ALPHA2 "1.544414"
*HW_XG_WAVE_LENGTH_BETA "1.392250"
*MEAS_COND_AXIS_NAME-0 "2θ/θ"
*MEAS_COND_AXIS_NAME-1 "2θ"
*MEAS_COND_AXIS_NAME-2 "ω"
*MEAS_COND_AXIS_NAME-3 "Z"
*MEAS_COND_AXIS_NAME-4 "2θ/ω"
*MEAS_COND_AXIS_NAME-5 "θs"
*MEAS_COND_AXIS_NAME-6 "θd"
*MEAS_COND_AXIS_NAME-7 "Ts"
*MEAS_COND_AXIS_NAME-8 "CBO選択スリット"
*MEAS_COND_AXIS_NAME-9 "M"
*MEAS_COND_AXIS_NAME-10 "入射平行スリット"
*MEAS_COND_AXIS_NAME-11 "入射スリット"
*MEAS_COND_AXIS_NAME-12 ""
*MEAS_COND_AXIS_NAME-13 "Zs"
*MEAS_COND_AXIS_NAME-14 "入射光学素子"
*MEAS_COND_AXIS_NAME-15 "長手制限スリット"
*MEAS_COND_AXIS_NAME-16 "センタースリット"
*MEAS_COND_AXIS_NAME-17 "フィルター"
*MEAS_COND_AXIS_NAME-18 "受光スリット1"
*MEAS_COND_AXIS_NAME-19 "受光スリット2"
*MEAS_COND_AXIS_NAME-20 "受光光学素子"
*MEAS_COND_AXIS_NAME-21 "受光平行スリット"
*MEAS_COND_AXIS_NAME-22 "調整用受光スリット"
*MEAS_COND_AXIS_NAME-23 ""
*MEAS_COND_AXIS_NAME-24 ""
*MEAS_COND_AXIS_NAME-25 "Zd"
*MEAS_COND_AXIS_NAME-26 "アッテネータ"
*MEAS_COND_AXIS_NAME-27 "検出器モノクロメータ"
*MEAS_COND_AXIS_NAME-28 "モノクロメータスリット"
*MEAS_COND_AXIS_NAME-29 "プライマリビーム"
*MEAS_COND_AXIS_NAME-30 "PHA"
*MEAS_COND_AXIS_NAME_INTERNAL-0 "TwoThetaTheta"
*MEAS_COND_AXIS_NAME_INTERNAL-1 "TwoTheta"
*MEAS_COND_AXIS_NAME_INTERNAL-2 "Omega"
*MEAS_COND_AXIS_NAME_INTERNAL-3 "Z"
*MEAS_COND_AXIS_NAME_INTERNAL-4 "TwoThetaOmega"
*MEAS_COND_AXIS_NAME_INTERNAL-5 "ThetaS"
*MEAS_COND_AXIS_NAME_INTERNAL-6 "ThetaD"
*MEAS_COND_AXIS_NAME_INTERNAL-7 "Ts"
*MEAS_COND_AXIS_NAME_INTERNAL-8 "CBO"
*MEAS_COND_AXIS_NAME_INTERNAL-9 "CBO-M"
*MEAS_COND_AXIS_NAME_INTERNAL-10 "IncidentSollerSlit"
*MEAS_COND_AXIS_NAME_INTERNAL-11 "IncidentSlitBox"
*MEAS_COND_AXIS_NAME_INTERNAL-12 "IncidentSlitBox-_Axis"
*MEAS_COND_AXIS_NAME_INTERNAL-13 "Zs"
*MEAS_COND_AXIS_NAME_INTERNAL-14 "IncidentMonochromator"
*MEAS_COND_AXIS_NAME_INTERNAL-15 "IncidentAxdSlit"
*MEAS_COND_AXIS_NAME_INTERNAL-16 "CenterSlit"
*MEAS_COND_AXIS_NAME_INTERNAL-17 "Filter"
*MEAS_COND_AXIS_NAME_INTERNAL-18 "ReceivingSlitBox1"
*MEAS_COND_AXIS_NAME_INTERNAL-19 "ReceivingSlitBox2"
*MEAS_COND_AXIS_NAME_INTERNAL-20 "ReceivingOptics"
*MEAS_COND_AXIS_NAME_INTERNAL-21 "ReceivingSollerSlit"
*MEAS_COND_AXIS_NAME_INTERNAL-22 "ReceivingAxdSlit"
*MEAS_COND_AXIS_NAME_INTERNAL-23 "ReceivingSlitBox1-_Axis"
*MEAS_COND_AXIS_NAME_INTERNAL-24 "ReceivingSlitBox2-_Axis"
*MEAS_COND_AXIS_NAME_INTERNAL-25 "ReceivingSlitBox2-Zd"
*MEAS_COND_AXIS_NAME_INTERNAL-26 "Attenuator"
*MEAS_COND_AXIS_NAME_INTERNAL-27 "CounterMonochromator"
*MEAS_COND_AXIS_NAME_INTERNAL-28 "CounterSlit"
*MEAS_COND_AXIS_NAME_INTERNAL-29 "IncidentPrimary"
*MEAS_COND_AXIS_NAME_INTERNAL-30 "PHA"
*MEAS_COND_AXIS_NAME_MAGICNO-0 "83951616.0000000000"
*MEAS_COND_AXIS_NAME_MAGICNO-1 "268632064.0000000000"
*MEAS_COND_AXIS_NAME_MAGICNO-2 "268500992.0000000000"
*MEAS_COND_AXIS_NAME_MAGICNO-3 "285278208.0000000000"
*MEAS_COND_AXIS_NAME_MAGICNO-4 "83951616.0000000000"
*MEAS_COND_AXIS_NAME_MAGICNO-5 "131072.0000000000"
*MEAS_COND_AXIS_NAME_MAGICNO-6 "131072.0000000000"
*MEAS_COND_AXIS_NAME_MAGICNO-7 "318898176.0000000000"
*MEAS_COND_AXIS_NAME_MAGICNO-8 "20971521.0000000000"
*MEAS_COND_AXIS_NAME_MAGICNO-9 "285343744.0000000000"
*MEAS_COND_AXIS_NAME_MAGICNO-10 "20971521.0000000000"
*MEAS_COND_AXIS_NAME_MAGICNO-11 "22020097.0000000000"
*MEAS_COND_AXIS_NAME_MAGICNO-12 "25165824.0000000000"
*MEAS_COND_AXIS_NAME_MAGICNO-13 "318898176.0000000000"
*MEAS_COND_AXIS_NAME_MAGICNO-14 "1.0000000000"
*MEAS_COND_AXIS_NAME_MAGICNO-15 "20971521.0000000000"
*MEAS_COND_AXIS_NAME_MAGICNO-16 "20971521.0000000000"
*MEAS_COND_AXIS_NAME_MAGICNO-17 "20971521.0000000000"
*MEAS_COND_AXIS_NAME_MAGICNO-18 "23068673.0000000000"
*MEAS_COND_AXIS_NAME_MAGICNO-19 "23068673.0000000000"
*MEAS_COND_AXIS_NAME_MAGICNO-20 "20971521.0000000000"
*MEAS_COND_AXIS_NAME_MAGICNO-21 "20971521.0000000000"
*MEAS_COND_AXIS_NAME_MAGICNO-22 "20971521.0000000000"
*MEAS_COND_AXIS_NAME_MAGICNO-23 "25165824.0000000000"
*MEAS_COND_AXIS_NAME_MAGICNO-24 "25165824.0000000000"
*MEAS_COND_AXIS_NAME_MAGICNO-25 "285343744.0000000000"
*MEAS_COND_AXIS_NAME_MAGICNO-26 "17301505.0000000000"
*MEAS_COND_AXIS_NAME_MAGICNO-27 "20971521.0000000000"
*MEAS_COND_AXIS_NAME_MAGICNO-28 "20971521.0000000000"
*MEAS_COND_AXIS_NAME_MAGICNO-29 "20971521.0000000000"
*MEAS_COND_AXIS_NAME_MAGICNO-30 "0.0000000000"
*MEAS_COND_AXIS_OFFSET-0 "-"
*MEAS_COND_AXIS_OFFSET-1 "-0.1081000000"
*MEAS_COND_AXIS_OFFSET-2 "0.3758000000"
*MEAS_COND_AXIS_OFFSET-3 "-"
*MEAS_COND_AXIS_OFFSET-4 "-"
*MEAS_COND_AXIS_OFFSET-5 "0.3758000000"
*MEAS_COND_AXIS_OFFSET-6 "-0.4839000000"
*MEAS_COND_AXIS_OFFSET-7 "-"
*MEAS_COND_AXIS_OFFSET-8 "-"
*MEAS_COND_AXIS_OFFSET-9 "-"
*MEAS_COND_AXIS_OFFSET-10 "-"
*MEAS_COND_AXIS_OFFSET-11 "-"
*MEAS_COND_AXIS_OFFSET-12 "-"
*MEAS_COND_AXIS_OFFSET-13 "-"
*MEAS_COND_AXIS_OFFSET-14 "-"
*MEAS_COND_AXIS_OFFSET-15 "-"
*MEAS_COND_AXIS_OFFSET-16 "-"
*MEAS_COND_AXIS_OFFSET-17 "-"
*MEAS_COND_AXIS_OFFSET-18 "-"
*MEAS_COND_AXIS_OFFSET-19 "-"
*MEAS_COND_AXIS_OFFSET-20 "-"
*MEAS_COND_AXIS_OFFSET-21 "-"
*MEAS_COND_AXIS_OFFSET-22 "-"
*MEAS_COND_AXIS_OFFSET-23 "-"
*MEAS_COND_AXIS_OFFSET-24 "-"
*MEAS_COND_AXIS_OFFSET-25 "-"
*MEAS_COND_AXIS_OFFSET-26 "-"
*MEAS_COND_AXIS_OFFSET-27 "-"
*MEAS_COND_AXIS_OFFSET-28 "-"
*MEAS_COND_AXIS_OFFSET-29 "-"
*MEAS_COND_AXIS_OFFSET-30 "-"
*MEAS_COND_AXIS_POSITION-0 "0.0000000000"
*MEAS_COND_AXIS_POSITION-1 "0.0000000000"
*MEAS_COND_AXIS_POSITION-2 "0.0000000000"
*MEAS_COND_AXIS_POSITION-3 "-0.5500000000"
*MEAS_COND_AXIS_POSITION-4 "0.0000000000"
*MEAS_COND_AXIS_POSITION-5 "0.0000000000"
*MEAS_COND_AXIS_POSITION-6 "0.0000000000"
*MEAS_COND_AXIS_POSITION-7 "-0.4278800000"
*MEAS_COND_AXIS_POSITION-8 "BB"
*MEAS_COND_AXIS_POSITION-9 "0.0000000000"
*MEAS_COND_AXIS_POSITION-10 "Soller_slit_5.0deg"
*MEAS_COND_AXIS_POSITION-11 "2/3deg"
*MEAS_COND_AXIS_POSITION-12 "2.2088000000"
*MEAS_COND_AXIS_POSITION-13 "-0.4140600000"
*MEAS_COND_AXIS_POSITION-14 "0.0000000000"
*MEAS_COND_AXIS_POSITION-15 "10.0mm"
*MEAS_COND_AXIS_POSITION-16 "None"
*MEAS_COND_AXIS_POSITION-17 "Cu_K-beta"
*MEAS_COND_AXIS_POSITION-18 "13.000mm"
*MEAS_COND_AXIS_POSITION-19 "13.000mm"
*MEAS_COND_AXIS_POSITION-20 "No_unit"
*MEAS_COND_AXIS_POSITION-21 "Soller_slit_5.0deg"
*MEAS_COND_AXIS_POSITION-22 "None"
*MEAS_COND_AXIS_POSITION-23 "13.0000000000"
*MEAS_COND_AXIS_POSITION-24 "13.0000000000"
*MEAS_COND_AXIS_POSITION-25 "0.0109400000"
*MEAS_COND_AXIS_POSITION-26 "Open"
*MEAS_COND_AXIS_POSITION-27 "None"
*MEAS_COND_AXIS_POSITION-28 "None"
*MEAS_COND_AXIS_POSITION-29 "None"
*MEAS_COND_AXIS_POSITION-30 "38.0000000000"
*MEAS_COND_AXIS_UNIT-0 "deg"
*MEAS_COND_AXIS_UNIT-1 "deg"
*MEAS_COND_AXIS_UNIT-2 "deg"
*MEAS_COND_AXIS_UNIT-3 "mm"
*MEAS_COND_AXIS_UNIT-4 "deg"
*MEAS_COND_AXIS_UNIT-5 "deg"
*MEAS_COND_AXIS_UNIT-6 "deg"
*MEAS_COND_AXIS_UNIT-7 "mm"
*MEAS_COND_AXIS_UNIT-8 ""
*MEAS_COND_AXIS_UNIT-9 "pulse"
*MEAS_COND_AXIS_UNIT-10 ""
*MEAS_COND_AXIS_UNIT-11 ""
*MEAS_COND_AXIS_UNIT-12 "mm"
*MEAS_COND_AXIS_UNIT-13 "mm"
*MEAS_COND_AXIS_UNIT-14 ""
*MEAS_COND_AXIS_UNIT-15 ""
*MEAS_COND_AXIS_UNIT-16 ""
*MEAS_COND_AXIS_UNIT-17 ""
*MEAS_COND_AXIS_UNIT-18 ""
*MEAS_COND_AXIS_UNIT-19 ""
*MEAS_COND_AXIS_UNIT-20 ""
*MEAS_COND_AXIS_UNIT-21 ""
*MEAS_COND_AXIS_UNIT-22 ""
*MEAS_COND_AXIS_UNIT-23 "mm"
*MEAS_COND_AXIS_UNIT-24 "mm"
*MEAS_COND_AXIS_UNIT-25 "mm"
*MEAS_COND_AXIS_UNIT-26 ""
*MEAS_COND_AXIS_UNIT-27 ""
*MEAS_COND_AXIS_UNIT-28 ""
*MEAS_COND_AXIS_UNIT-29 ""
*MEAS_COND_AXIS_UNIT-30 "div"
*MEAS_COND_COUNTER_CNTLOSS_CORR "0.0000000000"
*MEAS_COND_COUNTER_PHABASE "38.0000000000"
*MEAS_COND_COUNTER_PHAWINDOW "16.0000000000"
*MEAS_COND_COUNTER_PHA_UNIT "div"
*MEAS_COND_COUNTER_TAUDIFF "30.0000000000"
*MEAS_COND_COUNTER_TAUINT "0.0000000000"
*MEAS_COND_IRRADIATION_MODE "OFF"
*MEAS_COND_IRRADIATION_WIDTH ""
*MEAS_COND_OPT_ATTR "集中法"
*MEAS_COND_OPT_NAME "@集中法"
*MEAS_COND_UNSYMMETRIC_MODE "OFF"
*MEAS_COND_XG_CURRENT "30.0000000000"
*MEAS_COND_XG_VOLTAGE "40.0000000000"
*MEAS_COND_XG_WAVE_TYPE "Ka"
*MEAS_DATA_COUNT "5001.0000000000"
*MEAS_SCAN_AXIS_X "2θ/θ"
*MEAS_SCAN_AXIS_X_INTERNAL "TwoThetaTheta"
*MEAS_SCAN_END_TIME "07/06/21 17:53:17"
*MEAS_SCAN_MODE "CONTINUOUS"
*MEAS_SCAN_MONITOR "0"
*MEAS_SCAN_RESOLUTION_X "0.0002"
*MEAS_SCAN_SPEED "1.0"
*MEAS_SCAN_SPEED_UNIT "deg/min"
*MEAS_SCAN_START "20.0000000000"
*MEAS_SCAN_START_TIME "07/06/21 17:00:24"
*MEAS_SCAN_STEP "0.0100000000"
*MEAS_SCAN_STOP "70.0000000000"
*MEAS_SCAN_UNIT_X "deg"
*MEAS_SCAN_UNIT_Y "counts"
*RAS_HEADER_END
*RAS_INT_START
20.0000 1526.0000 1.0000
20.0400 1516.0000 1.0000
20.0800 1519.0000 1.0000
20.1200 1557.0000 1.0000
20.1600 1497.0000 1.0000
20.2000 1571.0000 1.0000
20.2400 1589.0000 1.0000
20.2800 1595.0000 1.0000
20.3200 1509.0000 1.0000
20.3600 1479.0000 1.0000
20.4000 1520.0000 1.0000
20.4400 1521.0000 1.0000
20.4800 1577.0000 1.0000
20.5200 1569.0000 1.0000
20.5600 1518.0000 1.0000
20.6000 1511.0000 1.0000
20.6400 1535.0000 1.0000
20.6800 1630.0000 1.0000
20.7200 1575.0000 1.0000
20.7600 1556.0000 1.0000
20.8000 1548.0000 1.0000
20.8400 1567.0000 1.0000
20.8800 1505.0000 1.0000
20.9200 1594.0000 1.0000
20.9600 1532.0000 1.0000
21.0000 1536.0000 1.0000
21.0400 1669.0000 1.0000
21.0800 1516.0000 1.0000
21.1200 1558.0000 1.0000
21.1600 1569.0000 1.0000
21.2000 1487.0000 1.0000
21.2400 1576.0000 1.0000
21.2800 1559.0000 1.0000
21.3200 1584.0000 1.0000
21.3600 1572.0000 1.0000
21.4000 1536.0000 1.0000
21.4400 1515.0000 1.0000
21.4800 1546.0000 1.0000
21.5200 1578.0000 1.0000
21.5600 1486.0000 1.0000
21.6000 1504.0000 1.0000
21.6400 1549.0000 1.0000
21.6800 1438.0000 1.0000
21.7200 1591.0000 1.0000
21.7600 1554.0000 1.0000
21.8000 1509.0000 1.0000
21.8400 1554.0000 1.0000
21.8800 1515.0000 1.0000
21.9200 1564.0000 1.0000
21.9600 1538.0000 1.0000
22.0000 1504.0000 1.0000
22.0400 1530.0000 1.0000
22.0800 1574.0000 1.0000
22.1200 1539.0000 1.0000
22.1600 1611.0000 1.0000
22.2000 1580.0000 1.0000
22.2400 1545.0000 1.0000
22.2800 1550.0000 1.0000
22.3200 1576.0000 1.0000
22.3600 1603.0000 1.0000
22.4000 1540.0000 1.0000
22.4400 1514.0000 1.0000
22.4800 1505.0000 1.0000
22.5200 1493.0000 1.0000
22.5600 1505.0000 1.0000
22.6000 1546.0000 1.0000
22.6400 1536.0000 1.0000
22.6800 1620.0000 1.0000
22.7200 1547.0000 1.0000
22.7600 1556.0000 1.0000
22.8000 1508.0000 1.0000
22.8400 1554.0000 1.0000
22.8800 1571.0000 1.0000
22.9200 1541.0000 1.0000
22.9600 1534.0000 1.0000
23.0000 1555.0000 1.0000
23.0400 1583.0000 1.0000
23.0800 1532.0000 1.0000
23.1200 1548.0000 1.0000
23.1600 1566.0000 1.0000
23.2000 1532.0000 1.0000
23.2400 1579.0000 1.0000
23.2800 1576.0000 1.0000
23.3200 1561.0000 1.0000
23.3600 1559.0000 1.0000
23.4000 1597.0000 1.0000
23.4400 1502.0000 1.0000
23.4800 1588.0000 1.0000
23.5200 1542.0000 1.0000
23.5600 1563.0000 1.0000
23.6000 1584.0000 1.0000
23.6400 1532.0000 1.0000
23.6800 1561.0000 1.0000
23.7200 1577.0000 1.0000
23.7600 1617.0000 1.0000
23.8000 1559.0000 1.0000
23.8400 1539.0000 1.0000
23.8800 1612.0000 1.0000
23.9200 1586.0000 1.0000
23.9600 1581.0000 1.0000
24.0000 1611.0000 1.0000
24.0400 1563.0000 1.0000
24.0800 1591.0000 1.0000
24.1200 1555.0000 1.0000
24.1600 1640.0000 1.0000
24.2000 1521.0000 1.0000
24.2400 1589.0000 1.0000
24.2800 1650.0000 1.0000
24.3200 1595.0000 1.0000
24.3600 1580.0000 1.0000
24.4000 1594.0000 1.0000
24.4400 1624.0000 1.0000
24.4800 1587.0000 1.0000
24.5200 1603.0000 1.0000
24.5600 1651.0000 1.0000
24.6000 1548.0000 1.0000
24.6400 1600.0000 1.0000
24.6800 1578.0000 1.0000
24.7200 1611.0000 1.0000
24.7600 1650.0000 1.0000
24.8000 1618.0000 1.0000
24.8400 1654.0000 1.0000
24.8800 1685.0000 1.0000
24.9200 1584.0000 1.0000
24.9600 1617.0000 1.0000
25.0000 1691.0000 1.0000
25.0400 1662.0000 1.0000
25.0800 1582.0000 1.0000
25.1200 1560.0000 1.0000
25.1600 1678.0000 1.0000
25.2000 1580.0000 1.0000
25.2400 1579.0000 1.0000
25.2800 1694.0000 1.0000
25.3200 1680.0000 1.0000
25.3600 1597.0000 1.0000
25.4000 1603.0000 1.0000
25.4400 1604.0000 1.0000
25.4800 1645.0000 1.0000
25.5200 1719.0000 1.0000
25.5600 1673.0000 1.0000
25.6000 1643.0000 1.0000
25.6400 1604.0000 1.0000
25.6800 1580.0000 1.0000
25.7200 1616.0000 1.0000
25.7600 1637.0000 1.0000
25.8000 1597.0000 1.0000
25.8400 1678.0000 1.0000
25.8800 1574.0000 1.0000
25.9200 1663.0000 1.0000
25.9600 1606.0000 1.0000
26.0000 1579.0000 1.0000
26.0400 1624.0000 1.0000
26.0800 1628.0000 1.0000
26.1200 1596.0000 1.0000
26.1600 1639.0000 1.0000
26.2000 1592.0000 1.0000
26.2400 1619.0000 1.0000
26.2800 1590.0000 1.0000
26.3200 1607.0000 1.0000
26.3600 1642.0000 1.0000
26.4000 1749.0000 1.0000
26.4400 1707.0000 1.0000
26.4800 1727.0000 1.0000
26.5200 1661.0000 1.0000
26.5600 1785.0000 1.0000
26.6000 1650.0000 1.0000
26.6400 1758.0000 1.0000
26.6800 1679.0000 1.0000
26.7200 1729.0000 1.0000
26.7600 1769.0000 1.0000
26.8000 1801.0000 1.0000
26.8400 1826.0000 1.0000
26.8800 1769.0000 1.0000
26.9200 1944.0000 1.0000
26.9600 1996.0000 1.0000
27.0000 2100.0000 1.0000
27.0400 2319.0000 1.0000
27.0800 2542.0000 1.0000
27.1200 2839.0000 1.0000
27.1600 3433.0000 1.0000
27.2000 4034.0000 1.0000
27.2400 5075.0000 1.0000
27.2800 5852.0000 1.0000
27.3200 6197.0000 1.0000
27.3600 5826.0000 1.0000
27.4000 4827.0000 1.0000
27.4400 3855.0000 1.0000
27.4800 3237.0000 1.0000
27.5200 2754.0000 1.0000
27.5600 2530.0000 1.0000
27.6000 2208.0000 1.0000
27.6400 2205.0000 1.0000
27.6800 2024.0000 1.0000
27.7200 1968.0000 1.0000
27.7600 1892.0000 1.0000
27.8000 1796.0000 1.0000
27.8400 1802.0000 1.0000
27.8800 1727.0000 1.0000
27.9200 1667.0000 1.0000
27.9600 1721.0000 1.0000
28.0000 1725.0000 1.0000
28.0400 1640.0000 1.0000
28.0800 1690.0000 1.0000
28.1200 1631.0000 1.0000
28.1600 1622.0000 1.0000
28.2000 1588.0000 1.0000
28.2400 1591.0000 1.0000
28.2800 1622.0000 1.0000
28.3200 1596.0000 1.0000
28.3600 1605.0000 1.0000
28.4000 1599.0000 1.0000
28.4400 1621.0000 1.0000
28.4800 1557.0000 1.0000
28.5200 1638.0000 1.0000
28.5600 1614.0000 1.0000
28.6000 1553.0000 1.0000
28.6400 1604.0000 1.0000
28.6800 1607.0000 1.0000
28.7200 1564.0000 1.0000
28.7600 1514.0000 1.0000
28.8000 1559.0000 1.0000
28.8400 1581.0000 1.0000
28.8800 1576.0000 1.0000
28.9200 1612.0000 1.0000
28.9600 1529.0000 1.0000
29.0000 1578.0000 1.0000
29.0400 1516.0000 1.0000
29.0800 1579.0000 1.0000
29.1200 1553.0000 1.0000
29.1600 1540.0000 1.0000
29.2000 1558.0000 1.0000
29.2400 1582.0000 1.0000
29.2800 1543.0000 1.0000
29.3200 1509.0000 1.0000
29.3600 1538.0000 1.0000
29.4000 1505.0000 1.0000
29.4400 1530.0000 1.0000
29.4800 1571.0000 1.0000
29.5200 1504.0000 1.0000
29.5600 1477.0000 1.0000
29.6000 1548.0000 1.0000
29.6400 1562.0000 1.0000
29.6800 1587.0000 1.0000
29.7200 1561.0000 1.0000
29.7600 1485.0000 1.0000
29.8000 1554.0000 1.0000
29.8400 1549.0000 1.0000
29.8800 1530.0000 1.0000
29.9200 1575.0000 1.0000
29.9600 1633.0000 1.0000
30.0000 1544.0000 1.0000
30.0400 1516.0000 1.0000
30.0800 1575.0000 1.0000
30.1200 1527.0000 1.0000
30.1600 1494.0000 1.0000
30.2000 1549.0000 1.0000
30.2400 1536.0000 1.0000
30.2800 1558.0000 1.0000
30.3200 1543.0000 1.0000
30.3600 1567.0000 1.0000
30.4000 1525.0000 1.0000
30.4400 1482.0000 1.0000
30.4800 1501.0000 1.0000
30.5200 1459.0000 1.0000
30.5600 1529.0000 1.0000
30.6000 1512.0000 1.0000
30.6400 1568.0000 1.0000
30.6800 1503.0000 1.0000
30.7200 1536.0000 1.0000
30.7600 1529.0000 1.0000
30.8000 1477.0000 1.0000
30.8400 1456.0000 1.0000
30.8800 1408.0000 1.0000
30.9200 1433.0000 1.0000
30.9600 1480.0000 1.0000
31.0000 1455.0000 1.0000
31.0400 1505.0000 1.0000
31.0800 1499.0000 1.0000
31.1200 1510.0000 1.0000
31.1600 1513.0000 1.0000
31.2000 1472.0000 1.0000
31.2400 1535.0000 1.0000
31.2800 1533.0000 1.0000
31.3200 1489.0000 1.0000
31.3600 1490.0000 1.0000
31.4000 1492.0000 1.0000
31.4400 1518.0000 1.0000
31.4800 1490.0000 1.0000
31.5200 1520.0000 1.0000
31.5600 1481.0000 1.0000
31.6000 1463.0000 1.0000
31.6400 1432.0000 1.0000
31.6800 1488.0000 1.0000
31.7200 1466.0000 1.0000
31.7600 1507.0000 1.0000
31.8000 1521.0000 1.0000
31.8400 1492.0000 1.0000
31.8800 1476.0000 1.0000
31.9200 1493.0000 1.0000
31.9600 1440.0000 1.0000
32.0000 1478.0000 1.0000
32.0400 1483.0000 1.0000
32.0800 1439.0000 1.0000
32.1200 1523.0000 1.0000
32.1600 1466.0000 1.0000
32.2000 1422.0000 1.0000
32.2400 1391.0000 1.0000
32.2800 1451.0000 1.0000
32.3200 1442.0000 1.0000
32.3600 1406.0000 1.0000
32.4000 1421.0000 1.0000
32.4400 1431.0000 1.0000
32.4800 1442.0000 1.0000
32.5200 1417.0000 1.0000
32.5600 1369.0000 1.0000
32.6000 1353.0000 1.0000
32.6400 1403.0000 1.0000
32.6800 1404.0000 1.0000
32.7200 1397.0000 1.0000
32.7600 1410.0000 1.0000
32.8000 1383.0000 1.0000
32.8400 1428.0000 1.0000
32.8800 1381.0000 1.0000
32.9200 1436.0000 1.0000
32.9600 1375.0000 1.0000
33.0000 1442.0000 1.0000
33.0400 1399.0000 1.0000
33.0800 1394.0000 1.0000
33.1200 1417.0000 1.0000
33.1600 1368.0000 1.0000
33.2000 1347.0000 1.0000
33.2400 1374.0000 1.0000
33.2800 1409.0000 1.0000
33.3200 1412.0000 1.0000
33.3600 1401.0000 1.0000
33.4000 1417.0000 1.0000
33.4400 1283.0000 1.0000
33.4800 1451.0000 1.0000
33.5200 1407.0000 1.0000
33.5600 1387.0000 1.0000
33.6000 1385.0000 1.0000
33.6400 1372.0000 1.0000
33.6800 1424.0000 1.0000
33.7200 1418.0000 1.0000
33.7600 1461.0000 1.0000
33.8000 1482.0000 1.0000
33.8400 1496.0000 1.0000
33.8800 1575.0000 1.0000
33.9200 1613.0000 1.0000
33.9600 1655.0000 1.0000
34.0000 1628.0000 1.0000
34.0400 1551.0000 1.0000
34.0800 1571.0000 1.0000
34.1200 1523.0000 1.0000
34.1600 1609.0000 1.0000
34.2000 1621.0000 1.0000
34.2400 1642.0000 1.0000
34.2800 1816.0000 1.0000
34.3200 1865.0000 1.0000
34.3600 2124.0000 1.0000
34.4000 2410.0000 1.0000
34.4400 2724.0000 1.0000
34.4800 3125.0000 1.0000
34.5200 3086.0000 1.0000
34.5600 2985.0000 1.0000
34.6000 2693.0000 1.0000
34.6400 2272.0000 1.0000
34.6800 2070.0000 1.0000
34.7200 1870.0000 1.0000
34.7600 1723.0000 1.0000
34.8000 1654.0000 1.0000
34.8400 1581.0000 1.0000
34.8800 1533.0000 1.0000
34.9200 1446.0000 1.0000
34.9600 1417.0000 1.0000
35.0000 1374.0000 1.0000
35.0400 1314.0000 1.0000
35.0800 1379.0000 1.0000
35.1200 1304.0000 1.0000
35.1600 1329.0000 1.0000
35.2000 1289.0000 1.0000
35.2400 1278.0000 1.0000
35.2800 1313.0000 1.0000
35.3200 1256.0000 1.0000
35.3600 1222.0000 1.0000
35.4000 1226.0000 1.0000
35.4400 1256.0000 1.0000
35.4800 1217.0000 1.0000
35.5200 1221.0000 1.0000
35.5600 1280.0000 1.0000
35.6000 1208.0000 1.0000
35.6400 1247.0000 1.0000
35.6800 1202.0000 1.0000
35.7200 1189.0000 1.0000
35.7600 1194.0000 1.0000
35.8000 1236.0000 1.0000
35.8400 1167.0000 1.0000
35.8800 1224.0000 1.0000
35.9200 1205.0000 1.0000
35.9600 1168.0000 1.0000
36.0000 1241.0000 1.0000
36.0400 1255.0000 1.0000
36.0800 1178.0000 1.0000
36.1200 1273.0000 1.0000
36.1600 1238.0000 1.0000
36.2000 1373.0000 1.0000
36.2400 1391.0000 1.0000
36.2800 1515.0000 1.0000
36.3200 1739.0000 1.0000
36.3600 2000.0000 1.0000
36.4000 2344.0000 1.0000
36.4400 2280.0000 1.0000
36.4800 2141.0000 1.0000
36.5200 1830.0000 1.0000
36.5600 1543.0000 1.0000
36.6000 1393.0000 1.0000
36.6400 1289.0000 1.0000
36.6800 1283.0000 1.0000
36.7200 1157.0000 1.0000
36.7600 1182.0000 1.0000
36.8000 1174.0000 1.0000
36.8400 1159.0000 1.0000
36.8800 1134.0000 1.0000
36.9200 1113.0000 1.0000
36.9600 1069.0000 1.0000
37.0000 1063.0000 1.0000
37.0400 1089.0000 1.0000
37.0800 1129.0000 1.0000
37.1200 1088.0000 1.0000
37.1600 1109.0000 1.0000
37.2000 1150.0000 1.0000
37.2400 1119.0000 1.0000
37.2800 1101.0000 1.0000
37.3200 1102.0000 1.0000
37.3600 1119.0000 1.0000
37.4000 1118.0000 1.0000
37.4400 1110.0000 1.0000
37.4800 1090.0000 1.0000
37.5200 1112.0000 1.0000
37.5600 1053.0000 1.0000
37.6000 1132.0000 1.0000
37.6400 1087.0000 1.0000
37.6800 1057.0000 1.0000
37.7200 1101.0000 1.0000
37.7600 1108.0000 1.0000
37.8000 1063.0000 1.0000
37.8400 1157.0000 1.0000
37.8800 1176.0000 1.0000
37.9200 1181.0000 1.0000
37.9600 1174.0000 1.0000
38.0000 1238.0000 1.0000
38.0400 1229.0000 1.0000
38.0800 1265.0000 1.0000
38.1200 1239.0000 1.0000
38.1600 1359.0000 1.0000
38.2000 1501.0000 1.0000
38.2400 1664.0000 1.0000
38.2800 1898.0000 1.0000
38.3200 2209.0000 1.0000
38.3600 2764.0000 1.0000
38.4000 3400.0000 1.0000
38.4400 4422.0000 1.0000
38.4800 5844.0000 1.0000
38.5200 7052.0000 1.0000
38.5600 7574.0000 1.0000
38.6000 7376.0000 1.0000
38.6400 6352.0000 1.0000
38.6800 5122.0000 1.0000
38.7200 3950.0000 1.0000
38.7600 2986.0000 1.0000
38.8000 2371.0000 1.0000
38.8400 1871.0000 1.0000
38.8800 1678.0000 1.0000
38.9200 1486.0000 1.0000
38.9600 1359.0000 1.0000
39.0000 1271.0000 1.0000
39.0400 1144.0000 1.0000
39.0800 1123.0000 1.0000
39.1200 1123.0000 1.0000
39.1600 1079.0000 1.0000
39.2000 1072.0000 1.0000
39.2400 1064.0000 1.0000
39.2800 1018.0000 1.0000
39.3200 967.0000 1.0000
39.3600 1022.0000 1.0000
39.4000 1031.0000 1.0000
39.4400 994.0000 1.0000
39.4800 998.0000 1.0000
39.5200 1028.0000 1.0000
39.5600 1021.0000 1.0000
39.6000 1090.0000 1.0000
39.6400 1015.0000 1.0000
39.6800 1019.0000 1.0000
39.7200 988.0000 1.0000
39.7600 975.0000 1.0000
39.8000 943.0000 1.0000
39.8400 985.0000 1.0000
39.8800 1004.0000 1.0000
39.9200 1001.0000 1.0000
39.9600 961.0000 1.0000
40.0000 942.0000 1.0000
40.0400 974.0000 1.0000
40.0800 947.0000 1.0000
40.1200 923.0000 1.0000
40.1600 927.0000 1.0000
40.2000 946.0000 1.0000
40.2400 927.0000 1.0000
40.2800 921.0000 1.0000
40.3200 972.0000 1.0000
40.3600 910.0000 1.0000
40.4000 930.0000 1.0000
40.4400 929.0000 1.0000
40.4800 910.0000 1.0000
40.5200 935.0000 1.0000
40.5600 879.0000 1.0000
40.6000 888.0000 1.0000
40.6400 925.0000 1.0000
40.6800 939.0000 1.0000
40.7200 917.0000 1.0000
40.7600 928.0000 1.0000
40.8000 889.0000 1.0000
40.8400 908.0000 1.0000
40.8800 900.0000 1.0000
40.9200 888.0000 1.0000
40.9600 928.0000 1.0000
41.0000 968.0000 1.0000
41.0400 934.0000 1.0000
41.0800 923.0000 1.0000
41.1200 951.0000 1.0000
41.1600 908.0000 1.0000
41.2000 877.0000 1.0000
41.2400 863.0000 1.0000
41.2800 868.0000 1.0000
41.3200 911.0000 1.0000
41.3600 899.0000 1.0000
41.4000 860.0000 1.0000
41.4400 892.0000 1.0000
41.4800 841.0000 1.0000
41.5200 930.0000 1.0000
41.5600 902.0000 1.0000
41.6000 939.0000 1.0000
41.6400 938.0000 1.0000
41.6800 901.0000 1.0000
41.7200 933.0000 1.0000
41.7600 919.0000 1.0000
41.8000 900.0000 1.0000
41.8400 905.0000 1.0000
41.8800 923.0000 1.0000
41.9200 850.0000 1.0000
41.9600 922.0000 1.0000
42.0000 914.0000 1.0000
42.0400 923.0000 1.0000
42.0800 873.0000 1.0000
42.1200 884.0000 1.0000
42.1600 885.0000 1.0000
42.2000 863.0000 1.0000
42.2400 894.0000 1.0000
42.2800 880.0000 1.0000
42.3200 851.0000 1.0000
42.3600 882.0000 1.0000
42.4000 872.0000 1.0000
42.4400 963.0000 1.0000
42.4800 872.0000 1.0000
42.5200 838.0000 1.0000
42.5600 864.0000 1.0000
42.6000 919.0000 1.0000
42.6400 875.0000 1.0000
42.6800 915.0000 1.0000
42.7200 854.0000 1.0000
42.7600 910.0000 1.0000
42.8000 900.0000 1.0000
42.8400 836.0000 1.0000
42.8800 885.0000 1.0000
42.9200 871.0000 1.0000
42.9600 881.0000 1.0000
43.0000 941.0000 1.0000
43.0400 914.0000 1.0000
43.0800 894.0000 1.0000
43.1200 935.0000 1.0000
43.1600 933.0000 1.0000
43.2000 984.0000 1.0000
43.2400 964.0000 1.0000
43.2800 989.0000 1.0000
43.3200 990.0000 1.0000
43.3600 906.0000 1.0000
43.4000 949.0000 1.0000
43.4400 901.0000 1.0000
43.4800 891.0000 1.0000
43.5200 854.0000 1.0000
43.5600 905.0000 1.0000
43.6000 901.0000 1.0000
43.6400 865.0000 1.0000
43.6800 864.0000 1.0000
43.7200 887.0000 1.0000
43.7600 872.0000 1.0000
43.8000 855.0000 1.0000
43.8400 896.0000 1.0000
43.8800 910.0000 1.0000
43.9200 913.0000 1.0000
43.9600 845.0000 1.0000
44.0000 860.0000 1.0000
44.0400 872.0000 1.0000
44.0800 868.0000 1.0000
44.1200 844.0000 1.0000
44.1600 836.0000 1.0000
44.2000 884.0000 1.0000
44.2400 875.0000 1.0000
44.2800 894.0000 1.0000
44.3200 871.0000 1.0000
44.3600 874.0000 1.0000
44.4000 850.0000 1.0000
44.4400 866.0000 1.0000
44.4800 818.0000 1.0000
44.5200 838.0000 1.0000
44.5600 851.0000 1.0000
44.6000 840.0000 1.0000
44.6400 838.0000 1.0000
44.6800 824.0000 1.0000
44.7200 873.0000 1.0000
44.7600 802.0000 1.0000
44.8000 846.0000 1.0000
44.8400 814.0000 1.0000
44.8800 847.0000 1.0000
44.9200 839.0000 1.0000
44.9600 843.0000 1.0000
45.0000 835.0000 1.0000
45.0400 826.0000 1.0000
45.0800 862.0000 1.0000
45.1200 785.0000 1.0000
45.1600 798.0000 1.0000
45.2000 806.0000 1.0000
45.2400 798.0000 1.0000
45.2800 824.0000 1.0000
45.3200 807.0000 1.0000
45.3600 825.0000 1.0000
45.4000 875.0000 1.0000
45.4400 779.0000 1.0000
45.4800 840.0000 1.0000
45.5200 806.0000 1.0000
45.5600 802.0000 1.0000
45.6000 836.0000 1.0000
45.6400 844.0000 1.0000
45.6800 811.0000 1.0000
45.7200 807.0000 1.0000
45.7600 813.0000 1.0000
45.8000 846.0000 1.0000
45.8400 838.0000 1.0000
45.8800 804.0000 1.0000
45.9200 835.0000 1.0000
45.9600 825.0000 1.0000
46.0000 835.0000 1.0000
46.0400 867.0000 1.0000
46.0800 808.0000 1.0000
46.1200 811.0000 1.0000
46.1600 841.0000 1.0000
46.2000 834.0000 1.0000
46.2400 864.0000 1.0000
46.2800 802.0000 1.0000
46.3200 752.0000 1.0000
46.3600 834.0000 1.0000
46.4000 779.0000 1.0000
46.4400 849.0000 1.0000
46.4800 836.0000 1.0000
46.5200 824.0000 1.0000
46.5600 797.0000 1.0000
46.6000 803.0000 1.0000
46.6400 797.0000 1.0000
46.6800 809.0000 1.0000
46.7200 784.0000 1.0000
46.7600 769.0000 1.0000
46.8000 799.0000 1.0000
46.8400 799.0000 1.0000
46.8800 790.0000 1.0000
46.9200 789.0000 1.0000
46.9600 835.0000 1.0000
47.0000 857.0000 1.0000
47.0400 793.0000 1.0000
47.0800 833.0000 1.0000
47.1200 806.0000 1.0000
47.1600 834.0000 1.0000
47.2000 818.0000 1.0000
47.2400 806.0000 1.0000
47.2800 745.0000 1.0000
47.3200 803.0000 1.0000
47.3600 810.0000 1.0000
47.4000 818.0000 1.0000
47.4400 786.0000 1.0000
47.4800 796.0000 1.0000
47.5200 760.0000 1.0000
47.5600 769.0000 1.0000
47.6000 812.0000 1.0000
47.6400 786.0000 1.0000
47.6800 785.0000 1.0000
47.7200 771.0000 1.0000
47.7600 739.0000 1.0000
47.8000 799.0000 1.0000
47.8400 814.0000 1.0000
47.8800 759.0000 1.0000
47.9200 829.0000 1.0000
47.9600 807.0000 1.0000
48.0000 808.0000 1.0000
48.0400 767.0000 1.0000
48.0800 760.0000 1.0000
48.1200 765.0000 1.0000
48.1600 768.0000 1.0000
48.2000 781.0000 1.0000
48.2400 779.0000 1.0000
48.2800 711.0000 1.0000
48.3200 806.0000 1.0000
48.3600 807.0000 1.0000
48.4000 787.0000 1.0000
48.4400 788.0000 1.0000
48.4800 793.0000 1.0000
48.5200 753.0000 1.0000
48.5600 785.0000 1.0000
48.6000 757.0000 1.0000
48.6400 746.0000 1.0000
48.6800 755.0000 1.0000
48.7200 754.0000 1.0000
48.7600 747.0000 1.0000
48.8000 758.0000 1.0000
48.8400 764.0000 1.0000
48.8800 770.0000 1.0000
48.9200 788.0000 1.0000
48.9600 770.0000 1.0000
49.0000 771.0000 1.0000
49.0400 706.0000 1.0000
49.0800 759.0000 1.0000
49.1200 770.0000 1.0000
49.1600 777.0000 1.0000
49.2000 740.0000 1.0000
49.2400 743.0000 1.0000
49.2800 770.0000 1.0000
49.3200 779.0000 1.0000
49.3600 748.0000 1.0000
49.4000 778.0000 1.0000
49.4400 808.0000 1.0000
49.4800 791.0000 1.0000
49.5200 718.0000 1.0000
49.5600 795.0000 1.0000
49.6000 732.0000 1.0000
49.6400 742.0000 1.0000
49.6800 802.0000 1.0000
49.7200 701.0000 1.0000
49.7600 769.0000 1.0000
49.8000 739.0000 1.0000
49.8400 752.0000 1.0000
49.8800 734.0000 1.0000
49.9200 756.0000 1.0000
49.9600 720.0000 1.0000
50.0000 764.0000 1.0000
50.0400 777.0000 1.0000
50.0800 777.0000 1.0000
50.1200 752.0000 1.0000
50.1600 758.0000 1.0000
50.2000 778.0000 1.0000
50.2400 792.0000 1.0000
50.2800 812.0000 1.0000
50.3200 774.0000 1.0000
50.3600 838.0000 1.0000
50.4000 801.0000 1.0000
50.4400 843.0000 1.0000
50.4800 777.0000 1.0000
50.5200 835.0000 1.0000
50.5600 764.0000 1.0000
50.6000 789.0000 1.0000
50.6400 733.0000 1.0000
50.6800 792.0000 1.0000
50.7200 756.0000 1.0000
50.7600 767.0000 1.0000
50.8000 774.0000 1.0000
50.8400 812.0000 1.0000
50.8800 785.0000 1.0000
50.9200 747.0000 1.0000
50.9600 802.0000 1.0000
51.0000 745.0000 1.0000
51.0400 815.0000 1.0000
51.0800 763.0000 1.0000
51.1200 685.0000 1.0000
51.1600 781.0000 1.0000
51.2000 728.0000 1.0000
51.2400 726.0000 1.0000
51.2800 782.0000 1.0000
51.3200 762.0000 1.0000
51.3600 804.0000 1.0000
51.4000 773.0000 1.0000
51.4400 807.0000 1.0000
51.4800 779.0000 1.0000
51.5200 768.0000 1.0000
51.5600 752.0000 1.0000
51.6000 795.0000 1.0000
51.6400 775.0000 1.0000
51.6800 821.0000 1.0000
51.7200 813.0000 1.0000
51.7600 836.0000 1.0000
51.8000 866.0000 1.0000
51.8400 870.0000 1.0000
51.8800 873.0000 1.0000
51.9200 995.0000 1.0000
51.9600 1045.0000 1.0000
52.0000 1152.0000 1.0000
52.0400 1273.0000 1.0000
52.0800 1569.0000 1.0000
52.1200 1928.0000 1.0000
52.1600 2504.0000 1.0000
52.2000 3465.0000 1.0000
52.2400 4552.0000 1.0000
52.2800 5099.0000 1.0000
52.3200 4892.0000 1.0000
52.3600 4448.0000 1.0000
52.4000 3851.0000 1.0000
52.4400 3316.0000 1.0000
52.4800 2719.0000 1.0000
52.5200 2043.0000 1.0000
52.5600 1585.0000 1.0000
52.6000 1364.0000 1.0000
52.6400 1157.0000 1.0000
52.6800 1087.0000 1.0000
52.7200 983.0000 1.0000
52.7600 941.0000 1.0000
52.8000 889.0000 1.0000
52.8400 878.0000 1.0000
52.8800 886.0000 1.0000
52.9200 841.0000 1.0000
52.9600 819.0000 1.0000
53.0000 810.0000 1.0000
53.0400 834.0000 1.0000
53.0800 776.0000 1.0000
53.1200 791.0000 1.0000
53.1600 815.0000 1.0000
53.2000 745.0000 1.0000
53.2400 724.0000 1.0000
53.2800 733.0000 1.0000
53.3200 786.0000 1.0000
53.3600 796.0000 1.0000
53.4000 719.0000 1.0000
53.4400 816.0000 1.0000
53.4800 763.0000 1.0000
53.5200 752.0000 1.0000
53.5600 766.0000 1.0000
53.6000 731.0000 1.0000
53.6400 802.0000 1.0000
53.6800 755.0000 1.0000
53.7200 761.0000 1.0000
53.7600 759.0000 1.0000
53.8000 767.0000 1.0000
53.8400 754.0000 1.0000
53.8800 774.0000 1.0000
53.9200 786.0000 1.0000
53.9600 740.0000 1.0000
54.0000 735.0000 1.0000
54.0400 753.0000 1.0000
54.0800 738.0000 1.0000
54.1200 728.0000 1.0000
54.1600 710.0000 1.0000
54.2000 780.0000 1.0000
54.2400 692.0000 1.0000
54.2800 697.0000 1.0000
54.3200 724.0000 1.0000
54.3600 754.0000 1.0000
54.4000 721.0000 1.0000
54.4400 768.0000 1.0000
54.4800 714.0000 1.0000
54.5200 765.0000 1.0000
54.5600 800.0000 1.0000
54.6000 745.0000 1.0000
54.6400 740.0000 1.0000
54.6800 782.0000 1.0000
54.7200 790.0000 1.0000
54.7600 782.0000 1.0000
54.8000 791.0000 1.0000
54.8400 799.0000 1.0000
54.8800 782.0000 1.0000
54.9200 753.0000 1.0000
54.9600 777.0000 1.0000
55.0000 781.0000 1.0000
55.0400 840.0000 1.0000
55.0800 786.0000 1.0000
55.1200 940.0000 1.0000
55.1600 948.0000 1.0000
55.2000 985.0000 1.0000
55.2400 1093.0000 1.0000
55.2800 1126.0000 1.0000
55.3200 1114.0000 1.0000
55.3600 1141.0000 1.0000
55.4000 1031.0000 1.0000
55.4400 1050.0000 1.0000
55.4800 981.0000 1.0000
55.5200 913.0000 1.0000
55.5600 834.0000 1.0000
55.6000 788.0000 1.0000
55.6400 804.0000 1.0000
55.6800 810.0000 1.0000
55.7200 764.0000 1.0000
55.7600 775.0000 1.0000
55.8000 756.0000 1.0000
55.8400 766.0000 1.0000
55.8800 751.0000 1.0000
55.9200 758.0000 1.0000
55.9600 731.0000 1.0000
56.0000 750.0000 1.0000
56.0400 755.0000 1.0000
56.0800 713.0000 1.0000
56.1200 741.0000 1.0000
56.1600 745.0000 1.0000
56.2000 700.0000 1.0000
56.2400 702.0000 1.0000
56.2800 748.0000 1.0000
56.3200 704.0000 1.0000
56.3600 768.0000 1.0000
56.4000 746.0000 1.0000
56.4400 688.0000 1.0000
56.4800 751.0000 1.0000
56.5200 711.0000 1.0000
56.5600 724.0000 1.0000
56.6000 744.0000 1.0000
56.6400 720.0000 1.0000
56.6800 722.0000 1.0000
56.7200 718.0000 1.0000
56.7600 732.0000 1.0000
56.8000 700.0000 1.0000
56.8400 691.0000 1.0000
56.8800 682.0000 1.0000
56.9200 699.0000 1.0000
56.9600 705.0000 1.0000
57.0000 714.0000 1.0000
57.0400 702.0000 1.0000
57.0800 737.0000 1.0000
57.1200 703.0000 1.0000
57.1600 716.0000 1.0000
57.2000 757.0000 1.0000
57.2400 716.0000 1.0000
57.2800 729.0000 1.0000
57.3200 731.0000 1.0000
57.3600 705.0000 1.0000
57.4000 716.0000 1.0000
57.4400 704.0000 1.0000
57.4800 698.0000 1.0000
57.5200 732.0000 1.0000
57.5600 742.0000 1.0000
57.6000 666.0000 1.0000
57.6400 670.0000 1.0000
57.6800 695.0000 1.0000
57.7200 678.0000 1.0000
57.7600 732.0000 1.0000
57.8000 740.0000 1.0000
57.8400 700.0000 1.0000
57.8800 697.0000 1.0000
57.9200 751.0000 1.0000
57.9600 681.0000 1.0000
58.0000 708.0000 1.0000
58.0400 716.0000 1.0000
58.0800 777.0000 1.0000
58.1200 708.0000 1.0000
58.1600 772.0000 1.0000
58.2000 725.0000 1.0000
58.2400 727.0000 1.0000
58.2800 709.0000 1.0000
58.3200 660.0000 1.0000
58.3600 736.0000 1.0000
58.4000 749.0000 1.0000
58.4400 700.0000 1.0000
58.4800 715.0000 1.0000
58.5200 699.0000 1.0000
58.5600 723.0000 1.0000
58.6000 724.0000 1.0000
58.6400 703.0000 1.0000
58.6800 703.0000 1.0000
58.7200 690.0000 1.0000
58.7600 708.0000 1.0000
58.8000 702.0000 1.0000
58.8400 733.0000 1.0000
58.8800 743.0000 1.0000
58.9200 708.0000 1.0000
58.9600 686.0000 1.0000
59.0000 682.0000 1.0000
59.0400 694.0000 1.0000
59.0800 708.0000 1.0000
59.1200 699.0000 1.0000
59.1600 739.0000 1.0000
59.2000 657.0000 1.0000
59.2400 716.0000 1.0000
59.2800 712.0000 1.0000
59.3200 720.0000 1.0000
59.3600 723.0000 1.0000
59.4000 661.0000 1.0000
59.4400 706.0000 1.0000
59.4800 726.0000 1.0000
59.5200 717.0000 1.0000
59.5600 708.0000 1.0000
59.6000 710.0000 1.0000
59.6400 713.0000 1.0000
59.6800 692.0000 1.0000
59.7200 677.0000 1.0000
59.7600 729.0000 1.0000
59.8000 700.0000 1.0000
59.8400 699.0000 1.0000
59.8800 673.0000 1.0000
59.9200 668.0000 1.0000
59.9600 721.0000 1.0000
60.0000 707.0000 1.0000
60.0400 691.0000 1.0000
60.0800 732.0000 1.0000
60.1200 688.0000 1.0000
60.1600 728.0000 1.0000
60.2000 722.0000 1.0000
60.2400 726.0000 1.0000
60.2800 732.0000 1.0000
60.3200 728.0000 1.0000
60.3600 707.0000 1.0000
60.4000 689.0000 1.0000
60.4400 671.0000 1.0000
60.4800 689.0000 1.0000
60.5200 683.0000 1.0000
60.5600 735.0000 1.0000
60.6000 730.0000 1.0000
60.6400 683.0000 1.0000
60.6800 740.0000 1.0000
60.7200 721.0000 1.0000
60.7600 715.0000 1.0000
60.8000 723.0000 1.0000
60.8400 715.0000 1.0000
60.8800 729.0000 1.0000
60.9200 704.0000 1.0000
60.9600 708.0000 1.0000
61.0000 671.0000 1.0000
61.0400 659.0000 1.0000
61.0800 717.0000 1.0000
61.1200 672.0000 1.0000
61.1600 699.0000 1.0000
61.2000 720.0000 1.0000
61.2400 722.0000 1.0000
61.2800 747.0000 1.0000
61.3200 764.0000 1.0000
61.3600 710.0000 1.0000
61.4000 741.0000 1.0000
61.4400 730.0000 1.0000
61.4800 726.0000 1.0000
61.5200 743.0000 1.0000
61.5600 742.0000 1.0000
61.6000 731.0000 1.0000
61.6400 754.0000 1.0000
61.6800 736.0000 1.0000
61.7200 782.0000 1.0000
61.7600 765.0000 1.0000
61.8000 751.0000 1.0000
61.8400 748.0000 1.0000
61.8800 820.0000 1.0000
61.9200 837.0000 1.0000
61.9600 862.0000 1.0000
62.0000 952.0000 1.0000
62.0400 969.0000 1.0000
62.0800 990.0000 1.0000
62.1200 1159.0000 1.0000
62.1600 1254.0000 1.0000
62.2000 1382.0000 1.0000
62.2400 1565.0000 1.0000
62.2800 1614.0000 1.0000
62.3200 1659.0000 1.0000
62.3600 1643.0000 1.0000
62.4000 1634.0000 1.0000
62.4400 1602.0000 1.0000
62.4800 1439.0000 1.0000
62.5200 1371.0000 1.0000
62.5600 1270.0000 1.0000
62.6000 1182.0000 1.0000
62.6400 1089.0000 1.0000
62.6800 1002.0000 1.0000
62.7200 873.0000 1.0000
62.7600 935.0000 1.0000
62.8000 830.0000 1.0000
62.8400 787.0000 1.0000
62.8800 816.0000 1.0000
62.9200 770.0000 1.0000
62.9600 837.0000 1.0000
63.0000 764.0000 1.0000
63.0400 756.0000 1.0000
63.0800 766.0000 1.0000
63.1200 781.0000 1.0000
63.1600 832.0000 1.0000
63.2000 767.0000 1.0000
63.2400 736.0000 1.0000
63.2800 734.0000 1.0000
63.3200 740.0000 1.0000
63.3600 702.0000 1.0000
63.4000 722.0000 1.0000
63.4400 715.0000 1.0000
63.4800 711.0000 1.0000
63.5200 747.0000 1.0000
63.5600 687.0000 1.0000
63.6000 703.0000 1.0000
63.6400 755.0000 1.0000
63.6800 685.0000 1.0000
63.7200 708.0000 1.0000
63.7600 743.0000 1.0000
63.8000 726.0000 1.0000
63.8400 673.0000 1.0000
63.8800 695.0000 1.0000
63.9200 713.0000 1.0000
63.9600 700.0000 1.0000
64.0000 693.0000 1.0000
64.0400 701.0000 1.0000
64.0800 686.0000 1.0000
64.1200 712.0000 1.0000
64.1600 739.0000 1.0000
64.2000 713.0000 1.0000
64.2400 695.0000 1.0000
64.2800 727.0000 1.0000
64.3200 700.0000 1.0000
64.3600 698.0000 1.0000
64.4000 754.0000 1.0000
64.4400 740.0000 1.0000
64.4800 729.0000 1.0000
64.5200 725.0000 1.0000
64.5600 776.0000 1.0000
64.6000 830.0000 1.0000
64.6400 881.0000 1.0000
64.6800 959.0000 1.0000
64.7200 940.0000 1.0000
64.7600 877.0000 1.0000
64.8000 860.0000 1.0000
64.8400 881.0000 1.0000
64.8800 880.0000 1.0000
64.9200 828.0000 1.0000
64.9600 787.0000 1.0000
65.0000 719.0000 1.0000
65.0400 761.0000 1.0000
65.0800 758.0000 1.0000
65.1200 761.0000 1.0000
65.1600 801.0000 1.0000
65.2000 765.0000 1.0000
65.2400 707.0000 1.0000
65.2800 731.0000 1.0000
65.3200 750.0000 1.0000
65.3600 725.0000 1.0000
65.4000 709.0000 1.0000
65.4400 720.0000 1.0000
65.4800 766.0000 1.0000
65.5200 723.0000 1.0000
65.5600 753.0000 1.0000
65.6000 767.0000 1.0000
65.6400 748.0000 1.0000
65.6800 813.0000 1.0000
65.7200 754.0000 1.0000
65.7600 778.0000 1.0000
65.8000 819.0000 1.0000
65.8400 817.0000 1.0000
65.8800 827.0000 1.0000
65.9200 941.0000 1.0000
65.9600 972.0000 1.0000
66.0000 1037.0000 1.0000
66.0400 1128.0000 1.0000
66.0800 1319.0000 1.0000
66.1200 1584.0000 1.0000
66.1600 1868.0000 1.0000
66.2000 2341.0000 1.0000
66.2400 2678.0000 1.0000
66.2800 2811.0000 1.0000
66.3200 2696.0000 1.0000
66.3600 2610.0000 1.0000
66.4000 2350.0000 1.0000
66.4400 2250.0000 1.0000
66.4800 2015.0000 1.0000
66.5200 1811.0000 1.0000
66.5600 1465.0000 1.0000
66.6000 1319.0000 1.0000
66.6400 1139.0000 1.0000
66.6800 1057.0000 1.0000
66.7200 965.0000 1.0000
66.7600 875.0000 1.0000
66.8000 827.0000 1.0000
66.8400 815.0000 1.0000
66.8800 765.0000 1.0000
66.9200 802.0000 1.0000
66.9600 711.0000 1.0000
67.0000 706.0000 1.0000
67.0400 720.0000 1.0000
67.0800 778.0000 1.0000
67.1200 699.0000 1.0000
67.1600 705.0000 1.0000
67.2000 681.0000 1.0000
67.2400 668.0000 1.0000
67.2800 700.0000 1.0000
67.3200 647.0000 1.0000
67.3600 670.0000 1.0000
67.4000 654.0000 1.0000
67.4400 664.0000 1.0000
67.4800 648.0000 1.0000
67.5200 701.0000 1.0000
67.5600 702.0000 1.0000
67.6000 636.0000 1.0000
67.6400 650.0000 1.0000
67.6800 700.0000 1.0000
67.7200 668.0000 1.0000
67.7600 681.0000 1.0000
67.8000 641.0000 1.0000
67.8400 692.0000 1.0000
67.8800 634.0000 1.0000
67.9200 632.0000 1.0000
67.9600 641.0000 1.0000
68.0000 666.0000 1.0000
68.0400 679.0000 1.0000
68.0800 639.0000 1.0000
68.1200 678.0000 1.0000
68.1600 634.0000 1.0000
68.2000 615.0000 1.0000
68.2400 638.0000 1.0000
68.2800 643.0000 1.0000
68.3200 660.0000 1.0000
68.3600 616.0000 1.0000
68.4000 638.0000 1.0000
68.4400 638.0000 1.0000
68.4800 615.0000 1.0000
68.5200 592.0000 1.0000
68.5600 665.0000 1.0000
68.6000 611.0000 1.0000
68.6400 616.0000 1.0000
68.6800 599.0000 1.0000
68.7200 640.0000 1.0000
68.7600 611.0000 1.0000
68.8000 643.0000 1.0000
68.8400 614.0000 1.0000
68.8800 607.0000 1.0000
68.9200 656.0000 1.0000
68.9600 656.0000 1.0000
69.0000 604.0000 1.0000
69.0400 601.0000 1.0000
69.0800 626.0000 1.0000
69.1200 663.0000 1.0000
69.1600 601.0000 1.0000
69.2000 633.0000 1.0000
69.2400 613.0000 1.0000
69.2800 626.0000 1.0000
69.3200 626.0000 1.0000
69.3600 640.0000 1.0000
69.4000 644.0000 1.0000
69.4400 635.0000 1.0000
69.4800 667.0000 1.0000
69.5200 601.0000 1.0000
69.5600 641.0000 1.0000
69.6000 660.0000 1.0000
69.6400 624.0000 1.0000
69.6800 635.0000 1.0000
69.7200 611.0000 1.0000
69.7600 622.0000 1.0000
69.8000 631.0000 1.0000
69.8400 610.0000 1.0000
69.8800 608.0000 1.0000
69.9200 605.0000 1.0000
69.9600 612.0000 1.0000
70.0000 577.0000 1.0000
*RAS_INT_END
*RAS_TEMPERATURE_START
*RAS_TEMPERATURE_END
*RAS_DATA_END