File: Data/Dataset1_Only_water/5_XRD/No_023_VS2_2.ras
*RAS_DATA_START
*RAS_HEADER_START
*DISP_FMT_X "%.2f"
*DISP_FMT_Y "%.0f"
*DISP_FULLSCALE "16356.0000000000"
*DISP_LINE_COLOR "255.0000000000"
*DISP_LINE_STYLE "0.0000000000"
*DISP_LINE_WIDTH "0.2500000000"
*DISP_NOTE "測定データ-2"
*DISP_OFFSET_Y "0.0000000000"
*DISP_PEAKSEARCH_UNIT_Y "cps"
*DISP_RANGE_BOTTOM "0.0000000000"
*DISP_RANGE_LEFT "20.0000000000"
*DISP_RANGE_LOGCUTOFF "0.0100000000"
*DISP_RANGE_RIGHT "70.0000000000"
*DISP_RANGE_TOP "16356.0000000000"
*DISP_SCALE_MODE_Y "0.0000000000"
*DISP_TAB_NAME "2θ/θ"
*DISP_TITLE_Y "強度"
*DISP_UNIT_Y "cps"
*DISP_WINDOW_NAME "MSG_MACROENGINE"
*FILE_COMMENT " "
*FILE_MD5 ""
*FILE_MEMO " "
*FILE_OPERATOR "Administrator"
*FILE_SAMPLE " "
*FILE_TYPE "RAS_RAW"
*FILE_USERGROUP "システムマネージャ"
*FILE_VERSION "1.0000000000"
*HW_ATTACHMENT_ID "ATT0025"
*HW_ATTACHMENT_NAME "標準|Standard"
*HW_COUNTER_ID-0 "CUT0025"
*HW_COUNTER_ID-1 "CUT0020"
*HW_COUNTER_ID-2 "CUT0020"
*HW_COUNTER_ID-3 "CSL0021"
*HW_COUNTER_ID-4 "CMC0021"
*HW_COUNTER_NAME-0 "D/teX Ultra|D/teX Ultra"
*HW_COUNTER_NAME-1 "None|None"
*HW_COUNTER_NAME-2 "None|None"
*HW_COUNTER_NAME-3 "BBM|BBM"
*HW_COUNTER_NAME-4 "検出器モノクロメータ|Detector monochromator"
*HW_COUNTER_SELECT_NAME "D/teX Ultra|D/teX Ultra"
*HW_GONIOMETER_ID "GON0023"
*HW_GONIOMETER_NAME "SmartLab|SmartLab"
*HW_GONIOMETER_RADIUS-0 "90.0"
*HW_GONIOMETER_RADIUS-1 "114.0"
*HW_GONIOMETER_RADIUS-2 "190.0"
*HW_GONIOMETER_RADIUS-3 "300.0"
*HW_GONIOMETER_RADIUS-4 "187.0"
*HW_GONIOMETER_RADIUS-5 "300.0"
*HW_GONIOMETER_RADIUS-6 "113.0"
*HW_GONIOMETER_RADIUS-7 "331.0"
*HW_I_OPT_ID-0 "CBO0021"
*HW_I_OPT_ID-1 "ICR0023"
*HW_I_OPT_ID-2 "ISL0021"
*HW_I_OPT_ID-3 "ISO0021"
*HW_I_OPT_ID-4 "IAD0021"
*HW_I_OPT_ID-5 "IPR0001"
*HW_I_OPT_NAME-0 "CBOユニット|CBO unit"
*HW_I_OPT_NAME-1 "標準入射光学ユニット|Standard incident optical unit"
*HW_I_OPT_NAME-2 "標準入射スリットボックス|Standard incident slit box"
*HW_I_OPT_NAME-3 "入射平行スリット|Incident parallel slit"
*HW_I_OPT_NAME-4 "長手制限スリット|Length limiting slit"
*HW_I_OPT_NAME-5 "None|None"
*HW_R_ATTENUATER_AUTOMODE "0"
*HW_R_OPT_ID-0 "RSS0021"
*HW_R_OPT_ID-1 "RCR0023"
*HW_R_OPT_ID-2 "RSO0021"
*HW_R_OPT_ID-3 "RRS0021"
*HW_R_OPT_ID-4 "ATN0021"
*HW_R_OPT_ID-5 "RFL0021"
*HW_R_OPT_ID-6 "RAD0021"
*HW_R_OPT_NAME-0 "標準受光スリットボックス1|Standard receiving slit box # 1"
*HW_R_OPT_NAME-1 "標準受光光学ユニット1|Standard receiving unit # 1"
*HW_R_OPT_NAME-2 "標準受光光学ユニット2|Standard receiving optical unit # 2"
*HW_R_OPT_NAME-3 "標準受光スリットボックス2|Standard receiving slit box # 2"
*HW_R_OPT_NAME-4 "標準アッテネータ|Standard Attenuator"
*HW_R_OPT_NAME-5 "Cu Kβ|Cu K-beta"
*HW_R_OPT_NAME-6 "調整用受光スリット|Alignment receiving slit"
*HW_SAMPLE_HOLDER_ID "SMP0023"
*HW_SAMPLE_HOLDER_NAME "標準Zステージ|Standard Z stage"
*HW_XG_CURRENT_MAX "50"
*HW_XG_CURRENT_MIN "2"
*HW_XG_CURRENT_RESOLUTION "1"
*HW_XG_CURRENT_UNIT "mA"
*HW_XG_FOCUS "1mm x 10mm"
*HW_XG_FOCUS_TYPE "Normal"
*HW_XG_ID ""
*HW_XG_NAME "3kW 封入管(ID:1200)|3kW Sealed tube(ID:1200)"
*HW_XG_TARGET_ATOMIC_NUMBER "29.0000000000"
*HW_XG_TARGET_NAME "Cu"
*HW_XG_TYPE "Hermetic"
*HW_XG_VOLTAGE_MAX "60"
*HW_XG_VOLTAGE_MIN "20"
*HW_XG_VOLTAGE_RESOLUTION "1"
*HW_XG_VOLTAGE_UNIT "kV"
*HW_XG_WATT_MAX "1.500"
*HW_XG_WATT_UNIT "kW"
*HW_XG_WAVE_LENGTH_ALPHA1 "1.540593"
*HW_XG_WAVE_LENGTH_ALPHA2 "1.544414"
*HW_XG_WAVE_LENGTH_BETA "1.392250"
*MEAS_COND_AXIS_NAME-0 "2θ/θ"
*MEAS_COND_AXIS_NAME-1 "2θ"
*MEAS_COND_AXIS_NAME-2 "ω"
*MEAS_COND_AXIS_NAME-3 "Z"
*MEAS_COND_AXIS_NAME-4 "2θ/ω"
*MEAS_COND_AXIS_NAME-5 "θs"
*MEAS_COND_AXIS_NAME-6 "θd"
*MEAS_COND_AXIS_NAME-7 "Ts"
*MEAS_COND_AXIS_NAME-8 "CBO選択スリット"
*MEAS_COND_AXIS_NAME-9 "M"
*MEAS_COND_AXIS_NAME-10 "入射平行スリット"
*MEAS_COND_AXIS_NAME-11 "入射スリット"
*MEAS_COND_AXIS_NAME-12 ""
*MEAS_COND_AXIS_NAME-13 "Zs"
*MEAS_COND_AXIS_NAME-14 "入射光学素子"
*MEAS_COND_AXIS_NAME-15 "長手制限スリット"
*MEAS_COND_AXIS_NAME-16 "センタースリット"
*MEAS_COND_AXIS_NAME-17 "フィルター"
*MEAS_COND_AXIS_NAME-18 "受光スリット1"
*MEAS_COND_AXIS_NAME-19 "受光スリット2"
*MEAS_COND_AXIS_NAME-20 "受光光学素子"
*MEAS_COND_AXIS_NAME-21 "受光平行スリット"
*MEAS_COND_AXIS_NAME-22 "調整用受光スリット"
*MEAS_COND_AXIS_NAME-23 ""
*MEAS_COND_AXIS_NAME-24 ""
*MEAS_COND_AXIS_NAME-25 "Zd"
*MEAS_COND_AXIS_NAME-26 "アッテネータ"
*MEAS_COND_AXIS_NAME-27 "検出器モノクロメータ"
*MEAS_COND_AXIS_NAME-28 "モノクロメータスリット"
*MEAS_COND_AXIS_NAME-29 "プライマリビーム"
*MEAS_COND_AXIS_NAME-30 "PHA"
*MEAS_COND_AXIS_NAME_INTERNAL-0 "TwoThetaTheta"
*MEAS_COND_AXIS_NAME_INTERNAL-1 "TwoTheta"
*MEAS_COND_AXIS_NAME_INTERNAL-2 "Omega"
*MEAS_COND_AXIS_NAME_INTERNAL-3 "Z"
*MEAS_COND_AXIS_NAME_INTERNAL-4 "TwoThetaOmega"
*MEAS_COND_AXIS_NAME_INTERNAL-5 "ThetaS"
*MEAS_COND_AXIS_NAME_INTERNAL-6 "ThetaD"
*MEAS_COND_AXIS_NAME_INTERNAL-7 "Ts"
*MEAS_COND_AXIS_NAME_INTERNAL-8 "CBO"
*MEAS_COND_AXIS_NAME_INTERNAL-9 "CBO-M"
*MEAS_COND_AXIS_NAME_INTERNAL-10 "IncidentSollerSlit"
*MEAS_COND_AXIS_NAME_INTERNAL-11 "IncidentSlitBox"
*MEAS_COND_AXIS_NAME_INTERNAL-12 "IncidentSlitBox-_Axis"
*MEAS_COND_AXIS_NAME_INTERNAL-13 "Zs"
*MEAS_COND_AXIS_NAME_INTERNAL-14 "IncidentMonochromator"
*MEAS_COND_AXIS_NAME_INTERNAL-15 "IncidentAxdSlit"
*MEAS_COND_AXIS_NAME_INTERNAL-16 "CenterSlit"
*MEAS_COND_AXIS_NAME_INTERNAL-17 "Filter"
*MEAS_COND_AXIS_NAME_INTERNAL-18 "ReceivingSlitBox1"
*MEAS_COND_AXIS_NAME_INTERNAL-19 "ReceivingSlitBox2"
*MEAS_COND_AXIS_NAME_INTERNAL-20 "ReceivingOptics"
*MEAS_COND_AXIS_NAME_INTERNAL-21 "ReceivingSollerSlit"
*MEAS_COND_AXIS_NAME_INTERNAL-22 "ReceivingAxdSlit"
*MEAS_COND_AXIS_NAME_INTERNAL-23 "ReceivingSlitBox1-_Axis"
*MEAS_COND_AXIS_NAME_INTERNAL-24 "ReceivingSlitBox2-_Axis"
*MEAS_COND_AXIS_NAME_INTERNAL-25 "ReceivingSlitBox2-Zd"
*MEAS_COND_AXIS_NAME_INTERNAL-26 "Attenuator"
*MEAS_COND_AXIS_NAME_INTERNAL-27 "CounterMonochromator"
*MEAS_COND_AXIS_NAME_INTERNAL-28 "CounterSlit"
*MEAS_COND_AXIS_NAME_INTERNAL-29 "IncidentPrimary"
*MEAS_COND_AXIS_NAME_INTERNAL-30 "PHA"
*MEAS_COND_AXIS_NAME_MAGICNO-0 "83951616.0000000000"
*MEAS_COND_AXIS_NAME_MAGICNO-1 "268632064.0000000000"
*MEAS_COND_AXIS_NAME_MAGICNO-2 "268500992.0000000000"
*MEAS_COND_AXIS_NAME_MAGICNO-3 "285278208.0000000000"
*MEAS_COND_AXIS_NAME_MAGICNO-4 "83951616.0000000000"
*MEAS_COND_AXIS_NAME_MAGICNO-5 "131072.0000000000"
*MEAS_COND_AXIS_NAME_MAGICNO-6 "131072.0000000000"
*MEAS_COND_AXIS_NAME_MAGICNO-7 "318898176.0000000000"
*MEAS_COND_AXIS_NAME_MAGICNO-8 "20971521.0000000000"
*MEAS_COND_AXIS_NAME_MAGICNO-9 "285343744.0000000000"
*MEAS_COND_AXIS_NAME_MAGICNO-10 "20971521.0000000000"
*MEAS_COND_AXIS_NAME_MAGICNO-11 "22020097.0000000000"
*MEAS_COND_AXIS_NAME_MAGICNO-12 "25165824.0000000000"
*MEAS_COND_AXIS_NAME_MAGICNO-13 "318898176.0000000000"
*MEAS_COND_AXIS_NAME_MAGICNO-14 "1.0000000000"
*MEAS_COND_AXIS_NAME_MAGICNO-15 "20971521.0000000000"
*MEAS_COND_AXIS_NAME_MAGICNO-16 "20971521.0000000000"
*MEAS_COND_AXIS_NAME_MAGICNO-17 "20971521.0000000000"
*MEAS_COND_AXIS_NAME_MAGICNO-18 "23068673.0000000000"
*MEAS_COND_AXIS_NAME_MAGICNO-19 "23068673.0000000000"
*MEAS_COND_AXIS_NAME_MAGICNO-20 "20971521.0000000000"
*MEAS_COND_AXIS_NAME_MAGICNO-21 "20971521.0000000000"
*MEAS_COND_AXIS_NAME_MAGICNO-22 "20971521.0000000000"
*MEAS_COND_AXIS_NAME_MAGICNO-23 "25165824.0000000000"
*MEAS_COND_AXIS_NAME_MAGICNO-24 "25165824.0000000000"
*MEAS_COND_AXIS_NAME_MAGICNO-25 "285343744.0000000000"
*MEAS_COND_AXIS_NAME_MAGICNO-26 "17301505.0000000000"
*MEAS_COND_AXIS_NAME_MAGICNO-27 "20971521.0000000000"
*MEAS_COND_AXIS_NAME_MAGICNO-28 "20971521.0000000000"
*MEAS_COND_AXIS_NAME_MAGICNO-29 "20971521.0000000000"
*MEAS_COND_AXIS_NAME_MAGICNO-30 "0.0000000000"
*MEAS_COND_AXIS_OFFSET-0 "-"
*MEAS_COND_AXIS_OFFSET-1 "-0.1081000000"
*MEAS_COND_AXIS_OFFSET-2 "0.3758000000"
*MEAS_COND_AXIS_OFFSET-3 "-"
*MEAS_COND_AXIS_OFFSET-4 "-"
*MEAS_COND_AXIS_OFFSET-5 "0.3758000000"
*MEAS_COND_AXIS_OFFSET-6 "-0.4839000000"
*MEAS_COND_AXIS_OFFSET-7 "-"
*MEAS_COND_AXIS_OFFSET-8 "-"
*MEAS_COND_AXIS_OFFSET-9 "-"
*MEAS_COND_AXIS_OFFSET-10 "-"
*MEAS_COND_AXIS_OFFSET-11 "-"
*MEAS_COND_AXIS_OFFSET-12 "-"
*MEAS_COND_AXIS_OFFSET-13 "-"
*MEAS_COND_AXIS_OFFSET-14 "-"
*MEAS_COND_AXIS_OFFSET-15 "-"
*MEAS_COND_AXIS_OFFSET-16 "-"
*MEAS_COND_AXIS_OFFSET-17 "-"
*MEAS_COND_AXIS_OFFSET-18 "-"
*MEAS_COND_AXIS_OFFSET-19 "-"
*MEAS_COND_AXIS_OFFSET-20 "-"
*MEAS_COND_AXIS_OFFSET-21 "-"
*MEAS_COND_AXIS_OFFSET-22 "-"
*MEAS_COND_AXIS_OFFSET-23 "-"
*MEAS_COND_AXIS_OFFSET-24 "-"
*MEAS_COND_AXIS_OFFSET-25 "-"
*MEAS_COND_AXIS_OFFSET-26 "-"
*MEAS_COND_AXIS_OFFSET-27 "-"
*MEAS_COND_AXIS_OFFSET-28 "-"
*MEAS_COND_AXIS_OFFSET-29 "-"
*MEAS_COND_AXIS_OFFSET-30 "-"
*MEAS_COND_AXIS_POSITION-0 "0.0000000000"
*MEAS_COND_AXIS_POSITION-1 "0.0000000000"
*MEAS_COND_AXIS_POSITION-2 "0.0000000000"
*MEAS_COND_AXIS_POSITION-3 "-0.5500000000"
*MEAS_COND_AXIS_POSITION-4 "0.0000000000"
*MEAS_COND_AXIS_POSITION-5 "0.0000000000"
*MEAS_COND_AXIS_POSITION-6 "0.0000000000"
*MEAS_COND_AXIS_POSITION-7 "-0.4278800000"
*MEAS_COND_AXIS_POSITION-8 "BB"
*MEAS_COND_AXIS_POSITION-9 "0.0000000000"
*MEAS_COND_AXIS_POSITION-10 "Soller_slit_5.0deg"
*MEAS_COND_AXIS_POSITION-11 "2/3deg"
*MEAS_COND_AXIS_POSITION-12 "2.2088000000"
*MEAS_COND_AXIS_POSITION-13 "-0.4140600000"
*MEAS_COND_AXIS_POSITION-14 "0.0000000000"
*MEAS_COND_AXIS_POSITION-15 "10.0mm"
*MEAS_COND_AXIS_POSITION-16 "None"
*MEAS_COND_AXIS_POSITION-17 "Cu_K-beta"
*MEAS_COND_AXIS_POSITION-18 "13.000mm"
*MEAS_COND_AXIS_POSITION-19 "13.000mm"
*MEAS_COND_AXIS_POSITION-20 "No_unit"
*MEAS_COND_AXIS_POSITION-21 "Soller_slit_5.0deg"
*MEAS_COND_AXIS_POSITION-22 "None"
*MEAS_COND_AXIS_POSITION-23 "13.0000000000"
*MEAS_COND_AXIS_POSITION-24 "13.0000000000"
*MEAS_COND_AXIS_POSITION-25 "0.0109400000"
*MEAS_COND_AXIS_POSITION-26 "Open"
*MEAS_COND_AXIS_POSITION-27 "None"
*MEAS_COND_AXIS_POSITION-28 "None"
*MEAS_COND_AXIS_POSITION-29 "None"
*MEAS_COND_AXIS_POSITION-30 "38.0000000000"
*MEAS_COND_AXIS_UNIT-0 "deg"
*MEAS_COND_AXIS_UNIT-1 "deg"
*MEAS_COND_AXIS_UNIT-2 "deg"
*MEAS_COND_AXIS_UNIT-3 "mm"
*MEAS_COND_AXIS_UNIT-4 "deg"
*MEAS_COND_AXIS_UNIT-5 "deg"
*MEAS_COND_AXIS_UNIT-6 "deg"
*MEAS_COND_AXIS_UNIT-7 "mm"
*MEAS_COND_AXIS_UNIT-8 ""
*MEAS_COND_AXIS_UNIT-9 "pulse"
*MEAS_COND_AXIS_UNIT-10 ""
*MEAS_COND_AXIS_UNIT-11 ""
*MEAS_COND_AXIS_UNIT-12 "mm"
*MEAS_COND_AXIS_UNIT-13 "mm"
*MEAS_COND_AXIS_UNIT-14 ""
*MEAS_COND_AXIS_UNIT-15 ""
*MEAS_COND_AXIS_UNIT-16 ""
*MEAS_COND_AXIS_UNIT-17 ""
*MEAS_COND_AXIS_UNIT-18 ""
*MEAS_COND_AXIS_UNIT-19 ""
*MEAS_COND_AXIS_UNIT-20 ""
*MEAS_COND_AXIS_UNIT-21 ""
*MEAS_COND_AXIS_UNIT-22 ""
*MEAS_COND_AXIS_UNIT-23 "mm"
*MEAS_COND_AXIS_UNIT-24 "mm"
*MEAS_COND_AXIS_UNIT-25 "mm"
*MEAS_COND_AXIS_UNIT-26 ""
*MEAS_COND_AXIS_UNIT-27 ""
*MEAS_COND_AXIS_UNIT-28 ""
*MEAS_COND_AXIS_UNIT-29 ""
*MEAS_COND_AXIS_UNIT-30 "div"
*MEAS_COND_COUNTER_CNTLOSS_CORR "0.0000000000"
*MEAS_COND_COUNTER_PHABASE "38.0000000000"
*MEAS_COND_COUNTER_PHAWINDOW "16.0000000000"
*MEAS_COND_COUNTER_PHA_UNIT "div"
*MEAS_COND_COUNTER_TAUDIFF "30.0000000000"
*MEAS_COND_COUNTER_TAUINT "0.0000000000"
*MEAS_COND_IRRADIATION_MODE "OFF"
*MEAS_COND_IRRADIATION_WIDTH ""
*MEAS_COND_OPT_ATTR "集中法"
*MEAS_COND_OPT_NAME "@集中法"
*MEAS_COND_UNSYMMETRIC_MODE "OFF"
*MEAS_COND_XG_CURRENT "30.0000000000"
*MEAS_COND_XG_VOLTAGE "40.0000000000"
*MEAS_COND_XG_WAVE_TYPE "Ka"
*MEAS_DATA_COUNT "5001.0000000000"
*MEAS_SCAN_AXIS_X "2θ/θ"
*MEAS_SCAN_AXIS_X_INTERNAL "TwoThetaTheta"
*MEAS_SCAN_END_TIME "07/20/21 12:15:43"
*MEAS_SCAN_MODE "CONTINUOUS"
*MEAS_SCAN_MONITOR "0"
*MEAS_SCAN_RESOLUTION_X "0.0002"
*MEAS_SCAN_SPEED "1.0"
*MEAS_SCAN_SPEED_UNIT "deg/min"
*MEAS_SCAN_START "20.0000000000"
*MEAS_SCAN_START_TIME "07/20/21 11:22:50"
*MEAS_SCAN_STEP "0.0100000000"
*MEAS_SCAN_STOP "70.0000000000"
*MEAS_SCAN_UNIT_X "deg"
*MEAS_SCAN_UNIT_Y "counts"
*RAS_HEADER_END
*RAS_INT_START
20.0000 1517.0000 1.0000
20.0400 1544.0000 1.0000
20.0800 1557.0000 1.0000
20.1200 1519.0000 1.0000
20.1600 1519.0000 1.0000
20.2000 1497.0000 1.0000
20.2400 1543.0000 1.0000
20.2800 1517.0000 1.0000
20.3200 1538.0000 1.0000
20.3600 1552.0000 1.0000
20.4000 1544.0000 1.0000
20.4400 1486.0000 1.0000
20.4800 1579.0000 1.0000
20.5200 1470.0000 1.0000
20.5600 1551.0000 1.0000
20.6000 1578.0000 1.0000
20.6400 1585.0000 1.0000
20.6800 1557.0000 1.0000
20.7200 1526.0000 1.0000
20.7600 1537.0000 1.0000
20.8000 1489.0000 1.0000
20.8400 1506.0000 1.0000
20.8800 1476.0000 1.0000
20.9200 1485.0000 1.0000
20.9600 1495.0000 1.0000
21.0000 1586.0000 1.0000
21.0400 1567.0000 1.0000
21.0800 1518.0000 1.0000
21.1200 1538.0000 1.0000
21.1600 1537.0000 1.0000
21.2000 1466.0000 1.0000
21.2400 1568.0000 1.0000
21.2800 1522.0000 1.0000
21.3200 1485.0000 1.0000
21.3600 1541.0000 1.0000
21.4000 1492.0000 1.0000
21.4400 1587.0000 1.0000
21.4800 1517.0000 1.0000
21.5200 1596.0000 1.0000
21.5600 1589.0000 1.0000
21.6000 1514.0000 1.0000
21.6400 1529.0000 1.0000
21.6800 1572.0000 1.0000
21.7200 1599.0000 1.0000
21.7600 1545.0000 1.0000
21.8000 1559.0000 1.0000
21.8400 1520.0000 1.0000
21.8800 1531.0000 1.0000
21.9200 1494.0000 1.0000
21.9600 1543.0000 1.0000
22.0000 1554.0000 1.0000
22.0400 1563.0000 1.0000
22.0800 1582.0000 1.0000
22.1200 1598.0000 1.0000
22.1600 1541.0000 1.0000
22.2000 1574.0000 1.0000
22.2400 1526.0000 1.0000
22.2800 1560.0000 1.0000
22.3200 1567.0000 1.0000
22.3600 1566.0000 1.0000
22.4000 1514.0000 1.0000
22.4400 1578.0000 1.0000
22.4800 1496.0000 1.0000
22.5200 1561.0000 1.0000
22.5600 1577.0000 1.0000
22.6000 1565.0000 1.0000
22.6400 1534.0000 1.0000
22.6800 1526.0000 1.0000
22.7200 1559.0000 1.0000
22.7600 1589.0000 1.0000
22.8000 1558.0000 1.0000
22.8400 1599.0000 1.0000
22.8800 1557.0000 1.0000
22.9200 1539.0000 1.0000
22.9600 1564.0000 1.0000
23.0000 1636.0000 1.0000
23.0400 1547.0000 1.0000
23.0800 1582.0000 1.0000
23.1200 1554.0000 1.0000
23.1600 1562.0000 1.0000
23.2000 1632.0000 1.0000
23.2400 1597.0000 1.0000
23.2800 1580.0000 1.0000
23.3200 1557.0000 1.0000
23.3600 1577.0000 1.0000
23.4000 1570.0000 1.0000
23.4400 1588.0000 1.0000
23.4800 1591.0000 1.0000
23.5200 1619.0000 1.0000
23.5600 1581.0000 1.0000
23.6000 1586.0000 1.0000
23.6400 1603.0000 1.0000
23.6800 1642.0000 1.0000
23.7200 1610.0000 1.0000
23.7600 1618.0000 1.0000
23.8000 1528.0000 1.0000
23.8400 1555.0000 1.0000
23.8800 1613.0000 1.0000
23.9200 1602.0000 1.0000
23.9600 1664.0000 1.0000
24.0000 1651.0000 1.0000
24.0400 1585.0000 1.0000
24.0800 1545.0000 1.0000
24.1200 1604.0000 1.0000
24.1600 1541.0000 1.0000
24.2000 1646.0000 1.0000
24.2400 1540.0000 1.0000
24.2800 1582.0000 1.0000
24.3200 1527.0000 1.0000
24.3600 1623.0000 1.0000
24.4000 1625.0000 1.0000
24.4400 1653.0000 1.0000
24.4800 1690.0000 1.0000
24.5200 1657.0000 1.0000
24.5600 1665.0000 1.0000
24.6000 1658.0000 1.0000
24.6400 1652.0000 1.0000
24.6800 1667.0000 1.0000
24.7200 1652.0000 1.0000
24.7600 1608.0000 1.0000
24.8000 1597.0000 1.0000
24.8400 1616.0000 1.0000
24.8800 1690.0000 1.0000
24.9200 1721.0000 1.0000
24.9600 1646.0000 1.0000
25.0000 1676.0000 1.0000
25.0400 1722.0000 1.0000
25.0800 1753.0000 1.0000
25.1200 1686.0000 1.0000
25.1600 1694.0000 1.0000
25.2000 1693.0000 1.0000
25.2400 1686.0000 1.0000
25.2800 1609.0000 1.0000
25.3200 1632.0000 1.0000
25.3600 1613.0000 1.0000
25.4000 1704.0000 1.0000
25.4400 1641.0000 1.0000
25.4800 1620.0000 1.0000
25.5200 1682.0000 1.0000
25.5600 1732.0000 1.0000
25.6000 1651.0000 1.0000
25.6400 1638.0000 1.0000
25.6800 1585.0000 1.0000
25.7200 1621.0000 1.0000
25.7600 1624.0000 1.0000
25.8000 1660.0000 1.0000
25.8400 1648.0000 1.0000
25.8800 1742.0000 1.0000
25.9200 1640.0000 1.0000
25.9600 1668.0000 1.0000
26.0000 1721.0000 1.0000
26.0400 1648.0000 1.0000
26.0800 1618.0000 1.0000
26.1200 1717.0000 1.0000
26.1600 1694.0000 1.0000
26.2000 1669.0000 1.0000
26.2400 1644.0000 1.0000
26.2800 1671.0000 1.0000
26.3200 1741.0000 1.0000
26.3600 1707.0000 1.0000
26.4000 1681.0000 1.0000
26.4400 1677.0000 1.0000
26.4800 1728.0000 1.0000
26.5200 1734.0000 1.0000
26.5600 1788.0000 1.0000
26.6000 1800.0000 1.0000
26.6400 1756.0000 1.0000
26.6800 1762.0000 1.0000
26.7200 1796.0000 1.0000
26.7600 1912.0000 1.0000
26.8000 1943.0000 1.0000
26.8400 1843.0000 1.0000
26.8800 2000.0000 1.0000
26.9200 2100.0000 1.0000
26.9600 2285.0000 1.0000
27.0000 2421.0000 1.0000
27.0400 2734.0000 1.0000
27.0800 3060.0000 1.0000
27.1200 3591.0000 1.0000
27.1600 4392.0000 1.0000
27.2000 5433.0000 1.0000
27.2400 6457.0000 1.0000
27.2800 7054.0000 1.0000
27.3200 6347.0000 1.0000
27.3600 5411.0000 1.0000
27.4000 4350.0000 1.0000
27.4400 3632.0000 1.0000
27.4800 3065.0000 1.0000
27.5200 2764.0000 1.0000
27.5600 2375.0000 1.0000
27.6000 2230.0000 1.0000
27.6400 2140.0000 1.0000
27.6800 1963.0000 1.0000
27.7200 1999.0000 1.0000
27.7600 1919.0000 1.0000
27.8000 1892.0000 1.0000
27.8400 1796.0000 1.0000
27.8800 1785.0000 1.0000
27.9200 1765.0000 1.0000
27.9600 1777.0000 1.0000
28.0000 1696.0000 1.0000
28.0400 1686.0000 1.0000
28.0800 1689.0000 1.0000
28.1200 1699.0000 1.0000
28.1600 1653.0000 1.0000
28.2000 1673.0000 1.0000
28.2400 1658.0000 1.0000
28.2800 1634.0000 1.0000
28.3200 1678.0000 1.0000
28.3600 1637.0000 1.0000
28.4000 1619.0000 1.0000
28.4400 1634.0000 1.0000
28.4800 1669.0000 1.0000
28.5200 1585.0000 1.0000
28.5600 1575.0000 1.0000
28.6000 1614.0000 1.0000
28.6400 1534.0000 1.0000
28.6800 1596.0000 1.0000
28.7200 1566.0000 1.0000
28.7600 1579.0000 1.0000
28.8000 1594.0000 1.0000
28.8400 1602.0000 1.0000
28.8800 1619.0000 1.0000
28.9200 1596.0000 1.0000
28.9600 1475.0000 1.0000
29.0000 1588.0000 1.0000
29.0400 1539.0000 1.0000
29.0800 1604.0000 1.0000
29.1200 1606.0000 1.0000
29.1600 1553.0000 1.0000
29.2000 1589.0000 1.0000
29.2400 1482.0000 1.0000
29.2800 1520.0000 1.0000
29.3200 1540.0000 1.0000
29.3600 1491.0000 1.0000
29.4000 1541.0000 1.0000
29.4400 1541.0000 1.0000
29.4800 1578.0000 1.0000
29.5200 1579.0000 1.0000
29.5600 1631.0000 1.0000
29.6000 1496.0000 1.0000
29.6400 1518.0000 1.0000
29.6800 1542.0000 1.0000
29.7200 1550.0000 1.0000
29.7600 1515.0000 1.0000
29.8000 1555.0000 1.0000
29.8400 1442.0000 1.0000
29.8800 1493.0000 1.0000
29.9200 1540.0000 1.0000
29.9600 1505.0000 1.0000
30.0000 1495.0000 1.0000
30.0400 1533.0000 1.0000
30.0800 1496.0000 1.0000
30.1200 1470.0000 1.0000
30.1600 1484.0000 1.0000
30.2000 1457.0000 1.0000
30.2400 1477.0000 1.0000
30.2800 1488.0000 1.0000
30.3200 1446.0000 1.0000
30.3600 1466.0000 1.0000
30.4000 1400.0000 1.0000
30.4400 1469.0000 1.0000
30.4800 1447.0000 1.0000
30.5200 1440.0000 1.0000
30.5600 1428.0000 1.0000
30.6000 1473.0000 1.0000
30.6400 1439.0000 1.0000
30.6800 1520.0000 1.0000
30.7200 1466.0000 1.0000
30.7600 1479.0000 1.0000
30.8000 1491.0000 1.0000
30.8400 1536.0000 1.0000
30.8800 1445.0000 1.0000
30.9200 1434.0000 1.0000
30.9600 1430.0000 1.0000
31.0000 1495.0000 1.0000
31.0400 1497.0000 1.0000
31.0800 1397.0000 1.0000
31.1200 1503.0000 1.0000
31.1600 1435.0000 1.0000
31.2000 1434.0000 1.0000
31.2400 1412.0000 1.0000
31.2800 1419.0000 1.0000
31.3200 1377.0000 1.0000
31.3600 1368.0000 1.0000
31.4000 1409.0000 1.0000
31.4400 1417.0000 1.0000
31.4800 1398.0000 1.0000
31.5200 1409.0000 1.0000
31.5600 1421.0000 1.0000
31.6000 1387.0000 1.0000
31.6400 1389.0000 1.0000
31.6800 1431.0000 1.0000
31.7200 1368.0000 1.0000
31.7600 1441.0000 1.0000
31.8000 1414.0000 1.0000
31.8400 1434.0000 1.0000
31.8800 1434.0000 1.0000
31.9200 1448.0000 1.0000
31.9600 1418.0000 1.0000
32.0000 1461.0000 1.0000
32.0400 1417.0000 1.0000
32.0800 1429.0000 1.0000
32.1200 1446.0000 1.0000
32.1600 1396.0000 1.0000
32.2000 1379.0000 1.0000
32.2400 1401.0000 1.0000
32.2800 1313.0000 1.0000
32.3200 1359.0000 1.0000
32.3600 1363.0000 1.0000
32.4000 1349.0000 1.0000
32.4400 1377.0000 1.0000
32.4800 1378.0000 1.0000
32.5200 1322.0000 1.0000
32.5600 1340.0000 1.0000
32.6000 1393.0000 1.0000
32.6400 1349.0000 1.0000
32.6800 1312.0000 1.0000
32.7200 1341.0000 1.0000
32.7600 1360.0000 1.0000
32.8000 1358.0000 1.0000
32.8400 1308.0000 1.0000
32.8800 1319.0000 1.0000
32.9200 1366.0000 1.0000
32.9600 1343.0000 1.0000
33.0000 1286.0000 1.0000
33.0400 1358.0000 1.0000
33.0800 1278.0000 1.0000
33.1200 1340.0000 1.0000
33.1600 1301.0000 1.0000
33.2000 1321.0000 1.0000
33.2400 1284.0000 1.0000
33.2800 1340.0000 1.0000
33.3200 1375.0000 1.0000
33.3600 1373.0000 1.0000
33.4000 1274.0000 1.0000
33.4400 1296.0000 1.0000
33.4800 1312.0000 1.0000
33.5200 1317.0000 1.0000
33.5600 1317.0000 1.0000
33.6000 1392.0000 1.0000
33.6400 1292.0000 1.0000
33.6800 1345.0000 1.0000
33.7200 1384.0000 1.0000
33.7600 1448.0000 1.0000
33.8000 1472.0000 1.0000
33.8400 1456.0000 1.0000
33.8800 1490.0000 1.0000
33.9200 1503.0000 1.0000
33.9600 1558.0000 1.0000
34.0000 1547.0000 1.0000
34.0400 1465.0000 1.0000
34.0800 1461.0000 1.0000
34.1200 1508.0000 1.0000
34.1600 1496.0000 1.0000
34.2000 1632.0000 1.0000
34.2400 1707.0000 1.0000
34.2800 1883.0000 1.0000
34.3200 1967.0000 1.0000
34.3600 2367.0000 1.0000
34.4000 2688.0000 1.0000
34.4400 2935.0000 1.0000
34.4800 2922.0000 1.0000
34.5200 2881.0000 1.0000
34.5600 2473.0000 1.0000
34.6000 2178.0000 1.0000
34.6400 2016.0000 1.0000
34.6800 1740.0000 1.0000
34.7200 1708.0000 1.0000
34.7600 1615.0000 1.0000
34.8000 1427.0000 1.0000
34.8400 1422.0000 1.0000
34.8800 1353.0000 1.0000
34.9200 1285.0000 1.0000
34.9600 1294.0000 1.0000
35.0000 1251.0000 1.0000
35.0400 1264.0000 1.0000
35.0800 1205.0000 1.0000
35.1200 1262.0000 1.0000
35.1600 1166.0000 1.0000
35.2000 1179.0000 1.0000
35.2400 1194.0000 1.0000
35.2800 1185.0000 1.0000
35.3200 1178.0000 1.0000
35.3600 1194.0000 1.0000
35.4000 1125.0000 1.0000
35.4400 1144.0000 1.0000
35.4800 1136.0000 1.0000
35.5200 1092.0000 1.0000
35.5600 1188.0000 1.0000
35.6000 1149.0000 1.0000
35.6400 1151.0000 1.0000
35.6800 1135.0000 1.0000
35.7200 1158.0000 1.0000
35.7600 1143.0000 1.0000
35.8000 1181.0000 1.0000
35.8400 1100.0000 1.0000
35.8800 1148.0000 1.0000
35.9200 1138.0000 1.0000
35.9600 1136.0000 1.0000
36.0000 1138.0000 1.0000
36.0400 1158.0000 1.0000
36.0800 1160.0000 1.0000
36.1200 1189.0000 1.0000
36.1600 1264.0000 1.0000
36.2000 1214.0000 1.0000
36.2400 1244.0000 1.0000
36.2800 1349.0000 1.0000
36.3200 1467.0000 1.0000
36.3600 1466.0000 1.0000
36.4000 1494.0000 1.0000
36.4400 1512.0000 1.0000
36.4800 1399.0000 1.0000
36.5200 1292.0000 1.0000
36.5600 1271.0000 1.0000
36.6000 1195.0000 1.0000
36.6400 1157.0000 1.0000
36.6800 1119.0000 1.0000
36.7200 1117.0000 1.0000
36.7600 1070.0000 1.0000
36.8000 1043.0000 1.0000
36.8400 1050.0000 1.0000
36.8800 1033.0000 1.0000
36.9200 1002.0000 1.0000
36.9600 1024.0000 1.0000
37.0000 1046.0000 1.0000
37.0400 1040.0000 1.0000
37.0800 1004.0000 1.0000
37.1200 988.0000 1.0000
37.1600 1054.0000 1.0000
37.2000 1032.0000 1.0000
37.2400 1038.0000 1.0000
37.2800 1024.0000 1.0000
37.3200 1072.0000 1.0000
37.3600 1013.0000 1.0000
37.4000 1091.0000 1.0000
37.4400 1013.0000 1.0000
37.4800 1044.0000 1.0000
37.5200 1046.0000 1.0000
37.5600 1051.0000 1.0000
37.6000 1080.0000 1.0000
37.6400 1069.0000 1.0000
37.6800 1057.0000 1.0000
37.7200 1012.0000 1.0000
37.7600 1116.0000 1.0000
37.8000 1046.0000 1.0000
37.8400 1060.0000 1.0000
37.8800 1099.0000 1.0000
37.9200 1082.0000 1.0000
37.9600 1102.0000 1.0000
38.0000 1189.0000 1.0000
38.0400 1181.0000 1.0000
38.0800 1190.0000 1.0000
38.1200 1336.0000 1.0000
38.1600 1504.0000 1.0000
38.2000 1645.0000 1.0000
38.2400 1892.0000 1.0000
38.2800 2179.0000 1.0000
38.3200 2829.0000 1.0000
38.3600 3663.0000 1.0000
38.4000 4945.0000 1.0000
38.4400 6332.0000 1.0000
38.4800 7665.0000 1.0000
38.5200 7979.0000 1.0000
38.5600 7243.0000 1.0000
38.6000 6257.0000 1.0000
38.6400 4872.0000 1.0000
38.6800 3764.0000 1.0000
38.7200 2859.0000 1.0000
38.7600 2107.0000 1.0000
38.8000 1779.0000 1.0000
38.8400 1537.0000 1.0000
38.8800 1410.0000 1.0000
38.9200 1306.0000 1.0000
38.9600 1169.0000 1.0000
39.0000 1121.0000 1.0000
39.0400 1098.0000 1.0000
39.0800 1038.0000 1.0000
39.1200 1038.0000 1.0000
39.1600 1006.0000 1.0000
39.2000 955.0000 1.0000
39.2400 970.0000 1.0000
39.2800 991.0000 1.0000
39.3200 932.0000 1.0000
39.3600 925.0000 1.0000
39.4000 933.0000 1.0000
39.4400 1003.0000 1.0000
39.4800 965.0000 1.0000
39.5200 966.0000 1.0000
39.5600 953.0000 1.0000
39.6000 996.0000 1.0000
39.6400 994.0000 1.0000
39.6800 975.0000 1.0000
39.7200 899.0000 1.0000
39.7600 892.0000 1.0000
39.8000 976.0000 1.0000
39.8400 871.0000 1.0000
39.8800 908.0000 1.0000
39.9200 914.0000 1.0000
39.9600 890.0000 1.0000
40.0000 905.0000 1.0000
40.0400 865.0000 1.0000
40.0800 860.0000 1.0000
40.1200 863.0000 1.0000
40.1600 884.0000 1.0000
40.2000 862.0000 1.0000
40.2400 858.0000 1.0000
40.2800 875.0000 1.0000
40.3200 852.0000 1.0000
40.3600 852.0000 1.0000
40.4000 825.0000 1.0000
40.4400 881.0000 1.0000
40.4800 831.0000 1.0000
40.5200 881.0000 1.0000
40.5600 864.0000 1.0000
40.6000 903.0000 1.0000
40.6400 832.0000 1.0000
40.6800 867.0000 1.0000
40.7200 853.0000 1.0000
40.7600 854.0000 1.0000
40.8000 817.0000 1.0000
40.8400 878.0000 1.0000
40.8800 797.0000 1.0000
40.9200 858.0000 1.0000
40.9600 799.0000 1.0000
41.0000 829.0000 1.0000
41.0400 802.0000 1.0000
41.0800 877.0000 1.0000
41.1200 840.0000 1.0000
41.1600 865.0000 1.0000
41.2000 857.0000 1.0000
41.2400 860.0000 1.0000
41.2800 868.0000 1.0000
41.3200 864.0000 1.0000
41.3600 845.0000 1.0000
41.4000 864.0000 1.0000
41.4400 882.0000 1.0000
41.4800 891.0000 1.0000
41.5200 866.0000 1.0000
41.5600 856.0000 1.0000
41.6000 885.0000 1.0000
41.6400 854.0000 1.0000
41.6800 836.0000 1.0000
41.7200 869.0000 1.0000
41.7600 868.0000 1.0000
41.8000 821.0000 1.0000
41.8400 826.0000 1.0000
41.8800 852.0000 1.0000
41.9200 851.0000 1.0000
41.9600 835.0000 1.0000
42.0000 855.0000 1.0000
42.0400 821.0000 1.0000
42.0800 857.0000 1.0000
42.1200 763.0000 1.0000
42.1600 805.0000 1.0000
42.2000 797.0000 1.0000
42.2400 843.0000 1.0000
42.2800 854.0000 1.0000
42.3200 827.0000 1.0000
42.3600 852.0000 1.0000
42.4000 829.0000 1.0000
42.4400 851.0000 1.0000
42.4800 806.0000 1.0000
42.5200 760.0000 1.0000
42.5600 841.0000 1.0000
42.6000 830.0000 1.0000
42.6400 818.0000 1.0000
42.6800 819.0000 1.0000
42.7200 850.0000 1.0000
42.7600 811.0000 1.0000
42.8000 828.0000 1.0000
42.8400 801.0000 1.0000
42.8800 844.0000 1.0000
42.9200 823.0000 1.0000
42.9600 820.0000 1.0000
43.0000 870.0000 1.0000
43.0400 862.0000 1.0000
43.0800 854.0000 1.0000
43.1200 933.0000 1.0000
43.1600 913.0000 1.0000
43.2000 945.0000 1.0000
43.2400 914.0000 1.0000
43.2800 897.0000 1.0000
43.3200 882.0000 1.0000
43.3600 877.0000 1.0000
43.4000 860.0000 1.0000
43.4400 884.0000 1.0000
43.4800 845.0000 1.0000
43.5200 849.0000 1.0000
43.5600 841.0000 1.0000
43.6000 800.0000 1.0000
43.6400 795.0000 1.0000
43.6800 835.0000 1.0000
43.7200 841.0000 1.0000
43.7600 806.0000 1.0000
43.8000 814.0000 1.0000
43.8400 806.0000 1.0000
43.8800 815.0000 1.0000
43.9200 825.0000 1.0000
43.9600 800.0000 1.0000
44.0000 797.0000 1.0000
44.0400 768.0000 1.0000
44.0800 765.0000 1.0000
44.1200 789.0000 1.0000
44.1600 806.0000 1.0000
44.2000 836.0000 1.0000
44.2400 805.0000 1.0000
44.2800 795.0000 1.0000
44.3200 813.0000 1.0000
44.3600 808.0000 1.0000
44.4000 774.0000 1.0000
44.4400 799.0000 1.0000
44.4800 808.0000 1.0000
44.5200 759.0000 1.0000
44.5600 792.0000 1.0000
44.6000 775.0000 1.0000
44.6400 811.0000 1.0000
44.6800 768.0000 1.0000
44.7200 782.0000 1.0000
44.7600 757.0000 1.0000
44.8000 766.0000 1.0000
44.8400 769.0000 1.0000
44.8800 808.0000 1.0000
44.9200 745.0000 1.0000
44.9600 781.0000 1.0000
45.0000 775.0000 1.0000
45.0400 780.0000 1.0000
45.0800 783.0000 1.0000
45.1200 770.0000 1.0000
45.1600 755.0000 1.0000
45.2000 737.0000 1.0000
45.2400 754.0000 1.0000
45.2800 803.0000 1.0000
45.3200 752.0000 1.0000
45.3600 785.0000 1.0000
45.4000 749.0000 1.0000
45.4400 807.0000 1.0000
45.4800 750.0000 1.0000
45.5200 773.0000 1.0000
45.5600 758.0000 1.0000
45.6000 823.0000 1.0000
45.6400 743.0000 1.0000
45.6800 796.0000 1.0000
45.7200 760.0000 1.0000
45.7600 784.0000 1.0000
45.8000 810.0000 1.0000
45.8400 783.0000 1.0000
45.8800 759.0000 1.0000
45.9200 760.0000 1.0000
45.9600 737.0000 1.0000
46.0000 795.0000 1.0000
46.0400 752.0000 1.0000
46.0800 743.0000 1.0000
46.1200 758.0000 1.0000
46.1600 708.0000 1.0000
46.2000 785.0000 1.0000
46.2400 764.0000 1.0000
46.2800 768.0000 1.0000
46.3200 732.0000 1.0000
46.3600 748.0000 1.0000
46.4000 759.0000 1.0000
46.4400 739.0000 1.0000
46.4800 707.0000 1.0000
46.5200 755.0000 1.0000
46.5600 742.0000 1.0000
46.6000 739.0000 1.0000
46.6400 750.0000 1.0000
46.6800 713.0000 1.0000
46.7200 725.0000 1.0000
46.7600 762.0000 1.0000
46.8000 773.0000 1.0000
46.8400 761.0000 1.0000
46.8800 763.0000 1.0000
46.9200 780.0000 1.0000
46.9600 751.0000 1.0000
47.0000 787.0000 1.0000
47.0400 738.0000 1.0000
47.0800 747.0000 1.0000
47.1200 760.0000 1.0000
47.1600 731.0000 1.0000
47.2000 734.0000 1.0000
47.2400 761.0000 1.0000
47.2800 738.0000 1.0000
47.3200 719.0000 1.0000
47.3600 730.0000 1.0000
47.4000 704.0000 1.0000
47.4400 719.0000 1.0000
47.4800 770.0000 1.0000
47.5200 752.0000 1.0000
47.5600 780.0000 1.0000
47.6000 730.0000 1.0000
47.6400 725.0000 1.0000
47.6800 692.0000 1.0000
47.7200 685.0000 1.0000
47.7600 705.0000 1.0000
47.8000 712.0000 1.0000
47.8400 721.0000 1.0000
47.8800 738.0000 1.0000
47.9200 666.0000 1.0000
47.9600 692.0000 1.0000
48.0000 758.0000 1.0000
48.0400 780.0000 1.0000
48.0800 700.0000 1.0000
48.1200 724.0000 1.0000
48.1600 691.0000 1.0000
48.2000 701.0000 1.0000
48.2400 723.0000 1.0000
48.2800 729.0000 1.0000
48.3200 709.0000 1.0000
48.3600 718.0000 1.0000
48.4000 746.0000 1.0000
48.4400 718.0000 1.0000
48.4800 693.0000 1.0000
48.5200 736.0000 1.0000
48.5600 708.0000 1.0000
48.6000 723.0000 1.0000
48.6400 701.0000 1.0000
48.6800 718.0000 1.0000
48.7200 684.0000 1.0000
48.7600 713.0000 1.0000
48.8000 709.0000 1.0000
48.8400 686.0000 1.0000
48.8800 710.0000 1.0000
48.9200 699.0000 1.0000
48.9600 722.0000 1.0000
49.0000 721.0000 1.0000
49.0400 654.0000 1.0000
49.0800 728.0000 1.0000
49.1200 713.0000 1.0000
49.1600 680.0000 1.0000
49.2000 663.0000 1.0000
49.2400 739.0000 1.0000
49.2800 704.0000 1.0000
49.3200 703.0000 1.0000
49.3600 753.0000 1.0000
49.4000 698.0000 1.0000
49.4400 698.0000 1.0000
49.4800 669.0000 1.0000
49.5200 690.0000 1.0000
49.5600 725.0000 1.0000
49.6000 690.0000 1.0000
49.6400 746.0000 1.0000
49.6800 706.0000 1.0000
49.7200 708.0000 1.0000
49.7600 685.0000 1.0000
49.8000 738.0000 1.0000
49.8400 728.0000 1.0000
49.8800 694.0000 1.0000
49.9200 704.0000 1.0000
49.9600 708.0000 1.0000
50.0000 731.0000 1.0000
50.0400 694.0000 1.0000
50.0800 689.0000 1.0000
50.1200 714.0000 1.0000
50.1600 702.0000 1.0000
50.2000 713.0000 1.0000
50.2400 736.0000 1.0000
50.2800 709.0000 1.0000
50.3200 752.0000 1.0000
50.3600 769.0000 1.0000
50.4000 753.0000 1.0000
50.4400 751.0000 1.0000
50.4800 719.0000 1.0000
50.5200 740.0000 1.0000
50.5600 728.0000 1.0000
50.6000 742.0000 1.0000
50.6400 730.0000 1.0000
50.6800 673.0000 1.0000
50.7200 724.0000 1.0000
50.7600 721.0000 1.0000
50.8000 689.0000 1.0000
50.8400 741.0000 1.0000
50.8800 721.0000 1.0000
50.9200 753.0000 1.0000
50.9600 734.0000 1.0000
51.0000 703.0000 1.0000
51.0400 756.0000 1.0000
51.0800 732.0000 1.0000
51.1200 721.0000 1.0000
51.1600 734.0000 1.0000
51.2000 752.0000 1.0000
51.2400 746.0000 1.0000
51.2800 662.0000 1.0000
51.3200 712.0000 1.0000
51.3600 726.0000 1.0000
51.4000 735.0000 1.0000
51.4400 745.0000 1.0000
51.4800 733.0000 1.0000
51.5200 726.0000 1.0000
51.5600 727.0000 1.0000
51.6000 751.0000 1.0000
51.6400 767.0000 1.0000
51.6800 757.0000 1.0000
51.7200 789.0000 1.0000
51.7600 764.0000 1.0000
51.8000 821.0000 1.0000
51.8400 842.0000 1.0000
51.8800 904.0000 1.0000
51.9200 1036.0000 1.0000
51.9600 1164.0000 1.0000
52.0000 1265.0000 1.0000
52.0400 1527.0000 1.0000
52.0800 1882.0000 1.0000
52.1200 2610.0000 1.0000
52.1600 3604.0000 1.0000
52.2000 4789.0000 1.0000
52.2400 5288.0000 1.0000
52.2800 4596.0000 1.0000
52.3200 4091.0000 1.0000
52.3600 3898.0000 1.0000
52.4000 3270.0000 1.0000
52.4400 2448.0000 1.0000
52.4800 1858.0000 1.0000
52.5200 1524.0000 1.0000
52.5600 1287.0000 1.0000
52.6000 1110.0000 1.0000
52.6400 1069.0000 1.0000
52.6800 940.0000 1.0000
52.7200 883.0000 1.0000
52.7600 868.0000 1.0000
52.8000 841.0000 1.0000
52.8400 805.0000 1.0000
52.8800 793.0000 1.0000
52.9200 781.0000 1.0000
52.9600 776.0000 1.0000
53.0000 779.0000 1.0000
53.0400 742.0000 1.0000
53.0800 718.0000 1.0000
53.1200 774.0000 1.0000
53.1600 712.0000 1.0000
53.2000 691.0000 1.0000
53.2400 723.0000 1.0000
53.2800 726.0000 1.0000
53.3200 711.0000 1.0000
53.3600 740.0000 1.0000
53.4000 706.0000 1.0000
53.4400 696.0000 1.0000
53.4800 682.0000 1.0000
53.5200 707.0000 1.0000
53.5600 694.0000 1.0000
53.6000 702.0000 1.0000
53.6400 708.0000 1.0000
53.6800 672.0000 1.0000
53.7200 695.0000 1.0000
53.7600 700.0000 1.0000
53.8000 715.0000 1.0000
53.8400 688.0000 1.0000
53.8800 712.0000 1.0000
53.9200 666.0000 1.0000
53.9600 671.0000 1.0000
54.0000 744.0000 1.0000
54.0400 679.0000 1.0000
54.0800 686.0000 1.0000
54.1200 698.0000 1.0000
54.1600 714.0000 1.0000
54.2000 684.0000 1.0000
54.2400 707.0000 1.0000
54.2800 705.0000 1.0000
54.3200 670.0000 1.0000
54.3600 670.0000 1.0000
54.4000 673.0000 1.0000
54.4400 692.0000 1.0000
54.4800 667.0000 1.0000
54.5200 685.0000 1.0000
54.5600 715.0000 1.0000
54.6000 702.0000 1.0000
54.6400 771.0000 1.0000
54.6800 740.0000 1.0000
54.7200 725.0000 1.0000
54.7600 738.0000 1.0000
54.8000 763.0000 1.0000
54.8400 745.0000 1.0000
54.8800 797.0000 1.0000
54.9200 782.0000 1.0000
54.9600 787.0000 1.0000
55.0000 806.0000 1.0000
55.0400 834.0000 1.0000
55.0800 862.0000 1.0000
55.1200 934.0000 1.0000
55.1600 984.0000 1.0000
55.2000 1022.0000 1.0000
55.2400 1138.0000 1.0000
55.2800 1078.0000 1.0000
55.3200 1077.0000 1.0000
55.3600 1046.0000 1.0000
55.4000 1036.0000 1.0000
55.4400 922.0000 1.0000
55.4800 899.0000 1.0000
55.5200 845.0000 1.0000
55.5600 827.0000 1.0000
55.6000 755.0000 1.0000
55.6400 745.0000 1.0000
55.6800 680.0000 1.0000
55.7200 740.0000 1.0000
55.7600 708.0000 1.0000
55.8000 692.0000 1.0000
55.8400 719.0000 1.0000
55.8800 718.0000 1.0000
55.9200 651.0000 1.0000
55.9600 698.0000 1.0000
56.0000 671.0000 1.0000
56.0400 699.0000 1.0000
56.0800 714.0000 1.0000
56.1200 702.0000 1.0000
56.1600 676.0000 1.0000
56.2000 666.0000 1.0000
56.2400 667.0000 1.0000
56.2800 666.0000 1.0000
56.3200 646.0000 1.0000
56.3600 700.0000 1.0000
56.4000 647.0000 1.0000
56.4400 665.0000 1.0000
56.4800 666.0000 1.0000
56.5200 672.0000 1.0000
56.5600 664.0000 1.0000
56.6000 653.0000 1.0000
56.6400 667.0000 1.0000
56.6800 665.0000 1.0000
56.7200 689.0000 1.0000
56.7600 665.0000 1.0000
56.8000 672.0000 1.0000
56.8400 675.0000 1.0000
56.8800 652.0000 1.0000
56.9200 693.0000 1.0000
56.9600 654.0000 1.0000
57.0000 649.0000 1.0000
57.0400 668.0000 1.0000
57.0800 665.0000 1.0000
57.1200 669.0000 1.0000
57.1600 684.0000 1.0000
57.2000 650.0000 1.0000
57.2400 678.0000 1.0000
57.2800 673.0000 1.0000
57.3200 694.0000 1.0000
57.3600 667.0000 1.0000
57.4000 681.0000 1.0000
57.4400 687.0000 1.0000
57.4800 681.0000 1.0000
57.5200 677.0000 1.0000
57.5600 641.0000 1.0000
57.6000 684.0000 1.0000
57.6400 668.0000 1.0000
57.6800 662.0000 1.0000
57.7200 674.0000 1.0000
57.7600 667.0000 1.0000
57.8000 651.0000 1.0000
57.8400 673.0000 1.0000
57.8800 666.0000 1.0000
57.9200 639.0000 1.0000
57.9600 712.0000 1.0000
58.0000 667.0000 1.0000
58.0400 677.0000 1.0000
58.0800 672.0000 1.0000
58.1200 709.0000 1.0000
58.1600 674.0000 1.0000
58.2000 651.0000 1.0000
58.2400 707.0000 1.0000
58.2800 657.0000 1.0000
58.3200 687.0000 1.0000
58.3600 680.0000 1.0000
58.4000 700.0000 1.0000
58.4400 635.0000 1.0000
58.4800 678.0000 1.0000
58.5200 640.0000 1.0000
58.5600 655.0000 1.0000
58.6000 641.0000 1.0000
58.6400 653.0000 1.0000
58.6800 659.0000 1.0000
58.7200 670.0000 1.0000
58.7600 646.0000 1.0000
58.8000 665.0000 1.0000
58.8400 659.0000 1.0000
58.8800 694.0000 1.0000
58.9200 647.0000 1.0000
58.9600 660.0000 1.0000
59.0000 675.0000 1.0000
59.0400 687.0000 1.0000
59.0800 678.0000 1.0000
59.1200 666.0000 1.0000
59.1600 673.0000 1.0000
59.2000 716.0000 1.0000
59.2400 693.0000 1.0000
59.2800 639.0000 1.0000
59.3200 719.0000 1.0000
59.3600 648.0000 1.0000
59.4000 675.0000 1.0000
59.4400 624.0000 1.0000
59.4800 716.0000 1.0000
59.5200 646.0000 1.0000
59.5600 650.0000 1.0000
59.6000 684.0000 1.0000
59.6400 655.0000 1.0000
59.6800 644.0000 1.0000
59.7200 675.0000 1.0000
59.7600 658.0000 1.0000
59.8000 639.0000 1.0000
59.8400 672.0000 1.0000
59.8800 645.0000 1.0000
59.9200 695.0000 1.0000
59.9600 665.0000 1.0000
60.0000 683.0000 1.0000
60.0400 658.0000 1.0000
60.0800 655.0000 1.0000
60.1200 665.0000 1.0000
60.1600 666.0000 1.0000
60.2000 668.0000 1.0000
60.2400 690.0000 1.0000
60.2800 683.0000 1.0000
60.3200 673.0000 1.0000
60.3600 662.0000 1.0000
60.4000 667.0000 1.0000
60.4400 686.0000 1.0000
60.4800 663.0000 1.0000
60.5200 634.0000 1.0000
60.5600 647.0000 1.0000
60.6000 652.0000 1.0000
60.6400 652.0000 1.0000
60.6800 667.0000 1.0000
60.7200 711.0000 1.0000
60.7600 679.0000 1.0000
60.8000 629.0000 1.0000
60.8400 646.0000 1.0000
60.8800 660.0000 1.0000
60.9200 648.0000 1.0000
60.9600 635.0000 1.0000
61.0000 635.0000 1.0000
61.0400 681.0000 1.0000
61.0800 714.0000 1.0000
61.1200 699.0000 1.0000
61.1600 657.0000 1.0000
61.2000 684.0000 1.0000
61.2400 728.0000 1.0000
61.2800 704.0000 1.0000
61.3200 700.0000 1.0000
61.3600 670.0000 1.0000
61.4000 651.0000 1.0000
61.4400 675.0000 1.0000
61.4800 713.0000 1.0000
61.5200 703.0000 1.0000
61.5600 697.0000 1.0000
61.6000 707.0000 1.0000
61.6400 732.0000 1.0000
61.6800 713.0000 1.0000
61.7200 719.0000 1.0000
61.7600 774.0000 1.0000
61.8000 747.0000 1.0000
61.8400 766.0000 1.0000
61.8800 738.0000 1.0000
61.9200 820.0000 1.0000
61.9600 882.0000 1.0000
62.0000 956.0000 1.0000
62.0400 1049.0000 1.0000
62.0800 1173.0000 1.0000
62.1200 1321.0000 1.0000
62.1600 1483.0000 1.0000
62.2000 1637.0000 1.0000
62.2400 1729.0000 1.0000
62.2800 1743.0000 1.0000
62.3200 1689.0000 1.0000
62.3600 1593.0000 1.0000
62.4000 1494.0000 1.0000
62.4400 1429.0000 1.0000
62.4800 1254.0000 1.0000
62.5200 1196.0000 1.0000
62.5600 1060.0000 1.0000
62.6000 1009.0000 1.0000
62.6400 985.0000 1.0000
62.6800 889.0000 1.0000
62.7200 877.0000 1.0000
62.7600 861.0000 1.0000
62.8000 805.0000 1.0000
62.8400 775.0000 1.0000
62.8800 731.0000 1.0000
62.9200 800.0000 1.0000
62.9600 730.0000 1.0000
63.0000 786.0000 1.0000
63.0400 721.0000 1.0000
63.0800 731.0000 1.0000
63.1200 770.0000 1.0000
63.1600 712.0000 1.0000
63.2000 710.0000 1.0000
63.2400 678.0000 1.0000
63.2800 701.0000 1.0000
63.3200 731.0000 1.0000
63.3600 685.0000 1.0000
63.4000 692.0000 1.0000
63.4400 716.0000 1.0000
63.4800 687.0000 1.0000
63.5200 655.0000 1.0000
63.5600 654.0000 1.0000
63.6000 715.0000 1.0000
63.6400 649.0000 1.0000
63.6800 677.0000 1.0000
63.7200 658.0000 1.0000
63.7600 659.0000 1.0000
63.8000 673.0000 1.0000
63.8400 671.0000 1.0000
63.8800 682.0000 1.0000
63.9200 677.0000 1.0000
63.9600 706.0000 1.0000
64.0000 663.0000 1.0000
64.0400 659.0000 1.0000
64.0800 693.0000 1.0000
64.1200 674.0000 1.0000
64.1600 702.0000 1.0000
64.2000 709.0000 1.0000
64.2400 694.0000 1.0000
64.2800 630.0000 1.0000
64.3200 684.0000 1.0000
64.3600 719.0000 1.0000
64.4000 718.0000 1.0000
64.4400 758.0000 1.0000
64.4800 729.0000 1.0000
64.5200 714.0000 1.0000
64.5600 713.0000 1.0000
64.6000 725.0000 1.0000
64.6400 799.0000 1.0000
64.6800 719.0000 1.0000
64.7200 725.0000 1.0000
64.7600 741.0000 1.0000
64.8000 773.0000 1.0000
64.8400 744.0000 1.0000
64.8800 789.0000 1.0000
64.9200 762.0000 1.0000
64.9600 688.0000 1.0000
65.0000 719.0000 1.0000
65.0400 736.0000 1.0000
65.0800 699.0000 1.0000
65.1200 711.0000 1.0000
65.1600 661.0000 1.0000
65.2000 713.0000 1.0000
65.2400 728.0000 1.0000
65.2800 685.0000 1.0000
65.3200 738.0000 1.0000
65.3600 696.0000 1.0000
65.4000 730.0000 1.0000
65.4400 704.0000 1.0000
65.4800 722.0000 1.0000
65.5200 682.0000 1.0000
65.5600 744.0000 1.0000
65.6000 725.0000 1.0000
65.6400 716.0000 1.0000
65.6800 759.0000 1.0000
65.7200 742.0000 1.0000
65.7600 787.0000 1.0000
65.8000 809.0000 1.0000
65.8400 860.0000 1.0000
65.8800 885.0000 1.0000
65.9200 984.0000 1.0000
65.9600 1042.0000 1.0000
66.0000 1193.0000 1.0000
66.0400 1471.0000 1.0000
66.0800 1642.0000 1.0000
66.1200 2172.0000 1.0000
66.1600 2542.0000 1.0000
66.2000 2803.0000 1.0000
66.2400 2622.0000 1.0000
66.2800 2635.0000 1.0000
66.3200 2352.0000 1.0000
66.3600 2354.0000 1.0000
66.4000 2129.0000 1.0000
66.4400 1864.0000 1.0000
66.4800 1628.0000 1.0000
66.5200 1347.0000 1.0000
66.5600 1234.0000 1.0000
66.6000 1030.0000 1.0000
66.6400 945.0000 1.0000
66.6800 916.0000 1.0000
66.7200 849.0000 1.0000
66.7600 807.0000 1.0000
66.8000 773.0000 1.0000
66.8400 776.0000 1.0000
66.8800 733.0000 1.0000
66.9200 675.0000 1.0000
66.9600 706.0000 1.0000
67.0000 732.0000 1.0000
67.0400 676.0000 1.0000
67.0800 660.0000 1.0000
67.1200 699.0000 1.0000
67.1600 674.0000 1.0000
67.2000 648.0000 1.0000
67.2400 671.0000 1.0000
67.2800 621.0000 1.0000
67.3200 636.0000 1.0000
67.3600 634.0000 1.0000
67.4000 648.0000 1.0000
67.4400 632.0000 1.0000
67.4800 599.0000 1.0000
67.5200 628.0000 1.0000
67.5600 608.0000 1.0000
67.6000 664.0000 1.0000
67.6400 650.0000 1.0000
67.6800 595.0000 1.0000
67.7200 654.0000 1.0000
67.7600 623.0000 1.0000
67.8000 626.0000 1.0000
67.8400 649.0000 1.0000
67.8800 624.0000 1.0000
67.9200 636.0000 1.0000
67.9600 617.0000 1.0000
68.0000 603.0000 1.0000
68.0400 594.0000 1.0000
68.0800 589.0000 1.0000
68.1200 606.0000 1.0000
68.1600 619.0000 1.0000
68.2000 635.0000 1.0000
68.2400 625.0000 1.0000
68.2800 584.0000 1.0000
68.3200 595.0000 1.0000
68.3600 624.0000 1.0000
68.4000 607.0000 1.0000
68.4400 629.0000 1.0000
68.4800 603.0000 1.0000
68.5200 591.0000 1.0000
68.5600 620.0000 1.0000
68.6000 603.0000 1.0000
68.6400 608.0000 1.0000
68.6800 580.0000 1.0000
68.7200 605.0000 1.0000
68.7600 605.0000 1.0000
68.8000 595.0000 1.0000
68.8400 624.0000 1.0000
68.8800 615.0000 1.0000
68.9200 583.0000 1.0000
68.9600 603.0000 1.0000
69.0000 560.0000 1.0000
69.0400 606.0000 1.0000
69.0800 598.0000 1.0000
69.1200 600.0000 1.0000
69.1600 611.0000 1.0000
69.2000 627.0000 1.0000
69.2400 599.0000 1.0000
69.2800 647.0000 1.0000
69.3200 609.0000 1.0000
69.3600 556.0000 1.0000
69.4000 600.0000 1.0000
69.4400 596.0000 1.0000
69.4800 595.0000 1.0000
69.5200 632.0000 1.0000
69.5600 637.0000 1.0000
69.6000 613.0000 1.0000
69.6400 613.0000 1.0000
69.6800 635.0000 1.0000
69.7200 632.0000 1.0000
69.7600 614.0000 1.0000
69.8000 606.0000 1.0000
69.8400 634.0000 1.0000
69.8800 595.0000 1.0000
69.9200 556.0000 1.0000
69.9600 602.0000 1.0000
70.0000 541.0000 1.0000
*RAS_INT_END
*RAS_TEMPERATURE_START
*RAS_TEMPERATURE_END
*RAS_DATA_END