File: Data/Dataset1_Only_water/5_XRD/No_057_deposition_3h_TiO2_Air_4.ras
*RAS_DATA_START
*RAS_HEADER_START
*DISP_FMT_X "%.2f"
*DISP_FMT_Y "%.0f"
*DISP_FULLSCALE "16990.0000000000"
*DISP_LINE_COLOR "255.0000000000"
*DISP_LINE_STYLE "0.0000000000"
*DISP_LINE_WIDTH "0.2500000000"
*DISP_NOTE "測定データ-2"
*DISP_OFFSET_Y "0.0000000000"
*DISP_PEAKSEARCH_UNIT_Y "cps"
*DISP_RANGE_BOTTOM "0.0000000000"
*DISP_RANGE_LEFT "20.0000000000"
*DISP_RANGE_LOGCUTOFF "0.0100000000"
*DISP_RANGE_RIGHT "70.0000000000"
*DISP_RANGE_TOP "16990.0000000000"
*DISP_SCALE_MODE_Y "0.0000000000"
*DISP_TAB_NAME "2θ/θ"
*DISP_TITLE_Y "強度"
*DISP_UNIT_Y "cps"
*DISP_WINDOW_NAME "MSG_MACROENGINE"
*FILE_COMMENT " "
*FILE_MD5 ""
*FILE_MEMO " "
*FILE_OPERATOR "Administrator"
*FILE_SAMPLE " "
*FILE_TYPE "RAS_RAW"
*FILE_USERGROUP "システムマネージャ"
*FILE_VERSION "1.0000000000"
*HW_ATTACHMENT_ID "ATT0025"
*HW_ATTACHMENT_NAME "標準|Standard"
*HW_COUNTER_ID-0 "CUT0025"
*HW_COUNTER_ID-1 "CUT0020"
*HW_COUNTER_ID-2 "CUT0020"
*HW_COUNTER_ID-3 "CSL0021"
*HW_COUNTER_ID-4 "CMC0021"
*HW_COUNTER_NAME-0 "D/teX Ultra|D/teX Ultra"
*HW_COUNTER_NAME-1 "None|None"
*HW_COUNTER_NAME-2 "None|None"
*HW_COUNTER_NAME-3 "BBM|BBM"
*HW_COUNTER_NAME-4 "検出器モノクロメータ|Detector monochromator"
*HW_COUNTER_SELECT_NAME "D/teX Ultra|D/teX Ultra"
*HW_GONIOMETER_ID "GON0023"
*HW_GONIOMETER_NAME "SmartLab|SmartLab"
*HW_GONIOMETER_RADIUS-0 "90.0"
*HW_GONIOMETER_RADIUS-1 "114.0"
*HW_GONIOMETER_RADIUS-2 "190.0"
*HW_GONIOMETER_RADIUS-3 "300.0"
*HW_GONIOMETER_RADIUS-4 "187.0"
*HW_GONIOMETER_RADIUS-5 "300.0"
*HW_GONIOMETER_RADIUS-6 "113.0"
*HW_GONIOMETER_RADIUS-7 "331.0"
*HW_I_OPT_ID-0 "CBO0021"
*HW_I_OPT_ID-1 "ICR0023"
*HW_I_OPT_ID-2 "ISL0021"
*HW_I_OPT_ID-3 "ISO0021"
*HW_I_OPT_ID-4 "IAD0021"
*HW_I_OPT_ID-5 "IPR0001"
*HW_I_OPT_NAME-0 "CBOユニット|CBO unit"
*HW_I_OPT_NAME-1 "標準入射光学ユニット|Standard incident optical unit"
*HW_I_OPT_NAME-2 "標準入射スリットボックス|Standard incident slit box"
*HW_I_OPT_NAME-3 "入射平行スリット|Incident parallel slit"
*HW_I_OPT_NAME-4 "長手制限スリット|Length limiting slit"
*HW_I_OPT_NAME-5 "None|None"
*HW_R_ATTENUATER_AUTOMODE "0"
*HW_R_OPT_ID-0 "RSS0021"
*HW_R_OPT_ID-1 "RCR0023"
*HW_R_OPT_ID-2 "RSO0021"
*HW_R_OPT_ID-3 "RRS0021"
*HW_R_OPT_ID-4 "ATN0021"
*HW_R_OPT_ID-5 "RFL0021"
*HW_R_OPT_ID-6 "RAD0021"
*HW_R_OPT_NAME-0 "標準受光スリットボックス1|Standard receiving slit box # 1"
*HW_R_OPT_NAME-1 "標準受光光学ユニット1|Standard receiving unit # 1"
*HW_R_OPT_NAME-2 "標準受光光学ユニット2|Standard receiving optical unit # 2"
*HW_R_OPT_NAME-3 "標準受光スリットボックス2|Standard receiving slit box # 2"
*HW_R_OPT_NAME-4 "標準アッテネータ|Standard Attenuator"
*HW_R_OPT_NAME-5 "Cu Kβ|Cu K-beta"
*HW_R_OPT_NAME-6 "調整用受光スリット|Alignment receiving slit"
*HW_SAMPLE_HOLDER_ID "SMP0023"
*HW_SAMPLE_HOLDER_NAME "標準Zステージ|Standard Z stage"
*HW_XG_CURRENT_MAX "50"
*HW_XG_CURRENT_MIN "2"
*HW_XG_CURRENT_RESOLUTION "1"
*HW_XG_CURRENT_UNIT "mA"
*HW_XG_FOCUS "1mm x 10mm"
*HW_XG_FOCUS_TYPE "Normal"
*HW_XG_ID ""
*HW_XG_NAME "3kW 封入管(ID:1200)|3kW Sealed tube(ID:1200)"
*HW_XG_TARGET_ATOMIC_NUMBER "29.0000000000"
*HW_XG_TARGET_NAME "Cu"
*HW_XG_TYPE "Hermetic"
*HW_XG_VOLTAGE_MAX "60"
*HW_XG_VOLTAGE_MIN "20"
*HW_XG_VOLTAGE_RESOLUTION "1"
*HW_XG_VOLTAGE_UNIT "kV"
*HW_XG_WATT_MAX "1.500"
*HW_XG_WATT_UNIT "kW"
*HW_XG_WAVE_LENGTH_ALPHA1 "1.540593"
*HW_XG_WAVE_LENGTH_ALPHA2 "1.544414"
*HW_XG_WAVE_LENGTH_BETA "1.392250"
*MEAS_COND_AXIS_NAME-0 "2θ/θ"
*MEAS_COND_AXIS_NAME-1 "2θ"
*MEAS_COND_AXIS_NAME-2 "ω"
*MEAS_COND_AXIS_NAME-3 "Z"
*MEAS_COND_AXIS_NAME-4 "2θ/ω"
*MEAS_COND_AXIS_NAME-5 "θs"
*MEAS_COND_AXIS_NAME-6 "θd"
*MEAS_COND_AXIS_NAME-7 "Ts"
*MEAS_COND_AXIS_NAME-8 "CBO選択スリット"
*MEAS_COND_AXIS_NAME-9 "M"
*MEAS_COND_AXIS_NAME-10 "入射平行スリット"
*MEAS_COND_AXIS_NAME-11 "入射スリット"
*MEAS_COND_AXIS_NAME-12 ""
*MEAS_COND_AXIS_NAME-13 "Zs"
*MEAS_COND_AXIS_NAME-14 "入射光学素子"
*MEAS_COND_AXIS_NAME-15 "長手制限スリット"
*MEAS_COND_AXIS_NAME-16 "センタースリット"
*MEAS_COND_AXIS_NAME-17 "フィルター"
*MEAS_COND_AXIS_NAME-18 "受光スリット1"
*MEAS_COND_AXIS_NAME-19 "受光スリット2"
*MEAS_COND_AXIS_NAME-20 "受光光学素子"
*MEAS_COND_AXIS_NAME-21 "受光平行スリット"
*MEAS_COND_AXIS_NAME-22 "調整用受光スリット"
*MEAS_COND_AXIS_NAME-23 ""
*MEAS_COND_AXIS_NAME-24 ""
*MEAS_COND_AXIS_NAME-25 "Zd"
*MEAS_COND_AXIS_NAME-26 "アッテネータ"
*MEAS_COND_AXIS_NAME-27 "検出器モノクロメータ"
*MEAS_COND_AXIS_NAME-28 "モノクロメータスリット"
*MEAS_COND_AXIS_NAME-29 "プライマリビーム"
*MEAS_COND_AXIS_NAME-30 "PHA"
*MEAS_COND_AXIS_NAME_INTERNAL-0 "TwoThetaTheta"
*MEAS_COND_AXIS_NAME_INTERNAL-1 "TwoTheta"
*MEAS_COND_AXIS_NAME_INTERNAL-2 "Omega"
*MEAS_COND_AXIS_NAME_INTERNAL-3 "Z"
*MEAS_COND_AXIS_NAME_INTERNAL-4 "TwoThetaOmega"
*MEAS_COND_AXIS_NAME_INTERNAL-5 "ThetaS"
*MEAS_COND_AXIS_NAME_INTERNAL-6 "ThetaD"
*MEAS_COND_AXIS_NAME_INTERNAL-7 "Ts"
*MEAS_COND_AXIS_NAME_INTERNAL-8 "CBO"
*MEAS_COND_AXIS_NAME_INTERNAL-9 "CBO-M"
*MEAS_COND_AXIS_NAME_INTERNAL-10 "IncidentSollerSlit"
*MEAS_COND_AXIS_NAME_INTERNAL-11 "IncidentSlitBox"
*MEAS_COND_AXIS_NAME_INTERNAL-12 "IncidentSlitBox-_Axis"
*MEAS_COND_AXIS_NAME_INTERNAL-13 "Zs"
*MEAS_COND_AXIS_NAME_INTERNAL-14 "IncidentMonochromator"
*MEAS_COND_AXIS_NAME_INTERNAL-15 "IncidentAxdSlit"
*MEAS_COND_AXIS_NAME_INTERNAL-16 "CenterSlit"
*MEAS_COND_AXIS_NAME_INTERNAL-17 "Filter"
*MEAS_COND_AXIS_NAME_INTERNAL-18 "ReceivingSlitBox1"
*MEAS_COND_AXIS_NAME_INTERNAL-19 "ReceivingSlitBox2"
*MEAS_COND_AXIS_NAME_INTERNAL-20 "ReceivingOptics"
*MEAS_COND_AXIS_NAME_INTERNAL-21 "ReceivingSollerSlit"
*MEAS_COND_AXIS_NAME_INTERNAL-22 "ReceivingAxdSlit"
*MEAS_COND_AXIS_NAME_INTERNAL-23 "ReceivingSlitBox1-_Axis"
*MEAS_COND_AXIS_NAME_INTERNAL-24 "ReceivingSlitBox2-_Axis"
*MEAS_COND_AXIS_NAME_INTERNAL-25 "ReceivingSlitBox2-Zd"
*MEAS_COND_AXIS_NAME_INTERNAL-26 "Attenuator"
*MEAS_COND_AXIS_NAME_INTERNAL-27 "CounterMonochromator"
*MEAS_COND_AXIS_NAME_INTERNAL-28 "CounterSlit"
*MEAS_COND_AXIS_NAME_INTERNAL-29 "IncidentPrimary"
*MEAS_COND_AXIS_NAME_INTERNAL-30 "PHA"
*MEAS_COND_AXIS_NAME_MAGICNO-0 "83951616.0000000000"
*MEAS_COND_AXIS_NAME_MAGICNO-1 "268632064.0000000000"
*MEAS_COND_AXIS_NAME_MAGICNO-2 "268500992.0000000000"
*MEAS_COND_AXIS_NAME_MAGICNO-3 "285278208.0000000000"
*MEAS_COND_AXIS_NAME_MAGICNO-4 "83951616.0000000000"
*MEAS_COND_AXIS_NAME_MAGICNO-5 "131072.0000000000"
*MEAS_COND_AXIS_NAME_MAGICNO-6 "131072.0000000000"
*MEAS_COND_AXIS_NAME_MAGICNO-7 "318898176.0000000000"
*MEAS_COND_AXIS_NAME_MAGICNO-8 "20971521.0000000000"
*MEAS_COND_AXIS_NAME_MAGICNO-9 "285343744.0000000000"
*MEAS_COND_AXIS_NAME_MAGICNO-10 "20971521.0000000000"
*MEAS_COND_AXIS_NAME_MAGICNO-11 "22020097.0000000000"
*MEAS_COND_AXIS_NAME_MAGICNO-12 "25165824.0000000000"
*MEAS_COND_AXIS_NAME_MAGICNO-13 "318898176.0000000000"
*MEAS_COND_AXIS_NAME_MAGICNO-14 "1.0000000000"
*MEAS_COND_AXIS_NAME_MAGICNO-15 "20971521.0000000000"
*MEAS_COND_AXIS_NAME_MAGICNO-16 "20971521.0000000000"
*MEAS_COND_AXIS_NAME_MAGICNO-17 "20971521.0000000000"
*MEAS_COND_AXIS_NAME_MAGICNO-18 "23068673.0000000000"
*MEAS_COND_AXIS_NAME_MAGICNO-19 "23068673.0000000000"
*MEAS_COND_AXIS_NAME_MAGICNO-20 "20971521.0000000000"
*MEAS_COND_AXIS_NAME_MAGICNO-21 "20971521.0000000000"
*MEAS_COND_AXIS_NAME_MAGICNO-22 "20971521.0000000000"
*MEAS_COND_AXIS_NAME_MAGICNO-23 "25165824.0000000000"
*MEAS_COND_AXIS_NAME_MAGICNO-24 "25165824.0000000000"
*MEAS_COND_AXIS_NAME_MAGICNO-25 "285343744.0000000000"
*MEAS_COND_AXIS_NAME_MAGICNO-26 "17301505.0000000000"
*MEAS_COND_AXIS_NAME_MAGICNO-27 "20971521.0000000000"
*MEAS_COND_AXIS_NAME_MAGICNO-28 "20971521.0000000000"
*MEAS_COND_AXIS_NAME_MAGICNO-29 "20971521.0000000000"
*MEAS_COND_AXIS_NAME_MAGICNO-30 "0.0000000000"
*MEAS_COND_AXIS_OFFSET-0 "-"
*MEAS_COND_AXIS_OFFSET-1 "-0.0801000000"
*MEAS_COND_AXIS_OFFSET-2 "0.1646000000"
*MEAS_COND_AXIS_OFFSET-3 "-"
*MEAS_COND_AXIS_OFFSET-4 "-"
*MEAS_COND_AXIS_OFFSET-5 "0.1646000000"
*MEAS_COND_AXIS_OFFSET-6 "-0.2447000000"
*MEAS_COND_AXIS_OFFSET-7 "-"
*MEAS_COND_AXIS_OFFSET-8 "-"
*MEAS_COND_AXIS_OFFSET-9 "-"
*MEAS_COND_AXIS_OFFSET-10 "-"
*MEAS_COND_AXIS_OFFSET-11 "-"
*MEAS_COND_AXIS_OFFSET-12 "-"
*MEAS_COND_AXIS_OFFSET-13 "-"
*MEAS_COND_AXIS_OFFSET-14 "-"
*MEAS_COND_AXIS_OFFSET-15 "-"
*MEAS_COND_AXIS_OFFSET-16 "-"
*MEAS_COND_AXIS_OFFSET-17 "-"
*MEAS_COND_AXIS_OFFSET-18 "-"
*MEAS_COND_AXIS_OFFSET-19 "-"
*MEAS_COND_AXIS_OFFSET-20 "-"
*MEAS_COND_AXIS_OFFSET-21 "-"
*MEAS_COND_AXIS_OFFSET-22 "-"
*MEAS_COND_AXIS_OFFSET-23 "-"
*MEAS_COND_AXIS_OFFSET-24 "-"
*MEAS_COND_AXIS_OFFSET-25 "-"
*MEAS_COND_AXIS_OFFSET-26 "-"
*MEAS_COND_AXIS_OFFSET-27 "-"
*MEAS_COND_AXIS_OFFSET-28 "-"
*MEAS_COND_AXIS_OFFSET-29 "-"
*MEAS_COND_AXIS_OFFSET-30 "-"
*MEAS_COND_AXIS_POSITION-0 "0.0000000000"
*MEAS_COND_AXIS_POSITION-1 "0.0000000000"
*MEAS_COND_AXIS_POSITION-2 "0.0000000000"
*MEAS_COND_AXIS_POSITION-3 "-2.9256400000"
*MEAS_COND_AXIS_POSITION-4 "0.0000000000"
*MEAS_COND_AXIS_POSITION-5 "0.0000000000"
*MEAS_COND_AXIS_POSITION-6 "0.0000000000"
*MEAS_COND_AXIS_POSITION-7 "-0.4278800000"
*MEAS_COND_AXIS_POSITION-8 "BB"
*MEAS_COND_AXIS_POSITION-9 "0.0000000000"
*MEAS_COND_AXIS_POSITION-10 "Soller_slit_5.0deg"
*MEAS_COND_AXIS_POSITION-11 "2/3deg"
*MEAS_COND_AXIS_POSITION-12 "2.2088000000"
*MEAS_COND_AXIS_POSITION-13 "-1.0609400000"
*MEAS_COND_AXIS_POSITION-14 "0.0000000000"
*MEAS_COND_AXIS_POSITION-15 "10.0mm"
*MEAS_COND_AXIS_POSITION-16 "None"
*MEAS_COND_AXIS_POSITION-17 "Cu_K-beta"
*MEAS_COND_AXIS_POSITION-18 "13.000mm"
*MEAS_COND_AXIS_POSITION-19 "13.000mm"
*MEAS_COND_AXIS_POSITION-20 "No_unit"
*MEAS_COND_AXIS_POSITION-21 "Soller_slit_5.0deg"
*MEAS_COND_AXIS_POSITION-22 "None"
*MEAS_COND_AXIS_POSITION-23 "13.0000000000"
*MEAS_COND_AXIS_POSITION-24 "13.0000000000"
*MEAS_COND_AXIS_POSITION-25 "0.0081300000"
*MEAS_COND_AXIS_POSITION-26 "Open"
*MEAS_COND_AXIS_POSITION-27 "None"
*MEAS_COND_AXIS_POSITION-28 "None"
*MEAS_COND_AXIS_POSITION-29 "None"
*MEAS_COND_AXIS_POSITION-30 "38.0000000000"
*MEAS_COND_AXIS_UNIT-0 "deg"
*MEAS_COND_AXIS_UNIT-1 "deg"
*MEAS_COND_AXIS_UNIT-2 "deg"
*MEAS_COND_AXIS_UNIT-3 "mm"
*MEAS_COND_AXIS_UNIT-4 "deg"
*MEAS_COND_AXIS_UNIT-5 "deg"
*MEAS_COND_AXIS_UNIT-6 "deg"
*MEAS_COND_AXIS_UNIT-7 "mm"
*MEAS_COND_AXIS_UNIT-8 ""
*MEAS_COND_AXIS_UNIT-9 "pulse"
*MEAS_COND_AXIS_UNIT-10 ""
*MEAS_COND_AXIS_UNIT-11 ""
*MEAS_COND_AXIS_UNIT-12 "mm"
*MEAS_COND_AXIS_UNIT-13 "mm"
*MEAS_COND_AXIS_UNIT-14 ""
*MEAS_COND_AXIS_UNIT-15 ""
*MEAS_COND_AXIS_UNIT-16 ""
*MEAS_COND_AXIS_UNIT-17 ""
*MEAS_COND_AXIS_UNIT-18 ""
*MEAS_COND_AXIS_UNIT-19 ""
*MEAS_COND_AXIS_UNIT-20 ""
*MEAS_COND_AXIS_UNIT-21 ""
*MEAS_COND_AXIS_UNIT-22 ""
*MEAS_COND_AXIS_UNIT-23 "mm"
*MEAS_COND_AXIS_UNIT-24 "mm"
*MEAS_COND_AXIS_UNIT-25 "mm"
*MEAS_COND_AXIS_UNIT-26 ""
*MEAS_COND_AXIS_UNIT-27 ""
*MEAS_COND_AXIS_UNIT-28 ""
*MEAS_COND_AXIS_UNIT-29 ""
*MEAS_COND_AXIS_UNIT-30 "div"
*MEAS_COND_COUNTER_CNTLOSS_CORR "0.0000000000"
*MEAS_COND_COUNTER_PHABASE "38.0000000000"
*MEAS_COND_COUNTER_PHAWINDOW "16.0000000000"
*MEAS_COND_COUNTER_PHA_UNIT "div"
*MEAS_COND_COUNTER_TAUDIFF "30.0000000000"
*MEAS_COND_COUNTER_TAUINT "0.0000000000"
*MEAS_COND_IRRADIATION_MODE "OFF"
*MEAS_COND_IRRADIATION_WIDTH ""
*MEAS_COND_OPT_ATTR "集中法"
*MEAS_COND_OPT_NAME "@集中法"
*MEAS_COND_UNSYMMETRIC_MODE "OFF"
*MEAS_COND_XG_CURRENT "30.0000000000"
*MEAS_COND_XG_VOLTAGE "40.0000000000"
*MEAS_COND_XG_WAVE_TYPE "Ka"
*MEAS_DATA_COUNT "5001.0000000000"
*MEAS_SCAN_AXIS_X "2θ/θ"
*MEAS_SCAN_AXIS_X_INTERNAL "TwoThetaTheta"
*MEAS_SCAN_END_TIME "07/09/22 13:24:42"
*MEAS_SCAN_MODE "CONTINUOUS"
*MEAS_SCAN_MONITOR "0"
*MEAS_SCAN_RESOLUTION_X "0.0002"
*MEAS_SCAN_SPEED "2.5"
*MEAS_SCAN_SPEED_UNIT "deg/min"
*MEAS_SCAN_START "20.0000000000"
*MEAS_SCAN_START_TIME "07/09/22 13:03:18"
*MEAS_SCAN_STEP "0.0100000000"
*MEAS_SCAN_STOP "70.0000000000"
*MEAS_SCAN_UNIT_X "deg"
*MEAS_SCAN_UNIT_Y "counts"
*RAS_HEADER_END
*RAS_INT_START
20.0000 1003.0000 1.0000
20.0400 972.0000 1.0000
20.0800 911.0000 1.0000
20.1200 959.0000 1.0000
20.1600 953.0000 1.0000
20.2000 954.0000 1.0000
20.2400 968.0000 1.0000
20.2800 977.0000 1.0000
20.3200 976.0000 1.0000
20.3600 968.0000 1.0000
20.4000 985.0000 1.0000
20.4400 978.0000 1.0000
20.4800 958.0000 1.0000
20.5200 928.0000 1.0000
20.5600 941.0000 1.0000
20.6000 946.0000 1.0000
20.6400 929.0000 1.0000
20.6800 1009.0000 1.0000
20.7200 925.0000 1.0000
20.7600 926.0000 1.0000
20.8000 950.0000 1.0000
20.8400 920.0000 1.0000
20.8800 951.0000 1.0000
20.9200 989.0000 1.0000
20.9600 982.0000 1.0000
21.0000 928.0000 1.0000
21.0400 912.0000 1.0000
21.0800 971.0000 1.0000
21.1200 982.0000 1.0000
21.1600 925.0000 1.0000
21.2000 957.0000 1.0000
21.2400 908.0000 1.0000
21.2800 987.0000 1.0000
21.3200 977.0000 1.0000
21.3600 954.0000 1.0000
21.4000 950.0000 1.0000
21.4400 925.0000 1.0000
21.4800 976.0000 1.0000
21.5200 917.0000 1.0000
21.5600 943.0000 1.0000
21.6000 965.0000 1.0000
21.6400 912.0000 1.0000
21.6800 969.0000 1.0000
21.7200 931.0000 1.0000
21.7600 962.0000 1.0000
21.8000 969.0000 1.0000
21.8400 998.0000 1.0000
21.8800 948.0000 1.0000
21.9200 934.0000 1.0000
21.9600 954.0000 1.0000
22.0000 933.0000 1.0000
22.0400 994.0000 1.0000
22.0800 953.0000 1.0000
22.1200 949.0000 1.0000
22.1600 990.0000 1.0000
22.2000 945.0000 1.0000
22.2400 927.0000 1.0000
22.2800 966.0000 1.0000
22.3200 913.0000 1.0000
22.3600 928.0000 1.0000
22.4000 934.0000 1.0000
22.4400 915.0000 1.0000
22.4800 909.0000 1.0000
22.5200 932.0000 1.0000
22.5600 925.0000 1.0000
22.6000 917.0000 1.0000
22.6400 949.0000 1.0000
22.6800 973.0000 1.0000
22.7200 891.0000 1.0000
22.7600 992.0000 1.0000
22.8000 970.0000 1.0000
22.8400 948.0000 1.0000
22.8800 976.0000 1.0000
22.9200 908.0000 1.0000
22.9600 921.0000 1.0000
23.0000 930.0000 1.0000
23.0400 900.0000 1.0000
23.0800 930.0000 1.0000
23.1200 939.0000 1.0000
23.1600 910.0000 1.0000
23.2000 919.0000 1.0000
23.2400 936.0000 1.0000
23.2800 866.0000 1.0000
23.3200 932.0000 1.0000
23.3600 939.0000 1.0000
23.4000 901.0000 1.0000
23.4400 941.0000 1.0000
23.4800 937.0000 1.0000
23.5200 923.0000 1.0000
23.5600 930.0000 1.0000
23.6000 949.0000 1.0000
23.6400 941.0000 1.0000
23.6800 933.0000 1.0000
23.7200 939.0000 1.0000
23.7600 963.0000 1.0000
23.8000 954.0000 1.0000
23.8400 966.0000 1.0000
23.8800 967.0000 1.0000
23.9200 925.0000 1.0000
23.9600 966.0000 1.0000
24.0000 1001.0000 1.0000
24.0400 985.0000 1.0000
24.0800 1014.0000 1.0000
24.1200 988.0000 1.0000
24.1600 976.0000 1.0000
24.2000 952.0000 1.0000
24.2400 948.0000 1.0000
24.2800 940.0000 1.0000
24.3200 930.0000 1.0000
24.3600 959.0000 1.0000
24.4000 968.0000 1.0000
24.4400 884.0000 1.0000
24.4800 928.0000 1.0000
24.5200 928.0000 1.0000
24.5600 944.0000 1.0000
24.6000 980.0000 1.0000
24.6400 881.0000 1.0000
24.6800 860.0000 1.0000
24.7200 900.0000 1.0000
24.7600 936.0000 1.0000
24.8000 887.0000 1.0000
24.8400 897.0000 1.0000
24.8800 949.0000 1.0000
24.9200 944.0000 1.0000
24.9600 921.0000 1.0000
25.0000 928.0000 1.0000
25.0400 895.0000 1.0000
25.0800 946.0000 1.0000
25.1200 882.0000 1.0000
25.1600 910.0000 1.0000
25.2000 916.0000 1.0000
25.2400 944.0000 1.0000
25.2800 893.0000 1.0000
25.3200 951.0000 1.0000
25.3600 911.0000 1.0000
25.4000 887.0000 1.0000
25.4400 958.0000 1.0000
25.4800 917.0000 1.0000
25.5200 865.0000 1.0000
25.5600 891.0000 1.0000
25.6000 955.0000 1.0000
25.6400 915.0000 1.0000
25.6800 938.0000 1.0000
25.7200 942.0000 1.0000
25.7600 936.0000 1.0000
25.8000 965.0000 1.0000
25.8400 990.0000 1.0000
25.8800 929.0000 1.0000
25.9200 960.0000 1.0000
25.9600 1024.0000 1.0000
26.0000 1045.0000 1.0000
26.0400 1031.0000 1.0000
26.0800 1099.0000 1.0000
26.1200 1148.0000 1.0000
26.1600 1193.0000 1.0000
26.2000 1332.0000 1.0000
26.2400 1485.0000 1.0000
26.2800 1768.0000 1.0000
26.3200 2115.0000 1.0000
26.3600 2612.0000 1.0000
26.4000 3141.0000 1.0000
26.4400 3359.0000 1.0000
26.4800 3205.0000 1.0000
26.5200 2724.0000 1.0000
26.5600 2227.0000 1.0000
26.6000 1827.0000 1.0000
26.6400 1500.0000 1.0000
26.6800 1388.0000 1.0000
26.7200 1156.0000 1.0000
26.7600 1134.0000 1.0000
26.8000 1084.0000 1.0000
26.8400 1016.0000 1.0000
26.8800 991.0000 1.0000
26.9200 949.0000 1.0000
26.9600 968.0000 1.0000
27.0000 951.0000 1.0000
27.0400 964.0000 1.0000
27.0800 872.0000 1.0000
27.1200 917.0000 1.0000
27.1600 909.0000 1.0000
27.2000 854.0000 1.0000
27.2400 877.0000 1.0000
27.2800 859.0000 1.0000
27.3200 928.0000 1.0000
27.3600 891.0000 1.0000
27.4000 849.0000 1.0000
27.4400 873.0000 1.0000
27.4800 871.0000 1.0000
27.5200 853.0000 1.0000
27.5600 892.0000 1.0000
27.6000 851.0000 1.0000
27.6400 863.0000 1.0000
27.6800 816.0000 1.0000
27.7200 843.0000 1.0000
27.7600 863.0000 1.0000
27.8000 873.0000 1.0000
27.8400 868.0000 1.0000
27.8800 789.0000 1.0000
27.9200 829.0000 1.0000
27.9600 814.0000 1.0000
28.0000 825.0000 1.0000
28.0400 808.0000 1.0000
28.0800 811.0000 1.0000
28.1200 819.0000 1.0000
28.1600 823.0000 1.0000
28.2000 806.0000 1.0000
28.2400 759.0000 1.0000
28.2800 880.0000 1.0000
28.3200 835.0000 1.0000
28.3600 797.0000 1.0000
28.4000 850.0000 1.0000
28.4400 809.0000 1.0000
28.4800 768.0000 1.0000
28.5200 802.0000 1.0000
28.5600 794.0000 1.0000
28.6000 798.0000 1.0000
28.6400 790.0000 1.0000
28.6800 808.0000 1.0000
28.7200 772.0000 1.0000
28.7600 775.0000 1.0000
28.8000 751.0000 1.0000
28.8400 799.0000 1.0000
28.8800 764.0000 1.0000
28.9200 779.0000 1.0000
28.9600 762.0000 1.0000
29.0000 801.0000 1.0000
29.0400 735.0000 1.0000
29.0800 805.0000 1.0000
29.1200 817.0000 1.0000
29.1600 739.0000 1.0000
29.2000 771.0000 1.0000
29.2400 771.0000 1.0000
29.2800 758.0000 1.0000
29.3200 767.0000 1.0000
29.3600 782.0000 1.0000
29.4000 772.0000 1.0000
29.4400 729.0000 1.0000
29.4800 752.0000 1.0000
29.5200 763.0000 1.0000
29.5600 780.0000 1.0000
29.6000 770.0000 1.0000
29.6400 742.0000 1.0000
29.6800 819.0000 1.0000
29.7200 745.0000 1.0000
29.7600 781.0000 1.0000
29.8000 736.0000 1.0000
29.8400 745.0000 1.0000
29.8800 760.0000 1.0000
29.9200 731.0000 1.0000
29.9600 771.0000 1.0000
30.0000 792.0000 1.0000
30.0400 731.0000 1.0000
30.0800 789.0000 1.0000
30.1200 769.0000 1.0000
30.1600 739.0000 1.0000
30.2000 797.0000 1.0000
30.2400 711.0000 1.0000
30.2800 730.0000 1.0000
30.3200 717.0000 1.0000
30.3600 754.0000 1.0000
30.4000 792.0000 1.0000
30.4400 709.0000 1.0000
30.4800 747.0000 1.0000
30.5200 749.0000 1.0000
30.5600 707.0000 1.0000
30.6000 762.0000 1.0000
30.6400 713.0000 1.0000
30.6800 704.0000 1.0000
30.7200 711.0000 1.0000
30.7600 716.0000 1.0000
30.8000 741.0000 1.0000
30.8400 719.0000 1.0000
30.8800 744.0000 1.0000
30.9200 720.0000 1.0000
30.9600 717.0000 1.0000
31.0000 776.0000 1.0000
31.0400 776.0000 1.0000
31.0800 742.0000 1.0000
31.1200 688.0000 1.0000
31.1600 699.0000 1.0000
31.2000 740.0000 1.0000
31.2400 774.0000 1.0000
31.2800 704.0000 1.0000
31.3200 745.0000 1.0000
31.3600 699.0000 1.0000
31.4000 730.0000 1.0000
31.4400 692.0000 1.0000
31.4800 760.0000 1.0000
31.5200 707.0000 1.0000
31.5600 706.0000 1.0000
31.6000 772.0000 1.0000
31.6400 721.0000 1.0000
31.6800 745.0000 1.0000
31.7200 663.0000 1.0000
31.7600 667.0000 1.0000
31.8000 687.0000 1.0000
31.8400 715.0000 1.0000
31.8800 682.0000 1.0000
31.9200 718.0000 1.0000
31.9600 729.0000 1.0000
32.0000 698.0000 1.0000
32.0400 681.0000 1.0000
32.0800 675.0000 1.0000
32.1200 672.0000 1.0000
32.1600 703.0000 1.0000
32.2000 675.0000 1.0000
32.2400 690.0000 1.0000
32.2800 689.0000 1.0000
32.3200 610.0000 1.0000
32.3600 698.0000 1.0000
32.4000 688.0000 1.0000
32.4400 630.0000 1.0000
32.4800 642.0000 1.0000
32.5200 663.0000 1.0000
32.5600 671.0000 1.0000
32.6000 691.0000 1.0000
32.6400 670.0000 1.0000
32.6800 709.0000 1.0000
32.7200 640.0000 1.0000
32.7600 660.0000 1.0000
32.8000 721.0000 1.0000
32.8400 746.0000 1.0000
32.8800 733.0000 1.0000
32.9200 768.0000 1.0000
32.9600 747.0000 1.0000
33.0000 866.0000 1.0000
33.0400 860.0000 1.0000
33.0800 880.0000 1.0000
33.1200 906.0000 1.0000
33.1600 938.0000 1.0000
33.2000 854.0000 1.0000
33.2400 847.0000 1.0000
33.2800 785.0000 1.0000
33.3200 823.0000 1.0000
33.3600 821.0000 1.0000
33.4000 864.0000 1.0000
33.4400 884.0000 1.0000
33.4800 947.0000 1.0000
33.5200 1135.0000 1.0000
33.5600 1293.0000 1.0000
33.6000 1471.0000 1.0000
33.6400 1616.0000 1.0000
33.6800 1670.0000 1.0000
33.7200 1576.0000 1.0000
33.7600 1285.0000 1.0000
33.8000 1172.0000 1.0000
33.8400 966.0000 1.0000
33.8800 902.0000 1.0000
33.9200 778.0000 1.0000
33.9600 785.0000 1.0000
34.0000 742.0000 1.0000
34.0400 739.0000 1.0000
34.0800 687.0000 1.0000
34.1200 692.0000 1.0000
34.1600 682.0000 1.0000
34.2000 656.0000 1.0000
34.2400 642.0000 1.0000
34.2800 633.0000 1.0000
34.3200 642.0000 1.0000
34.3600 710.0000 1.0000
34.4000 602.0000 1.0000
34.4400 620.0000 1.0000
34.4800 619.0000 1.0000
34.5200 627.0000 1.0000
34.5600 614.0000 1.0000
34.6000 623.0000 1.0000
34.6400 616.0000 1.0000
34.6800 585.0000 1.0000
34.7200 594.0000 1.0000
34.7600 621.0000 1.0000
34.8000 527.0000 1.0000
34.8400 604.0000 1.0000
34.8800 602.0000 1.0000
34.9200 625.0000 1.0000
34.9600 634.0000 1.0000
35.0000 587.0000 1.0000
35.0400 576.0000 1.0000
35.0800 593.0000 1.0000
35.1200 601.0000 1.0000
35.1600 591.0000 1.0000
35.2000 553.0000 1.0000
35.2400 608.0000 1.0000
35.2800 631.0000 1.0000
35.3200 652.0000 1.0000
35.3600 665.0000 1.0000
35.4000 700.0000 1.0000
35.4400 734.0000 1.0000
35.4800 830.0000 1.0000
35.5200 845.0000 1.0000
35.5600 1013.0000 1.0000
35.6000 1005.0000 1.0000
35.6400 937.0000 1.0000
35.6800 827.0000 1.0000
35.7200 750.0000 1.0000
35.7600 697.0000 1.0000
35.8000 649.0000 1.0000
35.8400 617.0000 1.0000
35.8800 586.0000 1.0000
35.9200 589.0000 1.0000
35.9600 578.0000 1.0000
36.0000 541.0000 1.0000
36.0400 553.0000 1.0000
36.0800 563.0000 1.0000
36.1200 580.0000 1.0000
36.1600 574.0000 1.0000
36.2000 493.0000 1.0000
36.2400 519.0000 1.0000
36.2800 546.0000 1.0000
36.3200 550.0000 1.0000
36.3600 524.0000 1.0000
36.4000 585.0000 1.0000
36.4400 551.0000 1.0000
36.4800 518.0000 1.0000
36.5200 542.0000 1.0000
36.5600 536.0000 1.0000
36.6000 555.0000 1.0000
36.6400 551.0000 1.0000
36.6800 521.0000 1.0000
36.7200 539.0000 1.0000
36.7600 495.0000 1.0000
36.8000 559.0000 1.0000
36.8400 551.0000 1.0000
36.8800 524.0000 1.0000
36.9200 530.0000 1.0000
36.9600 543.0000 1.0000
37.0000 557.0000 1.0000
37.0400 550.0000 1.0000
37.0800 531.0000 1.0000
37.1200 545.0000 1.0000
37.1600 538.0000 1.0000
37.2000 559.0000 1.0000
37.2400 562.0000 1.0000
37.2800 621.0000 1.0000
37.3200 652.0000 1.0000
37.3600 636.0000 1.0000
37.4000 739.0000 1.0000
37.4400 834.0000 1.0000
37.4800 957.0000 1.0000
37.5200 1070.0000 1.0000
37.5600 1365.0000 1.0000
37.6000 1671.0000 1.0000
37.6400 2133.0000 1.0000
37.6800 2504.0000 1.0000
37.7200 2587.0000 1.0000
37.7600 2510.0000 1.0000
37.8000 2198.0000 1.0000
37.8400 1808.0000 1.0000
37.8800 1544.0000 1.0000
37.9200 1187.0000 1.0000
37.9600 974.0000 1.0000
38.0000 788.0000 1.0000
38.0400 682.0000 1.0000
38.0800 629.0000 1.0000
38.1200 628.0000 1.0000
38.1600 600.0000 1.0000
38.2000 556.0000 1.0000
38.2400 549.0000 1.0000
38.2800 517.0000 1.0000
38.3200 533.0000 1.0000
38.3600 511.0000 1.0000
38.4000 509.0000 1.0000
38.4400 492.0000 1.0000
38.4800 517.0000 1.0000
38.5200 498.0000 1.0000
38.5600 523.0000 1.0000
38.6000 511.0000 1.0000
38.6400 561.0000 1.0000
38.6800 488.0000 1.0000
38.7200 543.0000 1.0000
38.7600 523.0000 1.0000
38.8000 511.0000 1.0000
38.8400 498.0000 1.0000
38.8800 522.0000 1.0000
38.9200 484.0000 1.0000
38.9600 523.0000 1.0000
39.0000 488.0000 1.0000
39.0400 496.0000 1.0000
39.0800 481.0000 1.0000
39.1200 545.0000 1.0000
39.1600 476.0000 1.0000
39.2000 516.0000 1.0000
39.2400 463.0000 1.0000
39.2800 476.0000 1.0000
39.3200 464.0000 1.0000
39.3600 488.0000 1.0000
39.4000 467.0000 1.0000
39.4400 481.0000 1.0000
39.4800 428.0000 1.0000
39.5200 492.0000 1.0000
39.5600 458.0000 1.0000
39.6000 461.0000 1.0000
39.6400 453.0000 1.0000
39.6800 456.0000 1.0000
39.7200 464.0000 1.0000
39.7600 448.0000 1.0000
39.8000 444.0000 1.0000
39.8400 446.0000 1.0000
39.8800 455.0000 1.0000
39.9200 463.0000 1.0000
39.9600 498.0000 1.0000
40.0000 447.0000 1.0000
40.0400 455.0000 1.0000
40.0800 467.0000 1.0000
40.1200 493.0000 1.0000
40.1600 459.0000 1.0000
40.2000 437.0000 1.0000
40.2400 466.0000 1.0000
40.2800 429.0000 1.0000
40.3200 445.0000 1.0000
40.3600 451.0000 1.0000
40.4000 473.0000 1.0000
40.4400 445.0000 1.0000
40.4800 440.0000 1.0000
40.5200 450.0000 1.0000
40.5600 464.0000 1.0000
40.6000 465.0000 1.0000
40.6400 421.0000 1.0000
40.6800 452.0000 1.0000
40.7200 465.0000 1.0000
40.7600 513.0000 1.0000
40.8000 506.0000 1.0000
40.8400 517.0000 1.0000
40.8800 528.0000 1.0000
40.9200 487.0000 1.0000
40.9600 465.0000 1.0000
41.0000 449.0000 1.0000
41.0400 477.0000 1.0000
41.0800 418.0000 1.0000
41.1200 472.0000 1.0000
41.1600 473.0000 1.0000
41.2000 443.0000 1.0000
41.2400 448.0000 1.0000
41.2800 445.0000 1.0000
41.3200 460.0000 1.0000
41.3600 422.0000 1.0000
41.4000 461.0000 1.0000
41.4400 408.0000 1.0000
41.4800 435.0000 1.0000
41.5200 435.0000 1.0000
41.5600 431.0000 1.0000
41.6000 458.0000 1.0000
41.6400 433.0000 1.0000
41.6800 440.0000 1.0000
41.7200 423.0000 1.0000
41.7600 444.0000 1.0000
41.8000 421.0000 1.0000
41.8400 391.0000 1.0000
41.8800 429.0000 1.0000
41.9200 485.0000 1.0000
41.9600 390.0000 1.0000
42.0000 448.0000 1.0000
42.0400 402.0000 1.0000
42.0800 434.0000 1.0000
42.1200 445.0000 1.0000
42.1600 447.0000 1.0000
42.2000 422.0000 1.0000
42.2400 449.0000 1.0000
42.2800 479.0000 1.0000
42.3200 455.0000 1.0000
42.3600 452.0000 1.0000
42.4000 490.0000 1.0000
42.4400 466.0000 1.0000
42.4800 485.0000 1.0000
42.5200 438.0000 1.0000
42.5600 472.0000 1.0000
42.6000 419.0000 1.0000
42.6400 506.0000 1.0000
42.6800 453.0000 1.0000
42.7200 451.0000 1.0000
42.7600 436.0000 1.0000
42.8000 447.0000 1.0000
42.8400 458.0000 1.0000
42.8800 426.0000 1.0000
42.9200 420.0000 1.0000
42.9600 434.0000 1.0000
43.0000 424.0000 1.0000
43.0400 445.0000 1.0000
43.0800 434.0000 1.0000
43.1200 417.0000 1.0000
43.1600 407.0000 1.0000
43.2000 452.0000 1.0000
43.2400 435.0000 1.0000
43.2800 406.0000 1.0000
43.3200 431.0000 1.0000
43.3600 426.0000 1.0000
43.4000 461.0000 1.0000
43.4400 431.0000 1.0000
43.4800 405.0000 1.0000
43.5200 391.0000 1.0000
43.5600 459.0000 1.0000
43.6000 425.0000 1.0000
43.6400 424.0000 1.0000
43.6800 422.0000 1.0000
43.7200 428.0000 1.0000
43.7600 442.0000 1.0000
43.8000 419.0000 1.0000
43.8400 368.0000 1.0000
43.8800 396.0000 1.0000
43.9200 434.0000 1.0000
43.9600 432.0000 1.0000
44.0000 413.0000 1.0000
44.0400 388.0000 1.0000
44.0800 408.0000 1.0000
44.1200 407.0000 1.0000
44.1600 450.0000 1.0000
44.2000 385.0000 1.0000
44.2400 414.0000 1.0000
44.2800 436.0000 1.0000
44.3200 392.0000 1.0000
44.3600 384.0000 1.0000
44.4000 412.0000 1.0000
44.4400 437.0000 1.0000
44.4800 409.0000 1.0000
44.5200 417.0000 1.0000
44.5600 421.0000 1.0000
44.6000 423.0000 1.0000
44.6400 418.0000 1.0000
44.6800 423.0000 1.0000
44.7200 403.0000 1.0000
44.7600 432.0000 1.0000
44.8000 447.0000 1.0000
44.8400 422.0000 1.0000
44.8800 421.0000 1.0000
44.9200 413.0000 1.0000
44.9600 403.0000 1.0000
45.0000 368.0000 1.0000
45.0400 373.0000 1.0000
45.0800 377.0000 1.0000
45.1200 417.0000 1.0000
45.1600 421.0000 1.0000
45.2000 399.0000 1.0000
45.2400 404.0000 1.0000
45.2800 446.0000 1.0000
45.3200 376.0000 1.0000
45.3600 401.0000 1.0000
45.4000 422.0000 1.0000
45.4400 421.0000 1.0000
45.4800 399.0000 1.0000
45.5200 388.0000 1.0000
45.5600 413.0000 1.0000
45.6000 402.0000 1.0000
45.6400 395.0000 1.0000
45.6800 390.0000 1.0000
45.7200 405.0000 1.0000
45.7600 396.0000 1.0000
45.8000 402.0000 1.0000
45.8400 396.0000 1.0000
45.8800 353.0000 1.0000
45.9200 412.0000 1.0000
45.9600 386.0000 1.0000
46.0000 375.0000 1.0000
46.0400 403.0000 1.0000
46.0800 406.0000 1.0000
46.1200 420.0000 1.0000
46.1600 432.0000 1.0000
46.2000 420.0000 1.0000
46.2400 424.0000 1.0000
46.2800 381.0000 1.0000
46.3200 410.0000 1.0000
46.3600 398.0000 1.0000
46.4000 405.0000 1.0000
46.4400 381.0000 1.0000
46.4800 412.0000 1.0000
46.5200 365.0000 1.0000
46.5600 388.0000 1.0000
46.6000 403.0000 1.0000
46.6400 399.0000 1.0000
46.6800 412.0000 1.0000
46.7200 402.0000 1.0000
46.7600 372.0000 1.0000
46.8000 382.0000 1.0000
46.8400 355.0000 1.0000
46.8800 379.0000 1.0000
46.9200 353.0000 1.0000
46.9600 391.0000 1.0000
47.0000 379.0000 1.0000
47.0400 384.0000 1.0000
47.0800 396.0000 1.0000
47.1200 375.0000 1.0000
47.1600 384.0000 1.0000
47.2000 366.0000 1.0000
47.2400 398.0000 1.0000
47.2800 374.0000 1.0000
47.3200 373.0000 1.0000
47.3600 387.0000 1.0000
47.4000 363.0000 1.0000
47.4400 354.0000 1.0000
47.4800 388.0000 1.0000
47.5200 433.0000 1.0000
47.5600 363.0000 1.0000
47.6000 405.0000 1.0000
47.6400 403.0000 1.0000
47.6800 384.0000 1.0000
47.7200 383.0000 1.0000
47.7600 388.0000 1.0000
47.8000 383.0000 1.0000
47.8400 369.0000 1.0000
47.8800 394.0000 1.0000
47.9200 361.0000 1.0000
47.9600 352.0000 1.0000
48.0000 339.0000 1.0000
48.0400 377.0000 1.0000
48.0800 376.0000 1.0000
48.1200 355.0000 1.0000
48.1600 396.0000 1.0000
48.2000 338.0000 1.0000
48.2400 358.0000 1.0000
48.2800 375.0000 1.0000
48.3200 412.0000 1.0000
48.3600 380.0000 1.0000
48.4000 386.0000 1.0000
48.4400 382.0000 1.0000
48.4800 361.0000 1.0000
48.5200 367.0000 1.0000
48.5600 390.0000 1.0000
48.6000 375.0000 1.0000
48.6400 375.0000 1.0000
48.6800 374.0000 1.0000
48.7200 349.0000 1.0000
48.7600 387.0000 1.0000
48.8000 341.0000 1.0000
48.8400 367.0000 1.0000
48.8800 398.0000 1.0000
48.9200 356.0000 1.0000
48.9600 387.0000 1.0000
49.0000 353.0000 1.0000
49.0400 377.0000 1.0000
49.0800 369.0000 1.0000
49.1200 367.0000 1.0000
49.1600 380.0000 1.0000
49.2000 389.0000 1.0000
49.2400 385.0000 1.0000
49.2800 433.0000 1.0000
49.3200 412.0000 1.0000
49.3600 454.0000 1.0000
49.4000 419.0000 1.0000
49.4400 401.0000 1.0000
49.4800 416.0000 1.0000
49.5200 421.0000 1.0000
49.5600 408.0000 1.0000
49.6000 385.0000 1.0000
49.6400 411.0000 1.0000
49.6800 359.0000 1.0000
49.7200 385.0000 1.0000
49.7600 377.0000 1.0000
49.8000 371.0000 1.0000
49.8400 367.0000 1.0000
49.8800 366.0000 1.0000
49.9200 390.0000 1.0000
49.9600 363.0000 1.0000
50.0000 370.0000 1.0000
50.0400 381.0000 1.0000
50.0800 364.0000 1.0000
50.1200 385.0000 1.0000
50.1600 353.0000 1.0000
50.2000 371.0000 1.0000
50.2400 377.0000 1.0000
50.2800 346.0000 1.0000
50.3200 365.0000 1.0000
50.3600 387.0000 1.0000
50.4000 398.0000 1.0000
50.4400 402.0000 1.0000
50.4800 372.0000 1.0000
50.5200 372.0000 1.0000
50.5600 403.0000 1.0000
50.6000 373.0000 1.0000
50.6400 376.0000 1.0000
50.6800 395.0000 1.0000
50.7200 377.0000 1.0000
50.7600 383.0000 1.0000
50.8000 406.0000 1.0000
50.8400 383.0000 1.0000
50.8800 394.0000 1.0000
50.9200 421.0000 1.0000
50.9600 409.0000 1.0000
51.0000 413.0000 1.0000
51.0400 431.0000 1.0000
51.0800 432.0000 1.0000
51.1200 461.0000 1.0000
51.1600 512.0000 1.0000
51.2000 572.0000 1.0000
51.2400 646.0000 1.0000
51.2800 778.0000 1.0000
51.3200 887.0000 1.0000
51.3600 1159.0000 1.0000
51.4000 1569.0000 1.0000
51.4400 1932.0000 1.0000
51.4800 2356.0000 1.0000
51.5200 2429.0000 1.0000
51.5600 2073.0000 1.0000
51.6000 1952.0000 1.0000
51.6400 1659.0000 1.0000
51.6800 1326.0000 1.0000
51.7200 1049.0000 1.0000
51.7600 875.0000 1.0000
51.8000 663.0000 1.0000
51.8400 568.0000 1.0000
51.8800 514.0000 1.0000
51.9200 453.0000 1.0000
51.9600 468.0000 1.0000
52.0000 439.0000 1.0000
52.0400 463.0000 1.0000
52.0800 449.0000 1.0000
52.1200 402.0000 1.0000
52.1600 382.0000 1.0000
52.2000 364.0000 1.0000
52.2400 382.0000 1.0000
52.2800 368.0000 1.0000
52.3200 366.0000 1.0000
52.3600 375.0000 1.0000
52.4000 405.0000 1.0000
52.4400 400.0000 1.0000
52.4800 389.0000 1.0000
52.5200 372.0000 1.0000
52.5600 349.0000 1.0000
52.6000 336.0000 1.0000
52.6400 373.0000 1.0000
52.6800 357.0000 1.0000
52.7200 373.0000 1.0000
52.7600 347.0000 1.0000
52.8000 357.0000 1.0000
52.8400 343.0000 1.0000
52.8800 344.0000 1.0000
52.9200 365.0000 1.0000
52.9600 385.0000 1.0000
53.0000 349.0000 1.0000
53.0400 334.0000 1.0000
53.0800 382.0000 1.0000
53.1200 385.0000 1.0000
53.1600 367.0000 1.0000
53.2000 373.0000 1.0000
53.2400 357.0000 1.0000
53.2800 355.0000 1.0000
53.3200 340.0000 1.0000
53.3600 339.0000 1.0000
53.4000 345.0000 1.0000
53.4400 357.0000 1.0000
53.4800 348.0000 1.0000
53.5200 371.0000 1.0000
53.5600 375.0000 1.0000
53.6000 342.0000 1.0000
53.6400 374.0000 1.0000
53.6800 348.0000 1.0000
53.7200 374.0000 1.0000
53.7600 338.0000 1.0000
53.8000 393.0000 1.0000
53.8400 361.0000 1.0000
53.8800 386.0000 1.0000
53.9200 356.0000 1.0000
53.9600 403.0000 1.0000
54.0000 443.0000 1.0000
54.0400 442.0000 1.0000
54.0800 411.0000 1.0000
54.1200 422.0000 1.0000
54.1600 399.0000 1.0000
54.2000 441.0000 1.0000
54.2400 394.0000 1.0000
54.2800 399.0000 1.0000
54.3200 429.0000 1.0000
54.3600 416.0000 1.0000
54.4000 475.0000 1.0000
54.4400 519.0000 1.0000
54.4800 547.0000 1.0000
54.5200 554.0000 1.0000
54.5600 557.0000 1.0000
54.6000 521.0000 1.0000
54.6400 540.0000 1.0000
54.6800 525.0000 1.0000
54.7200 464.0000 1.0000
54.7600 419.0000 1.0000
54.8000 406.0000 1.0000
54.8400 387.0000 1.0000
54.8800 376.0000 1.0000
54.9200 371.0000 1.0000
54.9600 377.0000 1.0000
55.0000 356.0000 1.0000
55.0400 347.0000 1.0000
55.0800 346.0000 1.0000
55.1200 372.0000 1.0000
55.1600 332.0000 1.0000
55.2000 340.0000 1.0000
55.2400 359.0000 1.0000
55.2800 351.0000 1.0000
55.3200 349.0000 1.0000
55.3600 368.0000 1.0000
55.4000 334.0000 1.0000
55.4400 329.0000 1.0000
55.4800 357.0000 1.0000
55.5200 339.0000 1.0000
55.5600 342.0000 1.0000
55.6000 354.0000 1.0000
55.6400 354.0000 1.0000
55.6800 344.0000 1.0000
55.7200 355.0000 1.0000
55.7600 356.0000 1.0000
55.8000 317.0000 1.0000
55.8400 339.0000 1.0000
55.8800 324.0000 1.0000
55.9200 328.0000 1.0000
55.9600 340.0000 1.0000
56.0000 335.0000 1.0000
56.0400 362.0000 1.0000
56.0800 369.0000 1.0000
56.1200 352.0000 1.0000
56.1600 367.0000 1.0000
56.2000 313.0000 1.0000
56.2400 329.0000 1.0000
56.2800 338.0000 1.0000
56.3200 351.0000 1.0000
56.3600 334.0000 1.0000
56.4000 355.0000 1.0000
56.4400 338.0000 1.0000
56.4800 317.0000 1.0000
56.5200 345.0000 1.0000
56.5600 365.0000 1.0000
56.6000 339.0000 1.0000
56.6400 346.0000 1.0000
56.6800 358.0000 1.0000
56.7200 365.0000 1.0000
56.7600 364.0000 1.0000
56.8000 331.0000 1.0000
56.8400 335.0000 1.0000
56.8800 380.0000 1.0000
56.9200 333.0000 1.0000
56.9600 348.0000 1.0000
57.0000 338.0000 1.0000
57.0400 321.0000 1.0000
57.0800 341.0000 1.0000
57.1200 372.0000 1.0000
57.1600 365.0000 1.0000
57.2000 348.0000 1.0000
57.2400 350.0000 1.0000
57.2800 342.0000 1.0000
57.3200 347.0000 1.0000
57.3600 350.0000 1.0000
57.4000 344.0000 1.0000
57.4400 363.0000 1.0000
57.4800 352.0000 1.0000
57.5200 350.0000 1.0000
57.5600 363.0000 1.0000
57.6000 339.0000 1.0000
57.6400 337.0000 1.0000
57.6800 340.0000 1.0000
57.7200 370.0000 1.0000
57.7600 341.0000 1.0000
57.8000 336.0000 1.0000
57.8400 329.0000 1.0000
57.8800 342.0000 1.0000
57.9200 375.0000 1.0000
57.9600 342.0000 1.0000
58.0000 373.0000 1.0000
58.0400 363.0000 1.0000
58.0800 332.0000 1.0000
58.1200 374.0000 1.0000
58.1600 369.0000 1.0000
58.2000 332.0000 1.0000
58.2400 346.0000 1.0000
58.2800 324.0000 1.0000
58.3200 349.0000 1.0000
58.3600 336.0000 1.0000
58.4000 340.0000 1.0000
58.4400 351.0000 1.0000
58.4800 329.0000 1.0000
58.5200 352.0000 1.0000
58.5600 364.0000 1.0000
58.6000 312.0000 1.0000
58.6400 344.0000 1.0000
58.6800 330.0000 1.0000
58.7200 305.0000 1.0000
58.7600 326.0000 1.0000
58.8000 327.0000 1.0000
58.8400 331.0000 1.0000
58.8800 338.0000 1.0000
58.9200 336.0000 1.0000
58.9600 330.0000 1.0000
59.0000 344.0000 1.0000
59.0400 312.0000 1.0000
59.0800 320.0000 1.0000
59.1200 332.0000 1.0000
59.1600 329.0000 1.0000
59.2000 327.0000 1.0000
59.2400 358.0000 1.0000
59.2800 345.0000 1.0000
59.3200 331.0000 1.0000
59.3600 357.0000 1.0000
59.4000 341.0000 1.0000
59.4400 314.0000 1.0000
59.4800 375.0000 1.0000
59.5200 311.0000 1.0000
59.5600 336.0000 1.0000
59.6000 356.0000 1.0000
59.6400 316.0000 1.0000
59.6800 325.0000 1.0000
59.7200 316.0000 1.0000
59.7600 345.0000 1.0000
59.8000 352.0000 1.0000
59.8400 367.0000 1.0000
59.8800 319.0000 1.0000
59.9200 348.0000 1.0000
59.9600 308.0000 1.0000
60.0000 340.0000 1.0000
60.0400 365.0000 1.0000
60.0800 333.0000 1.0000
60.1200 352.0000 1.0000
60.1600 329.0000 1.0000
60.2000 367.0000 1.0000
60.2400 310.0000 1.0000
60.2800 363.0000 1.0000
60.3200 326.0000 1.0000
60.3600 333.0000 1.0000
60.4000 346.0000 1.0000
60.4400 311.0000 1.0000
60.4800 346.0000 1.0000
60.5200 336.0000 1.0000
60.5600 349.0000 1.0000
60.6000 337.0000 1.0000
60.6400 328.0000 1.0000
60.6800 331.0000 1.0000
60.7200 343.0000 1.0000
60.7600 351.0000 1.0000
60.8000 304.0000 1.0000
60.8400 323.0000 1.0000
60.8800 303.0000 1.0000
60.9200 339.0000 1.0000
60.9600 365.0000 1.0000
61.0000 357.0000 1.0000
61.0400 350.0000 1.0000
61.0800 360.0000 1.0000
61.1200 339.0000 1.0000
61.1600 365.0000 1.0000
61.2000 417.0000 1.0000
61.2400 422.0000 1.0000
61.2800 440.0000 1.0000
61.3200 496.0000 1.0000
61.3600 496.0000 1.0000
61.4000 529.0000 1.0000
61.4400 588.0000 1.0000
61.4800 676.0000 1.0000
61.5200 749.0000 1.0000
61.5600 737.0000 1.0000
61.6000 674.0000 1.0000
61.6400 712.0000 1.0000
61.6800 644.0000 1.0000
61.7200 622.0000 1.0000
61.7600 612.0000 1.0000
61.8000 504.0000 1.0000
61.8400 512.0000 1.0000
61.8800 531.0000 1.0000
61.9200 459.0000 1.0000
61.9600 417.0000 1.0000
62.0000 461.0000 1.0000
62.0400 400.0000 1.0000
62.0800 402.0000 1.0000
62.1200 394.0000 1.0000
62.1600 391.0000 1.0000
62.2000 355.0000 1.0000
62.2400 379.0000 1.0000
62.2800 371.0000 1.0000
62.3200 378.0000 1.0000
62.3600 411.0000 1.0000
62.4000 417.0000 1.0000
62.4400 413.0000 1.0000
62.4800 381.0000 1.0000
62.5200 368.0000 1.0000
62.5600 388.0000 1.0000
62.6000 350.0000 1.0000
62.6400 325.0000 1.0000
62.6800 359.0000 1.0000
62.7200 376.0000 1.0000
62.7600 338.0000 1.0000
62.8000 347.0000 1.0000
62.8400 354.0000 1.0000
62.8800 342.0000 1.0000
62.9200 328.0000 1.0000
62.9600 300.0000 1.0000
63.0000 376.0000 1.0000
63.0400 325.0000 1.0000
63.0800 328.0000 1.0000
63.1200 381.0000 1.0000
63.1600 348.0000 1.0000
63.2000 361.0000 1.0000
63.2400 312.0000 1.0000
63.2800 327.0000 1.0000
63.3200 356.0000 1.0000
63.3600 358.0000 1.0000
63.4000 338.0000 1.0000
63.4400 305.0000 1.0000
63.4800 339.0000 1.0000
63.5200 357.0000 1.0000
63.5600 335.0000 1.0000
63.6000 344.0000 1.0000
63.6400 372.0000 1.0000
63.6800 353.0000 1.0000
63.7200 342.0000 1.0000
63.7600 395.0000 1.0000
63.8000 390.0000 1.0000
63.8400 381.0000 1.0000
63.8800 450.0000 1.0000
63.9200 441.0000 1.0000
63.9600 448.0000 1.0000
64.0000 435.0000 1.0000
64.0400 441.0000 1.0000
64.0800 413.0000 1.0000
64.1200 401.0000 1.0000
64.1600 423.0000 1.0000
64.2000 433.0000 1.0000
64.2400 401.0000 1.0000
64.2800 391.0000 1.0000
64.3200 376.0000 1.0000
64.3600 373.0000 1.0000
64.4000 349.0000 1.0000
64.4400 387.0000 1.0000
64.4800 355.0000 1.0000
64.5200 361.0000 1.0000
64.5600 362.0000 1.0000
64.6000 354.0000 1.0000
64.6400 355.0000 1.0000
64.6800 355.0000 1.0000
64.7200 344.0000 1.0000
64.7600 349.0000 1.0000
64.8000 337.0000 1.0000
64.8400 355.0000 1.0000
64.8800 359.0000 1.0000
64.9200 340.0000 1.0000
64.9600 369.0000 1.0000
65.0000 376.0000 1.0000
65.0400 381.0000 1.0000
65.0800 367.0000 1.0000
65.1200 367.0000 1.0000
65.1600 391.0000 1.0000
65.2000 408.0000 1.0000
65.2400 447.0000 1.0000
65.2800 471.0000 1.0000
65.3200 555.0000 1.0000
65.3600 642.0000 1.0000
65.4000 695.0000 1.0000
65.4400 849.0000 1.0000
65.4800 968.0000 1.0000
65.5200 1092.0000 1.0000
65.5600 1175.0000 1.0000
65.6000 1135.0000 1.0000
65.6400 1025.0000 1.0000
65.6800 939.0000 1.0000
65.7200 935.0000 1.0000
65.7600 833.0000 1.0000
65.8000 788.0000 1.0000
65.8400 623.0000 1.0000
65.8800 543.0000 1.0000
65.9200 495.0000 1.0000
65.9600 467.0000 1.0000
66.0000 421.0000 1.0000
66.0400 407.0000 1.0000
66.0800 391.0000 1.0000
66.1200 346.0000 1.0000
66.1600 391.0000 1.0000
66.2000 382.0000 1.0000
66.2400 330.0000 1.0000
66.2800 336.0000 1.0000
66.3200 323.0000 1.0000
66.3600 345.0000 1.0000
66.4000 344.0000 1.0000
66.4400 301.0000 1.0000
66.4800 349.0000 1.0000
66.5200 317.0000 1.0000
66.5600 322.0000 1.0000
66.6000 373.0000 1.0000
66.6400 329.0000 1.0000
66.6800 348.0000 1.0000
66.7200 306.0000 1.0000
66.7600 331.0000 1.0000
66.8000 304.0000 1.0000
66.8400 308.0000 1.0000
66.8800 297.0000 1.0000
66.9200 326.0000 1.0000
66.9600 290.0000 1.0000
67.0000 292.0000 1.0000
67.0400 278.0000 1.0000
67.0800 318.0000 1.0000
67.1200 333.0000 1.0000
67.1600 330.0000 1.0000
67.2000 340.0000 1.0000
67.2400 340.0000 1.0000
67.2800 307.0000 1.0000
67.3200 339.0000 1.0000
67.3600 310.0000 1.0000
67.4000 307.0000 1.0000
67.4400 306.0000 1.0000
67.4800 304.0000 1.0000
67.5200 316.0000 1.0000
67.5600 287.0000 1.0000
67.6000 288.0000 1.0000
67.6400 304.0000 1.0000
67.6800 308.0000 1.0000
67.7200 313.0000 1.0000
67.7600 287.0000 1.0000
67.8000 298.0000 1.0000
67.8400 307.0000 1.0000
67.8800 310.0000 1.0000
67.9200 320.0000 1.0000
67.9600 297.0000 1.0000
68.0000 268.0000 1.0000
68.0400 301.0000 1.0000
68.0800 297.0000 1.0000
68.1200 307.0000 1.0000
68.1600 307.0000 1.0000
68.2000 305.0000 1.0000
68.2400 292.0000 1.0000
68.2800 289.0000 1.0000
68.3200 306.0000 1.0000
68.3600 306.0000 1.0000
68.4000 282.0000 1.0000
68.4400 301.0000 1.0000
68.4800 279.0000 1.0000
68.5200 267.0000 1.0000
68.5600 277.0000 1.0000
68.6000 281.0000 1.0000
68.6400 313.0000 1.0000
68.6800 305.0000 1.0000
68.7200 285.0000 1.0000
68.7600 318.0000 1.0000
68.8000 308.0000 1.0000
68.8400 317.0000 1.0000
68.8800 322.0000 1.0000
68.9200 303.0000 1.0000
68.9600 295.0000 1.0000
69.0000 305.0000 1.0000
69.0400 317.0000 1.0000
69.0800 303.0000 1.0000
69.1200 297.0000 1.0000
69.1600 302.0000 1.0000
69.2000 289.0000 1.0000
69.2400 299.0000 1.0000
69.2800 293.0000 1.0000
69.3200 284.0000 1.0000
69.3600 282.0000 1.0000
69.4000 310.0000 1.0000
69.4400 293.0000 1.0000
69.4800 304.0000 1.0000
69.5200 327.0000 1.0000
69.5600 291.0000 1.0000
69.6000 301.0000 1.0000
69.6400 323.0000 1.0000
69.6800 296.0000 1.0000
69.7200 299.0000 1.0000
69.7600 284.0000 1.0000
69.8000 274.0000 1.0000
69.8400 311.0000 1.0000
69.8800 298.0000 1.0000
69.9200 306.0000 1.0000
69.9600 290.0000 1.0000
70.0000 291.0000 1.0000
*RAS_INT_END
*RAS_TEMPERATURE_START
*RAS_TEMPERATURE_END
*RAS_DATA_END