File: Data/Dataset1_Only_water/5_XRD/No_095_FTO_TiO2_Hematite_700_7.ras
*RAS_DATA_START
*RAS_HEADER_START
*DISP_FMT_X "%.2f"
*DISP_FMT_Y "%.0f"
*DISP_FULLSCALE "15310.0000000000"
*DISP_LINE_COLOR "255.0000000000"
*DISP_LINE_STYLE "0.0000000000"
*DISP_LINE_WIDTH "0.2500000000"
*DISP_NOTE "測定データ-1"
*DISP_OFFSET_Y "0.0000000000"
*DISP_PEAKSEARCH_UNIT_Y "cps"
*DISP_RANGE_BOTTOM "0.0000000000"
*DISP_RANGE_LEFT "20.0000000000"
*DISP_RANGE_LOGCUTOFF "0.0100000000"
*DISP_RANGE_RIGHT "70.0000000000"
*DISP_RANGE_TOP "15310.0000000000"
*DISP_SCALE_MODE_Y "0.0000000000"
*DISP_TAB_NAME "2θ/θ"
*DISP_TITLE_Y "強度"
*DISP_UNIT_Y "cps"
*DISP_WINDOW_NAME "MSG_MACROENGINE"
*FILE_COMMENT " "
*FILE_MD5 ""
*FILE_MEMO " "
*FILE_OPERATOR "Administrator"
*FILE_SAMPLE " "
*FILE_TYPE "RAS_RAW"
*FILE_USERGROUP "システムマネージャ"
*FILE_VERSION "1.0000000000"
*HW_ATTACHMENT_ID "ATT0025"
*HW_ATTACHMENT_NAME "標準|Standard"
*HW_COUNTER_ID-0 "CUT0025"
*HW_COUNTER_ID-1 "CUT0020"
*HW_COUNTER_ID-2 "CUT0020"
*HW_COUNTER_ID-3 "CSL0021"
*HW_COUNTER_ID-4 "CMC0021"
*HW_COUNTER_NAME-0 "D/teX Ultra|D/teX Ultra"
*HW_COUNTER_NAME-1 "None|None"
*HW_COUNTER_NAME-2 "None|None"
*HW_COUNTER_NAME-3 "BBM|BBM"
*HW_COUNTER_NAME-4 "検出器モノクロメータ|Detector monochromator"
*HW_COUNTER_SELECT_NAME "D/teX Ultra|D/teX Ultra"
*HW_GONIOMETER_ID "GON0023"
*HW_GONIOMETER_NAME "SmartLab|SmartLab"
*HW_GONIOMETER_RADIUS-0 "90.0"
*HW_GONIOMETER_RADIUS-1 "114.0"
*HW_GONIOMETER_RADIUS-2 "190.0"
*HW_GONIOMETER_RADIUS-3 "300.0"
*HW_GONIOMETER_RADIUS-4 "187.0"
*HW_GONIOMETER_RADIUS-5 "300.0"
*HW_GONIOMETER_RADIUS-6 "113.0"
*HW_GONIOMETER_RADIUS-7 "331.0"
*HW_I_OPT_ID-0 "CBO0021"
*HW_I_OPT_ID-1 "ICR0023"
*HW_I_OPT_ID-2 "ISL0021"
*HW_I_OPT_ID-3 "ISO0021"
*HW_I_OPT_ID-4 "IAD0021"
*HW_I_OPT_ID-5 "IPR0001"
*HW_I_OPT_NAME-0 "CBOユニット|CBO unit"
*HW_I_OPT_NAME-1 "標準入射光学ユニット|Standard incident optical unit"
*HW_I_OPT_NAME-2 "標準入射スリットボックス|Standard incident slit box"
*HW_I_OPT_NAME-3 "入射平行スリット|Incident parallel slit"
*HW_I_OPT_NAME-4 "長手制限スリット|Length limiting slit"
*HW_I_OPT_NAME-5 "None|None"
*HW_R_ATTENUATER_AUTOMODE "0"
*HW_R_OPT_ID-0 "RSS0021"
*HW_R_OPT_ID-1 "RCR0023"
*HW_R_OPT_ID-2 "RSO0021"
*HW_R_OPT_ID-3 "RRS0021"
*HW_R_OPT_ID-4 "ATN0021"
*HW_R_OPT_ID-5 "RFL0021"
*HW_R_OPT_ID-6 "RAD0021"
*HW_R_OPT_NAME-0 "標準受光スリットボックス1|Standard receiving slit box # 1"
*HW_R_OPT_NAME-1 "標準受光光学ユニット1|Standard receiving unit # 1"
*HW_R_OPT_NAME-2 "標準受光光学ユニット2|Standard receiving optical unit # 2"
*HW_R_OPT_NAME-3 "標準受光スリットボックス2|Standard receiving slit box # 2"
*HW_R_OPT_NAME-4 "標準アッテネータ|Standard Attenuator"
*HW_R_OPT_NAME-5 "Cu Kβ|Cu K-beta"
*HW_R_OPT_NAME-6 "調整用受光スリット|Alignment receiving slit"
*HW_SAMPLE_HOLDER_ID "SMP0023"
*HW_SAMPLE_HOLDER_NAME "標準Zステージ|Standard Z stage"
*HW_XG_CURRENT_MAX "50"
*HW_XG_CURRENT_MIN "2"
*HW_XG_CURRENT_RESOLUTION "1"
*HW_XG_CURRENT_UNIT "mA"
*HW_XG_FOCUS "1mm x 10mm"
*HW_XG_FOCUS_TYPE "Normal"
*HW_XG_ID ""
*HW_XG_NAME "3kW 封入管(ID:1200)|3kW Sealed tube(ID:1200)"
*HW_XG_TARGET_ATOMIC_NUMBER "29.0000000000"
*HW_XG_TARGET_NAME "Cu"
*HW_XG_TYPE "Hermetic"
*HW_XG_VOLTAGE_MAX "60"
*HW_XG_VOLTAGE_MIN "20"
*HW_XG_VOLTAGE_RESOLUTION "1"
*HW_XG_VOLTAGE_UNIT "kV"
*HW_XG_WATT_MAX "1.500"
*HW_XG_WATT_UNIT "kW"
*HW_XG_WAVE_LENGTH_ALPHA1 "1.540593"
*HW_XG_WAVE_LENGTH_ALPHA2 "1.544414"
*HW_XG_WAVE_LENGTH_BETA "1.392250"
*MEAS_COND_AXIS_NAME-0 "2θ/θ"
*MEAS_COND_AXIS_NAME-1 "2θ"
*MEAS_COND_AXIS_NAME-2 "ω"
*MEAS_COND_AXIS_NAME-3 "Z"
*MEAS_COND_AXIS_NAME-4 "2θ/ω"
*MEAS_COND_AXIS_NAME-5 "θs"
*MEAS_COND_AXIS_NAME-6 "θd"
*MEAS_COND_AXIS_NAME-7 "Ts"
*MEAS_COND_AXIS_NAME-8 "CBO選択スリット"
*MEAS_COND_AXIS_NAME-9 "M"
*MEAS_COND_AXIS_NAME-10 "入射平行スリット"
*MEAS_COND_AXIS_NAME-11 "入射スリット"
*MEAS_COND_AXIS_NAME-12 ""
*MEAS_COND_AXIS_NAME-13 "Zs"
*MEAS_COND_AXIS_NAME-14 "入射光学素子"
*MEAS_COND_AXIS_NAME-15 "長手制限スリット"
*MEAS_COND_AXIS_NAME-16 "センタースリット"
*MEAS_COND_AXIS_NAME-17 "フィルター"
*MEAS_COND_AXIS_NAME-18 "受光スリット1"
*MEAS_COND_AXIS_NAME-19 "受光スリット2"
*MEAS_COND_AXIS_NAME-20 "受光光学素子"
*MEAS_COND_AXIS_NAME-21 "受光平行スリット"
*MEAS_COND_AXIS_NAME-22 "調整用受光スリット"
*MEAS_COND_AXIS_NAME-23 ""
*MEAS_COND_AXIS_NAME-24 ""
*MEAS_COND_AXIS_NAME-25 "Zd"
*MEAS_COND_AXIS_NAME-26 "アッテネータ"
*MEAS_COND_AXIS_NAME-27 "検出器モノクロメータ"
*MEAS_COND_AXIS_NAME-28 "モノクロメータスリット"
*MEAS_COND_AXIS_NAME-29 "プライマリビーム"
*MEAS_COND_AXIS_NAME-30 "PHA"
*MEAS_COND_AXIS_NAME_INTERNAL-0 "TwoThetaTheta"
*MEAS_COND_AXIS_NAME_INTERNAL-1 "TwoTheta"
*MEAS_COND_AXIS_NAME_INTERNAL-2 "Omega"
*MEAS_COND_AXIS_NAME_INTERNAL-3 "Z"
*MEAS_COND_AXIS_NAME_INTERNAL-4 "TwoThetaOmega"
*MEAS_COND_AXIS_NAME_INTERNAL-5 "ThetaS"
*MEAS_COND_AXIS_NAME_INTERNAL-6 "ThetaD"
*MEAS_COND_AXIS_NAME_INTERNAL-7 "Ts"
*MEAS_COND_AXIS_NAME_INTERNAL-8 "CBO"
*MEAS_COND_AXIS_NAME_INTERNAL-9 "CBO-M"
*MEAS_COND_AXIS_NAME_INTERNAL-10 "IncidentSollerSlit"
*MEAS_COND_AXIS_NAME_INTERNAL-11 "IncidentSlitBox"
*MEAS_COND_AXIS_NAME_INTERNAL-12 "IncidentSlitBox-_Axis"
*MEAS_COND_AXIS_NAME_INTERNAL-13 "Zs"
*MEAS_COND_AXIS_NAME_INTERNAL-14 "IncidentMonochromator"
*MEAS_COND_AXIS_NAME_INTERNAL-15 "IncidentAxdSlit"
*MEAS_COND_AXIS_NAME_INTERNAL-16 "CenterSlit"
*MEAS_COND_AXIS_NAME_INTERNAL-17 "Filter"
*MEAS_COND_AXIS_NAME_INTERNAL-18 "ReceivingSlitBox1"
*MEAS_COND_AXIS_NAME_INTERNAL-19 "ReceivingSlitBox2"
*MEAS_COND_AXIS_NAME_INTERNAL-20 "ReceivingOptics"
*MEAS_COND_AXIS_NAME_INTERNAL-21 "ReceivingSollerSlit"
*MEAS_COND_AXIS_NAME_INTERNAL-22 "ReceivingAxdSlit"
*MEAS_COND_AXIS_NAME_INTERNAL-23 "ReceivingSlitBox1-_Axis"
*MEAS_COND_AXIS_NAME_INTERNAL-24 "ReceivingSlitBox2-_Axis"
*MEAS_COND_AXIS_NAME_INTERNAL-25 "ReceivingSlitBox2-Zd"
*MEAS_COND_AXIS_NAME_INTERNAL-26 "Attenuator"
*MEAS_COND_AXIS_NAME_INTERNAL-27 "CounterMonochromator"
*MEAS_COND_AXIS_NAME_INTERNAL-28 "CounterSlit"
*MEAS_COND_AXIS_NAME_INTERNAL-29 "IncidentPrimary"
*MEAS_COND_AXIS_NAME_INTERNAL-30 "PHA"
*MEAS_COND_AXIS_NAME_MAGICNO-0 "83951616.0000000000"
*MEAS_COND_AXIS_NAME_MAGICNO-1 "268632064.0000000000"
*MEAS_COND_AXIS_NAME_MAGICNO-2 "268500992.0000000000"
*MEAS_COND_AXIS_NAME_MAGICNO-3 "285278208.0000000000"
*MEAS_COND_AXIS_NAME_MAGICNO-4 "83951616.0000000000"
*MEAS_COND_AXIS_NAME_MAGICNO-5 "131072.0000000000"
*MEAS_COND_AXIS_NAME_MAGICNO-6 "131072.0000000000"
*MEAS_COND_AXIS_NAME_MAGICNO-7 "318898176.0000000000"
*MEAS_COND_AXIS_NAME_MAGICNO-8 "20971521.0000000000"
*MEAS_COND_AXIS_NAME_MAGICNO-9 "285343744.0000000000"
*MEAS_COND_AXIS_NAME_MAGICNO-10 "20971521.0000000000"
*MEAS_COND_AXIS_NAME_MAGICNO-11 "22020097.0000000000"
*MEAS_COND_AXIS_NAME_MAGICNO-12 "25165824.0000000000"
*MEAS_COND_AXIS_NAME_MAGICNO-13 "318898176.0000000000"
*MEAS_COND_AXIS_NAME_MAGICNO-14 "1.0000000000"
*MEAS_COND_AXIS_NAME_MAGICNO-15 "20971521.0000000000"
*MEAS_COND_AXIS_NAME_MAGICNO-16 "20971521.0000000000"
*MEAS_COND_AXIS_NAME_MAGICNO-17 "20971521.0000000000"
*MEAS_COND_AXIS_NAME_MAGICNO-18 "23068673.0000000000"
*MEAS_COND_AXIS_NAME_MAGICNO-19 "23068673.0000000000"
*MEAS_COND_AXIS_NAME_MAGICNO-20 "20971521.0000000000"
*MEAS_COND_AXIS_NAME_MAGICNO-21 "20971521.0000000000"
*MEAS_COND_AXIS_NAME_MAGICNO-22 "20971521.0000000000"
*MEAS_COND_AXIS_NAME_MAGICNO-23 "25165824.0000000000"
*MEAS_COND_AXIS_NAME_MAGICNO-24 "25165824.0000000000"
*MEAS_COND_AXIS_NAME_MAGICNO-25 "285343744.0000000000"
*MEAS_COND_AXIS_NAME_MAGICNO-26 "17301505.0000000000"
*MEAS_COND_AXIS_NAME_MAGICNO-27 "20971521.0000000000"
*MEAS_COND_AXIS_NAME_MAGICNO-28 "20971521.0000000000"
*MEAS_COND_AXIS_NAME_MAGICNO-29 "20971521.0000000000"
*MEAS_COND_AXIS_NAME_MAGICNO-30 "0.0000000000"
*MEAS_COND_AXIS_OFFSET-0 "-"
*MEAS_COND_AXIS_OFFSET-1 "-0.0310000000"
*MEAS_COND_AXIS_OFFSET-2 "0.5143000000"
*MEAS_COND_AXIS_OFFSET-3 "-"
*MEAS_COND_AXIS_OFFSET-4 "-"
*MEAS_COND_AXIS_OFFSET-5 "0.5143000000"
*MEAS_COND_AXIS_OFFSET-6 "-0.5453000000"
*MEAS_COND_AXIS_OFFSET-7 "-"
*MEAS_COND_AXIS_OFFSET-8 "-"
*MEAS_COND_AXIS_OFFSET-9 "-"
*MEAS_COND_AXIS_OFFSET-10 "-"
*MEAS_COND_AXIS_OFFSET-11 "-"
*MEAS_COND_AXIS_OFFSET-12 "-"
*MEAS_COND_AXIS_OFFSET-13 "-"
*MEAS_COND_AXIS_OFFSET-14 "-"
*MEAS_COND_AXIS_OFFSET-15 "-"
*MEAS_COND_AXIS_OFFSET-16 "-"
*MEAS_COND_AXIS_OFFSET-17 "-"
*MEAS_COND_AXIS_OFFSET-18 "-"
*MEAS_COND_AXIS_OFFSET-19 "-"
*MEAS_COND_AXIS_OFFSET-20 "-"
*MEAS_COND_AXIS_OFFSET-21 "-"
*MEAS_COND_AXIS_OFFSET-22 "-"
*MEAS_COND_AXIS_OFFSET-23 "-"
*MEAS_COND_AXIS_OFFSET-24 "-"
*MEAS_COND_AXIS_OFFSET-25 "-"
*MEAS_COND_AXIS_OFFSET-26 "-"
*MEAS_COND_AXIS_OFFSET-27 "-"
*MEAS_COND_AXIS_OFFSET-28 "-"
*MEAS_COND_AXIS_OFFSET-29 "-"
*MEAS_COND_AXIS_OFFSET-30 "-"
*MEAS_COND_AXIS_POSITION-0 "0.0000000000"
*MEAS_COND_AXIS_POSITION-1 "0.0000000000"
*MEAS_COND_AXIS_POSITION-2 "0.0000000000"
*MEAS_COND_AXIS_POSITION-3 "-2.9061800000"
*MEAS_COND_AXIS_POSITION-4 "0.0000000000"
*MEAS_COND_AXIS_POSITION-5 "0.0000000000"
*MEAS_COND_AXIS_POSITION-6 "0.0000000000"
*MEAS_COND_AXIS_POSITION-7 "-0.7498700000"
*MEAS_COND_AXIS_POSITION-8 "BB"
*MEAS_COND_AXIS_POSITION-9 "0.0000000000"
*MEAS_COND_AXIS_POSITION-10 "Soller_slit_5.0deg"
*MEAS_COND_AXIS_POSITION-11 "2/3deg"
*MEAS_COND_AXIS_POSITION-12 "2.2088000000"
*MEAS_COND_AXIS_POSITION-13 "-0.6412500000"
*MEAS_COND_AXIS_POSITION-14 "0.0000000000"
*MEAS_COND_AXIS_POSITION-15 "10.0mm"
*MEAS_COND_AXIS_POSITION-16 "None"
*MEAS_COND_AXIS_POSITION-17 "Cu_K-beta"
*MEAS_COND_AXIS_POSITION-18 "13.000mm"
*MEAS_COND_AXIS_POSITION-19 "13.000mm"
*MEAS_COND_AXIS_POSITION-20 "No_unit"
*MEAS_COND_AXIS_POSITION-21 "Soller_slit_5.0deg"
*MEAS_COND_AXIS_POSITION-22 "None"
*MEAS_COND_AXIS_POSITION-23 "13.0000000000"
*MEAS_COND_AXIS_POSITION-24 "13.0000000000"
*MEAS_COND_AXIS_POSITION-25 "0.0281300000"
*MEAS_COND_AXIS_POSITION-26 "Open"
*MEAS_COND_AXIS_POSITION-27 "None"
*MEAS_COND_AXIS_POSITION-28 "None"
*MEAS_COND_AXIS_POSITION-29 "None"
*MEAS_COND_AXIS_POSITION-30 "38.0000000000"
*MEAS_COND_AXIS_UNIT-0 "deg"
*MEAS_COND_AXIS_UNIT-1 "deg"
*MEAS_COND_AXIS_UNIT-2 "deg"
*MEAS_COND_AXIS_UNIT-3 "mm"
*MEAS_COND_AXIS_UNIT-4 "deg"
*MEAS_COND_AXIS_UNIT-5 "deg"
*MEAS_COND_AXIS_UNIT-6 "deg"
*MEAS_COND_AXIS_UNIT-7 "mm"
*MEAS_COND_AXIS_UNIT-8 ""
*MEAS_COND_AXIS_UNIT-9 "pulse"
*MEAS_COND_AXIS_UNIT-10 ""
*MEAS_COND_AXIS_UNIT-11 ""
*MEAS_COND_AXIS_UNIT-12 "mm"
*MEAS_COND_AXIS_UNIT-13 "mm"
*MEAS_COND_AXIS_UNIT-14 ""
*MEAS_COND_AXIS_UNIT-15 ""
*MEAS_COND_AXIS_UNIT-16 ""
*MEAS_COND_AXIS_UNIT-17 ""
*MEAS_COND_AXIS_UNIT-18 ""
*MEAS_COND_AXIS_UNIT-19 ""
*MEAS_COND_AXIS_UNIT-20 ""
*MEAS_COND_AXIS_UNIT-21 ""
*MEAS_COND_AXIS_UNIT-22 ""
*MEAS_COND_AXIS_UNIT-23 "mm"
*MEAS_COND_AXIS_UNIT-24 "mm"
*MEAS_COND_AXIS_UNIT-25 "mm"
*MEAS_COND_AXIS_UNIT-26 ""
*MEAS_COND_AXIS_UNIT-27 ""
*MEAS_COND_AXIS_UNIT-28 ""
*MEAS_COND_AXIS_UNIT-29 ""
*MEAS_COND_AXIS_UNIT-30 "div"
*MEAS_COND_COUNTER_CNTLOSS_CORR "0.0000000000"
*MEAS_COND_COUNTER_PHABASE "38.0000000000"
*MEAS_COND_COUNTER_PHAWINDOW "16.0000000000"
*MEAS_COND_COUNTER_PHA_UNIT "div"
*MEAS_COND_COUNTER_TAUDIFF "30.0000000000"
*MEAS_COND_COUNTER_TAUINT "0.0000000000"
*MEAS_COND_IRRADIATION_MODE "OFF"
*MEAS_COND_IRRADIATION_WIDTH ""
*MEAS_COND_OPT_ATTR "集中法"
*MEAS_COND_OPT_NAME "@集中法"
*MEAS_COND_UNSYMMETRIC_MODE "OFF"
*MEAS_COND_XG_CURRENT "30.0000000000"
*MEAS_COND_XG_VOLTAGE "40.0000000000"
*MEAS_COND_XG_WAVE_TYPE "Ka"
*MEAS_DATA_COUNT "5001.0000000000"
*MEAS_SCAN_AXIS_X "2θ/θ"
*MEAS_SCAN_AXIS_X_INTERNAL "TwoThetaTheta"
*MEAS_SCAN_END_TIME "12/20/22 18:15:52"
*MEAS_SCAN_MODE "CONTINUOUS"
*MEAS_SCAN_MONITOR "0"
*MEAS_SCAN_RESOLUTION_X "0.0002"
*MEAS_SCAN_SPEED "2.5"
*MEAS_SCAN_SPEED_UNIT "deg/min"
*MEAS_SCAN_START "20.0000000000"
*MEAS_SCAN_START_TIME "12/20/22 17:54:28"
*MEAS_SCAN_STEP "0.0100000000"
*MEAS_SCAN_STOP "70.0000000000"
*MEAS_SCAN_UNIT_X "deg"
*MEAS_SCAN_UNIT_Y "counts"
*RAS_HEADER_END
*RAS_INT_START
20.0000 960.0000 1.0000
20.0400 965.0000 1.0000
20.0800 982.0000 1.0000
20.1200 1003.0000 1.0000
20.1600 984.0000 1.0000
20.2000 961.0000 1.0000
20.2400 1006.0000 1.0000
20.2800 983.0000 1.0000
20.3200 960.0000 1.0000
20.3600 926.0000 1.0000
20.4000 975.0000 1.0000
20.4400 976.0000 1.0000
20.4800 948.0000 1.0000
20.5200 956.0000 1.0000
20.5600 991.0000 1.0000
20.6000 981.0000 1.0000
20.6400 993.0000 1.0000
20.6800 990.0000 1.0000
20.7200 967.0000 1.0000
20.7600 1010.0000 1.0000
20.8000 977.0000 1.0000
20.8400 929.0000 1.0000
20.8800 993.0000 1.0000
20.9200 989.0000 1.0000
20.9600 967.0000 1.0000
21.0000 987.0000 1.0000
21.0400 973.0000 1.0000
21.0800 1009.0000 1.0000
21.1200 895.0000 1.0000
21.1600 943.0000 1.0000
21.2000 978.0000 1.0000
21.2400 963.0000 1.0000
21.2800 960.0000 1.0000
21.3200 949.0000 1.0000
21.3600 946.0000 1.0000
21.4000 979.0000 1.0000
21.4400 921.0000 1.0000
21.4800 932.0000 1.0000
21.5200 979.0000 1.0000
21.5600 996.0000 1.0000
21.6000 943.0000 1.0000
21.6400 962.0000 1.0000
21.6800 971.0000 1.0000
21.7200 894.0000 1.0000
21.7600 920.0000 1.0000
21.8000 1013.0000 1.0000
21.8400 943.0000 1.0000
21.8800 1038.0000 1.0000
21.9200 1003.0000 1.0000
21.9600 969.0000 1.0000
22.0000 919.0000 1.0000
22.0400 987.0000 1.0000
22.0800 941.0000 1.0000
22.1200 996.0000 1.0000
22.1600 975.0000 1.0000
22.2000 964.0000 1.0000
22.2400 935.0000 1.0000
22.2800 902.0000 1.0000
22.3200 976.0000 1.0000
22.3600 912.0000 1.0000
22.4000 959.0000 1.0000
22.4400 950.0000 1.0000
22.4800 993.0000 1.0000
22.5200 966.0000 1.0000
22.5600 920.0000 1.0000
22.6000 948.0000 1.0000
22.6400 918.0000 1.0000
22.6800 962.0000 1.0000
22.7200 924.0000 1.0000
22.7600 935.0000 1.0000
22.8000 950.0000 1.0000
22.8400 918.0000 1.0000
22.8800 943.0000 1.0000
22.9200 940.0000 1.0000
22.9600 951.0000 1.0000
23.0000 941.0000 1.0000
23.0400 941.0000 1.0000
23.0800 922.0000 1.0000
23.1200 919.0000 1.0000
23.1600 928.0000 1.0000
23.2000 882.0000 1.0000
23.2400 944.0000 1.0000
23.2800 958.0000 1.0000
23.3200 911.0000 1.0000
23.3600 963.0000 1.0000
23.4000 921.0000 1.0000
23.4400 894.0000 1.0000
23.4800 909.0000 1.0000
23.5200 919.0000 1.0000
23.5600 932.0000 1.0000
23.6000 917.0000 1.0000
23.6400 913.0000 1.0000
23.6800 896.0000 1.0000
23.7200 936.0000 1.0000
23.7600 916.0000 1.0000
23.8000 975.0000 1.0000
23.8400 937.0000 1.0000
23.8800 985.0000 1.0000
23.9200 960.0000 1.0000
23.9600 913.0000 1.0000
24.0000 992.0000 1.0000
24.0400 999.0000 1.0000
24.0800 1010.0000 1.0000
24.1200 992.0000 1.0000
24.1600 992.0000 1.0000
24.2000 977.0000 1.0000
24.2400 950.0000 1.0000
24.2800 958.0000 1.0000
24.3200 925.0000 1.0000
24.3600 900.0000 1.0000
24.4000 910.0000 1.0000
24.4400 886.0000 1.0000
24.4800 948.0000 1.0000
24.5200 941.0000 1.0000
24.5600 957.0000 1.0000
24.6000 941.0000 1.0000
24.6400 847.0000 1.0000
24.6800 950.0000 1.0000
24.7200 900.0000 1.0000
24.7600 966.0000 1.0000
24.8000 899.0000 1.0000
24.8400 886.0000 1.0000
24.8800 868.0000 1.0000
24.9200 887.0000 1.0000
24.9600 918.0000 1.0000
25.0000 969.0000 1.0000
25.0400 888.0000 1.0000
25.0800 871.0000 1.0000
25.1200 862.0000 1.0000
25.1600 871.0000 1.0000
25.2000 929.0000 1.0000
25.2400 859.0000 1.0000
25.2800 847.0000 1.0000
25.3200 821.0000 1.0000
25.3600 895.0000 1.0000
25.4000 850.0000 1.0000
25.4400 875.0000 1.0000
25.4800 910.0000 1.0000
25.5200 859.0000 1.0000
25.5600 926.0000 1.0000
25.6000 892.0000 1.0000
25.6400 922.0000 1.0000
25.6800 848.0000 1.0000
25.7200 929.0000 1.0000
25.7600 930.0000 1.0000
25.8000 903.0000 1.0000
25.8400 947.0000 1.0000
25.8800 943.0000 1.0000
25.9200 918.0000 1.0000
25.9600 966.0000 1.0000
26.0000 1052.0000 1.0000
26.0400 978.0000 1.0000
26.0800 1041.0000 1.0000
26.1200 1057.0000 1.0000
26.1600 1126.0000 1.0000
26.2000 1231.0000 1.0000
26.2400 1302.0000 1.0000
26.2800 1545.0000 1.0000
26.3200 1764.0000 1.0000
26.3600 2156.0000 1.0000
26.4000 2666.0000 1.0000
26.4400 3048.0000 1.0000
26.4800 2942.0000 1.0000
26.5200 2501.0000 1.0000
26.5600 2042.0000 1.0000
26.6000 1693.0000 1.0000
26.6400 1433.0000 1.0000
26.6800 1277.0000 1.0000
26.7200 1124.0000 1.0000
26.7600 1069.0000 1.0000
26.8000 1040.0000 1.0000
26.8400 994.0000 1.0000
26.8800 934.0000 1.0000
26.9200 891.0000 1.0000
26.9600 928.0000 1.0000
27.0000 881.0000 1.0000
27.0400 912.0000 1.0000
27.0800 899.0000 1.0000
27.1200 866.0000 1.0000
27.1600 875.0000 1.0000
27.2000 852.0000 1.0000
27.2400 851.0000 1.0000
27.2800 875.0000 1.0000
27.3200 854.0000 1.0000
27.3600 792.0000 1.0000
27.4000 850.0000 1.0000
27.4400 813.0000 1.0000
27.4800 858.0000 1.0000
27.5200 734.0000 1.0000
27.5600 778.0000 1.0000
27.6000 807.0000 1.0000
27.6400 791.0000 1.0000
27.6800 811.0000 1.0000
27.7200 786.0000 1.0000
27.7600 813.0000 1.0000
27.8000 817.0000 1.0000
27.8400 810.0000 1.0000
27.8800 754.0000 1.0000
27.9200 843.0000 1.0000
27.9600 778.0000 1.0000
28.0000 811.0000 1.0000
28.0400 751.0000 1.0000
28.0800 747.0000 1.0000
28.1200 770.0000 1.0000
28.1600 718.0000 1.0000
28.2000 796.0000 1.0000
28.2400 781.0000 1.0000
28.2800 774.0000 1.0000
28.3200 743.0000 1.0000
28.3600 685.0000 1.0000
28.4000 731.0000 1.0000
28.4400 778.0000 1.0000
28.4800 776.0000 1.0000
28.5200 722.0000 1.0000
28.5600 773.0000 1.0000
28.6000 731.0000 1.0000
28.6400 728.0000 1.0000
28.6800 739.0000 1.0000
28.7200 723.0000 1.0000
28.7600 754.0000 1.0000
28.8000 727.0000 1.0000
28.8400 738.0000 1.0000
28.8800 770.0000 1.0000
28.9200 741.0000 1.0000
28.9600 717.0000 1.0000
29.0000 682.0000 1.0000
29.0400 779.0000 1.0000
29.0800 722.0000 1.0000
29.1200 755.0000 1.0000
29.1600 710.0000 1.0000
29.2000 714.0000 1.0000
29.2400 764.0000 1.0000
29.2800 683.0000 1.0000
29.3200 704.0000 1.0000
29.3600 694.0000 1.0000
29.4000 680.0000 1.0000
29.4400 734.0000 1.0000
29.4800 702.0000 1.0000
29.5200 695.0000 1.0000
29.5600 728.0000 1.0000
29.6000 702.0000 1.0000
29.6400 666.0000 1.0000
29.6800 682.0000 1.0000
29.7200 678.0000 1.0000
29.7600 709.0000 1.0000
29.8000 716.0000 1.0000
29.8400 686.0000 1.0000
29.8800 705.0000 1.0000
29.9200 698.0000 1.0000
29.9600 679.0000 1.0000
30.0000 691.0000 1.0000
30.0400 672.0000 1.0000
30.0800 683.0000 1.0000
30.1200 709.0000 1.0000
30.1600 696.0000 1.0000
30.2000 701.0000 1.0000
30.2400 704.0000 1.0000
30.2800 692.0000 1.0000
30.3200 686.0000 1.0000
30.3600 670.0000 1.0000
30.4000 720.0000 1.0000
30.4400 725.0000 1.0000
30.4800 652.0000 1.0000
30.5200 675.0000 1.0000
30.5600 659.0000 1.0000
30.6000 625.0000 1.0000
30.6400 666.0000 1.0000
30.6800 684.0000 1.0000
30.7200 676.0000 1.0000
30.7600 648.0000 1.0000
30.8000 708.0000 1.0000
30.8400 678.0000 1.0000
30.8800 683.0000 1.0000
30.9200 647.0000 1.0000
30.9600 656.0000 1.0000
31.0000 695.0000 1.0000
31.0400 643.0000 1.0000
31.0800 668.0000 1.0000
31.1200 675.0000 1.0000
31.1600 720.0000 1.0000
31.2000 700.0000 1.0000
31.2400 680.0000 1.0000
31.2800 640.0000 1.0000
31.3200 660.0000 1.0000
31.3600 649.0000 1.0000
31.4000 697.0000 1.0000
31.4400 644.0000 1.0000
31.4800 667.0000 1.0000
31.5200 675.0000 1.0000
31.5600 649.0000 1.0000
31.6000 685.0000 1.0000
31.6400 637.0000 1.0000
31.6800 659.0000 1.0000
31.7200 649.0000 1.0000
31.7600 671.0000 1.0000
31.8000 658.0000 1.0000
31.8400 638.0000 1.0000
31.8800 645.0000 1.0000
31.9200 652.0000 1.0000
31.9600 662.0000 1.0000
32.0000 654.0000 1.0000
32.0400 626.0000 1.0000
32.0800 652.0000 1.0000
32.1200 641.0000 1.0000
32.1600 621.0000 1.0000
32.2000 674.0000 1.0000
32.2400 630.0000 1.0000
32.2800 646.0000 1.0000
32.3200 686.0000 1.0000
32.3600 668.0000 1.0000
32.4000 636.0000 1.0000
32.4400 630.0000 1.0000
32.4800 639.0000 1.0000
32.5200 697.0000 1.0000
32.5600 668.0000 1.0000
32.6000 639.0000 1.0000
32.6400 618.0000 1.0000
32.6800 647.0000 1.0000
32.7200 626.0000 1.0000
32.7600 638.0000 1.0000
32.8000 626.0000 1.0000
32.8400 650.0000 1.0000
32.8800 677.0000 1.0000
32.9200 730.0000 1.0000
32.9600 692.0000 1.0000
33.0000 713.0000 1.0000
33.0400 731.0000 1.0000
33.0800 748.0000 1.0000
33.1200 782.0000 1.0000
33.1600 776.0000 1.0000
33.2000 735.0000 1.0000
33.2400 698.0000 1.0000
33.2800 682.0000 1.0000
33.3200 723.0000 1.0000
33.3600 760.0000 1.0000
33.4000 759.0000 1.0000
33.4400 798.0000 1.0000
33.4800 885.0000 1.0000
33.5200 994.0000 1.0000
33.5600 1082.0000 1.0000
33.6000 1357.0000 1.0000
33.6400 1583.0000 1.0000
33.6800 1634.0000 1.0000
33.7200 1447.0000 1.0000
33.7600 1245.0000 1.0000
33.8000 995.0000 1.0000
33.8400 952.0000 1.0000
33.8800 834.0000 1.0000
33.9200 779.0000 1.0000
33.9600 770.0000 1.0000
34.0000 761.0000 1.0000
34.0400 652.0000 1.0000
34.0800 666.0000 1.0000
34.1200 628.0000 1.0000
34.1600 626.0000 1.0000
34.2000 637.0000 1.0000
34.2400 613.0000 1.0000
34.2800 633.0000 1.0000
34.3200 631.0000 1.0000
34.3600 613.0000 1.0000
34.4000 622.0000 1.0000
34.4400 619.0000 1.0000
34.4800 555.0000 1.0000
34.5200 594.0000 1.0000
34.5600 546.0000 1.0000
34.6000 603.0000 1.0000
34.6400 566.0000 1.0000
34.6800 560.0000 1.0000
34.7200 548.0000 1.0000
34.7600 590.0000 1.0000
34.8000 568.0000 1.0000
34.8400 573.0000 1.0000
34.8800 522.0000 1.0000
34.9200 556.0000 1.0000
34.9600 584.0000 1.0000
35.0000 567.0000 1.0000
35.0400 560.0000 1.0000
35.0800 571.0000 1.0000
35.1200 566.0000 1.0000
35.1600 570.0000 1.0000
35.2000 544.0000 1.0000
35.2400 564.0000 1.0000
35.2800 559.0000 1.0000
35.3200 607.0000 1.0000
35.3600 597.0000 1.0000
35.4000 652.0000 1.0000
35.4400 713.0000 1.0000
35.4800 810.0000 1.0000
35.5200 918.0000 1.0000
35.5600 1059.0000 1.0000
35.6000 1051.0000 1.0000
35.6400 987.0000 1.0000
35.6800 875.0000 1.0000
35.7200 739.0000 1.0000
35.7600 697.0000 1.0000
35.8000 642.0000 1.0000
35.8400 596.0000 1.0000
35.8800 541.0000 1.0000
35.9200 573.0000 1.0000
35.9600 543.0000 1.0000
36.0000 545.0000 1.0000
36.0400 548.0000 1.0000
36.0800 494.0000 1.0000
36.1200 525.0000 1.0000
36.1600 539.0000 1.0000
36.2000 563.0000 1.0000
36.2400 494.0000 1.0000
36.2800 503.0000 1.0000
36.3200 508.0000 1.0000
36.3600 547.0000 1.0000
36.4000 537.0000 1.0000
36.4400 501.0000 1.0000
36.4800 506.0000 1.0000
36.5200 529.0000 1.0000
36.5600 540.0000 1.0000
36.6000 529.0000 1.0000
36.6400 497.0000 1.0000
36.6800 490.0000 1.0000
36.7200 511.0000 1.0000
36.7600 481.0000 1.0000
36.8000 476.0000 1.0000
36.8400 497.0000 1.0000
36.8800 501.0000 1.0000
36.9200 493.0000 1.0000
36.9600 516.0000 1.0000
37.0000 541.0000 1.0000
37.0400 511.0000 1.0000
37.0800 489.0000 1.0000
37.1200 525.0000 1.0000
37.1600 513.0000 1.0000
37.2000 528.0000 1.0000
37.2400 514.0000 1.0000
37.2800 524.0000 1.0000
37.3200 562.0000 1.0000
37.3600 646.0000 1.0000
37.4000 683.0000 1.0000
37.4400 740.0000 1.0000
37.4800 842.0000 1.0000
37.5200 1003.0000 1.0000
37.5600 1227.0000 1.0000
37.6000 1510.0000 1.0000
37.6400 1926.0000 1.0000
37.6800 2305.0000 1.0000
37.7200 2400.0000 1.0000
37.7600 2380.0000 1.0000
37.8000 2078.0000 1.0000
37.8400 1689.0000 1.0000
37.8800 1309.0000 1.0000
37.9200 1039.0000 1.0000
37.9600 847.0000 1.0000
38.0000 706.0000 1.0000
38.0400 615.0000 1.0000
38.0800 590.0000 1.0000
38.1200 619.0000 1.0000
38.1600 574.0000 1.0000
38.2000 540.0000 1.0000
38.2400 492.0000 1.0000
38.2800 461.0000 1.0000
38.3200 494.0000 1.0000
38.3600 456.0000 1.0000
38.4000 503.0000 1.0000
38.4400 487.0000 1.0000
38.4800 475.0000 1.0000
38.5200 492.0000 1.0000
38.5600 473.0000 1.0000
38.6000 473.0000 1.0000
38.6400 467.0000 1.0000
38.6800 489.0000 1.0000
38.7200 508.0000 1.0000
38.7600 514.0000 1.0000
38.8000 421.0000 1.0000
38.8400 475.0000 1.0000
38.8800 448.0000 1.0000
38.9200 440.0000 1.0000
38.9600 438.0000 1.0000
39.0000 495.0000 1.0000
39.0400 477.0000 1.0000
39.0800 447.0000 1.0000
39.1200 429.0000 1.0000
39.1600 446.0000 1.0000
39.2000 433.0000 1.0000
39.2400 458.0000 1.0000
39.2800 447.0000 1.0000
39.3200 429.0000 1.0000
39.3600 449.0000 1.0000
39.4000 452.0000 1.0000
39.4400 445.0000 1.0000
39.4800 463.0000 1.0000
39.5200 452.0000 1.0000
39.5600 448.0000 1.0000
39.6000 426.0000 1.0000
39.6400 419.0000 1.0000
39.6800 424.0000 1.0000
39.7200 400.0000 1.0000
39.7600 426.0000 1.0000
39.8000 427.0000 1.0000
39.8400 445.0000 1.0000
39.8800 399.0000 1.0000
39.9200 463.0000 1.0000
39.9600 433.0000 1.0000
40.0000 398.0000 1.0000
40.0400 419.0000 1.0000
40.0800 449.0000 1.0000
40.1200 444.0000 1.0000
40.1600 398.0000 1.0000
40.2000 426.0000 1.0000
40.2400 421.0000 1.0000
40.2800 413.0000 1.0000
40.3200 429.0000 1.0000
40.3600 407.0000 1.0000
40.4000 446.0000 1.0000
40.4400 412.0000 1.0000
40.4800 425.0000 1.0000
40.5200 366.0000 1.0000
40.5600 414.0000 1.0000
40.6000 380.0000 1.0000
40.6400 414.0000 1.0000
40.6800 399.0000 1.0000
40.7200 413.0000 1.0000
40.7600 449.0000 1.0000
40.8000 433.0000 1.0000
40.8400 414.0000 1.0000
40.8800 427.0000 1.0000
40.9200 402.0000 1.0000
40.9600 415.0000 1.0000
41.0000 391.0000 1.0000
41.0400 405.0000 1.0000
41.0800 386.0000 1.0000
41.1200 415.0000 1.0000
41.1600 403.0000 1.0000
41.2000 390.0000 1.0000
41.2400 428.0000 1.0000
41.2800 384.0000 1.0000
41.3200 370.0000 1.0000
41.3600 399.0000 1.0000
41.4000 387.0000 1.0000
41.4400 395.0000 1.0000
41.4800 400.0000 1.0000
41.5200 406.0000 1.0000
41.5600 396.0000 1.0000
41.6000 369.0000 1.0000
41.6400 373.0000 1.0000
41.6800 404.0000 1.0000
41.7200 346.0000 1.0000
41.7600 411.0000 1.0000
41.8000 381.0000 1.0000
41.8400 364.0000 1.0000
41.8800 388.0000 1.0000
41.9200 396.0000 1.0000
41.9600 362.0000 1.0000
42.0000 413.0000 1.0000
42.0400 417.0000 1.0000
42.0800 396.0000 1.0000
42.1200 411.0000 1.0000
42.1600 380.0000 1.0000
42.2000 385.0000 1.0000
42.2400 413.0000 1.0000
42.2800 412.0000 1.0000
42.3200 387.0000 1.0000
42.3600 390.0000 1.0000
42.4000 409.0000 1.0000
42.4400 386.0000 1.0000
42.4800 418.0000 1.0000
42.5200 367.0000 1.0000
42.5600 385.0000 1.0000
42.6000 386.0000 1.0000
42.6400 394.0000 1.0000
42.6800 372.0000 1.0000
42.7200 356.0000 1.0000
42.7600 375.0000 1.0000
42.8000 393.0000 1.0000
42.8400 398.0000 1.0000
42.8800 358.0000 1.0000
42.9200 408.0000 1.0000
42.9600 394.0000 1.0000
43.0000 386.0000 1.0000
43.0400 360.0000 1.0000
43.0800 374.0000 1.0000
43.1200 372.0000 1.0000
43.1600 374.0000 1.0000
43.2000 385.0000 1.0000
43.2400 379.0000 1.0000
43.2800 364.0000 1.0000
43.3200 383.0000 1.0000
43.3600 384.0000 1.0000
43.4000 350.0000 1.0000
43.4400 364.0000 1.0000
43.4800 352.0000 1.0000
43.5200 390.0000 1.0000
43.5600 358.0000 1.0000
43.6000 362.0000 1.0000
43.6400 382.0000 1.0000
43.6800 363.0000 1.0000
43.7200 389.0000 1.0000
43.7600 389.0000 1.0000
43.8000 387.0000 1.0000
43.8400 392.0000 1.0000
43.8800 368.0000 1.0000
43.9200 380.0000 1.0000
43.9600 398.0000 1.0000
44.0000 354.0000 1.0000
44.0400 403.0000 1.0000
44.0800 383.0000 1.0000
44.1200 419.0000 1.0000
44.1600 388.0000 1.0000
44.2000 356.0000 1.0000
44.2400 388.0000 1.0000
44.2800 369.0000 1.0000
44.3200 365.0000 1.0000
44.3600 422.0000 1.0000
44.4000 377.0000 1.0000
44.4400 385.0000 1.0000
44.4800 360.0000 1.0000
44.5200 407.0000 1.0000
44.5600 352.0000 1.0000
44.6000 349.0000 1.0000
44.6400 327.0000 1.0000
44.6800 369.0000 1.0000
44.7200 379.0000 1.0000
44.7600 400.0000 1.0000
44.8000 374.0000 1.0000
44.8400 369.0000 1.0000
44.8800 363.0000 1.0000
44.9200 368.0000 1.0000
44.9600 369.0000 1.0000
45.0000 353.0000 1.0000
45.0400 365.0000 1.0000
45.0800 366.0000 1.0000
45.1200 339.0000 1.0000
45.1600 380.0000 1.0000
45.2000 382.0000 1.0000
45.2400 342.0000 1.0000
45.2800 363.0000 1.0000
45.3200 348.0000 1.0000
45.3600 346.0000 1.0000
45.4000 352.0000 1.0000
45.4400 340.0000 1.0000
45.4800 358.0000 1.0000
45.5200 367.0000 1.0000
45.5600 368.0000 1.0000
45.6000 382.0000 1.0000
45.6400 395.0000 1.0000
45.6800 391.0000 1.0000
45.7200 359.0000 1.0000
45.7600 363.0000 1.0000
45.8000 363.0000 1.0000
45.8400 378.0000 1.0000
45.8800 354.0000 1.0000
45.9200 346.0000 1.0000
45.9600 371.0000 1.0000
46.0000 351.0000 1.0000
46.0400 399.0000 1.0000
46.0800 389.0000 1.0000
46.1200 349.0000 1.0000
46.1600 390.0000 1.0000
46.2000 403.0000 1.0000
46.2400 380.0000 1.0000
46.2800 367.0000 1.0000
46.3200 382.0000 1.0000
46.3600 370.0000 1.0000
46.4000 367.0000 1.0000
46.4400 360.0000 1.0000
46.4800 379.0000 1.0000
46.5200 368.0000 1.0000
46.5600 379.0000 1.0000
46.6000 351.0000 1.0000
46.6400 371.0000 1.0000
46.6800 326.0000 1.0000
46.7200 397.0000 1.0000
46.7600 351.0000 1.0000
46.8000 368.0000 1.0000
46.8400 332.0000 1.0000
46.8800 364.0000 1.0000
46.9200 332.0000 1.0000
46.9600 361.0000 1.0000
47.0000 348.0000 1.0000
47.0400 335.0000 1.0000
47.0800 327.0000 1.0000
47.1200 350.0000 1.0000
47.1600 355.0000 1.0000
47.2000 321.0000 1.0000
47.2400 379.0000 1.0000
47.2800 398.0000 1.0000
47.3200 392.0000 1.0000
47.3600 362.0000 1.0000
47.4000 366.0000 1.0000
47.4400 377.0000 1.0000
47.4800 387.0000 1.0000
47.5200 336.0000 1.0000
47.5600 321.0000 1.0000
47.6000 343.0000 1.0000
47.6400 364.0000 1.0000
47.6800 356.0000 1.0000
47.7200 366.0000 1.0000
47.7600 330.0000 1.0000
47.8000 399.0000 1.0000
47.8400 351.0000 1.0000
47.8800 352.0000 1.0000
47.9200 338.0000 1.0000
47.9600 375.0000 1.0000
48.0000 353.0000 1.0000
48.0400 351.0000 1.0000
48.0800 354.0000 1.0000
48.1200 353.0000 1.0000
48.1600 334.0000 1.0000
48.2000 364.0000 1.0000
48.2400 358.0000 1.0000
48.2800 330.0000 1.0000
48.3200 347.0000 1.0000
48.3600 367.0000 1.0000
48.4000 338.0000 1.0000
48.4400 365.0000 1.0000
48.4800 351.0000 1.0000
48.5200 351.0000 1.0000
48.5600 341.0000 1.0000
48.6000 365.0000 1.0000
48.6400 363.0000 1.0000
48.6800 350.0000 1.0000
48.7200 335.0000 1.0000
48.7600 342.0000 1.0000
48.8000 354.0000 1.0000
48.8400 331.0000 1.0000
48.8800 324.0000 1.0000
48.9200 335.0000 1.0000
48.9600 380.0000 1.0000
49.0000 363.0000 1.0000
49.0400 343.0000 1.0000
49.0800 333.0000 1.0000
49.1200 372.0000 1.0000
49.1600 327.0000 1.0000
49.2000 318.0000 1.0000
49.2400 325.0000 1.0000
49.2800 357.0000 1.0000
49.3200 367.0000 1.0000
49.3600 363.0000 1.0000
49.4000 352.0000 1.0000
49.4400 377.0000 1.0000
49.4800 379.0000 1.0000
49.5200 389.0000 1.0000
49.5600 358.0000 1.0000
49.6000 351.0000 1.0000
49.6400 342.0000 1.0000
49.6800 366.0000 1.0000
49.7200 365.0000 1.0000
49.7600 310.0000 1.0000
49.8000 350.0000 1.0000
49.8400 315.0000 1.0000
49.8800 329.0000 1.0000
49.9200 366.0000 1.0000
49.9600 366.0000 1.0000
50.0000 352.0000 1.0000
50.0400 365.0000 1.0000
50.0800 348.0000 1.0000
50.1200 373.0000 1.0000
50.1600 354.0000 1.0000
50.2000 340.0000 1.0000
50.2400 376.0000 1.0000
50.2800 352.0000 1.0000
50.3200 358.0000 1.0000
50.3600 376.0000 1.0000
50.4000 326.0000 1.0000
50.4400 331.0000 1.0000
50.4800 342.0000 1.0000
50.5200 397.0000 1.0000
50.5600 368.0000 1.0000
50.6000 340.0000 1.0000
50.6400 366.0000 1.0000
50.6800 342.0000 1.0000
50.7200 360.0000 1.0000
50.7600 346.0000 1.0000
50.8000 381.0000 1.0000
50.8400 354.0000 1.0000
50.8800 360.0000 1.0000
50.9200 368.0000 1.0000
50.9600 340.0000 1.0000
51.0000 366.0000 1.0000
51.0400 380.0000 1.0000
51.0800 416.0000 1.0000
51.1200 413.0000 1.0000
51.1600 478.0000 1.0000
51.2000 469.0000 1.0000
51.2400 571.0000 1.0000
51.2800 699.0000 1.0000
51.3200 826.0000 1.0000
51.3600 1097.0000 1.0000
51.4000 1503.0000 1.0000
51.4400 1998.0000 1.0000
51.4800 2304.0000 1.0000
51.5200 2276.0000 1.0000
51.5600 1945.0000 1.0000
51.6000 1765.0000 1.0000
51.6400 1515.0000 1.0000
51.6800 1244.0000 1.0000
51.7200 914.0000 1.0000
51.7600 751.0000 1.0000
51.8000 572.0000 1.0000
51.8400 507.0000 1.0000
51.8800 477.0000 1.0000
51.9200 421.0000 1.0000
51.9600 410.0000 1.0000
52.0000 434.0000 1.0000
52.0400 396.0000 1.0000
52.0800 400.0000 1.0000
52.1200 388.0000 1.0000
52.1600 365.0000 1.0000
52.2000 366.0000 1.0000
52.2400 353.0000 1.0000
52.2800 359.0000 1.0000
52.3200 357.0000 1.0000
52.3600 342.0000 1.0000
52.4000 336.0000 1.0000
52.4400 353.0000 1.0000
52.4800 345.0000 1.0000
52.5200 336.0000 1.0000
52.5600 375.0000 1.0000
52.6000 321.0000 1.0000
52.6400 351.0000 1.0000
52.6800 326.0000 1.0000
52.7200 312.0000 1.0000
52.7600 323.0000 1.0000
52.8000 312.0000 1.0000
52.8400 362.0000 1.0000
52.8800 361.0000 1.0000
52.9200 328.0000 1.0000
52.9600 323.0000 1.0000
53.0000 298.0000 1.0000
53.0400 333.0000 1.0000
53.0800 292.0000 1.0000
53.1200 336.0000 1.0000
53.1600 308.0000 1.0000
53.2000 312.0000 1.0000
53.2400 332.0000 1.0000
53.2800 337.0000 1.0000
53.3200 293.0000 1.0000
53.3600 337.0000 1.0000
53.4000 316.0000 1.0000
53.4400 296.0000 1.0000
53.4800 350.0000 1.0000
53.5200 313.0000 1.0000
53.5600 320.0000 1.0000
53.6000 308.0000 1.0000
53.6400 337.0000 1.0000
53.6800 307.0000 1.0000
53.7200 329.0000 1.0000
53.7600 298.0000 1.0000
53.8000 324.0000 1.0000
53.8400 315.0000 1.0000
53.8800 369.0000 1.0000
53.9200 309.0000 1.0000
53.9600 362.0000 1.0000
54.0000 322.0000 1.0000
54.0400 365.0000 1.0000
54.0800 316.0000 1.0000
54.1200 362.0000 1.0000
54.1600 369.0000 1.0000
54.2000 341.0000 1.0000
54.2400 311.0000 1.0000
54.2800 351.0000 1.0000
54.3200 358.0000 1.0000
54.3600 375.0000 1.0000
54.4000 387.0000 1.0000
54.4400 433.0000 1.0000
54.4800 449.0000 1.0000
54.5200 446.0000 1.0000
54.5600 448.0000 1.0000
54.6000 427.0000 1.0000
54.6400 459.0000 1.0000
54.6800 414.0000 1.0000
54.7200 388.0000 1.0000
54.7600 364.0000 1.0000
54.8000 348.0000 1.0000
54.8400 311.0000 1.0000
54.8800 331.0000 1.0000
54.9200 324.0000 1.0000
54.9600 344.0000 1.0000
55.0000 308.0000 1.0000
55.0400 302.0000 1.0000
55.0800 313.0000 1.0000
55.1200 301.0000 1.0000
55.1600 314.0000 1.0000
55.2000 300.0000 1.0000
55.2400 309.0000 1.0000
55.2800 324.0000 1.0000
55.3200 285.0000 1.0000
55.3600 303.0000 1.0000
55.4000 308.0000 1.0000
55.4400 307.0000 1.0000
55.4800 294.0000 1.0000
55.5200 295.0000 1.0000
55.5600 281.0000 1.0000
55.6000 295.0000 1.0000
55.6400 286.0000 1.0000
55.6800 305.0000 1.0000
55.7200 260.0000 1.0000
55.7600 300.0000 1.0000
55.8000 329.0000 1.0000
55.8400 290.0000 1.0000
55.8800 323.0000 1.0000
55.9200 310.0000 1.0000
55.9600 307.0000 1.0000
56.0000 312.0000 1.0000
56.0400 294.0000 1.0000
56.0800 297.0000 1.0000
56.1200 303.0000 1.0000
56.1600 275.0000 1.0000
56.2000 288.0000 1.0000
56.2400 278.0000 1.0000
56.2800 288.0000 1.0000
56.3200 300.0000 1.0000
56.3600 294.0000 1.0000
56.4000 258.0000 1.0000
56.4400 342.0000 1.0000
56.4800 320.0000 1.0000
56.5200 286.0000 1.0000
56.5600 262.0000 1.0000
56.6000 315.0000 1.0000
56.6400 322.0000 1.0000
56.6800 292.0000 1.0000
56.7200 301.0000 1.0000
56.7600 291.0000 1.0000
56.8000 318.0000 1.0000
56.8400 282.0000 1.0000
56.8800 286.0000 1.0000
56.9200 306.0000 1.0000
56.9600 320.0000 1.0000
57.0000 302.0000 1.0000
57.0400 301.0000 1.0000
57.0800 283.0000 1.0000
57.1200 296.0000 1.0000
57.1600 308.0000 1.0000
57.2000 258.0000 1.0000
57.2400 304.0000 1.0000
57.2800 267.0000 1.0000
57.3200 298.0000 1.0000
57.3600 283.0000 1.0000
57.4000 294.0000 1.0000
57.4400 299.0000 1.0000
57.4800 311.0000 1.0000
57.5200 315.0000 1.0000
57.5600 287.0000 1.0000
57.6000 298.0000 1.0000
57.6400 277.0000 1.0000
57.6800 296.0000 1.0000
57.7200 298.0000 1.0000
57.7600 289.0000 1.0000
57.8000 287.0000 1.0000
57.8400 275.0000 1.0000
57.8800 295.0000 1.0000
57.9200 292.0000 1.0000
57.9600 302.0000 1.0000
58.0000 295.0000 1.0000
58.0400 282.0000 1.0000
58.0800 269.0000 1.0000
58.1200 293.0000 1.0000
58.1600 276.0000 1.0000
58.2000 269.0000 1.0000
58.2400 286.0000 1.0000
58.2800 290.0000 1.0000
58.3200 292.0000 1.0000
58.3600 284.0000 1.0000
58.4000 300.0000 1.0000
58.4400 294.0000 1.0000
58.4800 285.0000 1.0000
58.5200 274.0000 1.0000
58.5600 277.0000 1.0000
58.6000 304.0000 1.0000
58.6400 265.0000 1.0000
58.6800 295.0000 1.0000
58.7200 277.0000 1.0000
58.7600 272.0000 1.0000
58.8000 269.0000 1.0000
58.8400 275.0000 1.0000
58.8800 303.0000 1.0000
58.9200 311.0000 1.0000
58.9600 285.0000 1.0000
59.0000 273.0000 1.0000
59.0400 264.0000 1.0000
59.0800 291.0000 1.0000
59.1200 295.0000 1.0000
59.1600 278.0000 1.0000
59.2000 311.0000 1.0000
59.2400 270.0000 1.0000
59.2800 284.0000 1.0000
59.3200 283.0000 1.0000
59.3600 266.0000 1.0000
59.4000 271.0000 1.0000
59.4400 269.0000 1.0000
59.4800 267.0000 1.0000
59.5200 295.0000 1.0000
59.5600 274.0000 1.0000
59.6000 266.0000 1.0000
59.6400 302.0000 1.0000
59.6800 274.0000 1.0000
59.7200 326.0000 1.0000
59.7600 307.0000 1.0000
59.8000 280.0000 1.0000
59.8400 289.0000 1.0000
59.8800 283.0000 1.0000
59.9200 325.0000 1.0000
59.9600 295.0000 1.0000
60.0000 300.0000 1.0000
60.0400 294.0000 1.0000
60.0800 279.0000 1.0000
60.1200 310.0000 1.0000
60.1600 274.0000 1.0000
60.2000 274.0000 1.0000
60.2400 293.0000 1.0000
60.2800 303.0000 1.0000
60.3200 294.0000 1.0000
60.3600 280.0000 1.0000
60.4000 321.0000 1.0000
60.4400 279.0000 1.0000
60.4800 263.0000 1.0000
60.5200 293.0000 1.0000
60.5600 273.0000 1.0000
60.6000 278.0000 1.0000
60.6400 257.0000 1.0000
60.6800 295.0000 1.0000
60.7200 271.0000 1.0000
60.7600 315.0000 1.0000
60.8000 284.0000 1.0000
60.8400 289.0000 1.0000
60.8800 307.0000 1.0000
60.9200 298.0000 1.0000
60.9600 323.0000 1.0000
61.0000 303.0000 1.0000
61.0400 293.0000 1.0000
61.0800 314.0000 1.0000
61.1200 324.0000 1.0000
61.1600 327.0000 1.0000
61.2000 339.0000 1.0000
61.2400 343.0000 1.0000
61.2800 352.0000 1.0000
61.3200 384.0000 1.0000
61.3600 405.0000 1.0000
61.4000 477.0000 1.0000
61.4400 511.0000 1.0000
61.4800 566.0000 1.0000
61.5200 574.0000 1.0000
61.5600 565.0000 1.0000
61.6000 594.0000 1.0000
61.6400 550.0000 1.0000
61.6800 586.0000 1.0000
61.7200 536.0000 1.0000
61.7600 464.0000 1.0000
61.8000 448.0000 1.0000
61.8400 397.0000 1.0000
61.8800 409.0000 1.0000
61.9200 356.0000 1.0000
61.9600 342.0000 1.0000
62.0000 354.0000 1.0000
62.0400 345.0000 1.0000
62.0800 314.0000 1.0000
62.1200 307.0000 1.0000
62.1600 321.0000 1.0000
62.2000 291.0000 1.0000
62.2400 300.0000 1.0000
62.2800 307.0000 1.0000
62.3200 328.0000 1.0000
62.3600 309.0000 1.0000
62.4000 297.0000 1.0000
62.4400 322.0000 1.0000
62.4800 304.0000 1.0000
62.5200 290.0000 1.0000
62.5600 308.0000 1.0000
62.6000 314.0000 1.0000
62.6400 298.0000 1.0000
62.6800 289.0000 1.0000
62.7200 293.0000 1.0000
62.7600 294.0000 1.0000
62.8000 294.0000 1.0000
62.8400 277.0000 1.0000
62.8800 271.0000 1.0000
62.9200 296.0000 1.0000
62.9600 297.0000 1.0000
63.0000 287.0000 1.0000
63.0400 270.0000 1.0000
63.0800 268.0000 1.0000
63.1200 282.0000 1.0000
63.1600 287.0000 1.0000
63.2000 271.0000 1.0000
63.2400 294.0000 1.0000
63.2800 291.0000 1.0000
63.3200 296.0000 1.0000
63.3600 282.0000 1.0000
63.4000 269.0000 1.0000
63.4400 272.0000 1.0000
63.4800 282.0000 1.0000
63.5200 286.0000 1.0000
63.5600 283.0000 1.0000
63.6000 284.0000 1.0000
63.6400 279.0000 1.0000
63.6800 309.0000 1.0000
63.7200 324.0000 1.0000
63.7600 293.0000 1.0000
63.8000 340.0000 1.0000
63.8400 366.0000 1.0000
63.8800 375.0000 1.0000
63.9200 419.0000 1.0000
63.9600 450.0000 1.0000
64.0000 428.0000 1.0000
64.0400 380.0000 1.0000
64.0800 428.0000 1.0000
64.1200 378.0000 1.0000
64.1600 399.0000 1.0000
64.2000 368.0000 1.0000
64.2400 329.0000 1.0000
64.2800 349.0000 1.0000
64.3200 327.0000 1.0000
64.3600 319.0000 1.0000
64.4000 295.0000 1.0000
64.4400 280.0000 1.0000
64.4800 334.0000 1.0000
64.5200 279.0000 1.0000
64.5600 283.0000 1.0000
64.6000 276.0000 1.0000
64.6400 324.0000 1.0000
64.6800 294.0000 1.0000
64.7200 298.0000 1.0000
64.7600 326.0000 1.0000
64.8000 314.0000 1.0000
64.8400 304.0000 1.0000
64.8800 295.0000 1.0000
64.9200 291.0000 1.0000
64.9600 328.0000 1.0000
65.0000 306.0000 1.0000
65.0400 311.0000 1.0000
65.0800 340.0000 1.0000
65.1200 354.0000 1.0000
65.1600 346.0000 1.0000
65.2000 362.0000 1.0000
65.2400 388.0000 1.0000
65.2800 432.0000 1.0000
65.3200 497.0000 1.0000
65.3600 556.0000 1.0000
65.4000 649.0000 1.0000
65.4400 770.0000 1.0000
65.4800 897.0000 1.0000
65.5200 992.0000 1.0000
65.5600 1039.0000 1.0000
65.6000 1054.0000 1.0000
65.6400 944.0000 1.0000
65.6800 892.0000 1.0000
65.7200 835.0000 1.0000
65.7600 744.0000 1.0000
65.8000 628.0000 1.0000
65.8400 540.0000 1.0000
65.8800 468.0000 1.0000
65.9200 403.0000 1.0000
65.9600 390.0000 1.0000
66.0000 384.0000 1.0000
66.0400 336.0000 1.0000
66.0800 331.0000 1.0000
66.1200 341.0000 1.0000
66.1600 316.0000 1.0000
66.2000 292.0000 1.0000
66.2400 292.0000 1.0000
66.2800 302.0000 1.0000
66.3200 266.0000 1.0000
66.3600 264.0000 1.0000
66.4000 260.0000 1.0000
66.4400 252.0000 1.0000
66.4800 252.0000 1.0000
66.5200 290.0000 1.0000
66.5600 265.0000 1.0000
66.6000 280.0000 1.0000
66.6400 275.0000 1.0000
66.6800 293.0000 1.0000
66.7200 253.0000 1.0000
66.7600 249.0000 1.0000
66.8000 255.0000 1.0000
66.8400 275.0000 1.0000
66.8800 261.0000 1.0000
66.9200 258.0000 1.0000
66.9600 283.0000 1.0000
67.0000 265.0000 1.0000
67.0400 256.0000 1.0000
67.0800 326.0000 1.0000
67.1200 239.0000 1.0000
67.1600 264.0000 1.0000
67.2000 238.0000 1.0000
67.2400 274.0000 1.0000
67.2800 237.0000 1.0000
67.3200 243.0000 1.0000
67.3600 247.0000 1.0000
67.4000 260.0000 1.0000
67.4400 245.0000 1.0000
67.4800 245.0000 1.0000
67.5200 250.0000 1.0000
67.5600 246.0000 1.0000
67.6000 271.0000 1.0000
67.6400 262.0000 1.0000
67.6800 245.0000 1.0000
67.7200 219.0000 1.0000
67.7600 238.0000 1.0000
67.8000 244.0000 1.0000
67.8400 240.0000 1.0000
67.8800 240.0000 1.0000
67.9200 258.0000 1.0000
67.9600 239.0000 1.0000
68.0000 236.0000 1.0000
68.0400 252.0000 1.0000
68.0800 271.0000 1.0000
68.1200 257.0000 1.0000
68.1600 241.0000 1.0000
68.2000 238.0000 1.0000
68.2400 244.0000 1.0000
68.2800 236.0000 1.0000
68.3200 232.0000 1.0000
68.3600 274.0000 1.0000
68.4000 230.0000 1.0000
68.4400 284.0000 1.0000
68.4800 233.0000 1.0000
68.5200 233.0000 1.0000
68.5600 239.0000 1.0000
68.6000 248.0000 1.0000
68.6400 236.0000 1.0000
68.6800 237.0000 1.0000
68.7200 244.0000 1.0000
68.7600 235.0000 1.0000
68.8000 248.0000 1.0000
68.8400 229.0000 1.0000
68.8800 263.0000 1.0000
68.9200 243.0000 1.0000
68.9600 268.0000 1.0000
69.0000 252.0000 1.0000
69.0400 216.0000 1.0000
69.0800 230.0000 1.0000
69.1200 239.0000 1.0000
69.1600 247.0000 1.0000
69.2000 241.0000 1.0000
69.2400 223.0000 1.0000
69.2800 218.0000 1.0000
69.3200 235.0000 1.0000
69.3600 222.0000 1.0000
69.4000 242.0000 1.0000
69.4400 229.0000 1.0000
69.4800 243.0000 1.0000
69.5200 237.0000 1.0000
69.5600 235.0000 1.0000
69.6000 214.0000 1.0000
69.6400 242.0000 1.0000
69.6800 215.0000 1.0000
69.7200 232.0000 1.0000
69.7600 237.0000 1.0000
69.8000 208.0000 1.0000
69.8400 229.0000 1.0000
69.8800 244.0000 1.0000
69.9200 230.0000 1.0000
69.9600 248.0000 1.0000
70.0000 251.0000 1.0000
*RAS_INT_END
*RAS_TEMPERATURE_START
*RAS_TEMPERATURE_END
*RAS_DATA_END