File: Data/Dataset1_Only_water/5_XRD/No_062_deposition_3h_TiO2_Air_9.ras
*RAS_DATA_START
*RAS_HEADER_START
*DISP_FMT_X "%.2f"
*DISP_FMT_Y "%.0f"
*DISP_FULLSCALE "20150.0000000000"
*DISP_LINE_COLOR "255.0000000000"
*DISP_LINE_STYLE "0.0000000000"
*DISP_LINE_WIDTH "0.2500000000"
*DISP_NOTE "測定データ-3"
*DISP_OFFSET_Y "0.0000000000"
*DISP_PEAKSEARCH_UNIT_Y "cps"
*DISP_RANGE_BOTTOM "0.0000000000"
*DISP_RANGE_LEFT "20.0000000000"
*DISP_RANGE_LOGCUTOFF "0.0100000000"
*DISP_RANGE_RIGHT "70.0000000000"
*DISP_RANGE_TOP "20150.0000000000"
*DISP_SCALE_MODE_Y "0.0000000000"
*DISP_TAB_NAME "2θ/θ"
*DISP_TITLE_Y "強度"
*DISP_UNIT_Y "cps"
*DISP_WINDOW_NAME "MSG_MACROENGINE"
*FILE_COMMENT " "
*FILE_MD5 ""
*FILE_MEMO " "
*FILE_OPERATOR "Administrator"
*FILE_SAMPLE " "
*FILE_TYPE "RAS_RAW"
*FILE_USERGROUP "システムマネージャ"
*FILE_VERSION "1.0000000000"
*HW_ATTACHMENT_ID "ATT0025"
*HW_ATTACHMENT_NAME "標準|Standard"
*HW_COUNTER_ID-0 "CUT0025"
*HW_COUNTER_ID-1 "CUT0020"
*HW_COUNTER_ID-2 "CUT0020"
*HW_COUNTER_ID-3 "CSL0021"
*HW_COUNTER_ID-4 "CMC0021"
*HW_COUNTER_NAME-0 "D/teX Ultra|D/teX Ultra"
*HW_COUNTER_NAME-1 "None|None"
*HW_COUNTER_NAME-2 "None|None"
*HW_COUNTER_NAME-3 "BBM|BBM"
*HW_COUNTER_NAME-4 "検出器モノクロメータ|Detector monochromator"
*HW_COUNTER_SELECT_NAME "D/teX Ultra|D/teX Ultra"
*HW_GONIOMETER_ID "GON0023"
*HW_GONIOMETER_NAME "SmartLab|SmartLab"
*HW_GONIOMETER_RADIUS-0 "90.0"
*HW_GONIOMETER_RADIUS-1 "114.0"
*HW_GONIOMETER_RADIUS-2 "190.0"
*HW_GONIOMETER_RADIUS-3 "300.0"
*HW_GONIOMETER_RADIUS-4 "187.0"
*HW_GONIOMETER_RADIUS-5 "300.0"
*HW_GONIOMETER_RADIUS-6 "113.0"
*HW_GONIOMETER_RADIUS-7 "331.0"
*HW_I_OPT_ID-0 "CBO0021"
*HW_I_OPT_ID-1 "ICR0023"
*HW_I_OPT_ID-2 "ISL0021"
*HW_I_OPT_ID-3 "ISO0021"
*HW_I_OPT_ID-4 "IAD0021"
*HW_I_OPT_ID-5 "IPR0001"
*HW_I_OPT_NAME-0 "CBOユニット|CBO unit"
*HW_I_OPT_NAME-1 "標準入射光学ユニット|Standard incident optical unit"
*HW_I_OPT_NAME-2 "標準入射スリットボックス|Standard incident slit box"
*HW_I_OPT_NAME-3 "入射平行スリット|Incident parallel slit"
*HW_I_OPT_NAME-4 "長手制限スリット|Length limiting slit"
*HW_I_OPT_NAME-5 "None|None"
*HW_R_ATTENUATER_AUTOMODE "0"
*HW_R_OPT_ID-0 "RSS0021"
*HW_R_OPT_ID-1 "RCR0023"
*HW_R_OPT_ID-2 "RSO0021"
*HW_R_OPT_ID-3 "RRS0021"
*HW_R_OPT_ID-4 "ATN0021"
*HW_R_OPT_ID-5 "RFL0021"
*HW_R_OPT_ID-6 "RAD0021"
*HW_R_OPT_NAME-0 "標準受光スリットボックス1|Standard receiving slit box # 1"
*HW_R_OPT_NAME-1 "標準受光光学ユニット1|Standard receiving unit # 1"
*HW_R_OPT_NAME-2 "標準受光光学ユニット2|Standard receiving optical unit # 2"
*HW_R_OPT_NAME-3 "標準受光スリットボックス2|Standard receiving slit box # 2"
*HW_R_OPT_NAME-4 "標準アッテネータ|Standard Attenuator"
*HW_R_OPT_NAME-5 "Cu Kβ|Cu K-beta"
*HW_R_OPT_NAME-6 "調整用受光スリット|Alignment receiving slit"
*HW_SAMPLE_HOLDER_ID "SMP0023"
*HW_SAMPLE_HOLDER_NAME "標準Zステージ|Standard Z stage"
*HW_XG_CURRENT_MAX "50"
*HW_XG_CURRENT_MIN "2"
*HW_XG_CURRENT_RESOLUTION "1"
*HW_XG_CURRENT_UNIT "mA"
*HW_XG_FOCUS "1mm x 10mm"
*HW_XG_FOCUS_TYPE "Normal"
*HW_XG_ID ""
*HW_XG_NAME "3kW 封入管(ID:1200)|3kW Sealed tube(ID:1200)"
*HW_XG_TARGET_ATOMIC_NUMBER "29.0000000000"
*HW_XG_TARGET_NAME "Cu"
*HW_XG_TYPE "Hermetic"
*HW_XG_VOLTAGE_MAX "60"
*HW_XG_VOLTAGE_MIN "20"
*HW_XG_VOLTAGE_RESOLUTION "1"
*HW_XG_VOLTAGE_UNIT "kV"
*HW_XG_WATT_MAX "1.500"
*HW_XG_WATT_UNIT "kW"
*HW_XG_WAVE_LENGTH_ALPHA1 "1.540593"
*HW_XG_WAVE_LENGTH_ALPHA2 "1.544414"
*HW_XG_WAVE_LENGTH_BETA "1.392250"
*MEAS_COND_AXIS_NAME-0 "2θ/θ"
*MEAS_COND_AXIS_NAME-1 "2θ"
*MEAS_COND_AXIS_NAME-2 "ω"
*MEAS_COND_AXIS_NAME-3 "Z"
*MEAS_COND_AXIS_NAME-4 "2θ/ω"
*MEAS_COND_AXIS_NAME-5 "θs"
*MEAS_COND_AXIS_NAME-6 "θd"
*MEAS_COND_AXIS_NAME-7 "Ts"
*MEAS_COND_AXIS_NAME-8 "CBO選択スリット"
*MEAS_COND_AXIS_NAME-9 "M"
*MEAS_COND_AXIS_NAME-10 "入射平行スリット"
*MEAS_COND_AXIS_NAME-11 "入射スリット"
*MEAS_COND_AXIS_NAME-12 ""
*MEAS_COND_AXIS_NAME-13 "Zs"
*MEAS_COND_AXIS_NAME-14 "入射光学素子"
*MEAS_COND_AXIS_NAME-15 "長手制限スリット"
*MEAS_COND_AXIS_NAME-16 "センタースリット"
*MEAS_COND_AXIS_NAME-17 "フィルター"
*MEAS_COND_AXIS_NAME-18 "受光スリット1"
*MEAS_COND_AXIS_NAME-19 "受光スリット2"
*MEAS_COND_AXIS_NAME-20 "受光光学素子"
*MEAS_COND_AXIS_NAME-21 "受光平行スリット"
*MEAS_COND_AXIS_NAME-22 "調整用受光スリット"
*MEAS_COND_AXIS_NAME-23 ""
*MEAS_COND_AXIS_NAME-24 ""
*MEAS_COND_AXIS_NAME-25 "Zd"
*MEAS_COND_AXIS_NAME-26 "アッテネータ"
*MEAS_COND_AXIS_NAME-27 "検出器モノクロメータ"
*MEAS_COND_AXIS_NAME-28 "モノクロメータスリット"
*MEAS_COND_AXIS_NAME-29 "プライマリビーム"
*MEAS_COND_AXIS_NAME-30 "PHA"
*MEAS_COND_AXIS_NAME_INTERNAL-0 "TwoThetaTheta"
*MEAS_COND_AXIS_NAME_INTERNAL-1 "TwoTheta"
*MEAS_COND_AXIS_NAME_INTERNAL-2 "Omega"
*MEAS_COND_AXIS_NAME_INTERNAL-3 "Z"
*MEAS_COND_AXIS_NAME_INTERNAL-4 "TwoThetaOmega"
*MEAS_COND_AXIS_NAME_INTERNAL-5 "ThetaS"
*MEAS_COND_AXIS_NAME_INTERNAL-6 "ThetaD"
*MEAS_COND_AXIS_NAME_INTERNAL-7 "Ts"
*MEAS_COND_AXIS_NAME_INTERNAL-8 "CBO"
*MEAS_COND_AXIS_NAME_INTERNAL-9 "CBO-M"
*MEAS_COND_AXIS_NAME_INTERNAL-10 "IncidentSollerSlit"
*MEAS_COND_AXIS_NAME_INTERNAL-11 "IncidentSlitBox"
*MEAS_COND_AXIS_NAME_INTERNAL-12 "IncidentSlitBox-_Axis"
*MEAS_COND_AXIS_NAME_INTERNAL-13 "Zs"
*MEAS_COND_AXIS_NAME_INTERNAL-14 "IncidentMonochromator"
*MEAS_COND_AXIS_NAME_INTERNAL-15 "IncidentAxdSlit"
*MEAS_COND_AXIS_NAME_INTERNAL-16 "CenterSlit"
*MEAS_COND_AXIS_NAME_INTERNAL-17 "Filter"
*MEAS_COND_AXIS_NAME_INTERNAL-18 "ReceivingSlitBox1"
*MEAS_COND_AXIS_NAME_INTERNAL-19 "ReceivingSlitBox2"
*MEAS_COND_AXIS_NAME_INTERNAL-20 "ReceivingOptics"
*MEAS_COND_AXIS_NAME_INTERNAL-21 "ReceivingSollerSlit"
*MEAS_COND_AXIS_NAME_INTERNAL-22 "ReceivingAxdSlit"
*MEAS_COND_AXIS_NAME_INTERNAL-23 "ReceivingSlitBox1-_Axis"
*MEAS_COND_AXIS_NAME_INTERNAL-24 "ReceivingSlitBox2-_Axis"
*MEAS_COND_AXIS_NAME_INTERNAL-25 "ReceivingSlitBox2-Zd"
*MEAS_COND_AXIS_NAME_INTERNAL-26 "Attenuator"
*MEAS_COND_AXIS_NAME_INTERNAL-27 "CounterMonochromator"
*MEAS_COND_AXIS_NAME_INTERNAL-28 "CounterSlit"
*MEAS_COND_AXIS_NAME_INTERNAL-29 "IncidentPrimary"
*MEAS_COND_AXIS_NAME_INTERNAL-30 "PHA"
*MEAS_COND_AXIS_NAME_MAGICNO-0 "83951616.0000000000"
*MEAS_COND_AXIS_NAME_MAGICNO-1 "268632064.0000000000"
*MEAS_COND_AXIS_NAME_MAGICNO-2 "268500992.0000000000"
*MEAS_COND_AXIS_NAME_MAGICNO-3 "285278208.0000000000"
*MEAS_COND_AXIS_NAME_MAGICNO-4 "83951616.0000000000"
*MEAS_COND_AXIS_NAME_MAGICNO-5 "131072.0000000000"
*MEAS_COND_AXIS_NAME_MAGICNO-6 "131072.0000000000"
*MEAS_COND_AXIS_NAME_MAGICNO-7 "318898176.0000000000"
*MEAS_COND_AXIS_NAME_MAGICNO-8 "20971521.0000000000"
*MEAS_COND_AXIS_NAME_MAGICNO-9 "285343744.0000000000"
*MEAS_COND_AXIS_NAME_MAGICNO-10 "20971521.0000000000"
*MEAS_COND_AXIS_NAME_MAGICNO-11 "22020097.0000000000"
*MEAS_COND_AXIS_NAME_MAGICNO-12 "25165824.0000000000"
*MEAS_COND_AXIS_NAME_MAGICNO-13 "318898176.0000000000"
*MEAS_COND_AXIS_NAME_MAGICNO-14 "1.0000000000"
*MEAS_COND_AXIS_NAME_MAGICNO-15 "20971521.0000000000"
*MEAS_COND_AXIS_NAME_MAGICNO-16 "20971521.0000000000"
*MEAS_COND_AXIS_NAME_MAGICNO-17 "20971521.0000000000"
*MEAS_COND_AXIS_NAME_MAGICNO-18 "23068673.0000000000"
*MEAS_COND_AXIS_NAME_MAGICNO-19 "23068673.0000000000"
*MEAS_COND_AXIS_NAME_MAGICNO-20 "20971521.0000000000"
*MEAS_COND_AXIS_NAME_MAGICNO-21 "20971521.0000000000"
*MEAS_COND_AXIS_NAME_MAGICNO-22 "20971521.0000000000"
*MEAS_COND_AXIS_NAME_MAGICNO-23 "25165824.0000000000"
*MEAS_COND_AXIS_NAME_MAGICNO-24 "25165824.0000000000"
*MEAS_COND_AXIS_NAME_MAGICNO-25 "285343744.0000000000"
*MEAS_COND_AXIS_NAME_MAGICNO-26 "17301505.0000000000"
*MEAS_COND_AXIS_NAME_MAGICNO-27 "20971521.0000000000"
*MEAS_COND_AXIS_NAME_MAGICNO-28 "20971521.0000000000"
*MEAS_COND_AXIS_NAME_MAGICNO-29 "20971521.0000000000"
*MEAS_COND_AXIS_NAME_MAGICNO-30 "0.0000000000"
*MEAS_COND_AXIS_OFFSET-0 "-"
*MEAS_COND_AXIS_OFFSET-1 "-0.0801000000"
*MEAS_COND_AXIS_OFFSET-2 "0.1283000000"
*MEAS_COND_AXIS_OFFSET-3 "-"
*MEAS_COND_AXIS_OFFSET-4 "-"
*MEAS_COND_AXIS_OFFSET-5 "0.1283000000"
*MEAS_COND_AXIS_OFFSET-6 "-0.2084000000"
*MEAS_COND_AXIS_OFFSET-7 "-"
*MEAS_COND_AXIS_OFFSET-8 "-"
*MEAS_COND_AXIS_OFFSET-9 "-"
*MEAS_COND_AXIS_OFFSET-10 "-"
*MEAS_COND_AXIS_OFFSET-11 "-"
*MEAS_COND_AXIS_OFFSET-12 "-"
*MEAS_COND_AXIS_OFFSET-13 "-"
*MEAS_COND_AXIS_OFFSET-14 "-"
*MEAS_COND_AXIS_OFFSET-15 "-"
*MEAS_COND_AXIS_OFFSET-16 "-"
*MEAS_COND_AXIS_OFFSET-17 "-"
*MEAS_COND_AXIS_OFFSET-18 "-"
*MEAS_COND_AXIS_OFFSET-19 "-"
*MEAS_COND_AXIS_OFFSET-20 "-"
*MEAS_COND_AXIS_OFFSET-21 "-"
*MEAS_COND_AXIS_OFFSET-22 "-"
*MEAS_COND_AXIS_OFFSET-23 "-"
*MEAS_COND_AXIS_OFFSET-24 "-"
*MEAS_COND_AXIS_OFFSET-25 "-"
*MEAS_COND_AXIS_OFFSET-26 "-"
*MEAS_COND_AXIS_OFFSET-27 "-"
*MEAS_COND_AXIS_OFFSET-28 "-"
*MEAS_COND_AXIS_OFFSET-29 "-"
*MEAS_COND_AXIS_OFFSET-30 "-"
*MEAS_COND_AXIS_POSITION-0 "0.0000000000"
*MEAS_COND_AXIS_POSITION-1 "0.0000000000"
*MEAS_COND_AXIS_POSITION-2 "0.0000000000"
*MEAS_COND_AXIS_POSITION-3 "-2.9935200000"
*MEAS_COND_AXIS_POSITION-4 "0.0000000000"
*MEAS_COND_AXIS_POSITION-5 "0.0000000000"
*MEAS_COND_AXIS_POSITION-6 "0.0000000000"
*MEAS_COND_AXIS_POSITION-7 "-0.4278800000"
*MEAS_COND_AXIS_POSITION-8 "BB"
*MEAS_COND_AXIS_POSITION-9 "0.0000000000"
*MEAS_COND_AXIS_POSITION-10 "Soller_slit_5.0deg"
*MEAS_COND_AXIS_POSITION-11 "2/3deg"
*MEAS_COND_AXIS_POSITION-12 "2.2088000000"
*MEAS_COND_AXIS_POSITION-13 "-1.0609400000"
*MEAS_COND_AXIS_POSITION-14 "0.0000000000"
*MEAS_COND_AXIS_POSITION-15 "10.0mm"
*MEAS_COND_AXIS_POSITION-16 "None"
*MEAS_COND_AXIS_POSITION-17 "Cu_K-beta"
*MEAS_COND_AXIS_POSITION-18 "13.000mm"
*MEAS_COND_AXIS_POSITION-19 "13.000mm"
*MEAS_COND_AXIS_POSITION-20 "No_unit"
*MEAS_COND_AXIS_POSITION-21 "Soller_slit_5.0deg"
*MEAS_COND_AXIS_POSITION-22 "None"
*MEAS_COND_AXIS_POSITION-23 "13.0000000000"
*MEAS_COND_AXIS_POSITION-24 "13.0000000000"
*MEAS_COND_AXIS_POSITION-25 "0.0081300000"
*MEAS_COND_AXIS_POSITION-26 "Open"
*MEAS_COND_AXIS_POSITION-27 "None"
*MEAS_COND_AXIS_POSITION-28 "None"
*MEAS_COND_AXIS_POSITION-29 "None"
*MEAS_COND_AXIS_POSITION-30 "38.0000000000"
*MEAS_COND_AXIS_UNIT-0 "deg"
*MEAS_COND_AXIS_UNIT-1 "deg"
*MEAS_COND_AXIS_UNIT-2 "deg"
*MEAS_COND_AXIS_UNIT-3 "mm"
*MEAS_COND_AXIS_UNIT-4 "deg"
*MEAS_COND_AXIS_UNIT-5 "deg"
*MEAS_COND_AXIS_UNIT-6 "deg"
*MEAS_COND_AXIS_UNIT-7 "mm"
*MEAS_COND_AXIS_UNIT-8 ""
*MEAS_COND_AXIS_UNIT-9 "pulse"
*MEAS_COND_AXIS_UNIT-10 ""
*MEAS_COND_AXIS_UNIT-11 ""
*MEAS_COND_AXIS_UNIT-12 "mm"
*MEAS_COND_AXIS_UNIT-13 "mm"
*MEAS_COND_AXIS_UNIT-14 ""
*MEAS_COND_AXIS_UNIT-15 ""
*MEAS_COND_AXIS_UNIT-16 ""
*MEAS_COND_AXIS_UNIT-17 ""
*MEAS_COND_AXIS_UNIT-18 ""
*MEAS_COND_AXIS_UNIT-19 ""
*MEAS_COND_AXIS_UNIT-20 ""
*MEAS_COND_AXIS_UNIT-21 ""
*MEAS_COND_AXIS_UNIT-22 ""
*MEAS_COND_AXIS_UNIT-23 "mm"
*MEAS_COND_AXIS_UNIT-24 "mm"
*MEAS_COND_AXIS_UNIT-25 "mm"
*MEAS_COND_AXIS_UNIT-26 ""
*MEAS_COND_AXIS_UNIT-27 ""
*MEAS_COND_AXIS_UNIT-28 ""
*MEAS_COND_AXIS_UNIT-29 ""
*MEAS_COND_AXIS_UNIT-30 "div"
*MEAS_COND_COUNTER_CNTLOSS_CORR "0.0000000000"
*MEAS_COND_COUNTER_PHABASE "38.0000000000"
*MEAS_COND_COUNTER_PHAWINDOW "16.0000000000"
*MEAS_COND_COUNTER_PHA_UNIT "div"
*MEAS_COND_COUNTER_TAUDIFF "30.0000000000"
*MEAS_COND_COUNTER_TAUINT "0.0000000000"
*MEAS_COND_IRRADIATION_MODE "OFF"
*MEAS_COND_IRRADIATION_WIDTH ""
*MEAS_COND_OPT_ATTR "集中法"
*MEAS_COND_OPT_NAME "@集中法"
*MEAS_COND_UNSYMMETRIC_MODE "OFF"
*MEAS_COND_XG_CURRENT "30.0000000000"
*MEAS_COND_XG_VOLTAGE "40.0000000000"
*MEAS_COND_XG_WAVE_TYPE "Ka"
*MEAS_DATA_COUNT "5001.0000000000"
*MEAS_SCAN_AXIS_X "2θ/θ"
*MEAS_SCAN_AXIS_X_INTERNAL "TwoThetaTheta"
*MEAS_SCAN_END_TIME "07/20/22 16:10:07"
*MEAS_SCAN_MODE "CONTINUOUS"
*MEAS_SCAN_MONITOR "0"
*MEAS_SCAN_RESOLUTION_X "0.0002"
*MEAS_SCAN_SPEED "2.5"
*MEAS_SCAN_SPEED_UNIT "deg/min"
*MEAS_SCAN_START "20.0000000000"
*MEAS_SCAN_START_TIME "07/20/22 15:48:43"
*MEAS_SCAN_STEP "0.0100000000"
*MEAS_SCAN_STOP "70.0000000000"
*MEAS_SCAN_UNIT_X "deg"
*MEAS_SCAN_UNIT_Y "counts"
*RAS_HEADER_END
*RAS_INT_START
20.0000 1055.0000 1.0000
20.0400 1087.0000 1.0000
20.0800 1056.0000 1.0000
20.1200 1051.0000 1.0000
20.1600 1033.0000 1.0000
20.2000 1081.0000 1.0000
20.2400 1034.0000 1.0000
20.2800 1068.0000 1.0000
20.3200 1078.0000 1.0000
20.3600 1042.0000 1.0000
20.4000 1038.0000 1.0000
20.4400 1056.0000 1.0000
20.4800 1048.0000 1.0000
20.5200 1024.0000 1.0000
20.5600 1076.0000 1.0000
20.6000 1036.0000 1.0000
20.6400 1072.0000 1.0000
20.6800 984.0000 1.0000
20.7200 1081.0000 1.0000
20.7600 979.0000 1.0000
20.8000 1034.0000 1.0000
20.8400 1035.0000 1.0000
20.8800 1060.0000 1.0000
20.9200 1022.0000 1.0000
20.9600 1048.0000 1.0000
21.0000 1022.0000 1.0000
21.0400 1047.0000 1.0000
21.0800 1092.0000 1.0000
21.1200 1030.0000 1.0000
21.1600 1047.0000 1.0000
21.2000 1057.0000 1.0000
21.2400 1048.0000 1.0000
21.2800 1069.0000 1.0000
21.3200 1033.0000 1.0000
21.3600 1084.0000 1.0000
21.4000 1075.0000 1.0000
21.4400 1022.0000 1.0000
21.4800 1042.0000 1.0000
21.5200 1038.0000 1.0000
21.5600 1043.0000 1.0000
21.6000 1004.0000 1.0000
21.6400 1051.0000 1.0000
21.6800 1032.0000 1.0000
21.7200 1049.0000 1.0000
21.7600 1045.0000 1.0000
21.8000 1090.0000 1.0000
21.8400 1022.0000 1.0000
21.8800 1067.0000 1.0000
21.9200 1020.0000 1.0000
21.9600 1036.0000 1.0000
22.0000 1006.0000 1.0000
22.0400 1048.0000 1.0000
22.0800 1054.0000 1.0000
22.1200 1049.0000 1.0000
22.1600 1060.0000 1.0000
22.2000 1042.0000 1.0000
22.2400 1061.0000 1.0000
22.2800 1036.0000 1.0000
22.3200 992.0000 1.0000
22.3600 1034.0000 1.0000
22.4000 1044.0000 1.0000
22.4400 1016.0000 1.0000
22.4800 1026.0000 1.0000
22.5200 1085.0000 1.0000
22.5600 1017.0000 1.0000
22.6000 1049.0000 1.0000
22.6400 1054.0000 1.0000
22.6800 1050.0000 1.0000
22.7200 1016.0000 1.0000
22.7600 1015.0000 1.0000
22.8000 980.0000 1.0000
22.8400 989.0000 1.0000
22.8800 1069.0000 1.0000
22.9200 1015.0000 1.0000
22.9600 1030.0000 1.0000
23.0000 999.0000 1.0000
23.0400 1015.0000 1.0000
23.0800 1074.0000 1.0000
23.1200 1031.0000 1.0000
23.1600 1020.0000 1.0000
23.2000 1039.0000 1.0000
23.2400 1088.0000 1.0000
23.2800 1041.0000 1.0000
23.3200 1059.0000 1.0000
23.3600 1038.0000 1.0000
23.4000 1011.0000 1.0000
23.4400 1050.0000 1.0000
23.4800 1024.0000 1.0000
23.5200 991.0000 1.0000
23.5600 1021.0000 1.0000
23.6000 1052.0000 1.0000
23.6400 983.0000 1.0000
23.6800 1033.0000 1.0000
23.7200 1038.0000 1.0000
23.7600 1001.0000 1.0000
23.8000 1086.0000 1.0000
23.8400 1097.0000 1.0000
23.8800 1070.0000 1.0000
23.9200 1035.0000 1.0000
23.9600 1049.0000 1.0000
24.0000 1078.0000 1.0000
24.0400 1191.0000 1.0000
24.0800 1185.0000 1.0000
24.1200 1249.0000 1.0000
24.1600 1155.0000 1.0000
24.2000 1122.0000 1.0000
24.2400 1056.0000 1.0000
24.2800 1039.0000 1.0000
24.3200 1005.0000 1.0000
24.3600 1022.0000 1.0000
24.4000 1043.0000 1.0000
24.4400 1061.0000 1.0000
24.4800 1059.0000 1.0000
24.5200 1042.0000 1.0000
24.5600 1026.0000 1.0000
24.6000 1026.0000 1.0000
24.6400 1002.0000 1.0000
24.6800 1025.0000 1.0000
24.7200 1057.0000 1.0000
24.7600 993.0000 1.0000
24.8000 973.0000 1.0000
24.8400 1007.0000 1.0000
24.8800 1005.0000 1.0000
24.9200 1041.0000 1.0000
24.9600 1025.0000 1.0000
25.0000 1058.0000 1.0000
25.0400 1020.0000 1.0000
25.0800 1037.0000 1.0000
25.1200 1022.0000 1.0000
25.1600 1023.0000 1.0000
25.2000 962.0000 1.0000
25.2400 1005.0000 1.0000
25.2800 1019.0000 1.0000
25.3200 1018.0000 1.0000
25.3600 1012.0000 1.0000
25.4000 1031.0000 1.0000
25.4400 1021.0000 1.0000
25.4800 994.0000 1.0000
25.5200 1029.0000 1.0000
25.5600 1011.0000 1.0000
25.6000 1032.0000 1.0000
25.6400 987.0000 1.0000
25.6800 1017.0000 1.0000
25.7200 1103.0000 1.0000
25.7600 1075.0000 1.0000
25.8000 1048.0000 1.0000
25.8400 1083.0000 1.0000
25.8800 1090.0000 1.0000
25.9200 1063.0000 1.0000
25.9600 1096.0000 1.0000
26.0000 1154.0000 1.0000
26.0400 1177.0000 1.0000
26.0800 1216.0000 1.0000
26.1200 1362.0000 1.0000
26.1600 1375.0000 1.0000
26.2000 1500.0000 1.0000
26.2400 1746.0000 1.0000
26.2800 1935.0000 1.0000
26.3200 2344.0000 1.0000
26.3600 2896.0000 1.0000
26.4000 3563.0000 1.0000
26.4400 3992.0000 1.0000
26.4800 3762.0000 1.0000
26.5200 3204.0000 1.0000
26.5600 2507.0000 1.0000
26.6000 2094.0000 1.0000
26.6400 1683.0000 1.0000
26.6800 1532.0000 1.0000
26.7200 1364.0000 1.0000
26.7600 1240.0000 1.0000
26.8000 1201.0000 1.0000
26.8400 1212.0000 1.0000
26.8800 1105.0000 1.0000
26.9200 1149.0000 1.0000
26.9600 1043.0000 1.0000
27.0000 1023.0000 1.0000
27.0400 1050.0000 1.0000
27.0800 1044.0000 1.0000
27.1200 1028.0000 1.0000
27.1600 1021.0000 1.0000
27.2000 1008.0000 1.0000
27.2400 1027.0000 1.0000
27.2800 999.0000 1.0000
27.3200 985.0000 1.0000
27.3600 977.0000 1.0000
27.4000 995.0000 1.0000
27.4400 979.0000 1.0000
27.4800 990.0000 1.0000
27.5200 993.0000 1.0000
27.5600 965.0000 1.0000
27.6000 939.0000 1.0000
27.6400 953.0000 1.0000
27.6800 965.0000 1.0000
27.7200 930.0000 1.0000
27.7600 999.0000 1.0000
27.8000 910.0000 1.0000
27.8400 912.0000 1.0000
27.8800 984.0000 1.0000
27.9200 896.0000 1.0000
27.9600 889.0000 1.0000
28.0000 916.0000 1.0000
28.0400 941.0000 1.0000
28.0800 939.0000 1.0000
28.1200 934.0000 1.0000
28.1600 934.0000 1.0000
28.2000 937.0000 1.0000
28.2400 914.0000 1.0000
28.2800 909.0000 1.0000
28.3200 930.0000 1.0000
28.3600 945.0000 1.0000
28.4000 922.0000 1.0000
28.4400 905.0000 1.0000
28.4800 882.0000 1.0000
28.5200 907.0000 1.0000
28.5600 891.0000 1.0000
28.6000 958.0000 1.0000
28.6400 941.0000 1.0000
28.6800 873.0000 1.0000
28.7200 863.0000 1.0000
28.7600 892.0000 1.0000
28.8000 878.0000 1.0000
28.8400 896.0000 1.0000
28.8800 915.0000 1.0000
28.9200 907.0000 1.0000
28.9600 894.0000 1.0000
29.0000 907.0000 1.0000
29.0400 889.0000 1.0000
29.0800 912.0000 1.0000
29.1200 900.0000 1.0000
29.1600 950.0000 1.0000
29.2000 922.0000 1.0000
29.2400 932.0000 1.0000
29.2800 866.0000 1.0000
29.3200 848.0000 1.0000
29.3600 887.0000 1.0000
29.4000 909.0000 1.0000
29.4400 910.0000 1.0000
29.4800 911.0000 1.0000
29.5200 848.0000 1.0000
29.5600 858.0000 1.0000
29.6000 886.0000 1.0000
29.6400 889.0000 1.0000
29.6800 867.0000 1.0000
29.7200 828.0000 1.0000
29.7600 852.0000 1.0000
29.8000 894.0000 1.0000
29.8400 859.0000 1.0000
29.8800 810.0000 1.0000
29.9200 886.0000 1.0000
29.9600 850.0000 1.0000
30.0000 838.0000 1.0000
30.0400 827.0000 1.0000
30.0800 845.0000 1.0000
30.1200 850.0000 1.0000
30.1600 872.0000 1.0000
30.2000 884.0000 1.0000
30.2400 820.0000 1.0000
30.2800 851.0000 1.0000
30.3200 864.0000 1.0000
30.3600 861.0000 1.0000
30.4000 865.0000 1.0000
30.4400 838.0000 1.0000
30.4800 808.0000 1.0000
30.5200 865.0000 1.0000
30.5600 840.0000 1.0000
30.6000 835.0000 1.0000
30.6400 817.0000 1.0000
30.6800 814.0000 1.0000
30.7200 827.0000 1.0000
30.7600 829.0000 1.0000
30.8000 768.0000 1.0000
30.8400 845.0000 1.0000
30.8800 814.0000 1.0000
30.9200 844.0000 1.0000
30.9600 773.0000 1.0000
31.0000 873.0000 1.0000
31.0400 834.0000 1.0000
31.0800 834.0000 1.0000
31.1200 859.0000 1.0000
31.1600 822.0000 1.0000
31.2000 830.0000 1.0000
31.2400 824.0000 1.0000
31.2800 784.0000 1.0000
31.3200 815.0000 1.0000
31.3600 820.0000 1.0000
31.4000 871.0000 1.0000
31.4400 825.0000 1.0000
31.4800 775.0000 1.0000
31.5200 814.0000 1.0000
31.5600 757.0000 1.0000
31.6000 765.0000 1.0000
31.6400 807.0000 1.0000
31.6800 784.0000 1.0000
31.7200 746.0000 1.0000
31.7600 772.0000 1.0000
31.8000 788.0000 1.0000
31.8400 782.0000 1.0000
31.8800 819.0000 1.0000
31.9200 775.0000 1.0000
31.9600 792.0000 1.0000
32.0000 817.0000 1.0000
32.0400 783.0000 1.0000
32.0800 806.0000 1.0000
32.1200 798.0000 1.0000
32.1600 786.0000 1.0000
32.2000 784.0000 1.0000
32.2400 846.0000 1.0000
32.2800 808.0000 1.0000
32.3200 799.0000 1.0000
32.3600 780.0000 1.0000
32.4000 778.0000 1.0000
32.4400 814.0000 1.0000
32.4800 788.0000 1.0000
32.5200 781.0000 1.0000
32.5600 775.0000 1.0000
32.6000 799.0000 1.0000
32.6400 797.0000 1.0000
32.6800 832.0000 1.0000
32.7200 792.0000 1.0000
32.7600 796.0000 1.0000
32.8000 783.0000 1.0000
32.8400 830.0000 1.0000
32.8800 850.0000 1.0000
32.9200 871.0000 1.0000
32.9600 941.0000 1.0000
33.0000 963.0000 1.0000
33.0400 1120.0000 1.0000
33.0800 1231.0000 1.0000
33.1200 1232.0000 1.0000
33.1600 1170.0000 1.0000
33.2000 1082.0000 1.0000
33.2400 1003.0000 1.0000
33.2800 946.0000 1.0000
33.3200 905.0000 1.0000
33.3600 944.0000 1.0000
33.4000 1017.0000 1.0000
33.4400 1069.0000 1.0000
33.4800 1159.0000 1.0000
33.5200 1326.0000 1.0000
33.5600 1500.0000 1.0000
33.6000 1829.0000 1.0000
33.6400 1978.0000 1.0000
33.6800 2015.0000 1.0000
33.7200 1762.0000 1.0000
33.7600 1558.0000 1.0000
33.8000 1340.0000 1.0000
33.8400 1061.0000 1.0000
33.8800 1032.0000 1.0000
33.9200 941.0000 1.0000
33.9600 929.0000 1.0000
34.0000 910.0000 1.0000
34.0400 867.0000 1.0000
34.0800 857.0000 1.0000
34.1200 868.0000 1.0000
34.1600 762.0000 1.0000
34.2000 740.0000 1.0000
34.2400 806.0000 1.0000
34.2800 782.0000 1.0000
34.3200 725.0000 1.0000
34.3600 702.0000 1.0000
34.4000 752.0000 1.0000
34.4400 733.0000 1.0000
34.4800 749.0000 1.0000
34.5200 750.0000 1.0000
34.5600 733.0000 1.0000
34.6000 711.0000 1.0000
34.6400 741.0000 1.0000
34.6800 692.0000 1.0000
34.7200 743.0000 1.0000
34.7600 712.0000 1.0000
34.8000 675.0000 1.0000
34.8400 728.0000 1.0000
34.8800 680.0000 1.0000
34.9200 677.0000 1.0000
34.9600 678.0000 1.0000
35.0000 687.0000 1.0000
35.0400 746.0000 1.0000
35.0800 684.0000 1.0000
35.1200 662.0000 1.0000
35.1600 679.0000 1.0000
35.2000 687.0000 1.0000
35.2400 684.0000 1.0000
35.2800 704.0000 1.0000
35.3200 694.0000 1.0000
35.3600 757.0000 1.0000
35.4000 766.0000 1.0000
35.4400 839.0000 1.0000
35.4800 903.0000 1.0000
35.5200 1074.0000 1.0000
35.5600 1236.0000 1.0000
35.6000 1201.0000 1.0000
35.6400 1055.0000 1.0000
35.6800 1019.0000 1.0000
35.7200 851.0000 1.0000
35.7600 769.0000 1.0000
35.8000 715.0000 1.0000
35.8400 668.0000 1.0000
35.8800 645.0000 1.0000
35.9200 655.0000 1.0000
35.9600 626.0000 1.0000
36.0000 645.0000 1.0000
36.0400 604.0000 1.0000
36.0800 641.0000 1.0000
36.1200 660.0000 1.0000
36.1600 625.0000 1.0000
36.2000 638.0000 1.0000
36.2400 636.0000 1.0000
36.2800 630.0000 1.0000
36.3200 619.0000 1.0000
36.3600 618.0000 1.0000
36.4000 637.0000 1.0000
36.4400 640.0000 1.0000
36.4800 664.0000 1.0000
36.5200 628.0000 1.0000
36.5600 621.0000 1.0000
36.6000 653.0000 1.0000
36.6400 616.0000 1.0000
36.6800 615.0000 1.0000
36.7200 624.0000 1.0000
36.7600 664.0000 1.0000
36.8000 670.0000 1.0000
36.8400 612.0000 1.0000
36.8800 628.0000 1.0000
36.9200 654.0000 1.0000
36.9600 632.0000 1.0000
37.0000 627.0000 1.0000
37.0400 655.0000 1.0000
37.0800 660.0000 1.0000
37.1200 661.0000 1.0000
37.1600 656.0000 1.0000
37.2000 657.0000 1.0000
37.2400 693.0000 1.0000
37.2800 731.0000 1.0000
37.3200 746.0000 1.0000
37.3600 817.0000 1.0000
37.4000 852.0000 1.0000
37.4400 993.0000 1.0000
37.4800 1131.0000 1.0000
37.5200 1359.0000 1.0000
37.5600 1672.0000 1.0000
37.6000 2150.0000 1.0000
37.6400 2816.0000 1.0000
37.6800 3257.0000 1.0000
37.7200 3227.0000 1.0000
37.7600 3076.0000 1.0000
37.8000 2587.0000 1.0000
37.8400 2138.0000 1.0000
37.8800 1605.0000 1.0000
37.9200 1334.0000 1.0000
37.9600 1082.0000 1.0000
38.0000 894.0000 1.0000
38.0400 862.0000 1.0000
38.0800 742.0000 1.0000
38.1200 700.0000 1.0000
38.1600 641.0000 1.0000
38.2000 637.0000 1.0000
38.2400 611.0000 1.0000
38.2800 642.0000 1.0000
38.3200 608.0000 1.0000
38.3600 566.0000 1.0000
38.4000 611.0000 1.0000
38.4400 586.0000 1.0000
38.4800 642.0000 1.0000
38.5200 569.0000 1.0000
38.5600 591.0000 1.0000
38.6000 595.0000 1.0000
38.6400 604.0000 1.0000
38.6800 591.0000 1.0000
38.7200 644.0000 1.0000
38.7600 637.0000 1.0000
38.8000 602.0000 1.0000
38.8400 612.0000 1.0000
38.8800 589.0000 1.0000
38.9200 579.0000 1.0000
38.9600 561.0000 1.0000
39.0000 564.0000 1.0000
39.0400 580.0000 1.0000
39.0800 566.0000 1.0000
39.1200 568.0000 1.0000
39.1600 543.0000 1.0000
39.2000 601.0000 1.0000
39.2400 597.0000 1.0000
39.2800 571.0000 1.0000
39.3200 558.0000 1.0000
39.3600 552.0000 1.0000
39.4000 543.0000 1.0000
39.4400 568.0000 1.0000
39.4800 586.0000 1.0000
39.5200 587.0000 1.0000
39.5600 553.0000 1.0000
39.6000 558.0000 1.0000
39.6400 525.0000 1.0000
39.6800 530.0000 1.0000
39.7200 555.0000 1.0000
39.7600 568.0000 1.0000
39.8000 539.0000 1.0000
39.8400 532.0000 1.0000
39.8800 548.0000 1.0000
39.9200 557.0000 1.0000
39.9600 545.0000 1.0000
40.0000 553.0000 1.0000
40.0400 526.0000 1.0000
40.0800 540.0000 1.0000
40.1200 552.0000 1.0000
40.1600 539.0000 1.0000
40.2000 544.0000 1.0000
40.2400 558.0000 1.0000
40.2800 515.0000 1.0000
40.3200 536.0000 1.0000
40.3600 557.0000 1.0000
40.4000 546.0000 1.0000
40.4400 547.0000 1.0000
40.4800 529.0000 1.0000
40.5200 518.0000 1.0000
40.5600 555.0000 1.0000
40.6000 549.0000 1.0000
40.6400 523.0000 1.0000
40.6800 564.0000 1.0000
40.7200 598.0000 1.0000
40.7600 649.0000 1.0000
40.8000 625.0000 1.0000
40.8400 630.0000 1.0000
40.8800 613.0000 1.0000
40.9200 622.0000 1.0000
40.9600 578.0000 1.0000
41.0000 580.0000 1.0000
41.0400 519.0000 1.0000
41.0800 536.0000 1.0000
41.1200 533.0000 1.0000
41.1600 505.0000 1.0000
41.2000 549.0000 1.0000
41.2400 516.0000 1.0000
41.2800 501.0000 1.0000
41.3200 524.0000 1.0000
41.3600 501.0000 1.0000
41.4000 532.0000 1.0000
41.4400 523.0000 1.0000
41.4800 513.0000 1.0000
41.5200 545.0000 1.0000
41.5600 530.0000 1.0000
41.6000 519.0000 1.0000
41.6400 529.0000 1.0000
41.6800 518.0000 1.0000
41.7200 526.0000 1.0000
41.7600 527.0000 1.0000
41.8000 522.0000 1.0000
41.8400 526.0000 1.0000
41.8800 499.0000 1.0000
41.9200 502.0000 1.0000
41.9600 510.0000 1.0000
42.0000 491.0000 1.0000
42.0400 526.0000 1.0000
42.0800 558.0000 1.0000
42.1200 524.0000 1.0000
42.1600 548.0000 1.0000
42.2000 511.0000 1.0000
42.2400 533.0000 1.0000
42.2800 527.0000 1.0000
42.3200 564.0000 1.0000
42.3600 584.0000 1.0000
42.4000 626.0000 1.0000
42.4400 561.0000 1.0000
42.4800 547.0000 1.0000
42.5200 525.0000 1.0000
42.5600 559.0000 1.0000
42.6000 538.0000 1.0000
42.6400 535.0000 1.0000
42.6800 549.0000 1.0000
42.7200 532.0000 1.0000
42.7600 482.0000 1.0000
42.8000 478.0000 1.0000
42.8400 502.0000 1.0000
42.8800 478.0000 1.0000
42.9200 554.0000 1.0000
42.9600 498.0000 1.0000
43.0000 511.0000 1.0000
43.0400 542.0000 1.0000
43.0800 502.0000 1.0000
43.1200 533.0000 1.0000
43.1600 507.0000 1.0000
43.2000 493.0000 1.0000
43.2400 506.0000 1.0000
43.2800 488.0000 1.0000
43.3200 514.0000 1.0000
43.3600 521.0000 1.0000
43.4000 531.0000 1.0000
43.4400 498.0000 1.0000
43.4800 501.0000 1.0000
43.5200 509.0000 1.0000
43.5600 540.0000 1.0000
43.6000 499.0000 1.0000
43.6400 518.0000 1.0000
43.6800 519.0000 1.0000
43.7200 477.0000 1.0000
43.7600 537.0000 1.0000
43.8000 535.0000 1.0000
43.8400 459.0000 1.0000
43.8800 449.0000 1.0000
43.9200 489.0000 1.0000
43.9600 497.0000 1.0000
44.0000 482.0000 1.0000
44.0400 451.0000 1.0000
44.0800 465.0000 1.0000
44.1200 495.0000 1.0000
44.1600 465.0000 1.0000
44.2000 504.0000 1.0000
44.2400 489.0000 1.0000
44.2800 473.0000 1.0000
44.3200 476.0000 1.0000
44.3600 504.0000 1.0000
44.4000 502.0000 1.0000
44.4400 444.0000 1.0000
44.4800 472.0000 1.0000
44.5200 460.0000 1.0000
44.5600 473.0000 1.0000
44.6000 485.0000 1.0000
44.6400 498.0000 1.0000
44.6800 467.0000 1.0000
44.7200 465.0000 1.0000
44.7600 473.0000 1.0000
44.8000 453.0000 1.0000
44.8400 497.0000 1.0000
44.8800 463.0000 1.0000
44.9200 476.0000 1.0000
44.9600 464.0000 1.0000
45.0000 477.0000 1.0000
45.0400 514.0000 1.0000
45.0800 492.0000 1.0000
45.1200 443.0000 1.0000
45.1600 458.0000 1.0000
45.2000 446.0000 1.0000
45.2400 457.0000 1.0000
45.2800 452.0000 1.0000
45.3200 506.0000 1.0000
45.3600 469.0000 1.0000
45.4000 476.0000 1.0000
45.4400 458.0000 1.0000
45.4800 496.0000 1.0000
45.5200 484.0000 1.0000
45.5600 462.0000 1.0000
45.6000 463.0000 1.0000
45.6400 456.0000 1.0000
45.6800 445.0000 1.0000
45.7200 469.0000 1.0000
45.7600 483.0000 1.0000
45.8000 487.0000 1.0000
45.8400 495.0000 1.0000
45.8800 460.0000 1.0000
45.9200 445.0000 1.0000
45.9600 471.0000 1.0000
46.0000 474.0000 1.0000
46.0400 469.0000 1.0000
46.0800 493.0000 1.0000
46.1200 443.0000 1.0000
46.1600 493.0000 1.0000
46.2000 473.0000 1.0000
46.2400 479.0000 1.0000
46.2800 497.0000 1.0000
46.3200 455.0000 1.0000
46.3600 501.0000 1.0000
46.4000 469.0000 1.0000
46.4400 467.0000 1.0000
46.4800 466.0000 1.0000
46.5200 479.0000 1.0000
46.5600 481.0000 1.0000
46.6000 467.0000 1.0000
46.6400 450.0000 1.0000
46.6800 473.0000 1.0000
46.7200 424.0000 1.0000
46.7600 478.0000 1.0000
46.8000 461.0000 1.0000
46.8400 450.0000 1.0000
46.8800 437.0000 1.0000
46.9200 464.0000 1.0000
46.9600 481.0000 1.0000
47.0000 479.0000 1.0000
47.0400 463.0000 1.0000
47.0800 422.0000 1.0000
47.1200 435.0000 1.0000
47.1600 468.0000 1.0000
47.2000 459.0000 1.0000
47.2400 437.0000 1.0000
47.2800 469.0000 1.0000
47.3200 438.0000 1.0000
47.3600 439.0000 1.0000
47.4000 424.0000 1.0000
47.4400 446.0000 1.0000
47.4800 426.0000 1.0000
47.5200 430.0000 1.0000
47.5600 446.0000 1.0000
47.6000 451.0000 1.0000
47.6400 429.0000 1.0000
47.6800 492.0000 1.0000
47.7200 417.0000 1.0000
47.7600 419.0000 1.0000
47.8000 442.0000 1.0000
47.8400 465.0000 1.0000
47.8800 467.0000 1.0000
47.9200 443.0000 1.0000
47.9600 421.0000 1.0000
48.0000 439.0000 1.0000
48.0400 434.0000 1.0000
48.0800 447.0000 1.0000
48.1200 442.0000 1.0000
48.1600 453.0000 1.0000
48.2000 456.0000 1.0000
48.2400 444.0000 1.0000
48.2800 415.0000 1.0000
48.3200 481.0000 1.0000
48.3600 444.0000 1.0000
48.4000 460.0000 1.0000
48.4400 439.0000 1.0000
48.4800 441.0000 1.0000
48.5200 441.0000 1.0000
48.5600 442.0000 1.0000
48.6000 433.0000 1.0000
48.6400 434.0000 1.0000
48.6800 408.0000 1.0000
48.7200 447.0000 1.0000
48.7600 442.0000 1.0000
48.8000 408.0000 1.0000
48.8400 459.0000 1.0000
48.8800 426.0000 1.0000
48.9200 434.0000 1.0000
48.9600 450.0000 1.0000
49.0000 445.0000 1.0000
49.0400 433.0000 1.0000
49.0800 450.0000 1.0000
49.1200 451.0000 1.0000
49.1600 435.0000 1.0000
49.2000 466.0000 1.0000
49.2400 457.0000 1.0000
49.2800 480.0000 1.0000
49.3200 482.0000 1.0000
49.3600 551.0000 1.0000
49.4000 560.0000 1.0000
49.4400 546.0000 1.0000
49.4800 537.0000 1.0000
49.5200 468.0000 1.0000
49.5600 489.0000 1.0000
49.6000 496.0000 1.0000
49.6400 455.0000 1.0000
49.6800 451.0000 1.0000
49.7200 491.0000 1.0000
49.7600 479.0000 1.0000
49.8000 463.0000 1.0000
49.8400 466.0000 1.0000
49.8800 425.0000 1.0000
49.9200 450.0000 1.0000
49.9600 451.0000 1.0000
50.0000 402.0000 1.0000
50.0400 453.0000 1.0000
50.0800 444.0000 1.0000
50.1200 432.0000 1.0000
50.1600 413.0000 1.0000
50.2000 453.0000 1.0000
50.2400 433.0000 1.0000
50.2800 437.0000 1.0000
50.3200 437.0000 1.0000
50.3600 448.0000 1.0000
50.4000 478.0000 1.0000
50.4400 446.0000 1.0000
50.4800 472.0000 1.0000
50.5200 415.0000 1.0000
50.5600 442.0000 1.0000
50.6000 452.0000 1.0000
50.6400 485.0000 1.0000
50.6800 457.0000 1.0000
50.7200 490.0000 1.0000
50.7600 463.0000 1.0000
50.8000 457.0000 1.0000
50.8400 474.0000 1.0000
50.8800 450.0000 1.0000
50.9200 485.0000 1.0000
50.9600 476.0000 1.0000
51.0000 464.0000 1.0000
51.0400 504.0000 1.0000
51.0800 532.0000 1.0000
51.1200 522.0000 1.0000
51.1600 615.0000 1.0000
51.2000 703.0000 1.0000
51.2400 784.0000 1.0000
51.2800 924.0000 1.0000
51.3200 1111.0000 1.0000
51.3600 1557.0000 1.0000
51.4000 1947.0000 1.0000
51.4400 2626.0000 1.0000
51.4800 2946.0000 1.0000
51.5200 2879.0000 1.0000
51.5600 2509.0000 1.0000
51.6000 2283.0000 1.0000
51.6400 1912.0000 1.0000
51.6800 1561.0000 1.0000
51.7200 1191.0000 1.0000
51.7600 893.0000 1.0000
51.8000 781.0000 1.0000
51.8400 664.0000 1.0000
51.8800 655.0000 1.0000
51.9200 571.0000 1.0000
51.9600 543.0000 1.0000
52.0000 513.0000 1.0000
52.0400 477.0000 1.0000
52.0800 492.0000 1.0000
52.1200 470.0000 1.0000
52.1600 443.0000 1.0000
52.2000 456.0000 1.0000
52.2400 446.0000 1.0000
52.2800 445.0000 1.0000
52.3200 454.0000 1.0000
52.3600 425.0000 1.0000
52.4000 428.0000 1.0000
52.4400 485.0000 1.0000
52.4800 440.0000 1.0000
52.5200 451.0000 1.0000
52.5600 463.0000 1.0000
52.6000 432.0000 1.0000
52.6400 436.0000 1.0000
52.6800 424.0000 1.0000
52.7200 424.0000 1.0000
52.7600 420.0000 1.0000
52.8000 437.0000 1.0000
52.8400 445.0000 1.0000
52.8800 399.0000 1.0000
52.9200 449.0000 1.0000
52.9600 440.0000 1.0000
53.0000 431.0000 1.0000
53.0400 424.0000 1.0000
53.0800 429.0000 1.0000
53.1200 432.0000 1.0000
53.1600 440.0000 1.0000
53.2000 416.0000 1.0000
53.2400 438.0000 1.0000
53.2800 424.0000 1.0000
53.3200 458.0000 1.0000
53.3600 428.0000 1.0000
53.4000 414.0000 1.0000
53.4400 441.0000 1.0000
53.4800 422.0000 1.0000
53.5200 432.0000 1.0000
53.5600 430.0000 1.0000
53.6000 421.0000 1.0000
53.6400 431.0000 1.0000
53.6800 445.0000 1.0000
53.7200 441.0000 1.0000
53.7600 475.0000 1.0000
53.8000 427.0000 1.0000
53.8400 436.0000 1.0000
53.8800 454.0000 1.0000
53.9200 508.0000 1.0000
53.9600 499.0000 1.0000
54.0000 539.0000 1.0000
54.0400 559.0000 1.0000
54.0800 513.0000 1.0000
54.1200 506.0000 1.0000
54.1600 530.0000 1.0000
54.2000 499.0000 1.0000
54.2400 489.0000 1.0000
54.2800 475.0000 1.0000
54.3200 501.0000 1.0000
54.3600 540.0000 1.0000
54.4000 551.0000 1.0000
54.4400 658.0000 1.0000
54.4800 629.0000 1.0000
54.5200 627.0000 1.0000
54.5600 633.0000 1.0000
54.6000 632.0000 1.0000
54.6400 583.0000 1.0000
54.6800 582.0000 1.0000
54.7200 569.0000 1.0000
54.7600 510.0000 1.0000
54.8000 486.0000 1.0000
54.8400 495.0000 1.0000
54.8800 482.0000 1.0000
54.9200 426.0000 1.0000
54.9600 456.0000 1.0000
55.0000 423.0000 1.0000
55.0400 435.0000 1.0000
55.0800 441.0000 1.0000
55.1200 426.0000 1.0000
55.1600 389.0000 1.0000
55.2000 434.0000 1.0000
55.2400 440.0000 1.0000
55.2800 409.0000 1.0000
55.3200 451.0000 1.0000
55.3600 426.0000 1.0000
55.4000 417.0000 1.0000
55.4400 398.0000 1.0000
55.4800 399.0000 1.0000
55.5200 414.0000 1.0000
55.5600 412.0000 1.0000
55.6000 407.0000 1.0000
55.6400 407.0000 1.0000
55.6800 432.0000 1.0000
55.7200 438.0000 1.0000
55.7600 440.0000 1.0000
55.8000 409.0000 1.0000
55.8400 399.0000 1.0000
55.8800 434.0000 1.0000
55.9200 423.0000 1.0000
55.9600 402.0000 1.0000
56.0000 416.0000 1.0000
56.0400 391.0000 1.0000
56.0800 405.0000 1.0000
56.1200 422.0000 1.0000
56.1600 398.0000 1.0000
56.2000 443.0000 1.0000
56.2400 421.0000 1.0000
56.2800 422.0000 1.0000
56.3200 415.0000 1.0000
56.3600 423.0000 1.0000
56.4000 422.0000 1.0000
56.4400 394.0000 1.0000
56.4800 365.0000 1.0000
56.5200 405.0000 1.0000
56.5600 431.0000 1.0000
56.6000 415.0000 1.0000
56.6400 441.0000 1.0000
56.6800 393.0000 1.0000
56.7200 417.0000 1.0000
56.7600 428.0000 1.0000
56.8000 397.0000 1.0000
56.8400 390.0000 1.0000
56.8800 385.0000 1.0000
56.9200 399.0000 1.0000
56.9600 393.0000 1.0000
57.0000 416.0000 1.0000
57.0400 408.0000 1.0000
57.0800 434.0000 1.0000
57.1200 427.0000 1.0000
57.1600 427.0000 1.0000
57.2000 405.0000 1.0000
57.2400 421.0000 1.0000
57.2800 450.0000 1.0000
57.3200 434.0000 1.0000
57.3600 407.0000 1.0000
57.4000 440.0000 1.0000
57.4400 404.0000 1.0000
57.4800 462.0000 1.0000
57.5200 406.0000 1.0000
57.5600 434.0000 1.0000
57.6000 427.0000 1.0000
57.6400 445.0000 1.0000
57.6800 410.0000 1.0000
57.7200 427.0000 1.0000
57.7600 425.0000 1.0000
57.8000 398.0000 1.0000
57.8400 434.0000 1.0000
57.8800 401.0000 1.0000
57.9200 457.0000 1.0000
57.9600 407.0000 1.0000
58.0000 413.0000 1.0000
58.0400 420.0000 1.0000
58.0800 429.0000 1.0000
58.1200 398.0000 1.0000
58.1600 432.0000 1.0000
58.2000 415.0000 1.0000
58.2400 424.0000 1.0000
58.2800 400.0000 1.0000
58.3200 389.0000 1.0000
58.3600 417.0000 1.0000
58.4000 389.0000 1.0000
58.4400 397.0000 1.0000
58.4800 427.0000 1.0000
58.5200 382.0000 1.0000
58.5600 439.0000 1.0000
58.6000 393.0000 1.0000
58.6400 360.0000 1.0000
58.6800 397.0000 1.0000
58.7200 411.0000 1.0000
58.7600 396.0000 1.0000
58.8000 407.0000 1.0000
58.8400 418.0000 1.0000
58.8800 376.0000 1.0000
58.9200 392.0000 1.0000
58.9600 374.0000 1.0000
59.0000 393.0000 1.0000
59.0400 385.0000 1.0000
59.0800 400.0000 1.0000
59.1200 388.0000 1.0000
59.1600 393.0000 1.0000
59.2000 439.0000 1.0000
59.2400 379.0000 1.0000
59.2800 420.0000 1.0000
59.3200 426.0000 1.0000
59.3600 378.0000 1.0000
59.4000 406.0000 1.0000
59.4400 377.0000 1.0000
59.4800 421.0000 1.0000
59.5200 417.0000 1.0000
59.5600 434.0000 1.0000
59.6000 395.0000 1.0000
59.6400 407.0000 1.0000
59.6800 388.0000 1.0000
59.7200 379.0000 1.0000
59.7600 393.0000 1.0000
59.8000 407.0000 1.0000
59.8400 386.0000 1.0000
59.8800 409.0000 1.0000
59.9200 379.0000 1.0000
59.9600 396.0000 1.0000
60.0000 462.0000 1.0000
60.0400 423.0000 1.0000
60.0800 405.0000 1.0000
60.1200 380.0000 1.0000
60.1600 395.0000 1.0000
60.2000 419.0000 1.0000
60.2400 411.0000 1.0000
60.2800 411.0000 1.0000
60.3200 422.0000 1.0000
60.3600 387.0000 1.0000
60.4000 405.0000 1.0000
60.4400 394.0000 1.0000
60.4800 414.0000 1.0000
60.5200 416.0000 1.0000
60.5600 391.0000 1.0000
60.6000 388.0000 1.0000
60.6400 375.0000 1.0000
60.6800 408.0000 1.0000
60.7200 388.0000 1.0000
60.7600 407.0000 1.0000
60.8000 391.0000 1.0000
60.8400 405.0000 1.0000
60.8800 426.0000 1.0000
60.9200 419.0000 1.0000
60.9600 395.0000 1.0000
61.0000 421.0000 1.0000
61.0400 414.0000 1.0000
61.0800 452.0000 1.0000
61.1200 436.0000 1.0000
61.1600 462.0000 1.0000
61.2000 511.0000 1.0000
61.2400 496.0000 1.0000
61.2800 533.0000 1.0000
61.3200 618.0000 1.0000
61.3600 604.0000 1.0000
61.4000 671.0000 1.0000
61.4400 766.0000 1.0000
61.4800 818.0000 1.0000
61.5200 855.0000 1.0000
61.5600 900.0000 1.0000
61.6000 832.0000 1.0000
61.6400 820.0000 1.0000
61.6800 766.0000 1.0000
61.7200 750.0000 1.0000
61.7600 698.0000 1.0000
61.8000 623.0000 1.0000
61.8400 564.0000 1.0000
61.8800 537.0000 1.0000
61.9200 490.0000 1.0000
61.9600 490.0000 1.0000
62.0000 462.0000 1.0000
62.0400 457.0000 1.0000
62.0800 464.0000 1.0000
62.1200 457.0000 1.0000
62.1600 452.0000 1.0000
62.2000 477.0000 1.0000
62.2400 471.0000 1.0000
62.2800 461.0000 1.0000
62.3200 466.0000 1.0000
62.3600 510.0000 1.0000
62.4000 491.0000 1.0000
62.4400 478.0000 1.0000
62.4800 457.0000 1.0000
62.5200 456.0000 1.0000
62.5600 456.0000 1.0000
62.6000 457.0000 1.0000
62.6400 414.0000 1.0000
62.6800 403.0000 1.0000
62.7200 402.0000 1.0000
62.7600 407.0000 1.0000
62.8000 412.0000 1.0000
62.8400 380.0000 1.0000
62.8800 426.0000 1.0000
62.9200 353.0000 1.0000
62.9600 430.0000 1.0000
63.0000 392.0000 1.0000
63.0400 396.0000 1.0000
63.0800 378.0000 1.0000
63.1200 383.0000 1.0000
63.1600 418.0000 1.0000
63.2000 427.0000 1.0000
63.2400 389.0000 1.0000
63.2800 396.0000 1.0000
63.3200 371.0000 1.0000
63.3600 371.0000 1.0000
63.4000 407.0000 1.0000
63.4400 395.0000 1.0000
63.4800 422.0000 1.0000
63.5200 385.0000 1.0000
63.5600 393.0000 1.0000
63.6000 425.0000 1.0000
63.6400 426.0000 1.0000
63.6800 398.0000 1.0000
63.7200 385.0000 1.0000
63.7600 398.0000 1.0000
63.8000 441.0000 1.0000
63.8400 484.0000 1.0000
63.8800 485.0000 1.0000
63.9200 539.0000 1.0000
63.9600 573.0000 1.0000
64.0000 501.0000 1.0000
64.0400 466.0000 1.0000
64.0800 502.0000 1.0000
64.1200 470.0000 1.0000
64.1600 468.0000 1.0000
64.2000 434.0000 1.0000
64.2400 412.0000 1.0000
64.2800 411.0000 1.0000
64.3200 409.0000 1.0000
64.3600 433.0000 1.0000
64.4000 428.0000 1.0000
64.4400 440.0000 1.0000
64.4800 448.0000 1.0000
64.5200 430.0000 1.0000
64.5600 417.0000 1.0000
64.6000 415.0000 1.0000
64.6400 426.0000 1.0000
64.6800 413.0000 1.0000
64.7200 424.0000 1.0000
64.7600 411.0000 1.0000
64.8000 407.0000 1.0000
64.8400 425.0000 1.0000
64.8800 425.0000 1.0000
64.9200 396.0000 1.0000
64.9600 458.0000 1.0000
65.0000 469.0000 1.0000
65.0400 451.0000 1.0000
65.0800 466.0000 1.0000
65.1200 477.0000 1.0000
65.1600 477.0000 1.0000
65.2000 516.0000 1.0000
65.2400 575.0000 1.0000
65.2800 643.0000 1.0000
65.3200 680.0000 1.0000
65.3600 779.0000 1.0000
65.4000 977.0000 1.0000
65.4400 1161.0000 1.0000
65.4800 1310.0000 1.0000
65.5200 1492.0000 1.0000
65.5600 1414.0000 1.0000
65.6000 1343.0000 1.0000
65.6400 1289.0000 1.0000
65.6800 1164.0000 1.0000
65.7200 1079.0000 1.0000
65.7600 968.0000 1.0000
65.8000 875.0000 1.0000
65.8400 725.0000 1.0000
65.8800 614.0000 1.0000
65.9200 559.0000 1.0000
65.9600 535.0000 1.0000
66.0000 531.0000 1.0000
66.0400 515.0000 1.0000
66.0800 449.0000 1.0000
66.1200 426.0000 1.0000
66.1600 436.0000 1.0000
66.2000 399.0000 1.0000
66.2400 412.0000 1.0000
66.2800 401.0000 1.0000
66.3200 418.0000 1.0000
66.3600 386.0000 1.0000
66.4000 387.0000 1.0000
66.4400 394.0000 1.0000
66.4800 386.0000 1.0000
66.5200 370.0000 1.0000
66.5600 392.0000 1.0000
66.6000 389.0000 1.0000
66.6400 398.0000 1.0000
66.6800 393.0000 1.0000
66.7200 361.0000 1.0000
66.7600 353.0000 1.0000
66.8000 362.0000 1.0000
66.8400 386.0000 1.0000
66.8800 388.0000 1.0000
66.9200 382.0000 1.0000
66.9600 366.0000 1.0000
67.0000 368.0000 1.0000
67.0400 375.0000 1.0000
67.0800 347.0000 1.0000
67.1200 380.0000 1.0000
67.1600 385.0000 1.0000
67.2000 332.0000 1.0000
67.2400 338.0000 1.0000
67.2800 366.0000 1.0000
67.3200 371.0000 1.0000
67.3600 382.0000 1.0000
67.4000 382.0000 1.0000
67.4400 393.0000 1.0000
67.4800 372.0000 1.0000
67.5200 363.0000 1.0000
67.5600 398.0000 1.0000
67.6000 328.0000 1.0000
67.6400 379.0000 1.0000
67.6800 373.0000 1.0000
67.7200 372.0000 1.0000
67.7600 389.0000 1.0000
67.8000 367.0000 1.0000
67.8400 361.0000 1.0000
67.8800 349.0000 1.0000
67.9200 330.0000 1.0000
67.9600 332.0000 1.0000
68.0000 366.0000 1.0000
68.0400 357.0000 1.0000
68.0800 334.0000 1.0000
68.1200 377.0000 1.0000
68.1600 372.0000 1.0000
68.2000 372.0000 1.0000
68.2400 352.0000 1.0000
68.2800 321.0000 1.0000
68.3200 349.0000 1.0000
68.3600 372.0000 1.0000
68.4000 361.0000 1.0000
68.4400 347.0000 1.0000
68.4800 324.0000 1.0000
68.5200 344.0000 1.0000
68.5600 342.0000 1.0000
68.6000 337.0000 1.0000
68.6400 340.0000 1.0000
68.6800 347.0000 1.0000
68.7200 345.0000 1.0000
68.7600 358.0000 1.0000
68.8000 401.0000 1.0000
68.8400 341.0000 1.0000
68.8800 355.0000 1.0000
68.9200 376.0000 1.0000
68.9600 398.0000 1.0000
69.0000 382.0000 1.0000
69.0400 348.0000 1.0000
69.0800 325.0000 1.0000
69.1200 383.0000 1.0000
69.1600 361.0000 1.0000
69.2000 337.0000 1.0000
69.2400 331.0000 1.0000
69.2800 356.0000 1.0000
69.3200 346.0000 1.0000
69.3600 339.0000 1.0000
69.4000 354.0000 1.0000
69.4400 361.0000 1.0000
69.4800 362.0000 1.0000
69.5200 357.0000 1.0000
69.5600 350.0000 1.0000
69.6000 370.0000 1.0000
69.6400 386.0000 1.0000
69.6800 362.0000 1.0000
69.7200 347.0000 1.0000
69.7600 357.0000 1.0000
69.8000 361.0000 1.0000
69.8400 369.0000 1.0000
69.8800 353.0000 1.0000
69.9200 321.0000 1.0000
69.9600 355.0000 1.0000
70.0000 360.0000 1.0000
*RAS_INT_END
*RAS_TEMPERATURE_START
*RAS_TEMPERATURE_END
*RAS_DATA_END