File: Data/Dataset1_Only_water/5_XRD/No_049_deposition_3h_Air_5.ras
*RAS_DATA_START
*RAS_HEADER_START
*DISP_FMT_X "%.2f"
*DISP_FMT_Y "%.0f"
*DISP_FULLSCALE "18050.0000000000"
*DISP_LINE_COLOR "255.0000000000"
*DISP_LINE_STYLE "0.0000000000"
*DISP_LINE_WIDTH "0.2500000000"
*DISP_NOTE "測定データ-6"
*DISP_OFFSET_Y "0.0000000000"
*DISP_PEAKSEARCH_UNIT_Y "cps"
*DISP_RANGE_BOTTOM "0.0000000000"
*DISP_RANGE_LEFT "20.0000000000"
*DISP_RANGE_LOGCUTOFF "0.0100000000"
*DISP_RANGE_RIGHT "70.0000000000"
*DISP_RANGE_TOP "18050.0000000000"
*DISP_SCALE_MODE_Y "0.0000000000"
*DISP_TAB_NAME "2θ/θ"
*DISP_TITLE_Y "強度"
*DISP_UNIT_Y "cps"
*DISP_WINDOW_NAME "MSG_MACROENGINE"
*FILE_COMMENT " "
*FILE_MD5 ""
*FILE_MEMO " "
*FILE_OPERATOR "Administrator"
*FILE_SAMPLE " "
*FILE_TYPE "RAS_RAW"
*FILE_USERGROUP "システムマネージャ"
*FILE_VERSION "1.0000000000"
*HW_ATTACHMENT_ID "ATT0025"
*HW_ATTACHMENT_NAME "標準|Standard"
*HW_COUNTER_ID-0 "CUT0025"
*HW_COUNTER_ID-1 "CUT0020"
*HW_COUNTER_ID-2 "CUT0020"
*HW_COUNTER_ID-3 "CSL0021"
*HW_COUNTER_ID-4 "CMC0021"
*HW_COUNTER_NAME-0 "D/teX Ultra|D/teX Ultra"
*HW_COUNTER_NAME-1 "None|None"
*HW_COUNTER_NAME-2 "None|None"
*HW_COUNTER_NAME-3 "BBM|BBM"
*HW_COUNTER_NAME-4 "検出器モノクロメータ|Detector monochromator"
*HW_COUNTER_SELECT_NAME "D/teX Ultra|D/teX Ultra"
*HW_GONIOMETER_ID "GON0023"
*HW_GONIOMETER_NAME "SmartLab|SmartLab"
*HW_GONIOMETER_RADIUS-0 "90.0"
*HW_GONIOMETER_RADIUS-1 "114.0"
*HW_GONIOMETER_RADIUS-2 "190.0"
*HW_GONIOMETER_RADIUS-3 "300.0"
*HW_GONIOMETER_RADIUS-4 "187.0"
*HW_GONIOMETER_RADIUS-5 "300.0"
*HW_GONIOMETER_RADIUS-6 "113.0"
*HW_GONIOMETER_RADIUS-7 "331.0"
*HW_I_OPT_ID-0 "CBO0021"
*HW_I_OPT_ID-1 "ICR0023"
*HW_I_OPT_ID-2 "ISL0021"
*HW_I_OPT_ID-3 "ISO0021"
*HW_I_OPT_ID-4 "IAD0021"
*HW_I_OPT_ID-5 "IPR0001"
*HW_I_OPT_NAME-0 "CBOユニット|CBO unit"
*HW_I_OPT_NAME-1 "標準入射光学ユニット|Standard incident optical unit"
*HW_I_OPT_NAME-2 "標準入射スリットボックス|Standard incident slit box"
*HW_I_OPT_NAME-3 "入射平行スリット|Incident parallel slit"
*HW_I_OPT_NAME-4 "長手制限スリット|Length limiting slit"
*HW_I_OPT_NAME-5 "None|None"
*HW_R_ATTENUATER_AUTOMODE "0"
*HW_R_OPT_ID-0 "RSS0021"
*HW_R_OPT_ID-1 "RCR0023"
*HW_R_OPT_ID-2 "RSO0021"
*HW_R_OPT_ID-3 "RRS0021"
*HW_R_OPT_ID-4 "ATN0021"
*HW_R_OPT_ID-5 "RFL0021"
*HW_R_OPT_ID-6 "RAD0021"
*HW_R_OPT_NAME-0 "標準受光スリットボックス1|Standard receiving slit box # 1"
*HW_R_OPT_NAME-1 "標準受光光学ユニット1|Standard receiving unit # 1"
*HW_R_OPT_NAME-2 "標準受光光学ユニット2|Standard receiving optical unit # 2"
*HW_R_OPT_NAME-3 "標準受光スリットボックス2|Standard receiving slit box # 2"
*HW_R_OPT_NAME-4 "標準アッテネータ|Standard Attenuator"
*HW_R_OPT_NAME-5 "Cu Kβ|Cu K-beta"
*HW_R_OPT_NAME-6 "調整用受光スリット|Alignment receiving slit"
*HW_SAMPLE_HOLDER_ID "SMP0023"
*HW_SAMPLE_HOLDER_NAME "標準Zステージ|Standard Z stage"
*HW_XG_CURRENT_MAX "50"
*HW_XG_CURRENT_MIN "2"
*HW_XG_CURRENT_RESOLUTION "1"
*HW_XG_CURRENT_UNIT "mA"
*HW_XG_FOCUS "1mm x 10mm"
*HW_XG_FOCUS_TYPE "Normal"
*HW_XG_ID ""
*HW_XG_NAME "3kW 封入管(ID:1200)|3kW Sealed tube(ID:1200)"
*HW_XG_TARGET_ATOMIC_NUMBER "29.0000000000"
*HW_XG_TARGET_NAME "Cu"
*HW_XG_TYPE "Hermetic"
*HW_XG_VOLTAGE_MAX "60"
*HW_XG_VOLTAGE_MIN "20"
*HW_XG_VOLTAGE_RESOLUTION "1"
*HW_XG_VOLTAGE_UNIT "kV"
*HW_XG_WATT_MAX "1.500"
*HW_XG_WATT_UNIT "kW"
*HW_XG_WAVE_LENGTH_ALPHA1 "1.540593"
*HW_XG_WAVE_LENGTH_ALPHA2 "1.544414"
*HW_XG_WAVE_LENGTH_BETA "1.392250"
*MEAS_COND_AXIS_NAME-0 "2θ/θ"
*MEAS_COND_AXIS_NAME-1 "2θ"
*MEAS_COND_AXIS_NAME-2 "ω"
*MEAS_COND_AXIS_NAME-3 "Z"
*MEAS_COND_AXIS_NAME-4 "2θ/ω"
*MEAS_COND_AXIS_NAME-5 "θs"
*MEAS_COND_AXIS_NAME-6 "θd"
*MEAS_COND_AXIS_NAME-7 "Ts"
*MEAS_COND_AXIS_NAME-8 "CBO選択スリット"
*MEAS_COND_AXIS_NAME-9 "M"
*MEAS_COND_AXIS_NAME-10 "入射平行スリット"
*MEAS_COND_AXIS_NAME-11 "入射スリット"
*MEAS_COND_AXIS_NAME-12 ""
*MEAS_COND_AXIS_NAME-13 "Zs"
*MEAS_COND_AXIS_NAME-14 "入射光学素子"
*MEAS_COND_AXIS_NAME-15 "長手制限スリット"
*MEAS_COND_AXIS_NAME-16 "センタースリット"
*MEAS_COND_AXIS_NAME-17 "フィルター"
*MEAS_COND_AXIS_NAME-18 "受光スリット1"
*MEAS_COND_AXIS_NAME-19 "受光スリット2"
*MEAS_COND_AXIS_NAME-20 "受光光学素子"
*MEAS_COND_AXIS_NAME-21 "受光平行スリット"
*MEAS_COND_AXIS_NAME-22 "調整用受光スリット"
*MEAS_COND_AXIS_NAME-23 ""
*MEAS_COND_AXIS_NAME-24 ""
*MEAS_COND_AXIS_NAME-25 "Zd"
*MEAS_COND_AXIS_NAME-26 "アッテネータ"
*MEAS_COND_AXIS_NAME-27 "検出器モノクロメータ"
*MEAS_COND_AXIS_NAME-28 "モノクロメータスリット"
*MEAS_COND_AXIS_NAME-29 "プライマリビーム"
*MEAS_COND_AXIS_NAME-30 "PHA"
*MEAS_COND_AXIS_NAME_INTERNAL-0 "TwoThetaTheta"
*MEAS_COND_AXIS_NAME_INTERNAL-1 "TwoTheta"
*MEAS_COND_AXIS_NAME_INTERNAL-2 "Omega"
*MEAS_COND_AXIS_NAME_INTERNAL-3 "Z"
*MEAS_COND_AXIS_NAME_INTERNAL-4 "TwoThetaOmega"
*MEAS_COND_AXIS_NAME_INTERNAL-5 "ThetaS"
*MEAS_COND_AXIS_NAME_INTERNAL-6 "ThetaD"
*MEAS_COND_AXIS_NAME_INTERNAL-7 "Ts"
*MEAS_COND_AXIS_NAME_INTERNAL-8 "CBO"
*MEAS_COND_AXIS_NAME_INTERNAL-9 "CBO-M"
*MEAS_COND_AXIS_NAME_INTERNAL-10 "IncidentSollerSlit"
*MEAS_COND_AXIS_NAME_INTERNAL-11 "IncidentSlitBox"
*MEAS_COND_AXIS_NAME_INTERNAL-12 "IncidentSlitBox-_Axis"
*MEAS_COND_AXIS_NAME_INTERNAL-13 "Zs"
*MEAS_COND_AXIS_NAME_INTERNAL-14 "IncidentMonochromator"
*MEAS_COND_AXIS_NAME_INTERNAL-15 "IncidentAxdSlit"
*MEAS_COND_AXIS_NAME_INTERNAL-16 "CenterSlit"
*MEAS_COND_AXIS_NAME_INTERNAL-17 "Filter"
*MEAS_COND_AXIS_NAME_INTERNAL-18 "ReceivingSlitBox1"
*MEAS_COND_AXIS_NAME_INTERNAL-19 "ReceivingSlitBox2"
*MEAS_COND_AXIS_NAME_INTERNAL-20 "ReceivingOptics"
*MEAS_COND_AXIS_NAME_INTERNAL-21 "ReceivingSollerSlit"
*MEAS_COND_AXIS_NAME_INTERNAL-22 "ReceivingAxdSlit"
*MEAS_COND_AXIS_NAME_INTERNAL-23 "ReceivingSlitBox1-_Axis"
*MEAS_COND_AXIS_NAME_INTERNAL-24 "ReceivingSlitBox2-_Axis"
*MEAS_COND_AXIS_NAME_INTERNAL-25 "ReceivingSlitBox2-Zd"
*MEAS_COND_AXIS_NAME_INTERNAL-26 "Attenuator"
*MEAS_COND_AXIS_NAME_INTERNAL-27 "CounterMonochromator"
*MEAS_COND_AXIS_NAME_INTERNAL-28 "CounterSlit"
*MEAS_COND_AXIS_NAME_INTERNAL-29 "IncidentPrimary"
*MEAS_COND_AXIS_NAME_INTERNAL-30 "PHA"
*MEAS_COND_AXIS_NAME_MAGICNO-0 "83951616.0000000000"
*MEAS_COND_AXIS_NAME_MAGICNO-1 "268632064.0000000000"
*MEAS_COND_AXIS_NAME_MAGICNO-2 "268500992.0000000000"
*MEAS_COND_AXIS_NAME_MAGICNO-3 "285278208.0000000000"
*MEAS_COND_AXIS_NAME_MAGICNO-4 "83951616.0000000000"
*MEAS_COND_AXIS_NAME_MAGICNO-5 "131072.0000000000"
*MEAS_COND_AXIS_NAME_MAGICNO-6 "131072.0000000000"
*MEAS_COND_AXIS_NAME_MAGICNO-7 "318898176.0000000000"
*MEAS_COND_AXIS_NAME_MAGICNO-8 "20971521.0000000000"
*MEAS_COND_AXIS_NAME_MAGICNO-9 "285343744.0000000000"
*MEAS_COND_AXIS_NAME_MAGICNO-10 "20971521.0000000000"
*MEAS_COND_AXIS_NAME_MAGICNO-11 "22020097.0000000000"
*MEAS_COND_AXIS_NAME_MAGICNO-12 "25165824.0000000000"
*MEAS_COND_AXIS_NAME_MAGICNO-13 "318898176.0000000000"
*MEAS_COND_AXIS_NAME_MAGICNO-14 "1.0000000000"
*MEAS_COND_AXIS_NAME_MAGICNO-15 "20971521.0000000000"
*MEAS_COND_AXIS_NAME_MAGICNO-16 "20971521.0000000000"
*MEAS_COND_AXIS_NAME_MAGICNO-17 "20971521.0000000000"
*MEAS_COND_AXIS_NAME_MAGICNO-18 "23068673.0000000000"
*MEAS_COND_AXIS_NAME_MAGICNO-19 "23068673.0000000000"
*MEAS_COND_AXIS_NAME_MAGICNO-20 "20971521.0000000000"
*MEAS_COND_AXIS_NAME_MAGICNO-21 "20971521.0000000000"
*MEAS_COND_AXIS_NAME_MAGICNO-22 "20971521.0000000000"
*MEAS_COND_AXIS_NAME_MAGICNO-23 "25165824.0000000000"
*MEAS_COND_AXIS_NAME_MAGICNO-24 "25165824.0000000000"
*MEAS_COND_AXIS_NAME_MAGICNO-25 "285343744.0000000000"
*MEAS_COND_AXIS_NAME_MAGICNO-26 "17301505.0000000000"
*MEAS_COND_AXIS_NAME_MAGICNO-27 "20971521.0000000000"
*MEAS_COND_AXIS_NAME_MAGICNO-28 "20971521.0000000000"
*MEAS_COND_AXIS_NAME_MAGICNO-29 "20971521.0000000000"
*MEAS_COND_AXIS_NAME_MAGICNO-30 "0.0000000000"
*MEAS_COND_AXIS_OFFSET-0 "-"
*MEAS_COND_AXIS_OFFSET-1 "-0.0801000000"
*MEAS_COND_AXIS_OFFSET-2 "0.1646000000"
*MEAS_COND_AXIS_OFFSET-3 "-"
*MEAS_COND_AXIS_OFFSET-4 "-"
*MEAS_COND_AXIS_OFFSET-5 "0.1646000000"
*MEAS_COND_AXIS_OFFSET-6 "-0.2447000000"
*MEAS_COND_AXIS_OFFSET-7 "-"
*MEAS_COND_AXIS_OFFSET-8 "-"
*MEAS_COND_AXIS_OFFSET-9 "-"
*MEAS_COND_AXIS_OFFSET-10 "-"
*MEAS_COND_AXIS_OFFSET-11 "-"
*MEAS_COND_AXIS_OFFSET-12 "-"
*MEAS_COND_AXIS_OFFSET-13 "-"
*MEAS_COND_AXIS_OFFSET-14 "-"
*MEAS_COND_AXIS_OFFSET-15 "-"
*MEAS_COND_AXIS_OFFSET-16 "-"
*MEAS_COND_AXIS_OFFSET-17 "-"
*MEAS_COND_AXIS_OFFSET-18 "-"
*MEAS_COND_AXIS_OFFSET-19 "-"
*MEAS_COND_AXIS_OFFSET-20 "-"
*MEAS_COND_AXIS_OFFSET-21 "-"
*MEAS_COND_AXIS_OFFSET-22 "-"
*MEAS_COND_AXIS_OFFSET-23 "-"
*MEAS_COND_AXIS_OFFSET-24 "-"
*MEAS_COND_AXIS_OFFSET-25 "-"
*MEAS_COND_AXIS_OFFSET-26 "-"
*MEAS_COND_AXIS_OFFSET-27 "-"
*MEAS_COND_AXIS_OFFSET-28 "-"
*MEAS_COND_AXIS_OFFSET-29 "-"
*MEAS_COND_AXIS_OFFSET-30 "-"
*MEAS_COND_AXIS_POSITION-0 "0.0000000000"
*MEAS_COND_AXIS_POSITION-1 "0.0000000000"
*MEAS_COND_AXIS_POSITION-2 "0.0000000000"
*MEAS_COND_AXIS_POSITION-3 "-2.9256400000"
*MEAS_COND_AXIS_POSITION-4 "0.0000000000"
*MEAS_COND_AXIS_POSITION-5 "0.0000000000"
*MEAS_COND_AXIS_POSITION-6 "0.0000000000"
*MEAS_COND_AXIS_POSITION-7 "-0.4278800000"
*MEAS_COND_AXIS_POSITION-8 "BB"
*MEAS_COND_AXIS_POSITION-9 "0.0000000000"
*MEAS_COND_AXIS_POSITION-10 "Soller_slit_5.0deg"
*MEAS_COND_AXIS_POSITION-11 "2/3deg"
*MEAS_COND_AXIS_POSITION-12 "2.2088000000"
*MEAS_COND_AXIS_POSITION-13 "-1.0609400000"
*MEAS_COND_AXIS_POSITION-14 "0.0000000000"
*MEAS_COND_AXIS_POSITION-15 "10.0mm"
*MEAS_COND_AXIS_POSITION-16 "None"
*MEAS_COND_AXIS_POSITION-17 "Cu_K-beta"
*MEAS_COND_AXIS_POSITION-18 "13.000mm"
*MEAS_COND_AXIS_POSITION-19 "13.000mm"
*MEAS_COND_AXIS_POSITION-20 "No_unit"
*MEAS_COND_AXIS_POSITION-21 "Soller_slit_5.0deg"
*MEAS_COND_AXIS_POSITION-22 "None"
*MEAS_COND_AXIS_POSITION-23 "13.0000000000"
*MEAS_COND_AXIS_POSITION-24 "13.0000000000"
*MEAS_COND_AXIS_POSITION-25 "0.0081300000"
*MEAS_COND_AXIS_POSITION-26 "Open"
*MEAS_COND_AXIS_POSITION-27 "None"
*MEAS_COND_AXIS_POSITION-28 "None"
*MEAS_COND_AXIS_POSITION-29 "None"
*MEAS_COND_AXIS_POSITION-30 "38.0000000000"
*MEAS_COND_AXIS_UNIT-0 "deg"
*MEAS_COND_AXIS_UNIT-1 "deg"
*MEAS_COND_AXIS_UNIT-2 "deg"
*MEAS_COND_AXIS_UNIT-3 "mm"
*MEAS_COND_AXIS_UNIT-4 "deg"
*MEAS_COND_AXIS_UNIT-5 "deg"
*MEAS_COND_AXIS_UNIT-6 "deg"
*MEAS_COND_AXIS_UNIT-7 "mm"
*MEAS_COND_AXIS_UNIT-8 ""
*MEAS_COND_AXIS_UNIT-9 "pulse"
*MEAS_COND_AXIS_UNIT-10 ""
*MEAS_COND_AXIS_UNIT-11 ""
*MEAS_COND_AXIS_UNIT-12 "mm"
*MEAS_COND_AXIS_UNIT-13 "mm"
*MEAS_COND_AXIS_UNIT-14 ""
*MEAS_COND_AXIS_UNIT-15 ""
*MEAS_COND_AXIS_UNIT-16 ""
*MEAS_COND_AXIS_UNIT-17 ""
*MEAS_COND_AXIS_UNIT-18 ""
*MEAS_COND_AXIS_UNIT-19 ""
*MEAS_COND_AXIS_UNIT-20 ""
*MEAS_COND_AXIS_UNIT-21 ""
*MEAS_COND_AXIS_UNIT-22 ""
*MEAS_COND_AXIS_UNIT-23 "mm"
*MEAS_COND_AXIS_UNIT-24 "mm"
*MEAS_COND_AXIS_UNIT-25 "mm"
*MEAS_COND_AXIS_UNIT-26 ""
*MEAS_COND_AXIS_UNIT-27 ""
*MEAS_COND_AXIS_UNIT-28 ""
*MEAS_COND_AXIS_UNIT-29 ""
*MEAS_COND_AXIS_UNIT-30 "div"
*MEAS_COND_COUNTER_CNTLOSS_CORR "0.0000000000"
*MEAS_COND_COUNTER_PHABASE "38.0000000000"
*MEAS_COND_COUNTER_PHAWINDOW "16.0000000000"
*MEAS_COND_COUNTER_PHA_UNIT "div"
*MEAS_COND_COUNTER_TAUDIFF "30.0000000000"
*MEAS_COND_COUNTER_TAUINT "0.0000000000"
*MEAS_COND_IRRADIATION_MODE "OFF"
*MEAS_COND_IRRADIATION_WIDTH ""
*MEAS_COND_OPT_ATTR "集中法"
*MEAS_COND_OPT_NAME "@集中法"
*MEAS_COND_UNSYMMETRIC_MODE "OFF"
*MEAS_COND_XG_CURRENT "30.0000000000"
*MEAS_COND_XG_VOLTAGE "40.0000000000"
*MEAS_COND_XG_WAVE_TYPE "Ka"
*MEAS_DATA_COUNT "5001.0000000000"
*MEAS_SCAN_AXIS_X "2θ/θ"
*MEAS_SCAN_AXIS_X_INTERNAL "TwoThetaTheta"
*MEAS_SCAN_END_TIME "07/09/22 15:02:19"
*MEAS_SCAN_MODE "CONTINUOUS"
*MEAS_SCAN_MONITOR "0"
*MEAS_SCAN_RESOLUTION_X "0.0002"
*MEAS_SCAN_SPEED "2.5"
*MEAS_SCAN_SPEED_UNIT "deg/min"
*MEAS_SCAN_START "20.0000000000"
*MEAS_SCAN_START_TIME "07/09/22 14:40:54"
*MEAS_SCAN_STEP "0.0100000000"
*MEAS_SCAN_STOP "70.0000000000"
*MEAS_SCAN_UNIT_X "deg"
*MEAS_SCAN_UNIT_Y "counts"
*RAS_HEADER_END
*RAS_INT_START
20.0000 1053.0000 1.0000
20.0400 1011.0000 1.0000
20.0800 1050.0000 1.0000
20.1200 1009.0000 1.0000
20.1600 1015.0000 1.0000
20.2000 1060.0000 1.0000
20.2400 1049.0000 1.0000
20.2800 1029.0000 1.0000
20.3200 1040.0000 1.0000
20.3600 1015.0000 1.0000
20.4000 1060.0000 1.0000
20.4400 1031.0000 1.0000
20.4800 1021.0000 1.0000
20.5200 1020.0000 1.0000
20.5600 1065.0000 1.0000
20.6000 1006.0000 1.0000
20.6400 995.0000 1.0000
20.6800 1072.0000 1.0000
20.7200 1039.0000 1.0000
20.7600 1052.0000 1.0000
20.8000 1038.0000 1.0000
20.8400 1030.0000 1.0000
20.8800 1041.0000 1.0000
20.9200 1091.0000 1.0000
20.9600 1013.0000 1.0000
21.0000 972.0000 1.0000
21.0400 1030.0000 1.0000
21.0800 1024.0000 1.0000
21.1200 991.0000 1.0000
21.1600 1009.0000 1.0000
21.2000 1040.0000 1.0000
21.2400 1071.0000 1.0000
21.2800 1085.0000 1.0000
21.3200 1043.0000 1.0000
21.3600 981.0000 1.0000
21.4000 1021.0000 1.0000
21.4400 979.0000 1.0000
21.4800 1044.0000 1.0000
21.5200 1018.0000 1.0000
21.5600 1044.0000 1.0000
21.6000 1016.0000 1.0000
21.6400 942.0000 1.0000
21.6800 989.0000 1.0000
21.7200 1060.0000 1.0000
21.7600 1030.0000 1.0000
21.8000 1020.0000 1.0000
21.8400 1074.0000 1.0000
21.8800 1029.0000 1.0000
21.9200 1005.0000 1.0000
21.9600 1018.0000 1.0000
22.0000 1069.0000 1.0000
22.0400 1019.0000 1.0000
22.0800 1017.0000 1.0000
22.1200 1033.0000 1.0000
22.1600 1016.0000 1.0000
22.2000 1029.0000 1.0000
22.2400 1047.0000 1.0000
22.2800 1000.0000 1.0000
22.3200 1012.0000 1.0000
22.3600 1033.0000 1.0000
22.4000 1036.0000 1.0000
22.4400 1072.0000 1.0000
22.4800 1063.0000 1.0000
22.5200 1070.0000 1.0000
22.5600 1031.0000 1.0000
22.6000 1039.0000 1.0000
22.6400 991.0000 1.0000
22.6800 1028.0000 1.0000
22.7200 1063.0000 1.0000
22.7600 1056.0000 1.0000
22.8000 1057.0000 1.0000
22.8400 1036.0000 1.0000
22.8800 1087.0000 1.0000
22.9200 1005.0000 1.0000
22.9600 1014.0000 1.0000
23.0000 1038.0000 1.0000
23.0400 1035.0000 1.0000
23.0800 1022.0000 1.0000
23.1200 1005.0000 1.0000
23.1600 1039.0000 1.0000
23.2000 1041.0000 1.0000
23.2400 984.0000 1.0000
23.2800 1030.0000 1.0000
23.3200 1040.0000 1.0000
23.3600 1008.0000 1.0000
23.4000 1034.0000 1.0000
23.4400 1004.0000 1.0000
23.4800 977.0000 1.0000
23.5200 1049.0000 1.0000
23.5600 998.0000 1.0000
23.6000 1018.0000 1.0000
23.6400 1008.0000 1.0000
23.6800 1047.0000 1.0000
23.7200 1022.0000 1.0000
23.7600 1044.0000 1.0000
23.8000 1015.0000 1.0000
23.8400 1029.0000 1.0000
23.8800 1078.0000 1.0000
23.9200 1033.0000 1.0000
23.9600 1021.0000 1.0000
24.0000 1073.0000 1.0000
24.0400 1113.0000 1.0000
24.0800 1139.0000 1.0000
24.1200 1104.0000 1.0000
24.1600 1086.0000 1.0000
24.2000 1069.0000 1.0000
24.2400 1014.0000 1.0000
24.2800 1033.0000 1.0000
24.3200 964.0000 1.0000
24.3600 1051.0000 1.0000
24.4000 1005.0000 1.0000
24.4400 1011.0000 1.0000
24.4800 1043.0000 1.0000
24.5200 1028.0000 1.0000
24.5600 954.0000 1.0000
24.6000 1037.0000 1.0000
24.6400 1036.0000 1.0000
24.6800 1042.0000 1.0000
24.7200 1002.0000 1.0000
24.7600 984.0000 1.0000
24.8000 1015.0000 1.0000
24.8400 1040.0000 1.0000
24.8800 1039.0000 1.0000
24.9200 993.0000 1.0000
24.9600 967.0000 1.0000
25.0000 963.0000 1.0000
25.0400 985.0000 1.0000
25.0800 942.0000 1.0000
25.1200 943.0000 1.0000
25.1600 962.0000 1.0000
25.2000 1000.0000 1.0000
25.2400 1010.0000 1.0000
25.2800 987.0000 1.0000
25.3200 969.0000 1.0000
25.3600 988.0000 1.0000
25.4000 1024.0000 1.0000
25.4400 1030.0000 1.0000
25.4800 1041.0000 1.0000
25.5200 1020.0000 1.0000
25.5600 983.0000 1.0000
25.6000 1030.0000 1.0000
25.6400 984.0000 1.0000
25.6800 1014.0000 1.0000
25.7200 1021.0000 1.0000
25.7600 1008.0000 1.0000
25.8000 1044.0000 1.0000
25.8400 1025.0000 1.0000
25.8800 1116.0000 1.0000
25.9200 1096.0000 1.0000
25.9600 1119.0000 1.0000
26.0000 1112.0000 1.0000
26.0400 1130.0000 1.0000
26.0800 1193.0000 1.0000
26.1200 1250.0000 1.0000
26.1600 1406.0000 1.0000
26.2000 1456.0000 1.0000
26.2400 1791.0000 1.0000
26.2800 2052.0000 1.0000
26.3200 2459.0000 1.0000
26.3600 3071.0000 1.0000
26.4000 3447.0000 1.0000
26.4400 3599.0000 1.0000
26.4800 3112.0000 1.0000
26.5200 2464.0000 1.0000
26.5600 2057.0000 1.0000
26.6000 1703.0000 1.0000
26.6400 1471.0000 1.0000
26.6800 1342.0000 1.0000
26.7200 1206.0000 1.0000
26.7600 1150.0000 1.0000
26.8000 1142.0000 1.0000
26.8400 1074.0000 1.0000
26.8800 1026.0000 1.0000
26.9200 1050.0000 1.0000
26.9600 1108.0000 1.0000
27.0000 1024.0000 1.0000
27.0400 1035.0000 1.0000
27.0800 986.0000 1.0000
27.1200 979.0000 1.0000
27.1600 931.0000 1.0000
27.2000 969.0000 1.0000
27.2400 926.0000 1.0000
27.2800 927.0000 1.0000
27.3200 927.0000 1.0000
27.3600 966.0000 1.0000
27.4000 973.0000 1.0000
27.4400 909.0000 1.0000
27.4800 936.0000 1.0000
27.5200 913.0000 1.0000
27.5600 965.0000 1.0000
27.6000 923.0000 1.0000
27.6400 951.0000 1.0000
27.6800 897.0000 1.0000
27.7200 849.0000 1.0000
27.7600 909.0000 1.0000
27.8000 901.0000 1.0000
27.8400 946.0000 1.0000
27.8800 930.0000 1.0000
27.9200 912.0000 1.0000
27.9600 887.0000 1.0000
28.0000 896.0000 1.0000
28.0400 858.0000 1.0000
28.0800 854.0000 1.0000
28.1200 876.0000 1.0000
28.1600 935.0000 1.0000
28.2000 844.0000 1.0000
28.2400 872.0000 1.0000
28.2800 909.0000 1.0000
28.3200 910.0000 1.0000
28.3600 868.0000 1.0000
28.4000 911.0000 1.0000
28.4400 867.0000 1.0000
28.4800 914.0000 1.0000
28.5200 799.0000 1.0000
28.5600 854.0000 1.0000
28.6000 830.0000 1.0000
28.6400 866.0000 1.0000
28.6800 834.0000 1.0000
28.7200 871.0000 1.0000
28.7600 850.0000 1.0000
28.8000 835.0000 1.0000
28.8400 839.0000 1.0000
28.8800 865.0000 1.0000
28.9200 816.0000 1.0000
28.9600 813.0000 1.0000
29.0000 847.0000 1.0000
29.0400 853.0000 1.0000
29.0800 847.0000 1.0000
29.1200 843.0000 1.0000
29.1600 893.0000 1.0000
29.2000 823.0000 1.0000
29.2400 798.0000 1.0000
29.2800 843.0000 1.0000
29.3200 833.0000 1.0000
29.3600 828.0000 1.0000
29.4000 786.0000 1.0000
29.4400 793.0000 1.0000
29.4800 809.0000 1.0000
29.5200 820.0000 1.0000
29.5600 760.0000 1.0000
29.6000 856.0000 1.0000
29.6400 804.0000 1.0000
29.6800 823.0000 1.0000
29.7200 810.0000 1.0000
29.7600 793.0000 1.0000
29.8000 848.0000 1.0000
29.8400 777.0000 1.0000
29.8800 807.0000 1.0000
29.9200 845.0000 1.0000
29.9600 827.0000 1.0000
30.0000 807.0000 1.0000
30.0400 767.0000 1.0000
30.0800 806.0000 1.0000
30.1200 812.0000 1.0000
30.1600 758.0000 1.0000
30.2000 804.0000 1.0000
30.2400 858.0000 1.0000
30.2800 792.0000 1.0000
30.3200 787.0000 1.0000
30.3600 800.0000 1.0000
30.4000 830.0000 1.0000
30.4400 791.0000 1.0000
30.4800 811.0000 1.0000
30.5200 825.0000 1.0000
30.5600 765.0000 1.0000
30.6000 765.0000 1.0000
30.6400 787.0000 1.0000
30.6800 748.0000 1.0000
30.7200 756.0000 1.0000
30.7600 751.0000 1.0000
30.8000 820.0000 1.0000
30.8400 796.0000 1.0000
30.8800 734.0000 1.0000
30.9200 789.0000 1.0000
30.9600 747.0000 1.0000
31.0000 767.0000 1.0000
31.0400 789.0000 1.0000
31.0800 827.0000 1.0000
31.1200 767.0000 1.0000
31.1600 805.0000 1.0000
31.2000 795.0000 1.0000
31.2400 810.0000 1.0000
31.2800 773.0000 1.0000
31.3200 752.0000 1.0000
31.3600 775.0000 1.0000
31.4000 757.0000 1.0000
31.4400 774.0000 1.0000
31.4800 769.0000 1.0000
31.5200 755.0000 1.0000
31.5600 739.0000 1.0000
31.6000 729.0000 1.0000
31.6400 761.0000 1.0000
31.6800 795.0000 1.0000
31.7200 784.0000 1.0000
31.7600 795.0000 1.0000
31.8000 772.0000 1.0000
31.8400 728.0000 1.0000
31.8800 688.0000 1.0000
31.9200 744.0000 1.0000
31.9600 737.0000 1.0000
32.0000 710.0000 1.0000
32.0400 750.0000 1.0000
32.0800 746.0000 1.0000
32.1200 784.0000 1.0000
32.1600 745.0000 1.0000
32.2000 753.0000 1.0000
32.2400 772.0000 1.0000
32.2800 718.0000 1.0000
32.3200 725.0000 1.0000
32.3600 726.0000 1.0000
32.4000 728.0000 1.0000
32.4400 755.0000 1.0000
32.4800 692.0000 1.0000
32.5200 720.0000 1.0000
32.5600 770.0000 1.0000
32.6000 719.0000 1.0000
32.6400 747.0000 1.0000
32.6800 745.0000 1.0000
32.7200 756.0000 1.0000
32.7600 740.0000 1.0000
32.8000 778.0000 1.0000
32.8400 768.0000 1.0000
32.8800 750.0000 1.0000
32.9200 769.0000 1.0000
32.9600 810.0000 1.0000
33.0000 812.0000 1.0000
33.0400 893.0000 1.0000
33.0800 907.0000 1.0000
33.1200 911.0000 1.0000
33.1600 886.0000 1.0000
33.2000 866.0000 1.0000
33.2400 811.0000 1.0000
33.2800 854.0000 1.0000
33.3200 848.0000 1.0000
33.3600 851.0000 1.0000
33.4000 955.0000 1.0000
33.4400 1017.0000 1.0000
33.4800 1114.0000 1.0000
33.5200 1339.0000 1.0000
33.5600 1619.0000 1.0000
33.6000 1899.0000 1.0000
33.6400 1776.0000 1.0000
33.6800 1735.0000 1.0000
33.7200 1465.0000 1.0000
33.7600 1293.0000 1.0000
33.8000 1132.0000 1.0000
33.8400 987.0000 1.0000
33.8800 910.0000 1.0000
33.9200 875.0000 1.0000
33.9600 822.0000 1.0000
34.0000 759.0000 1.0000
34.0400 748.0000 1.0000
34.0800 711.0000 1.0000
34.1200 701.0000 1.0000
34.1600 683.0000 1.0000
34.2000 713.0000 1.0000
34.2400 719.0000 1.0000
34.2800 691.0000 1.0000
34.3200 729.0000 1.0000
34.3600 654.0000 1.0000
34.4000 712.0000 1.0000
34.4400 645.0000 1.0000
34.4800 678.0000 1.0000
34.5200 657.0000 1.0000
34.5600 655.0000 1.0000
34.6000 680.0000 1.0000
34.6400 617.0000 1.0000
34.6800 639.0000 1.0000
34.7200 645.0000 1.0000
34.7600 646.0000 1.0000
34.8000 639.0000 1.0000
34.8400 658.0000 1.0000
34.8800 644.0000 1.0000
34.9200 642.0000 1.0000
34.9600 670.0000 1.0000
35.0000 614.0000 1.0000
35.0400 626.0000 1.0000
35.0800 652.0000 1.0000
35.1200 659.0000 1.0000
35.1600 651.0000 1.0000
35.2000 686.0000 1.0000
35.2400 681.0000 1.0000
35.2800 632.0000 1.0000
35.3200 653.0000 1.0000
35.3600 737.0000 1.0000
35.4000 746.0000 1.0000
35.4400 935.0000 1.0000
35.4800 1118.0000 1.0000
35.5200 1275.0000 1.0000
35.5600 1265.0000 1.0000
35.6000 1116.0000 1.0000
35.6400 947.0000 1.0000
35.6800 876.0000 1.0000
35.7200 750.0000 1.0000
35.7600 649.0000 1.0000
35.8000 606.0000 1.0000
35.8400 581.0000 1.0000
35.8800 594.0000 1.0000
35.9200 586.0000 1.0000
35.9600 629.0000 1.0000
36.0000 604.0000 1.0000
36.0400 574.0000 1.0000
36.0800 602.0000 1.0000
36.1200 585.0000 1.0000
36.1600 587.0000 1.0000
36.2000 593.0000 1.0000
36.2400 559.0000 1.0000
36.2800 589.0000 1.0000
36.3200 600.0000 1.0000
36.3600 630.0000 1.0000
36.4000 594.0000 1.0000
36.4400 590.0000 1.0000
36.4800 597.0000 1.0000
36.5200 584.0000 1.0000
36.5600 608.0000 1.0000
36.6000 579.0000 1.0000
36.6400 576.0000 1.0000
36.6800 589.0000 1.0000
36.7200 589.0000 1.0000
36.7600 568.0000 1.0000
36.8000 559.0000 1.0000
36.8400 600.0000 1.0000
36.8800 616.0000 1.0000
36.9200 592.0000 1.0000
36.9600 594.0000 1.0000
37.0000 572.0000 1.0000
37.0400 596.0000 1.0000
37.0800 599.0000 1.0000
37.1200 625.0000 1.0000
37.1600 618.0000 1.0000
37.2000 601.0000 1.0000
37.2400 683.0000 1.0000
37.2800 676.0000 1.0000
37.3200 698.0000 1.0000
37.3600 782.0000 1.0000
37.4000 817.0000 1.0000
37.4400 908.0000 1.0000
37.4800 1100.0000 1.0000
37.5200 1296.0000 1.0000
37.5600 1703.0000 1.0000
37.6000 2150.0000 1.0000
37.6400 2543.0000 1.0000
37.6800 2752.0000 1.0000
37.7200 2507.0000 1.0000
37.7600 2256.0000 1.0000
37.8000 1762.0000 1.0000
37.8400 1475.0000 1.0000
37.8800 1193.0000 1.0000
37.9200 1005.0000 1.0000
37.9600 855.0000 1.0000
38.0000 739.0000 1.0000
38.0400 623.0000 1.0000
38.0800 630.0000 1.0000
38.1200 592.0000 1.0000
38.1600 596.0000 1.0000
38.2000 603.0000 1.0000
38.2400 527.0000 1.0000
38.2800 587.0000 1.0000
38.3200 509.0000 1.0000
38.3600 546.0000 1.0000
38.4000 537.0000 1.0000
38.4400 538.0000 1.0000
38.4800 566.0000 1.0000
38.5200 544.0000 1.0000
38.5600 555.0000 1.0000
38.6000 558.0000 1.0000
38.6400 549.0000 1.0000
38.6800 568.0000 1.0000
38.7200 522.0000 1.0000
38.7600 578.0000 1.0000
38.8000 552.0000 1.0000
38.8400 535.0000 1.0000
38.8800 511.0000 1.0000
38.9200 543.0000 1.0000
38.9600 550.0000 1.0000
39.0000 528.0000 1.0000
39.0400 508.0000 1.0000
39.0800 508.0000 1.0000
39.1200 502.0000 1.0000
39.1600 512.0000 1.0000
39.2000 497.0000 1.0000
39.2400 510.0000 1.0000
39.2800 510.0000 1.0000
39.3200 524.0000 1.0000
39.3600 506.0000 1.0000
39.4000 477.0000 1.0000
39.4400 506.0000 1.0000
39.4800 480.0000 1.0000
39.5200 520.0000 1.0000
39.5600 471.0000 1.0000
39.6000 502.0000 1.0000
39.6400 483.0000 1.0000
39.6800 527.0000 1.0000
39.7200 457.0000 1.0000
39.7600 519.0000 1.0000
39.8000 481.0000 1.0000
39.8400 494.0000 1.0000
39.8800 512.0000 1.0000
39.9200 521.0000 1.0000
39.9600 466.0000 1.0000
40.0000 526.0000 1.0000
40.0400 477.0000 1.0000
40.0800 494.0000 1.0000
40.1200 485.0000 1.0000
40.1600 464.0000 1.0000
40.2000 491.0000 1.0000
40.2400 500.0000 1.0000
40.2800 509.0000 1.0000
40.3200 446.0000 1.0000
40.3600 473.0000 1.0000
40.4000 459.0000 1.0000
40.4400 521.0000 1.0000
40.4800 499.0000 1.0000
40.5200 469.0000 1.0000
40.5600 530.0000 1.0000
40.6000 481.0000 1.0000
40.6400 472.0000 1.0000
40.6800 515.0000 1.0000
40.7200 489.0000 1.0000
40.7600 541.0000 1.0000
40.8000 524.0000 1.0000
40.8400 479.0000 1.0000
40.8800 493.0000 1.0000
40.9200 482.0000 1.0000
40.9600 482.0000 1.0000
41.0000 511.0000 1.0000
41.0400 506.0000 1.0000
41.0800 474.0000 1.0000
41.1200 489.0000 1.0000
41.1600 512.0000 1.0000
41.2000 457.0000 1.0000
41.2400 462.0000 1.0000
41.2800 484.0000 1.0000
41.3200 490.0000 1.0000
41.3600 485.0000 1.0000
41.4000 467.0000 1.0000
41.4400 463.0000 1.0000
41.4800 460.0000 1.0000
41.5200 488.0000 1.0000
41.5600 473.0000 1.0000
41.6000 470.0000 1.0000
41.6400 481.0000 1.0000
41.6800 460.0000 1.0000
41.7200 484.0000 1.0000
41.7600 478.0000 1.0000
41.8000 479.0000 1.0000
41.8400 505.0000 1.0000
41.8800 489.0000 1.0000
41.9200 464.0000 1.0000
41.9600 493.0000 1.0000
42.0000 476.0000 1.0000
42.0400 481.0000 1.0000
42.0800 487.0000 1.0000
42.1200 471.0000 1.0000
42.1600 476.0000 1.0000
42.2000 457.0000 1.0000
42.2400 498.0000 1.0000
42.2800 502.0000 1.0000
42.3200 516.0000 1.0000
42.3600 486.0000 1.0000
42.4000 511.0000 1.0000
42.4400 514.0000 1.0000
42.4800 506.0000 1.0000
42.5200 503.0000 1.0000
42.5600 495.0000 1.0000
42.6000 448.0000 1.0000
42.6400 438.0000 1.0000
42.6800 468.0000 1.0000
42.7200 447.0000 1.0000
42.7600 456.0000 1.0000
42.8000 440.0000 1.0000
42.8400 459.0000 1.0000
42.8800 442.0000 1.0000
42.9200 435.0000 1.0000
42.9600 461.0000 1.0000
43.0000 440.0000 1.0000
43.0400 466.0000 1.0000
43.0800 464.0000 1.0000
43.1200 462.0000 1.0000
43.1600 445.0000 1.0000
43.2000 434.0000 1.0000
43.2400 463.0000 1.0000
43.2800 462.0000 1.0000
43.3200 433.0000 1.0000
43.3600 441.0000 1.0000
43.4000 464.0000 1.0000
43.4400 479.0000 1.0000
43.4800 443.0000 1.0000
43.5200 472.0000 1.0000
43.5600 440.0000 1.0000
43.6000 478.0000 1.0000
43.6400 457.0000 1.0000
43.6800 477.0000 1.0000
43.7200 443.0000 1.0000
43.7600 469.0000 1.0000
43.8000 460.0000 1.0000
43.8400 465.0000 1.0000
43.8800 486.0000 1.0000
43.9200 450.0000 1.0000
43.9600 458.0000 1.0000
44.0000 464.0000 1.0000
44.0400 435.0000 1.0000
44.0800 475.0000 1.0000
44.1200 464.0000 1.0000
44.1600 439.0000 1.0000
44.2000 434.0000 1.0000
44.2400 411.0000 1.0000
44.2800 462.0000 1.0000
44.3200 452.0000 1.0000
44.3600 458.0000 1.0000
44.4000 426.0000 1.0000
44.4400 428.0000 1.0000
44.4800 435.0000 1.0000
44.5200 450.0000 1.0000
44.5600 413.0000 1.0000
44.6000 418.0000 1.0000
44.6400 449.0000 1.0000
44.6800 421.0000 1.0000
44.7200 458.0000 1.0000
44.7600 430.0000 1.0000
44.8000 445.0000 1.0000
44.8400 420.0000 1.0000
44.8800 427.0000 1.0000
44.9200 486.0000 1.0000
44.9600 410.0000 1.0000
45.0000 415.0000 1.0000
45.0400 409.0000 1.0000
45.0800 446.0000 1.0000
45.1200 419.0000 1.0000
45.1600 442.0000 1.0000
45.2000 442.0000 1.0000
45.2400 438.0000 1.0000
45.2800 441.0000 1.0000
45.3200 441.0000 1.0000
45.3600 427.0000 1.0000
45.4000 431.0000 1.0000
45.4400 450.0000 1.0000
45.4800 432.0000 1.0000
45.5200 382.0000 1.0000
45.5600 407.0000 1.0000
45.6000 421.0000 1.0000
45.6400 443.0000 1.0000
45.6800 425.0000 1.0000
45.7200 394.0000 1.0000
45.7600 412.0000 1.0000
45.8000 454.0000 1.0000
45.8400 409.0000 1.0000
45.8800 412.0000 1.0000
45.9200 428.0000 1.0000
45.9600 428.0000 1.0000
46.0000 433.0000 1.0000
46.0400 433.0000 1.0000
46.0800 438.0000 1.0000
46.1200 438.0000 1.0000
46.1600 457.0000 1.0000
46.2000 442.0000 1.0000
46.2400 450.0000 1.0000
46.2800 415.0000 1.0000
46.3200 416.0000 1.0000
46.3600 422.0000 1.0000
46.4000 458.0000 1.0000
46.4400 443.0000 1.0000
46.4800 416.0000 1.0000
46.5200 430.0000 1.0000
46.5600 424.0000 1.0000
46.6000 404.0000 1.0000
46.6400 426.0000 1.0000
46.6800 438.0000 1.0000
46.7200 423.0000 1.0000
46.7600 400.0000 1.0000
46.8000 390.0000 1.0000
46.8400 417.0000 1.0000
46.8800 433.0000 1.0000
46.9200 403.0000 1.0000
46.9600 437.0000 1.0000
47.0000 405.0000 1.0000
47.0400 435.0000 1.0000
47.0800 423.0000 1.0000
47.1200 448.0000 1.0000
47.1600 406.0000 1.0000
47.2000 421.0000 1.0000
47.2400 414.0000 1.0000
47.2800 411.0000 1.0000
47.3200 408.0000 1.0000
47.3600 388.0000 1.0000
47.4000 399.0000 1.0000
47.4400 423.0000 1.0000
47.4800 431.0000 1.0000
47.5200 427.0000 1.0000
47.5600 395.0000 1.0000
47.6000 412.0000 1.0000
47.6400 415.0000 1.0000
47.6800 445.0000 1.0000
47.7200 408.0000 1.0000
47.7600 429.0000 1.0000
47.8000 364.0000 1.0000
47.8400 429.0000 1.0000
47.8800 423.0000 1.0000
47.9200 401.0000 1.0000
47.9600 420.0000 1.0000
48.0000 416.0000 1.0000
48.0400 424.0000 1.0000
48.0800 390.0000 1.0000
48.1200 378.0000 1.0000
48.1600 393.0000 1.0000
48.2000 424.0000 1.0000
48.2400 385.0000 1.0000
48.2800 424.0000 1.0000
48.3200 401.0000 1.0000
48.3600 396.0000 1.0000
48.4000 436.0000 1.0000
48.4400 386.0000 1.0000
48.4800 415.0000 1.0000
48.5200 412.0000 1.0000
48.5600 388.0000 1.0000
48.6000 374.0000 1.0000
48.6400 392.0000 1.0000
48.6800 389.0000 1.0000
48.7200 401.0000 1.0000
48.7600 402.0000 1.0000
48.8000 374.0000 1.0000
48.8400 400.0000 1.0000
48.8800 380.0000 1.0000
48.9200 367.0000 1.0000
48.9600 382.0000 1.0000
49.0000 422.0000 1.0000
49.0400 383.0000 1.0000
49.0800 431.0000 1.0000
49.1200 386.0000 1.0000
49.1600 426.0000 1.0000
49.2000 411.0000 1.0000
49.2400 410.0000 1.0000
49.2800 431.0000 1.0000
49.3200 421.0000 1.0000
49.3600 449.0000 1.0000
49.4000 448.0000 1.0000
49.4400 412.0000 1.0000
49.4800 410.0000 1.0000
49.5200 458.0000 1.0000
49.5600 387.0000 1.0000
49.6000 416.0000 1.0000
49.6400 420.0000 1.0000
49.6800 413.0000 1.0000
49.7200 398.0000 1.0000
49.7600 434.0000 1.0000
49.8000 400.0000 1.0000
49.8400 400.0000 1.0000
49.8800 406.0000 1.0000
49.9200 398.0000 1.0000
49.9600 414.0000 1.0000
50.0000 401.0000 1.0000
50.0400 411.0000 1.0000
50.0800 411.0000 1.0000
50.1200 361.0000 1.0000
50.1600 382.0000 1.0000
50.2000 404.0000 1.0000
50.2400 429.0000 1.0000
50.2800 429.0000 1.0000
50.3200 430.0000 1.0000
50.3600 414.0000 1.0000
50.4000 408.0000 1.0000
50.4400 403.0000 1.0000
50.4800 403.0000 1.0000
50.5200 416.0000 1.0000
50.5600 436.0000 1.0000
50.6000 393.0000 1.0000
50.6400 419.0000 1.0000
50.6800 434.0000 1.0000
50.7200 427.0000 1.0000
50.7600 422.0000 1.0000
50.8000 448.0000 1.0000
50.8400 386.0000 1.0000
50.8800 430.0000 1.0000
50.9200 429.0000 1.0000
50.9600 459.0000 1.0000
51.0000 427.0000 1.0000
51.0400 496.0000 1.0000
51.0800 479.0000 1.0000
51.1200 575.0000 1.0000
51.1600 575.0000 1.0000
51.2000 677.0000 1.0000
51.2400 785.0000 1.0000
51.2800 925.0000 1.0000
51.3200 1252.0000 1.0000
51.3600 1687.0000 1.0000
51.4000 2435.0000 1.0000
51.4400 2776.0000 1.0000
51.4800 2747.0000 1.0000
51.5200 2405.0000 1.0000
51.5600 2122.0000 1.0000
51.6000 1883.0000 1.0000
51.6400 1535.0000 1.0000
51.6800 1167.0000 1.0000
51.7200 911.0000 1.0000
51.7600 706.0000 1.0000
51.8000 651.0000 1.0000
51.8400 541.0000 1.0000
51.8800 558.0000 1.0000
51.9200 488.0000 1.0000
51.9600 486.0000 1.0000
52.0000 461.0000 1.0000
52.0400 451.0000 1.0000
52.0800 454.0000 1.0000
52.1200 429.0000 1.0000
52.1600 469.0000 1.0000
52.2000 454.0000 1.0000
52.2400 443.0000 1.0000
52.2800 414.0000 1.0000
52.3200 424.0000 1.0000
52.3600 396.0000 1.0000
52.4000 417.0000 1.0000
52.4400 411.0000 1.0000
52.4800 388.0000 1.0000
52.5200 403.0000 1.0000
52.5600 369.0000 1.0000
52.6000 418.0000 1.0000
52.6400 377.0000 1.0000
52.6800 370.0000 1.0000
52.7200 398.0000 1.0000
52.7600 404.0000 1.0000
52.8000 418.0000 1.0000
52.8400 381.0000 1.0000
52.8800 388.0000 1.0000
52.9200 424.0000 1.0000
52.9600 425.0000 1.0000
53.0000 412.0000 1.0000
53.0400 378.0000 1.0000
53.0800 376.0000 1.0000
53.1200 376.0000 1.0000
53.1600 405.0000 1.0000
53.2000 382.0000 1.0000
53.2400 405.0000 1.0000
53.2800 402.0000 1.0000
53.3200 419.0000 1.0000
53.3600 374.0000 1.0000
53.4000 351.0000 1.0000
53.4400 390.0000 1.0000
53.4800 406.0000 1.0000
53.5200 382.0000 1.0000
53.5600 371.0000 1.0000
53.6000 370.0000 1.0000
53.6400 400.0000 1.0000
53.6800 386.0000 1.0000
53.7200 382.0000 1.0000
53.7600 407.0000 1.0000
53.8000 419.0000 1.0000
53.8400 423.0000 1.0000
53.8800 372.0000 1.0000
53.9200 435.0000 1.0000
53.9600 431.0000 1.0000
54.0000 464.0000 1.0000
54.0400 419.0000 1.0000
54.0800 438.0000 1.0000
54.1200 439.0000 1.0000
54.1600 442.0000 1.0000
54.2000 435.0000 1.0000
54.2400 422.0000 1.0000
54.2800 465.0000 1.0000
54.3200 427.0000 1.0000
54.3600 477.0000 1.0000
54.4000 528.0000 1.0000
54.4400 524.0000 1.0000
54.4800 563.0000 1.0000
54.5200 563.0000 1.0000
54.5600 561.0000 1.0000
54.6000 571.0000 1.0000
54.6400 498.0000 1.0000
54.6800 515.0000 1.0000
54.7200 472.0000 1.0000
54.7600 462.0000 1.0000
54.8000 446.0000 1.0000
54.8400 422.0000 1.0000
54.8800 397.0000 1.0000
54.9200 410.0000 1.0000
54.9600 415.0000 1.0000
55.0000 380.0000 1.0000
55.0400 369.0000 1.0000
55.0800 362.0000 1.0000
55.1200 394.0000 1.0000
55.1600 375.0000 1.0000
55.2000 400.0000 1.0000
55.2400 368.0000 1.0000
55.2800 386.0000 1.0000
55.3200 381.0000 1.0000
55.3600 384.0000 1.0000
55.4000 376.0000 1.0000
55.4400 366.0000 1.0000
55.4800 365.0000 1.0000
55.5200 384.0000 1.0000
55.5600 387.0000 1.0000
55.6000 387.0000 1.0000
55.6400 333.0000 1.0000
55.6800 373.0000 1.0000
55.7200 353.0000 1.0000
55.7600 386.0000 1.0000
55.8000 359.0000 1.0000
55.8400 374.0000 1.0000
55.8800 364.0000 1.0000
55.9200 380.0000 1.0000
55.9600 365.0000 1.0000
56.0000 389.0000 1.0000
56.0400 376.0000 1.0000
56.0800 360.0000 1.0000
56.1200 349.0000 1.0000
56.1600 416.0000 1.0000
56.2000 372.0000 1.0000
56.2400 367.0000 1.0000
56.2800 358.0000 1.0000
56.3200 388.0000 1.0000
56.3600 378.0000 1.0000
56.4000 394.0000 1.0000
56.4400 372.0000 1.0000
56.4800 378.0000 1.0000
56.5200 396.0000 1.0000
56.5600 341.0000 1.0000
56.6000 367.0000 1.0000
56.6400 373.0000 1.0000
56.6800 365.0000 1.0000
56.7200 366.0000 1.0000
56.7600 380.0000 1.0000
56.8000 386.0000 1.0000
56.8400 369.0000 1.0000
56.8800 336.0000 1.0000
56.9200 373.0000 1.0000
56.9600 358.0000 1.0000
57.0000 369.0000 1.0000
57.0400 370.0000 1.0000
57.0800 372.0000 1.0000
57.1200 361.0000 1.0000
57.1600 372.0000 1.0000
57.2000 390.0000 1.0000
57.2400 380.0000 1.0000
57.2800 391.0000 1.0000
57.3200 359.0000 1.0000
57.3600 373.0000 1.0000
57.4000 383.0000 1.0000
57.4400 399.0000 1.0000
57.4800 390.0000 1.0000
57.5200 403.0000 1.0000
57.5600 364.0000 1.0000
57.6000 390.0000 1.0000
57.6400 389.0000 1.0000
57.6800 340.0000 1.0000
57.7200 348.0000 1.0000
57.7600 358.0000 1.0000
57.8000 393.0000 1.0000
57.8400 384.0000 1.0000
57.8800 387.0000 1.0000
57.9200 362.0000 1.0000
57.9600 360.0000 1.0000
58.0000 370.0000 1.0000
58.0400 347.0000 1.0000
58.0800 386.0000 1.0000
58.1200 366.0000 1.0000
58.1600 354.0000 1.0000
58.2000 348.0000 1.0000
58.2400 329.0000 1.0000
58.2800 347.0000 1.0000
58.3200 358.0000 1.0000
58.3600 337.0000 1.0000
58.4000 374.0000 1.0000
58.4400 388.0000 1.0000
58.4800 359.0000 1.0000
58.5200 387.0000 1.0000
58.5600 354.0000 1.0000
58.6000 378.0000 1.0000
58.6400 341.0000 1.0000
58.6800 380.0000 1.0000
58.7200 371.0000 1.0000
58.7600 372.0000 1.0000
58.8000 349.0000 1.0000
58.8400 374.0000 1.0000
58.8800 349.0000 1.0000
58.9200 358.0000 1.0000
58.9600 377.0000 1.0000
59.0000 367.0000 1.0000
59.0400 360.0000 1.0000
59.0800 371.0000 1.0000
59.1200 384.0000 1.0000
59.1600 368.0000 1.0000
59.2000 365.0000 1.0000
59.2400 353.0000 1.0000
59.2800 355.0000 1.0000
59.3200 396.0000 1.0000
59.3600 359.0000 1.0000
59.4000 372.0000 1.0000
59.4400 379.0000 1.0000
59.4800 363.0000 1.0000
59.5200 330.0000 1.0000
59.5600 364.0000 1.0000
59.6000 373.0000 1.0000
59.6400 398.0000 1.0000
59.6800 362.0000 1.0000
59.7200 365.0000 1.0000
59.7600 346.0000 1.0000
59.8000 384.0000 1.0000
59.8400 357.0000 1.0000
59.8800 379.0000 1.0000
59.9200 376.0000 1.0000
59.9600 345.0000 1.0000
60.0000 397.0000 1.0000
60.0400 373.0000 1.0000
60.0800 395.0000 1.0000
60.1200 381.0000 1.0000
60.1600 378.0000 1.0000
60.2000 376.0000 1.0000
60.2400 335.0000 1.0000
60.2800 344.0000 1.0000
60.3200 356.0000 1.0000
60.3600 411.0000 1.0000
60.4000 380.0000 1.0000
60.4400 345.0000 1.0000
60.4800 378.0000 1.0000
60.5200 374.0000 1.0000
60.5600 365.0000 1.0000
60.6000 351.0000 1.0000
60.6400 362.0000 1.0000
60.6800 365.0000 1.0000
60.7200 364.0000 1.0000
60.7600 371.0000 1.0000
60.8000 361.0000 1.0000
60.8400 370.0000 1.0000
60.8800 356.0000 1.0000
60.9200 376.0000 1.0000
60.9600 378.0000 1.0000
61.0000 390.0000 1.0000
61.0400 368.0000 1.0000
61.0800 384.0000 1.0000
61.1200 389.0000 1.0000
61.1600 410.0000 1.0000
61.2000 406.0000 1.0000
61.2400 476.0000 1.0000
61.2800 498.0000 1.0000
61.3200 492.0000 1.0000
61.3600 616.0000 1.0000
61.4000 648.0000 1.0000
61.4400 712.0000 1.0000
61.4800 719.0000 1.0000
61.5200 740.0000 1.0000
61.5600 737.0000 1.0000
61.6000 699.0000 1.0000
61.6400 666.0000 1.0000
61.6800 686.0000 1.0000
61.7200 573.0000 1.0000
61.7600 524.0000 1.0000
61.8000 488.0000 1.0000
61.8400 477.0000 1.0000
61.8800 446.0000 1.0000
61.9200 418.0000 1.0000
61.9600 420.0000 1.0000
62.0000 427.0000 1.0000
62.0400 391.0000 1.0000
62.0800 407.0000 1.0000
62.1200 386.0000 1.0000
62.1600 373.0000 1.0000
62.2000 415.0000 1.0000
62.2400 390.0000 1.0000
62.2800 421.0000 1.0000
62.3200 394.0000 1.0000
62.3600 418.0000 1.0000
62.4000 398.0000 1.0000
62.4400 426.0000 1.0000
62.4800 390.0000 1.0000
62.5200 409.0000 1.0000
62.5600 367.0000 1.0000
62.6000 417.0000 1.0000
62.6400 367.0000 1.0000
62.6800 379.0000 1.0000
62.7200 397.0000 1.0000
62.7600 361.0000 1.0000
62.8000 362.0000 1.0000
62.8400 372.0000 1.0000
62.8800 387.0000 1.0000
62.9200 386.0000 1.0000
62.9600 355.0000 1.0000
63.0000 339.0000 1.0000
63.0400 364.0000 1.0000
63.0800 356.0000 1.0000
63.1200 385.0000 1.0000
63.1600 397.0000 1.0000
63.2000 368.0000 1.0000
63.2400 385.0000 1.0000
63.2800 373.0000 1.0000
63.3200 355.0000 1.0000
63.3600 367.0000 1.0000
63.4000 376.0000 1.0000
63.4400 379.0000 1.0000
63.4800 398.0000 1.0000
63.5200 402.0000 1.0000
63.5600 372.0000 1.0000
63.6000 365.0000 1.0000
63.6400 347.0000 1.0000
63.6800 395.0000 1.0000
63.7200 388.0000 1.0000
63.7600 416.0000 1.0000
63.8000 462.0000 1.0000
63.8400 527.0000 1.0000
63.8800 606.0000 1.0000
63.9200 623.0000 1.0000
63.9600 578.0000 1.0000
64.0000 485.0000 1.0000
64.0400 508.0000 1.0000
64.0800 546.0000 1.0000
64.1200 495.0000 1.0000
64.1600 453.0000 1.0000
64.2000 439.0000 1.0000
64.2400 411.0000 1.0000
64.2800 386.0000 1.0000
64.3200 372.0000 1.0000
64.3600 340.0000 1.0000
64.4000 346.0000 1.0000
64.4400 377.0000 1.0000
64.4800 398.0000 1.0000
64.5200 380.0000 1.0000
64.5600 354.0000 1.0000
64.6000 368.0000 1.0000
64.6400 367.0000 1.0000
64.6800 359.0000 1.0000
64.7200 371.0000 1.0000
64.7600 373.0000 1.0000
64.8000 400.0000 1.0000
64.8400 399.0000 1.0000
64.8800 375.0000 1.0000
64.9200 382.0000 1.0000
64.9600 397.0000 1.0000
65.0000 386.0000 1.0000
65.0400 409.0000 1.0000
65.0800 401.0000 1.0000
65.1200 418.0000 1.0000
65.1600 510.0000 1.0000
65.2000 512.0000 1.0000
65.2400 552.0000 1.0000
65.2800 568.0000 1.0000
65.3200 700.0000 1.0000
65.3600 816.0000 1.0000
65.4000 976.0000 1.0000
65.4400 1167.0000 1.0000
65.4800 1298.0000 1.0000
65.5200 1364.0000 1.0000
65.5600 1329.0000 1.0000
65.6000 1150.0000 1.0000
65.6400 1077.0000 1.0000
65.6800 1084.0000 1.0000
65.7200 897.0000 1.0000
65.7600 804.0000 1.0000
65.8000 655.0000 1.0000
65.8400 621.0000 1.0000
65.8800 510.0000 1.0000
65.9200 476.0000 1.0000
65.9600 425.0000 1.0000
66.0000 453.0000 1.0000
66.0400 446.0000 1.0000
66.0800 416.0000 1.0000
66.1200 398.0000 1.0000
66.1600 352.0000 1.0000
66.2000 387.0000 1.0000
66.2400 395.0000 1.0000
66.2800 358.0000 1.0000
66.3200 339.0000 1.0000
66.3600 385.0000 1.0000
66.4000 356.0000 1.0000
66.4400 323.0000 1.0000
66.4800 353.0000 1.0000
66.5200 346.0000 1.0000
66.5600 330.0000 1.0000
66.6000 320.0000 1.0000
66.6400 321.0000 1.0000
66.6800 331.0000 1.0000
66.7200 335.0000 1.0000
66.7600 357.0000 1.0000
66.8000 342.0000 1.0000
66.8400 352.0000 1.0000
66.8800 313.0000 1.0000
66.9200 345.0000 1.0000
66.9600 357.0000 1.0000
67.0000 329.0000 1.0000
67.0400 348.0000 1.0000
67.0800 358.0000 1.0000
67.1200 385.0000 1.0000
67.1600 349.0000 1.0000
67.2000 337.0000 1.0000
67.2400 339.0000 1.0000
67.2800 333.0000 1.0000
67.3200 340.0000 1.0000
67.3600 337.0000 1.0000
67.4000 328.0000 1.0000
67.4400 304.0000 1.0000
67.4800 310.0000 1.0000
67.5200 337.0000 1.0000
67.5600 324.0000 1.0000
67.6000 343.0000 1.0000
67.6400 331.0000 1.0000
67.6800 339.0000 1.0000
67.7200 350.0000 1.0000
67.7600 307.0000 1.0000
67.8000 299.0000 1.0000
67.8400 320.0000 1.0000
67.8800 379.0000 1.0000
67.9200 349.0000 1.0000
67.9600 347.0000 1.0000
68.0000 330.0000 1.0000
68.0400 329.0000 1.0000
68.0800 341.0000 1.0000
68.1200 339.0000 1.0000
68.1600 314.0000 1.0000
68.2000 313.0000 1.0000
68.2400 340.0000 1.0000
68.2800 311.0000 1.0000
68.3200 321.0000 1.0000
68.3600 298.0000 1.0000
68.4000 335.0000 1.0000
68.4400 326.0000 1.0000
68.4800 336.0000 1.0000
68.5200 308.0000 1.0000
68.5600 335.0000 1.0000
68.6000 301.0000 1.0000
68.6400 328.0000 1.0000
68.6800 299.0000 1.0000
68.7200 325.0000 1.0000
68.7600 327.0000 1.0000
68.8000 331.0000 1.0000
68.8400 323.0000 1.0000
68.8800 334.0000 1.0000
68.9200 340.0000 1.0000
68.9600 323.0000 1.0000
69.0000 339.0000 1.0000
69.0400 322.0000 1.0000
69.0800 293.0000 1.0000
69.1200 305.0000 1.0000
69.1600 314.0000 1.0000
69.2000 333.0000 1.0000
69.2400 334.0000 1.0000
69.2800 310.0000 1.0000
69.3200 327.0000 1.0000
69.3600 335.0000 1.0000
69.4000 298.0000 1.0000
69.4400 307.0000 1.0000
69.4800 330.0000 1.0000
69.5200 325.0000 1.0000
69.5600 304.0000 1.0000
69.6000 318.0000 1.0000
69.6400 352.0000 1.0000
69.6800 318.0000 1.0000
69.7200 316.0000 1.0000
69.7600 292.0000 1.0000
69.8000 328.0000 1.0000
69.8400 304.0000 1.0000
69.8800 272.0000 1.0000
69.9200 308.0000 1.0000
69.9600 295.0000 1.0000
70.0000 302.0000 1.0000
*RAS_INT_END
*RAS_TEMPERATURE_START
*RAS_TEMPERATURE_END
*RAS_DATA_END