File: Data/Dataset1_Only_water/5_XRD/No_024_VS2_3.ras
*RAS_DATA_START
*RAS_HEADER_START
*DISP_FMT_X "%.2f"
*DISP_FMT_Y "%.0f"
*DISP_FULLSCALE "16584.0000000000"
*DISP_LINE_COLOR "255.0000000000"
*DISP_LINE_STYLE "0.0000000000"
*DISP_LINE_WIDTH "0.2500000000"
*DISP_NOTE "測定データ-3"
*DISP_OFFSET_Y "0.0000000000"
*DISP_PEAKSEARCH_UNIT_Y "cps"
*DISP_RANGE_BOTTOM "0.0000000000"
*DISP_RANGE_LEFT "20.0000000000"
*DISP_RANGE_LOGCUTOFF "0.0100000000"
*DISP_RANGE_RIGHT "70.0000000000"
*DISP_RANGE_TOP "16584.0000000000"
*DISP_SCALE_MODE_Y "0.0000000000"
*DISP_TAB_NAME "2θ/θ"
*DISP_TITLE_Y "強度"
*DISP_UNIT_Y "cps"
*DISP_WINDOW_NAME "MSG_MACROENGINE"
*FILE_COMMENT " "
*FILE_MD5 ""
*FILE_MEMO " "
*FILE_OPERATOR "Administrator"
*FILE_SAMPLE " "
*FILE_TYPE "RAS_RAW"
*FILE_USERGROUP "システムマネージャ"
*FILE_VERSION "1.0000000000"
*HW_ATTACHMENT_ID "ATT0025"
*HW_ATTACHMENT_NAME "標準|Standard"
*HW_COUNTER_ID-0 "CUT0025"
*HW_COUNTER_ID-1 "CUT0020"
*HW_COUNTER_ID-2 "CUT0020"
*HW_COUNTER_ID-3 "CSL0021"
*HW_COUNTER_ID-4 "CMC0021"
*HW_COUNTER_NAME-0 "D/teX Ultra|D/teX Ultra"
*HW_COUNTER_NAME-1 "None|None"
*HW_COUNTER_NAME-2 "None|None"
*HW_COUNTER_NAME-3 "BBM|BBM"
*HW_COUNTER_NAME-4 "検出器モノクロメータ|Detector monochromator"
*HW_COUNTER_SELECT_NAME "D/teX Ultra|D/teX Ultra"
*HW_GONIOMETER_ID "GON0023"
*HW_GONIOMETER_NAME "SmartLab|SmartLab"
*HW_GONIOMETER_RADIUS-0 "90.0"
*HW_GONIOMETER_RADIUS-1 "114.0"
*HW_GONIOMETER_RADIUS-2 "190.0"
*HW_GONIOMETER_RADIUS-3 "300.0"
*HW_GONIOMETER_RADIUS-4 "187.0"
*HW_GONIOMETER_RADIUS-5 "300.0"
*HW_GONIOMETER_RADIUS-6 "113.0"
*HW_GONIOMETER_RADIUS-7 "331.0"
*HW_I_OPT_ID-0 "CBO0021"
*HW_I_OPT_ID-1 "ICR0023"
*HW_I_OPT_ID-2 "ISL0021"
*HW_I_OPT_ID-3 "ISO0021"
*HW_I_OPT_ID-4 "IAD0021"
*HW_I_OPT_ID-5 "IPR0001"
*HW_I_OPT_NAME-0 "CBOユニット|CBO unit"
*HW_I_OPT_NAME-1 "標準入射光学ユニット|Standard incident optical unit"
*HW_I_OPT_NAME-2 "標準入射スリットボックス|Standard incident slit box"
*HW_I_OPT_NAME-3 "入射平行スリット|Incident parallel slit"
*HW_I_OPT_NAME-4 "長手制限スリット|Length limiting slit"
*HW_I_OPT_NAME-5 "None|None"
*HW_R_ATTENUATER_AUTOMODE "0"
*HW_R_OPT_ID-0 "RSS0021"
*HW_R_OPT_ID-1 "RCR0023"
*HW_R_OPT_ID-2 "RSO0021"
*HW_R_OPT_ID-3 "RRS0021"
*HW_R_OPT_ID-4 "ATN0021"
*HW_R_OPT_ID-5 "RFL0021"
*HW_R_OPT_ID-6 "RAD0021"
*HW_R_OPT_NAME-0 "標準受光スリットボックス1|Standard receiving slit box # 1"
*HW_R_OPT_NAME-1 "標準受光光学ユニット1|Standard receiving unit # 1"
*HW_R_OPT_NAME-2 "標準受光光学ユニット2|Standard receiving optical unit # 2"
*HW_R_OPT_NAME-3 "標準受光スリットボックス2|Standard receiving slit box # 2"
*HW_R_OPT_NAME-4 "標準アッテネータ|Standard Attenuator"
*HW_R_OPT_NAME-5 "Cu Kβ|Cu K-beta"
*HW_R_OPT_NAME-6 "調整用受光スリット|Alignment receiving slit"
*HW_SAMPLE_HOLDER_ID "SMP0023"
*HW_SAMPLE_HOLDER_NAME "標準Zステージ|Standard Z stage"
*HW_XG_CURRENT_MAX "50"
*HW_XG_CURRENT_MIN "2"
*HW_XG_CURRENT_RESOLUTION "1"
*HW_XG_CURRENT_UNIT "mA"
*HW_XG_FOCUS "1mm x 10mm"
*HW_XG_FOCUS_TYPE "Normal"
*HW_XG_ID ""
*HW_XG_NAME "3kW 封入管(ID:1200)|3kW Sealed tube(ID:1200)"
*HW_XG_TARGET_ATOMIC_NUMBER "29.0000000000"
*HW_XG_TARGET_NAME "Cu"
*HW_XG_TYPE "Hermetic"
*HW_XG_VOLTAGE_MAX "60"
*HW_XG_VOLTAGE_MIN "20"
*HW_XG_VOLTAGE_RESOLUTION "1"
*HW_XG_VOLTAGE_UNIT "kV"
*HW_XG_WATT_MAX "1.500"
*HW_XG_WATT_UNIT "kW"
*HW_XG_WAVE_LENGTH_ALPHA1 "1.540593"
*HW_XG_WAVE_LENGTH_ALPHA2 "1.544414"
*HW_XG_WAVE_LENGTH_BETA "1.392250"
*MEAS_COND_AXIS_NAME-0 "2θ/θ"
*MEAS_COND_AXIS_NAME-1 "2θ"
*MEAS_COND_AXIS_NAME-2 "ω"
*MEAS_COND_AXIS_NAME-3 "Z"
*MEAS_COND_AXIS_NAME-4 "2θ/ω"
*MEAS_COND_AXIS_NAME-5 "θs"
*MEAS_COND_AXIS_NAME-6 "θd"
*MEAS_COND_AXIS_NAME-7 "Ts"
*MEAS_COND_AXIS_NAME-8 "CBO選択スリット"
*MEAS_COND_AXIS_NAME-9 "M"
*MEAS_COND_AXIS_NAME-10 "入射平行スリット"
*MEAS_COND_AXIS_NAME-11 "入射スリット"
*MEAS_COND_AXIS_NAME-12 ""
*MEAS_COND_AXIS_NAME-13 "Zs"
*MEAS_COND_AXIS_NAME-14 "入射光学素子"
*MEAS_COND_AXIS_NAME-15 "長手制限スリット"
*MEAS_COND_AXIS_NAME-16 "センタースリット"
*MEAS_COND_AXIS_NAME-17 "フィルター"
*MEAS_COND_AXIS_NAME-18 "受光スリット1"
*MEAS_COND_AXIS_NAME-19 "受光スリット2"
*MEAS_COND_AXIS_NAME-20 "受光光学素子"
*MEAS_COND_AXIS_NAME-21 "受光平行スリット"
*MEAS_COND_AXIS_NAME-22 "調整用受光スリット"
*MEAS_COND_AXIS_NAME-23 ""
*MEAS_COND_AXIS_NAME-24 ""
*MEAS_COND_AXIS_NAME-25 "Zd"
*MEAS_COND_AXIS_NAME-26 "アッテネータ"
*MEAS_COND_AXIS_NAME-27 "検出器モノクロメータ"
*MEAS_COND_AXIS_NAME-28 "モノクロメータスリット"
*MEAS_COND_AXIS_NAME-29 "プライマリビーム"
*MEAS_COND_AXIS_NAME-30 "PHA"
*MEAS_COND_AXIS_NAME_INTERNAL-0 "TwoThetaTheta"
*MEAS_COND_AXIS_NAME_INTERNAL-1 "TwoTheta"
*MEAS_COND_AXIS_NAME_INTERNAL-2 "Omega"
*MEAS_COND_AXIS_NAME_INTERNAL-3 "Z"
*MEAS_COND_AXIS_NAME_INTERNAL-4 "TwoThetaOmega"
*MEAS_COND_AXIS_NAME_INTERNAL-5 "ThetaS"
*MEAS_COND_AXIS_NAME_INTERNAL-6 "ThetaD"
*MEAS_COND_AXIS_NAME_INTERNAL-7 "Ts"
*MEAS_COND_AXIS_NAME_INTERNAL-8 "CBO"
*MEAS_COND_AXIS_NAME_INTERNAL-9 "CBO-M"
*MEAS_COND_AXIS_NAME_INTERNAL-10 "IncidentSollerSlit"
*MEAS_COND_AXIS_NAME_INTERNAL-11 "IncidentSlitBox"
*MEAS_COND_AXIS_NAME_INTERNAL-12 "IncidentSlitBox-_Axis"
*MEAS_COND_AXIS_NAME_INTERNAL-13 "Zs"
*MEAS_COND_AXIS_NAME_INTERNAL-14 "IncidentMonochromator"
*MEAS_COND_AXIS_NAME_INTERNAL-15 "IncidentAxdSlit"
*MEAS_COND_AXIS_NAME_INTERNAL-16 "CenterSlit"
*MEAS_COND_AXIS_NAME_INTERNAL-17 "Filter"
*MEAS_COND_AXIS_NAME_INTERNAL-18 "ReceivingSlitBox1"
*MEAS_COND_AXIS_NAME_INTERNAL-19 "ReceivingSlitBox2"
*MEAS_COND_AXIS_NAME_INTERNAL-20 "ReceivingOptics"
*MEAS_COND_AXIS_NAME_INTERNAL-21 "ReceivingSollerSlit"
*MEAS_COND_AXIS_NAME_INTERNAL-22 "ReceivingAxdSlit"
*MEAS_COND_AXIS_NAME_INTERNAL-23 "ReceivingSlitBox1-_Axis"
*MEAS_COND_AXIS_NAME_INTERNAL-24 "ReceivingSlitBox2-_Axis"
*MEAS_COND_AXIS_NAME_INTERNAL-25 "ReceivingSlitBox2-Zd"
*MEAS_COND_AXIS_NAME_INTERNAL-26 "Attenuator"
*MEAS_COND_AXIS_NAME_INTERNAL-27 "CounterMonochromator"
*MEAS_COND_AXIS_NAME_INTERNAL-28 "CounterSlit"
*MEAS_COND_AXIS_NAME_INTERNAL-29 "IncidentPrimary"
*MEAS_COND_AXIS_NAME_INTERNAL-30 "PHA"
*MEAS_COND_AXIS_NAME_MAGICNO-0 "83951616.0000000000"
*MEAS_COND_AXIS_NAME_MAGICNO-1 "268632064.0000000000"
*MEAS_COND_AXIS_NAME_MAGICNO-2 "268500992.0000000000"
*MEAS_COND_AXIS_NAME_MAGICNO-3 "285278208.0000000000"
*MEAS_COND_AXIS_NAME_MAGICNO-4 "83951616.0000000000"
*MEAS_COND_AXIS_NAME_MAGICNO-5 "131072.0000000000"
*MEAS_COND_AXIS_NAME_MAGICNO-6 "131072.0000000000"
*MEAS_COND_AXIS_NAME_MAGICNO-7 "318898176.0000000000"
*MEAS_COND_AXIS_NAME_MAGICNO-8 "20971521.0000000000"
*MEAS_COND_AXIS_NAME_MAGICNO-9 "285343744.0000000000"
*MEAS_COND_AXIS_NAME_MAGICNO-10 "20971521.0000000000"
*MEAS_COND_AXIS_NAME_MAGICNO-11 "22020097.0000000000"
*MEAS_COND_AXIS_NAME_MAGICNO-12 "25165824.0000000000"
*MEAS_COND_AXIS_NAME_MAGICNO-13 "318898176.0000000000"
*MEAS_COND_AXIS_NAME_MAGICNO-14 "1.0000000000"
*MEAS_COND_AXIS_NAME_MAGICNO-15 "20971521.0000000000"
*MEAS_COND_AXIS_NAME_MAGICNO-16 "20971521.0000000000"
*MEAS_COND_AXIS_NAME_MAGICNO-17 "20971521.0000000000"
*MEAS_COND_AXIS_NAME_MAGICNO-18 "23068673.0000000000"
*MEAS_COND_AXIS_NAME_MAGICNO-19 "23068673.0000000000"
*MEAS_COND_AXIS_NAME_MAGICNO-20 "20971521.0000000000"
*MEAS_COND_AXIS_NAME_MAGICNO-21 "20971521.0000000000"
*MEAS_COND_AXIS_NAME_MAGICNO-22 "20971521.0000000000"
*MEAS_COND_AXIS_NAME_MAGICNO-23 "25165824.0000000000"
*MEAS_COND_AXIS_NAME_MAGICNO-24 "25165824.0000000000"
*MEAS_COND_AXIS_NAME_MAGICNO-25 "285343744.0000000000"
*MEAS_COND_AXIS_NAME_MAGICNO-26 "17301505.0000000000"
*MEAS_COND_AXIS_NAME_MAGICNO-27 "20971521.0000000000"
*MEAS_COND_AXIS_NAME_MAGICNO-28 "20971521.0000000000"
*MEAS_COND_AXIS_NAME_MAGICNO-29 "20971521.0000000000"
*MEAS_COND_AXIS_NAME_MAGICNO-30 "0.0000000000"
*MEAS_COND_AXIS_OFFSET-0 "-"
*MEAS_COND_AXIS_OFFSET-1 "-0.1081000000"
*MEAS_COND_AXIS_OFFSET-2 "0.3758000000"
*MEAS_COND_AXIS_OFFSET-3 "-"
*MEAS_COND_AXIS_OFFSET-4 "-"
*MEAS_COND_AXIS_OFFSET-5 "0.3758000000"
*MEAS_COND_AXIS_OFFSET-6 "-0.4839000000"
*MEAS_COND_AXIS_OFFSET-7 "-"
*MEAS_COND_AXIS_OFFSET-8 "-"
*MEAS_COND_AXIS_OFFSET-9 "-"
*MEAS_COND_AXIS_OFFSET-10 "-"
*MEAS_COND_AXIS_OFFSET-11 "-"
*MEAS_COND_AXIS_OFFSET-12 "-"
*MEAS_COND_AXIS_OFFSET-13 "-"
*MEAS_COND_AXIS_OFFSET-14 "-"
*MEAS_COND_AXIS_OFFSET-15 "-"
*MEAS_COND_AXIS_OFFSET-16 "-"
*MEAS_COND_AXIS_OFFSET-17 "-"
*MEAS_COND_AXIS_OFFSET-18 "-"
*MEAS_COND_AXIS_OFFSET-19 "-"
*MEAS_COND_AXIS_OFFSET-20 "-"
*MEAS_COND_AXIS_OFFSET-21 "-"
*MEAS_COND_AXIS_OFFSET-22 "-"
*MEAS_COND_AXIS_OFFSET-23 "-"
*MEAS_COND_AXIS_OFFSET-24 "-"
*MEAS_COND_AXIS_OFFSET-25 "-"
*MEAS_COND_AXIS_OFFSET-26 "-"
*MEAS_COND_AXIS_OFFSET-27 "-"
*MEAS_COND_AXIS_OFFSET-28 "-"
*MEAS_COND_AXIS_OFFSET-29 "-"
*MEAS_COND_AXIS_OFFSET-30 "-"
*MEAS_COND_AXIS_POSITION-0 "0.0000000000"
*MEAS_COND_AXIS_POSITION-1 "0.0000000000"
*MEAS_COND_AXIS_POSITION-2 "0.0000000000"
*MEAS_COND_AXIS_POSITION-3 "-0.5500000000"
*MEAS_COND_AXIS_POSITION-4 "0.0000000000"
*MEAS_COND_AXIS_POSITION-5 "0.0000000000"
*MEAS_COND_AXIS_POSITION-6 "0.0000000000"
*MEAS_COND_AXIS_POSITION-7 "-0.4278800000"
*MEAS_COND_AXIS_POSITION-8 "BB"
*MEAS_COND_AXIS_POSITION-9 "0.0000000000"
*MEAS_COND_AXIS_POSITION-10 "Soller_slit_5.0deg"
*MEAS_COND_AXIS_POSITION-11 "2/3deg"
*MEAS_COND_AXIS_POSITION-12 "2.2088000000"
*MEAS_COND_AXIS_POSITION-13 "-0.4140600000"
*MEAS_COND_AXIS_POSITION-14 "0.0000000000"
*MEAS_COND_AXIS_POSITION-15 "10.0mm"
*MEAS_COND_AXIS_POSITION-16 "None"
*MEAS_COND_AXIS_POSITION-17 "Cu_K-beta"
*MEAS_COND_AXIS_POSITION-18 "13.000mm"
*MEAS_COND_AXIS_POSITION-19 "13.000mm"
*MEAS_COND_AXIS_POSITION-20 "No_unit"
*MEAS_COND_AXIS_POSITION-21 "Soller_slit_5.0deg"
*MEAS_COND_AXIS_POSITION-22 "None"
*MEAS_COND_AXIS_POSITION-23 "13.0000000000"
*MEAS_COND_AXIS_POSITION-24 "13.0000000000"
*MEAS_COND_AXIS_POSITION-25 "0.0109400000"
*MEAS_COND_AXIS_POSITION-26 "Open"
*MEAS_COND_AXIS_POSITION-27 "None"
*MEAS_COND_AXIS_POSITION-28 "None"
*MEAS_COND_AXIS_POSITION-29 "None"
*MEAS_COND_AXIS_POSITION-30 "38.0000000000"
*MEAS_COND_AXIS_UNIT-0 "deg"
*MEAS_COND_AXIS_UNIT-1 "deg"
*MEAS_COND_AXIS_UNIT-2 "deg"
*MEAS_COND_AXIS_UNIT-3 "mm"
*MEAS_COND_AXIS_UNIT-4 "deg"
*MEAS_COND_AXIS_UNIT-5 "deg"
*MEAS_COND_AXIS_UNIT-6 "deg"
*MEAS_COND_AXIS_UNIT-7 "mm"
*MEAS_COND_AXIS_UNIT-8 ""
*MEAS_COND_AXIS_UNIT-9 "pulse"
*MEAS_COND_AXIS_UNIT-10 ""
*MEAS_COND_AXIS_UNIT-11 ""
*MEAS_COND_AXIS_UNIT-12 "mm"
*MEAS_COND_AXIS_UNIT-13 "mm"
*MEAS_COND_AXIS_UNIT-14 ""
*MEAS_COND_AXIS_UNIT-15 ""
*MEAS_COND_AXIS_UNIT-16 ""
*MEAS_COND_AXIS_UNIT-17 ""
*MEAS_COND_AXIS_UNIT-18 ""
*MEAS_COND_AXIS_UNIT-19 ""
*MEAS_COND_AXIS_UNIT-20 ""
*MEAS_COND_AXIS_UNIT-21 ""
*MEAS_COND_AXIS_UNIT-22 ""
*MEAS_COND_AXIS_UNIT-23 "mm"
*MEAS_COND_AXIS_UNIT-24 "mm"
*MEAS_COND_AXIS_UNIT-25 "mm"
*MEAS_COND_AXIS_UNIT-26 ""
*MEAS_COND_AXIS_UNIT-27 ""
*MEAS_COND_AXIS_UNIT-28 ""
*MEAS_COND_AXIS_UNIT-29 ""
*MEAS_COND_AXIS_UNIT-30 "div"
*MEAS_COND_COUNTER_CNTLOSS_CORR "0.0000000000"
*MEAS_COND_COUNTER_PHABASE "38.0000000000"
*MEAS_COND_COUNTER_PHAWINDOW "16.0000000000"
*MEAS_COND_COUNTER_PHA_UNIT "div"
*MEAS_COND_COUNTER_TAUDIFF "30.0000000000"
*MEAS_COND_COUNTER_TAUINT "0.0000000000"
*MEAS_COND_IRRADIATION_MODE "OFF"
*MEAS_COND_IRRADIATION_WIDTH ""
*MEAS_COND_OPT_ATTR "集中法"
*MEAS_COND_OPT_NAME "@集中法"
*MEAS_COND_UNSYMMETRIC_MODE "OFF"
*MEAS_COND_XG_CURRENT "30.0000000000"
*MEAS_COND_XG_VOLTAGE "40.0000000000"
*MEAS_COND_XG_WAVE_TYPE "Ka"
*MEAS_DATA_COUNT "5001.0000000000"
*MEAS_SCAN_AXIS_X "2θ/θ"
*MEAS_SCAN_AXIS_X_INTERNAL "TwoThetaTheta"
*MEAS_SCAN_END_TIME "07/20/21 13:09:56"
*MEAS_SCAN_MODE "CONTINUOUS"
*MEAS_SCAN_MONITOR "0"
*MEAS_SCAN_RESOLUTION_X "0.0002"
*MEAS_SCAN_SPEED "1.0"
*MEAS_SCAN_SPEED_UNIT "deg/min"
*MEAS_SCAN_START "20.0000000000"
*MEAS_SCAN_START_TIME "07/20/21 12:17:03"
*MEAS_SCAN_STEP "0.0100000000"
*MEAS_SCAN_STOP "70.0000000000"
*MEAS_SCAN_UNIT_X "deg"
*MEAS_SCAN_UNIT_Y "counts"
*RAS_HEADER_END
*RAS_INT_START
20.0000 1475.0000 1.0000
20.0400 1592.0000 1.0000
20.0800 1606.0000 1.0000
20.1200 1576.0000 1.0000
20.1600 1622.0000 1.0000
20.2000 1653.0000 1.0000
20.2400 1610.0000 1.0000
20.2800 1633.0000 1.0000
20.3200 1571.0000 1.0000
20.3600 1587.0000 1.0000
20.4000 1560.0000 1.0000
20.4400 1600.0000 1.0000
20.4800 1659.0000 1.0000
20.5200 1654.0000 1.0000
20.5600 1574.0000 1.0000
20.6000 1676.0000 1.0000
20.6400 1608.0000 1.0000
20.6800 1605.0000 1.0000
20.7200 1576.0000 1.0000
20.7600 1609.0000 1.0000
20.8000 1619.0000 1.0000
20.8400 1589.0000 1.0000
20.8800 1585.0000 1.0000
20.9200 1617.0000 1.0000
20.9600 1599.0000 1.0000
21.0000 1612.0000 1.0000
21.0400 1595.0000 1.0000
21.0800 1635.0000 1.0000
21.1200 1636.0000 1.0000
21.1600 1608.0000 1.0000
21.2000 1569.0000 1.0000
21.2400 1679.0000 1.0000
21.2800 1590.0000 1.0000
21.3200 1695.0000 1.0000
21.3600 1610.0000 1.0000
21.4000 1671.0000 1.0000
21.4400 1651.0000 1.0000
21.4800 1688.0000 1.0000
21.5200 1603.0000 1.0000
21.5600 1619.0000 1.0000
21.6000 1688.0000 1.0000
21.6400 1649.0000 1.0000
21.6800 1652.0000 1.0000
21.7200 1633.0000 1.0000
21.7600 1642.0000 1.0000
21.8000 1613.0000 1.0000
21.8400 1577.0000 1.0000
21.8800 1608.0000 1.0000
21.9200 1603.0000 1.0000
21.9600 1637.0000 1.0000
22.0000 1675.0000 1.0000
22.0400 1607.0000 1.0000
22.0800 1593.0000 1.0000
22.1200 1634.0000 1.0000
22.1600 1628.0000 1.0000
22.2000 1641.0000 1.0000
22.2400 1628.0000 1.0000
22.2800 1678.0000 1.0000
22.3200 1627.0000 1.0000
22.3600 1596.0000 1.0000
22.4000 1641.0000 1.0000
22.4400 1588.0000 1.0000
22.4800 1641.0000 1.0000
22.5200 1608.0000 1.0000
22.5600 1660.0000 1.0000
22.6000 1680.0000 1.0000
22.6400 1645.0000 1.0000
22.6800 1659.0000 1.0000
22.7200 1645.0000 1.0000
22.7600 1625.0000 1.0000
22.8000 1688.0000 1.0000
22.8400 1694.0000 1.0000
22.8800 1677.0000 1.0000
22.9200 1693.0000 1.0000
22.9600 1661.0000 1.0000
23.0000 1654.0000 1.0000
23.0400 1702.0000 1.0000
23.0800 1715.0000 1.0000
23.1200 1695.0000 1.0000
23.1600 1710.0000 1.0000
23.2000 1723.0000 1.0000
23.2400 1719.0000 1.0000
23.2800 1702.0000 1.0000
23.3200 1698.0000 1.0000
23.3600 1686.0000 1.0000
23.4000 1658.0000 1.0000
23.4400 1683.0000 1.0000
23.4800 1691.0000 1.0000
23.5200 1675.0000 1.0000
23.5600 1639.0000 1.0000
23.6000 1671.0000 1.0000
23.6400 1686.0000 1.0000
23.6800 1653.0000 1.0000
23.7200 1720.0000 1.0000
23.7600 1710.0000 1.0000
23.8000 1691.0000 1.0000
23.8400 1694.0000 1.0000
23.8800 1686.0000 1.0000
23.9200 1637.0000 1.0000
23.9600 1722.0000 1.0000
24.0000 1722.0000 1.0000
24.0400 1696.0000 1.0000
24.0800 1776.0000 1.0000
24.1200 1700.0000 1.0000
24.1600 1674.0000 1.0000
24.2000 1692.0000 1.0000
24.2400 1671.0000 1.0000
24.2800 1678.0000 1.0000
24.3200 1687.0000 1.0000
24.3600 1739.0000 1.0000
24.4000 1690.0000 1.0000
24.4400 1703.0000 1.0000
24.4800 1710.0000 1.0000
24.5200 1773.0000 1.0000
24.5600 1721.0000 1.0000
24.6000 1760.0000 1.0000
24.6400 1760.0000 1.0000
24.6800 1788.0000 1.0000
24.7200 1773.0000 1.0000
24.7600 1835.0000 1.0000
24.8000 1717.0000 1.0000
24.8400 1799.0000 1.0000
24.8800 1762.0000 1.0000
24.9200 1772.0000 1.0000
24.9600 1840.0000 1.0000
25.0000 1826.0000 1.0000
25.0400 1777.0000 1.0000
25.0800 1824.0000 1.0000
25.1200 1766.0000 1.0000
25.1600 1731.0000 1.0000
25.2000 1734.0000 1.0000
25.2400 1783.0000 1.0000
25.2800 1779.0000 1.0000
25.3200 1765.0000 1.0000
25.3600 1866.0000 1.0000
25.4000 1804.0000 1.0000
25.4400 1789.0000 1.0000
25.4800 1771.0000 1.0000
25.5200 1746.0000 1.0000
25.5600 1770.0000 1.0000
25.6000 1811.0000 1.0000
25.6400 1783.0000 1.0000
25.6800 1777.0000 1.0000
25.7200 1821.0000 1.0000
25.7600 1753.0000 1.0000
25.8000 1793.0000 1.0000
25.8400 1755.0000 1.0000
25.8800 1701.0000 1.0000
25.9200 1786.0000 1.0000
25.9600 1859.0000 1.0000
26.0000 1759.0000 1.0000
26.0400 1760.0000 1.0000
26.0800 1763.0000 1.0000
26.1200 1754.0000 1.0000
26.1600 1772.0000 1.0000
26.2000 1784.0000 1.0000
26.2400 1837.0000 1.0000
26.2800 1791.0000 1.0000
26.3200 1842.0000 1.0000
26.3600 1791.0000 1.0000
26.4000 1867.0000 1.0000
26.4400 1896.0000 1.0000
26.4800 1837.0000 1.0000
26.5200 1845.0000 1.0000
26.5600 1858.0000 1.0000
26.6000 1817.0000 1.0000
26.6400 1897.0000 1.0000
26.6800 1912.0000 1.0000
26.7200 1946.0000 1.0000
26.7600 1938.0000 1.0000
26.8000 2044.0000 1.0000
26.8400 2050.0000 1.0000
26.8800 2133.0000 1.0000
26.9200 2241.0000 1.0000
26.9600 2420.0000 1.0000
27.0000 2441.0000 1.0000
27.0400 2797.0000 1.0000
27.0800 3225.0000 1.0000
27.1200 3872.0000 1.0000
27.1600 4650.0000 1.0000
27.2000 5905.0000 1.0000
27.2400 6881.0000 1.0000
27.2800 7478.0000 1.0000
27.3200 6801.0000 1.0000
27.3600 5716.0000 1.0000
27.4000 4554.0000 1.0000
27.4400 3727.0000 1.0000
27.4800 3199.0000 1.0000
27.5200 2757.0000 1.0000
27.5600 2573.0000 1.0000
27.6000 2374.0000 1.0000
27.6400 2241.0000 1.0000
27.6800 2135.0000 1.0000
27.7200 2057.0000 1.0000
27.7600 1991.0000 1.0000
27.8000 1938.0000 1.0000
27.8400 1905.0000 1.0000
27.8800 1870.0000 1.0000
27.9200 1742.0000 1.0000
27.9600 1816.0000 1.0000
28.0000 1760.0000 1.0000
28.0400 1797.0000 1.0000
28.0800 1776.0000 1.0000
28.1200 1777.0000 1.0000
28.1600 1655.0000 1.0000
28.2000 1655.0000 1.0000
28.2400 1710.0000 1.0000
28.2800 1733.0000 1.0000
28.3200 1676.0000 1.0000
28.3600 1657.0000 1.0000
28.4000 1672.0000 1.0000
28.4400 1739.0000 1.0000
28.4800 1688.0000 1.0000
28.5200 1642.0000 1.0000
28.5600 1611.0000 1.0000
28.6000 1599.0000 1.0000
28.6400 1722.0000 1.0000
28.6800 1697.0000 1.0000
28.7200 1578.0000 1.0000
28.7600 1706.0000 1.0000
28.8000 1735.0000 1.0000
28.8400 1646.0000 1.0000
28.8800 1605.0000 1.0000
28.9200 1651.0000 1.0000
28.9600 1657.0000 1.0000
29.0000 1623.0000 1.0000
29.0400 1612.0000 1.0000
29.0800 1569.0000 1.0000
29.1200 1617.0000 1.0000
29.1600 1620.0000 1.0000
29.2000 1632.0000 1.0000
29.2400 1560.0000 1.0000
29.2800 1580.0000 1.0000
29.3200 1591.0000 1.0000
29.3600 1585.0000 1.0000
29.4000 1587.0000 1.0000
29.4400 1630.0000 1.0000
29.4800 1576.0000 1.0000
29.5200 1579.0000 1.0000
29.5600 1562.0000 1.0000
29.6000 1611.0000 1.0000
29.6400 1495.0000 1.0000
29.6800 1531.0000 1.0000
29.7200 1512.0000 1.0000
29.7600 1571.0000 1.0000
29.8000 1490.0000 1.0000
29.8400 1568.0000 1.0000
29.8800 1552.0000 1.0000
29.9200 1640.0000 1.0000
29.9600 1498.0000 1.0000
30.0000 1505.0000 1.0000
30.0400 1603.0000 1.0000
30.0800 1526.0000 1.0000
30.1200 1554.0000 1.0000
30.1600 1535.0000 1.0000
30.2000 1432.0000 1.0000
30.2400 1581.0000 1.0000
30.2800 1493.0000 1.0000
30.3200 1580.0000 1.0000
30.3600 1481.0000 1.0000
30.4000 1519.0000 1.0000
30.4400 1494.0000 1.0000
30.4800 1510.0000 1.0000
30.5200 1467.0000 1.0000
30.5600 1468.0000 1.0000
30.6000 1451.0000 1.0000
30.6400 1476.0000 1.0000
30.6800 1603.0000 1.0000
30.7200 1451.0000 1.0000
30.7600 1538.0000 1.0000
30.8000 1419.0000 1.0000
30.8400 1452.0000 1.0000
30.8800 1474.0000 1.0000
30.9200 1495.0000 1.0000
30.9600 1449.0000 1.0000
31.0000 1517.0000 1.0000
31.0400 1448.0000 1.0000
31.0800 1444.0000 1.0000
31.1200 1543.0000 1.0000
31.1600 1453.0000 1.0000
31.2000 1435.0000 1.0000
31.2400 1417.0000 1.0000
31.2800 1464.0000 1.0000
31.3200 1404.0000 1.0000
31.3600 1493.0000 1.0000
31.4000 1490.0000 1.0000
31.4400 1467.0000 1.0000
31.4800 1419.0000 1.0000
31.5200 1419.0000 1.0000
31.5600 1460.0000 1.0000
31.6000 1404.0000 1.0000
31.6400 1453.0000 1.0000
31.6800 1472.0000 1.0000
31.7200 1431.0000 1.0000
31.7600 1446.0000 1.0000
31.8000 1459.0000 1.0000
31.8400 1430.0000 1.0000
31.8800 1459.0000 1.0000
31.9200 1512.0000 1.0000
31.9600 1483.0000 1.0000
32.0000 1558.0000 1.0000
32.0400 1480.0000 1.0000
32.0800 1422.0000 1.0000
32.1200 1443.0000 1.0000
32.1600 1403.0000 1.0000
32.2000 1371.0000 1.0000
32.2400 1396.0000 1.0000
32.2800 1421.0000 1.0000
32.3200 1465.0000 1.0000
32.3600 1363.0000 1.0000
32.4000 1316.0000 1.0000
32.4400 1367.0000 1.0000
32.4800 1356.0000 1.0000
32.5200 1369.0000 1.0000
32.5600 1427.0000 1.0000
32.6000 1373.0000 1.0000
32.6400 1376.0000 1.0000
32.6800 1390.0000 1.0000
32.7200 1347.0000 1.0000
32.7600 1334.0000 1.0000
32.8000 1402.0000 1.0000
32.8400 1366.0000 1.0000
32.8800 1357.0000 1.0000
32.9200 1421.0000 1.0000
32.9600 1374.0000 1.0000
33.0000 1367.0000 1.0000
33.0400 1361.0000 1.0000
33.0800 1312.0000 1.0000
33.1200 1305.0000 1.0000
33.1600 1328.0000 1.0000
33.2000 1354.0000 1.0000
33.2400 1317.0000 1.0000
33.2800 1345.0000 1.0000
33.3200 1405.0000 1.0000
33.3600 1371.0000 1.0000
33.4000 1346.0000 1.0000
33.4400 1292.0000 1.0000
33.4800 1385.0000 1.0000
33.5200 1347.0000 1.0000
33.5600 1380.0000 1.0000
33.6000 1396.0000 1.0000
33.6400 1380.0000 1.0000
33.6800 1374.0000 1.0000
33.7200 1418.0000 1.0000
33.7600 1446.0000 1.0000
33.8000 1381.0000 1.0000
33.8400 1530.0000 1.0000
33.8800 1502.0000 1.0000
33.9200 1534.0000 1.0000
33.9600 1498.0000 1.0000
34.0000 1593.0000 1.0000
34.0400 1546.0000 1.0000
34.0800 1519.0000 1.0000
34.1200 1575.0000 1.0000
34.1600 1585.0000 1.0000
34.2000 1646.0000 1.0000
34.2400 1752.0000 1.0000
34.2800 1835.0000 1.0000
34.3200 2031.0000 1.0000
34.3600 2406.0000 1.0000
34.4000 2709.0000 1.0000
34.4400 3027.0000 1.0000
34.4800 3033.0000 1.0000
34.5200 2894.0000 1.0000
34.5600 2636.0000 1.0000
34.6000 2273.0000 1.0000
34.6400 2021.0000 1.0000
34.6800 1836.0000 1.0000
34.7200 1617.0000 1.0000
34.7600 1623.0000 1.0000
34.8000 1522.0000 1.0000
34.8400 1486.0000 1.0000
34.8800 1423.0000 1.0000
34.9200 1386.0000 1.0000
34.9600 1340.0000 1.0000
35.0000 1350.0000 1.0000
35.0400 1338.0000 1.0000
35.0800 1248.0000 1.0000
35.1200 1290.0000 1.0000
35.1600 1213.0000 1.0000
35.2000 1245.0000 1.0000
35.2400 1223.0000 1.0000
35.2800 1195.0000 1.0000
35.3200 1201.0000 1.0000
35.3600 1185.0000 1.0000
35.4000 1219.0000 1.0000
35.4400 1175.0000 1.0000
35.4800 1128.0000 1.0000
35.5200 1193.0000 1.0000
35.5600 1145.0000 1.0000
35.6000 1154.0000 1.0000
35.6400 1197.0000 1.0000
35.6800 1141.0000 1.0000
35.7200 1104.0000 1.0000
35.7600 1120.0000 1.0000
35.8000 1189.0000 1.0000
35.8400 1139.0000 1.0000
35.8800 1102.0000 1.0000
35.9200 1117.0000 1.0000
35.9600 1120.0000 1.0000
36.0000 1219.0000 1.0000
36.0400 1121.0000 1.0000
36.0800 1184.0000 1.0000
36.1200 1242.0000 1.0000
36.1600 1206.0000 1.0000
36.2000 1280.0000 1.0000
36.2400 1263.0000 1.0000
36.2800 1495.0000 1.0000
36.3200 1499.0000 1.0000
36.3600 1563.0000 1.0000
36.4000 1604.0000 1.0000
36.4400 1565.0000 1.0000
36.4800 1434.0000 1.0000
36.5200 1370.0000 1.0000
36.5600 1245.0000 1.0000
36.6000 1194.0000 1.0000
36.6400 1158.0000 1.0000
36.6800 1154.0000 1.0000
36.7200 1083.0000 1.0000
36.7600 1127.0000 1.0000
36.8000 1133.0000 1.0000
36.8400 1044.0000 1.0000
36.8800 1080.0000 1.0000
36.9200 1028.0000 1.0000
36.9600 1121.0000 1.0000
37.0000 1020.0000 1.0000
37.0400 1087.0000 1.0000
37.0800 1044.0000 1.0000
37.1200 1040.0000 1.0000
37.1600 1027.0000 1.0000
37.2000 1066.0000 1.0000
37.2400 1126.0000 1.0000
37.2800 1051.0000 1.0000
37.3200 1016.0000 1.0000
37.3600 1055.0000 1.0000
37.4000 1067.0000 1.0000
37.4400 1076.0000 1.0000
37.4800 1059.0000 1.0000
37.5200 1084.0000 1.0000
37.5600 1067.0000 1.0000
37.6000 1092.0000 1.0000
37.6400 1090.0000 1.0000
37.6800 1089.0000 1.0000
37.7200 1035.0000 1.0000
37.7600 1166.0000 1.0000
37.8000 1100.0000 1.0000
37.8400 1077.0000 1.0000
37.8800 1152.0000 1.0000
37.9200 1127.0000 1.0000
37.9600 1173.0000 1.0000
38.0000 1161.0000 1.0000
38.0400 1247.0000 1.0000
38.0800 1301.0000 1.0000
38.1200 1384.0000 1.0000
38.1600 1475.0000 1.0000
38.2000 1716.0000 1.0000
38.2400 1958.0000 1.0000
38.2800 2285.0000 1.0000
38.3200 2820.0000 1.0000
38.3600 3568.0000 1.0000
38.4000 4824.0000 1.0000
38.4400 6508.0000 1.0000
38.4800 7802.0000 1.0000
38.5200 8170.0000 1.0000
38.5600 7440.0000 1.0000
38.6000 6469.0000 1.0000
38.6400 5182.0000 1.0000
38.6800 3826.0000 1.0000
38.7200 2910.0000 1.0000
38.7600 2333.0000 1.0000
38.8000 1834.0000 1.0000
38.8400 1621.0000 1.0000
38.8800 1420.0000 1.0000
38.9200 1339.0000 1.0000
38.9600 1211.0000 1.0000
39.0000 1212.0000 1.0000
39.0400 1106.0000 1.0000
39.0800 1042.0000 1.0000
39.1200 1095.0000 1.0000
39.1600 990.0000 1.0000
39.2000 1023.0000 1.0000
39.2400 1023.0000 1.0000
39.2800 999.0000 1.0000
39.3200 932.0000 1.0000
39.3600 992.0000 1.0000
39.4000 971.0000 1.0000
39.4400 993.0000 1.0000
39.4800 1005.0000 1.0000
39.5200 1029.0000 1.0000
39.5600 1068.0000 1.0000
39.6000 981.0000 1.0000
39.6400 1004.0000 1.0000
39.6800 980.0000 1.0000
39.7200 972.0000 1.0000
39.7600 980.0000 1.0000
39.8000 984.0000 1.0000
39.8400 865.0000 1.0000
39.8800 949.0000 1.0000
39.9200 943.0000 1.0000
39.9600 895.0000 1.0000
40.0000 919.0000 1.0000
40.0400 908.0000 1.0000
40.0800 923.0000 1.0000
40.1200 890.0000 1.0000
40.1600 900.0000 1.0000
40.2000 842.0000 1.0000
40.2400 876.0000 1.0000
40.2800 905.0000 1.0000
40.3200 910.0000 1.0000
40.3600 863.0000 1.0000
40.4000 883.0000 1.0000
40.4400 895.0000 1.0000
40.4800 857.0000 1.0000
40.5200 863.0000 1.0000
40.5600 887.0000 1.0000
40.6000 866.0000 1.0000
40.6400 900.0000 1.0000
40.6800 852.0000 1.0000
40.7200 877.0000 1.0000
40.7600 847.0000 1.0000
40.8000 855.0000 1.0000
40.8400 823.0000 1.0000
40.8800 897.0000 1.0000
40.9200 917.0000 1.0000
40.9600 881.0000 1.0000
41.0000 880.0000 1.0000
41.0400 885.0000 1.0000
41.0800 839.0000 1.0000
41.1200 875.0000 1.0000
41.1600 913.0000 1.0000
41.2000 893.0000 1.0000
41.2400 853.0000 1.0000
41.2800 866.0000 1.0000
41.3200 885.0000 1.0000
41.3600 818.0000 1.0000
41.4000 923.0000 1.0000
41.4400 864.0000 1.0000
41.4800 883.0000 1.0000
41.5200 876.0000 1.0000
41.5600 839.0000 1.0000
41.6000 861.0000 1.0000
41.6400 857.0000 1.0000
41.6800 906.0000 1.0000
41.7200 880.0000 1.0000
41.7600 864.0000 1.0000
41.8000 869.0000 1.0000
41.8400 878.0000 1.0000
41.8800 852.0000 1.0000
41.9200 890.0000 1.0000
41.9600 812.0000 1.0000
42.0000 871.0000 1.0000
42.0400 885.0000 1.0000
42.0800 881.0000 1.0000
42.1200 891.0000 1.0000
42.1600 850.0000 1.0000
42.2000 857.0000 1.0000
42.2400 878.0000 1.0000
42.2800 859.0000 1.0000
42.3200 825.0000 1.0000
42.3600 820.0000 1.0000
42.4000 860.0000 1.0000
42.4400 861.0000 1.0000
42.4800 827.0000 1.0000
42.5200 849.0000 1.0000
42.5600 843.0000 1.0000
42.6000 840.0000 1.0000
42.6400 813.0000 1.0000
42.6800 876.0000 1.0000
42.7200 854.0000 1.0000
42.7600 856.0000 1.0000
42.8000 859.0000 1.0000
42.8400 855.0000 1.0000
42.8800 824.0000 1.0000
42.9200 868.0000 1.0000
42.9600 892.0000 1.0000
43.0000 856.0000 1.0000
43.0400 889.0000 1.0000
43.0800 871.0000 1.0000
43.1200 914.0000 1.0000
43.1600 912.0000 1.0000
43.2000 933.0000 1.0000
43.2400 968.0000 1.0000
43.2800 882.0000 1.0000
43.3200 904.0000 1.0000
43.3600 897.0000 1.0000
43.4000 845.0000 1.0000
43.4400 879.0000 1.0000
43.4800 840.0000 1.0000
43.5200 875.0000 1.0000
43.5600 885.0000 1.0000
43.6000 836.0000 1.0000
43.6400 823.0000 1.0000
43.6800 800.0000 1.0000
43.7200 880.0000 1.0000
43.7600 876.0000 1.0000
43.8000 844.0000 1.0000
43.8400 851.0000 1.0000
43.8800 818.0000 1.0000
43.9200 872.0000 1.0000
43.9600 779.0000 1.0000
44.0000 775.0000 1.0000
44.0400 794.0000 1.0000
44.0800 800.0000 1.0000
44.1200 790.0000 1.0000
44.1600 801.0000 1.0000
44.2000 834.0000 1.0000
44.2400 791.0000 1.0000
44.2800 819.0000 1.0000
44.3200 795.0000 1.0000
44.3600 813.0000 1.0000
44.4000 832.0000 1.0000
44.4400 869.0000 1.0000
44.4800 822.0000 1.0000
44.5200 803.0000 1.0000
44.5600 872.0000 1.0000
44.6000 786.0000 1.0000
44.6400 813.0000 1.0000
44.6800 780.0000 1.0000
44.7200 808.0000 1.0000
44.7600 826.0000 1.0000
44.8000 856.0000 1.0000
44.8400 839.0000 1.0000
44.8800 766.0000 1.0000
44.9200 782.0000 1.0000
44.9600 817.0000 1.0000
45.0000 814.0000 1.0000
45.0400 801.0000 1.0000
45.0800 758.0000 1.0000
45.1200 786.0000 1.0000
45.1600 815.0000 1.0000
45.2000 792.0000 1.0000
45.2400 761.0000 1.0000
45.2800 810.0000 1.0000
45.3200 849.0000 1.0000
45.3600 772.0000 1.0000
45.4000 765.0000 1.0000
45.4400 810.0000 1.0000
45.4800 744.0000 1.0000
45.5200 775.0000 1.0000
45.5600 776.0000 1.0000
45.6000 813.0000 1.0000
45.6400 731.0000 1.0000
45.6800 782.0000 1.0000
45.7200 827.0000 1.0000
45.7600 738.0000 1.0000
45.8000 793.0000 1.0000
45.8400 759.0000 1.0000
45.8800 791.0000 1.0000
45.9200 801.0000 1.0000
45.9600 820.0000 1.0000
46.0000 822.0000 1.0000
46.0400 769.0000 1.0000
46.0800 793.0000 1.0000
46.1200 745.0000 1.0000
46.1600 820.0000 1.0000
46.2000 775.0000 1.0000
46.2400 780.0000 1.0000
46.2800 803.0000 1.0000
46.3200 753.0000 1.0000
46.3600 795.0000 1.0000
46.4000 750.0000 1.0000
46.4400 781.0000 1.0000
46.4800 780.0000 1.0000
46.5200 745.0000 1.0000
46.5600 797.0000 1.0000
46.6000 767.0000 1.0000
46.6400 759.0000 1.0000
46.6800 753.0000 1.0000
46.7200 759.0000 1.0000
46.7600 776.0000 1.0000
46.8000 762.0000 1.0000
46.8400 774.0000 1.0000
46.8800 792.0000 1.0000
46.9200 827.0000 1.0000
46.9600 802.0000 1.0000
47.0000 785.0000 1.0000
47.0400 810.0000 1.0000
47.0800 746.0000 1.0000
47.1200 757.0000 1.0000
47.1600 746.0000 1.0000
47.2000 780.0000 1.0000
47.2400 782.0000 1.0000
47.2800 722.0000 1.0000
47.3200 729.0000 1.0000
47.3600 770.0000 1.0000
47.4000 741.0000 1.0000
47.4400 790.0000 1.0000
47.4800 714.0000 1.0000
47.5200 754.0000 1.0000
47.5600 776.0000 1.0000
47.6000 758.0000 1.0000
47.6400 723.0000 1.0000
47.6800 738.0000 1.0000
47.7200 693.0000 1.0000
47.7600 776.0000 1.0000
47.8000 744.0000 1.0000
47.8400 758.0000 1.0000
47.8800 739.0000 1.0000
47.9200 772.0000 1.0000
47.9600 763.0000 1.0000
48.0000 737.0000 1.0000
48.0400 730.0000 1.0000
48.0800 747.0000 1.0000
48.1200 747.0000 1.0000
48.1600 770.0000 1.0000
48.2000 732.0000 1.0000
48.2400 728.0000 1.0000
48.2800 701.0000 1.0000
48.3200 719.0000 1.0000
48.3600 738.0000 1.0000
48.4000 722.0000 1.0000
48.4400 747.0000 1.0000
48.4800 730.0000 1.0000
48.5200 721.0000 1.0000
48.5600 722.0000 1.0000
48.6000 756.0000 1.0000
48.6400 766.0000 1.0000
48.6800 732.0000 1.0000
48.7200 745.0000 1.0000
48.7600 763.0000 1.0000
48.8000 725.0000 1.0000
48.8400 743.0000 1.0000
48.8800 769.0000 1.0000
48.9200 701.0000 1.0000
48.9600 737.0000 1.0000
49.0000 763.0000 1.0000
49.0400 728.0000 1.0000
49.0800 714.0000 1.0000
49.1200 746.0000 1.0000
49.1600 749.0000 1.0000
49.2000 716.0000 1.0000
49.2400 733.0000 1.0000
49.2800 744.0000 1.0000
49.3200 740.0000 1.0000
49.3600 712.0000 1.0000
49.4000 761.0000 1.0000
49.4400 727.0000 1.0000
49.4800 699.0000 1.0000
49.5200 732.0000 1.0000
49.5600 717.0000 1.0000
49.6000 778.0000 1.0000
49.6400 707.0000 1.0000
49.6800 737.0000 1.0000
49.7200 735.0000 1.0000
49.7600 690.0000 1.0000
49.8000 708.0000 1.0000
49.8400 777.0000 1.0000
49.8800 711.0000 1.0000
49.9200 656.0000 1.0000
49.9600 722.0000 1.0000
50.0000 700.0000 1.0000
50.0400 784.0000 1.0000
50.0800 730.0000 1.0000
50.1200 699.0000 1.0000
50.1600 740.0000 1.0000
50.2000 768.0000 1.0000
50.2400 718.0000 1.0000
50.2800 708.0000 1.0000
50.3200 742.0000 1.0000
50.3600 780.0000 1.0000
50.4000 755.0000 1.0000
50.4400 745.0000 1.0000
50.4800 728.0000 1.0000
50.5200 782.0000 1.0000
50.5600 710.0000 1.0000
50.6000 800.0000 1.0000
50.6400 755.0000 1.0000
50.6800 734.0000 1.0000
50.7200 732.0000 1.0000
50.7600 743.0000 1.0000
50.8000 774.0000 1.0000
50.8400 722.0000 1.0000
50.8800 734.0000 1.0000
50.9200 752.0000 1.0000
50.9600 783.0000 1.0000
51.0000 700.0000 1.0000
51.0400 715.0000 1.0000
51.0800 740.0000 1.0000
51.1200 726.0000 1.0000
51.1600 703.0000 1.0000
51.2000 711.0000 1.0000
51.2400 737.0000 1.0000
51.2800 754.0000 1.0000
51.3200 729.0000 1.0000
51.3600 758.0000 1.0000
51.4000 776.0000 1.0000
51.4400 725.0000 1.0000
51.4800 778.0000 1.0000
51.5200 757.0000 1.0000
51.5600 748.0000 1.0000
51.6000 752.0000 1.0000
51.6400 751.0000 1.0000
51.6800 790.0000 1.0000
51.7200 819.0000 1.0000
51.7600 785.0000 1.0000
51.8000 860.0000 1.0000
51.8400 835.0000 1.0000
51.8800 931.0000 1.0000
51.9200 1035.0000 1.0000
51.9600 1162.0000 1.0000
52.0000 1343.0000 1.0000
52.0400 1572.0000 1.0000
52.0800 1948.0000 1.0000
52.1200 2654.0000 1.0000
52.1600 3683.0000 1.0000
52.2000 4730.0000 1.0000
52.2400 5304.0000 1.0000
52.2800 4839.0000 1.0000
52.3200 4357.0000 1.0000
52.3600 4027.0000 1.0000
52.4000 3457.0000 1.0000
52.4400 2546.0000 1.0000
52.4800 1922.0000 1.0000
52.5200 1583.0000 1.0000
52.5600 1321.0000 1.0000
52.6000 1151.0000 1.0000
52.6400 1059.0000 1.0000
52.6800 1009.0000 1.0000
52.7200 951.0000 1.0000
52.7600 914.0000 1.0000
52.8000 923.0000 1.0000
52.8400 885.0000 1.0000
52.8800 811.0000 1.0000
52.9200 816.0000 1.0000
52.9600 799.0000 1.0000
53.0000 751.0000 1.0000
53.0400 785.0000 1.0000
53.0800 705.0000 1.0000
53.1200 741.0000 1.0000
53.1600 756.0000 1.0000
53.2000 733.0000 1.0000
53.2400 784.0000 1.0000
53.2800 759.0000 1.0000
53.3200 716.0000 1.0000
53.3600 772.0000 1.0000
53.4000 732.0000 1.0000
53.4400 768.0000 1.0000
53.4800 706.0000 1.0000
53.5200 745.0000 1.0000
53.5600 734.0000 1.0000
53.6000 710.0000 1.0000
53.6400 755.0000 1.0000
53.6800 723.0000 1.0000
53.7200 760.0000 1.0000
53.7600 702.0000 1.0000
53.8000 785.0000 1.0000
53.8400 735.0000 1.0000
53.8800 705.0000 1.0000
53.9200 723.0000 1.0000
53.9600 758.0000 1.0000
54.0000 699.0000 1.0000
54.0400 728.0000 1.0000
54.0800 724.0000 1.0000
54.1200 669.0000 1.0000
54.1600 725.0000 1.0000
54.2000 725.0000 1.0000
54.2400 700.0000 1.0000
54.2800 747.0000 1.0000
54.3200 704.0000 1.0000
54.3600 751.0000 1.0000
54.4000 731.0000 1.0000
54.4400 729.0000 1.0000
54.4800 725.0000 1.0000
54.5200 701.0000 1.0000
54.5600 695.0000 1.0000
54.6000 703.0000 1.0000
54.6400 723.0000 1.0000
54.6800 739.0000 1.0000
54.7200 762.0000 1.0000
54.7600 769.0000 1.0000
54.8000 755.0000 1.0000
54.8400 820.0000 1.0000
54.8800 776.0000 1.0000
54.9200 791.0000 1.0000
54.9600 819.0000 1.0000
55.0000 773.0000 1.0000
55.0400 823.0000 1.0000
55.0800 874.0000 1.0000
55.1200 921.0000 1.0000
55.1600 1054.0000 1.0000
55.2000 1121.0000 1.0000
55.2400 1174.0000 1.0000
55.2800 1149.0000 1.0000
55.3200 1091.0000 1.0000
55.3600 1122.0000 1.0000
55.4000 994.0000 1.0000
55.4400 1011.0000 1.0000
55.4800 878.0000 1.0000
55.5200 809.0000 1.0000
55.5600 850.0000 1.0000
55.6000 827.0000 1.0000
55.6400 768.0000 1.0000
55.6800 743.0000 1.0000
55.7200 781.0000 1.0000
55.7600 752.0000 1.0000
55.8000 807.0000 1.0000
55.8400 721.0000 1.0000
55.8800 673.0000 1.0000
55.9200 708.0000 1.0000
55.9600 748.0000 1.0000
56.0000 725.0000 1.0000
56.0400 677.0000 1.0000
56.0800 651.0000 1.0000
56.1200 678.0000 1.0000
56.1600 733.0000 1.0000
56.2000 649.0000 1.0000
56.2400 723.0000 1.0000
56.2800 728.0000 1.0000
56.3200 714.0000 1.0000
56.3600 660.0000 1.0000
56.4000 710.0000 1.0000
56.4400 720.0000 1.0000
56.4800 720.0000 1.0000
56.5200 663.0000 1.0000
56.5600 660.0000 1.0000
56.6000 702.0000 1.0000
56.6400 694.0000 1.0000
56.6800 705.0000 1.0000
56.7200 706.0000 1.0000
56.7600 707.0000 1.0000
56.8000 665.0000 1.0000
56.8400 716.0000 1.0000
56.8800 693.0000 1.0000
56.9200 710.0000 1.0000
56.9600 666.0000 1.0000
57.0000 704.0000 1.0000
57.0400 698.0000 1.0000
57.0800 674.0000 1.0000
57.1200 681.0000 1.0000
57.1600 686.0000 1.0000
57.2000 675.0000 1.0000
57.2400 670.0000 1.0000
57.2800 706.0000 1.0000
57.3200 648.0000 1.0000
57.3600 677.0000 1.0000
57.4000 667.0000 1.0000
57.4400 681.0000 1.0000
57.4800 706.0000 1.0000
57.5200 639.0000 1.0000
57.5600 668.0000 1.0000
57.6000 687.0000 1.0000
57.6400 717.0000 1.0000
57.6800 698.0000 1.0000
57.7200 705.0000 1.0000
57.7600 700.0000 1.0000
57.8000 710.0000 1.0000
57.8400 673.0000 1.0000
57.8800 688.0000 1.0000
57.9200 671.0000 1.0000
57.9600 696.0000 1.0000
58.0000 668.0000 1.0000
58.0400 682.0000 1.0000
58.0800 693.0000 1.0000
58.1200 694.0000 1.0000
58.1600 690.0000 1.0000
58.2000 733.0000 1.0000
58.2400 735.0000 1.0000
58.2800 726.0000 1.0000
58.3200 714.0000 1.0000
58.3600 705.0000 1.0000
58.4000 710.0000 1.0000
58.4400 727.0000 1.0000
58.4800 708.0000 1.0000
58.5200 732.0000 1.0000
58.5600 725.0000 1.0000
58.6000 714.0000 1.0000
58.6400 708.0000 1.0000
58.6800 729.0000 1.0000
58.7200 699.0000 1.0000
58.7600 643.0000 1.0000
58.8000 643.0000 1.0000
58.8400 714.0000 1.0000
58.8800 635.0000 1.0000
58.9200 680.0000 1.0000
58.9600 675.0000 1.0000
59.0000 721.0000 1.0000
59.0400 713.0000 1.0000
59.0800 659.0000 1.0000
59.1200 690.0000 1.0000
59.1600 696.0000 1.0000
59.2000 658.0000 1.0000
59.2400 699.0000 1.0000
59.2800 713.0000 1.0000
59.3200 705.0000 1.0000
59.3600 693.0000 1.0000
59.4000 702.0000 1.0000
59.4400 710.0000 1.0000
59.4800 701.0000 1.0000
59.5200 667.0000 1.0000
59.5600 652.0000 1.0000
59.6000 709.0000 1.0000
59.6400 697.0000 1.0000
59.6800 648.0000 1.0000
59.7200 693.0000 1.0000
59.7600 668.0000 1.0000
59.8000 654.0000 1.0000
59.8400 725.0000 1.0000
59.8800 690.0000 1.0000
59.9200 702.0000 1.0000
59.9600 672.0000 1.0000
60.0000 683.0000 1.0000
60.0400 728.0000 1.0000
60.0800 694.0000 1.0000
60.1200 686.0000 1.0000
60.1600 714.0000 1.0000
60.2000 667.0000 1.0000
60.2400 677.0000 1.0000
60.2800 729.0000 1.0000
60.3200 693.0000 1.0000
60.3600 652.0000 1.0000
60.4000 683.0000 1.0000
60.4400 694.0000 1.0000
60.4800 702.0000 1.0000
60.5200 676.0000 1.0000
60.5600 695.0000 1.0000
60.6000 705.0000 1.0000
60.6400 678.0000 1.0000
60.6800 689.0000 1.0000
60.7200 707.0000 1.0000
60.7600 680.0000 1.0000
60.8000 698.0000 1.0000
60.8400 661.0000 1.0000
60.8800 693.0000 1.0000
60.9200 704.0000 1.0000
60.9600 693.0000 1.0000
61.0000 695.0000 1.0000
61.0400 702.0000 1.0000
61.0800 680.0000 1.0000
61.1200 695.0000 1.0000
61.1600 684.0000 1.0000
61.2000 685.0000 1.0000
61.2400 687.0000 1.0000
61.2800 687.0000 1.0000
61.3200 713.0000 1.0000
61.3600 736.0000 1.0000
61.4000 692.0000 1.0000
61.4400 742.0000 1.0000
61.4800 715.0000 1.0000
61.5200 734.0000 1.0000
61.5600 726.0000 1.0000
61.6000 757.0000 1.0000
61.6400 741.0000 1.0000
61.6800 746.0000 1.0000
61.7200 746.0000 1.0000
61.7600 773.0000 1.0000
61.8000 815.0000 1.0000
61.8400 802.0000 1.0000
61.8800 866.0000 1.0000
61.9200 869.0000 1.0000
61.9600 910.0000 1.0000
62.0000 962.0000 1.0000
62.0400 1106.0000 1.0000
62.0800 1180.0000 1.0000
62.1200 1370.0000 1.0000
62.1600 1550.0000 1.0000
62.2000 1744.0000 1.0000
62.2400 1727.0000 1.0000
62.2800 1780.0000 1.0000
62.3200 1785.0000 1.0000
62.3600 1739.0000 1.0000
62.4000 1628.0000 1.0000
62.4400 1508.0000 1.0000
62.4800 1336.0000 1.0000
62.5200 1272.0000 1.0000
62.5600 1146.0000 1.0000
62.6000 1096.0000 1.0000
62.6400 1022.0000 1.0000
62.6800 900.0000 1.0000
62.7200 907.0000 1.0000
62.7600 849.0000 1.0000
62.8000 849.0000 1.0000
62.8400 813.0000 1.0000
62.8800 804.0000 1.0000
62.9200 751.0000 1.0000
62.9600 812.0000 1.0000
63.0000 801.0000 1.0000
63.0400 779.0000 1.0000
63.0800 789.0000 1.0000
63.1200 787.0000 1.0000
63.1600 773.0000 1.0000
63.2000 800.0000 1.0000
63.2400 737.0000 1.0000
63.2800 739.0000 1.0000
63.3200 715.0000 1.0000
63.3600 722.0000 1.0000
63.4000 700.0000 1.0000
63.4400 693.0000 1.0000
63.4800 736.0000 1.0000
63.5200 697.0000 1.0000
63.5600 730.0000 1.0000
63.6000 705.0000 1.0000
63.6400 705.0000 1.0000
63.6800 702.0000 1.0000
63.7200 669.0000 1.0000
63.7600 717.0000 1.0000
63.8000 693.0000 1.0000
63.8400 708.0000 1.0000
63.8800 743.0000 1.0000
63.9200 740.0000 1.0000
63.9600 698.0000 1.0000
64.0000 732.0000 1.0000
64.0400 740.0000 1.0000
64.0800 737.0000 1.0000
64.1200 701.0000 1.0000
64.1600 677.0000 1.0000
64.2000 695.0000 1.0000
64.2400 740.0000 1.0000
64.2800 759.0000 1.0000
64.3200 729.0000 1.0000
64.3600 691.0000 1.0000
64.4000 712.0000 1.0000
64.4400 747.0000 1.0000
64.4800 737.0000 1.0000
64.5200 747.0000 1.0000
64.5600 833.0000 1.0000
64.6000 781.0000 1.0000
64.6400 796.0000 1.0000
64.6800 807.0000 1.0000
64.7200 837.0000 1.0000
64.7600 797.0000 1.0000
64.8000 774.0000 1.0000
64.8400 806.0000 1.0000
64.8800 814.0000 1.0000
64.9200 825.0000 1.0000
64.9600 757.0000 1.0000
65.0000 751.0000 1.0000
65.0400 761.0000 1.0000
65.0800 729.0000 1.0000
65.1200 762.0000 1.0000
65.1600 698.0000 1.0000
65.2000 722.0000 1.0000
65.2400 748.0000 1.0000
65.2800 736.0000 1.0000
65.3200 725.0000 1.0000
65.3600 711.0000 1.0000
65.4000 760.0000 1.0000
65.4400 737.0000 1.0000
65.4800 801.0000 1.0000
65.5200 733.0000 1.0000
65.5600 728.0000 1.0000
65.6000 763.0000 1.0000
65.6400 740.0000 1.0000
65.6800 746.0000 1.0000
65.7200 741.0000 1.0000
65.7600 844.0000 1.0000
65.8000 848.0000 1.0000
65.8400 922.0000 1.0000
65.8800 923.0000 1.0000
65.9200 980.0000 1.0000
65.9600 1112.0000 1.0000
66.0000 1183.0000 1.0000
66.0400 1411.0000 1.0000
66.0800 1699.0000 1.0000
66.1200 2039.0000 1.0000
66.1600 2571.0000 1.0000
66.2000 2925.0000 1.0000
66.2400 2907.0000 1.0000
66.2800 2726.0000 1.0000
66.3200 2439.0000 1.0000
66.3600 2370.0000 1.0000
66.4000 2293.0000 1.0000
66.4400 1932.0000 1.0000
66.4800 1677.0000 1.0000
66.5200 1413.0000 1.0000
66.5600 1287.0000 1.0000
66.6000 1169.0000 1.0000
66.6400 982.0000 1.0000
66.6800 937.0000 1.0000
66.7200 839.0000 1.0000
66.7600 818.0000 1.0000
66.8000 757.0000 1.0000
66.8400 782.0000 1.0000
66.8800 778.0000 1.0000
66.9200 735.0000 1.0000
66.9600 708.0000 1.0000
67.0000 758.0000 1.0000
67.0400 729.0000 1.0000
67.0800 682.0000 1.0000
67.1200 697.0000 1.0000
67.1600 688.0000 1.0000
67.2000 714.0000 1.0000
67.2400 719.0000 1.0000
67.2800 681.0000 1.0000
67.3200 686.0000 1.0000
67.3600 661.0000 1.0000
67.4000 676.0000 1.0000
67.4400 691.0000 1.0000
67.4800 649.0000 1.0000
67.5200 650.0000 1.0000
67.5600 665.0000 1.0000
67.6000 668.0000 1.0000
67.6400 635.0000 1.0000
67.6800 661.0000 1.0000
67.7200 602.0000 1.0000
67.7600 606.0000 1.0000
67.8000 664.0000 1.0000
67.8400 647.0000 1.0000
67.8800 665.0000 1.0000
67.9200 644.0000 1.0000
67.9600 652.0000 1.0000
68.0000 652.0000 1.0000
68.0400 646.0000 1.0000
68.0800 625.0000 1.0000
68.1200 662.0000 1.0000
68.1600 629.0000 1.0000
68.2000 644.0000 1.0000
68.2400 664.0000 1.0000
68.2800 626.0000 1.0000
68.3200 628.0000 1.0000
68.3600 648.0000 1.0000
68.4000 644.0000 1.0000
68.4400 654.0000 1.0000
68.4800 609.0000 1.0000
68.5200 573.0000 1.0000
68.5600 608.0000 1.0000
68.6000 635.0000 1.0000
68.6400 638.0000 1.0000
68.6800 644.0000 1.0000
68.7200 617.0000 1.0000
68.7600 602.0000 1.0000
68.8000 634.0000 1.0000
68.8400 613.0000 1.0000
68.8800 617.0000 1.0000
68.9200 628.0000 1.0000
68.9600 581.0000 1.0000
69.0000 624.0000 1.0000
69.0400 596.0000 1.0000
69.0800 574.0000 1.0000
69.1200 668.0000 1.0000
69.1600 599.0000 1.0000
69.2000 634.0000 1.0000
69.2400 626.0000 1.0000
69.2800 607.0000 1.0000
69.3200 610.0000 1.0000
69.3600 652.0000 1.0000
69.4000 617.0000 1.0000
69.4400 644.0000 1.0000
69.4800 618.0000 1.0000
69.5200 626.0000 1.0000
69.5600 622.0000 1.0000
69.6000 611.0000 1.0000
69.6400 580.0000 1.0000
69.6800 626.0000 1.0000
69.7200 607.0000 1.0000
69.7600 620.0000 1.0000
69.8000 638.0000 1.0000
69.8400 638.0000 1.0000
69.8800 579.0000 1.0000
69.9200 544.0000 1.0000
69.9600 591.0000 1.0000
70.0000 603.0000 1.0000
*RAS_INT_END
*RAS_TEMPERATURE_START
*RAS_TEMPERATURE_END
*RAS_DATA_END