File: Data/Dataset1_Only_water/5_XRD/No_044_deposition_2h_Air_2.ras
*RAS_DATA_START
*RAS_HEADER_START
*DISP_FMT_X "%.2f"
*DISP_FMT_Y "%.0f"
*DISP_FULLSCALE "15390.0000000000"
*DISP_LINE_COLOR "255.0000000000"
*DISP_LINE_STYLE "0.0000000000"
*DISP_LINE_WIDTH "0.2500000000"
*DISP_NOTE "測定データ-9"
*DISP_OFFSET_Y "0.0000000000"
*DISP_PEAKSEARCH_UNIT_Y "cps"
*DISP_RANGE_BOTTOM "0.0000000000"
*DISP_RANGE_LEFT "20.0000000000"
*DISP_RANGE_LOGCUTOFF "0.0100000000"
*DISP_RANGE_RIGHT "70.0000000000"
*DISP_RANGE_TOP "15390.0000000000"
*DISP_SCALE_MODE_Y "0.0000000000"
*DISP_TAB_NAME "2θ/θ"
*DISP_TITLE_Y "強度"
*DISP_UNIT_Y "cps"
*DISP_WINDOW_NAME "MSG_MACROENGINE"
*FILE_COMMENT " "
*FILE_MD5 ""
*FILE_MEMO " "
*FILE_OPERATOR "Administrator"
*FILE_SAMPLE " "
*FILE_TYPE "RAS_RAW"
*FILE_USERGROUP "システムマネージャ"
*FILE_VERSION "1.0000000000"
*HW_ATTACHMENT_ID "ATT0025"
*HW_ATTACHMENT_NAME "標準|Standard"
*HW_COUNTER_ID-0 "CUT0025"
*HW_COUNTER_ID-1 "CUT0020"
*HW_COUNTER_ID-2 "CUT0020"
*HW_COUNTER_ID-3 "CSL0021"
*HW_COUNTER_ID-4 "CMC0021"
*HW_COUNTER_NAME-0 "D/teX Ultra|D/teX Ultra"
*HW_COUNTER_NAME-1 "None|None"
*HW_COUNTER_NAME-2 "None|None"
*HW_COUNTER_NAME-3 "BBM|BBM"
*HW_COUNTER_NAME-4 "検出器モノクロメータ|Detector monochromator"
*HW_COUNTER_SELECT_NAME "D/teX Ultra|D/teX Ultra"
*HW_GONIOMETER_ID "GON0023"
*HW_GONIOMETER_NAME "SmartLab|SmartLab"
*HW_GONIOMETER_RADIUS-0 "90.0"
*HW_GONIOMETER_RADIUS-1 "114.0"
*HW_GONIOMETER_RADIUS-2 "190.0"
*HW_GONIOMETER_RADIUS-3 "300.0"
*HW_GONIOMETER_RADIUS-4 "187.0"
*HW_GONIOMETER_RADIUS-5 "300.0"
*HW_GONIOMETER_RADIUS-6 "113.0"
*HW_GONIOMETER_RADIUS-7 "331.0"
*HW_I_OPT_ID-0 "CBO0021"
*HW_I_OPT_ID-1 "ICR0023"
*HW_I_OPT_ID-2 "ISL0021"
*HW_I_OPT_ID-3 "ISO0021"
*HW_I_OPT_ID-4 "IAD0021"
*HW_I_OPT_ID-5 "IPR0001"
*HW_I_OPT_NAME-0 "CBOユニット|CBO unit"
*HW_I_OPT_NAME-1 "標準入射光学ユニット|Standard incident optical unit"
*HW_I_OPT_NAME-2 "標準入射スリットボックス|Standard incident slit box"
*HW_I_OPT_NAME-3 "入射平行スリット|Incident parallel slit"
*HW_I_OPT_NAME-4 "長手制限スリット|Length limiting slit"
*HW_I_OPT_NAME-5 "None|None"
*HW_R_ATTENUATER_AUTOMODE "0"
*HW_R_OPT_ID-0 "RSS0021"
*HW_R_OPT_ID-1 "RCR0023"
*HW_R_OPT_ID-2 "RSO0021"
*HW_R_OPT_ID-3 "RRS0021"
*HW_R_OPT_ID-4 "ATN0021"
*HW_R_OPT_ID-5 "RFL0021"
*HW_R_OPT_ID-6 "RAD0021"
*HW_R_OPT_NAME-0 "標準受光スリットボックス1|Standard receiving slit box # 1"
*HW_R_OPT_NAME-1 "標準受光光学ユニット1|Standard receiving unit # 1"
*HW_R_OPT_NAME-2 "標準受光光学ユニット2|Standard receiving optical unit # 2"
*HW_R_OPT_NAME-3 "標準受光スリットボックス2|Standard receiving slit box # 2"
*HW_R_OPT_NAME-4 "標準アッテネータ|Standard Attenuator"
*HW_R_OPT_NAME-5 "Cu Kβ|Cu K-beta"
*HW_R_OPT_NAME-6 "調整用受光スリット|Alignment receiving slit"
*HW_SAMPLE_HOLDER_ID "SMP0023"
*HW_SAMPLE_HOLDER_NAME "標準Zステージ|Standard Z stage"
*HW_XG_CURRENT_MAX "50"
*HW_XG_CURRENT_MIN "2"
*HW_XG_CURRENT_RESOLUTION "1"
*HW_XG_CURRENT_UNIT "mA"
*HW_XG_FOCUS "1mm x 10mm"
*HW_XG_FOCUS_TYPE "Normal"
*HW_XG_ID ""
*HW_XG_NAME "3kW 封入管(ID:1200)|3kW Sealed tube(ID:1200)"
*HW_XG_TARGET_ATOMIC_NUMBER "29.0000000000"
*HW_XG_TARGET_NAME "Cu"
*HW_XG_TYPE "Hermetic"
*HW_XG_VOLTAGE_MAX "60"
*HW_XG_VOLTAGE_MIN "20"
*HW_XG_VOLTAGE_RESOLUTION "1"
*HW_XG_VOLTAGE_UNIT "kV"
*HW_XG_WATT_MAX "1.500"
*HW_XG_WATT_UNIT "kW"
*HW_XG_WAVE_LENGTH_ALPHA1 "1.540593"
*HW_XG_WAVE_LENGTH_ALPHA2 "1.544414"
*HW_XG_WAVE_LENGTH_BETA "1.392250"
*MEAS_COND_AXIS_NAME-0 "2θ/θ"
*MEAS_COND_AXIS_NAME-1 "2θ"
*MEAS_COND_AXIS_NAME-2 "ω"
*MEAS_COND_AXIS_NAME-3 "Z"
*MEAS_COND_AXIS_NAME-4 "2θ/ω"
*MEAS_COND_AXIS_NAME-5 "θs"
*MEAS_COND_AXIS_NAME-6 "θd"
*MEAS_COND_AXIS_NAME-7 "Ts"
*MEAS_COND_AXIS_NAME-8 "CBO選択スリット"
*MEAS_COND_AXIS_NAME-9 "M"
*MEAS_COND_AXIS_NAME-10 "入射平行スリット"
*MEAS_COND_AXIS_NAME-11 "入射スリット"
*MEAS_COND_AXIS_NAME-12 ""
*MEAS_COND_AXIS_NAME-13 "Zs"
*MEAS_COND_AXIS_NAME-14 "入射光学素子"
*MEAS_COND_AXIS_NAME-15 "長手制限スリット"
*MEAS_COND_AXIS_NAME-16 "センタースリット"
*MEAS_COND_AXIS_NAME-17 "フィルター"
*MEAS_COND_AXIS_NAME-18 "受光スリット1"
*MEAS_COND_AXIS_NAME-19 "受光スリット2"
*MEAS_COND_AXIS_NAME-20 "受光光学素子"
*MEAS_COND_AXIS_NAME-21 "受光平行スリット"
*MEAS_COND_AXIS_NAME-22 "調整用受光スリット"
*MEAS_COND_AXIS_NAME-23 ""
*MEAS_COND_AXIS_NAME-24 ""
*MEAS_COND_AXIS_NAME-25 "Zd"
*MEAS_COND_AXIS_NAME-26 "アッテネータ"
*MEAS_COND_AXIS_NAME-27 "検出器モノクロメータ"
*MEAS_COND_AXIS_NAME-28 "モノクロメータスリット"
*MEAS_COND_AXIS_NAME-29 "プライマリビーム"
*MEAS_COND_AXIS_NAME-30 "PHA"
*MEAS_COND_AXIS_NAME_INTERNAL-0 "TwoThetaTheta"
*MEAS_COND_AXIS_NAME_INTERNAL-1 "TwoTheta"
*MEAS_COND_AXIS_NAME_INTERNAL-2 "Omega"
*MEAS_COND_AXIS_NAME_INTERNAL-3 "Z"
*MEAS_COND_AXIS_NAME_INTERNAL-4 "TwoThetaOmega"
*MEAS_COND_AXIS_NAME_INTERNAL-5 "ThetaS"
*MEAS_COND_AXIS_NAME_INTERNAL-6 "ThetaD"
*MEAS_COND_AXIS_NAME_INTERNAL-7 "Ts"
*MEAS_COND_AXIS_NAME_INTERNAL-8 "CBO"
*MEAS_COND_AXIS_NAME_INTERNAL-9 "CBO-M"
*MEAS_COND_AXIS_NAME_INTERNAL-10 "IncidentSollerSlit"
*MEAS_COND_AXIS_NAME_INTERNAL-11 "IncidentSlitBox"
*MEAS_COND_AXIS_NAME_INTERNAL-12 "IncidentSlitBox-_Axis"
*MEAS_COND_AXIS_NAME_INTERNAL-13 "Zs"
*MEAS_COND_AXIS_NAME_INTERNAL-14 "IncidentMonochromator"
*MEAS_COND_AXIS_NAME_INTERNAL-15 "IncidentAxdSlit"
*MEAS_COND_AXIS_NAME_INTERNAL-16 "CenterSlit"
*MEAS_COND_AXIS_NAME_INTERNAL-17 "Filter"
*MEAS_COND_AXIS_NAME_INTERNAL-18 "ReceivingSlitBox1"
*MEAS_COND_AXIS_NAME_INTERNAL-19 "ReceivingSlitBox2"
*MEAS_COND_AXIS_NAME_INTERNAL-20 "ReceivingOptics"
*MEAS_COND_AXIS_NAME_INTERNAL-21 "ReceivingSollerSlit"
*MEAS_COND_AXIS_NAME_INTERNAL-22 "ReceivingAxdSlit"
*MEAS_COND_AXIS_NAME_INTERNAL-23 "ReceivingSlitBox1-_Axis"
*MEAS_COND_AXIS_NAME_INTERNAL-24 "ReceivingSlitBox2-_Axis"
*MEAS_COND_AXIS_NAME_INTERNAL-25 "ReceivingSlitBox2-Zd"
*MEAS_COND_AXIS_NAME_INTERNAL-26 "Attenuator"
*MEAS_COND_AXIS_NAME_INTERNAL-27 "CounterMonochromator"
*MEAS_COND_AXIS_NAME_INTERNAL-28 "CounterSlit"
*MEAS_COND_AXIS_NAME_INTERNAL-29 "IncidentPrimary"
*MEAS_COND_AXIS_NAME_INTERNAL-30 "PHA"
*MEAS_COND_AXIS_NAME_MAGICNO-0 "83951616.0000000000"
*MEAS_COND_AXIS_NAME_MAGICNO-1 "268632064.0000000000"
*MEAS_COND_AXIS_NAME_MAGICNO-2 "268500992.0000000000"
*MEAS_COND_AXIS_NAME_MAGICNO-3 "285278208.0000000000"
*MEAS_COND_AXIS_NAME_MAGICNO-4 "83951616.0000000000"
*MEAS_COND_AXIS_NAME_MAGICNO-5 "131072.0000000000"
*MEAS_COND_AXIS_NAME_MAGICNO-6 "131072.0000000000"
*MEAS_COND_AXIS_NAME_MAGICNO-7 "318898176.0000000000"
*MEAS_COND_AXIS_NAME_MAGICNO-8 "20971521.0000000000"
*MEAS_COND_AXIS_NAME_MAGICNO-9 "285343744.0000000000"
*MEAS_COND_AXIS_NAME_MAGICNO-10 "20971521.0000000000"
*MEAS_COND_AXIS_NAME_MAGICNO-11 "22020097.0000000000"
*MEAS_COND_AXIS_NAME_MAGICNO-12 "25165824.0000000000"
*MEAS_COND_AXIS_NAME_MAGICNO-13 "318898176.0000000000"
*MEAS_COND_AXIS_NAME_MAGICNO-14 "1.0000000000"
*MEAS_COND_AXIS_NAME_MAGICNO-15 "20971521.0000000000"
*MEAS_COND_AXIS_NAME_MAGICNO-16 "20971521.0000000000"
*MEAS_COND_AXIS_NAME_MAGICNO-17 "20971521.0000000000"
*MEAS_COND_AXIS_NAME_MAGICNO-18 "23068673.0000000000"
*MEAS_COND_AXIS_NAME_MAGICNO-19 "23068673.0000000000"
*MEAS_COND_AXIS_NAME_MAGICNO-20 "20971521.0000000000"
*MEAS_COND_AXIS_NAME_MAGICNO-21 "20971521.0000000000"
*MEAS_COND_AXIS_NAME_MAGICNO-22 "20971521.0000000000"
*MEAS_COND_AXIS_NAME_MAGICNO-23 "25165824.0000000000"
*MEAS_COND_AXIS_NAME_MAGICNO-24 "25165824.0000000000"
*MEAS_COND_AXIS_NAME_MAGICNO-25 "285343744.0000000000"
*MEAS_COND_AXIS_NAME_MAGICNO-26 "17301505.0000000000"
*MEAS_COND_AXIS_NAME_MAGICNO-27 "20971521.0000000000"
*MEAS_COND_AXIS_NAME_MAGICNO-28 "20971521.0000000000"
*MEAS_COND_AXIS_NAME_MAGICNO-29 "20971521.0000000000"
*MEAS_COND_AXIS_NAME_MAGICNO-30 "0.0000000000"
*MEAS_COND_AXIS_OFFSET-0 "-"
*MEAS_COND_AXIS_OFFSET-1 "-0.0801000000"
*MEAS_COND_AXIS_OFFSET-2 "-0.1703000000"
*MEAS_COND_AXIS_OFFSET-3 "-"
*MEAS_COND_AXIS_OFFSET-4 "-"
*MEAS_COND_AXIS_OFFSET-5 "-0.1703000000"
*MEAS_COND_AXIS_OFFSET-6 "0.0902000000"
*MEAS_COND_AXIS_OFFSET-7 "-"
*MEAS_COND_AXIS_OFFSET-8 "-"
*MEAS_COND_AXIS_OFFSET-9 "-"
*MEAS_COND_AXIS_OFFSET-10 "-"
*MEAS_COND_AXIS_OFFSET-11 "-"
*MEAS_COND_AXIS_OFFSET-12 "-"
*MEAS_COND_AXIS_OFFSET-13 "-"
*MEAS_COND_AXIS_OFFSET-14 "-"
*MEAS_COND_AXIS_OFFSET-15 "-"
*MEAS_COND_AXIS_OFFSET-16 "-"
*MEAS_COND_AXIS_OFFSET-17 "-"
*MEAS_COND_AXIS_OFFSET-18 "-"
*MEAS_COND_AXIS_OFFSET-19 "-"
*MEAS_COND_AXIS_OFFSET-20 "-"
*MEAS_COND_AXIS_OFFSET-21 "-"
*MEAS_COND_AXIS_OFFSET-22 "-"
*MEAS_COND_AXIS_OFFSET-23 "-"
*MEAS_COND_AXIS_OFFSET-24 "-"
*MEAS_COND_AXIS_OFFSET-25 "-"
*MEAS_COND_AXIS_OFFSET-26 "-"
*MEAS_COND_AXIS_OFFSET-27 "-"
*MEAS_COND_AXIS_OFFSET-28 "-"
*MEAS_COND_AXIS_OFFSET-29 "-"
*MEAS_COND_AXIS_OFFSET-30 "-"
*MEAS_COND_AXIS_POSITION-0 "0.0000000000"
*MEAS_COND_AXIS_POSITION-1 "0.0000000000"
*MEAS_COND_AXIS_POSITION-2 "0.0000000000"
*MEAS_COND_AXIS_POSITION-3 "-2.8463000000"
*MEAS_COND_AXIS_POSITION-4 "0.0000000000"
*MEAS_COND_AXIS_POSITION-5 "0.0000000000"
*MEAS_COND_AXIS_POSITION-6 "0.0000000000"
*MEAS_COND_AXIS_POSITION-7 "-0.4278800000"
*MEAS_COND_AXIS_POSITION-8 "BB"
*MEAS_COND_AXIS_POSITION-9 "0.0000000000"
*MEAS_COND_AXIS_POSITION-10 "Soller_slit_5.0deg"
*MEAS_COND_AXIS_POSITION-11 "2/3deg"
*MEAS_COND_AXIS_POSITION-12 "2.2088000000"
*MEAS_COND_AXIS_POSITION-13 "-1.0609400000"
*MEAS_COND_AXIS_POSITION-14 "0.0000000000"
*MEAS_COND_AXIS_POSITION-15 "10.0mm"
*MEAS_COND_AXIS_POSITION-16 "None"
*MEAS_COND_AXIS_POSITION-17 "Cu_K-beta"
*MEAS_COND_AXIS_POSITION-18 "13.000mm"
*MEAS_COND_AXIS_POSITION-19 "13.000mm"
*MEAS_COND_AXIS_POSITION-20 "No_unit"
*MEAS_COND_AXIS_POSITION-21 "Soller_slit_5.0deg"
*MEAS_COND_AXIS_POSITION-22 "None"
*MEAS_COND_AXIS_POSITION-23 "13.0000000000"
*MEAS_COND_AXIS_POSITION-24 "13.0000000000"
*MEAS_COND_AXIS_POSITION-25 "0.0081300000"
*MEAS_COND_AXIS_POSITION-26 "Open"
*MEAS_COND_AXIS_POSITION-27 "None"
*MEAS_COND_AXIS_POSITION-28 "None"
*MEAS_COND_AXIS_POSITION-29 "None"
*MEAS_COND_AXIS_POSITION-30 "38.0000000000"
*MEAS_COND_AXIS_UNIT-0 "deg"
*MEAS_COND_AXIS_UNIT-1 "deg"
*MEAS_COND_AXIS_UNIT-2 "deg"
*MEAS_COND_AXIS_UNIT-3 "mm"
*MEAS_COND_AXIS_UNIT-4 "deg"
*MEAS_COND_AXIS_UNIT-5 "deg"
*MEAS_COND_AXIS_UNIT-6 "deg"
*MEAS_COND_AXIS_UNIT-7 "mm"
*MEAS_COND_AXIS_UNIT-8 ""
*MEAS_COND_AXIS_UNIT-9 "pulse"
*MEAS_COND_AXIS_UNIT-10 ""
*MEAS_COND_AXIS_UNIT-11 ""
*MEAS_COND_AXIS_UNIT-12 "mm"
*MEAS_COND_AXIS_UNIT-13 "mm"
*MEAS_COND_AXIS_UNIT-14 ""
*MEAS_COND_AXIS_UNIT-15 ""
*MEAS_COND_AXIS_UNIT-16 ""
*MEAS_COND_AXIS_UNIT-17 ""
*MEAS_COND_AXIS_UNIT-18 ""
*MEAS_COND_AXIS_UNIT-19 ""
*MEAS_COND_AXIS_UNIT-20 ""
*MEAS_COND_AXIS_UNIT-21 ""
*MEAS_COND_AXIS_UNIT-22 ""
*MEAS_COND_AXIS_UNIT-23 "mm"
*MEAS_COND_AXIS_UNIT-24 "mm"
*MEAS_COND_AXIS_UNIT-25 "mm"
*MEAS_COND_AXIS_UNIT-26 ""
*MEAS_COND_AXIS_UNIT-27 ""
*MEAS_COND_AXIS_UNIT-28 ""
*MEAS_COND_AXIS_UNIT-29 ""
*MEAS_COND_AXIS_UNIT-30 "div"
*MEAS_COND_COUNTER_CNTLOSS_CORR "0.0000000000"
*MEAS_COND_COUNTER_PHABASE "38.0000000000"
*MEAS_COND_COUNTER_PHAWINDOW "16.0000000000"
*MEAS_COND_COUNTER_PHA_UNIT "div"
*MEAS_COND_COUNTER_TAUDIFF "30.0000000000"
*MEAS_COND_COUNTER_TAUINT "0.0000000000"
*MEAS_COND_IRRADIATION_MODE "OFF"
*MEAS_COND_IRRADIATION_WIDTH ""
*MEAS_COND_OPT_ATTR "集中法"
*MEAS_COND_OPT_NAME "@集中法"
*MEAS_COND_UNSYMMETRIC_MODE "OFF"
*MEAS_COND_XG_CURRENT "30.0000000000"
*MEAS_COND_XG_VOLTAGE "40.0000000000"
*MEAS_COND_XG_WAVE_TYPE "Ka"
*MEAS_DATA_COUNT "5001.0000000000"
*MEAS_SCAN_AXIS_X "2θ/θ"
*MEAS_SCAN_AXIS_X_INTERNAL "TwoThetaTheta"
*MEAS_SCAN_END_TIME "07/02/22 17:50:19"
*MEAS_SCAN_MODE "CONTINUOUS"
*MEAS_SCAN_MONITOR "0"
*MEAS_SCAN_RESOLUTION_X "0.0002"
*MEAS_SCAN_SPEED "2.5"
*MEAS_SCAN_SPEED_UNIT "deg/min"
*MEAS_SCAN_START "20.0000000000"
*MEAS_SCAN_START_TIME "07/02/22 17:28:54"
*MEAS_SCAN_STEP "0.0100000000"
*MEAS_SCAN_STOP "70.0000000000"
*MEAS_SCAN_UNIT_X "deg"
*MEAS_SCAN_UNIT_Y "counts"
*RAS_HEADER_END
*RAS_INT_START
20.0000 952.0000 1.0000
20.0400 910.0000 1.0000
20.0800 953.0000 1.0000
20.1200 928.0000 1.0000
20.1600 928.0000 1.0000
20.2000 911.0000 1.0000
20.2400 904.0000 1.0000
20.2800 890.0000 1.0000
20.3200 923.0000 1.0000
20.3600 895.0000 1.0000
20.4000 900.0000 1.0000
20.4400 947.0000 1.0000
20.4800 925.0000 1.0000
20.5200 934.0000 1.0000
20.5600 912.0000 1.0000
20.6000 915.0000 1.0000
20.6400 898.0000 1.0000
20.6800 913.0000 1.0000
20.7200 922.0000 1.0000
20.7600 887.0000 1.0000
20.8000 954.0000 1.0000
20.8400 888.0000 1.0000
20.8800 925.0000 1.0000
20.9200 885.0000 1.0000
20.9600 915.0000 1.0000
21.0000 955.0000 1.0000
21.0400 881.0000 1.0000
21.0800 913.0000 1.0000
21.1200 916.0000 1.0000
21.1600 916.0000 1.0000
21.2000 863.0000 1.0000
21.2400 887.0000 1.0000
21.2800 931.0000 1.0000
21.3200 981.0000 1.0000
21.3600 934.0000 1.0000
21.4000 887.0000 1.0000
21.4400 938.0000 1.0000
21.4800 884.0000 1.0000
21.5200 869.0000 1.0000
21.5600 898.0000 1.0000
21.6000 892.0000 1.0000
21.6400 882.0000 1.0000
21.6800 909.0000 1.0000
21.7200 906.0000 1.0000
21.7600 895.0000 1.0000
21.8000 893.0000 1.0000
21.8400 952.0000 1.0000
21.8800 878.0000 1.0000
21.9200 936.0000 1.0000
21.9600 925.0000 1.0000
22.0000 922.0000 1.0000
22.0400 917.0000 1.0000
22.0800 886.0000 1.0000
22.1200 898.0000 1.0000
22.1600 910.0000 1.0000
22.2000 914.0000 1.0000
22.2400 883.0000 1.0000
22.2800 880.0000 1.0000
22.3200 846.0000 1.0000
22.3600 879.0000 1.0000
22.4000 935.0000 1.0000
22.4400 874.0000 1.0000
22.4800 861.0000 1.0000
22.5200 906.0000 1.0000
22.5600 906.0000 1.0000
22.6000 870.0000 1.0000
22.6400 897.0000 1.0000
22.6800 862.0000 1.0000
22.7200 890.0000 1.0000
22.7600 877.0000 1.0000
22.8000 890.0000 1.0000
22.8400 894.0000 1.0000
22.8800 844.0000 1.0000
22.9200 849.0000 1.0000
22.9600 877.0000 1.0000
23.0000 878.0000 1.0000
23.0400 856.0000 1.0000
23.0800 884.0000 1.0000
23.1200 843.0000 1.0000
23.1600 893.0000 1.0000
23.2000 876.0000 1.0000
23.2400 893.0000 1.0000
23.2800 865.0000 1.0000
23.3200 885.0000 1.0000
23.3600 881.0000 1.0000
23.4000 860.0000 1.0000
23.4400 848.0000 1.0000
23.4800 883.0000 1.0000
23.5200 879.0000 1.0000
23.5600 866.0000 1.0000
23.6000 856.0000 1.0000
23.6400 894.0000 1.0000
23.6800 888.0000 1.0000
23.7200 823.0000 1.0000
23.7600 873.0000 1.0000
23.8000 870.0000 1.0000
23.8400 904.0000 1.0000
23.8800 915.0000 1.0000
23.9200 920.0000 1.0000
23.9600 919.0000 1.0000
24.0000 914.0000 1.0000
24.0400 911.0000 1.0000
24.0800 953.0000 1.0000
24.1200 936.0000 1.0000
24.1600 954.0000 1.0000
24.2000 921.0000 1.0000
24.2400 900.0000 1.0000
24.2800 901.0000 1.0000
24.3200 917.0000 1.0000
24.3600 881.0000 1.0000
24.4000 857.0000 1.0000
24.4400 880.0000 1.0000
24.4800 874.0000 1.0000
24.5200 892.0000 1.0000
24.5600 873.0000 1.0000
24.6000 885.0000 1.0000
24.6400 910.0000 1.0000
24.6800 830.0000 1.0000
24.7200 820.0000 1.0000
24.7600 865.0000 1.0000
24.8000 828.0000 1.0000
24.8400 890.0000 1.0000
24.8800 890.0000 1.0000
24.9200 878.0000 1.0000
24.9600 892.0000 1.0000
25.0000 864.0000 1.0000
25.0400 860.0000 1.0000
25.0800 846.0000 1.0000
25.1200 822.0000 1.0000
25.1600 853.0000 1.0000
25.2000 889.0000 1.0000
25.2400 865.0000 1.0000
25.2800 844.0000 1.0000
25.3200 854.0000 1.0000
25.3600 891.0000 1.0000
25.4000 853.0000 1.0000
25.4400 871.0000 1.0000
25.4800 851.0000 1.0000
25.5200 867.0000 1.0000
25.5600 882.0000 1.0000
25.6000 876.0000 1.0000
25.6400 875.0000 1.0000
25.6800 836.0000 1.0000
25.7200 853.0000 1.0000
25.7600 878.0000 1.0000
25.8000 890.0000 1.0000
25.8400 857.0000 1.0000
25.8800 883.0000 1.0000
25.9200 923.0000 1.0000
25.9600 908.0000 1.0000
26.0000 917.0000 1.0000
26.0400 940.0000 1.0000
26.0800 995.0000 1.0000
26.1200 1022.0000 1.0000
26.1600 1071.0000 1.0000
26.2000 1165.0000 1.0000
26.2400 1275.0000 1.0000
26.2800 1477.0000 1.0000
26.3200 1768.0000 1.0000
26.3600 2117.0000 1.0000
26.4000 2641.0000 1.0000
26.4400 3009.0000 1.0000
26.4800 3047.0000 1.0000
26.5200 2628.0000 1.0000
26.5600 2126.0000 1.0000
26.6000 1760.0000 1.0000
26.6400 1482.0000 1.0000
26.6800 1280.0000 1.0000
26.7200 1161.0000 1.0000
26.7600 1106.0000 1.0000
26.8000 1017.0000 1.0000
26.8400 981.0000 1.0000
26.8800 908.0000 1.0000
26.9200 871.0000 1.0000
26.9600 913.0000 1.0000
27.0000 834.0000 1.0000
27.0400 851.0000 1.0000
27.0800 889.0000 1.0000
27.1200 803.0000 1.0000
27.1600 820.0000 1.0000
27.2000 825.0000 1.0000
27.2400 802.0000 1.0000
27.2800 827.0000 1.0000
27.3200 796.0000 1.0000
27.3600 808.0000 1.0000
27.4000 806.0000 1.0000
27.4400 788.0000 1.0000
27.4800 773.0000 1.0000
27.5200 758.0000 1.0000
27.5600 776.0000 1.0000
27.6000 770.0000 1.0000
27.6400 779.0000 1.0000
27.6800 777.0000 1.0000
27.7200 795.0000 1.0000
27.7600 758.0000 1.0000
27.8000 785.0000 1.0000
27.8400 749.0000 1.0000
27.8800 806.0000 1.0000
27.9200 749.0000 1.0000
27.9600 784.0000 1.0000
28.0000 776.0000 1.0000
28.0400 708.0000 1.0000
28.0800 775.0000 1.0000
28.1200 755.0000 1.0000
28.1600 767.0000 1.0000
28.2000 739.0000 1.0000
28.2400 776.0000 1.0000
28.2800 706.0000 1.0000
28.3200 761.0000 1.0000
28.3600 754.0000 1.0000
28.4000 733.0000 1.0000
28.4400 714.0000 1.0000
28.4800 751.0000 1.0000
28.5200 768.0000 1.0000
28.5600 781.0000 1.0000
28.6000 712.0000 1.0000
28.6400 698.0000 1.0000
28.6800 773.0000 1.0000
28.7200 738.0000 1.0000
28.7600 748.0000 1.0000
28.8000 745.0000 1.0000
28.8400 720.0000 1.0000
28.8800 709.0000 1.0000
28.9200 730.0000 1.0000
28.9600 747.0000 1.0000
29.0000 725.0000 1.0000
29.0400 741.0000 1.0000
29.0800 687.0000 1.0000
29.1200 711.0000 1.0000
29.1600 688.0000 1.0000
29.2000 660.0000 1.0000
29.2400 702.0000 1.0000
29.2800 713.0000 1.0000
29.3200 719.0000 1.0000
29.3600 716.0000 1.0000
29.4000 724.0000 1.0000
29.4400 726.0000 1.0000
29.4800 763.0000 1.0000
29.5200 677.0000 1.0000
29.5600 681.0000 1.0000
29.6000 696.0000 1.0000
29.6400 681.0000 1.0000
29.6800 722.0000 1.0000
29.7200 700.0000 1.0000
29.7600 709.0000 1.0000
29.8000 696.0000 1.0000
29.8400 648.0000 1.0000
29.8800 683.0000 1.0000
29.9200 735.0000 1.0000
29.9600 697.0000 1.0000
30.0000 714.0000 1.0000
30.0400 688.0000 1.0000
30.0800 673.0000 1.0000
30.1200 692.0000 1.0000
30.1600 701.0000 1.0000
30.2000 716.0000 1.0000
30.2400 675.0000 1.0000
30.2800 712.0000 1.0000
30.3200 661.0000 1.0000
30.3600 703.0000 1.0000
30.4000 684.0000 1.0000
30.4400 681.0000 1.0000
30.4800 665.0000 1.0000
30.5200 690.0000 1.0000
30.5600 683.0000 1.0000
30.6000 733.0000 1.0000
30.6400 641.0000 1.0000
30.6800 671.0000 1.0000
30.7200 642.0000 1.0000
30.7600 646.0000 1.0000
30.8000 646.0000 1.0000
30.8400 665.0000 1.0000
30.8800 687.0000 1.0000
30.9200 663.0000 1.0000
30.9600 683.0000 1.0000
31.0000 673.0000 1.0000
31.0400 643.0000 1.0000
31.0800 680.0000 1.0000
31.1200 682.0000 1.0000
31.1600 681.0000 1.0000
31.2000 710.0000 1.0000
31.2400 672.0000 1.0000
31.2800 708.0000 1.0000
31.3200 644.0000 1.0000
31.3600 648.0000 1.0000
31.4000 682.0000 1.0000
31.4400 633.0000 1.0000
31.4800 641.0000 1.0000
31.5200 671.0000 1.0000
31.5600 641.0000 1.0000
31.6000 701.0000 1.0000
31.6400 679.0000 1.0000
31.6800 657.0000 1.0000
31.7200 620.0000 1.0000
31.7600 642.0000 1.0000
31.8000 641.0000 1.0000
31.8400 599.0000 1.0000
31.8800 604.0000 1.0000
31.9200 652.0000 1.0000
31.9600 632.0000 1.0000
32.0000 645.0000 1.0000
32.0400 648.0000 1.0000
32.0800 642.0000 1.0000
32.1200 605.0000 1.0000
32.1600 664.0000 1.0000
32.2000 646.0000 1.0000
32.2400 661.0000 1.0000
32.2800 626.0000 1.0000
32.3200 651.0000 1.0000
32.3600 639.0000 1.0000
32.4000 616.0000 1.0000
32.4400 637.0000 1.0000
32.4800 623.0000 1.0000
32.5200 597.0000 1.0000
32.5600 645.0000 1.0000
32.6000 634.0000 1.0000
32.6400 613.0000 1.0000
32.6800 640.0000 1.0000
32.7200 638.0000 1.0000
32.7600 615.0000 1.0000
32.8000 679.0000 1.0000
32.8400 661.0000 1.0000
32.8800 691.0000 1.0000
32.9200 701.0000 1.0000
32.9600 691.0000 1.0000
33.0000 659.0000 1.0000
33.0400 772.0000 1.0000
33.0800 769.0000 1.0000
33.1200 747.0000 1.0000
33.1600 762.0000 1.0000
33.2000 781.0000 1.0000
33.2400 769.0000 1.0000
33.2800 693.0000 1.0000
33.3200 727.0000 1.0000
33.3600 748.0000 1.0000
33.4000 751.0000 1.0000
33.4400 804.0000 1.0000
33.4800 907.0000 1.0000
33.5200 980.0000 1.0000
33.5600 1106.0000 1.0000
33.6000 1318.0000 1.0000
33.6400 1517.0000 1.0000
33.6800 1584.0000 1.0000
33.7200 1442.0000 1.0000
33.7600 1251.0000 1.0000
33.8000 1096.0000 1.0000
33.8400 978.0000 1.0000
33.8800 824.0000 1.0000
33.9200 763.0000 1.0000
33.9600 730.0000 1.0000
34.0000 673.0000 1.0000
34.0400 670.0000 1.0000
34.0800 626.0000 1.0000
34.1200 590.0000 1.0000
34.1600 614.0000 1.0000
34.2000 593.0000 1.0000
34.2400 598.0000 1.0000
34.2800 607.0000 1.0000
34.3200 587.0000 1.0000
34.3600 587.0000 1.0000
34.4000 563.0000 1.0000
34.4400 551.0000 1.0000
34.4800 589.0000 1.0000
34.5200 538.0000 1.0000
34.5600 574.0000 1.0000
34.6000 579.0000 1.0000
34.6400 559.0000 1.0000
34.6800 576.0000 1.0000
34.7200 582.0000 1.0000
34.7600 539.0000 1.0000
34.8000 544.0000 1.0000
34.8400 495.0000 1.0000
34.8800 561.0000 1.0000
34.9200 544.0000 1.0000
34.9600 549.0000 1.0000
35.0000 556.0000 1.0000
35.0400 545.0000 1.0000
35.0800 546.0000 1.0000
35.1200 530.0000 1.0000
35.1600 514.0000 1.0000
35.2000 564.0000 1.0000
35.2400 546.0000 1.0000
35.2800 565.0000 1.0000
35.3200 588.0000 1.0000
35.3600 603.0000 1.0000
35.4000 616.0000 1.0000
35.4400 676.0000 1.0000
35.4800 754.0000 1.0000
35.5200 879.0000 1.0000
35.5600 925.0000 1.0000
35.6000 966.0000 1.0000
35.6400 893.0000 1.0000
35.6800 849.0000 1.0000
35.7200 718.0000 1.0000
35.7600 666.0000 1.0000
35.8000 622.0000 1.0000
35.8400 551.0000 1.0000
35.8800 543.0000 1.0000
35.9200 505.0000 1.0000
35.9600 526.0000 1.0000
36.0000 507.0000 1.0000
36.0400 510.0000 1.0000
36.0800 497.0000 1.0000
36.1200 496.0000 1.0000
36.1600 503.0000 1.0000
36.2000 477.0000 1.0000
36.2400 488.0000 1.0000
36.2800 523.0000 1.0000
36.3200 546.0000 1.0000
36.3600 510.0000 1.0000
36.4000 521.0000 1.0000
36.4400 533.0000 1.0000
36.4800 545.0000 1.0000
36.5200 500.0000 1.0000
36.5600 490.0000 1.0000
36.6000 500.0000 1.0000
36.6400 496.0000 1.0000
36.6800 523.0000 1.0000
36.7200 507.0000 1.0000
36.7600 476.0000 1.0000
36.8000 506.0000 1.0000
36.8400 506.0000 1.0000
36.8800 524.0000 1.0000
36.9200 504.0000 1.0000
36.9600 472.0000 1.0000
37.0000 491.0000 1.0000
37.0400 487.0000 1.0000
37.0800 491.0000 1.0000
37.1200 507.0000 1.0000
37.1600 467.0000 1.0000
37.2000 518.0000 1.0000
37.2400 516.0000 1.0000
37.2800 497.0000 1.0000
37.3200 577.0000 1.0000
37.3600 598.0000 1.0000
37.4000 634.0000 1.0000
37.4400 724.0000 1.0000
37.4800 785.0000 1.0000
37.5200 918.0000 1.0000
37.5600 1096.0000 1.0000
37.6000 1432.0000 1.0000
37.6400 1828.0000 1.0000
37.6800 2250.0000 1.0000
37.7200 2364.0000 1.0000
37.7600 2296.0000 1.0000
37.8000 2109.0000 1.0000
37.8400 1672.0000 1.0000
37.8800 1345.0000 1.0000
37.9200 1081.0000 1.0000
37.9600 848.0000 1.0000
38.0000 674.0000 1.0000
38.0400 639.0000 1.0000
38.0800 599.0000 1.0000
38.1200 582.0000 1.0000
38.1600 539.0000 1.0000
38.2000 496.0000 1.0000
38.2400 506.0000 1.0000
38.2800 479.0000 1.0000
38.3200 477.0000 1.0000
38.3600 503.0000 1.0000
38.4000 479.0000 1.0000
38.4400 449.0000 1.0000
38.4800 443.0000 1.0000
38.5200 461.0000 1.0000
38.5600 470.0000 1.0000
38.6000 482.0000 1.0000
38.6400 495.0000 1.0000
38.6800 448.0000 1.0000
38.7200 453.0000 1.0000
38.7600 454.0000 1.0000
38.8000 505.0000 1.0000
38.8400 463.0000 1.0000
38.8800 466.0000 1.0000
38.9200 462.0000 1.0000
38.9600 488.0000 1.0000
39.0000 428.0000 1.0000
39.0400 435.0000 1.0000
39.0800 425.0000 1.0000
39.1200 415.0000 1.0000
39.1600 438.0000 1.0000
39.2000 420.0000 1.0000
39.2400 442.0000 1.0000
39.2800 418.0000 1.0000
39.3200 438.0000 1.0000
39.3600 423.0000 1.0000
39.4000 440.0000 1.0000
39.4400 428.0000 1.0000
39.4800 456.0000 1.0000
39.5200 424.0000 1.0000
39.5600 427.0000 1.0000
39.6000 409.0000 1.0000
39.6400 416.0000 1.0000
39.6800 438.0000 1.0000
39.7200 427.0000 1.0000
39.7600 414.0000 1.0000
39.8000 433.0000 1.0000
39.8400 389.0000 1.0000
39.8800 413.0000 1.0000
39.9200 393.0000 1.0000
39.9600 448.0000 1.0000
40.0000 420.0000 1.0000
40.0400 384.0000 1.0000
40.0800 400.0000 1.0000
40.1200 413.0000 1.0000
40.1600 418.0000 1.0000
40.2000 428.0000 1.0000
40.2400 417.0000 1.0000
40.2800 393.0000 1.0000
40.3200 413.0000 1.0000
40.3600 409.0000 1.0000
40.4000 448.0000 1.0000
40.4400 430.0000 1.0000
40.4800 412.0000 1.0000
40.5200 363.0000 1.0000
40.5600 390.0000 1.0000
40.6000 408.0000 1.0000
40.6400 408.0000 1.0000
40.6800 450.0000 1.0000
40.7200 442.0000 1.0000
40.7600 455.0000 1.0000
40.8000 423.0000 1.0000
40.8400 464.0000 1.0000
40.8800 426.0000 1.0000
40.9200 441.0000 1.0000
40.9600 427.0000 1.0000
41.0000 418.0000 1.0000
41.0400 408.0000 1.0000
41.0800 422.0000 1.0000
41.1200 386.0000 1.0000
41.1600 385.0000 1.0000
41.2000 369.0000 1.0000
41.2400 392.0000 1.0000
41.2800 408.0000 1.0000
41.3200 384.0000 1.0000
41.3600 378.0000 1.0000
41.4000 381.0000 1.0000
41.4400 406.0000 1.0000
41.4800 398.0000 1.0000
41.5200 419.0000 1.0000
41.5600 390.0000 1.0000
41.6000 423.0000 1.0000
41.6400 373.0000 1.0000
41.6800 406.0000 1.0000
41.7200 410.0000 1.0000
41.7600 386.0000 1.0000
41.8000 379.0000 1.0000
41.8400 430.0000 1.0000
41.8800 385.0000 1.0000
41.9200 394.0000 1.0000
41.9600 406.0000 1.0000
42.0000 390.0000 1.0000
42.0400 394.0000 1.0000
42.0800 414.0000 1.0000
42.1200 412.0000 1.0000
42.1600 431.0000 1.0000
42.2000 395.0000 1.0000
42.2400 410.0000 1.0000
42.2800 424.0000 1.0000
42.3200 435.0000 1.0000
42.3600 419.0000 1.0000
42.4000 432.0000 1.0000
42.4400 444.0000 1.0000
42.4800 419.0000 1.0000
42.5200 422.0000 1.0000
42.5600 402.0000 1.0000
42.6000 379.0000 1.0000
42.6400 434.0000 1.0000
42.6800 393.0000 1.0000
42.7200 381.0000 1.0000
42.7600 367.0000 1.0000
42.8000 439.0000 1.0000
42.8400 417.0000 1.0000
42.8800 388.0000 1.0000
42.9200 410.0000 1.0000
42.9600 352.0000 1.0000
43.0000 399.0000 1.0000
43.0400 415.0000 1.0000
43.0800 378.0000 1.0000
43.1200 404.0000 1.0000
43.1600 408.0000 1.0000
43.2000 401.0000 1.0000
43.2400 397.0000 1.0000
43.2800 366.0000 1.0000
43.3200 417.0000 1.0000
43.3600 407.0000 1.0000
43.4000 398.0000 1.0000
43.4400 387.0000 1.0000
43.4800 392.0000 1.0000
43.5200 403.0000 1.0000
43.5600 356.0000 1.0000
43.6000 365.0000 1.0000
43.6400 361.0000 1.0000
43.6800 387.0000 1.0000
43.7200 392.0000 1.0000
43.7600 376.0000 1.0000
43.8000 376.0000 1.0000
43.8400 403.0000 1.0000
43.8800 366.0000 1.0000
43.9200 344.0000 1.0000
43.9600 372.0000 1.0000
44.0000 366.0000 1.0000
44.0400 366.0000 1.0000
44.0800 403.0000 1.0000
44.1200 364.0000 1.0000
44.1600 378.0000 1.0000
44.2000 400.0000 1.0000
44.2400 388.0000 1.0000
44.2800 363.0000 1.0000
44.3200 376.0000 1.0000
44.3600 396.0000 1.0000
44.4000 364.0000 1.0000
44.4400 373.0000 1.0000
44.4800 365.0000 1.0000
44.5200 389.0000 1.0000
44.5600 408.0000 1.0000
44.6000 404.0000 1.0000
44.6400 368.0000 1.0000
44.6800 363.0000 1.0000
44.7200 365.0000 1.0000
44.7600 378.0000 1.0000
44.8000 386.0000 1.0000
44.8400 358.0000 1.0000
44.8800 334.0000 1.0000
44.9200 394.0000 1.0000
44.9600 350.0000 1.0000
45.0000 366.0000 1.0000
45.0400 366.0000 1.0000
45.0800 376.0000 1.0000
45.1200 373.0000 1.0000
45.1600 401.0000 1.0000
45.2000 369.0000 1.0000
45.2400 393.0000 1.0000
45.2800 385.0000 1.0000
45.3200 360.0000 1.0000
45.3600 379.0000 1.0000
45.4000 379.0000 1.0000
45.4400 387.0000 1.0000
45.4800 339.0000 1.0000
45.5200 366.0000 1.0000
45.5600 360.0000 1.0000
45.6000 363.0000 1.0000
45.6400 375.0000 1.0000
45.6800 357.0000 1.0000
45.7200 388.0000 1.0000
45.7600 393.0000 1.0000
45.8000 335.0000 1.0000
45.8400 388.0000 1.0000
45.8800 365.0000 1.0000
45.9200 360.0000 1.0000
45.9600 348.0000 1.0000
46.0000 352.0000 1.0000
46.0400 359.0000 1.0000
46.0800 344.0000 1.0000
46.1200 365.0000 1.0000
46.1600 384.0000 1.0000
46.2000 348.0000 1.0000
46.2400 394.0000 1.0000
46.2800 371.0000 1.0000
46.3200 363.0000 1.0000
46.3600 349.0000 1.0000
46.4000 370.0000 1.0000
46.4400 349.0000 1.0000
46.4800 362.0000 1.0000
46.5200 343.0000 1.0000
46.5600 360.0000 1.0000
46.6000 363.0000 1.0000
46.6400 375.0000 1.0000
46.6800 343.0000 1.0000
46.7200 365.0000 1.0000
46.7600 350.0000 1.0000
46.8000 341.0000 1.0000
46.8400 353.0000 1.0000
46.8800 352.0000 1.0000
46.9200 375.0000 1.0000
46.9600 353.0000 1.0000
47.0000 359.0000 1.0000
47.0400 336.0000 1.0000
47.0800 358.0000 1.0000
47.1200 346.0000 1.0000
47.1600 356.0000 1.0000
47.2000 380.0000 1.0000
47.2400 320.0000 1.0000
47.2800 362.0000 1.0000
47.3200 333.0000 1.0000
47.3600 352.0000 1.0000
47.4000 350.0000 1.0000
47.4400 354.0000 1.0000
47.4800 338.0000 1.0000
47.5200 351.0000 1.0000
47.5600 322.0000 1.0000
47.6000 338.0000 1.0000
47.6400 335.0000 1.0000
47.6800 372.0000 1.0000
47.7200 345.0000 1.0000
47.7600 329.0000 1.0000
47.8000 339.0000 1.0000
47.8400 364.0000 1.0000
47.8800 340.0000 1.0000
47.9200 364.0000 1.0000
47.9600 338.0000 1.0000
48.0000 322.0000 1.0000
48.0400 333.0000 1.0000
48.0800 323.0000 1.0000
48.1200 325.0000 1.0000
48.1600 346.0000 1.0000
48.2000 334.0000 1.0000
48.2400 357.0000 1.0000
48.2800 332.0000 1.0000
48.3200 365.0000 1.0000
48.3600 346.0000 1.0000
48.4000 334.0000 1.0000
48.4400 342.0000 1.0000
48.4800 349.0000 1.0000
48.5200 331.0000 1.0000
48.5600 324.0000 1.0000
48.6000 334.0000 1.0000
48.6400 370.0000 1.0000
48.6800 353.0000 1.0000
48.7200 345.0000 1.0000
48.7600 352.0000 1.0000
48.8000 348.0000 1.0000
48.8400 345.0000 1.0000
48.8800 317.0000 1.0000
48.9200 321.0000 1.0000
48.9600 337.0000 1.0000
49.0000 334.0000 1.0000
49.0400 356.0000 1.0000
49.0800 317.0000 1.0000
49.1200 355.0000 1.0000
49.1600 365.0000 1.0000
49.2000 341.0000 1.0000
49.2400 333.0000 1.0000
49.2800 337.0000 1.0000
49.3200 403.0000 1.0000
49.3600 360.0000 1.0000
49.4000 366.0000 1.0000
49.4400 398.0000 1.0000
49.4800 364.0000 1.0000
49.5200 378.0000 1.0000
49.5600 352.0000 1.0000
49.6000 341.0000 1.0000
49.6400 354.0000 1.0000
49.6800 342.0000 1.0000
49.7200 351.0000 1.0000
49.7600 347.0000 1.0000
49.8000 358.0000 1.0000
49.8400 334.0000 1.0000
49.8800 311.0000 1.0000
49.9200 341.0000 1.0000
49.9600 346.0000 1.0000
50.0000 352.0000 1.0000
50.0400 352.0000 1.0000
50.0800 385.0000 1.0000
50.1200 363.0000 1.0000
50.1600 353.0000 1.0000
50.2000 335.0000 1.0000
50.2400 348.0000 1.0000
50.2800 345.0000 1.0000
50.3200 345.0000 1.0000
50.3600 357.0000 1.0000
50.4000 326.0000 1.0000
50.4400 360.0000 1.0000
50.4800 362.0000 1.0000
50.5200 353.0000 1.0000
50.5600 362.0000 1.0000
50.6000 353.0000 1.0000
50.6400 350.0000 1.0000
50.6800 351.0000 1.0000
50.7200 362.0000 1.0000
50.7600 361.0000 1.0000
50.8000 337.0000 1.0000
50.8400 341.0000 1.0000
50.8800 392.0000 1.0000
50.9200 370.0000 1.0000
50.9600 372.0000 1.0000
51.0000 382.0000 1.0000
51.0400 350.0000 1.0000
51.0800 387.0000 1.0000
51.1200 417.0000 1.0000
51.1600 460.0000 1.0000
51.2000 507.0000 1.0000
51.2400 572.0000 1.0000
51.2800 610.0000 1.0000
51.3200 756.0000 1.0000
51.3600 1050.0000 1.0000
51.4000 1425.0000 1.0000
51.4400 1834.0000 1.0000
51.4800 2188.0000 1.0000
51.5200 2288.0000 1.0000
51.5600 2069.0000 1.0000
51.6000 1780.0000 1.0000
51.6400 1650.0000 1.0000
51.6800 1247.0000 1.0000
51.7200 953.0000 1.0000
51.7600 748.0000 1.0000
51.8000 593.0000 1.0000
51.8400 517.0000 1.0000
51.8800 474.0000 1.0000
51.9200 446.0000 1.0000
51.9600 408.0000 1.0000
52.0000 430.0000 1.0000
52.0400 386.0000 1.0000
52.0800 355.0000 1.0000
52.1200 381.0000 1.0000
52.1600 343.0000 1.0000
52.2000 357.0000 1.0000
52.2400 340.0000 1.0000
52.2800 356.0000 1.0000
52.3200 366.0000 1.0000
52.3600 379.0000 1.0000
52.4000 342.0000 1.0000
52.4400 353.0000 1.0000
52.4800 334.0000 1.0000
52.5200 348.0000 1.0000
52.5600 325.0000 1.0000
52.6000 333.0000 1.0000
52.6400 311.0000 1.0000
52.6800 326.0000 1.0000
52.7200 322.0000 1.0000
52.7600 334.0000 1.0000
52.8000 314.0000 1.0000
52.8400 336.0000 1.0000
52.8800 335.0000 1.0000
52.9200 312.0000 1.0000
52.9600 321.0000 1.0000
53.0000 349.0000 1.0000
53.0400 321.0000 1.0000
53.0800 342.0000 1.0000
53.1200 328.0000 1.0000
53.1600 323.0000 1.0000
53.2000 353.0000 1.0000
53.2400 332.0000 1.0000
53.2800 309.0000 1.0000
53.3200 328.0000 1.0000
53.3600 363.0000 1.0000
53.4000 336.0000 1.0000
53.4400 327.0000 1.0000
53.4800 311.0000 1.0000
53.5200 349.0000 1.0000
53.5600 306.0000 1.0000
53.6000 319.0000 1.0000
53.6400 328.0000 1.0000
53.6800 344.0000 1.0000
53.7200 359.0000 1.0000
53.7600 332.0000 1.0000
53.8000 324.0000 1.0000
53.8400 345.0000 1.0000
53.8800 351.0000 1.0000
53.9200 377.0000 1.0000
53.9600 346.0000 1.0000
54.0000 360.0000 1.0000
54.0400 346.0000 1.0000
54.0800 347.0000 1.0000
54.1200 348.0000 1.0000
54.1600 355.0000 1.0000
54.2000 339.0000 1.0000
54.2400 371.0000 1.0000
54.2800 369.0000 1.0000
54.3200 397.0000 1.0000
54.3600 378.0000 1.0000
54.4000 367.0000 1.0000
54.4400 472.0000 1.0000
54.4800 469.0000 1.0000
54.5200 480.0000 1.0000
54.5600 447.0000 1.0000
54.6000 478.0000 1.0000
54.6400 436.0000 1.0000
54.6800 450.0000 1.0000
54.7200 423.0000 1.0000
54.7600 393.0000 1.0000
54.8000 379.0000 1.0000
54.8400 395.0000 1.0000
54.8800 336.0000 1.0000
54.9200 346.0000 1.0000
54.9600 354.0000 1.0000
55.0000 326.0000 1.0000
55.0400 318.0000 1.0000
55.0800 328.0000 1.0000
55.1200 316.0000 1.0000
55.1600 304.0000 1.0000
55.2000 335.0000 1.0000
55.2400 332.0000 1.0000
55.2800 304.0000 1.0000
55.3200 299.0000 1.0000
55.3600 333.0000 1.0000
55.4000 331.0000 1.0000
55.4400 340.0000 1.0000
55.4800 330.0000 1.0000
55.5200 314.0000 1.0000
55.5600 326.0000 1.0000
55.6000 314.0000 1.0000
55.6400 322.0000 1.0000
55.6800 321.0000 1.0000
55.7200 332.0000 1.0000
55.7600 303.0000 1.0000
55.8000 312.0000 1.0000
55.8400 304.0000 1.0000
55.8800 299.0000 1.0000
55.9200 310.0000 1.0000
55.9600 338.0000 1.0000
56.0000 296.0000 1.0000
56.0400 314.0000 1.0000
56.0800 324.0000 1.0000
56.1200 305.0000 1.0000
56.1600 304.0000 1.0000
56.2000 319.0000 1.0000
56.2400 316.0000 1.0000
56.2800 321.0000 1.0000
56.3200 342.0000 1.0000
56.3600 322.0000 1.0000
56.4000 341.0000 1.0000
56.4400 318.0000 1.0000
56.4800 316.0000 1.0000
56.5200 335.0000 1.0000
56.5600 322.0000 1.0000
56.6000 305.0000 1.0000
56.6400 311.0000 1.0000
56.6800 306.0000 1.0000
56.7200 299.0000 1.0000
56.7600 331.0000 1.0000
56.8000 303.0000 1.0000
56.8400 293.0000 1.0000
56.8800 320.0000 1.0000
56.9200 330.0000 1.0000
56.9600 339.0000 1.0000
57.0000 300.0000 1.0000
57.0400 327.0000 1.0000
57.0800 286.0000 1.0000
57.1200 318.0000 1.0000
57.1600 338.0000 1.0000
57.2000 330.0000 1.0000
57.2400 330.0000 1.0000
57.2800 304.0000 1.0000
57.3200 296.0000 1.0000
57.3600 326.0000 1.0000
57.4000 330.0000 1.0000
57.4400 322.0000 1.0000
57.4800 322.0000 1.0000
57.5200 297.0000 1.0000
57.5600 317.0000 1.0000
57.6000 324.0000 1.0000
57.6400 320.0000 1.0000
57.6800 330.0000 1.0000
57.7200 289.0000 1.0000
57.7600 327.0000 1.0000
57.8000 317.0000 1.0000
57.8400 335.0000 1.0000
57.8800 335.0000 1.0000
57.9200 289.0000 1.0000
57.9600 331.0000 1.0000
58.0000 305.0000 1.0000
58.0400 292.0000 1.0000
58.0800 322.0000 1.0000
58.1200 315.0000 1.0000
58.1600 313.0000 1.0000
58.2000 331.0000 1.0000
58.2400 310.0000 1.0000
58.2800 291.0000 1.0000
58.3200 297.0000 1.0000
58.3600 310.0000 1.0000
58.4000 310.0000 1.0000
58.4400 354.0000 1.0000
58.4800 285.0000 1.0000
58.5200 333.0000 1.0000
58.5600 294.0000 1.0000
58.6000 286.0000 1.0000
58.6400 310.0000 1.0000
58.6800 310.0000 1.0000
58.7200 282.0000 1.0000
58.7600 335.0000 1.0000
58.8000 316.0000 1.0000
58.8400 298.0000 1.0000
58.8800 309.0000 1.0000
58.9200 312.0000 1.0000
58.9600 288.0000 1.0000
59.0000 320.0000 1.0000
59.0400 320.0000 1.0000
59.0800 296.0000 1.0000
59.1200 280.0000 1.0000
59.1600 312.0000 1.0000
59.2000 289.0000 1.0000
59.2400 283.0000 1.0000
59.2800 327.0000 1.0000
59.3200 319.0000 1.0000
59.3600 325.0000 1.0000
59.4000 299.0000 1.0000
59.4400 334.0000 1.0000
59.4800 324.0000 1.0000
59.5200 311.0000 1.0000
59.5600 320.0000 1.0000
59.6000 297.0000 1.0000
59.6400 311.0000 1.0000
59.6800 291.0000 1.0000
59.7200 294.0000 1.0000
59.7600 312.0000 1.0000
59.8000 318.0000 1.0000
59.8400 343.0000 1.0000
59.8800 335.0000 1.0000
59.9200 299.0000 1.0000
59.9600 303.0000 1.0000
60.0000 304.0000 1.0000
60.0400 312.0000 1.0000
60.0800 329.0000 1.0000
60.1200 296.0000 1.0000
60.1600 346.0000 1.0000
60.2000 333.0000 1.0000
60.2400 296.0000 1.0000
60.2800 312.0000 1.0000
60.3200 297.0000 1.0000
60.3600 336.0000 1.0000
60.4000 306.0000 1.0000
60.4400 333.0000 1.0000
60.4800 287.0000 1.0000
60.5200 317.0000 1.0000
60.5600 289.0000 1.0000
60.6000 342.0000 1.0000
60.6400 289.0000 1.0000
60.6800 332.0000 1.0000
60.7200 299.0000 1.0000
60.7600 307.0000 1.0000
60.8000 299.0000 1.0000
60.8400 308.0000 1.0000
60.8800 324.0000 1.0000
60.9200 308.0000 1.0000
60.9600 311.0000 1.0000
61.0000 302.0000 1.0000
61.0400 327.0000 1.0000
61.0800 346.0000 1.0000
61.1200 366.0000 1.0000
61.1600 345.0000 1.0000
61.2000 326.0000 1.0000
61.2400 376.0000 1.0000
61.2800 412.0000 1.0000
61.3200 409.0000 1.0000
61.3600 431.0000 1.0000
61.4000 469.0000 1.0000
61.4400 558.0000 1.0000
61.4800 594.0000 1.0000
61.5200 642.0000 1.0000
61.5600 614.0000 1.0000
61.6000 647.0000 1.0000
61.6400 635.0000 1.0000
61.6800 598.0000 1.0000
61.7200 516.0000 1.0000
61.7600 554.0000 1.0000
61.8000 461.0000 1.0000
61.8400 431.0000 1.0000
61.8800 420.0000 1.0000
61.9200 405.0000 1.0000
61.9600 341.0000 1.0000
62.0000 341.0000 1.0000
62.0400 357.0000 1.0000
62.0800 352.0000 1.0000
62.1200 326.0000 1.0000
62.1600 312.0000 1.0000
62.2000 362.0000 1.0000
62.2400 339.0000 1.0000
62.2800 333.0000 1.0000
62.3200 324.0000 1.0000
62.3600 363.0000 1.0000
62.4000 335.0000 1.0000
62.4400 356.0000 1.0000
62.4800 350.0000 1.0000
62.5200 357.0000 1.0000
62.5600 349.0000 1.0000
62.6000 331.0000 1.0000
62.6400 311.0000 1.0000
62.6800 311.0000 1.0000
62.7200 320.0000 1.0000
62.7600 309.0000 1.0000
62.8000 302.0000 1.0000
62.8400 280.0000 1.0000
62.8800 320.0000 1.0000
62.9200 318.0000 1.0000
62.9600 318.0000 1.0000
63.0000 307.0000 1.0000
63.0400 312.0000 1.0000
63.0800 303.0000 1.0000
63.1200 316.0000 1.0000
63.1600 298.0000 1.0000
63.2000 314.0000 1.0000
63.2400 288.0000 1.0000
63.2800 308.0000 1.0000
63.3200 327.0000 1.0000
63.3600 287.0000 1.0000
63.4000 304.0000 1.0000
63.4400 308.0000 1.0000
63.4800 327.0000 1.0000
63.5200 312.0000 1.0000
63.5600 296.0000 1.0000
63.6000 311.0000 1.0000
63.6400 321.0000 1.0000
63.6800 336.0000 1.0000
63.7200 347.0000 1.0000
63.7600 339.0000 1.0000
63.8000 345.0000 1.0000
63.8400 373.0000 1.0000
63.8800 428.0000 1.0000
63.9200 427.0000 1.0000
63.9600 418.0000 1.0000
64.0000 437.0000 1.0000
64.0400 448.0000 1.0000
64.0800 427.0000 1.0000
64.1200 399.0000 1.0000
64.1600 386.0000 1.0000
64.2000 400.0000 1.0000
64.2400 335.0000 1.0000
64.2800 356.0000 1.0000
64.3200 358.0000 1.0000
64.3600 337.0000 1.0000
64.4000 314.0000 1.0000
64.4400 353.0000 1.0000
64.4800 332.0000 1.0000
64.5200 322.0000 1.0000
64.5600 309.0000 1.0000
64.6000 323.0000 1.0000
64.6400 322.0000 1.0000
64.6800 322.0000 1.0000
64.7200 305.0000 1.0000
64.7600 337.0000 1.0000
64.8000 314.0000 1.0000
64.8400 338.0000 1.0000
64.8800 313.0000 1.0000
64.9200 338.0000 1.0000
64.9600 348.0000 1.0000
65.0000 328.0000 1.0000
65.0400 351.0000 1.0000
65.0800 339.0000 1.0000
65.1200 361.0000 1.0000
65.1600 368.0000 1.0000
65.2000 396.0000 1.0000
65.2400 400.0000 1.0000
65.2800 479.0000 1.0000
65.3200 501.0000 1.0000
65.3600 569.0000 1.0000
65.4000 669.0000 1.0000
65.4400 862.0000 1.0000
65.4800 990.0000 1.0000
65.5200 1164.0000 1.0000
65.5600 1120.0000 1.0000
65.6000 1139.0000 1.0000
65.6400 1003.0000 1.0000
65.6800 972.0000 1.0000
65.7200 935.0000 1.0000
65.7600 826.0000 1.0000
65.8000 704.0000 1.0000
65.8400 630.0000 1.0000
65.8800 495.0000 1.0000
65.9200 469.0000 1.0000
65.9600 401.0000 1.0000
66.0000 409.0000 1.0000
66.0400 376.0000 1.0000
66.0800 361.0000 1.0000
66.1200 339.0000 1.0000
66.1600 332.0000 1.0000
66.2000 339.0000 1.0000
66.2400 297.0000 1.0000
66.2800 300.0000 1.0000
66.3200 335.0000 1.0000
66.3600 300.0000 1.0000
66.4000 325.0000 1.0000
66.4400 318.0000 1.0000
66.4800 303.0000 1.0000
66.5200 311.0000 1.0000
66.5600 284.0000 1.0000
66.6000 302.0000 1.0000
66.6400 290.0000 1.0000
66.6800 300.0000 1.0000
66.7200 297.0000 1.0000
66.7600 297.0000 1.0000
66.8000 290.0000 1.0000
66.8400 286.0000 1.0000
66.8800 302.0000 1.0000
66.9200 291.0000 1.0000
66.9600 299.0000 1.0000
67.0000 288.0000 1.0000
67.0400 277.0000 1.0000
67.0800 277.0000 1.0000
67.1200 291.0000 1.0000
67.1600 321.0000 1.0000
67.2000 305.0000 1.0000
67.2400 316.0000 1.0000
67.2800 307.0000 1.0000
67.3200 274.0000 1.0000
67.3600 285.0000 1.0000
67.4000 279.0000 1.0000
67.4400 295.0000 1.0000
67.4800 311.0000 1.0000
67.5200 288.0000 1.0000
67.5600 291.0000 1.0000
67.6000 282.0000 1.0000
67.6400 261.0000 1.0000
67.6800 280.0000 1.0000
67.7200 255.0000 1.0000
67.7600 275.0000 1.0000
67.8000 267.0000 1.0000
67.8400 284.0000 1.0000
67.8800 302.0000 1.0000
67.9200 264.0000 1.0000
67.9600 271.0000 1.0000
68.0000 290.0000 1.0000
68.0400 275.0000 1.0000
68.0800 297.0000 1.0000
68.1200 276.0000 1.0000
68.1600 276.0000 1.0000
68.2000 265.0000 1.0000
68.2400 330.0000 1.0000
68.2800 263.0000 1.0000
68.3200 282.0000 1.0000
68.3600 285.0000 1.0000
68.4000 295.0000 1.0000
68.4400 283.0000 1.0000
68.4800 263.0000 1.0000
68.5200 271.0000 1.0000
68.5600 275.0000 1.0000
68.6000 268.0000 1.0000
68.6400 283.0000 1.0000
68.6800 298.0000 1.0000
68.7200 279.0000 1.0000
68.7600 268.0000 1.0000
68.8000 299.0000 1.0000
68.8400 284.0000 1.0000
68.8800 292.0000 1.0000
68.9200 274.0000 1.0000
68.9600 292.0000 1.0000
69.0000 274.0000 1.0000
69.0400 288.0000 1.0000
69.0800 306.0000 1.0000
69.1200 272.0000 1.0000
69.1600 267.0000 1.0000
69.2000 237.0000 1.0000
69.2400 269.0000 1.0000
69.2800 290.0000 1.0000
69.3200 257.0000 1.0000
69.3600 280.0000 1.0000
69.4000 271.0000 1.0000
69.4400 248.0000 1.0000
69.4800 290.0000 1.0000
69.5200 280.0000 1.0000
69.5600 268.0000 1.0000
69.6000 295.0000 1.0000
69.6400 274.0000 1.0000
69.6800 273.0000 1.0000
69.7200 247.0000 1.0000
69.7600 247.0000 1.0000
69.8000 257.0000 1.0000
69.8400 267.0000 1.0000
69.8800 268.0000 1.0000
69.9200 265.0000 1.0000
69.9600 272.0000 1.0000
70.0000 260.0000 1.0000
*RAS_INT_END
*RAS_TEMPERATURE_START
*RAS_TEMPERATURE_END
*RAS_DATA_END