File: Data/Dataset1_Only_water/5_XRD/No_025_VS2_4.ras
*RAS_DATA_START
*RAS_HEADER_START
*DISP_FMT_X "%.2f"
*DISP_FMT_Y "%.0f"
*DISP_FULLSCALE "16892.0000000000"
*DISP_LINE_COLOR "255.0000000000"
*DISP_LINE_STYLE "0.0000000000"
*DISP_LINE_WIDTH "0.2500000000"
*DISP_NOTE "測定データ-4"
*DISP_OFFSET_Y "0.0000000000"
*DISP_PEAKSEARCH_UNIT_Y "cps"
*DISP_RANGE_BOTTOM "0.0000000000"
*DISP_RANGE_LEFT "20.0000000000"
*DISP_RANGE_LOGCUTOFF "0.0100000000"
*DISP_RANGE_RIGHT "70.0000000000"
*DISP_RANGE_TOP "16892.0000000000"
*DISP_SCALE_MODE_Y "0.0000000000"
*DISP_TAB_NAME "2θ/θ"
*DISP_TITLE_Y "強度"
*DISP_UNIT_Y "cps"
*DISP_WINDOW_NAME "MSG_MACROENGINE"
*FILE_COMMENT " "
*FILE_MD5 ""
*FILE_MEMO " "
*FILE_OPERATOR "Administrator"
*FILE_SAMPLE " "
*FILE_TYPE "RAS_RAW"
*FILE_USERGROUP "システムマネージャ"
*FILE_VERSION "1.0000000000"
*HW_ATTACHMENT_ID "ATT0025"
*HW_ATTACHMENT_NAME "標準|Standard"
*HW_COUNTER_ID-0 "CUT0025"
*HW_COUNTER_ID-1 "CUT0020"
*HW_COUNTER_ID-2 "CUT0020"
*HW_COUNTER_ID-3 "CSL0021"
*HW_COUNTER_ID-4 "CMC0021"
*HW_COUNTER_NAME-0 "D/teX Ultra|D/teX Ultra"
*HW_COUNTER_NAME-1 "None|None"
*HW_COUNTER_NAME-2 "None|None"
*HW_COUNTER_NAME-3 "BBM|BBM"
*HW_COUNTER_NAME-4 "検出器モノクロメータ|Detector monochromator"
*HW_COUNTER_SELECT_NAME "D/teX Ultra|D/teX Ultra"
*HW_GONIOMETER_ID "GON0023"
*HW_GONIOMETER_NAME "SmartLab|SmartLab"
*HW_GONIOMETER_RADIUS-0 "90.0"
*HW_GONIOMETER_RADIUS-1 "114.0"
*HW_GONIOMETER_RADIUS-2 "190.0"
*HW_GONIOMETER_RADIUS-3 "300.0"
*HW_GONIOMETER_RADIUS-4 "187.0"
*HW_GONIOMETER_RADIUS-5 "300.0"
*HW_GONIOMETER_RADIUS-6 "113.0"
*HW_GONIOMETER_RADIUS-7 "331.0"
*HW_I_OPT_ID-0 "CBO0021"
*HW_I_OPT_ID-1 "ICR0023"
*HW_I_OPT_ID-2 "ISL0021"
*HW_I_OPT_ID-3 "ISO0021"
*HW_I_OPT_ID-4 "IAD0021"
*HW_I_OPT_ID-5 "IPR0001"
*HW_I_OPT_NAME-0 "CBOユニット|CBO unit"
*HW_I_OPT_NAME-1 "標準入射光学ユニット|Standard incident optical unit"
*HW_I_OPT_NAME-2 "標準入射スリットボックス|Standard incident slit box"
*HW_I_OPT_NAME-3 "入射平行スリット|Incident parallel slit"
*HW_I_OPT_NAME-4 "長手制限スリット|Length limiting slit"
*HW_I_OPT_NAME-5 "None|None"
*HW_R_ATTENUATER_AUTOMODE "0"
*HW_R_OPT_ID-0 "RSS0021"
*HW_R_OPT_ID-1 "RCR0023"
*HW_R_OPT_ID-2 "RSO0021"
*HW_R_OPT_ID-3 "RRS0021"
*HW_R_OPT_ID-4 "ATN0021"
*HW_R_OPT_ID-5 "RFL0021"
*HW_R_OPT_ID-6 "RAD0021"
*HW_R_OPT_NAME-0 "標準受光スリットボックス1|Standard receiving slit box # 1"
*HW_R_OPT_NAME-1 "標準受光光学ユニット1|Standard receiving unit # 1"
*HW_R_OPT_NAME-2 "標準受光光学ユニット2|Standard receiving optical unit # 2"
*HW_R_OPT_NAME-3 "標準受光スリットボックス2|Standard receiving slit box # 2"
*HW_R_OPT_NAME-4 "標準アッテネータ|Standard Attenuator"
*HW_R_OPT_NAME-5 "Cu Kβ|Cu K-beta"
*HW_R_OPT_NAME-6 "調整用受光スリット|Alignment receiving slit"
*HW_SAMPLE_HOLDER_ID "SMP0023"
*HW_SAMPLE_HOLDER_NAME "標準Zステージ|Standard Z stage"
*HW_XG_CURRENT_MAX "50"
*HW_XG_CURRENT_MIN "2"
*HW_XG_CURRENT_RESOLUTION "1"
*HW_XG_CURRENT_UNIT "mA"
*HW_XG_FOCUS "1mm x 10mm"
*HW_XG_FOCUS_TYPE "Normal"
*HW_XG_ID ""
*HW_XG_NAME "3kW 封入管(ID:1200)|3kW Sealed tube(ID:1200)"
*HW_XG_TARGET_ATOMIC_NUMBER "29.0000000000"
*HW_XG_TARGET_NAME "Cu"
*HW_XG_TYPE "Hermetic"
*HW_XG_VOLTAGE_MAX "60"
*HW_XG_VOLTAGE_MIN "20"
*HW_XG_VOLTAGE_RESOLUTION "1"
*HW_XG_VOLTAGE_UNIT "kV"
*HW_XG_WATT_MAX "1.500"
*HW_XG_WATT_UNIT "kW"
*HW_XG_WAVE_LENGTH_ALPHA1 "1.540593"
*HW_XG_WAVE_LENGTH_ALPHA2 "1.544414"
*HW_XG_WAVE_LENGTH_BETA "1.392250"
*MEAS_COND_AXIS_NAME-0 "2θ/θ"
*MEAS_COND_AXIS_NAME-1 "2θ"
*MEAS_COND_AXIS_NAME-2 "ω"
*MEAS_COND_AXIS_NAME-3 "Z"
*MEAS_COND_AXIS_NAME-4 "2θ/ω"
*MEAS_COND_AXIS_NAME-5 "θs"
*MEAS_COND_AXIS_NAME-6 "θd"
*MEAS_COND_AXIS_NAME-7 "Ts"
*MEAS_COND_AXIS_NAME-8 "CBO選択スリット"
*MEAS_COND_AXIS_NAME-9 "M"
*MEAS_COND_AXIS_NAME-10 "入射平行スリット"
*MEAS_COND_AXIS_NAME-11 "入射スリット"
*MEAS_COND_AXIS_NAME-12 ""
*MEAS_COND_AXIS_NAME-13 "Zs"
*MEAS_COND_AXIS_NAME-14 "入射光学素子"
*MEAS_COND_AXIS_NAME-15 "長手制限スリット"
*MEAS_COND_AXIS_NAME-16 "センタースリット"
*MEAS_COND_AXIS_NAME-17 "フィルター"
*MEAS_COND_AXIS_NAME-18 "受光スリット1"
*MEAS_COND_AXIS_NAME-19 "受光スリット2"
*MEAS_COND_AXIS_NAME-20 "受光光学素子"
*MEAS_COND_AXIS_NAME-21 "受光平行スリット"
*MEAS_COND_AXIS_NAME-22 "調整用受光スリット"
*MEAS_COND_AXIS_NAME-23 ""
*MEAS_COND_AXIS_NAME-24 ""
*MEAS_COND_AXIS_NAME-25 "Zd"
*MEAS_COND_AXIS_NAME-26 "アッテネータ"
*MEAS_COND_AXIS_NAME-27 "検出器モノクロメータ"
*MEAS_COND_AXIS_NAME-28 "モノクロメータスリット"
*MEAS_COND_AXIS_NAME-29 "プライマリビーム"
*MEAS_COND_AXIS_NAME-30 "PHA"
*MEAS_COND_AXIS_NAME_INTERNAL-0 "TwoThetaTheta"
*MEAS_COND_AXIS_NAME_INTERNAL-1 "TwoTheta"
*MEAS_COND_AXIS_NAME_INTERNAL-2 "Omega"
*MEAS_COND_AXIS_NAME_INTERNAL-3 "Z"
*MEAS_COND_AXIS_NAME_INTERNAL-4 "TwoThetaOmega"
*MEAS_COND_AXIS_NAME_INTERNAL-5 "ThetaS"
*MEAS_COND_AXIS_NAME_INTERNAL-6 "ThetaD"
*MEAS_COND_AXIS_NAME_INTERNAL-7 "Ts"
*MEAS_COND_AXIS_NAME_INTERNAL-8 "CBO"
*MEAS_COND_AXIS_NAME_INTERNAL-9 "CBO-M"
*MEAS_COND_AXIS_NAME_INTERNAL-10 "IncidentSollerSlit"
*MEAS_COND_AXIS_NAME_INTERNAL-11 "IncidentSlitBox"
*MEAS_COND_AXIS_NAME_INTERNAL-12 "IncidentSlitBox-_Axis"
*MEAS_COND_AXIS_NAME_INTERNAL-13 "Zs"
*MEAS_COND_AXIS_NAME_INTERNAL-14 "IncidentMonochromator"
*MEAS_COND_AXIS_NAME_INTERNAL-15 "IncidentAxdSlit"
*MEAS_COND_AXIS_NAME_INTERNAL-16 "CenterSlit"
*MEAS_COND_AXIS_NAME_INTERNAL-17 "Filter"
*MEAS_COND_AXIS_NAME_INTERNAL-18 "ReceivingSlitBox1"
*MEAS_COND_AXIS_NAME_INTERNAL-19 "ReceivingSlitBox2"
*MEAS_COND_AXIS_NAME_INTERNAL-20 "ReceivingOptics"
*MEAS_COND_AXIS_NAME_INTERNAL-21 "ReceivingSollerSlit"
*MEAS_COND_AXIS_NAME_INTERNAL-22 "ReceivingAxdSlit"
*MEAS_COND_AXIS_NAME_INTERNAL-23 "ReceivingSlitBox1-_Axis"
*MEAS_COND_AXIS_NAME_INTERNAL-24 "ReceivingSlitBox2-_Axis"
*MEAS_COND_AXIS_NAME_INTERNAL-25 "ReceivingSlitBox2-Zd"
*MEAS_COND_AXIS_NAME_INTERNAL-26 "Attenuator"
*MEAS_COND_AXIS_NAME_INTERNAL-27 "CounterMonochromator"
*MEAS_COND_AXIS_NAME_INTERNAL-28 "CounterSlit"
*MEAS_COND_AXIS_NAME_INTERNAL-29 "IncidentPrimary"
*MEAS_COND_AXIS_NAME_INTERNAL-30 "PHA"
*MEAS_COND_AXIS_NAME_MAGICNO-0 "83951616.0000000000"
*MEAS_COND_AXIS_NAME_MAGICNO-1 "268632064.0000000000"
*MEAS_COND_AXIS_NAME_MAGICNO-2 "268500992.0000000000"
*MEAS_COND_AXIS_NAME_MAGICNO-3 "285278208.0000000000"
*MEAS_COND_AXIS_NAME_MAGICNO-4 "83951616.0000000000"
*MEAS_COND_AXIS_NAME_MAGICNO-5 "131072.0000000000"
*MEAS_COND_AXIS_NAME_MAGICNO-6 "131072.0000000000"
*MEAS_COND_AXIS_NAME_MAGICNO-7 "318898176.0000000000"
*MEAS_COND_AXIS_NAME_MAGICNO-8 "20971521.0000000000"
*MEAS_COND_AXIS_NAME_MAGICNO-9 "285343744.0000000000"
*MEAS_COND_AXIS_NAME_MAGICNO-10 "20971521.0000000000"
*MEAS_COND_AXIS_NAME_MAGICNO-11 "22020097.0000000000"
*MEAS_COND_AXIS_NAME_MAGICNO-12 "25165824.0000000000"
*MEAS_COND_AXIS_NAME_MAGICNO-13 "318898176.0000000000"
*MEAS_COND_AXIS_NAME_MAGICNO-14 "1.0000000000"
*MEAS_COND_AXIS_NAME_MAGICNO-15 "20971521.0000000000"
*MEAS_COND_AXIS_NAME_MAGICNO-16 "20971521.0000000000"
*MEAS_COND_AXIS_NAME_MAGICNO-17 "20971521.0000000000"
*MEAS_COND_AXIS_NAME_MAGICNO-18 "23068673.0000000000"
*MEAS_COND_AXIS_NAME_MAGICNO-19 "23068673.0000000000"
*MEAS_COND_AXIS_NAME_MAGICNO-20 "20971521.0000000000"
*MEAS_COND_AXIS_NAME_MAGICNO-21 "20971521.0000000000"
*MEAS_COND_AXIS_NAME_MAGICNO-22 "20971521.0000000000"
*MEAS_COND_AXIS_NAME_MAGICNO-23 "25165824.0000000000"
*MEAS_COND_AXIS_NAME_MAGICNO-24 "25165824.0000000000"
*MEAS_COND_AXIS_NAME_MAGICNO-25 "285343744.0000000000"
*MEAS_COND_AXIS_NAME_MAGICNO-26 "17301505.0000000000"
*MEAS_COND_AXIS_NAME_MAGICNO-27 "20971521.0000000000"
*MEAS_COND_AXIS_NAME_MAGICNO-28 "20971521.0000000000"
*MEAS_COND_AXIS_NAME_MAGICNO-29 "20971521.0000000000"
*MEAS_COND_AXIS_NAME_MAGICNO-30 "0.0000000000"
*MEAS_COND_AXIS_OFFSET-0 "-"
*MEAS_COND_AXIS_OFFSET-1 "-0.1081000000"
*MEAS_COND_AXIS_OFFSET-2 "0.3758000000"
*MEAS_COND_AXIS_OFFSET-3 "-"
*MEAS_COND_AXIS_OFFSET-4 "-"
*MEAS_COND_AXIS_OFFSET-5 "0.3758000000"
*MEAS_COND_AXIS_OFFSET-6 "-0.4839000000"
*MEAS_COND_AXIS_OFFSET-7 "-"
*MEAS_COND_AXIS_OFFSET-8 "-"
*MEAS_COND_AXIS_OFFSET-9 "-"
*MEAS_COND_AXIS_OFFSET-10 "-"
*MEAS_COND_AXIS_OFFSET-11 "-"
*MEAS_COND_AXIS_OFFSET-12 "-"
*MEAS_COND_AXIS_OFFSET-13 "-"
*MEAS_COND_AXIS_OFFSET-14 "-"
*MEAS_COND_AXIS_OFFSET-15 "-"
*MEAS_COND_AXIS_OFFSET-16 "-"
*MEAS_COND_AXIS_OFFSET-17 "-"
*MEAS_COND_AXIS_OFFSET-18 "-"
*MEAS_COND_AXIS_OFFSET-19 "-"
*MEAS_COND_AXIS_OFFSET-20 "-"
*MEAS_COND_AXIS_OFFSET-21 "-"
*MEAS_COND_AXIS_OFFSET-22 "-"
*MEAS_COND_AXIS_OFFSET-23 "-"
*MEAS_COND_AXIS_OFFSET-24 "-"
*MEAS_COND_AXIS_OFFSET-25 "-"
*MEAS_COND_AXIS_OFFSET-26 "-"
*MEAS_COND_AXIS_OFFSET-27 "-"
*MEAS_COND_AXIS_OFFSET-28 "-"
*MEAS_COND_AXIS_OFFSET-29 "-"
*MEAS_COND_AXIS_OFFSET-30 "-"
*MEAS_COND_AXIS_POSITION-0 "0.0000000000"
*MEAS_COND_AXIS_POSITION-1 "0.0000000000"
*MEAS_COND_AXIS_POSITION-2 "0.0000000000"
*MEAS_COND_AXIS_POSITION-3 "-0.5500000000"
*MEAS_COND_AXIS_POSITION-4 "0.0000000000"
*MEAS_COND_AXIS_POSITION-5 "0.0000000000"
*MEAS_COND_AXIS_POSITION-6 "0.0000000000"
*MEAS_COND_AXIS_POSITION-7 "-0.4278800000"
*MEAS_COND_AXIS_POSITION-8 "BB"
*MEAS_COND_AXIS_POSITION-9 "0.0000000000"
*MEAS_COND_AXIS_POSITION-10 "Soller_slit_5.0deg"
*MEAS_COND_AXIS_POSITION-11 "2/3deg"
*MEAS_COND_AXIS_POSITION-12 "2.2088000000"
*MEAS_COND_AXIS_POSITION-13 "-0.4140600000"
*MEAS_COND_AXIS_POSITION-14 "0.0000000000"
*MEAS_COND_AXIS_POSITION-15 "10.0mm"
*MEAS_COND_AXIS_POSITION-16 "None"
*MEAS_COND_AXIS_POSITION-17 "Cu_K-beta"
*MEAS_COND_AXIS_POSITION-18 "13.000mm"
*MEAS_COND_AXIS_POSITION-19 "13.000mm"
*MEAS_COND_AXIS_POSITION-20 "No_unit"
*MEAS_COND_AXIS_POSITION-21 "Soller_slit_5.0deg"
*MEAS_COND_AXIS_POSITION-22 "None"
*MEAS_COND_AXIS_POSITION-23 "13.0000000000"
*MEAS_COND_AXIS_POSITION-24 "13.0000000000"
*MEAS_COND_AXIS_POSITION-25 "0.0109400000"
*MEAS_COND_AXIS_POSITION-26 "Open"
*MEAS_COND_AXIS_POSITION-27 "None"
*MEAS_COND_AXIS_POSITION-28 "None"
*MEAS_COND_AXIS_POSITION-29 "None"
*MEAS_COND_AXIS_POSITION-30 "38.0000000000"
*MEAS_COND_AXIS_UNIT-0 "deg"
*MEAS_COND_AXIS_UNIT-1 "deg"
*MEAS_COND_AXIS_UNIT-2 "deg"
*MEAS_COND_AXIS_UNIT-3 "mm"
*MEAS_COND_AXIS_UNIT-4 "deg"
*MEAS_COND_AXIS_UNIT-5 "deg"
*MEAS_COND_AXIS_UNIT-6 "deg"
*MEAS_COND_AXIS_UNIT-7 "mm"
*MEAS_COND_AXIS_UNIT-8 ""
*MEAS_COND_AXIS_UNIT-9 "pulse"
*MEAS_COND_AXIS_UNIT-10 ""
*MEAS_COND_AXIS_UNIT-11 ""
*MEAS_COND_AXIS_UNIT-12 "mm"
*MEAS_COND_AXIS_UNIT-13 "mm"
*MEAS_COND_AXIS_UNIT-14 ""
*MEAS_COND_AXIS_UNIT-15 ""
*MEAS_COND_AXIS_UNIT-16 ""
*MEAS_COND_AXIS_UNIT-17 ""
*MEAS_COND_AXIS_UNIT-18 ""
*MEAS_COND_AXIS_UNIT-19 ""
*MEAS_COND_AXIS_UNIT-20 ""
*MEAS_COND_AXIS_UNIT-21 ""
*MEAS_COND_AXIS_UNIT-22 ""
*MEAS_COND_AXIS_UNIT-23 "mm"
*MEAS_COND_AXIS_UNIT-24 "mm"
*MEAS_COND_AXIS_UNIT-25 "mm"
*MEAS_COND_AXIS_UNIT-26 ""
*MEAS_COND_AXIS_UNIT-27 ""
*MEAS_COND_AXIS_UNIT-28 ""
*MEAS_COND_AXIS_UNIT-29 ""
*MEAS_COND_AXIS_UNIT-30 "div"
*MEAS_COND_COUNTER_CNTLOSS_CORR "0.0000000000"
*MEAS_COND_COUNTER_PHABASE "38.0000000000"
*MEAS_COND_COUNTER_PHAWINDOW "16.0000000000"
*MEAS_COND_COUNTER_PHA_UNIT "div"
*MEAS_COND_COUNTER_TAUDIFF "30.0000000000"
*MEAS_COND_COUNTER_TAUINT "0.0000000000"
*MEAS_COND_IRRADIATION_MODE "OFF"
*MEAS_COND_IRRADIATION_WIDTH ""
*MEAS_COND_OPT_ATTR "集中法"
*MEAS_COND_OPT_NAME "@集中法"
*MEAS_COND_UNSYMMETRIC_MODE "OFF"
*MEAS_COND_XG_CURRENT "30.0000000000"
*MEAS_COND_XG_VOLTAGE "40.0000000000"
*MEAS_COND_XG_WAVE_TYPE "Ka"
*MEAS_DATA_COUNT "5001.0000000000"
*MEAS_SCAN_AXIS_X "2θ/θ"
*MEAS_SCAN_AXIS_X_INTERNAL "TwoThetaTheta"
*MEAS_SCAN_END_TIME "07/20/21 14:03:53"
*MEAS_SCAN_MODE "CONTINUOUS"
*MEAS_SCAN_MONITOR "0"
*MEAS_SCAN_RESOLUTION_X "0.0002"
*MEAS_SCAN_SPEED "1.0"
*MEAS_SCAN_SPEED_UNIT "deg/min"
*MEAS_SCAN_START "20.0000000000"
*MEAS_SCAN_START_TIME "07/20/21 13:11:00"
*MEAS_SCAN_STEP "0.0100000000"
*MEAS_SCAN_STOP "70.0000000000"
*MEAS_SCAN_UNIT_X "deg"
*MEAS_SCAN_UNIT_Y "counts"
*RAS_HEADER_END
*RAS_INT_START
20.0000 1713.0000 1.0000
20.0400 1659.0000 1.0000
20.0800 1693.0000 1.0000
20.1200 1700.0000 1.0000
20.1600 1637.0000 1.0000
20.2000 1668.0000 1.0000
20.2400 1749.0000 1.0000
20.2800 1673.0000 1.0000
20.3200 1676.0000 1.0000
20.3600 1601.0000 1.0000
20.4000 1595.0000 1.0000
20.4400 1672.0000 1.0000
20.4800 1681.0000 1.0000
20.5200 1645.0000 1.0000
20.5600 1747.0000 1.0000
20.6000 1592.0000 1.0000
20.6400 1678.0000 1.0000
20.6800 1634.0000 1.0000
20.7200 1697.0000 1.0000
20.7600 1650.0000 1.0000
20.8000 1696.0000 1.0000
20.8400 1678.0000 1.0000
20.8800 1653.0000 1.0000
20.9200 1705.0000 1.0000
20.9600 1663.0000 1.0000
21.0000 1667.0000 1.0000
21.0400 1637.0000 1.0000
21.0800 1728.0000 1.0000
21.1200 1665.0000 1.0000
21.1600 1650.0000 1.0000
21.2000 1677.0000 1.0000
21.2400 1673.0000 1.0000
21.2800 1624.0000 1.0000
21.3200 1684.0000 1.0000
21.3600 1700.0000 1.0000
21.4000 1709.0000 1.0000
21.4400 1710.0000 1.0000
21.4800 1711.0000 1.0000
21.5200 1645.0000 1.0000
21.5600 1691.0000 1.0000
21.6000 1698.0000 1.0000
21.6400 1683.0000 1.0000
21.6800 1659.0000 1.0000
21.7200 1762.0000 1.0000
21.7600 1721.0000 1.0000
21.8000 1670.0000 1.0000
21.8400 1724.0000 1.0000
21.8800 1688.0000 1.0000
21.9200 1653.0000 1.0000
21.9600 1678.0000 1.0000
22.0000 1683.0000 1.0000
22.0400 1723.0000 1.0000
22.0800 1715.0000 1.0000
22.1200 1655.0000 1.0000
22.1600 1677.0000 1.0000
22.2000 1714.0000 1.0000
22.2400 1691.0000 1.0000
22.2800 1725.0000 1.0000
22.3200 1770.0000 1.0000
22.3600 1628.0000 1.0000
22.4000 1741.0000 1.0000
22.4400 1676.0000 1.0000
22.4800 1660.0000 1.0000
22.5200 1714.0000 1.0000
22.5600 1722.0000 1.0000
22.6000 1735.0000 1.0000
22.6400 1755.0000 1.0000
22.6800 1804.0000 1.0000
22.7200 1747.0000 1.0000
22.7600 1673.0000 1.0000
22.8000 1800.0000 1.0000
22.8400 1724.0000 1.0000
22.8800 1749.0000 1.0000
22.9200 1728.0000 1.0000
22.9600 1725.0000 1.0000
23.0000 1715.0000 1.0000
23.0400 1793.0000 1.0000
23.0800 1762.0000 1.0000
23.1200 1753.0000 1.0000
23.1600 1728.0000 1.0000
23.2000 1788.0000 1.0000
23.2400 1739.0000 1.0000
23.2800 1755.0000 1.0000
23.3200 1731.0000 1.0000
23.3600 1698.0000 1.0000
23.4000 1720.0000 1.0000
23.4400 1705.0000 1.0000
23.4800 1832.0000 1.0000
23.5200 1752.0000 1.0000
23.5600 1802.0000 1.0000
23.6000 1702.0000 1.0000
23.6400 1760.0000 1.0000
23.6800 1746.0000 1.0000
23.7200 1808.0000 1.0000
23.7600 1808.0000 1.0000
23.8000 1751.0000 1.0000
23.8400 1784.0000 1.0000
23.8800 1825.0000 1.0000
23.9200 1812.0000 1.0000
23.9600 1770.0000 1.0000
24.0000 1671.0000 1.0000
24.0400 1770.0000 1.0000
24.0800 1787.0000 1.0000
24.1200 1748.0000 1.0000
24.1600 1730.0000 1.0000
24.2000 1767.0000 1.0000
24.2400 1755.0000 1.0000
24.2800 1790.0000 1.0000
24.3200 1770.0000 1.0000
24.3600 1845.0000 1.0000
24.4000 1766.0000 1.0000
24.4400 1788.0000 1.0000
24.4800 1783.0000 1.0000
24.5200 1779.0000 1.0000
24.5600 1828.0000 1.0000
24.6000 1786.0000 1.0000
24.6400 1780.0000 1.0000
24.6800 1853.0000 1.0000
24.7200 1876.0000 1.0000
24.7600 1846.0000 1.0000
24.8000 1760.0000 1.0000
24.8400 1845.0000 1.0000
24.8800 1767.0000 1.0000
24.9200 1794.0000 1.0000
24.9600 1832.0000 1.0000
25.0000 1808.0000 1.0000
25.0400 1787.0000 1.0000
25.0800 1814.0000 1.0000
25.1200 1810.0000 1.0000
25.1600 1844.0000 1.0000
25.2000 1897.0000 1.0000
25.2400 1808.0000 1.0000
25.2800 1822.0000 1.0000
25.3200 1809.0000 1.0000
25.3600 1913.0000 1.0000
25.4000 1898.0000 1.0000
25.4400 1836.0000 1.0000
25.4800 1840.0000 1.0000
25.5200 1796.0000 1.0000
25.5600 1752.0000 1.0000
25.6000 1737.0000 1.0000
25.6400 1855.0000 1.0000
25.6800 1809.0000 1.0000
25.7200 1772.0000 1.0000
25.7600 1820.0000 1.0000
25.8000 1816.0000 1.0000
25.8400 1807.0000 1.0000
25.8800 1807.0000 1.0000
25.9200 1837.0000 1.0000
25.9600 1823.0000 1.0000
26.0000 1842.0000 1.0000
26.0400 1803.0000 1.0000
26.0800 1875.0000 1.0000
26.1200 1847.0000 1.0000
26.1600 1756.0000 1.0000
26.2000 1838.0000 1.0000
26.2400 1882.0000 1.0000
26.2800 1842.0000 1.0000
26.3200 1868.0000 1.0000
26.3600 1815.0000 1.0000
26.4000 1919.0000 1.0000
26.4400 1907.0000 1.0000
26.4800 1890.0000 1.0000
26.5200 1879.0000 1.0000
26.5600 1865.0000 1.0000
26.6000 1840.0000 1.0000
26.6400 1984.0000 1.0000
26.6800 1990.0000 1.0000
26.7200 2100.0000 1.0000
26.7600 2052.0000 1.0000
26.8000 2019.0000 1.0000
26.8400 2073.0000 1.0000
26.8800 2246.0000 1.0000
26.9200 2246.0000 1.0000
26.9600 2522.0000 1.0000
27.0000 2641.0000 1.0000
27.0400 2993.0000 1.0000
27.0800 3289.0000 1.0000
27.1200 3986.0000 1.0000
27.1600 4866.0000 1.0000
27.2000 5924.0000 1.0000
27.2400 7155.0000 1.0000
27.2800 7728.0000 1.0000
27.3200 7125.0000 1.0000
27.3600 5920.0000 1.0000
27.4000 4783.0000 1.0000
27.4400 3835.0000 1.0000
27.4800 3236.0000 1.0000
27.5200 2887.0000 1.0000
27.5600 2621.0000 1.0000
27.6000 2417.0000 1.0000
27.6400 2223.0000 1.0000
27.6800 2155.0000 1.0000
27.7200 2078.0000 1.0000
27.7600 1992.0000 1.0000
27.8000 1971.0000 1.0000
27.8400 2001.0000 1.0000
27.8800 1948.0000 1.0000
27.9200 1841.0000 1.0000
27.9600 1852.0000 1.0000
28.0000 1803.0000 1.0000
28.0400 1745.0000 1.0000
28.0800 1848.0000 1.0000
28.1200 1787.0000 1.0000
28.1600 1813.0000 1.0000
28.2000 1829.0000 1.0000
28.2400 1739.0000 1.0000
28.2800 1802.0000 1.0000
28.3200 1783.0000 1.0000
28.3600 1748.0000 1.0000
28.4000 1744.0000 1.0000
28.4400 1676.0000 1.0000
28.4800 1708.0000 1.0000
28.5200 1683.0000 1.0000
28.5600 1685.0000 1.0000
28.6000 1690.0000 1.0000
28.6400 1698.0000 1.0000
28.6800 1674.0000 1.0000
28.7200 1629.0000 1.0000
28.7600 1769.0000 1.0000
28.8000 1666.0000 1.0000
28.8400 1664.0000 1.0000
28.8800 1676.0000 1.0000
28.9200 1717.0000 1.0000
28.9600 1667.0000 1.0000
29.0000 1635.0000 1.0000
29.0400 1753.0000 1.0000
29.0800 1686.0000 1.0000
29.1200 1631.0000 1.0000
29.1600 1660.0000 1.0000
29.2000 1625.0000 1.0000
29.2400 1674.0000 1.0000
29.2800 1651.0000 1.0000
29.3200 1691.0000 1.0000
29.3600 1593.0000 1.0000
29.4000 1640.0000 1.0000
29.4400 1665.0000 1.0000
29.4800 1599.0000 1.0000
29.5200 1573.0000 1.0000
29.5600 1568.0000 1.0000
29.6000 1552.0000 1.0000
29.6400 1596.0000 1.0000
29.6800 1574.0000 1.0000
29.7200 1620.0000 1.0000
29.7600 1629.0000 1.0000
29.8000 1591.0000 1.0000
29.8400 1603.0000 1.0000
29.8800 1602.0000 1.0000
29.9200 1541.0000 1.0000
29.9600 1488.0000 1.0000
30.0000 1595.0000 1.0000
30.0400 1528.0000 1.0000
30.0800 1583.0000 1.0000
30.1200 1568.0000 1.0000
30.1600 1599.0000 1.0000
30.2000 1569.0000 1.0000
30.2400 1589.0000 1.0000
30.2800 1611.0000 1.0000
30.3200 1556.0000 1.0000
30.3600 1547.0000 1.0000
30.4000 1562.0000 1.0000
30.4400 1573.0000 1.0000
30.4800 1523.0000 1.0000
30.5200 1580.0000 1.0000
30.5600 1548.0000 1.0000
30.6000 1550.0000 1.0000
30.6400 1529.0000 1.0000
30.6800 1533.0000 1.0000
30.7200 1540.0000 1.0000
30.7600 1558.0000 1.0000
30.8000 1511.0000 1.0000
30.8400 1522.0000 1.0000
30.8800 1524.0000 1.0000
30.9200 1593.0000 1.0000
30.9600 1527.0000 1.0000
31.0000 1499.0000 1.0000
31.0400 1483.0000 1.0000
31.0800 1464.0000 1.0000
31.1200 1518.0000 1.0000
31.1600 1542.0000 1.0000
31.2000 1514.0000 1.0000
31.2400 1509.0000 1.0000
31.2800 1505.0000 1.0000
31.3200 1508.0000 1.0000
31.3600 1479.0000 1.0000
31.4000 1479.0000 1.0000
31.4400 1593.0000 1.0000
31.4800 1441.0000 1.0000
31.5200 1434.0000 1.0000
31.5600 1496.0000 1.0000
31.6000 1497.0000 1.0000
31.6400 1501.0000 1.0000
31.6800 1453.0000 1.0000
31.7200 1514.0000 1.0000
31.7600 1469.0000 1.0000
31.8000 1494.0000 1.0000
31.8400 1476.0000 1.0000
31.8800 1510.0000 1.0000
31.9200 1518.0000 1.0000
31.9600 1526.0000 1.0000
32.0000 1526.0000 1.0000
32.0400 1530.0000 1.0000
32.0800 1464.0000 1.0000
32.1200 1535.0000 1.0000
32.1600 1453.0000 1.0000
32.2000 1524.0000 1.0000
32.2400 1442.0000 1.0000
32.2800 1490.0000 1.0000
32.3200 1456.0000 1.0000
32.3600 1438.0000 1.0000
32.4000 1472.0000 1.0000
32.4400 1457.0000 1.0000
32.4800 1427.0000 1.0000
32.5200 1414.0000 1.0000
32.5600 1472.0000 1.0000
32.6000 1429.0000 1.0000
32.6400 1401.0000 1.0000
32.6800 1352.0000 1.0000
32.7200 1482.0000 1.0000
32.7600 1360.0000 1.0000
32.8000 1336.0000 1.0000
32.8400 1447.0000 1.0000
32.8800 1361.0000 1.0000
32.9200 1387.0000 1.0000
32.9600 1374.0000 1.0000
33.0000 1417.0000 1.0000
33.0400 1346.0000 1.0000
33.0800 1384.0000 1.0000
33.1200 1390.0000 1.0000
33.1600 1408.0000 1.0000
33.2000 1400.0000 1.0000
33.2400 1418.0000 1.0000
33.2800 1333.0000 1.0000
33.3200 1386.0000 1.0000
33.3600 1310.0000 1.0000
33.4000 1391.0000 1.0000
33.4400 1339.0000 1.0000
33.4800 1364.0000 1.0000
33.5200 1359.0000 1.0000
33.5600 1431.0000 1.0000
33.6000 1360.0000 1.0000
33.6400 1430.0000 1.0000
33.6800 1384.0000 1.0000
33.7200 1403.0000 1.0000
33.7600 1490.0000 1.0000
33.8000 1439.0000 1.0000
33.8400 1492.0000 1.0000
33.8800 1506.0000 1.0000
33.9200 1564.0000 1.0000
33.9600 1518.0000 1.0000
34.0000 1560.0000 1.0000
34.0400 1518.0000 1.0000
34.0800 1576.0000 1.0000
34.1200 1553.0000 1.0000
34.1600 1601.0000 1.0000
34.2000 1739.0000 1.0000
34.2400 1719.0000 1.0000
34.2800 1896.0000 1.0000
34.3200 2090.0000 1.0000
34.3600 2417.0000 1.0000
34.4000 2817.0000 1.0000
34.4400 3214.0000 1.0000
34.4800 3115.0000 1.0000
34.5200 2956.0000 1.0000
34.5600 2690.0000 1.0000
34.6000 2298.0000 1.0000
34.6400 2071.0000 1.0000
34.6800 1881.0000 1.0000
34.7200 1777.0000 1.0000
34.7600 1628.0000 1.0000
34.8000 1581.0000 1.0000
34.8400 1479.0000 1.0000
34.8800 1437.0000 1.0000
34.9200 1310.0000 1.0000
34.9600 1411.0000 1.0000
35.0000 1330.0000 1.0000
35.0400 1319.0000 1.0000
35.0800 1299.0000 1.0000
35.1200 1249.0000 1.0000
35.1600 1285.0000 1.0000
35.2000 1306.0000 1.0000
35.2400 1195.0000 1.0000
35.2800 1283.0000 1.0000
35.3200 1254.0000 1.0000
35.3600 1234.0000 1.0000
35.4000 1250.0000 1.0000
35.4400 1223.0000 1.0000
35.4800 1178.0000 1.0000
35.5200 1161.0000 1.0000
35.5600 1172.0000 1.0000
35.6000 1163.0000 1.0000
35.6400 1185.0000 1.0000
35.6800 1196.0000 1.0000
35.7200 1152.0000 1.0000
35.7600 1182.0000 1.0000
35.8000 1213.0000 1.0000
35.8400 1171.0000 1.0000
35.8800 1170.0000 1.0000
35.9200 1133.0000 1.0000
35.9600 1195.0000 1.0000
36.0000 1140.0000 1.0000
36.0400 1199.0000 1.0000
36.0800 1215.0000 1.0000
36.1200 1254.0000 1.0000
36.1600 1276.0000 1.0000
36.2000 1278.0000 1.0000
36.2400 1360.0000 1.0000
36.2800 1421.0000 1.0000
36.3200 1564.0000 1.0000
36.3600 1570.0000 1.0000
36.4000 1583.0000 1.0000
36.4400 1578.0000 1.0000
36.4800 1461.0000 1.0000
36.5200 1353.0000 1.0000
36.5600 1318.0000 1.0000
36.6000 1246.0000 1.0000
36.6400 1243.0000 1.0000
36.6800 1149.0000 1.0000
36.7200 1188.0000 1.0000
36.7600 1133.0000 1.0000
36.8000 1146.0000 1.0000
36.8400 1082.0000 1.0000
36.8800 1137.0000 1.0000
36.9200 1152.0000 1.0000
36.9600 1127.0000 1.0000
37.0000 1070.0000 1.0000
37.0400 1091.0000 1.0000
37.0800 1066.0000 1.0000
37.1200 1077.0000 1.0000
37.1600 1049.0000 1.0000
37.2000 1130.0000 1.0000
37.2400 1141.0000 1.0000
37.2800 1073.0000 1.0000
37.3200 1113.0000 1.0000
37.3600 1050.0000 1.0000
37.4000 1161.0000 1.0000
37.4400 1090.0000 1.0000
37.4800 1048.0000 1.0000
37.5200 1070.0000 1.0000
37.5600 1087.0000 1.0000
37.6000 1066.0000 1.0000
37.6400 1046.0000 1.0000
37.6800 1108.0000 1.0000
37.7200 1106.0000 1.0000
37.7600 1088.0000 1.0000
37.8000 1112.0000 1.0000
37.8400 1127.0000 1.0000
37.8800 1186.0000 1.0000
37.9200 1109.0000 1.0000
37.9600 1189.0000 1.0000
38.0000 1217.0000 1.0000
38.0400 1222.0000 1.0000
38.0800 1333.0000 1.0000
38.1200 1417.0000 1.0000
38.1600 1521.0000 1.0000
38.2000 1687.0000 1.0000
38.2400 1930.0000 1.0000
38.2800 2361.0000 1.0000
38.3200 2872.0000 1.0000
38.3600 3683.0000 1.0000
38.4000 5097.0000 1.0000
38.4400 6568.0000 1.0000
38.4800 7980.0000 1.0000
38.5200 8446.0000 1.0000
38.5600 7649.0000 1.0000
38.6000 6566.0000 1.0000
38.6400 5184.0000 1.0000
38.6800 4000.0000 1.0000
38.7200 2949.0000 1.0000
38.7600 2326.0000 1.0000
38.8000 1896.0000 1.0000
38.8400 1631.0000 1.0000
38.8800 1459.0000 1.0000
38.9200 1313.0000 1.0000
38.9600 1232.0000 1.0000
39.0000 1130.0000 1.0000
39.0400 1129.0000 1.0000
39.0800 1086.0000 1.0000
39.1200 1063.0000 1.0000
39.1600 1028.0000 1.0000
39.2000 999.0000 1.0000
39.2400 1007.0000 1.0000
39.2800 1039.0000 1.0000
39.3200 991.0000 1.0000
39.3600 1006.0000 1.0000
39.4000 993.0000 1.0000
39.4400 1008.0000 1.0000
39.4800 1042.0000 1.0000
39.5200 1005.0000 1.0000
39.5600 1052.0000 1.0000
39.6000 1024.0000 1.0000
39.6400 994.0000 1.0000
39.6800 1008.0000 1.0000
39.7200 1031.0000 1.0000
39.7600 945.0000 1.0000
39.8000 931.0000 1.0000
39.8400 927.0000 1.0000
39.8800 921.0000 1.0000
39.9200 916.0000 1.0000
39.9600 905.0000 1.0000
40.0000 935.0000 1.0000
40.0400 915.0000 1.0000
40.0800 916.0000 1.0000
40.1200 922.0000 1.0000
40.1600 914.0000 1.0000
40.2000 951.0000 1.0000
40.2400 881.0000 1.0000
40.2800 879.0000 1.0000
40.3200 903.0000 1.0000
40.3600 893.0000 1.0000
40.4000 860.0000 1.0000
40.4400 868.0000 1.0000
40.4800 904.0000 1.0000
40.5200 825.0000 1.0000
40.5600 902.0000 1.0000
40.6000 855.0000 1.0000
40.6400 876.0000 1.0000
40.6800 913.0000 1.0000
40.7200 891.0000 1.0000
40.7600 855.0000 1.0000
40.8000 894.0000 1.0000
40.8400 910.0000 1.0000
40.8800 890.0000 1.0000
40.9200 896.0000 1.0000
40.9600 858.0000 1.0000
41.0000 885.0000 1.0000
41.0400 873.0000 1.0000
41.0800 845.0000 1.0000
41.1200 944.0000 1.0000
41.1600 851.0000 1.0000
41.2000 883.0000 1.0000
41.2400 858.0000 1.0000
41.2800 855.0000 1.0000
41.3200 878.0000 1.0000
41.3600 911.0000 1.0000
41.4000 897.0000 1.0000
41.4400 876.0000 1.0000
41.4800 888.0000 1.0000
41.5200 867.0000 1.0000
41.5600 872.0000 1.0000
41.6000 870.0000 1.0000
41.6400 893.0000 1.0000
41.6800 875.0000 1.0000
41.7200 922.0000 1.0000
41.7600 885.0000 1.0000
41.8000 905.0000 1.0000
41.8400 841.0000 1.0000
41.8800 826.0000 1.0000
41.9200 858.0000 1.0000
41.9600 885.0000 1.0000
42.0000 859.0000 1.0000
42.0400 864.0000 1.0000
42.0800 836.0000 1.0000
42.1200 847.0000 1.0000
42.1600 839.0000 1.0000
42.2000 870.0000 1.0000
42.2400 826.0000 1.0000
42.2800 897.0000 1.0000
42.3200 844.0000 1.0000
42.3600 908.0000 1.0000
42.4000 849.0000 1.0000
42.4400 869.0000 1.0000
42.4800 849.0000 1.0000
42.5200 832.0000 1.0000
42.5600 882.0000 1.0000
42.6000 865.0000 1.0000
42.6400 866.0000 1.0000
42.6800 851.0000 1.0000
42.7200 869.0000 1.0000
42.7600 869.0000 1.0000
42.8000 829.0000 1.0000
42.8400 829.0000 1.0000
42.8800 852.0000 1.0000
42.9200 840.0000 1.0000
42.9600 890.0000 1.0000
43.0000 909.0000 1.0000
43.0400 885.0000 1.0000
43.0800 851.0000 1.0000
43.1200 958.0000 1.0000
43.1600 934.0000 1.0000
43.2000 980.0000 1.0000
43.2400 946.0000 1.0000
43.2800 975.0000 1.0000
43.3200 915.0000 1.0000
43.3600 890.0000 1.0000
43.4000 870.0000 1.0000
43.4400 841.0000 1.0000
43.4800 869.0000 1.0000
43.5200 834.0000 1.0000
43.5600 779.0000 1.0000
43.6000 856.0000 1.0000
43.6400 873.0000 1.0000
43.6800 819.0000 1.0000
43.7200 797.0000 1.0000
43.7600 809.0000 1.0000
43.8000 824.0000 1.0000
43.8400 863.0000 1.0000
43.8800 783.0000 1.0000
43.9200 859.0000 1.0000
43.9600 861.0000 1.0000
44.0000 829.0000 1.0000
44.0400 831.0000 1.0000
44.0800 844.0000 1.0000
44.1200 834.0000 1.0000
44.1600 791.0000 1.0000
44.2000 816.0000 1.0000
44.2400 822.0000 1.0000
44.2800 842.0000 1.0000
44.3200 823.0000 1.0000
44.3600 806.0000 1.0000
44.4000 852.0000 1.0000
44.4400 840.0000 1.0000
44.4800 804.0000 1.0000
44.5200 793.0000 1.0000
44.5600 763.0000 1.0000
44.6000 782.0000 1.0000
44.6400 811.0000 1.0000
44.6800 781.0000 1.0000
44.7200 772.0000 1.0000
44.7600 798.0000 1.0000
44.8000 803.0000 1.0000
44.8400 809.0000 1.0000
44.8800 790.0000 1.0000
44.9200 806.0000 1.0000
44.9600 795.0000 1.0000
45.0000 803.0000 1.0000
45.0400 824.0000 1.0000
45.0800 804.0000 1.0000
45.1200 811.0000 1.0000
45.1600 775.0000 1.0000
45.2000 806.0000 1.0000
45.2400 757.0000 1.0000
45.2800 785.0000 1.0000
45.3200 794.0000 1.0000
45.3600 813.0000 1.0000
45.4000 798.0000 1.0000
45.4400 754.0000 1.0000
45.4800 789.0000 1.0000
45.5200 772.0000 1.0000
45.5600 769.0000 1.0000
45.6000 822.0000 1.0000
45.6400 810.0000 1.0000
45.6800 770.0000 1.0000
45.7200 769.0000 1.0000
45.7600 798.0000 1.0000
45.8000 795.0000 1.0000
45.8400 785.0000 1.0000
45.8800 803.0000 1.0000
45.9200 855.0000 1.0000
45.9600 781.0000 1.0000
46.0000 777.0000 1.0000
46.0400 803.0000 1.0000
46.0800 812.0000 1.0000
46.1200 765.0000 1.0000
46.1600 775.0000 1.0000
46.2000 759.0000 1.0000
46.2400 772.0000 1.0000
46.2800 747.0000 1.0000
46.3200 821.0000 1.0000
46.3600 817.0000 1.0000
46.4000 796.0000 1.0000
46.4400 802.0000 1.0000
46.4800 790.0000 1.0000
46.5200 779.0000 1.0000
46.5600 785.0000 1.0000
46.6000 841.0000 1.0000
46.6400 789.0000 1.0000
46.6800 744.0000 1.0000
46.7200 765.0000 1.0000
46.7600 781.0000 1.0000
46.8000 808.0000 1.0000
46.8400 776.0000 1.0000
46.8800 780.0000 1.0000
46.9200 824.0000 1.0000
46.9600 791.0000 1.0000
47.0000 793.0000 1.0000
47.0400 846.0000 1.0000
47.0800 735.0000 1.0000
47.1200 765.0000 1.0000
47.1600 765.0000 1.0000
47.2000 729.0000 1.0000
47.2400 780.0000 1.0000
47.2800 803.0000 1.0000
47.3200 776.0000 1.0000
47.3600 763.0000 1.0000
47.4000 767.0000 1.0000
47.4400 778.0000 1.0000
47.4800 724.0000 1.0000
47.5200 753.0000 1.0000
47.5600 815.0000 1.0000
47.6000 747.0000 1.0000
47.6400 755.0000 1.0000
47.6800 761.0000 1.0000
47.7200 735.0000 1.0000
47.7600 718.0000 1.0000
47.8000 749.0000 1.0000
47.8400 720.0000 1.0000
47.8800 745.0000 1.0000
47.9200 770.0000 1.0000
47.9600 804.0000 1.0000
48.0000 716.0000 1.0000
48.0400 721.0000 1.0000
48.0800 720.0000 1.0000
48.1200 761.0000 1.0000
48.1600 757.0000 1.0000
48.2000 793.0000 1.0000
48.2400 716.0000 1.0000
48.2800 733.0000 1.0000
48.3200 736.0000 1.0000
48.3600 742.0000 1.0000
48.4000 741.0000 1.0000
48.4400 722.0000 1.0000
48.4800 700.0000 1.0000
48.5200 746.0000 1.0000
48.5600 731.0000 1.0000
48.6000 752.0000 1.0000
48.6400 712.0000 1.0000
48.6800 763.0000 1.0000
48.7200 721.0000 1.0000
48.7600 705.0000 1.0000
48.8000 725.0000 1.0000
48.8400 715.0000 1.0000
48.8800 691.0000 1.0000
48.9200 746.0000 1.0000
48.9600 738.0000 1.0000
49.0000 703.0000 1.0000
49.0400 684.0000 1.0000
49.0800 770.0000 1.0000
49.1200 716.0000 1.0000
49.1600 737.0000 1.0000
49.2000 740.0000 1.0000
49.2400 715.0000 1.0000
49.2800 696.0000 1.0000
49.3200 724.0000 1.0000
49.3600 671.0000 1.0000
49.4000 733.0000 1.0000
49.4400 710.0000 1.0000
49.4800 729.0000 1.0000
49.5200 704.0000 1.0000
49.5600 743.0000 1.0000
49.6000 709.0000 1.0000
49.6400 705.0000 1.0000
49.6800 741.0000 1.0000
49.7200 703.0000 1.0000
49.7600 723.0000 1.0000
49.8000 670.0000 1.0000
49.8400 721.0000 1.0000
49.8800 712.0000 1.0000
49.9200 727.0000 1.0000
49.9600 746.0000 1.0000
50.0000 726.0000 1.0000
50.0400 716.0000 1.0000
50.0800 693.0000 1.0000
50.1200 747.0000 1.0000
50.1600 720.0000 1.0000
50.2000 722.0000 1.0000
50.2400 737.0000 1.0000
50.2800 736.0000 1.0000
50.3200 722.0000 1.0000
50.3600 738.0000 1.0000
50.4000 750.0000 1.0000
50.4400 767.0000 1.0000
50.4800 757.0000 1.0000
50.5200 743.0000 1.0000
50.5600 749.0000 1.0000
50.6000 714.0000 1.0000
50.6400 724.0000 1.0000
50.6800 744.0000 1.0000
50.7200 748.0000 1.0000
50.7600 745.0000 1.0000
50.8000 676.0000 1.0000
50.8400 718.0000 1.0000
50.8800 711.0000 1.0000
50.9200 759.0000 1.0000
50.9600 783.0000 1.0000
51.0000 709.0000 1.0000
51.0400 746.0000 1.0000
51.0800 768.0000 1.0000
51.1200 734.0000 1.0000
51.1600 720.0000 1.0000
51.2000 695.0000 1.0000
51.2400 723.0000 1.0000
51.2800 751.0000 1.0000
51.3200 725.0000 1.0000
51.3600 758.0000 1.0000
51.4000 728.0000 1.0000
51.4400 746.0000 1.0000
51.4800 721.0000 1.0000
51.5200 796.0000 1.0000
51.5600 754.0000 1.0000
51.6000 786.0000 1.0000
51.6400 763.0000 1.0000
51.6800 792.0000 1.0000
51.7200 828.0000 1.0000
51.7600 848.0000 1.0000
51.8000 828.0000 1.0000
51.8400 883.0000 1.0000
51.8800 945.0000 1.0000
51.9200 1064.0000 1.0000
51.9600 1147.0000 1.0000
52.0000 1354.0000 1.0000
52.0400 1646.0000 1.0000
52.0800 1897.0000 1.0000
52.1200 2699.0000 1.0000
52.1600 3728.0000 1.0000
52.2000 4836.0000 1.0000
52.2400 5267.0000 1.0000
52.2800 4715.0000 1.0000
52.3200 4409.0000 1.0000
52.3600 3994.0000 1.0000
52.4000 3349.0000 1.0000
52.4400 2565.0000 1.0000
52.4800 1993.0000 1.0000
52.5200 1584.0000 1.0000
52.5600 1330.0000 1.0000
52.6000 1191.0000 1.0000
52.6400 1022.0000 1.0000
52.6800 949.0000 1.0000
52.7200 943.0000 1.0000
52.7600 842.0000 1.0000
52.8000 869.0000 1.0000
52.8400 821.0000 1.0000
52.8800 843.0000 1.0000
52.9200 721.0000 1.0000
52.9600 781.0000 1.0000
53.0000 824.0000 1.0000
53.0400 789.0000 1.0000
53.0800 747.0000 1.0000
53.1200 779.0000 1.0000
53.1600 731.0000 1.0000
53.2000 734.0000 1.0000
53.2400 756.0000 1.0000
53.2800 789.0000 1.0000
53.3200 745.0000 1.0000
53.3600 682.0000 1.0000
53.4000 694.0000 1.0000
53.4400 730.0000 1.0000
53.4800 743.0000 1.0000
53.5200 754.0000 1.0000
53.5600 682.0000 1.0000
53.6000 707.0000 1.0000
53.6400 742.0000 1.0000
53.6800 730.0000 1.0000
53.7200 727.0000 1.0000
53.7600 729.0000 1.0000
53.8000 702.0000 1.0000
53.8400 718.0000 1.0000
53.8800 744.0000 1.0000
53.9200 721.0000 1.0000
53.9600 684.0000 1.0000
54.0000 726.0000 1.0000
54.0400 703.0000 1.0000
54.0800 674.0000 1.0000
54.1200 672.0000 1.0000
54.1600 754.0000 1.0000
54.2000 706.0000 1.0000
54.2400 738.0000 1.0000
54.2800 696.0000 1.0000
54.3200 748.0000 1.0000
54.3600 729.0000 1.0000
54.4000 709.0000 1.0000
54.4400 678.0000 1.0000
54.4800 745.0000 1.0000
54.5200 704.0000 1.0000
54.5600 705.0000 1.0000
54.6000 764.0000 1.0000
54.6400 749.0000 1.0000
54.6800 751.0000 1.0000
54.7200 784.0000 1.0000
54.7600 719.0000 1.0000
54.8000 760.0000 1.0000
54.8400 791.0000 1.0000
54.8800 725.0000 1.0000
54.9200 793.0000 1.0000
54.9600 794.0000 1.0000
55.0000 832.0000 1.0000
55.0400 867.0000 1.0000
55.0800 868.0000 1.0000
55.1200 892.0000 1.0000
55.1600 1012.0000 1.0000
55.2000 1030.0000 1.0000
55.2400 1175.0000 1.0000
55.2800 1155.0000 1.0000
55.3200 1075.0000 1.0000
55.3600 1051.0000 1.0000
55.4000 1064.0000 1.0000
55.4400 981.0000 1.0000
55.4800 906.0000 1.0000
55.5200 835.0000 1.0000
55.5600 799.0000 1.0000
55.6000 743.0000 1.0000
55.6400 773.0000 1.0000
55.6800 727.0000 1.0000
55.7200 752.0000 1.0000
55.7600 722.0000 1.0000
55.8000 724.0000 1.0000
55.8400 756.0000 1.0000
55.8800 701.0000 1.0000
55.9200 720.0000 1.0000
55.9600 700.0000 1.0000
56.0000 688.0000 1.0000
56.0400 707.0000 1.0000
56.0800 691.0000 1.0000
56.1200 729.0000 1.0000
56.1600 747.0000 1.0000
56.2000 670.0000 1.0000
56.2400 704.0000 1.0000
56.2800 670.0000 1.0000
56.3200 653.0000 1.0000
56.3600 658.0000 1.0000
56.4000 691.0000 1.0000
56.4400 691.0000 1.0000
56.4800 709.0000 1.0000
56.5200 706.0000 1.0000
56.5600 673.0000 1.0000
56.6000 631.0000 1.0000
56.6400 674.0000 1.0000
56.6800 681.0000 1.0000
56.7200 679.0000 1.0000
56.7600 689.0000 1.0000
56.8000 678.0000 1.0000
56.8400 693.0000 1.0000
56.8800 685.0000 1.0000
56.9200 636.0000 1.0000
56.9600 653.0000 1.0000
57.0000 653.0000 1.0000
57.0400 663.0000 1.0000
57.0800 675.0000 1.0000
57.1200 640.0000 1.0000
57.1600 656.0000 1.0000
57.2000 682.0000 1.0000
57.2400 667.0000 1.0000
57.2800 684.0000 1.0000
57.3200 640.0000 1.0000
57.3600 659.0000 1.0000
57.4000 647.0000 1.0000
57.4400 694.0000 1.0000
57.4800 677.0000 1.0000
57.5200 698.0000 1.0000
57.5600 648.0000 1.0000
57.6000 631.0000 1.0000
57.6400 660.0000 1.0000
57.6800 689.0000 1.0000
57.7200 674.0000 1.0000
57.7600 659.0000 1.0000
57.8000 659.0000 1.0000
57.8400 662.0000 1.0000
57.8800 655.0000 1.0000
57.9200 707.0000 1.0000
57.9600 694.0000 1.0000
58.0000 715.0000 1.0000
58.0400 675.0000 1.0000
58.0800 679.0000 1.0000
58.1200 690.0000 1.0000
58.1600 703.0000 1.0000
58.2000 710.0000 1.0000
58.2400 702.0000 1.0000
58.2800 731.0000 1.0000
58.3200 672.0000 1.0000
58.3600 692.0000 1.0000
58.4000 676.0000 1.0000
58.4400 693.0000 1.0000
58.4800 663.0000 1.0000
58.5200 701.0000 1.0000
58.5600 700.0000 1.0000
58.6000 652.0000 1.0000
58.6400 688.0000 1.0000
58.6800 666.0000 1.0000
58.7200 691.0000 1.0000
58.7600 659.0000 1.0000
58.8000 679.0000 1.0000
58.8400 662.0000 1.0000
58.8800 675.0000 1.0000
58.9200 688.0000 1.0000
58.9600 684.0000 1.0000
59.0000 667.0000 1.0000
59.0400 711.0000 1.0000
59.0800 706.0000 1.0000
59.1200 660.0000 1.0000
59.1600 671.0000 1.0000
59.2000 674.0000 1.0000
59.2400 702.0000 1.0000
59.2800 718.0000 1.0000
59.3200 738.0000 1.0000
59.3600 614.0000 1.0000
59.4000 678.0000 1.0000
59.4400 690.0000 1.0000
59.4800 662.0000 1.0000
59.5200 695.0000 1.0000
59.5600 628.0000 1.0000
59.6000 674.0000 1.0000
59.6400 674.0000 1.0000
59.6800 640.0000 1.0000
59.7200 659.0000 1.0000
59.7600 719.0000 1.0000
59.8000 651.0000 1.0000
59.8400 680.0000 1.0000
59.8800 658.0000 1.0000
59.9200 625.0000 1.0000
59.9600 684.0000 1.0000
60.0000 683.0000 1.0000
60.0400 660.0000 1.0000
60.0800 677.0000 1.0000
60.1200 726.0000 1.0000
60.1600 677.0000 1.0000
60.2000 665.0000 1.0000
60.2400 712.0000 1.0000
60.2800 661.0000 1.0000
60.3200 661.0000 1.0000
60.3600 676.0000 1.0000
60.4000 658.0000 1.0000
60.4400 664.0000 1.0000
60.4800 711.0000 1.0000
60.5200 684.0000 1.0000
60.5600 652.0000 1.0000
60.6000 643.0000 1.0000
60.6400 653.0000 1.0000
60.6800 670.0000 1.0000
60.7200 638.0000 1.0000
60.7600 680.0000 1.0000
60.8000 717.0000 1.0000
60.8400 727.0000 1.0000
60.8800 678.0000 1.0000
60.9200 683.0000 1.0000
60.9600 655.0000 1.0000
61.0000 664.0000 1.0000
61.0400 661.0000 1.0000
61.0800 674.0000 1.0000
61.1200 706.0000 1.0000
61.1600 628.0000 1.0000
61.2000 634.0000 1.0000
61.2400 655.0000 1.0000
61.2800 679.0000 1.0000
61.3200 737.0000 1.0000
61.3600 723.0000 1.0000
61.4000 718.0000 1.0000
61.4400 727.0000 1.0000
61.4800 671.0000 1.0000
61.5200 751.0000 1.0000
61.5600 684.0000 1.0000
61.6000 714.0000 1.0000
61.6400 670.0000 1.0000
61.6800 755.0000 1.0000
61.7200 766.0000 1.0000
61.7600 733.0000 1.0000
61.8000 768.0000 1.0000
61.8400 722.0000 1.0000
61.8800 803.0000 1.0000
61.9200 855.0000 1.0000
61.9600 902.0000 1.0000
62.0000 911.0000 1.0000
62.0400 1056.0000 1.0000
62.0800 1196.0000 1.0000
62.1200 1303.0000 1.0000
62.1600 1489.0000 1.0000
62.2000 1676.0000 1.0000
62.2400 1795.0000 1.0000
62.2800 1715.0000 1.0000
62.3200 1772.0000 1.0000
62.3600 1660.0000 1.0000
62.4000 1652.0000 1.0000
62.4400 1522.0000 1.0000
62.4800 1318.0000 1.0000
62.5200 1280.0000 1.0000
62.5600 1111.0000 1.0000
62.6000 1038.0000 1.0000
62.6400 931.0000 1.0000
62.6800 893.0000 1.0000
62.7200 880.0000 1.0000
62.7600 841.0000 1.0000
62.8000 798.0000 1.0000
62.8400 786.0000 1.0000
62.8800 764.0000 1.0000
62.9200 776.0000 1.0000
62.9600 772.0000 1.0000
63.0000 741.0000 1.0000
63.0400 721.0000 1.0000
63.0800 758.0000 1.0000
63.1200 731.0000 1.0000
63.1600 709.0000 1.0000
63.2000 723.0000 1.0000
63.2400 701.0000 1.0000
63.2800 698.0000 1.0000
63.3200 678.0000 1.0000
63.3600 660.0000 1.0000
63.4000 699.0000 1.0000
63.4400 677.0000 1.0000
63.4800 683.0000 1.0000
63.5200 695.0000 1.0000
63.5600 725.0000 1.0000
63.6000 672.0000 1.0000
63.6400 734.0000 1.0000
63.6800 639.0000 1.0000
63.7200 699.0000 1.0000
63.7600 718.0000 1.0000
63.8000 682.0000 1.0000
63.8400 664.0000 1.0000
63.8800 653.0000 1.0000
63.9200 672.0000 1.0000
63.9600 643.0000 1.0000
64.0000 706.0000 1.0000
64.0400 688.0000 1.0000
64.0800 688.0000 1.0000
64.1200 653.0000 1.0000
64.1600 678.0000 1.0000
64.2000 723.0000 1.0000
64.2400 712.0000 1.0000
64.2800 681.0000 1.0000
64.3200 726.0000 1.0000
64.3600 690.0000 1.0000
64.4000 695.0000 1.0000
64.4400 689.0000 1.0000
64.4800 711.0000 1.0000
64.5200 731.0000 1.0000
64.5600 750.0000 1.0000
64.6000 734.0000 1.0000
64.6400 760.0000 1.0000
64.6800 778.0000 1.0000
64.7200 775.0000 1.0000
64.7600 780.0000 1.0000
64.8000 715.0000 1.0000
64.8400 740.0000 1.0000
64.8800 749.0000 1.0000
64.9200 784.0000 1.0000
64.9600 733.0000 1.0000
65.0000 752.0000 1.0000
65.0400 712.0000 1.0000
65.0800 738.0000 1.0000
65.1200 714.0000 1.0000
65.1600 725.0000 1.0000
65.2000 729.0000 1.0000
65.2400 692.0000 1.0000
65.2800 725.0000 1.0000
65.3200 676.0000 1.0000
65.3600 733.0000 1.0000
65.4000 693.0000 1.0000
65.4400 718.0000 1.0000
65.4800 714.0000 1.0000
65.5200 740.0000 1.0000
65.5600 738.0000 1.0000
65.6000 714.0000 1.0000
65.6400 753.0000 1.0000
65.6800 783.0000 1.0000
65.7200 769.0000 1.0000
65.7600 795.0000 1.0000
65.8000 840.0000 1.0000
65.8400 883.0000 1.0000
65.8800 917.0000 1.0000
65.9200 989.0000 1.0000
65.9600 1053.0000 1.0000
66.0000 1188.0000 1.0000
66.0400 1398.0000 1.0000
66.0800 1651.0000 1.0000
66.1200 2048.0000 1.0000
66.1600 2594.0000 1.0000
66.2000 2775.0000 1.0000
66.2400 2775.0000 1.0000
66.2800 2642.0000 1.0000
66.3200 2496.0000 1.0000
66.3600 2313.0000 1.0000
66.4000 2173.0000 1.0000
66.4400 1953.0000 1.0000
66.4800 1648.0000 1.0000
66.5200 1435.0000 1.0000
66.5600 1215.0000 1.0000
66.6000 1109.0000 1.0000
66.6400 1003.0000 1.0000
66.6800 880.0000 1.0000
66.7200 816.0000 1.0000
66.7600 842.0000 1.0000
66.8000 768.0000 1.0000
66.8400 756.0000 1.0000
66.8800 739.0000 1.0000
66.9200 681.0000 1.0000
66.9600 695.0000 1.0000
67.0000 688.0000 1.0000
67.0400 682.0000 1.0000
67.0800 633.0000 1.0000
67.1200 712.0000 1.0000
67.1600 645.0000 1.0000
67.2000 689.0000 1.0000
67.2400 671.0000 1.0000
67.2800 650.0000 1.0000
67.3200 669.0000 1.0000
67.3600 623.0000 1.0000
67.4000 656.0000 1.0000
67.4400 681.0000 1.0000
67.4800 621.0000 1.0000
67.5200 663.0000 1.0000
67.5600 604.0000 1.0000
67.6000 620.0000 1.0000
67.6400 637.0000 1.0000
67.6800 652.0000 1.0000
67.7200 601.0000 1.0000
67.7600 611.0000 1.0000
67.8000 654.0000 1.0000
67.8400 643.0000 1.0000
67.8800 628.0000 1.0000
67.9200 649.0000 1.0000
67.9600 598.0000 1.0000
68.0000 622.0000 1.0000
68.0400 621.0000 1.0000
68.0800 614.0000 1.0000
68.1200 612.0000 1.0000
68.1600 641.0000 1.0000
68.2000 556.0000 1.0000
68.2400 620.0000 1.0000
68.2800 582.0000 1.0000
68.3200 627.0000 1.0000
68.3600 626.0000 1.0000
68.4000 618.0000 1.0000
68.4400 609.0000 1.0000
68.4800 623.0000 1.0000
68.5200 615.0000 1.0000
68.5600 597.0000 1.0000
68.6000 593.0000 1.0000
68.6400 603.0000 1.0000
68.6800 615.0000 1.0000
68.7200 618.0000 1.0000
68.7600 623.0000 1.0000
68.8000 576.0000 1.0000
68.8400 611.0000 1.0000
68.8800 571.0000 1.0000
68.9200 601.0000 1.0000
68.9600 591.0000 1.0000
69.0000 585.0000 1.0000
69.0400 572.0000 1.0000
69.0800 568.0000 1.0000
69.1200 584.0000 1.0000
69.1600 565.0000 1.0000
69.2000 610.0000 1.0000
69.2400 588.0000 1.0000
69.2800 541.0000 1.0000
69.3200 593.0000 1.0000
69.3600 564.0000 1.0000
69.4000 591.0000 1.0000
69.4400 623.0000 1.0000
69.4800 588.0000 1.0000
69.5200 599.0000 1.0000
69.5600 632.0000 1.0000
69.6000 606.0000 1.0000
69.6400 602.0000 1.0000
69.6800 570.0000 1.0000
69.7200 574.0000 1.0000
69.7600 588.0000 1.0000
69.8000 583.0000 1.0000
69.8400 574.0000 1.0000
69.8800 588.0000 1.0000
69.9200 578.0000 1.0000
69.9600 589.0000 1.0000
70.0000 602.0000 1.0000
*RAS_INT_END
*RAS_TEMPERATURE_START
*RAS_TEMPERATURE_END
*RAS_DATA_END