File: Data/Dataset1_Only_water/5_XRD/No_058_deposition_3h_TiO2_Air_5.ras
*RAS_DATA_START
*RAS_HEADER_START
*DISP_FMT_X "%.2f"
*DISP_FMT_Y "%.0f"
*DISP_FULLSCALE "20970.0000000000"
*DISP_LINE_COLOR "255.0000000000"
*DISP_LINE_STYLE "0.0000000000"
*DISP_LINE_WIDTH "0.2500000000"
*DISP_NOTE "測定データ-1"
*DISP_OFFSET_Y "0.0000000000"
*DISP_PEAKSEARCH_UNIT_Y "cps"
*DISP_RANGE_BOTTOM "0.0000000000"
*DISP_RANGE_LEFT "20.0000000000"
*DISP_RANGE_LOGCUTOFF "0.0100000000"
*DISP_RANGE_RIGHT "70.0000000000"
*DISP_RANGE_TOP "20970.0000000000"
*DISP_SCALE_MODE_Y "0.0000000000"
*DISP_TAB_NAME "2θ/θ"
*DISP_TITLE_Y "強度"
*DISP_UNIT_Y "cps"
*DISP_WINDOW_NAME "MSG_MACROENGINE"
*FILE_COMMENT " "
*FILE_MD5 ""
*FILE_MEMO " "
*FILE_OPERATOR "Administrator"
*FILE_SAMPLE " "
*FILE_TYPE "RAS_RAW"
*FILE_USERGROUP "システムマネージャ"
*FILE_VERSION "1.0000000000"
*HW_ATTACHMENT_ID "ATT0025"
*HW_ATTACHMENT_NAME "標準|Standard"
*HW_COUNTER_ID-0 "CUT0025"
*HW_COUNTER_ID-1 "CUT0020"
*HW_COUNTER_ID-2 "CUT0020"
*HW_COUNTER_ID-3 "CSL0021"
*HW_COUNTER_ID-4 "CMC0021"
*HW_COUNTER_NAME-0 "D/teX Ultra|D/teX Ultra"
*HW_COUNTER_NAME-1 "None|None"
*HW_COUNTER_NAME-2 "None|None"
*HW_COUNTER_NAME-3 "BBM|BBM"
*HW_COUNTER_NAME-4 "検出器モノクロメータ|Detector monochromator"
*HW_COUNTER_SELECT_NAME "D/teX Ultra|D/teX Ultra"
*HW_GONIOMETER_ID "GON0023"
*HW_GONIOMETER_NAME "SmartLab|SmartLab"
*HW_GONIOMETER_RADIUS-0 "90.0"
*HW_GONIOMETER_RADIUS-1 "114.0"
*HW_GONIOMETER_RADIUS-2 "190.0"
*HW_GONIOMETER_RADIUS-3 "300.0"
*HW_GONIOMETER_RADIUS-4 "187.0"
*HW_GONIOMETER_RADIUS-5 "300.0"
*HW_GONIOMETER_RADIUS-6 "113.0"
*HW_GONIOMETER_RADIUS-7 "331.0"
*HW_I_OPT_ID-0 "CBO0021"
*HW_I_OPT_ID-1 "ICR0023"
*HW_I_OPT_ID-2 "ISL0021"
*HW_I_OPT_ID-3 "ISO0021"
*HW_I_OPT_ID-4 "IAD0021"
*HW_I_OPT_ID-5 "IPR0001"
*HW_I_OPT_NAME-0 "CBOユニット|CBO unit"
*HW_I_OPT_NAME-1 "標準入射光学ユニット|Standard incident optical unit"
*HW_I_OPT_NAME-2 "標準入射スリットボックス|Standard incident slit box"
*HW_I_OPT_NAME-3 "入射平行スリット|Incident parallel slit"
*HW_I_OPT_NAME-4 "長手制限スリット|Length limiting slit"
*HW_I_OPT_NAME-5 "None|None"
*HW_R_ATTENUATER_AUTOMODE "0"
*HW_R_OPT_ID-0 "RSS0021"
*HW_R_OPT_ID-1 "RCR0023"
*HW_R_OPT_ID-2 "RSO0021"
*HW_R_OPT_ID-3 "RRS0021"
*HW_R_OPT_ID-4 "ATN0021"
*HW_R_OPT_ID-5 "RFL0021"
*HW_R_OPT_ID-6 "RAD0021"
*HW_R_OPT_NAME-0 "標準受光スリットボックス1|Standard receiving slit box # 1"
*HW_R_OPT_NAME-1 "標準受光光学ユニット1|Standard receiving unit # 1"
*HW_R_OPT_NAME-2 "標準受光光学ユニット2|Standard receiving optical unit # 2"
*HW_R_OPT_NAME-3 "標準受光スリットボックス2|Standard receiving slit box # 2"
*HW_R_OPT_NAME-4 "標準アッテネータ|Standard Attenuator"
*HW_R_OPT_NAME-5 "Cu Kβ|Cu K-beta"
*HW_R_OPT_NAME-6 "調整用受光スリット|Alignment receiving slit"
*HW_SAMPLE_HOLDER_ID "SMP0023"
*HW_SAMPLE_HOLDER_NAME "標準Zステージ|Standard Z stage"
*HW_XG_CURRENT_MAX "50"
*HW_XG_CURRENT_MIN "2"
*HW_XG_CURRENT_RESOLUTION "1"
*HW_XG_CURRENT_UNIT "mA"
*HW_XG_FOCUS "1mm x 10mm"
*HW_XG_FOCUS_TYPE "Normal"
*HW_XG_ID ""
*HW_XG_NAME "3kW 封入管(ID:1200)|3kW Sealed tube(ID:1200)"
*HW_XG_TARGET_ATOMIC_NUMBER "29.0000000000"
*HW_XG_TARGET_NAME "Cu"
*HW_XG_TYPE "Hermetic"
*HW_XG_VOLTAGE_MAX "60"
*HW_XG_VOLTAGE_MIN "20"
*HW_XG_VOLTAGE_RESOLUTION "1"
*HW_XG_VOLTAGE_UNIT "kV"
*HW_XG_WATT_MAX "1.500"
*HW_XG_WATT_UNIT "kW"
*HW_XG_WAVE_LENGTH_ALPHA1 "1.540593"
*HW_XG_WAVE_LENGTH_ALPHA2 "1.544414"
*HW_XG_WAVE_LENGTH_BETA "1.392250"
*MEAS_COND_AXIS_NAME-0 "2θ/θ"
*MEAS_COND_AXIS_NAME-1 "2θ"
*MEAS_COND_AXIS_NAME-2 "ω"
*MEAS_COND_AXIS_NAME-3 "Z"
*MEAS_COND_AXIS_NAME-4 "2θ/ω"
*MEAS_COND_AXIS_NAME-5 "θs"
*MEAS_COND_AXIS_NAME-6 "θd"
*MEAS_COND_AXIS_NAME-7 "Ts"
*MEAS_COND_AXIS_NAME-8 "CBO選択スリット"
*MEAS_COND_AXIS_NAME-9 "M"
*MEAS_COND_AXIS_NAME-10 "入射平行スリット"
*MEAS_COND_AXIS_NAME-11 "入射スリット"
*MEAS_COND_AXIS_NAME-12 ""
*MEAS_COND_AXIS_NAME-13 "Zs"
*MEAS_COND_AXIS_NAME-14 "入射光学素子"
*MEAS_COND_AXIS_NAME-15 "長手制限スリット"
*MEAS_COND_AXIS_NAME-16 "センタースリット"
*MEAS_COND_AXIS_NAME-17 "フィルター"
*MEAS_COND_AXIS_NAME-18 "受光スリット1"
*MEAS_COND_AXIS_NAME-19 "受光スリット2"
*MEAS_COND_AXIS_NAME-20 "受光光学素子"
*MEAS_COND_AXIS_NAME-21 "受光平行スリット"
*MEAS_COND_AXIS_NAME-22 "調整用受光スリット"
*MEAS_COND_AXIS_NAME-23 ""
*MEAS_COND_AXIS_NAME-24 ""
*MEAS_COND_AXIS_NAME-25 "Zd"
*MEAS_COND_AXIS_NAME-26 "アッテネータ"
*MEAS_COND_AXIS_NAME-27 "検出器モノクロメータ"
*MEAS_COND_AXIS_NAME-28 "モノクロメータスリット"
*MEAS_COND_AXIS_NAME-29 "プライマリビーム"
*MEAS_COND_AXIS_NAME-30 "PHA"
*MEAS_COND_AXIS_NAME_INTERNAL-0 "TwoThetaTheta"
*MEAS_COND_AXIS_NAME_INTERNAL-1 "TwoTheta"
*MEAS_COND_AXIS_NAME_INTERNAL-2 "Omega"
*MEAS_COND_AXIS_NAME_INTERNAL-3 "Z"
*MEAS_COND_AXIS_NAME_INTERNAL-4 "TwoThetaOmega"
*MEAS_COND_AXIS_NAME_INTERNAL-5 "ThetaS"
*MEAS_COND_AXIS_NAME_INTERNAL-6 "ThetaD"
*MEAS_COND_AXIS_NAME_INTERNAL-7 "Ts"
*MEAS_COND_AXIS_NAME_INTERNAL-8 "CBO"
*MEAS_COND_AXIS_NAME_INTERNAL-9 "CBO-M"
*MEAS_COND_AXIS_NAME_INTERNAL-10 "IncidentSollerSlit"
*MEAS_COND_AXIS_NAME_INTERNAL-11 "IncidentSlitBox"
*MEAS_COND_AXIS_NAME_INTERNAL-12 "IncidentSlitBox-_Axis"
*MEAS_COND_AXIS_NAME_INTERNAL-13 "Zs"
*MEAS_COND_AXIS_NAME_INTERNAL-14 "IncidentMonochromator"
*MEAS_COND_AXIS_NAME_INTERNAL-15 "IncidentAxdSlit"
*MEAS_COND_AXIS_NAME_INTERNAL-16 "CenterSlit"
*MEAS_COND_AXIS_NAME_INTERNAL-17 "Filter"
*MEAS_COND_AXIS_NAME_INTERNAL-18 "ReceivingSlitBox1"
*MEAS_COND_AXIS_NAME_INTERNAL-19 "ReceivingSlitBox2"
*MEAS_COND_AXIS_NAME_INTERNAL-20 "ReceivingOptics"
*MEAS_COND_AXIS_NAME_INTERNAL-21 "ReceivingSollerSlit"
*MEAS_COND_AXIS_NAME_INTERNAL-22 "ReceivingAxdSlit"
*MEAS_COND_AXIS_NAME_INTERNAL-23 "ReceivingSlitBox1-_Axis"
*MEAS_COND_AXIS_NAME_INTERNAL-24 "ReceivingSlitBox2-_Axis"
*MEAS_COND_AXIS_NAME_INTERNAL-25 "ReceivingSlitBox2-Zd"
*MEAS_COND_AXIS_NAME_INTERNAL-26 "Attenuator"
*MEAS_COND_AXIS_NAME_INTERNAL-27 "CounterMonochromator"
*MEAS_COND_AXIS_NAME_INTERNAL-28 "CounterSlit"
*MEAS_COND_AXIS_NAME_INTERNAL-29 "IncidentPrimary"
*MEAS_COND_AXIS_NAME_INTERNAL-30 "PHA"
*MEAS_COND_AXIS_NAME_MAGICNO-0 "83951616.0000000000"
*MEAS_COND_AXIS_NAME_MAGICNO-1 "268632064.0000000000"
*MEAS_COND_AXIS_NAME_MAGICNO-2 "268500992.0000000000"
*MEAS_COND_AXIS_NAME_MAGICNO-3 "285278208.0000000000"
*MEAS_COND_AXIS_NAME_MAGICNO-4 "83951616.0000000000"
*MEAS_COND_AXIS_NAME_MAGICNO-5 "131072.0000000000"
*MEAS_COND_AXIS_NAME_MAGICNO-6 "131072.0000000000"
*MEAS_COND_AXIS_NAME_MAGICNO-7 "318898176.0000000000"
*MEAS_COND_AXIS_NAME_MAGICNO-8 "20971521.0000000000"
*MEAS_COND_AXIS_NAME_MAGICNO-9 "285343744.0000000000"
*MEAS_COND_AXIS_NAME_MAGICNO-10 "20971521.0000000000"
*MEAS_COND_AXIS_NAME_MAGICNO-11 "22020097.0000000000"
*MEAS_COND_AXIS_NAME_MAGICNO-12 "25165824.0000000000"
*MEAS_COND_AXIS_NAME_MAGICNO-13 "318898176.0000000000"
*MEAS_COND_AXIS_NAME_MAGICNO-14 "1.0000000000"
*MEAS_COND_AXIS_NAME_MAGICNO-15 "20971521.0000000000"
*MEAS_COND_AXIS_NAME_MAGICNO-16 "20971521.0000000000"
*MEAS_COND_AXIS_NAME_MAGICNO-17 "20971521.0000000000"
*MEAS_COND_AXIS_NAME_MAGICNO-18 "23068673.0000000000"
*MEAS_COND_AXIS_NAME_MAGICNO-19 "23068673.0000000000"
*MEAS_COND_AXIS_NAME_MAGICNO-20 "20971521.0000000000"
*MEAS_COND_AXIS_NAME_MAGICNO-21 "20971521.0000000000"
*MEAS_COND_AXIS_NAME_MAGICNO-22 "20971521.0000000000"
*MEAS_COND_AXIS_NAME_MAGICNO-23 "25165824.0000000000"
*MEAS_COND_AXIS_NAME_MAGICNO-24 "25165824.0000000000"
*MEAS_COND_AXIS_NAME_MAGICNO-25 "285343744.0000000000"
*MEAS_COND_AXIS_NAME_MAGICNO-26 "17301505.0000000000"
*MEAS_COND_AXIS_NAME_MAGICNO-27 "20971521.0000000000"
*MEAS_COND_AXIS_NAME_MAGICNO-28 "20971521.0000000000"
*MEAS_COND_AXIS_NAME_MAGICNO-29 "20971521.0000000000"
*MEAS_COND_AXIS_NAME_MAGICNO-30 "0.0000000000"
*MEAS_COND_AXIS_OFFSET-0 "-"
*MEAS_COND_AXIS_OFFSET-1 "-0.0801000000"
*MEAS_COND_AXIS_OFFSET-2 "0.1646000000"
*MEAS_COND_AXIS_OFFSET-3 "-"
*MEAS_COND_AXIS_OFFSET-4 "-"
*MEAS_COND_AXIS_OFFSET-5 "0.1646000000"
*MEAS_COND_AXIS_OFFSET-6 "-0.2447000000"
*MEAS_COND_AXIS_OFFSET-7 "-"
*MEAS_COND_AXIS_OFFSET-8 "-"
*MEAS_COND_AXIS_OFFSET-9 "-"
*MEAS_COND_AXIS_OFFSET-10 "-"
*MEAS_COND_AXIS_OFFSET-11 "-"
*MEAS_COND_AXIS_OFFSET-12 "-"
*MEAS_COND_AXIS_OFFSET-13 "-"
*MEAS_COND_AXIS_OFFSET-14 "-"
*MEAS_COND_AXIS_OFFSET-15 "-"
*MEAS_COND_AXIS_OFFSET-16 "-"
*MEAS_COND_AXIS_OFFSET-17 "-"
*MEAS_COND_AXIS_OFFSET-18 "-"
*MEAS_COND_AXIS_OFFSET-19 "-"
*MEAS_COND_AXIS_OFFSET-20 "-"
*MEAS_COND_AXIS_OFFSET-21 "-"
*MEAS_COND_AXIS_OFFSET-22 "-"
*MEAS_COND_AXIS_OFFSET-23 "-"
*MEAS_COND_AXIS_OFFSET-24 "-"
*MEAS_COND_AXIS_OFFSET-25 "-"
*MEAS_COND_AXIS_OFFSET-26 "-"
*MEAS_COND_AXIS_OFFSET-27 "-"
*MEAS_COND_AXIS_OFFSET-28 "-"
*MEAS_COND_AXIS_OFFSET-29 "-"
*MEAS_COND_AXIS_OFFSET-30 "-"
*MEAS_COND_AXIS_POSITION-0 "0.0000000000"
*MEAS_COND_AXIS_POSITION-1 "0.0000000000"
*MEAS_COND_AXIS_POSITION-2 "0.0000000000"
*MEAS_COND_AXIS_POSITION-3 "-2.9256400000"
*MEAS_COND_AXIS_POSITION-4 "0.0000000000"
*MEAS_COND_AXIS_POSITION-5 "0.0000000000"
*MEAS_COND_AXIS_POSITION-6 "0.0000000000"
*MEAS_COND_AXIS_POSITION-7 "-0.4278800000"
*MEAS_COND_AXIS_POSITION-8 "BB"
*MEAS_COND_AXIS_POSITION-9 "0.0000000000"
*MEAS_COND_AXIS_POSITION-10 "Soller_slit_5.0deg"
*MEAS_COND_AXIS_POSITION-11 "2/3deg"
*MEAS_COND_AXIS_POSITION-12 "2.2088000000"
*MEAS_COND_AXIS_POSITION-13 "-1.0609400000"
*MEAS_COND_AXIS_POSITION-14 "0.0000000000"
*MEAS_COND_AXIS_POSITION-15 "10.0mm"
*MEAS_COND_AXIS_POSITION-16 "None"
*MEAS_COND_AXIS_POSITION-17 "Cu_K-beta"
*MEAS_COND_AXIS_POSITION-18 "13.000mm"
*MEAS_COND_AXIS_POSITION-19 "13.000mm"
*MEAS_COND_AXIS_POSITION-20 "No_unit"
*MEAS_COND_AXIS_POSITION-21 "Soller_slit_5.0deg"
*MEAS_COND_AXIS_POSITION-22 "None"
*MEAS_COND_AXIS_POSITION-23 "13.0000000000"
*MEAS_COND_AXIS_POSITION-24 "13.0000000000"
*MEAS_COND_AXIS_POSITION-25 "0.0081300000"
*MEAS_COND_AXIS_POSITION-26 "Open"
*MEAS_COND_AXIS_POSITION-27 "None"
*MEAS_COND_AXIS_POSITION-28 "None"
*MEAS_COND_AXIS_POSITION-29 "None"
*MEAS_COND_AXIS_POSITION-30 "38.0000000000"
*MEAS_COND_AXIS_UNIT-0 "deg"
*MEAS_COND_AXIS_UNIT-1 "deg"
*MEAS_COND_AXIS_UNIT-2 "deg"
*MEAS_COND_AXIS_UNIT-3 "mm"
*MEAS_COND_AXIS_UNIT-4 "deg"
*MEAS_COND_AXIS_UNIT-5 "deg"
*MEAS_COND_AXIS_UNIT-6 "deg"
*MEAS_COND_AXIS_UNIT-7 "mm"
*MEAS_COND_AXIS_UNIT-8 ""
*MEAS_COND_AXIS_UNIT-9 "pulse"
*MEAS_COND_AXIS_UNIT-10 ""
*MEAS_COND_AXIS_UNIT-11 ""
*MEAS_COND_AXIS_UNIT-12 "mm"
*MEAS_COND_AXIS_UNIT-13 "mm"
*MEAS_COND_AXIS_UNIT-14 ""
*MEAS_COND_AXIS_UNIT-15 ""
*MEAS_COND_AXIS_UNIT-16 ""
*MEAS_COND_AXIS_UNIT-17 ""
*MEAS_COND_AXIS_UNIT-18 ""
*MEAS_COND_AXIS_UNIT-19 ""
*MEAS_COND_AXIS_UNIT-20 ""
*MEAS_COND_AXIS_UNIT-21 ""
*MEAS_COND_AXIS_UNIT-22 ""
*MEAS_COND_AXIS_UNIT-23 "mm"
*MEAS_COND_AXIS_UNIT-24 "mm"
*MEAS_COND_AXIS_UNIT-25 "mm"
*MEAS_COND_AXIS_UNIT-26 ""
*MEAS_COND_AXIS_UNIT-27 ""
*MEAS_COND_AXIS_UNIT-28 ""
*MEAS_COND_AXIS_UNIT-29 ""
*MEAS_COND_AXIS_UNIT-30 "div"
*MEAS_COND_COUNTER_CNTLOSS_CORR "0.0000000000"
*MEAS_COND_COUNTER_PHABASE "38.0000000000"
*MEAS_COND_COUNTER_PHAWINDOW "16.0000000000"
*MEAS_COND_COUNTER_PHA_UNIT "div"
*MEAS_COND_COUNTER_TAUDIFF "30.0000000000"
*MEAS_COND_COUNTER_TAUINT "0.0000000000"
*MEAS_COND_IRRADIATION_MODE "OFF"
*MEAS_COND_IRRADIATION_WIDTH ""
*MEAS_COND_OPT_ATTR "集中法"
*MEAS_COND_OPT_NAME "@集中法"
*MEAS_COND_UNSYMMETRIC_MODE "OFF"
*MEAS_COND_XG_CURRENT "30.0000000000"
*MEAS_COND_XG_VOLTAGE "40.0000000000"
*MEAS_COND_XG_WAVE_TYPE "Ka"
*MEAS_DATA_COUNT "5001.0000000000"
*MEAS_SCAN_AXIS_X "2θ/θ"
*MEAS_SCAN_AXIS_X_INTERNAL "TwoThetaTheta"
*MEAS_SCAN_END_TIME "07/09/22 13:00:19"
*MEAS_SCAN_MODE "CONTINUOUS"
*MEAS_SCAN_MONITOR "0"
*MEAS_SCAN_RESOLUTION_X "0.0002"
*MEAS_SCAN_SPEED "2.5"
*MEAS_SCAN_SPEED_UNIT "deg/min"
*MEAS_SCAN_START "20.0000000000"
*MEAS_SCAN_START_TIME "07/09/22 12:38:55"
*MEAS_SCAN_STEP "0.0100000000"
*MEAS_SCAN_STOP "70.0000000000"
*MEAS_SCAN_UNIT_X "deg"
*MEAS_SCAN_UNIT_Y "counts"
*RAS_HEADER_END
*RAS_INT_START
20.0000 1101.0000 1.0000
20.0400 1062.0000 1.0000
20.0800 1097.0000 1.0000
20.1200 1062.0000 1.0000
20.1600 1092.0000 1.0000
20.2000 1063.0000 1.0000
20.2400 1077.0000 1.0000
20.2800 1139.0000 1.0000
20.3200 1031.0000 1.0000
20.3600 1067.0000 1.0000
20.4000 1102.0000 1.0000
20.4400 1070.0000 1.0000
20.4800 1092.0000 1.0000
20.5200 1092.0000 1.0000
20.5600 1061.0000 1.0000
20.6000 1037.0000 1.0000
20.6400 1076.0000 1.0000
20.6800 1158.0000 1.0000
20.7200 1108.0000 1.0000
20.7600 1070.0000 1.0000
20.8000 1144.0000 1.0000
20.8400 1039.0000 1.0000
20.8800 1101.0000 1.0000
20.9200 1058.0000 1.0000
20.9600 1116.0000 1.0000
21.0000 1092.0000 1.0000
21.0400 1103.0000 1.0000
21.0800 1046.0000 1.0000
21.1200 1103.0000 1.0000
21.1600 1045.0000 1.0000
21.2000 1090.0000 1.0000
21.2400 1105.0000 1.0000
21.2800 1136.0000 1.0000
21.3200 1115.0000 1.0000
21.3600 1022.0000 1.0000
21.4000 1095.0000 1.0000
21.4400 1089.0000 1.0000
21.4800 1096.0000 1.0000
21.5200 1057.0000 1.0000
21.5600 1105.0000 1.0000
21.6000 1103.0000 1.0000
21.6400 1089.0000 1.0000
21.6800 1106.0000 1.0000
21.7200 1096.0000 1.0000
21.7600 1078.0000 1.0000
21.8000 1100.0000 1.0000
21.8400 1069.0000 1.0000
21.8800 1023.0000 1.0000
21.9200 1060.0000 1.0000
21.9600 1094.0000 1.0000
22.0000 1122.0000 1.0000
22.0400 1063.0000 1.0000
22.0800 1099.0000 1.0000
22.1200 1079.0000 1.0000
22.1600 1125.0000 1.0000
22.2000 1084.0000 1.0000
22.2400 1079.0000 1.0000
22.2800 1067.0000 1.0000
22.3200 1073.0000 1.0000
22.3600 1053.0000 1.0000
22.4000 1110.0000 1.0000
22.4400 1076.0000 1.0000
22.4800 1126.0000 1.0000
22.5200 1098.0000 1.0000
22.5600 1053.0000 1.0000
22.6000 1132.0000 1.0000
22.6400 1045.0000 1.0000
22.6800 1041.0000 1.0000
22.7200 1083.0000 1.0000
22.7600 1048.0000 1.0000
22.8000 1092.0000 1.0000
22.8400 1063.0000 1.0000
22.8800 1100.0000 1.0000
22.9200 1079.0000 1.0000
22.9600 1103.0000 1.0000
23.0000 1075.0000 1.0000
23.0400 1050.0000 1.0000
23.0800 1091.0000 1.0000
23.1200 1060.0000 1.0000
23.1600 1063.0000 1.0000
23.2000 1067.0000 1.0000
23.2400 1044.0000 1.0000
23.2800 1094.0000 1.0000
23.3200 1071.0000 1.0000
23.3600 1073.0000 1.0000
23.4000 1051.0000 1.0000
23.4400 1077.0000 1.0000
23.4800 1021.0000 1.0000
23.5200 1060.0000 1.0000
23.5600 1062.0000 1.0000
23.6000 1048.0000 1.0000
23.6400 1076.0000 1.0000
23.6800 1096.0000 1.0000
23.7200 1094.0000 1.0000
23.7600 1067.0000 1.0000
23.8000 1059.0000 1.0000
23.8400 1110.0000 1.0000
23.8800 1085.0000 1.0000
23.9200 1149.0000 1.0000
23.9600 1122.0000 1.0000
24.0000 1143.0000 1.0000
24.0400 1132.0000 1.0000
24.0800 1200.0000 1.0000
24.1200 1187.0000 1.0000
24.1600 1153.0000 1.0000
24.2000 1116.0000 1.0000
24.2400 1097.0000 1.0000
24.2800 1119.0000 1.0000
24.3200 1100.0000 1.0000
24.3600 1073.0000 1.0000
24.4000 1123.0000 1.0000
24.4400 1118.0000 1.0000
24.4800 1045.0000 1.0000
24.5200 1021.0000 1.0000
24.5600 1060.0000 1.0000
24.6000 1039.0000 1.0000
24.6400 1081.0000 1.0000
24.6800 1075.0000 1.0000
24.7200 1017.0000 1.0000
24.7600 1064.0000 1.0000
24.8000 1012.0000 1.0000
24.8400 1013.0000 1.0000
24.8800 1027.0000 1.0000
24.9200 1043.0000 1.0000
24.9600 1022.0000 1.0000
25.0000 1071.0000 1.0000
25.0400 1056.0000 1.0000
25.0800 1065.0000 1.0000
25.1200 1054.0000 1.0000
25.1600 1042.0000 1.0000
25.2000 1062.0000 1.0000
25.2400 1118.0000 1.0000
25.2800 1039.0000 1.0000
25.3200 1010.0000 1.0000
25.3600 1015.0000 1.0000
25.4000 1018.0000 1.0000
25.4400 1065.0000 1.0000
25.4800 1106.0000 1.0000
25.5200 1052.0000 1.0000
25.5600 1033.0000 1.0000
25.6000 1035.0000 1.0000
25.6400 1049.0000 1.0000
25.6800 1078.0000 1.0000
25.7200 1038.0000 1.0000
25.7600 1073.0000 1.0000
25.8000 1066.0000 1.0000
25.8400 1026.0000 1.0000
25.8800 1096.0000 1.0000
25.9200 1076.0000 1.0000
25.9600 1093.0000 1.0000
26.0000 1140.0000 1.0000
26.0400 1207.0000 1.0000
26.0800 1230.0000 1.0000
26.1200 1286.0000 1.0000
26.1600 1333.0000 1.0000
26.2000 1481.0000 1.0000
26.2400 1639.0000 1.0000
26.2800 1957.0000 1.0000
26.3200 2388.0000 1.0000
26.3600 2975.0000 1.0000
26.4000 3668.0000 1.0000
26.4400 4194.0000 1.0000
26.4800 3802.0000 1.0000
26.5200 3163.0000 1.0000
26.5600 2557.0000 1.0000
26.6000 2011.0000 1.0000
26.6400 1775.0000 1.0000
26.6800 1538.0000 1.0000
26.7200 1350.0000 1.0000
26.7600 1279.0000 1.0000
26.8000 1204.0000 1.0000
26.8400 1175.0000 1.0000
26.8800 1122.0000 1.0000
26.9200 1118.0000 1.0000
26.9600 1081.0000 1.0000
27.0000 1090.0000 1.0000
27.0400 1050.0000 1.0000
27.0800 980.0000 1.0000
27.1200 1039.0000 1.0000
27.1600 1036.0000 1.0000
27.2000 1015.0000 1.0000
27.2400 1005.0000 1.0000
27.2800 944.0000 1.0000
27.3200 955.0000 1.0000
27.3600 981.0000 1.0000
27.4000 993.0000 1.0000
27.4400 972.0000 1.0000
27.4800 982.0000 1.0000
27.5200 991.0000 1.0000
27.5600 941.0000 1.0000
27.6000 954.0000 1.0000
27.6400 991.0000 1.0000
27.6800 987.0000 1.0000
27.7200 982.0000 1.0000
27.7600 1019.0000 1.0000
27.8000 970.0000 1.0000
27.8400 972.0000 1.0000
27.8800 969.0000 1.0000
27.9200 906.0000 1.0000
27.9600 1037.0000 1.0000
28.0000 938.0000 1.0000
28.0400 947.0000 1.0000
28.0800 925.0000 1.0000
28.1200 920.0000 1.0000
28.1600 923.0000 1.0000
28.2000 953.0000 1.0000
28.2400 940.0000 1.0000
28.2800 946.0000 1.0000
28.3200 933.0000 1.0000
28.3600 881.0000 1.0000
28.4000 871.0000 1.0000
28.4400 959.0000 1.0000
28.4800 887.0000 1.0000
28.5200 918.0000 1.0000
28.5600 864.0000 1.0000
28.6000 941.0000 1.0000
28.6400 933.0000 1.0000
28.6800 939.0000 1.0000
28.7200 933.0000 1.0000
28.7600 910.0000 1.0000
28.8000 924.0000 1.0000
28.8400 884.0000 1.0000
28.8800 896.0000 1.0000
28.9200 886.0000 1.0000
28.9600 935.0000 1.0000
29.0000 864.0000 1.0000
29.0400 899.0000 1.0000
29.0800 869.0000 1.0000
29.1200 873.0000 1.0000
29.1600 960.0000 1.0000
29.2000 897.0000 1.0000
29.2400 851.0000 1.0000
29.2800 861.0000 1.0000
29.3200 887.0000 1.0000
29.3600 865.0000 1.0000
29.4000 896.0000 1.0000
29.4400 868.0000 1.0000
29.4800 899.0000 1.0000
29.5200 841.0000 1.0000
29.5600 849.0000 1.0000
29.6000 880.0000 1.0000
29.6400 869.0000 1.0000
29.6800 916.0000 1.0000
29.7200 854.0000 1.0000
29.7600 862.0000 1.0000
29.8000 875.0000 1.0000
29.8400 844.0000 1.0000
29.8800 867.0000 1.0000
29.9200 862.0000 1.0000
29.9600 851.0000 1.0000
30.0000 801.0000 1.0000
30.0400 846.0000 1.0000
30.0800 842.0000 1.0000
30.1200 851.0000 1.0000
30.1600 873.0000 1.0000
30.2000 821.0000 1.0000
30.2400 865.0000 1.0000
30.2800 882.0000 1.0000
30.3200 861.0000 1.0000
30.3600 838.0000 1.0000
30.4000 806.0000 1.0000
30.4400 800.0000 1.0000
30.4800 880.0000 1.0000
30.5200 854.0000 1.0000
30.5600 840.0000 1.0000
30.6000 868.0000 1.0000
30.6400 812.0000 1.0000
30.6800 881.0000 1.0000
30.7200 827.0000 1.0000
30.7600 813.0000 1.0000
30.8000 836.0000 1.0000
30.8400 830.0000 1.0000
30.8800 819.0000 1.0000
30.9200 808.0000 1.0000
30.9600 898.0000 1.0000
31.0000 801.0000 1.0000
31.0400 811.0000 1.0000
31.0800 811.0000 1.0000
31.1200 863.0000 1.0000
31.1600 877.0000 1.0000
31.2000 879.0000 1.0000
31.2400 845.0000 1.0000
31.2800 864.0000 1.0000
31.3200 831.0000 1.0000
31.3600 850.0000 1.0000
31.4000 831.0000 1.0000
31.4400 781.0000 1.0000
31.4800 821.0000 1.0000
31.5200 806.0000 1.0000
31.5600 794.0000 1.0000
31.6000 816.0000 1.0000
31.6400 796.0000 1.0000
31.6800 825.0000 1.0000
31.7200 758.0000 1.0000
31.7600 804.0000 1.0000
31.8000 845.0000 1.0000
31.8400 808.0000 1.0000
31.8800 810.0000 1.0000
31.9200 810.0000 1.0000
31.9600 806.0000 1.0000
32.0000 775.0000 1.0000
32.0400 801.0000 1.0000
32.0800 784.0000 1.0000
32.1200 789.0000 1.0000
32.1600 816.0000 1.0000
32.2000 776.0000 1.0000
32.2400 794.0000 1.0000
32.2800 826.0000 1.0000
32.3200 801.0000 1.0000
32.3600 813.0000 1.0000
32.4000 791.0000 1.0000
32.4400 782.0000 1.0000
32.4800 857.0000 1.0000
32.5200 838.0000 1.0000
32.5600 767.0000 1.0000
32.6000 818.0000 1.0000
32.6400 811.0000 1.0000
32.6800 787.0000 1.0000
32.7200 793.0000 1.0000
32.7600 778.0000 1.0000
32.8000 818.0000 1.0000
32.8400 861.0000 1.0000
32.8800 875.0000 1.0000
32.9200 842.0000 1.0000
32.9600 902.0000 1.0000
33.0000 919.0000 1.0000
33.0400 1022.0000 1.0000
33.0800 1029.0000 1.0000
33.1200 1030.0000 1.0000
33.1600 1019.0000 1.0000
33.2000 963.0000 1.0000
33.2400 904.0000 1.0000
33.2800 961.0000 1.0000
33.3200 887.0000 1.0000
33.3600 890.0000 1.0000
33.4000 977.0000 1.0000
33.4400 984.0000 1.0000
33.4800 1078.0000 1.0000
33.5200 1241.0000 1.0000
33.5600 1576.0000 1.0000
33.6000 1835.0000 1.0000
33.6400 2018.0000 1.0000
33.6800 1956.0000 1.0000
33.7200 1742.0000 1.0000
33.7600 1519.0000 1.0000
33.8000 1271.0000 1.0000
33.8400 1114.0000 1.0000
33.8800 967.0000 1.0000
33.9200 949.0000 1.0000
33.9600 899.0000 1.0000
34.0000 878.0000 1.0000
34.0400 789.0000 1.0000
34.0800 775.0000 1.0000
34.1200 786.0000 1.0000
34.1600 751.0000 1.0000
34.2000 736.0000 1.0000
34.2400 711.0000 1.0000
34.2800 754.0000 1.0000
34.3200 734.0000 1.0000
34.3600 721.0000 1.0000
34.4000 699.0000 1.0000
34.4400 715.0000 1.0000
34.4800 688.0000 1.0000
34.5200 693.0000 1.0000
34.5600 721.0000 1.0000
34.6000 729.0000 1.0000
34.6400 694.0000 1.0000
34.6800 693.0000 1.0000
34.7200 697.0000 1.0000
34.7600 728.0000 1.0000
34.8000 688.0000 1.0000
34.8400 668.0000 1.0000
34.8800 641.0000 1.0000
34.9200 639.0000 1.0000
34.9600 691.0000 1.0000
35.0000 647.0000 1.0000
35.0400 659.0000 1.0000
35.0800 662.0000 1.0000
35.1200 667.0000 1.0000
35.1600 632.0000 1.0000
35.2000 657.0000 1.0000
35.2400 684.0000 1.0000
35.2800 680.0000 1.0000
35.3200 716.0000 1.0000
35.3600 720.0000 1.0000
35.4000 780.0000 1.0000
35.4400 764.0000 1.0000
35.4800 896.0000 1.0000
35.5200 1034.0000 1.0000
35.5600 1081.0000 1.0000
35.6000 1159.0000 1.0000
35.6400 1085.0000 1.0000
35.6800 985.0000 1.0000
35.7200 886.0000 1.0000
35.7600 757.0000 1.0000
35.8000 695.0000 1.0000
35.8400 643.0000 1.0000
35.8800 634.0000 1.0000
35.9200 642.0000 1.0000
35.9600 700.0000 1.0000
36.0000 637.0000 1.0000
36.0400 618.0000 1.0000
36.0800 618.0000 1.0000
36.1200 573.0000 1.0000
36.1600 591.0000 1.0000
36.2000 610.0000 1.0000
36.2400 591.0000 1.0000
36.2800 606.0000 1.0000
36.3200 638.0000 1.0000
36.3600 638.0000 1.0000
36.4000 667.0000 1.0000
36.4400 615.0000 1.0000
36.4800 616.0000 1.0000
36.5200 605.0000 1.0000
36.5600 608.0000 1.0000
36.6000 595.0000 1.0000
36.6400 639.0000 1.0000
36.6800 624.0000 1.0000
36.7200 570.0000 1.0000
36.7600 587.0000 1.0000
36.8000 570.0000 1.0000
36.8400 631.0000 1.0000
36.8800 617.0000 1.0000
36.9200 614.0000 1.0000
36.9600 562.0000 1.0000
37.0000 601.0000 1.0000
37.0400 605.0000 1.0000
37.0800 594.0000 1.0000
37.1200 613.0000 1.0000
37.1600 625.0000 1.0000
37.2000 650.0000 1.0000
37.2400 619.0000 1.0000
37.2800 651.0000 1.0000
37.3200 686.0000 1.0000
37.3600 758.0000 1.0000
37.4000 769.0000 1.0000
37.4400 933.0000 1.0000
37.4800 1022.0000 1.0000
37.5200 1234.0000 1.0000
37.5600 1503.0000 1.0000
37.6000 1976.0000 1.0000
37.6400 2531.0000 1.0000
37.6800 2917.0000 1.0000
37.7200 3052.0000 1.0000
37.7600 2820.0000 1.0000
37.8000 2413.0000 1.0000
37.8400 2062.0000 1.0000
37.8800 1621.0000 1.0000
37.9200 1241.0000 1.0000
37.9600 1002.0000 1.0000
38.0000 902.0000 1.0000
38.0400 796.0000 1.0000
38.0800 719.0000 1.0000
38.1200 699.0000 1.0000
38.1600 633.0000 1.0000
38.2000 638.0000 1.0000
38.2400 594.0000 1.0000
38.2800 601.0000 1.0000
38.3200 575.0000 1.0000
38.3600 571.0000 1.0000
38.4000 599.0000 1.0000
38.4400 587.0000 1.0000
38.4800 548.0000 1.0000
38.5200 572.0000 1.0000
38.5600 598.0000 1.0000
38.6000 532.0000 1.0000
38.6400 543.0000 1.0000
38.6800 585.0000 1.0000
38.7200 588.0000 1.0000
38.7600 544.0000 1.0000
38.8000 588.0000 1.0000
38.8400 561.0000 1.0000
38.8800 521.0000 1.0000
38.9200 567.0000 1.0000
38.9600 543.0000 1.0000
39.0000 543.0000 1.0000
39.0400 540.0000 1.0000
39.0800 503.0000 1.0000
39.1200 482.0000 1.0000
39.1600 539.0000 1.0000
39.2000 528.0000 1.0000
39.2400 515.0000 1.0000
39.2800 543.0000 1.0000
39.3200 535.0000 1.0000
39.3600 525.0000 1.0000
39.4000 524.0000 1.0000
39.4400 502.0000 1.0000
39.4800 509.0000 1.0000
39.5200 512.0000 1.0000
39.5600 557.0000 1.0000
39.6000 541.0000 1.0000
39.6400 562.0000 1.0000
39.6800 518.0000 1.0000
39.7200 520.0000 1.0000
39.7600 490.0000 1.0000
39.8000 508.0000 1.0000
39.8400 463.0000 1.0000
39.8800 514.0000 1.0000
39.9200 488.0000 1.0000
39.9600 510.0000 1.0000
40.0000 484.0000 1.0000
40.0400 509.0000 1.0000
40.0800 536.0000 1.0000
40.1200 495.0000 1.0000
40.1600 518.0000 1.0000
40.2000 519.0000 1.0000
40.2400 517.0000 1.0000
40.2800 529.0000 1.0000
40.3200 518.0000 1.0000
40.3600 466.0000 1.0000
40.4000 508.0000 1.0000
40.4400 500.0000 1.0000
40.4800 505.0000 1.0000
40.5200 533.0000 1.0000
40.5600 547.0000 1.0000
40.6000 477.0000 1.0000
40.6400 533.0000 1.0000
40.6800 492.0000 1.0000
40.7200 534.0000 1.0000
40.7600 522.0000 1.0000
40.8000 571.0000 1.0000
40.8400 505.0000 1.0000
40.8800 543.0000 1.0000
40.9200 514.0000 1.0000
40.9600 560.0000 1.0000
41.0000 500.0000 1.0000
41.0400 487.0000 1.0000
41.0800 501.0000 1.0000
41.1200 478.0000 1.0000
41.1600 471.0000 1.0000
41.2000 474.0000 1.0000
41.2400 489.0000 1.0000
41.2800 497.0000 1.0000
41.3200 510.0000 1.0000
41.3600 470.0000 1.0000
41.4000 453.0000 1.0000
41.4400 458.0000 1.0000
41.4800 492.0000 1.0000
41.5200 496.0000 1.0000
41.5600 478.0000 1.0000
41.6000 514.0000 1.0000
41.6400 484.0000 1.0000
41.6800 468.0000 1.0000
41.7200 465.0000 1.0000
41.7600 461.0000 1.0000
41.8000 489.0000 1.0000
41.8400 486.0000 1.0000
41.8800 432.0000 1.0000
41.9200 451.0000 1.0000
41.9600 482.0000 1.0000
42.0000 457.0000 1.0000
42.0400 461.0000 1.0000
42.0800 454.0000 1.0000
42.1200 443.0000 1.0000
42.1600 442.0000 1.0000
42.2000 478.0000 1.0000
42.2400 460.0000 1.0000
42.2800 471.0000 1.0000
42.3200 501.0000 1.0000
42.3600 465.0000 1.0000
42.4000 540.0000 1.0000
42.4400 492.0000 1.0000
42.4800 487.0000 1.0000
42.5200 460.0000 1.0000
42.5600 452.0000 1.0000
42.6000 460.0000 1.0000
42.6400 469.0000 1.0000
42.6800 433.0000 1.0000
42.7200 463.0000 1.0000
42.7600 457.0000 1.0000
42.8000 446.0000 1.0000
42.8400 427.0000 1.0000
42.8800 452.0000 1.0000
42.9200 436.0000 1.0000
42.9600 442.0000 1.0000
43.0000 451.0000 1.0000
43.0400 477.0000 1.0000
43.0800 421.0000 1.0000
43.1200 437.0000 1.0000
43.1600 444.0000 1.0000
43.2000 414.0000 1.0000
43.2400 427.0000 1.0000
43.2800 417.0000 1.0000
43.3200 434.0000 1.0000
43.3600 443.0000 1.0000
43.4000 434.0000 1.0000
43.4400 444.0000 1.0000
43.4800 472.0000 1.0000
43.5200 446.0000 1.0000
43.5600 496.0000 1.0000
43.6000 446.0000 1.0000
43.6400 429.0000 1.0000
43.6800 436.0000 1.0000
43.7200 466.0000 1.0000
43.7600 469.0000 1.0000
43.8000 402.0000 1.0000
43.8400 420.0000 1.0000
43.8800 456.0000 1.0000
43.9200 469.0000 1.0000
43.9600 447.0000 1.0000
44.0000 434.0000 1.0000
44.0400 414.0000 1.0000
44.0800 438.0000 1.0000
44.1200 452.0000 1.0000
44.1600 440.0000 1.0000
44.2000 420.0000 1.0000
44.2400 441.0000 1.0000
44.2800 403.0000 1.0000
44.3200 412.0000 1.0000
44.3600 409.0000 1.0000
44.4000 402.0000 1.0000
44.4400 429.0000 1.0000
44.4800 456.0000 1.0000
44.5200 449.0000 1.0000
44.5600 426.0000 1.0000
44.6000 416.0000 1.0000
44.6400 412.0000 1.0000
44.6800 446.0000 1.0000
44.7200 420.0000 1.0000
44.7600 401.0000 1.0000
44.8000 397.0000 1.0000
44.8400 421.0000 1.0000
44.8800 442.0000 1.0000
44.9200 396.0000 1.0000
44.9600 413.0000 1.0000
45.0000 408.0000 1.0000
45.0400 388.0000 1.0000
45.0800 417.0000 1.0000
45.1200 441.0000 1.0000
45.1600 402.0000 1.0000
45.2000 416.0000 1.0000
45.2400 420.0000 1.0000
45.2800 393.0000 1.0000
45.3200 442.0000 1.0000
45.3600 430.0000 1.0000
45.4000 399.0000 1.0000
45.4400 395.0000 1.0000
45.4800 412.0000 1.0000
45.5200 425.0000 1.0000
45.5600 398.0000 1.0000
45.6000 407.0000 1.0000
45.6400 415.0000 1.0000
45.6800 398.0000 1.0000
45.7200 405.0000 1.0000
45.7600 433.0000 1.0000
45.8000 418.0000 1.0000
45.8400 410.0000 1.0000
45.8800 420.0000 1.0000
45.9200 404.0000 1.0000
45.9600 433.0000 1.0000
46.0000 402.0000 1.0000
46.0400 447.0000 1.0000
46.0800 421.0000 1.0000
46.1200 411.0000 1.0000
46.1600 392.0000 1.0000
46.2000 402.0000 1.0000
46.2400 438.0000 1.0000
46.2800 437.0000 1.0000
46.3200 425.0000 1.0000
46.3600 454.0000 1.0000
46.4000 388.0000 1.0000
46.4400 383.0000 1.0000
46.4800 394.0000 1.0000
46.5200 401.0000 1.0000
46.5600 409.0000 1.0000
46.6000 376.0000 1.0000
46.6400 383.0000 1.0000
46.6800 383.0000 1.0000
46.7200 381.0000 1.0000
46.7600 411.0000 1.0000
46.8000 381.0000 1.0000
46.8400 416.0000 1.0000
46.8800 401.0000 1.0000
46.9200 414.0000 1.0000
46.9600 433.0000 1.0000
47.0000 395.0000 1.0000
47.0400 402.0000 1.0000
47.0800 418.0000 1.0000
47.1200 405.0000 1.0000
47.1600 386.0000 1.0000
47.2000 408.0000 1.0000
47.2400 376.0000 1.0000
47.2800 415.0000 1.0000
47.3200 395.0000 1.0000
47.3600 379.0000 1.0000
47.4000 424.0000 1.0000
47.4400 361.0000 1.0000
47.4800 372.0000 1.0000
47.5200 386.0000 1.0000
47.5600 403.0000 1.0000
47.6000 374.0000 1.0000
47.6400 421.0000 1.0000
47.6800 397.0000 1.0000
47.7200 385.0000 1.0000
47.7600 363.0000 1.0000
47.8000 373.0000 1.0000
47.8400 415.0000 1.0000
47.8800 380.0000 1.0000
47.9200 380.0000 1.0000
47.9600 399.0000 1.0000
48.0000 354.0000 1.0000
48.0400 365.0000 1.0000
48.0800 416.0000 1.0000
48.1200 382.0000 1.0000
48.1600 388.0000 1.0000
48.2000 386.0000 1.0000
48.2400 403.0000 1.0000
48.2800 401.0000 1.0000
48.3200 394.0000 1.0000
48.3600 387.0000 1.0000
48.4000 382.0000 1.0000
48.4400 397.0000 1.0000
48.4800 405.0000 1.0000
48.5200 361.0000 1.0000
48.5600 378.0000 1.0000
48.6000 368.0000 1.0000
48.6400 351.0000 1.0000
48.6800 369.0000 1.0000
48.7200 370.0000 1.0000
48.7600 369.0000 1.0000
48.8000 384.0000 1.0000
48.8400 370.0000 1.0000
48.8800 382.0000 1.0000
48.9200 397.0000 1.0000
48.9600 413.0000 1.0000
49.0000 388.0000 1.0000
49.0400 411.0000 1.0000
49.0800 399.0000 1.0000
49.1200 360.0000 1.0000
49.1600 388.0000 1.0000
49.2000 409.0000 1.0000
49.2400 387.0000 1.0000
49.2800 405.0000 1.0000
49.3200 476.0000 1.0000
49.3600 443.0000 1.0000
49.4000 443.0000 1.0000
49.4400 422.0000 1.0000
49.4800 449.0000 1.0000
49.5200 424.0000 1.0000
49.5600 427.0000 1.0000
49.6000 398.0000 1.0000
49.6400 412.0000 1.0000
49.6800 371.0000 1.0000
49.7200 383.0000 1.0000
49.7600 441.0000 1.0000
49.8000 389.0000 1.0000
49.8400 369.0000 1.0000
49.8800 391.0000 1.0000
49.9200 374.0000 1.0000
49.9600 427.0000 1.0000
50.0000 368.0000 1.0000
50.0400 367.0000 1.0000
50.0800 375.0000 1.0000
50.1200 408.0000 1.0000
50.1600 370.0000 1.0000
50.2000 385.0000 1.0000
50.2400 370.0000 1.0000
50.2800 359.0000 1.0000
50.3200 383.0000 1.0000
50.3600 373.0000 1.0000
50.4000 375.0000 1.0000
50.4400 388.0000 1.0000
50.4800 400.0000 1.0000
50.5200 394.0000 1.0000
50.5600 392.0000 1.0000
50.6000 394.0000 1.0000
50.6400 380.0000 1.0000
50.6800 388.0000 1.0000
50.7200 421.0000 1.0000
50.7600 381.0000 1.0000
50.8000 412.0000 1.0000
50.8400 430.0000 1.0000
50.8800 417.0000 1.0000
50.9200 394.0000 1.0000
50.9600 399.0000 1.0000
51.0000 433.0000 1.0000
51.0400 410.0000 1.0000
51.0800 453.0000 1.0000
51.1200 487.0000 1.0000
51.1600 515.0000 1.0000
51.2000 637.0000 1.0000
51.2400 686.0000 1.0000
51.2800 763.0000 1.0000
51.3200 1057.0000 1.0000
51.3600 1268.0000 1.0000
51.4000 1762.0000 1.0000
51.4400 2349.0000 1.0000
51.4800 2600.0000 1.0000
51.5200 2566.0000 1.0000
51.5600 2246.0000 1.0000
51.6000 1971.0000 1.0000
51.6400 1695.0000 1.0000
51.6800 1313.0000 1.0000
51.7200 1043.0000 1.0000
51.7600 777.0000 1.0000
51.8000 669.0000 1.0000
51.8400 598.0000 1.0000
51.8800 523.0000 1.0000
51.9200 487.0000 1.0000
51.9600 480.0000 1.0000
52.0000 476.0000 1.0000
52.0400 458.0000 1.0000
52.0800 442.0000 1.0000
52.1200 447.0000 1.0000
52.1600 424.0000 1.0000
52.2000 401.0000 1.0000
52.2400 400.0000 1.0000
52.2800 395.0000 1.0000
52.3200 403.0000 1.0000
52.3600 395.0000 1.0000
52.4000 388.0000 1.0000
52.4400 383.0000 1.0000
52.4800 381.0000 1.0000
52.5200 371.0000 1.0000
52.5600 386.0000 1.0000
52.6000 351.0000 1.0000
52.6400 378.0000 1.0000
52.6800 375.0000 1.0000
52.7200 388.0000 1.0000
52.7600 394.0000 1.0000
52.8000 401.0000 1.0000
52.8400 377.0000 1.0000
52.8800 395.0000 1.0000
52.9200 377.0000 1.0000
52.9600 383.0000 1.0000
53.0000 346.0000 1.0000
53.0400 378.0000 1.0000
53.0800 387.0000 1.0000
53.1200 359.0000 1.0000
53.1600 355.0000 1.0000
53.2000 359.0000 1.0000
53.2400 364.0000 1.0000
53.2800 371.0000 1.0000
53.3200 350.0000 1.0000
53.3600 351.0000 1.0000
53.4000 379.0000 1.0000
53.4400 365.0000 1.0000
53.4800 377.0000 1.0000
53.5200 384.0000 1.0000
53.5600 366.0000 1.0000
53.6000 378.0000 1.0000
53.6400 404.0000 1.0000
53.6800 361.0000 1.0000
53.7200 389.0000 1.0000
53.7600 365.0000 1.0000
53.8000 367.0000 1.0000
53.8400 390.0000 1.0000
53.8800 407.0000 1.0000
53.9200 425.0000 1.0000
53.9600 437.0000 1.0000
54.0000 461.0000 1.0000
54.0400 423.0000 1.0000
54.0800 421.0000 1.0000
54.1200 424.0000 1.0000
54.1600 426.0000 1.0000
54.2000 450.0000 1.0000
54.2400 425.0000 1.0000
54.2800 434.0000 1.0000
54.3200 447.0000 1.0000
54.3600 464.0000 1.0000
54.4000 491.0000 1.0000
54.4400 542.0000 1.0000
54.4800 580.0000 1.0000
54.5200 597.0000 1.0000
54.5600 582.0000 1.0000
54.6000 560.0000 1.0000
54.6400 515.0000 1.0000
54.6800 489.0000 1.0000
54.7200 430.0000 1.0000
54.7600 424.0000 1.0000
54.8000 394.0000 1.0000
54.8400 408.0000 1.0000
54.8800 382.0000 1.0000
54.9200 406.0000 1.0000
54.9600 398.0000 1.0000
55.0000 345.0000 1.0000
55.0400 410.0000 1.0000
55.0800 373.0000 1.0000
55.1200 357.0000 1.0000
55.1600 378.0000 1.0000
55.2000 365.0000 1.0000
55.2400 391.0000 1.0000
55.2800 388.0000 1.0000
55.3200 374.0000 1.0000
55.3600 390.0000 1.0000
55.4000 339.0000 1.0000
55.4400 376.0000 1.0000
55.4800 348.0000 1.0000
55.5200 329.0000 1.0000
55.5600 350.0000 1.0000
55.6000 331.0000 1.0000
55.6400 335.0000 1.0000
55.6800 359.0000 1.0000
55.7200 376.0000 1.0000
55.7600 352.0000 1.0000
55.8000 362.0000 1.0000
55.8400 331.0000 1.0000
55.8800 347.0000 1.0000
55.9200 359.0000 1.0000
55.9600 389.0000 1.0000
56.0000 311.0000 1.0000
56.0400 361.0000 1.0000
56.0800 368.0000 1.0000
56.1200 380.0000 1.0000
56.1600 369.0000 1.0000
56.2000 350.0000 1.0000
56.2400 342.0000 1.0000
56.2800 336.0000 1.0000
56.3200 345.0000 1.0000
56.3600 368.0000 1.0000
56.4000 347.0000 1.0000
56.4400 361.0000 1.0000
56.4800 356.0000 1.0000
56.5200 376.0000 1.0000
56.5600 361.0000 1.0000
56.6000 352.0000 1.0000
56.6400 364.0000 1.0000
56.6800 353.0000 1.0000
56.7200 340.0000 1.0000
56.7600 359.0000 1.0000
56.8000 339.0000 1.0000
56.8400 348.0000 1.0000
56.8800 356.0000 1.0000
56.9200 345.0000 1.0000
56.9600 334.0000 1.0000
57.0000 354.0000 1.0000
57.0400 365.0000 1.0000
57.0800 340.0000 1.0000
57.1200 356.0000 1.0000
57.1600 323.0000 1.0000
57.2000 358.0000 1.0000
57.2400 365.0000 1.0000
57.2800 334.0000 1.0000
57.3200 383.0000 1.0000
57.3600 354.0000 1.0000
57.4000 349.0000 1.0000
57.4400 378.0000 1.0000
57.4800 373.0000 1.0000
57.5200 369.0000 1.0000
57.5600 365.0000 1.0000
57.6000 365.0000 1.0000
57.6400 357.0000 1.0000
57.6800 374.0000 1.0000
57.7200 362.0000 1.0000
57.7600 374.0000 1.0000
57.8000 368.0000 1.0000
57.8400 369.0000 1.0000
57.8800 330.0000 1.0000
57.9200 348.0000 1.0000
57.9600 363.0000 1.0000
58.0000 345.0000 1.0000
58.0400 342.0000 1.0000
58.0800 354.0000 1.0000
58.1200 332.0000 1.0000
58.1600 357.0000 1.0000
58.2000 334.0000 1.0000
58.2400 363.0000 1.0000
58.2800 333.0000 1.0000
58.3200 346.0000 1.0000
58.3600 332.0000 1.0000
58.4000 366.0000 1.0000
58.4400 376.0000 1.0000
58.4800 334.0000 1.0000
58.5200 382.0000 1.0000
58.5600 386.0000 1.0000
58.6000 326.0000 1.0000
58.6400 362.0000 1.0000
58.6800 318.0000 1.0000
58.7200 323.0000 1.0000
58.7600 343.0000 1.0000
58.8000 355.0000 1.0000
58.8400 355.0000 1.0000
58.8800 385.0000 1.0000
58.9200 336.0000 1.0000
58.9600 344.0000 1.0000
59.0000 337.0000 1.0000
59.0400 357.0000 1.0000
59.0800 361.0000 1.0000
59.1200 355.0000 1.0000
59.1600 359.0000 1.0000
59.2000 354.0000 1.0000
59.2400 314.0000 1.0000
59.2800 338.0000 1.0000
59.3200 332.0000 1.0000
59.3600 381.0000 1.0000
59.4000 351.0000 1.0000
59.4400 371.0000 1.0000
59.4800 341.0000 1.0000
59.5200 350.0000 1.0000
59.5600 357.0000 1.0000
59.6000 347.0000 1.0000
59.6400 324.0000 1.0000
59.6800 320.0000 1.0000
59.7200 366.0000 1.0000
59.7600 348.0000 1.0000
59.8000 367.0000 1.0000
59.8400 368.0000 1.0000
59.8800 347.0000 1.0000
59.9200 335.0000 1.0000
59.9600 332.0000 1.0000
60.0000 363.0000 1.0000
60.0400 330.0000 1.0000
60.0800 354.0000 1.0000
60.1200 343.0000 1.0000
60.1600 343.0000 1.0000
60.2000 368.0000 1.0000
60.2400 338.0000 1.0000
60.2800 366.0000 1.0000
60.3200 336.0000 1.0000
60.3600 349.0000 1.0000
60.4000 326.0000 1.0000
60.4400 340.0000 1.0000
60.4800 363.0000 1.0000
60.5200 343.0000 1.0000
60.5600 342.0000 1.0000
60.6000 338.0000 1.0000
60.6400 350.0000 1.0000
60.6800 306.0000 1.0000
60.7200 372.0000 1.0000
60.7600 354.0000 1.0000
60.8000 331.0000 1.0000
60.8400 372.0000 1.0000
60.8800 378.0000 1.0000
60.9200 342.0000 1.0000
60.9600 350.0000 1.0000
61.0000 361.0000 1.0000
61.0400 386.0000 1.0000
61.0800 362.0000 1.0000
61.1200 376.0000 1.0000
61.1600 379.0000 1.0000
61.2000 409.0000 1.0000
61.2400 437.0000 1.0000
61.2800 454.0000 1.0000
61.3200 535.0000 1.0000
61.3600 571.0000 1.0000
61.4000 568.0000 1.0000
61.4400 632.0000 1.0000
61.4800 710.0000 1.0000
61.5200 730.0000 1.0000
61.5600 725.0000 1.0000
61.6000 726.0000 1.0000
61.6400 719.0000 1.0000
61.6800 667.0000 1.0000
61.7200 614.0000 1.0000
61.7600 582.0000 1.0000
61.8000 590.0000 1.0000
61.8400 506.0000 1.0000
61.8800 461.0000 1.0000
61.9200 450.0000 1.0000
61.9600 433.0000 1.0000
62.0000 423.0000 1.0000
62.0400 376.0000 1.0000
62.0800 363.0000 1.0000
62.1200 397.0000 1.0000
62.1600 397.0000 1.0000
62.2000 388.0000 1.0000
62.2400 369.0000 1.0000
62.2800 388.0000 1.0000
62.3200 406.0000 1.0000
62.3600 389.0000 1.0000
62.4000 403.0000 1.0000
62.4400 382.0000 1.0000
62.4800 377.0000 1.0000
62.5200 367.0000 1.0000
62.5600 361.0000 1.0000
62.6000 361.0000 1.0000
62.6400 356.0000 1.0000
62.6800 341.0000 1.0000
62.7200 352.0000 1.0000
62.7600 363.0000 1.0000
62.8000 363.0000 1.0000
62.8400 329.0000 1.0000
62.8800 322.0000 1.0000
62.9200 353.0000 1.0000
62.9600 345.0000 1.0000
63.0000 326.0000 1.0000
63.0400 336.0000 1.0000
63.0800 331.0000 1.0000
63.1200 315.0000 1.0000
63.1600 347.0000 1.0000
63.2000 364.0000 1.0000
63.2400 331.0000 1.0000
63.2800 353.0000 1.0000
63.3200 375.0000 1.0000
63.3600 324.0000 1.0000
63.4000 386.0000 1.0000
63.4400 342.0000 1.0000
63.4800 363.0000 1.0000
63.5200 346.0000 1.0000
63.5600 373.0000 1.0000
63.6000 349.0000 1.0000
63.6400 367.0000 1.0000
63.6800 358.0000 1.0000
63.7200 351.0000 1.0000
63.7600 372.0000 1.0000
63.8000 363.0000 1.0000
63.8400 425.0000 1.0000
63.8800 423.0000 1.0000
63.9200 456.0000 1.0000
63.9600 450.0000 1.0000
64.0000 483.0000 1.0000
64.0400 457.0000 1.0000
64.0800 414.0000 1.0000
64.1200 425.0000 1.0000
64.1600 397.0000 1.0000
64.2000 410.0000 1.0000
64.2400 387.0000 1.0000
64.2800 374.0000 1.0000
64.3200 379.0000 1.0000
64.3600 383.0000 1.0000
64.4000 363.0000 1.0000
64.4400 370.0000 1.0000
64.4800 359.0000 1.0000
64.5200 364.0000 1.0000
64.5600 361.0000 1.0000
64.6000 353.0000 1.0000
64.6400 393.0000 1.0000
64.6800 370.0000 1.0000
64.7200 351.0000 1.0000
64.7600 376.0000 1.0000
64.8000 382.0000 1.0000
64.8400 363.0000 1.0000
64.8800 360.0000 1.0000
64.9200 364.0000 1.0000
64.9600 365.0000 1.0000
65.0000 366.0000 1.0000
65.0400 389.0000 1.0000
65.0800 400.0000 1.0000
65.1200 409.0000 1.0000
65.1600 398.0000 1.0000
65.2000 441.0000 1.0000
65.2400 473.0000 1.0000
65.2800 503.0000 1.0000
65.3200 580.0000 1.0000
65.3600 676.0000 1.0000
65.4000 790.0000 1.0000
65.4400 921.0000 1.0000
65.4800 1072.0000 1.0000
65.5200 1223.0000 1.0000
65.5600 1265.0000 1.0000
65.6000 1177.0000 1.0000
65.6400 1087.0000 1.0000
65.6800 1017.0000 1.0000
65.7200 928.0000 1.0000
65.7600 873.0000 1.0000
65.8000 750.0000 1.0000
65.8400 660.0000 1.0000
65.8800 543.0000 1.0000
65.9200 497.0000 1.0000
65.9600 485.0000 1.0000
66.0000 434.0000 1.0000
66.0400 415.0000 1.0000
66.0800 405.0000 1.0000
66.1200 346.0000 1.0000
66.1600 412.0000 1.0000
66.2000 338.0000 1.0000
66.2400 361.0000 1.0000
66.2800 366.0000 1.0000
66.3200 345.0000 1.0000
66.3600 359.0000 1.0000
66.4000 329.0000 1.0000
66.4400 321.0000 1.0000
66.4800 326.0000 1.0000
66.5200 318.0000 1.0000
66.5600 347.0000 1.0000
66.6000 349.0000 1.0000
66.6400 324.0000 1.0000
66.6800 353.0000 1.0000
66.7200 319.0000 1.0000
66.7600 346.0000 1.0000
66.8000 319.0000 1.0000
66.8400 329.0000 1.0000
66.8800 306.0000 1.0000
66.9200 337.0000 1.0000
66.9600 344.0000 1.0000
67.0000 327.0000 1.0000
67.0400 305.0000 1.0000
67.0800 329.0000 1.0000
67.1200 327.0000 1.0000
67.1600 321.0000 1.0000
67.2000 323.0000 1.0000
67.2400 322.0000 1.0000
67.2800 311.0000 1.0000
67.3200 318.0000 1.0000
67.3600 319.0000 1.0000
67.4000 290.0000 1.0000
67.4400 334.0000 1.0000
67.4800 299.0000 1.0000
67.5200 326.0000 1.0000
67.5600 316.0000 1.0000
67.6000 317.0000 1.0000
67.6400 322.0000 1.0000
67.6800 320.0000 1.0000
67.7200 333.0000 1.0000
67.7600 324.0000 1.0000
67.8000 309.0000 1.0000
67.8400 267.0000 1.0000
67.8800 346.0000 1.0000
67.9200 304.0000 1.0000
67.9600 302.0000 1.0000
68.0000 307.0000 1.0000
68.0400 304.0000 1.0000
68.0800 343.0000 1.0000
68.1200 295.0000 1.0000
68.1600 305.0000 1.0000
68.2000 310.0000 1.0000
68.2400 286.0000 1.0000
68.2800 309.0000 1.0000
68.3200 308.0000 1.0000
68.3600 310.0000 1.0000
68.4000 315.0000 1.0000
68.4400 330.0000 1.0000
68.4800 306.0000 1.0000
68.5200 328.0000 1.0000
68.5600 342.0000 1.0000
68.6000 326.0000 1.0000
68.6400 293.0000 1.0000
68.6800 315.0000 1.0000
68.7200 333.0000 1.0000
68.7600 314.0000 1.0000
68.8000 311.0000 1.0000
68.8400 280.0000 1.0000
68.8800 294.0000 1.0000
68.9200 320.0000 1.0000
68.9600 292.0000 1.0000
69.0000 301.0000 1.0000
69.0400 322.0000 1.0000
69.0800 310.0000 1.0000
69.1200 336.0000 1.0000
69.1600 314.0000 1.0000
69.2000 274.0000 1.0000
69.2400 315.0000 1.0000
69.2800 324.0000 1.0000
69.3200 296.0000 1.0000
69.3600 293.0000 1.0000
69.4000 325.0000 1.0000
69.4400 305.0000 1.0000
69.4800 309.0000 1.0000
69.5200 306.0000 1.0000
69.5600 325.0000 1.0000
69.6000 277.0000 1.0000
69.6400 276.0000 1.0000
69.6800 287.0000 1.0000
69.7200 293.0000 1.0000
69.7600 333.0000 1.0000
69.8000 294.0000 1.0000
69.8400 319.0000 1.0000
69.8800 299.0000 1.0000
69.9200 300.0000 1.0000
69.9600 298.0000 1.0000
70.0000 291.0000 1.0000
*RAS_INT_END
*RAS_TEMPERATURE_START
*RAS_TEMPERATURE_END
*RAS_DATA_END