File: Data/Dataset1_Only_water/5_XRD/No_019_FS5_3.ras
*RAS_DATA_START
*RAS_HEADER_START
*DISP_FMT_X "%.2f"
*DISP_FMT_Y "%.0f"
*DISP_FULLSCALE "13826.0000000000"
*DISP_LINE_COLOR "255.0000000000"
*DISP_LINE_STYLE "0.0000000000"
*DISP_LINE_WIDTH "0.2500000000"
*DISP_NOTE "測定データ-3"
*DISP_OFFSET_Y "0.0000000000"
*DISP_PEAKSEARCH_UNIT_Y "cps"
*DISP_RANGE_BOTTOM "0.0000000000"
*DISP_RANGE_LEFT "20.0000000000"
*DISP_RANGE_LOGCUTOFF "0.0100000000"
*DISP_RANGE_RIGHT "70.0000000000"
*DISP_RANGE_TOP "13826.0000000000"
*DISP_SCALE_MODE_Y "0.0000000000"
*DISP_TAB_NAME "2θ/θ"
*DISP_TITLE_Y "強度"
*DISP_UNIT_Y "cps"
*DISP_WINDOW_NAME "MSG_MACROENGINE"
*FILE_COMMENT " "
*FILE_MD5 ""
*FILE_MEMO " "
*FILE_OPERATOR "Administrator"
*FILE_SAMPLE " "
*FILE_TYPE "RAS_RAW"
*FILE_USERGROUP "システムマネージャ"
*FILE_VERSION "1.0000000000"
*HW_ATTACHMENT_ID "ATT0025"
*HW_ATTACHMENT_NAME "標準|Standard"
*HW_COUNTER_ID-0 "CUT0025"
*HW_COUNTER_ID-1 "CUT0020"
*HW_COUNTER_ID-2 "CUT0020"
*HW_COUNTER_ID-3 "CSL0021"
*HW_COUNTER_ID-4 "CMC0021"
*HW_COUNTER_NAME-0 "D/teX Ultra|D/teX Ultra"
*HW_COUNTER_NAME-1 "None|None"
*HW_COUNTER_NAME-2 "None|None"
*HW_COUNTER_NAME-3 "BBM|BBM"
*HW_COUNTER_NAME-4 "検出器モノクロメータ|Detector monochromator"
*HW_COUNTER_SELECT_NAME "D/teX Ultra|D/teX Ultra"
*HW_GONIOMETER_ID "GON0023"
*HW_GONIOMETER_NAME "SmartLab|SmartLab"
*HW_GONIOMETER_RADIUS-0 "90.0"
*HW_GONIOMETER_RADIUS-1 "114.0"
*HW_GONIOMETER_RADIUS-2 "190.0"
*HW_GONIOMETER_RADIUS-3 "300.0"
*HW_GONIOMETER_RADIUS-4 "187.0"
*HW_GONIOMETER_RADIUS-5 "300.0"
*HW_GONIOMETER_RADIUS-6 "113.0"
*HW_GONIOMETER_RADIUS-7 "331.0"
*HW_I_OPT_ID-0 "CBO0021"
*HW_I_OPT_ID-1 "ICR0023"
*HW_I_OPT_ID-2 "ISL0021"
*HW_I_OPT_ID-3 "ISO0021"
*HW_I_OPT_ID-4 "IAD0021"
*HW_I_OPT_ID-5 "IPR0001"
*HW_I_OPT_NAME-0 "CBOユニット|CBO unit"
*HW_I_OPT_NAME-1 "標準入射光学ユニット|Standard incident optical unit"
*HW_I_OPT_NAME-2 "標準入射スリットボックス|Standard incident slit box"
*HW_I_OPT_NAME-3 "入射平行スリット|Incident parallel slit"
*HW_I_OPT_NAME-4 "長手制限スリット|Length limiting slit"
*HW_I_OPT_NAME-5 "None|None"
*HW_R_ATTENUATER_AUTOMODE "0"
*HW_R_OPT_ID-0 "RSS0021"
*HW_R_OPT_ID-1 "RCR0023"
*HW_R_OPT_ID-2 "RSO0021"
*HW_R_OPT_ID-3 "RRS0021"
*HW_R_OPT_ID-4 "ATN0021"
*HW_R_OPT_ID-5 "RFL0021"
*HW_R_OPT_ID-6 "RAD0021"
*HW_R_OPT_NAME-0 "標準受光スリットボックス1|Standard receiving slit box # 1"
*HW_R_OPT_NAME-1 "標準受光光学ユニット1|Standard receiving unit # 1"
*HW_R_OPT_NAME-2 "標準受光光学ユニット2|Standard receiving optical unit # 2"
*HW_R_OPT_NAME-3 "標準受光スリットボックス2|Standard receiving slit box # 2"
*HW_R_OPT_NAME-4 "標準アッテネータ|Standard Attenuator"
*HW_R_OPT_NAME-5 "Cu Kβ|Cu K-beta"
*HW_R_OPT_NAME-6 "調整用受光スリット|Alignment receiving slit"
*HW_SAMPLE_HOLDER_ID "SMP0023"
*HW_SAMPLE_HOLDER_NAME "標準Zステージ|Standard Z stage"
*HW_XG_CURRENT_MAX "50"
*HW_XG_CURRENT_MIN "2"
*HW_XG_CURRENT_RESOLUTION "1"
*HW_XG_CURRENT_UNIT "mA"
*HW_XG_FOCUS "1mm x 10mm"
*HW_XG_FOCUS_TYPE "Normal"
*HW_XG_ID ""
*HW_XG_NAME "3kW 封入管(ID:1200)|3kW Sealed tube(ID:1200)"
*HW_XG_TARGET_ATOMIC_NUMBER "29.0000000000"
*HW_XG_TARGET_NAME "Cu"
*HW_XG_TYPE "Hermetic"
*HW_XG_VOLTAGE_MAX "60"
*HW_XG_VOLTAGE_MIN "20"
*HW_XG_VOLTAGE_RESOLUTION "1"
*HW_XG_VOLTAGE_UNIT "kV"
*HW_XG_WATT_MAX "1.500"
*HW_XG_WATT_UNIT "kW"
*HW_XG_WAVE_LENGTH_ALPHA1 "1.540593"
*HW_XG_WAVE_LENGTH_ALPHA2 "1.544414"
*HW_XG_WAVE_LENGTH_BETA "1.392250"
*MEAS_COND_AXIS_NAME-0 "2θ/θ"
*MEAS_COND_AXIS_NAME-1 "2θ"
*MEAS_COND_AXIS_NAME-2 "ω"
*MEAS_COND_AXIS_NAME-3 "Z"
*MEAS_COND_AXIS_NAME-4 "2θ/ω"
*MEAS_COND_AXIS_NAME-5 "θs"
*MEAS_COND_AXIS_NAME-6 "θd"
*MEAS_COND_AXIS_NAME-7 "Ts"
*MEAS_COND_AXIS_NAME-8 "CBO選択スリット"
*MEAS_COND_AXIS_NAME-9 "M"
*MEAS_COND_AXIS_NAME-10 "入射平行スリット"
*MEAS_COND_AXIS_NAME-11 "入射スリット"
*MEAS_COND_AXIS_NAME-12 ""
*MEAS_COND_AXIS_NAME-13 "Zs"
*MEAS_COND_AXIS_NAME-14 "入射光学素子"
*MEAS_COND_AXIS_NAME-15 "長手制限スリット"
*MEAS_COND_AXIS_NAME-16 "センタースリット"
*MEAS_COND_AXIS_NAME-17 "フィルター"
*MEAS_COND_AXIS_NAME-18 "受光スリット1"
*MEAS_COND_AXIS_NAME-19 "受光スリット2"
*MEAS_COND_AXIS_NAME-20 "受光光学素子"
*MEAS_COND_AXIS_NAME-21 "受光平行スリット"
*MEAS_COND_AXIS_NAME-22 "調整用受光スリット"
*MEAS_COND_AXIS_NAME-23 ""
*MEAS_COND_AXIS_NAME-24 ""
*MEAS_COND_AXIS_NAME-25 "Zd"
*MEAS_COND_AXIS_NAME-26 "アッテネータ"
*MEAS_COND_AXIS_NAME-27 "検出器モノクロメータ"
*MEAS_COND_AXIS_NAME-28 "モノクロメータスリット"
*MEAS_COND_AXIS_NAME-29 "プライマリビーム"
*MEAS_COND_AXIS_NAME-30 "PHA"
*MEAS_COND_AXIS_NAME_INTERNAL-0 "TwoThetaTheta"
*MEAS_COND_AXIS_NAME_INTERNAL-1 "TwoTheta"
*MEAS_COND_AXIS_NAME_INTERNAL-2 "Omega"
*MEAS_COND_AXIS_NAME_INTERNAL-3 "Z"
*MEAS_COND_AXIS_NAME_INTERNAL-4 "TwoThetaOmega"
*MEAS_COND_AXIS_NAME_INTERNAL-5 "ThetaS"
*MEAS_COND_AXIS_NAME_INTERNAL-6 "ThetaD"
*MEAS_COND_AXIS_NAME_INTERNAL-7 "Ts"
*MEAS_COND_AXIS_NAME_INTERNAL-8 "CBO"
*MEAS_COND_AXIS_NAME_INTERNAL-9 "CBO-M"
*MEAS_COND_AXIS_NAME_INTERNAL-10 "IncidentSollerSlit"
*MEAS_COND_AXIS_NAME_INTERNAL-11 "IncidentSlitBox"
*MEAS_COND_AXIS_NAME_INTERNAL-12 "IncidentSlitBox-_Axis"
*MEAS_COND_AXIS_NAME_INTERNAL-13 "Zs"
*MEAS_COND_AXIS_NAME_INTERNAL-14 "IncidentMonochromator"
*MEAS_COND_AXIS_NAME_INTERNAL-15 "IncidentAxdSlit"
*MEAS_COND_AXIS_NAME_INTERNAL-16 "CenterSlit"
*MEAS_COND_AXIS_NAME_INTERNAL-17 "Filter"
*MEAS_COND_AXIS_NAME_INTERNAL-18 "ReceivingSlitBox1"
*MEAS_COND_AXIS_NAME_INTERNAL-19 "ReceivingSlitBox2"
*MEAS_COND_AXIS_NAME_INTERNAL-20 "ReceivingOptics"
*MEAS_COND_AXIS_NAME_INTERNAL-21 "ReceivingSollerSlit"
*MEAS_COND_AXIS_NAME_INTERNAL-22 "ReceivingAxdSlit"
*MEAS_COND_AXIS_NAME_INTERNAL-23 "ReceivingSlitBox1-_Axis"
*MEAS_COND_AXIS_NAME_INTERNAL-24 "ReceivingSlitBox2-_Axis"
*MEAS_COND_AXIS_NAME_INTERNAL-25 "ReceivingSlitBox2-Zd"
*MEAS_COND_AXIS_NAME_INTERNAL-26 "Attenuator"
*MEAS_COND_AXIS_NAME_INTERNAL-27 "CounterMonochromator"
*MEAS_COND_AXIS_NAME_INTERNAL-28 "CounterSlit"
*MEAS_COND_AXIS_NAME_INTERNAL-29 "IncidentPrimary"
*MEAS_COND_AXIS_NAME_INTERNAL-30 "PHA"
*MEAS_COND_AXIS_NAME_MAGICNO-0 "83951616.0000000000"
*MEAS_COND_AXIS_NAME_MAGICNO-1 "268632064.0000000000"
*MEAS_COND_AXIS_NAME_MAGICNO-2 "268500992.0000000000"
*MEAS_COND_AXIS_NAME_MAGICNO-3 "285278208.0000000000"
*MEAS_COND_AXIS_NAME_MAGICNO-4 "83951616.0000000000"
*MEAS_COND_AXIS_NAME_MAGICNO-5 "131072.0000000000"
*MEAS_COND_AXIS_NAME_MAGICNO-6 "131072.0000000000"
*MEAS_COND_AXIS_NAME_MAGICNO-7 "318898176.0000000000"
*MEAS_COND_AXIS_NAME_MAGICNO-8 "20971521.0000000000"
*MEAS_COND_AXIS_NAME_MAGICNO-9 "285343744.0000000000"
*MEAS_COND_AXIS_NAME_MAGICNO-10 "20971521.0000000000"
*MEAS_COND_AXIS_NAME_MAGICNO-11 "22020097.0000000000"
*MEAS_COND_AXIS_NAME_MAGICNO-12 "25165824.0000000000"
*MEAS_COND_AXIS_NAME_MAGICNO-13 "318898176.0000000000"
*MEAS_COND_AXIS_NAME_MAGICNO-14 "1.0000000000"
*MEAS_COND_AXIS_NAME_MAGICNO-15 "20971521.0000000000"
*MEAS_COND_AXIS_NAME_MAGICNO-16 "20971521.0000000000"
*MEAS_COND_AXIS_NAME_MAGICNO-17 "20971521.0000000000"
*MEAS_COND_AXIS_NAME_MAGICNO-18 "23068673.0000000000"
*MEAS_COND_AXIS_NAME_MAGICNO-19 "23068673.0000000000"
*MEAS_COND_AXIS_NAME_MAGICNO-20 "20971521.0000000000"
*MEAS_COND_AXIS_NAME_MAGICNO-21 "20971521.0000000000"
*MEAS_COND_AXIS_NAME_MAGICNO-22 "20971521.0000000000"
*MEAS_COND_AXIS_NAME_MAGICNO-23 "25165824.0000000000"
*MEAS_COND_AXIS_NAME_MAGICNO-24 "25165824.0000000000"
*MEAS_COND_AXIS_NAME_MAGICNO-25 "285343744.0000000000"
*MEAS_COND_AXIS_NAME_MAGICNO-26 "17301505.0000000000"
*MEAS_COND_AXIS_NAME_MAGICNO-27 "20971521.0000000000"
*MEAS_COND_AXIS_NAME_MAGICNO-28 "20971521.0000000000"
*MEAS_COND_AXIS_NAME_MAGICNO-29 "20971521.0000000000"
*MEAS_COND_AXIS_NAME_MAGICNO-30 "0.0000000000"
*MEAS_COND_AXIS_OFFSET-0 "-"
*MEAS_COND_AXIS_OFFSET-1 "-0.1081000000"
*MEAS_COND_AXIS_OFFSET-2 "0.3758000000"
*MEAS_COND_AXIS_OFFSET-3 "-"
*MEAS_COND_AXIS_OFFSET-4 "-"
*MEAS_COND_AXIS_OFFSET-5 "0.3758000000"
*MEAS_COND_AXIS_OFFSET-6 "-0.4839000000"
*MEAS_COND_AXIS_OFFSET-7 "-"
*MEAS_COND_AXIS_OFFSET-8 "-"
*MEAS_COND_AXIS_OFFSET-9 "-"
*MEAS_COND_AXIS_OFFSET-10 "-"
*MEAS_COND_AXIS_OFFSET-11 "-"
*MEAS_COND_AXIS_OFFSET-12 "-"
*MEAS_COND_AXIS_OFFSET-13 "-"
*MEAS_COND_AXIS_OFFSET-14 "-"
*MEAS_COND_AXIS_OFFSET-15 "-"
*MEAS_COND_AXIS_OFFSET-16 "-"
*MEAS_COND_AXIS_OFFSET-17 "-"
*MEAS_COND_AXIS_OFFSET-18 "-"
*MEAS_COND_AXIS_OFFSET-19 "-"
*MEAS_COND_AXIS_OFFSET-20 "-"
*MEAS_COND_AXIS_OFFSET-21 "-"
*MEAS_COND_AXIS_OFFSET-22 "-"
*MEAS_COND_AXIS_OFFSET-23 "-"
*MEAS_COND_AXIS_OFFSET-24 "-"
*MEAS_COND_AXIS_OFFSET-25 "-"
*MEAS_COND_AXIS_OFFSET-26 "-"
*MEAS_COND_AXIS_OFFSET-27 "-"
*MEAS_COND_AXIS_OFFSET-28 "-"
*MEAS_COND_AXIS_OFFSET-29 "-"
*MEAS_COND_AXIS_OFFSET-30 "-"
*MEAS_COND_AXIS_POSITION-0 "0.0000000000"
*MEAS_COND_AXIS_POSITION-1 "0.0000000000"
*MEAS_COND_AXIS_POSITION-2 "0.0000000000"
*MEAS_COND_AXIS_POSITION-3 "-0.5500000000"
*MEAS_COND_AXIS_POSITION-4 "0.0000000000"
*MEAS_COND_AXIS_POSITION-5 "0.0000000000"
*MEAS_COND_AXIS_POSITION-6 "0.0000000000"
*MEAS_COND_AXIS_POSITION-7 "-0.4278800000"
*MEAS_COND_AXIS_POSITION-8 "BB"
*MEAS_COND_AXIS_POSITION-9 "0.0000000000"
*MEAS_COND_AXIS_POSITION-10 "Soller_slit_5.0deg"
*MEAS_COND_AXIS_POSITION-11 "2/3deg"
*MEAS_COND_AXIS_POSITION-12 "2.2088000000"
*MEAS_COND_AXIS_POSITION-13 "-0.4140600000"
*MEAS_COND_AXIS_POSITION-14 "0.0000000000"
*MEAS_COND_AXIS_POSITION-15 "10.0mm"
*MEAS_COND_AXIS_POSITION-16 "None"
*MEAS_COND_AXIS_POSITION-17 "Cu_K-beta"
*MEAS_COND_AXIS_POSITION-18 "13.000mm"
*MEAS_COND_AXIS_POSITION-19 "13.000mm"
*MEAS_COND_AXIS_POSITION-20 "No_unit"
*MEAS_COND_AXIS_POSITION-21 "Soller_slit_5.0deg"
*MEAS_COND_AXIS_POSITION-22 "None"
*MEAS_COND_AXIS_POSITION-23 "13.0000000000"
*MEAS_COND_AXIS_POSITION-24 "13.0000000000"
*MEAS_COND_AXIS_POSITION-25 "0.0109400000"
*MEAS_COND_AXIS_POSITION-26 "Open"
*MEAS_COND_AXIS_POSITION-27 "None"
*MEAS_COND_AXIS_POSITION-28 "None"
*MEAS_COND_AXIS_POSITION-29 "None"
*MEAS_COND_AXIS_POSITION-30 "38.0000000000"
*MEAS_COND_AXIS_UNIT-0 "deg"
*MEAS_COND_AXIS_UNIT-1 "deg"
*MEAS_COND_AXIS_UNIT-2 "deg"
*MEAS_COND_AXIS_UNIT-3 "mm"
*MEAS_COND_AXIS_UNIT-4 "deg"
*MEAS_COND_AXIS_UNIT-5 "deg"
*MEAS_COND_AXIS_UNIT-6 "deg"
*MEAS_COND_AXIS_UNIT-7 "mm"
*MEAS_COND_AXIS_UNIT-8 ""
*MEAS_COND_AXIS_UNIT-9 "pulse"
*MEAS_COND_AXIS_UNIT-10 ""
*MEAS_COND_AXIS_UNIT-11 ""
*MEAS_COND_AXIS_UNIT-12 "mm"
*MEAS_COND_AXIS_UNIT-13 "mm"
*MEAS_COND_AXIS_UNIT-14 ""
*MEAS_COND_AXIS_UNIT-15 ""
*MEAS_COND_AXIS_UNIT-16 ""
*MEAS_COND_AXIS_UNIT-17 ""
*MEAS_COND_AXIS_UNIT-18 ""
*MEAS_COND_AXIS_UNIT-19 ""
*MEAS_COND_AXIS_UNIT-20 ""
*MEAS_COND_AXIS_UNIT-21 ""
*MEAS_COND_AXIS_UNIT-22 ""
*MEAS_COND_AXIS_UNIT-23 "mm"
*MEAS_COND_AXIS_UNIT-24 "mm"
*MEAS_COND_AXIS_UNIT-25 "mm"
*MEAS_COND_AXIS_UNIT-26 ""
*MEAS_COND_AXIS_UNIT-27 ""
*MEAS_COND_AXIS_UNIT-28 ""
*MEAS_COND_AXIS_UNIT-29 ""
*MEAS_COND_AXIS_UNIT-30 "div"
*MEAS_COND_COUNTER_CNTLOSS_CORR "0.0000000000"
*MEAS_COND_COUNTER_PHABASE "38.0000000000"
*MEAS_COND_COUNTER_PHAWINDOW "16.0000000000"
*MEAS_COND_COUNTER_PHA_UNIT "div"
*MEAS_COND_COUNTER_TAUDIFF "30.0000000000"
*MEAS_COND_COUNTER_TAUINT "0.0000000000"
*MEAS_COND_IRRADIATION_MODE "OFF"
*MEAS_COND_IRRADIATION_WIDTH ""
*MEAS_COND_OPT_ATTR "集中法"
*MEAS_COND_OPT_NAME "@集中法"
*MEAS_COND_UNSYMMETRIC_MODE "OFF"
*MEAS_COND_XG_CURRENT "30.0000000000"
*MEAS_COND_XG_VOLTAGE "40.0000000000"
*MEAS_COND_XG_WAVE_TYPE "Ka"
*MEAS_DATA_COUNT "5001.0000000000"
*MEAS_SCAN_AXIS_X "2θ/θ"
*MEAS_SCAN_AXIS_X_INTERNAL "TwoThetaTheta"
*MEAS_SCAN_END_TIME "07/08/21 13:41:13"
*MEAS_SCAN_MODE "CONTINUOUS"
*MEAS_SCAN_MONITOR "0"
*MEAS_SCAN_RESOLUTION_X "0.0002"
*MEAS_SCAN_SPEED "1.0"
*MEAS_SCAN_SPEED_UNIT "deg/min"
*MEAS_SCAN_START "20.0000000000"
*MEAS_SCAN_START_TIME "07/08/21 12:48:19"
*MEAS_SCAN_STEP "0.0100000000"
*MEAS_SCAN_STOP "70.0000000000"
*MEAS_SCAN_UNIT_X "deg"
*MEAS_SCAN_UNIT_Y "counts"
*RAS_HEADER_END
*RAS_INT_START
20.0000 1471.0000 1.0000
20.0400 1579.0000 1.0000
20.0800 1598.0000 1.0000
20.1200 1652.0000 1.0000
20.1600 1636.0000 1.0000
20.2000 1603.0000 1.0000
20.2400 1570.0000 1.0000
20.2800 1624.0000 1.0000
20.3200 1629.0000 1.0000
20.3600 1647.0000 1.0000
20.4000 1546.0000 1.0000
20.4400 1592.0000 1.0000
20.4800 1625.0000 1.0000
20.5200 1652.0000 1.0000
20.5600 1585.0000 1.0000
20.6000 1618.0000 1.0000
20.6400 1708.0000 1.0000
20.6800 1587.0000 1.0000
20.7200 1659.0000 1.0000
20.7600 1579.0000 1.0000
20.8000 1598.0000 1.0000
20.8400 1599.0000 1.0000
20.8800 1657.0000 1.0000
20.9200 1638.0000 1.0000
20.9600 1584.0000 1.0000
21.0000 1629.0000 1.0000
21.0400 1687.0000 1.0000
21.0800 1586.0000 1.0000
21.1200 1601.0000 1.0000
21.1600 1659.0000 1.0000
21.2000 1624.0000 1.0000
21.2400 1683.0000 1.0000
21.2800 1604.0000 1.0000
21.3200 1658.0000 1.0000
21.3600 1607.0000 1.0000
21.4000 1658.0000 1.0000
21.4400 1627.0000 1.0000
21.4800 1548.0000 1.0000
21.5200 1596.0000 1.0000
21.5600 1627.0000 1.0000
21.6000 1626.0000 1.0000
21.6400 1602.0000 1.0000
21.6800 1603.0000 1.0000
21.7200 1622.0000 1.0000
21.7600 1628.0000 1.0000
21.8000 1594.0000 1.0000
21.8400 1597.0000 1.0000
21.8800 1629.0000 1.0000
21.9200 1631.0000 1.0000
21.9600 1611.0000 1.0000
22.0000 1699.0000 1.0000
22.0400 1696.0000 1.0000
22.0800 1604.0000 1.0000
22.1200 1653.0000 1.0000
22.1600 1638.0000 1.0000
22.2000 1666.0000 1.0000
22.2400 1724.0000 1.0000
22.2800 1638.0000 1.0000
22.3200 1669.0000 1.0000
22.3600 1634.0000 1.0000
22.4000 1678.0000 1.0000
22.4400 1644.0000 1.0000
22.4800 1637.0000 1.0000
22.5200 1633.0000 1.0000
22.5600 1642.0000 1.0000
22.6000 1634.0000 1.0000
22.6400 1671.0000 1.0000
22.6800 1658.0000 1.0000
22.7200 1689.0000 1.0000
22.7600 1632.0000 1.0000
22.8000 1617.0000 1.0000
22.8400 1688.0000 1.0000
22.8800 1684.0000 1.0000
22.9200 1611.0000 1.0000
22.9600 1662.0000 1.0000
23.0000 1664.0000 1.0000
23.0400 1652.0000 1.0000
23.0800 1602.0000 1.0000
23.1200 1636.0000 1.0000
23.1600 1680.0000 1.0000
23.2000 1749.0000 1.0000
23.2400 1671.0000 1.0000
23.2800 1710.0000 1.0000
23.3200 1708.0000 1.0000
23.3600 1650.0000 1.0000
23.4000 1639.0000 1.0000
23.4400 1703.0000 1.0000
23.4800 1664.0000 1.0000
23.5200 1664.0000 1.0000
23.5600 1606.0000 1.0000
23.6000 1651.0000 1.0000
23.6400 1629.0000 1.0000
23.6800 1738.0000 1.0000
23.7200 1732.0000 1.0000
23.7600 1731.0000 1.0000
23.8000 1700.0000 1.0000
23.8400 1676.0000 1.0000
23.8800 1633.0000 1.0000
23.9200 1693.0000 1.0000
23.9600 1713.0000 1.0000
24.0000 1702.0000 1.0000
24.0400 1775.0000 1.0000
24.0800 1700.0000 1.0000
24.1200 1681.0000 1.0000
24.1600 1661.0000 1.0000
24.2000 1670.0000 1.0000
24.2400 1694.0000 1.0000
24.2800 1634.0000 1.0000
24.3200 1723.0000 1.0000
24.3600 1638.0000 1.0000
24.4000 1653.0000 1.0000
24.4400 1705.0000 1.0000
24.4800 1742.0000 1.0000
24.5200 1734.0000 1.0000
24.5600 1734.0000 1.0000
24.6000 1695.0000 1.0000
24.6400 1780.0000 1.0000
24.6800 1694.0000 1.0000
24.7200 1747.0000 1.0000
24.7600 1815.0000 1.0000
24.8000 1681.0000 1.0000
24.8400 1746.0000 1.0000
24.8800 1755.0000 1.0000
24.9200 1863.0000 1.0000
24.9600 1828.0000 1.0000
25.0000 1744.0000 1.0000
25.0400 1831.0000 1.0000
25.0800 1763.0000 1.0000
25.1200 1777.0000 1.0000
25.1600 1721.0000 1.0000
25.2000 1761.0000 1.0000
25.2400 1753.0000 1.0000
25.2800 1729.0000 1.0000
25.3200 1743.0000 1.0000
25.3600 1714.0000 1.0000
25.4000 1690.0000 1.0000
25.4400 1701.0000 1.0000
25.4800 1749.0000 1.0000
25.5200 1772.0000 1.0000
25.5600 1680.0000 1.0000
25.6000 1775.0000 1.0000
25.6400 1718.0000 1.0000
25.6800 1702.0000 1.0000
25.7200 1758.0000 1.0000
25.7600 1716.0000 1.0000
25.8000 1721.0000 1.0000
25.8400 1694.0000 1.0000
25.8800 1738.0000 1.0000
25.9200 1797.0000 1.0000
25.9600 1768.0000 1.0000
26.0000 1717.0000 1.0000
26.0400 1670.0000 1.0000
26.0800 1810.0000 1.0000
26.1200 1723.0000 1.0000
26.1600 1758.0000 1.0000
26.2000 1731.0000 1.0000
26.2400 1742.0000 1.0000
26.2800 1792.0000 1.0000
26.3200 1734.0000 1.0000
26.3600 1779.0000 1.0000
26.4000 1773.0000 1.0000
26.4400 1740.0000 1.0000
26.4800 1770.0000 1.0000
26.5200 1837.0000 1.0000
26.5600 1883.0000 1.0000
26.6000 1874.0000 1.0000
26.6400 1844.0000 1.0000
26.6800 1899.0000 1.0000
26.7200 1870.0000 1.0000
26.7600 1849.0000 1.0000
26.8000 1901.0000 1.0000
26.8400 2007.0000 1.0000
26.8800 2088.0000 1.0000
26.9200 2129.0000 1.0000
26.9600 2216.0000 1.0000
27.0000 2282.0000 1.0000
27.0400 2514.0000 1.0000
27.0800 2884.0000 1.0000
27.1200 3187.0000 1.0000
27.1600 3693.0000 1.0000
27.2000 4668.0000 1.0000
27.2400 5819.0000 1.0000
27.2800 6557.0000 1.0000
27.3200 6841.0000 1.0000
27.3600 6166.0000 1.0000
27.4000 5220.0000 1.0000
27.4400 4004.0000 1.0000
27.4800 3344.0000 1.0000
27.5200 2950.0000 1.0000
27.5600 2619.0000 1.0000
27.6000 2336.0000 1.0000
27.6400 2273.0000 1.0000
27.6800 2052.0000 1.0000
27.7200 2070.0000 1.0000
27.7600 1979.0000 1.0000
27.8000 1934.0000 1.0000
27.8400 1892.0000 1.0000
27.8800 1884.0000 1.0000
27.9200 1798.0000 1.0000
27.9600 1783.0000 1.0000
28.0000 1722.0000 1.0000
28.0400 1768.0000 1.0000
28.0800 1777.0000 1.0000
28.1200 1718.0000 1.0000
28.1600 1731.0000 1.0000
28.2000 1764.0000 1.0000
28.2400 1747.0000 1.0000
28.2800 1739.0000 1.0000
28.3200 1683.0000 1.0000
28.3600 1700.0000 1.0000
28.4000 1609.0000 1.0000
28.4400 1711.0000 1.0000
28.4800 1659.0000 1.0000
28.5200 1616.0000 1.0000
28.5600 1636.0000 1.0000
28.6000 1624.0000 1.0000
28.6400 1675.0000 1.0000
28.6800 1658.0000 1.0000
28.7200 1666.0000 1.0000
28.7600 1628.0000 1.0000
28.8000 1631.0000 1.0000
28.8400 1596.0000 1.0000
28.8800 1648.0000 1.0000
28.9200 1652.0000 1.0000
28.9600 1646.0000 1.0000
29.0000 1604.0000 1.0000
29.0400 1643.0000 1.0000
29.0800 1615.0000 1.0000
29.1200 1607.0000 1.0000
29.1600 1620.0000 1.0000
29.2000 1587.0000 1.0000
29.2400 1605.0000 1.0000
29.2800 1594.0000 1.0000
29.3200 1581.0000 1.0000
29.3600 1603.0000 1.0000
29.4000 1542.0000 1.0000
29.4400 1516.0000 1.0000
29.4800 1590.0000 1.0000
29.5200 1541.0000 1.0000
29.5600 1541.0000 1.0000
29.6000 1575.0000 1.0000
29.6400 1565.0000 1.0000
29.6800 1500.0000 1.0000
29.7200 1537.0000 1.0000
29.7600 1530.0000 1.0000
29.8000 1615.0000 1.0000
29.8400 1576.0000 1.0000
29.8800 1563.0000 1.0000
29.9200 1546.0000 1.0000
29.9600 1642.0000 1.0000
30.0000 1507.0000 1.0000
30.0400 1563.0000 1.0000
30.0800 1513.0000 1.0000
30.1200 1577.0000 1.0000
30.1600 1554.0000 1.0000
30.2000 1555.0000 1.0000
30.2400 1548.0000 1.0000
30.2800 1552.0000 1.0000
30.3200 1549.0000 1.0000
30.3600 1464.0000 1.0000
30.4000 1499.0000 1.0000
30.4400 1538.0000 1.0000
30.4800 1478.0000 1.0000
30.5200 1560.0000 1.0000
30.5600 1474.0000 1.0000
30.6000 1475.0000 1.0000
30.6400 1485.0000 1.0000
30.6800 1501.0000 1.0000
30.7200 1495.0000 1.0000
30.7600 1507.0000 1.0000
30.8000 1471.0000 1.0000
30.8400 1513.0000 1.0000
30.8800 1506.0000 1.0000
30.9200 1561.0000 1.0000
30.9600 1477.0000 1.0000
31.0000 1433.0000 1.0000
31.0400 1478.0000 1.0000
31.0800 1551.0000 1.0000
31.1200 1476.0000 1.0000
31.1600 1548.0000 1.0000
31.2000 1505.0000 1.0000
31.2400 1476.0000 1.0000
31.2800 1494.0000 1.0000
31.3200 1506.0000 1.0000
31.3600 1403.0000 1.0000
31.4000 1478.0000 1.0000
31.4400 1484.0000 1.0000
31.4800 1457.0000 1.0000
31.5200 1450.0000 1.0000
31.5600 1473.0000 1.0000
31.6000 1445.0000 1.0000
31.6400 1413.0000 1.0000
31.6800 1414.0000 1.0000
31.7200 1453.0000 1.0000
31.7600 1448.0000 1.0000
31.8000 1468.0000 1.0000
31.8400 1475.0000 1.0000
31.8800 1493.0000 1.0000
31.9200 1494.0000 1.0000
31.9600 1467.0000 1.0000
32.0000 1485.0000 1.0000
32.0400 1490.0000 1.0000
32.0800 1496.0000 1.0000
32.1200 1498.0000 1.0000
32.1600 1413.0000 1.0000
32.2000 1454.0000 1.0000
32.2400 1476.0000 1.0000
32.2800 1443.0000 1.0000
32.3200 1409.0000 1.0000
32.3600 1392.0000 1.0000
32.4000 1471.0000 1.0000
32.4400 1389.0000 1.0000
32.4800 1556.0000 1.0000
32.5200 1419.0000 1.0000
32.5600 1420.0000 1.0000
32.6000 1408.0000 1.0000
32.6400 1379.0000 1.0000
32.6800 1350.0000 1.0000
32.7200 1393.0000 1.0000
32.7600 1392.0000 1.0000
32.8000 1355.0000 1.0000
32.8400 1427.0000 1.0000
32.8800 1390.0000 1.0000
32.9200 1434.0000 1.0000
32.9600 1419.0000 1.0000
33.0000 1414.0000 1.0000
33.0400 1325.0000 1.0000
33.0800 1391.0000 1.0000
33.1200 1339.0000 1.0000
33.1600 1398.0000 1.0000
33.2000 1384.0000 1.0000
33.2400 1364.0000 1.0000
33.2800 1399.0000 1.0000
33.3200 1390.0000 1.0000
33.3600 1420.0000 1.0000
33.4000 1428.0000 1.0000
33.4400 1378.0000 1.0000
33.4800 1444.0000 1.0000
33.5200 1413.0000 1.0000
33.5600 1413.0000 1.0000
33.6000 1383.0000 1.0000
33.6400 1393.0000 1.0000
33.6800 1414.0000 1.0000
33.7200 1413.0000 1.0000
33.7600 1449.0000 1.0000
33.8000 1482.0000 1.0000
33.8400 1549.0000 1.0000
33.8800 1591.0000 1.0000
33.9200 1641.0000 1.0000
33.9600 1671.0000 1.0000
34.0000 1623.0000 1.0000
34.0400 1594.0000 1.0000
34.0800 1575.0000 1.0000
34.1200 1502.0000 1.0000
34.1600 1600.0000 1.0000
34.2000 1593.0000 1.0000
34.2400 1681.0000 1.0000
34.2800 1758.0000 1.0000
34.3200 1980.0000 1.0000
34.3600 2181.0000 1.0000
34.4000 2586.0000 1.0000
34.4400 3116.0000 1.0000
34.4800 3399.0000 1.0000
34.5200 3388.0000 1.0000
34.5600 3113.0000 1.0000
34.6000 2792.0000 1.0000
34.6400 2390.0000 1.0000
34.6800 1976.0000 1.0000
34.7200 1793.0000 1.0000
34.7600 1743.0000 1.0000
34.8000 1559.0000 1.0000
34.8400 1575.0000 1.0000
34.8800 1508.0000 1.0000
34.9200 1442.0000 1.0000
34.9600 1449.0000 1.0000
35.0000 1350.0000 1.0000
35.0400 1328.0000 1.0000
35.0800 1311.0000 1.0000
35.1200 1314.0000 1.0000
35.1600 1316.0000 1.0000
35.2000 1297.0000 1.0000
35.2400 1243.0000 1.0000
35.2800 1266.0000 1.0000
35.3200 1284.0000 1.0000
35.3600 1252.0000 1.0000
35.4000 1220.0000 1.0000
35.4400 1230.0000 1.0000
35.4800 1225.0000 1.0000
35.5200 1214.0000 1.0000
35.5600 1238.0000 1.0000
35.6000 1239.0000 1.0000
35.6400 1162.0000 1.0000
35.6800 1180.0000 1.0000
35.7200 1212.0000 1.0000
35.7600 1247.0000 1.0000
35.8000 1233.0000 1.0000
35.8400 1169.0000 1.0000
35.8800 1154.0000 1.0000
35.9200 1191.0000 1.0000
35.9600 1141.0000 1.0000
36.0000 1189.0000 1.0000
36.0400 1160.0000 1.0000
36.0800 1157.0000 1.0000
36.1200 1297.0000 1.0000
36.1600 1289.0000 1.0000
36.2000 1282.0000 1.0000
36.2400 1373.0000 1.0000
36.2800 1480.0000 1.0000
36.3200 1630.0000 1.0000
36.3600 1886.0000 1.0000
36.4000 2257.0000 1.0000
36.4400 2103.0000 1.0000
36.4800 1881.0000 1.0000
36.5200 1747.0000 1.0000
36.5600 1458.0000 1.0000
36.6000 1304.0000 1.0000
36.6400 1240.0000 1.0000
36.6800 1185.0000 1.0000
36.7200 1172.0000 1.0000
36.7600 1157.0000 1.0000
36.8000 1143.0000 1.0000
36.8400 1139.0000 1.0000
36.8800 1136.0000 1.0000
36.9200 1100.0000 1.0000
36.9600 1096.0000 1.0000
37.0000 1125.0000 1.0000
37.0400 1051.0000 1.0000
37.0800 1102.0000 1.0000
37.1200 1057.0000 1.0000
37.1600 1105.0000 1.0000
37.2000 1039.0000 1.0000
37.2400 1075.0000 1.0000
37.2800 1096.0000 1.0000
37.3200 1070.0000 1.0000
37.3600 1089.0000 1.0000
37.4000 1082.0000 1.0000
37.4400 1107.0000 1.0000
37.4800 1089.0000 1.0000
37.5200 1079.0000 1.0000
37.5600 1054.0000 1.0000
37.6000 1103.0000 1.0000
37.6400 1085.0000 1.0000
37.6800 1070.0000 1.0000
37.7200 1124.0000 1.0000
37.7600 1052.0000 1.0000
37.8000 1058.0000 1.0000
37.8400 1076.0000 1.0000
37.8800 1091.0000 1.0000
37.9200 1128.0000 1.0000
37.9600 1135.0000 1.0000
38.0000 1163.0000 1.0000
38.0400 1112.0000 1.0000
38.0800 1199.0000 1.0000
38.1200 1240.0000 1.0000
38.1600 1325.0000 1.0000
38.2000 1408.0000 1.0000
38.2400 1561.0000 1.0000
38.2800 1794.0000 1.0000
38.3200 2062.0000 1.0000
38.3600 2554.0000 1.0000
38.4000 3284.0000 1.0000
38.4400 4294.0000 1.0000
38.4800 5365.0000 1.0000
38.5200 6289.0000 1.0000
38.5600 6442.0000 1.0000
38.6000 5862.0000 1.0000
38.6400 5014.0000 1.0000
38.6800 3998.0000 1.0000
38.7200 3091.0000 1.0000
38.7600 2337.0000 1.0000
38.8000 1905.0000 1.0000
38.8400 1650.0000 1.0000
38.8800 1419.0000 1.0000
38.9200 1300.0000 1.0000
38.9600 1226.0000 1.0000
39.0000 1127.0000 1.0000
39.0400 1112.0000 1.0000
39.0800 1081.0000 1.0000
39.1200 1066.0000 1.0000
39.1600 1050.0000 1.0000
39.2000 1065.0000 1.0000
39.2400 992.0000 1.0000
39.2800 1052.0000 1.0000
39.3200 1006.0000 1.0000
39.3600 1050.0000 1.0000
39.4000 1062.0000 1.0000
39.4400 1039.0000 1.0000
39.4800 1047.0000 1.0000
39.5200 1019.0000 1.0000
39.5600 1026.0000 1.0000
39.6000 1094.0000 1.0000
39.6400 1064.0000 1.0000
39.6800 1005.0000 1.0000
39.7200 971.0000 1.0000
39.7600 997.0000 1.0000
39.8000 997.0000 1.0000
39.8400 981.0000 1.0000
39.8800 924.0000 1.0000
39.9200 942.0000 1.0000
39.9600 939.0000 1.0000
40.0000 895.0000 1.0000
40.0400 927.0000 1.0000
40.0800 902.0000 1.0000
40.1200 951.0000 1.0000
40.1600 918.0000 1.0000
40.2000 986.0000 1.0000
40.2400 885.0000 1.0000
40.2800 905.0000 1.0000
40.3200 911.0000 1.0000
40.3600 932.0000 1.0000
40.4000 926.0000 1.0000
40.4400 946.0000 1.0000
40.4800 909.0000 1.0000
40.5200 953.0000 1.0000
40.5600 916.0000 1.0000
40.6000 929.0000 1.0000
40.6400 936.0000 1.0000
40.6800 891.0000 1.0000
40.7200 959.0000 1.0000
40.7600 928.0000 1.0000
40.8000 928.0000 1.0000
40.8400 900.0000 1.0000
40.8800 915.0000 1.0000
40.9200 887.0000 1.0000
40.9600 955.0000 1.0000
41.0000 920.0000 1.0000
41.0400 886.0000 1.0000
41.0800 924.0000 1.0000
41.1200 875.0000 1.0000
41.1600 861.0000 1.0000
41.2000 891.0000 1.0000
41.2400 913.0000 1.0000
41.2800 859.0000 1.0000
41.3200 906.0000 1.0000
41.3600 894.0000 1.0000
41.4000 905.0000 1.0000
41.4400 964.0000 1.0000
41.4800 949.0000 1.0000
41.5200 935.0000 1.0000
41.5600 931.0000 1.0000
41.6000 944.0000 1.0000
41.6400 950.0000 1.0000
41.6800 958.0000 1.0000
41.7200 914.0000 1.0000
41.7600 907.0000 1.0000
41.8000 962.0000 1.0000
41.8400 901.0000 1.0000
41.8800 905.0000 1.0000
41.9200 968.0000 1.0000
41.9600 872.0000 1.0000
42.0000 910.0000 1.0000
42.0400 894.0000 1.0000
42.0800 882.0000 1.0000
42.1200 916.0000 1.0000
42.1600 916.0000 1.0000
42.2000 884.0000 1.0000
42.2400 883.0000 1.0000
42.2800 874.0000 1.0000
42.3200 880.0000 1.0000
42.3600 833.0000 1.0000
42.4000 894.0000 1.0000
42.4400 870.0000 1.0000
42.4800 905.0000 1.0000
42.5200 921.0000 1.0000
42.5600 899.0000 1.0000
42.6000 852.0000 1.0000
42.6400 874.0000 1.0000
42.6800 876.0000 1.0000
42.7200 862.0000 1.0000
42.7600 871.0000 1.0000
42.8000 895.0000 1.0000
42.8400 882.0000 1.0000
42.8800 855.0000 1.0000
42.9200 905.0000 1.0000
42.9600 882.0000 1.0000
43.0000 914.0000 1.0000
43.0400 923.0000 1.0000
43.0800 930.0000 1.0000
43.1200 948.0000 1.0000
43.1600 931.0000 1.0000
43.2000 935.0000 1.0000
43.2400 913.0000 1.0000
43.2800 958.0000 1.0000
43.3200 962.0000 1.0000
43.3600 987.0000 1.0000
43.4000 916.0000 1.0000
43.4400 885.0000 1.0000
43.4800 920.0000 1.0000
43.5200 875.0000 1.0000
43.5600 845.0000 1.0000
43.6000 855.0000 1.0000
43.6400 819.0000 1.0000
43.6800 876.0000 1.0000
43.7200 842.0000 1.0000
43.7600 892.0000 1.0000
43.8000 843.0000 1.0000
43.8400 837.0000 1.0000
43.8800 882.0000 1.0000
43.9200 840.0000 1.0000
43.9600 835.0000 1.0000
44.0000 863.0000 1.0000
44.0400 877.0000 1.0000
44.0800 837.0000 1.0000
44.1200 833.0000 1.0000
44.1600 824.0000 1.0000
44.2000 858.0000 1.0000
44.2400 836.0000 1.0000
44.2800 841.0000 1.0000
44.3200 878.0000 1.0000
44.3600 903.0000 1.0000
44.4000 867.0000 1.0000
44.4400 838.0000 1.0000
44.4800 855.0000 1.0000
44.5200 867.0000 1.0000
44.5600 799.0000 1.0000
44.6000 799.0000 1.0000
44.6400 841.0000 1.0000
44.6800 838.0000 1.0000
44.7200 852.0000 1.0000
44.7600 845.0000 1.0000
44.8000 811.0000 1.0000
44.8400 805.0000 1.0000
44.8800 896.0000 1.0000
44.9200 837.0000 1.0000
44.9600 833.0000 1.0000
45.0000 834.0000 1.0000
45.0400 841.0000 1.0000
45.0800 817.0000 1.0000
45.1200 838.0000 1.0000
45.1600 841.0000 1.0000
45.2000 813.0000 1.0000
45.2400 843.0000 1.0000
45.2800 789.0000 1.0000
45.3200 853.0000 1.0000
45.3600 750.0000 1.0000
45.4000 826.0000 1.0000
45.4400 802.0000 1.0000
45.4800 801.0000 1.0000
45.5200 831.0000 1.0000
45.5600 823.0000 1.0000
45.6000 836.0000 1.0000
45.6400 815.0000 1.0000
45.6800 815.0000 1.0000
45.7200 867.0000 1.0000
45.7600 830.0000 1.0000
45.8000 829.0000 1.0000
45.8400 818.0000 1.0000
45.8800 820.0000 1.0000
45.9200 783.0000 1.0000
45.9600 813.0000 1.0000
46.0000 841.0000 1.0000
46.0400 831.0000 1.0000
46.0800 816.0000 1.0000
46.1200 790.0000 1.0000
46.1600 814.0000 1.0000
46.2000 812.0000 1.0000
46.2400 842.0000 1.0000
46.2800 779.0000 1.0000
46.3200 819.0000 1.0000
46.3600 829.0000 1.0000
46.4000 831.0000 1.0000
46.4400 737.0000 1.0000
46.4800 811.0000 1.0000
46.5200 798.0000 1.0000
46.5600 810.0000 1.0000
46.6000 798.0000 1.0000
46.6400 855.0000 1.0000
46.6800 815.0000 1.0000
46.7200 771.0000 1.0000
46.7600 784.0000 1.0000
46.8000 783.0000 1.0000
46.8400 781.0000 1.0000
46.8800 848.0000 1.0000
46.9200 851.0000 1.0000
46.9600 844.0000 1.0000
47.0000 840.0000 1.0000
47.0400 830.0000 1.0000
47.0800 817.0000 1.0000
47.1200 800.0000 1.0000
47.1600 798.0000 1.0000
47.2000 819.0000 1.0000
47.2400 755.0000 1.0000
47.2800 809.0000 1.0000
47.3200 836.0000 1.0000
47.3600 792.0000 1.0000
47.4000 844.0000 1.0000
47.4400 795.0000 1.0000
47.4800 766.0000 1.0000
47.5200 780.0000 1.0000
47.5600 820.0000 1.0000
47.6000 818.0000 1.0000
47.6400 751.0000 1.0000
47.6800 776.0000 1.0000
47.7200 784.0000 1.0000
47.7600 802.0000 1.0000
47.8000 788.0000 1.0000
47.8400 780.0000 1.0000
47.8800 802.0000 1.0000
47.9200 791.0000 1.0000
47.9600 717.0000 1.0000
48.0000 787.0000 1.0000
48.0400 772.0000 1.0000
48.0800 750.0000 1.0000
48.1200 781.0000 1.0000
48.1600 785.0000 1.0000
48.2000 784.0000 1.0000
48.2400 803.0000 1.0000
48.2800 809.0000 1.0000
48.3200 743.0000 1.0000
48.3600 763.0000 1.0000
48.4000 782.0000 1.0000
48.4400 753.0000 1.0000
48.4800 727.0000 1.0000
48.5200 810.0000 1.0000
48.5600 830.0000 1.0000
48.6000 781.0000 1.0000
48.6400 782.0000 1.0000
48.6800 775.0000 1.0000
48.7200 778.0000 1.0000
48.7600 792.0000 1.0000
48.8000 732.0000 1.0000
48.8400 765.0000 1.0000
48.8800 766.0000 1.0000
48.9200 793.0000 1.0000
48.9600 770.0000 1.0000
49.0000 732.0000 1.0000
49.0400 742.0000 1.0000
49.0800 803.0000 1.0000
49.1200 788.0000 1.0000
49.1600 720.0000 1.0000
49.2000 701.0000 1.0000
49.2400 765.0000 1.0000
49.2800 778.0000 1.0000
49.3200 722.0000 1.0000
49.3600 736.0000 1.0000
49.4000 789.0000 1.0000
49.4400 782.0000 1.0000
49.4800 787.0000 1.0000
49.5200 800.0000 1.0000
49.5600 759.0000 1.0000
49.6000 779.0000 1.0000
49.6400 761.0000 1.0000
49.6800 818.0000 1.0000
49.7200 749.0000 1.0000
49.7600 730.0000 1.0000
49.8000 759.0000 1.0000
49.8400 779.0000 1.0000
49.8800 810.0000 1.0000
49.9200 797.0000 1.0000
49.9600 723.0000 1.0000
50.0000 774.0000 1.0000
50.0400 761.0000 1.0000
50.0800 743.0000 1.0000
50.1200 781.0000 1.0000
50.1600 785.0000 1.0000
50.2000 821.0000 1.0000
50.2400 794.0000 1.0000
50.2800 798.0000 1.0000
50.3200 783.0000 1.0000
50.3600 801.0000 1.0000
50.4000 823.0000 1.0000
50.4400 817.0000 1.0000
50.4800 779.0000 1.0000
50.5200 788.0000 1.0000
50.5600 770.0000 1.0000
50.6000 784.0000 1.0000
50.6400 809.0000 1.0000
50.6800 762.0000 1.0000
50.7200 778.0000 1.0000
50.7600 772.0000 1.0000
50.8000 734.0000 1.0000
50.8400 780.0000 1.0000
50.8800 765.0000 1.0000
50.9200 732.0000 1.0000
50.9600 779.0000 1.0000
51.0000 776.0000 1.0000
51.0400 794.0000 1.0000
51.0800 747.0000 1.0000
51.1200 769.0000 1.0000
51.1600 803.0000 1.0000
51.2000 752.0000 1.0000
51.2400 770.0000 1.0000
51.2800 744.0000 1.0000
51.3200 700.0000 1.0000
51.3600 738.0000 1.0000
51.4000 797.0000 1.0000
51.4400 790.0000 1.0000
51.4800 773.0000 1.0000
51.5200 767.0000 1.0000
51.5600 803.0000 1.0000
51.6000 787.0000 1.0000
51.6400 778.0000 1.0000
51.6800 821.0000 1.0000
51.7200 838.0000 1.0000
51.7600 841.0000 1.0000
51.8000 853.0000 1.0000
51.8400 857.0000 1.0000
51.8800 925.0000 1.0000
51.9200 1011.0000 1.0000
51.9600 1090.0000 1.0000
52.0000 1215.0000 1.0000
52.0400 1388.0000 1.0000
52.0800 1647.0000 1.0000
52.1200 2112.0000 1.0000
52.1600 2890.0000 1.0000
52.2000 4061.0000 1.0000
52.2400 5133.0000 1.0000
52.2800 5677.0000 1.0000
52.3200 5096.0000 1.0000
52.3600 4641.0000 1.0000
52.4000 4160.0000 1.0000
52.4400 3543.0000 1.0000
52.4800 2688.0000 1.0000
52.5200 1985.0000 1.0000
52.5600 1623.0000 1.0000
52.6000 1366.0000 1.0000
52.6400 1194.0000 1.0000
52.6800 1080.0000 1.0000
52.7200 1014.0000 1.0000
52.7600 987.0000 1.0000
52.8000 960.0000 1.0000
52.8400 905.0000 1.0000
52.8800 848.0000 1.0000
52.9200 834.0000 1.0000
52.9600 840.0000 1.0000
53.0000 801.0000 1.0000
53.0400 839.0000 1.0000
53.0800 784.0000 1.0000
53.1200 804.0000 1.0000
53.1600 762.0000 1.0000
53.2000 772.0000 1.0000
53.2400 767.0000 1.0000
53.2800 772.0000 1.0000
53.3200 707.0000 1.0000
53.3600 772.0000 1.0000
53.4000 713.0000 1.0000
53.4400 735.0000 1.0000
53.4800 756.0000 1.0000
53.5200 771.0000 1.0000
53.5600 785.0000 1.0000
53.6000 746.0000 1.0000
53.6400 793.0000 1.0000
53.6800 724.0000 1.0000
53.7200 764.0000 1.0000
53.7600 686.0000 1.0000
53.8000 786.0000 1.0000
53.8400 730.0000 1.0000
53.8800 718.0000 1.0000
53.9200 780.0000 1.0000
53.9600 758.0000 1.0000
54.0000 732.0000 1.0000
54.0400 771.0000 1.0000
54.0800 739.0000 1.0000
54.1200 735.0000 1.0000
54.1600 768.0000 1.0000
54.2000 738.0000 1.0000
54.2400 761.0000 1.0000
54.2800 755.0000 1.0000
54.3200 686.0000 1.0000
54.3600 721.0000 1.0000
54.4000 743.0000 1.0000
54.4400 744.0000 1.0000
54.4800 717.0000 1.0000
54.5200 779.0000 1.0000
54.5600 757.0000 1.0000
54.6000 731.0000 1.0000
54.6400 785.0000 1.0000
54.6800 816.0000 1.0000
54.7200 766.0000 1.0000
54.7600 846.0000 1.0000
54.8000 789.0000 1.0000
54.8400 807.0000 1.0000
54.8800 883.0000 1.0000
54.9200 802.0000 1.0000
54.9600 811.0000 1.0000
55.0000 851.0000 1.0000
55.0400 871.0000 1.0000
55.0800 859.0000 1.0000
55.1200 903.0000 1.0000
55.1600 950.0000 1.0000
55.2000 1023.0000 1.0000
55.2400 1077.0000 1.0000
55.2800 1141.0000 1.0000
55.3200 1124.0000 1.0000
55.3600 1116.0000 1.0000
55.4000 1025.0000 1.0000
55.4400 1018.0000 1.0000
55.4800 948.0000 1.0000
55.5200 867.0000 1.0000
55.5600 863.0000 1.0000
55.6000 893.0000 1.0000
55.6400 803.0000 1.0000
55.6800 793.0000 1.0000
55.7200 757.0000 1.0000
55.7600 759.0000 1.0000
55.8000 750.0000 1.0000
55.8400 731.0000 1.0000
55.8800 766.0000 1.0000
55.9200 763.0000 1.0000
55.9600 751.0000 1.0000
56.0000 724.0000 1.0000
56.0400 751.0000 1.0000
56.0800 715.0000 1.0000
56.1200 722.0000 1.0000
56.1600 711.0000 1.0000
56.2000 717.0000 1.0000
56.2400 733.0000 1.0000
56.2800 748.0000 1.0000
56.3200 742.0000 1.0000
56.3600 731.0000 1.0000
56.4000 730.0000 1.0000
56.4400 705.0000 1.0000
56.4800 711.0000 1.0000
56.5200 706.0000 1.0000
56.5600 717.0000 1.0000
56.6000 709.0000 1.0000
56.6400 703.0000 1.0000
56.6800 703.0000 1.0000
56.7200 683.0000 1.0000
56.7600 753.0000 1.0000
56.8000 727.0000 1.0000
56.8400 691.0000 1.0000
56.8800 737.0000 1.0000
56.9200 726.0000 1.0000
56.9600 732.0000 1.0000
57.0000 745.0000 1.0000
57.0400 714.0000 1.0000
57.0800 712.0000 1.0000
57.1200 718.0000 1.0000
57.1600 738.0000 1.0000
57.2000 738.0000 1.0000
57.2400 700.0000 1.0000
57.2800 709.0000 1.0000
57.3200 696.0000 1.0000
57.3600 695.0000 1.0000
57.4000 685.0000 1.0000
57.4400 732.0000 1.0000
57.4800 717.0000 1.0000
57.5200 723.0000 1.0000
57.5600 686.0000 1.0000
57.6000 709.0000 1.0000
57.6400 733.0000 1.0000
57.6800 723.0000 1.0000
57.7200 723.0000 1.0000
57.7600 733.0000 1.0000
57.8000 741.0000 1.0000
57.8400 689.0000 1.0000
57.8800 710.0000 1.0000
57.9200 718.0000 1.0000
57.9600 724.0000 1.0000
58.0000 712.0000 1.0000
58.0400 695.0000 1.0000
58.0800 709.0000 1.0000
58.1200 736.0000 1.0000
58.1600 728.0000 1.0000
58.2000 723.0000 1.0000
58.2400 752.0000 1.0000
58.2800 756.0000 1.0000
58.3200 759.0000 1.0000
58.3600 711.0000 1.0000
58.4000 688.0000 1.0000
58.4400 718.0000 1.0000
58.4800 757.0000 1.0000
58.5200 732.0000 1.0000
58.5600 703.0000 1.0000
58.6000 723.0000 1.0000
58.6400 709.0000 1.0000
58.6800 722.0000 1.0000
58.7200 731.0000 1.0000
58.7600 727.0000 1.0000
58.8000 703.0000 1.0000
58.8400 717.0000 1.0000
58.8800 706.0000 1.0000
58.9200 731.0000 1.0000
58.9600 707.0000 1.0000
59.0000 724.0000 1.0000
59.0400 653.0000 1.0000
59.0800 676.0000 1.0000
59.1200 731.0000 1.0000
59.1600 710.0000 1.0000
59.2000 732.0000 1.0000
59.2400 743.0000 1.0000
59.2800 728.0000 1.0000
59.3200 687.0000 1.0000
59.3600 729.0000 1.0000
59.4000 747.0000 1.0000
59.4400 732.0000 1.0000
59.4800 723.0000 1.0000
59.5200 762.0000 1.0000
59.5600 718.0000 1.0000
59.6000 704.0000 1.0000
59.6400 721.0000 1.0000
59.6800 695.0000 1.0000
59.7200 707.0000 1.0000
59.7600 694.0000 1.0000
59.8000 679.0000 1.0000
59.8400 757.0000 1.0000
59.8800 707.0000 1.0000
59.9200 700.0000 1.0000
59.9600 728.0000 1.0000
60.0000 756.0000 1.0000
60.0400 654.0000 1.0000
60.0800 691.0000 1.0000
60.1200 679.0000 1.0000
60.1600 703.0000 1.0000
60.2000 673.0000 1.0000
60.2400 669.0000 1.0000
60.2800 713.0000 1.0000
60.3200 735.0000 1.0000
60.3600 744.0000 1.0000
60.4000 739.0000 1.0000
60.4400 750.0000 1.0000
60.4800 696.0000 1.0000
60.5200 668.0000 1.0000
60.5600 682.0000 1.0000
60.6000 711.0000 1.0000
60.6400 708.0000 1.0000
60.6800 700.0000 1.0000
60.7200 692.0000 1.0000
60.7600 728.0000 1.0000
60.8000 695.0000 1.0000
60.8400 743.0000 1.0000
60.8800 766.0000 1.0000
60.9200 691.0000 1.0000
60.9600 690.0000 1.0000
61.0000 701.0000 1.0000
61.0400 707.0000 1.0000
61.0800 736.0000 1.0000
61.1200 712.0000 1.0000
61.1600 670.0000 1.0000
61.2000 713.0000 1.0000
61.2400 680.0000 1.0000
61.2800 676.0000 1.0000
61.3200 711.0000 1.0000
61.3600 728.0000 1.0000
61.4000 682.0000 1.0000
61.4400 717.0000 1.0000
61.4800 702.0000 1.0000
61.5200 689.0000 1.0000
61.5600 710.0000 1.0000
61.6000 724.0000 1.0000
61.6400 709.0000 1.0000
61.6800 731.0000 1.0000
61.7200 742.0000 1.0000
61.7600 764.0000 1.0000
61.8000 734.0000 1.0000
61.8400 797.0000 1.0000
61.8800 797.0000 1.0000
61.9200 860.0000 1.0000
61.9600 856.0000 1.0000
62.0000 861.0000 1.0000
62.0400 1000.0000 1.0000
62.0800 1067.0000 1.0000
62.1200 1150.0000 1.0000
62.1600 1290.0000 1.0000
62.2000 1368.0000 1.0000
62.2400 1580.0000 1.0000
62.2800 1551.0000 1.0000
62.3200 1558.0000 1.0000
62.3600 1551.0000 1.0000
62.4000 1491.0000 1.0000
62.4400 1415.0000 1.0000
62.4800 1425.0000 1.0000
62.5200 1230.0000 1.0000
62.5600 1117.0000 1.0000
62.6000 1001.0000 1.0000
62.6400 989.0000 1.0000
62.6800 941.0000 1.0000
62.7200 871.0000 1.0000
62.7600 816.0000 1.0000
62.8000 869.0000 1.0000
62.8400 858.0000 1.0000
62.8800 776.0000 1.0000
62.9200 820.0000 1.0000
62.9600 837.0000 1.0000
63.0000 766.0000 1.0000
63.0400 786.0000 1.0000
63.0800 814.0000 1.0000
63.1200 772.0000 1.0000
63.1600 793.0000 1.0000
63.2000 754.0000 1.0000
63.2400 754.0000 1.0000
63.2800 763.0000 1.0000
63.3200 780.0000 1.0000
63.3600 776.0000 1.0000
63.4000 708.0000 1.0000
63.4400 686.0000 1.0000
63.4800 690.0000 1.0000
63.5200 710.0000 1.0000
63.5600 670.0000 1.0000
63.6000 740.0000 1.0000
63.6400 746.0000 1.0000
63.6800 724.0000 1.0000
63.7200 695.0000 1.0000
63.7600 719.0000 1.0000
63.8000 696.0000 1.0000
63.8400 731.0000 1.0000
63.8800 704.0000 1.0000
63.9200 706.0000 1.0000
63.9600 730.0000 1.0000
64.0000 696.0000 1.0000
64.0400 732.0000 1.0000
64.0800 731.0000 1.0000
64.1200 734.0000 1.0000
64.1600 736.0000 1.0000
64.2000 738.0000 1.0000
64.2400 675.0000 1.0000
64.2800 718.0000 1.0000
64.3200 690.0000 1.0000
64.3600 752.0000 1.0000
64.4000 752.0000 1.0000
64.4400 742.0000 1.0000
64.4800 735.0000 1.0000
64.5200 764.0000 1.0000
64.5600 833.0000 1.0000
64.6000 863.0000 1.0000
64.6400 962.0000 1.0000
64.6800 997.0000 1.0000
64.7200 937.0000 1.0000
64.7600 892.0000 1.0000
64.8000 924.0000 1.0000
64.8400 933.0000 1.0000
64.8800 878.0000 1.0000
64.9200 813.0000 1.0000
64.9600 830.0000 1.0000
65.0000 781.0000 1.0000
65.0400 803.0000 1.0000
65.0800 771.0000 1.0000
65.1200 766.0000 1.0000
65.1600 753.0000 1.0000
65.2000 748.0000 1.0000
65.2400 759.0000 1.0000
65.2800 754.0000 1.0000
65.3200 731.0000 1.0000
65.3600 775.0000 1.0000
65.4000 766.0000 1.0000
65.4400 722.0000 1.0000
65.4800 778.0000 1.0000
65.5200 741.0000 1.0000
65.5600 737.0000 1.0000
65.6000 754.0000 1.0000
65.6400 741.0000 1.0000
65.6800 781.0000 1.0000
65.7200 751.0000 1.0000
65.7600 818.0000 1.0000
65.8000 805.0000 1.0000
65.8400 868.0000 1.0000
65.8800 912.0000 1.0000
65.9200 936.0000 1.0000
65.9600 984.0000 1.0000
66.0000 1018.0000 1.0000
66.0400 1192.0000 1.0000
66.0800 1412.0000 1.0000
66.1200 1615.0000 1.0000
66.1600 1975.0000 1.0000
66.2000 2456.0000 1.0000
66.2400 2747.0000 1.0000
66.2800 2909.0000 1.0000
66.3200 2686.0000 1.0000
66.3600 2551.0000 1.0000
66.4000 2397.0000 1.0000
66.4400 2288.0000 1.0000
66.4800 2075.0000 1.0000
66.5200 1801.0000 1.0000
66.5600 1466.0000 1.0000
66.6000 1246.0000 1.0000
66.6400 1135.0000 1.0000
66.6800 1014.0000 1.0000
66.7200 1008.0000 1.0000
66.7600 949.0000 1.0000
66.8000 845.0000 1.0000
66.8400 828.0000 1.0000
66.8800 807.0000 1.0000
66.9200 770.0000 1.0000
66.9600 721.0000 1.0000
67.0000 729.0000 1.0000
67.0400 738.0000 1.0000
67.0800 753.0000 1.0000
67.1200 697.0000 1.0000
67.1600 707.0000 1.0000
67.2000 683.0000 1.0000
67.2400 722.0000 1.0000
67.2800 692.0000 1.0000
67.3200 685.0000 1.0000
67.3600 685.0000 1.0000
67.4000 710.0000 1.0000
67.4400 620.0000 1.0000
67.4800 650.0000 1.0000
67.5200 621.0000 1.0000
67.5600 676.0000 1.0000
67.6000 621.0000 1.0000
67.6400 677.0000 1.0000
67.6800 694.0000 1.0000
67.7200 655.0000 1.0000
67.7600 635.0000 1.0000
67.8000 661.0000 1.0000
67.8400 667.0000 1.0000
67.8800 643.0000 1.0000
67.9200 685.0000 1.0000
67.9600 657.0000 1.0000
68.0000 666.0000 1.0000
68.0400 687.0000 1.0000
68.0800 671.0000 1.0000
68.1200 650.0000 1.0000
68.1600 629.0000 1.0000
68.2000 652.0000 1.0000
68.2400 649.0000 1.0000
68.2800 597.0000 1.0000
68.3200 666.0000 1.0000
68.3600 646.0000 1.0000
68.4000 676.0000 1.0000
68.4400 643.0000 1.0000
68.4800 643.0000 1.0000
68.5200 659.0000 1.0000
68.5600 657.0000 1.0000
68.6000 643.0000 1.0000
68.6400 647.0000 1.0000
68.6800 641.0000 1.0000
68.7200 652.0000 1.0000
68.7600 631.0000 1.0000
68.8000 613.0000 1.0000
68.8400 647.0000 1.0000
68.8800 628.0000 1.0000
68.9200 635.0000 1.0000
68.9600 684.0000 1.0000
69.0000 629.0000 1.0000
69.0400 624.0000 1.0000
69.0800 613.0000 1.0000
69.1200 663.0000 1.0000
69.1600 663.0000 1.0000
69.2000 616.0000 1.0000
69.2400 640.0000 1.0000
69.2800 647.0000 1.0000
69.3200 627.0000 1.0000
69.3600 600.0000 1.0000
69.4000 666.0000 1.0000
69.4400 628.0000 1.0000
69.4800 613.0000 1.0000
69.5200 646.0000 1.0000
69.5600 641.0000 1.0000
69.6000 616.0000 1.0000
69.6400 611.0000 1.0000
69.6800 619.0000 1.0000
69.7200 632.0000 1.0000
69.7600 615.0000 1.0000
69.8000 653.0000 1.0000
69.8400 645.0000 1.0000
69.8800 618.0000 1.0000
69.9200 601.0000 1.0000
69.9600 621.0000 1.0000
70.0000 614.0000 1.0000
*RAS_INT_END
*RAS_TEMPERATURE_START
*RAS_TEMPERATURE_END
*RAS_DATA_END