File: Data/Dataset1_Only_water/5_XRD/No_048_deposition_3h_Air_4.ras
*RAS_DATA_START
*RAS_HEADER_START
*DISP_FMT_X "%.2f"
*DISP_FMT_Y "%.0f"
*DISP_FULLSCALE "17585.0000000000"
*DISP_LINE_COLOR "255.0000000000"
*DISP_LINE_STYLE "0.0000000000"
*DISP_LINE_WIDTH "0.2500000000"
*DISP_NOTE "測定データ-5"
*DISP_OFFSET_Y "0.0000000000"
*DISP_PEAKSEARCH_UNIT_Y "cps"
*DISP_RANGE_BOTTOM "0.0000000000"
*DISP_RANGE_LEFT "20.0000000000"
*DISP_RANGE_LOGCUTOFF "0.0100000000"
*DISP_RANGE_RIGHT "70.0000000000"
*DISP_RANGE_TOP "17585.0000000000"
*DISP_SCALE_MODE_Y "0.0000000000"
*DISP_TAB_NAME "2θ/θ"
*DISP_TITLE_Y "強度"
*DISP_UNIT_Y "cps"
*DISP_WINDOW_NAME "MSG_MACROENGINE"
*FILE_COMMENT " "
*FILE_MD5 ""
*FILE_MEMO " "
*FILE_OPERATOR "Administrator"
*FILE_SAMPLE " "
*FILE_TYPE "RAS_RAW"
*FILE_USERGROUP "システムマネージャ"
*FILE_VERSION "1.0000000000"
*HW_ATTACHMENT_ID "ATT0025"
*HW_ATTACHMENT_NAME "標準|Standard"
*HW_COUNTER_ID-0 "CUT0025"
*HW_COUNTER_ID-1 "CUT0020"
*HW_COUNTER_ID-2 "CUT0020"
*HW_COUNTER_ID-3 "CSL0021"
*HW_COUNTER_ID-4 "CMC0021"
*HW_COUNTER_NAME-0 "D/teX Ultra|D/teX Ultra"
*HW_COUNTER_NAME-1 "None|None"
*HW_COUNTER_NAME-2 "None|None"
*HW_COUNTER_NAME-3 "BBM|BBM"
*HW_COUNTER_NAME-4 "検出器モノクロメータ|Detector monochromator"
*HW_COUNTER_SELECT_NAME "D/teX Ultra|D/teX Ultra"
*HW_GONIOMETER_ID "GON0023"
*HW_GONIOMETER_NAME "SmartLab|SmartLab"
*HW_GONIOMETER_RADIUS-0 "90.0"
*HW_GONIOMETER_RADIUS-1 "114.0"
*HW_GONIOMETER_RADIUS-2 "190.0"
*HW_GONIOMETER_RADIUS-3 "300.0"
*HW_GONIOMETER_RADIUS-4 "187.0"
*HW_GONIOMETER_RADIUS-5 "300.0"
*HW_GONIOMETER_RADIUS-6 "113.0"
*HW_GONIOMETER_RADIUS-7 "331.0"
*HW_I_OPT_ID-0 "CBO0021"
*HW_I_OPT_ID-1 "ICR0023"
*HW_I_OPT_ID-2 "ISL0021"
*HW_I_OPT_ID-3 "ISO0021"
*HW_I_OPT_ID-4 "IAD0021"
*HW_I_OPT_ID-5 "IPR0001"
*HW_I_OPT_NAME-0 "CBOユニット|CBO unit"
*HW_I_OPT_NAME-1 "標準入射光学ユニット|Standard incident optical unit"
*HW_I_OPT_NAME-2 "標準入射スリットボックス|Standard incident slit box"
*HW_I_OPT_NAME-3 "入射平行スリット|Incident parallel slit"
*HW_I_OPT_NAME-4 "長手制限スリット|Length limiting slit"
*HW_I_OPT_NAME-5 "None|None"
*HW_R_ATTENUATER_AUTOMODE "0"
*HW_R_OPT_ID-0 "RSS0021"
*HW_R_OPT_ID-1 "RCR0023"
*HW_R_OPT_ID-2 "RSO0021"
*HW_R_OPT_ID-3 "RRS0021"
*HW_R_OPT_ID-4 "ATN0021"
*HW_R_OPT_ID-5 "RFL0021"
*HW_R_OPT_ID-6 "RAD0021"
*HW_R_OPT_NAME-0 "標準受光スリットボックス1|Standard receiving slit box # 1"
*HW_R_OPT_NAME-1 "標準受光光学ユニット1|Standard receiving unit # 1"
*HW_R_OPT_NAME-2 "標準受光光学ユニット2|Standard receiving optical unit # 2"
*HW_R_OPT_NAME-3 "標準受光スリットボックス2|Standard receiving slit box # 2"
*HW_R_OPT_NAME-4 "標準アッテネータ|Standard Attenuator"
*HW_R_OPT_NAME-5 "Cu Kβ|Cu K-beta"
*HW_R_OPT_NAME-6 "調整用受光スリット|Alignment receiving slit"
*HW_SAMPLE_HOLDER_ID "SMP0023"
*HW_SAMPLE_HOLDER_NAME "標準Zステージ|Standard Z stage"
*HW_XG_CURRENT_MAX "50"
*HW_XG_CURRENT_MIN "2"
*HW_XG_CURRENT_RESOLUTION "1"
*HW_XG_CURRENT_UNIT "mA"
*HW_XG_FOCUS "1mm x 10mm"
*HW_XG_FOCUS_TYPE "Normal"
*HW_XG_ID ""
*HW_XG_NAME "3kW 封入管(ID:1200)|3kW Sealed tube(ID:1200)"
*HW_XG_TARGET_ATOMIC_NUMBER "29.0000000000"
*HW_XG_TARGET_NAME "Cu"
*HW_XG_TYPE "Hermetic"
*HW_XG_VOLTAGE_MAX "60"
*HW_XG_VOLTAGE_MIN "20"
*HW_XG_VOLTAGE_RESOLUTION "1"
*HW_XG_VOLTAGE_UNIT "kV"
*HW_XG_WATT_MAX "1.500"
*HW_XG_WATT_UNIT "kW"
*HW_XG_WAVE_LENGTH_ALPHA1 "1.540593"
*HW_XG_WAVE_LENGTH_ALPHA2 "1.544414"
*HW_XG_WAVE_LENGTH_BETA "1.392250"
*MEAS_COND_AXIS_NAME-0 "2θ/θ"
*MEAS_COND_AXIS_NAME-1 "2θ"
*MEAS_COND_AXIS_NAME-2 "ω"
*MEAS_COND_AXIS_NAME-3 "Z"
*MEAS_COND_AXIS_NAME-4 "2θ/ω"
*MEAS_COND_AXIS_NAME-5 "θs"
*MEAS_COND_AXIS_NAME-6 "θd"
*MEAS_COND_AXIS_NAME-7 "Ts"
*MEAS_COND_AXIS_NAME-8 "CBO選択スリット"
*MEAS_COND_AXIS_NAME-9 "M"
*MEAS_COND_AXIS_NAME-10 "入射平行スリット"
*MEAS_COND_AXIS_NAME-11 "入射スリット"
*MEAS_COND_AXIS_NAME-12 ""
*MEAS_COND_AXIS_NAME-13 "Zs"
*MEAS_COND_AXIS_NAME-14 "入射光学素子"
*MEAS_COND_AXIS_NAME-15 "長手制限スリット"
*MEAS_COND_AXIS_NAME-16 "センタースリット"
*MEAS_COND_AXIS_NAME-17 "フィルター"
*MEAS_COND_AXIS_NAME-18 "受光スリット1"
*MEAS_COND_AXIS_NAME-19 "受光スリット2"
*MEAS_COND_AXIS_NAME-20 "受光光学素子"
*MEAS_COND_AXIS_NAME-21 "受光平行スリット"
*MEAS_COND_AXIS_NAME-22 "調整用受光スリット"
*MEAS_COND_AXIS_NAME-23 ""
*MEAS_COND_AXIS_NAME-24 ""
*MEAS_COND_AXIS_NAME-25 "Zd"
*MEAS_COND_AXIS_NAME-26 "アッテネータ"
*MEAS_COND_AXIS_NAME-27 "検出器モノクロメータ"
*MEAS_COND_AXIS_NAME-28 "モノクロメータスリット"
*MEAS_COND_AXIS_NAME-29 "プライマリビーム"
*MEAS_COND_AXIS_NAME-30 "PHA"
*MEAS_COND_AXIS_NAME_INTERNAL-0 "TwoThetaTheta"
*MEAS_COND_AXIS_NAME_INTERNAL-1 "TwoTheta"
*MEAS_COND_AXIS_NAME_INTERNAL-2 "Omega"
*MEAS_COND_AXIS_NAME_INTERNAL-3 "Z"
*MEAS_COND_AXIS_NAME_INTERNAL-4 "TwoThetaOmega"
*MEAS_COND_AXIS_NAME_INTERNAL-5 "ThetaS"
*MEAS_COND_AXIS_NAME_INTERNAL-6 "ThetaD"
*MEAS_COND_AXIS_NAME_INTERNAL-7 "Ts"
*MEAS_COND_AXIS_NAME_INTERNAL-8 "CBO"
*MEAS_COND_AXIS_NAME_INTERNAL-9 "CBO-M"
*MEAS_COND_AXIS_NAME_INTERNAL-10 "IncidentSollerSlit"
*MEAS_COND_AXIS_NAME_INTERNAL-11 "IncidentSlitBox"
*MEAS_COND_AXIS_NAME_INTERNAL-12 "IncidentSlitBox-_Axis"
*MEAS_COND_AXIS_NAME_INTERNAL-13 "Zs"
*MEAS_COND_AXIS_NAME_INTERNAL-14 "IncidentMonochromator"
*MEAS_COND_AXIS_NAME_INTERNAL-15 "IncidentAxdSlit"
*MEAS_COND_AXIS_NAME_INTERNAL-16 "CenterSlit"
*MEAS_COND_AXIS_NAME_INTERNAL-17 "Filter"
*MEAS_COND_AXIS_NAME_INTERNAL-18 "ReceivingSlitBox1"
*MEAS_COND_AXIS_NAME_INTERNAL-19 "ReceivingSlitBox2"
*MEAS_COND_AXIS_NAME_INTERNAL-20 "ReceivingOptics"
*MEAS_COND_AXIS_NAME_INTERNAL-21 "ReceivingSollerSlit"
*MEAS_COND_AXIS_NAME_INTERNAL-22 "ReceivingAxdSlit"
*MEAS_COND_AXIS_NAME_INTERNAL-23 "ReceivingSlitBox1-_Axis"
*MEAS_COND_AXIS_NAME_INTERNAL-24 "ReceivingSlitBox2-_Axis"
*MEAS_COND_AXIS_NAME_INTERNAL-25 "ReceivingSlitBox2-Zd"
*MEAS_COND_AXIS_NAME_INTERNAL-26 "Attenuator"
*MEAS_COND_AXIS_NAME_INTERNAL-27 "CounterMonochromator"
*MEAS_COND_AXIS_NAME_INTERNAL-28 "CounterSlit"
*MEAS_COND_AXIS_NAME_INTERNAL-29 "IncidentPrimary"
*MEAS_COND_AXIS_NAME_INTERNAL-30 "PHA"
*MEAS_COND_AXIS_NAME_MAGICNO-0 "83951616.0000000000"
*MEAS_COND_AXIS_NAME_MAGICNO-1 "268632064.0000000000"
*MEAS_COND_AXIS_NAME_MAGICNO-2 "268500992.0000000000"
*MEAS_COND_AXIS_NAME_MAGICNO-3 "285278208.0000000000"
*MEAS_COND_AXIS_NAME_MAGICNO-4 "83951616.0000000000"
*MEAS_COND_AXIS_NAME_MAGICNO-5 "131072.0000000000"
*MEAS_COND_AXIS_NAME_MAGICNO-6 "131072.0000000000"
*MEAS_COND_AXIS_NAME_MAGICNO-7 "318898176.0000000000"
*MEAS_COND_AXIS_NAME_MAGICNO-8 "20971521.0000000000"
*MEAS_COND_AXIS_NAME_MAGICNO-9 "285343744.0000000000"
*MEAS_COND_AXIS_NAME_MAGICNO-10 "20971521.0000000000"
*MEAS_COND_AXIS_NAME_MAGICNO-11 "22020097.0000000000"
*MEAS_COND_AXIS_NAME_MAGICNO-12 "25165824.0000000000"
*MEAS_COND_AXIS_NAME_MAGICNO-13 "318898176.0000000000"
*MEAS_COND_AXIS_NAME_MAGICNO-14 "1.0000000000"
*MEAS_COND_AXIS_NAME_MAGICNO-15 "20971521.0000000000"
*MEAS_COND_AXIS_NAME_MAGICNO-16 "20971521.0000000000"
*MEAS_COND_AXIS_NAME_MAGICNO-17 "20971521.0000000000"
*MEAS_COND_AXIS_NAME_MAGICNO-18 "23068673.0000000000"
*MEAS_COND_AXIS_NAME_MAGICNO-19 "23068673.0000000000"
*MEAS_COND_AXIS_NAME_MAGICNO-20 "20971521.0000000000"
*MEAS_COND_AXIS_NAME_MAGICNO-21 "20971521.0000000000"
*MEAS_COND_AXIS_NAME_MAGICNO-22 "20971521.0000000000"
*MEAS_COND_AXIS_NAME_MAGICNO-23 "25165824.0000000000"
*MEAS_COND_AXIS_NAME_MAGICNO-24 "25165824.0000000000"
*MEAS_COND_AXIS_NAME_MAGICNO-25 "285343744.0000000000"
*MEAS_COND_AXIS_NAME_MAGICNO-26 "17301505.0000000000"
*MEAS_COND_AXIS_NAME_MAGICNO-27 "20971521.0000000000"
*MEAS_COND_AXIS_NAME_MAGICNO-28 "20971521.0000000000"
*MEAS_COND_AXIS_NAME_MAGICNO-29 "20971521.0000000000"
*MEAS_COND_AXIS_NAME_MAGICNO-30 "0.0000000000"
*MEAS_COND_AXIS_OFFSET-0 "-"
*MEAS_COND_AXIS_OFFSET-1 "-0.0801000000"
*MEAS_COND_AXIS_OFFSET-2 "0.1646000000"
*MEAS_COND_AXIS_OFFSET-3 "-"
*MEAS_COND_AXIS_OFFSET-4 "-"
*MEAS_COND_AXIS_OFFSET-5 "0.1646000000"
*MEAS_COND_AXIS_OFFSET-6 "-0.2447000000"
*MEAS_COND_AXIS_OFFSET-7 "-"
*MEAS_COND_AXIS_OFFSET-8 "-"
*MEAS_COND_AXIS_OFFSET-9 "-"
*MEAS_COND_AXIS_OFFSET-10 "-"
*MEAS_COND_AXIS_OFFSET-11 "-"
*MEAS_COND_AXIS_OFFSET-12 "-"
*MEAS_COND_AXIS_OFFSET-13 "-"
*MEAS_COND_AXIS_OFFSET-14 "-"
*MEAS_COND_AXIS_OFFSET-15 "-"
*MEAS_COND_AXIS_OFFSET-16 "-"
*MEAS_COND_AXIS_OFFSET-17 "-"
*MEAS_COND_AXIS_OFFSET-18 "-"
*MEAS_COND_AXIS_OFFSET-19 "-"
*MEAS_COND_AXIS_OFFSET-20 "-"
*MEAS_COND_AXIS_OFFSET-21 "-"
*MEAS_COND_AXIS_OFFSET-22 "-"
*MEAS_COND_AXIS_OFFSET-23 "-"
*MEAS_COND_AXIS_OFFSET-24 "-"
*MEAS_COND_AXIS_OFFSET-25 "-"
*MEAS_COND_AXIS_OFFSET-26 "-"
*MEAS_COND_AXIS_OFFSET-27 "-"
*MEAS_COND_AXIS_OFFSET-28 "-"
*MEAS_COND_AXIS_OFFSET-29 "-"
*MEAS_COND_AXIS_OFFSET-30 "-"
*MEAS_COND_AXIS_POSITION-0 "0.0000000000"
*MEAS_COND_AXIS_POSITION-1 "0.0000000000"
*MEAS_COND_AXIS_POSITION-2 "0.0000000000"
*MEAS_COND_AXIS_POSITION-3 "-2.9256400000"
*MEAS_COND_AXIS_POSITION-4 "0.0000000000"
*MEAS_COND_AXIS_POSITION-5 "0.0000000000"
*MEAS_COND_AXIS_POSITION-6 "0.0000000000"
*MEAS_COND_AXIS_POSITION-7 "-0.4278800000"
*MEAS_COND_AXIS_POSITION-8 "BB"
*MEAS_COND_AXIS_POSITION-9 "0.0000000000"
*MEAS_COND_AXIS_POSITION-10 "Soller_slit_5.0deg"
*MEAS_COND_AXIS_POSITION-11 "2/3deg"
*MEAS_COND_AXIS_POSITION-12 "2.2088000000"
*MEAS_COND_AXIS_POSITION-13 "-1.0609400000"
*MEAS_COND_AXIS_POSITION-14 "0.0000000000"
*MEAS_COND_AXIS_POSITION-15 "10.0mm"
*MEAS_COND_AXIS_POSITION-16 "None"
*MEAS_COND_AXIS_POSITION-17 "Cu_K-beta"
*MEAS_COND_AXIS_POSITION-18 "13.000mm"
*MEAS_COND_AXIS_POSITION-19 "13.000mm"
*MEAS_COND_AXIS_POSITION-20 "No_unit"
*MEAS_COND_AXIS_POSITION-21 "Soller_slit_5.0deg"
*MEAS_COND_AXIS_POSITION-22 "None"
*MEAS_COND_AXIS_POSITION-23 "13.0000000000"
*MEAS_COND_AXIS_POSITION-24 "13.0000000000"
*MEAS_COND_AXIS_POSITION-25 "0.0081300000"
*MEAS_COND_AXIS_POSITION-26 "Open"
*MEAS_COND_AXIS_POSITION-27 "None"
*MEAS_COND_AXIS_POSITION-28 "None"
*MEAS_COND_AXIS_POSITION-29 "None"
*MEAS_COND_AXIS_POSITION-30 "38.0000000000"
*MEAS_COND_AXIS_UNIT-0 "deg"
*MEAS_COND_AXIS_UNIT-1 "deg"
*MEAS_COND_AXIS_UNIT-2 "deg"
*MEAS_COND_AXIS_UNIT-3 "mm"
*MEAS_COND_AXIS_UNIT-4 "deg"
*MEAS_COND_AXIS_UNIT-5 "deg"
*MEAS_COND_AXIS_UNIT-6 "deg"
*MEAS_COND_AXIS_UNIT-7 "mm"
*MEAS_COND_AXIS_UNIT-8 ""
*MEAS_COND_AXIS_UNIT-9 "pulse"
*MEAS_COND_AXIS_UNIT-10 ""
*MEAS_COND_AXIS_UNIT-11 ""
*MEAS_COND_AXIS_UNIT-12 "mm"
*MEAS_COND_AXIS_UNIT-13 "mm"
*MEAS_COND_AXIS_UNIT-14 ""
*MEAS_COND_AXIS_UNIT-15 ""
*MEAS_COND_AXIS_UNIT-16 ""
*MEAS_COND_AXIS_UNIT-17 ""
*MEAS_COND_AXIS_UNIT-18 ""
*MEAS_COND_AXIS_UNIT-19 ""
*MEAS_COND_AXIS_UNIT-20 ""
*MEAS_COND_AXIS_UNIT-21 ""
*MEAS_COND_AXIS_UNIT-22 ""
*MEAS_COND_AXIS_UNIT-23 "mm"
*MEAS_COND_AXIS_UNIT-24 "mm"
*MEAS_COND_AXIS_UNIT-25 "mm"
*MEAS_COND_AXIS_UNIT-26 ""
*MEAS_COND_AXIS_UNIT-27 ""
*MEAS_COND_AXIS_UNIT-28 ""
*MEAS_COND_AXIS_UNIT-29 ""
*MEAS_COND_AXIS_UNIT-30 "div"
*MEAS_COND_COUNTER_CNTLOSS_CORR "0.0000000000"
*MEAS_COND_COUNTER_PHABASE "38.0000000000"
*MEAS_COND_COUNTER_PHAWINDOW "16.0000000000"
*MEAS_COND_COUNTER_PHA_UNIT "div"
*MEAS_COND_COUNTER_TAUDIFF "30.0000000000"
*MEAS_COND_COUNTER_TAUINT "0.0000000000"
*MEAS_COND_IRRADIATION_MODE "OFF"
*MEAS_COND_IRRADIATION_WIDTH ""
*MEAS_COND_OPT_ATTR "集中法"
*MEAS_COND_OPT_NAME "@集中法"
*MEAS_COND_UNSYMMETRIC_MODE "OFF"
*MEAS_COND_XG_CURRENT "30.0000000000"
*MEAS_COND_XG_VOLTAGE "40.0000000000"
*MEAS_COND_XG_WAVE_TYPE "Ka"
*MEAS_DATA_COUNT "5001.0000000000"
*MEAS_SCAN_AXIS_X "2θ/θ"
*MEAS_SCAN_AXIS_X_INTERNAL "TwoThetaTheta"
*MEAS_SCAN_END_TIME "07/09/22 14:36:01"
*MEAS_SCAN_MODE "CONTINUOUS"
*MEAS_SCAN_MONITOR "0"
*MEAS_SCAN_RESOLUTION_X "0.0002"
*MEAS_SCAN_SPEED "2.5"
*MEAS_SCAN_SPEED_UNIT "deg/min"
*MEAS_SCAN_START "20.0000000000"
*MEAS_SCAN_START_TIME "07/09/22 14:14:37"
*MEAS_SCAN_STEP "0.0100000000"
*MEAS_SCAN_STOP "70.0000000000"
*MEAS_SCAN_UNIT_X "deg"
*MEAS_SCAN_UNIT_Y "counts"
*RAS_HEADER_END
*RAS_INT_START
20.0000 1071.0000 1.0000
20.0400 1003.0000 1.0000
20.0800 969.0000 1.0000
20.1200 1015.0000 1.0000
20.1600 990.0000 1.0000
20.2000 953.0000 1.0000
20.2400 981.0000 1.0000
20.2800 995.0000 1.0000
20.3200 1041.0000 1.0000
20.3600 1060.0000 1.0000
20.4000 1015.0000 1.0000
20.4400 976.0000 1.0000
20.4800 1035.0000 1.0000
20.5200 1028.0000 1.0000
20.5600 1006.0000 1.0000
20.6000 1027.0000 1.0000
20.6400 993.0000 1.0000
20.6800 1002.0000 1.0000
20.7200 1016.0000 1.0000
20.7600 996.0000 1.0000
20.8000 1000.0000 1.0000
20.8400 1019.0000 1.0000
20.8800 1047.0000 1.0000
20.9200 993.0000 1.0000
20.9600 988.0000 1.0000
21.0000 1055.0000 1.0000
21.0400 1010.0000 1.0000
21.0800 1034.0000 1.0000
21.1200 968.0000 1.0000
21.1600 973.0000 1.0000
21.2000 1034.0000 1.0000
21.2400 1054.0000 1.0000
21.2800 946.0000 1.0000
21.3200 987.0000 1.0000
21.3600 1015.0000 1.0000
21.4000 964.0000 1.0000
21.4400 1033.0000 1.0000
21.4800 982.0000 1.0000
21.5200 1031.0000 1.0000
21.5600 1046.0000 1.0000
21.6000 1028.0000 1.0000
21.6400 1003.0000 1.0000
21.6800 999.0000 1.0000
21.7200 1011.0000 1.0000
21.7600 1017.0000 1.0000
21.8000 1000.0000 1.0000
21.8400 983.0000 1.0000
21.8800 1002.0000 1.0000
21.9200 1010.0000 1.0000
21.9600 1000.0000 1.0000
22.0000 1004.0000 1.0000
22.0400 1037.0000 1.0000
22.0800 991.0000 1.0000
22.1200 985.0000 1.0000
22.1600 989.0000 1.0000
22.2000 1013.0000 1.0000
22.2400 1042.0000 1.0000
22.2800 1002.0000 1.0000
22.3200 1025.0000 1.0000
22.3600 1004.0000 1.0000
22.4000 998.0000 1.0000
22.4400 989.0000 1.0000
22.4800 1013.0000 1.0000
22.5200 1047.0000 1.0000
22.5600 990.0000 1.0000
22.6000 1049.0000 1.0000
22.6400 1026.0000 1.0000
22.6800 1012.0000 1.0000
22.7200 989.0000 1.0000
22.7600 989.0000 1.0000
22.8000 944.0000 1.0000
22.8400 990.0000 1.0000
22.8800 1001.0000 1.0000
22.9200 1023.0000 1.0000
22.9600 952.0000 1.0000
23.0000 1028.0000 1.0000
23.0400 1038.0000 1.0000
23.0800 934.0000 1.0000
23.1200 985.0000 1.0000
23.1600 986.0000 1.0000
23.2000 989.0000 1.0000
23.2400 941.0000 1.0000
23.2800 983.0000 1.0000
23.3200 1052.0000 1.0000
23.3600 962.0000 1.0000
23.4000 955.0000 1.0000
23.4400 1009.0000 1.0000
23.4800 989.0000 1.0000
23.5200 975.0000 1.0000
23.5600 1020.0000 1.0000
23.6000 958.0000 1.0000
23.6400 994.0000 1.0000
23.6800 961.0000 1.0000
23.7200 1007.0000 1.0000
23.7600 999.0000 1.0000
23.8000 998.0000 1.0000
23.8400 1001.0000 1.0000
23.8800 1008.0000 1.0000
23.9200 1023.0000 1.0000
23.9600 1021.0000 1.0000
24.0000 1089.0000 1.0000
24.0400 1068.0000 1.0000
24.0800 1058.0000 1.0000
24.1200 1032.0000 1.0000
24.1600 1068.0000 1.0000
24.2000 1035.0000 1.0000
24.2400 1063.0000 1.0000
24.2800 1070.0000 1.0000
24.3200 1003.0000 1.0000
24.3600 967.0000 1.0000
24.4000 1007.0000 1.0000
24.4400 1080.0000 1.0000
24.4800 1022.0000 1.0000
24.5200 1044.0000 1.0000
24.5600 989.0000 1.0000
24.6000 1001.0000 1.0000
24.6400 955.0000 1.0000
24.6800 959.0000 1.0000
24.7200 994.0000 1.0000
24.7600 969.0000 1.0000
24.8000 970.0000 1.0000
24.8400 940.0000 1.0000
24.8800 963.0000 1.0000
24.9200 980.0000 1.0000
24.9600 978.0000 1.0000
25.0000 1010.0000 1.0000
25.0400 952.0000 1.0000
25.0800 946.0000 1.0000
25.1200 950.0000 1.0000
25.1600 951.0000 1.0000
25.2000 973.0000 1.0000
25.2400 955.0000 1.0000
25.2800 1012.0000 1.0000
25.3200 955.0000 1.0000
25.3600 977.0000 1.0000
25.4000 936.0000 1.0000
25.4400 1005.0000 1.0000
25.4800 994.0000 1.0000
25.5200 1020.0000 1.0000
25.5600 1052.0000 1.0000
25.6000 1017.0000 1.0000
25.6400 962.0000 1.0000
25.6800 957.0000 1.0000
25.7200 961.0000 1.0000
25.7600 1015.0000 1.0000
25.8000 1024.0000 1.0000
25.8400 999.0000 1.0000
25.8800 1013.0000 1.0000
25.9200 1055.0000 1.0000
25.9600 1017.0000 1.0000
26.0000 1098.0000 1.0000
26.0400 1098.0000 1.0000
26.0800 1183.0000 1.0000
26.1200 1236.0000 1.0000
26.1600 1294.0000 1.0000
26.2000 1382.0000 1.0000
26.2400 1612.0000 1.0000
26.2800 1759.0000 1.0000
26.3200 2134.0000 1.0000
26.3600 2804.0000 1.0000
26.4000 3359.0000 1.0000
26.4400 3436.0000 1.0000
26.4800 3123.0000 1.0000
26.5200 2740.0000 1.0000
26.5600 2151.0000 1.0000
26.6000 1766.0000 1.0000
26.6400 1501.0000 1.0000
26.6800 1369.0000 1.0000
26.7200 1193.0000 1.0000
26.7600 1151.0000 1.0000
26.8000 1151.0000 1.0000
26.8400 1076.0000 1.0000
26.8800 1070.0000 1.0000
26.9200 995.0000 1.0000
26.9600 1013.0000 1.0000
27.0000 990.0000 1.0000
27.0400 965.0000 1.0000
27.0800 968.0000 1.0000
27.1200 990.0000 1.0000
27.1600 947.0000 1.0000
27.2000 989.0000 1.0000
27.2400 927.0000 1.0000
27.2800 899.0000 1.0000
27.3200 932.0000 1.0000
27.3600 918.0000 1.0000
27.4000 961.0000 1.0000
27.4400 949.0000 1.0000
27.4800 929.0000 1.0000
27.5200 886.0000 1.0000
27.5600 919.0000 1.0000
27.6000 881.0000 1.0000
27.6400 917.0000 1.0000
27.6800 883.0000 1.0000
27.7200 954.0000 1.0000
27.7600 886.0000 1.0000
27.8000 896.0000 1.0000
27.8400 906.0000 1.0000
27.8800 868.0000 1.0000
27.9200 927.0000 1.0000
27.9600 931.0000 1.0000
28.0000 827.0000 1.0000
28.0400 897.0000 1.0000
28.0800 919.0000 1.0000
28.1200 882.0000 1.0000
28.1600 850.0000 1.0000
28.2000 886.0000 1.0000
28.2400 911.0000 1.0000
28.2800 870.0000 1.0000
28.3200 821.0000 1.0000
28.3600 859.0000 1.0000
28.4000 878.0000 1.0000
28.4400 873.0000 1.0000
28.4800 908.0000 1.0000
28.5200 861.0000 1.0000
28.5600 853.0000 1.0000
28.6000 832.0000 1.0000
28.6400 858.0000 1.0000
28.6800 808.0000 1.0000
28.7200 842.0000 1.0000
28.7600 889.0000 1.0000
28.8000 852.0000 1.0000
28.8400 853.0000 1.0000
28.8800 891.0000 1.0000
28.9200 841.0000 1.0000
28.9600 822.0000 1.0000
29.0000 830.0000 1.0000
29.0400 868.0000 1.0000
29.0800 868.0000 1.0000
29.1200 859.0000 1.0000
29.1600 889.0000 1.0000
29.2000 840.0000 1.0000
29.2400 813.0000 1.0000
29.2800 889.0000 1.0000
29.3200 840.0000 1.0000
29.3600 811.0000 1.0000
29.4000 820.0000 1.0000
29.4400 821.0000 1.0000
29.4800 802.0000 1.0000
29.5200 800.0000 1.0000
29.5600 826.0000 1.0000
29.6000 857.0000 1.0000
29.6400 806.0000 1.0000
29.6800 834.0000 1.0000
29.7200 813.0000 1.0000
29.7600 834.0000 1.0000
29.8000 836.0000 1.0000
29.8400 837.0000 1.0000
29.8800 806.0000 1.0000
29.9200 781.0000 1.0000
29.9600 847.0000 1.0000
30.0000 783.0000 1.0000
30.0400 784.0000 1.0000
30.0800 792.0000 1.0000
30.1200 853.0000 1.0000
30.1600 825.0000 1.0000
30.2000 766.0000 1.0000
30.2400 801.0000 1.0000
30.2800 796.0000 1.0000
30.3200 804.0000 1.0000
30.3600 807.0000 1.0000
30.4000 814.0000 1.0000
30.4400 794.0000 1.0000
30.4800 843.0000 1.0000
30.5200 809.0000 1.0000
30.5600 776.0000 1.0000
30.6000 811.0000 1.0000
30.6400 791.0000 1.0000
30.6800 812.0000 1.0000
30.7200 785.0000 1.0000
30.7600 812.0000 1.0000
30.8000 757.0000 1.0000
30.8400 783.0000 1.0000
30.8800 785.0000 1.0000
30.9200 818.0000 1.0000
30.9600 786.0000 1.0000
31.0000 773.0000 1.0000
31.0400 784.0000 1.0000
31.0800 808.0000 1.0000
31.1200 778.0000 1.0000
31.1600 831.0000 1.0000
31.2000 773.0000 1.0000
31.2400 830.0000 1.0000
31.2800 775.0000 1.0000
31.3200 789.0000 1.0000
31.3600 788.0000 1.0000
31.4000 742.0000 1.0000
31.4400 765.0000 1.0000
31.4800 783.0000 1.0000
31.5200 800.0000 1.0000
31.5600 769.0000 1.0000
31.6000 764.0000 1.0000
31.6400 750.0000 1.0000
31.6800 767.0000 1.0000
31.7200 814.0000 1.0000
31.7600 768.0000 1.0000
31.8000 753.0000 1.0000
31.8400 767.0000 1.0000
31.8800 789.0000 1.0000
31.9200 760.0000 1.0000
31.9600 772.0000 1.0000
32.0000 730.0000 1.0000
32.0400 768.0000 1.0000
32.0800 743.0000 1.0000
32.1200 777.0000 1.0000
32.1600 772.0000 1.0000
32.2000 782.0000 1.0000
32.2400 749.0000 1.0000
32.2800 810.0000 1.0000
32.3200 683.0000 1.0000
32.3600 764.0000 1.0000
32.4000 709.0000 1.0000
32.4400 739.0000 1.0000
32.4800 788.0000 1.0000
32.5200 733.0000 1.0000
32.5600 767.0000 1.0000
32.6000 748.0000 1.0000
32.6400 775.0000 1.0000
32.6800 681.0000 1.0000
32.7200 735.0000 1.0000
32.7600 776.0000 1.0000
32.8000 749.0000 1.0000
32.8400 774.0000 1.0000
32.8800 776.0000 1.0000
32.9200 766.0000 1.0000
32.9600 844.0000 1.0000
33.0000 851.0000 1.0000
33.0400 884.0000 1.0000
33.0800 961.0000 1.0000
33.1200 879.0000 1.0000
33.1600 897.0000 1.0000
33.2000 837.0000 1.0000
33.2400 855.0000 1.0000
33.2800 828.0000 1.0000
33.3200 881.0000 1.0000
33.3600 885.0000 1.0000
33.4000 935.0000 1.0000
33.4400 998.0000 1.0000
33.4800 1087.0000 1.0000
33.5200 1267.0000 1.0000
33.5600 1561.0000 1.0000
33.6000 1776.0000 1.0000
33.6400 1915.0000 1.0000
33.6800 1909.0000 1.0000
33.7200 1623.0000 1.0000
33.7600 1486.0000 1.0000
33.8000 1206.0000 1.0000
33.8400 1020.0000 1.0000
33.8800 970.0000 1.0000
33.9200 906.0000 1.0000
33.9600 851.0000 1.0000
34.0000 787.0000 1.0000
34.0400 818.0000 1.0000
34.0800 750.0000 1.0000
34.1200 765.0000 1.0000
34.1600 706.0000 1.0000
34.2000 724.0000 1.0000
34.2400 709.0000 1.0000
34.2800 708.0000 1.0000
34.3200 652.0000 1.0000
34.3600 702.0000 1.0000
34.4000 680.0000 1.0000
34.4400 689.0000 1.0000
34.4800 670.0000 1.0000
34.5200 711.0000 1.0000
34.5600 667.0000 1.0000
34.6000 655.0000 1.0000
34.6400 695.0000 1.0000
34.6800 699.0000 1.0000
34.7200 640.0000 1.0000
34.7600 699.0000 1.0000
34.8000 639.0000 1.0000
34.8400 642.0000 1.0000
34.8800 683.0000 1.0000
34.9200 686.0000 1.0000
34.9600 659.0000 1.0000
35.0000 684.0000 1.0000
35.0400 670.0000 1.0000
35.0800 683.0000 1.0000
35.1200 673.0000 1.0000
35.1600 666.0000 1.0000
35.2000 661.0000 1.0000
35.2400 706.0000 1.0000
35.2800 677.0000 1.0000
35.3200 724.0000 1.0000
35.3600 690.0000 1.0000
35.4000 815.0000 1.0000
35.4400 839.0000 1.0000
35.4800 987.0000 1.0000
35.5200 1291.0000 1.0000
35.5600 1268.0000 1.0000
35.6000 1209.0000 1.0000
35.6400 1065.0000 1.0000
35.6800 888.0000 1.0000
35.7200 825.0000 1.0000
35.7600 758.0000 1.0000
35.8000 689.0000 1.0000
35.8400 634.0000 1.0000
35.8800 677.0000 1.0000
35.9200 606.0000 1.0000
35.9600 657.0000 1.0000
36.0000 594.0000 1.0000
36.0400 638.0000 1.0000
36.0800 648.0000 1.0000
36.1200 658.0000 1.0000
36.1600 599.0000 1.0000
36.2000 611.0000 1.0000
36.2400 636.0000 1.0000
36.2800 629.0000 1.0000
36.3200 637.0000 1.0000
36.3600 597.0000 1.0000
36.4000 591.0000 1.0000
36.4400 572.0000 1.0000
36.4800 579.0000 1.0000
36.5200 577.0000 1.0000
36.5600 622.0000 1.0000
36.6000 623.0000 1.0000
36.6400 573.0000 1.0000
36.6800 580.0000 1.0000
36.7200 588.0000 1.0000
36.7600 608.0000 1.0000
36.8000 612.0000 1.0000
36.8400 563.0000 1.0000
36.8800 600.0000 1.0000
36.9200 592.0000 1.0000
36.9600 566.0000 1.0000
37.0000 599.0000 1.0000
37.0400 564.0000 1.0000
37.0800 635.0000 1.0000
37.1200 594.0000 1.0000
37.1600 581.0000 1.0000
37.2000 645.0000 1.0000
37.2400 674.0000 1.0000
37.2800 652.0000 1.0000
37.3200 703.0000 1.0000
37.3600 709.0000 1.0000
37.4000 826.0000 1.0000
37.4400 917.0000 1.0000
37.4800 1005.0000 1.0000
37.5200 1180.0000 1.0000
37.5600 1474.0000 1.0000
37.6000 1959.0000 1.0000
37.6400 2420.0000 1.0000
37.6800 2738.0000 1.0000
37.7200 2729.0000 1.0000
37.7600 2349.0000 1.0000
37.8000 1978.0000 1.0000
37.8400 1623.0000 1.0000
37.8800 1300.0000 1.0000
37.9200 1027.0000 1.0000
37.9600 865.0000 1.0000
38.0000 747.0000 1.0000
38.0400 723.0000 1.0000
38.0800 654.0000 1.0000
38.1200 618.0000 1.0000
38.1600 604.0000 1.0000
38.2000 598.0000 1.0000
38.2400 573.0000 1.0000
38.2800 580.0000 1.0000
38.3200 570.0000 1.0000
38.3600 540.0000 1.0000
38.4000 499.0000 1.0000
38.4400 532.0000 1.0000
38.4800 545.0000 1.0000
38.5200 518.0000 1.0000
38.5600 521.0000 1.0000
38.6000 567.0000 1.0000
38.6400 578.0000 1.0000
38.6800 537.0000 1.0000
38.7200 555.0000 1.0000
38.7600 537.0000 1.0000
38.8000 554.0000 1.0000
38.8400 556.0000 1.0000
38.8800 549.0000 1.0000
38.9200 541.0000 1.0000
38.9600 515.0000 1.0000
39.0000 498.0000 1.0000
39.0400 488.0000 1.0000
39.0800 549.0000 1.0000
39.1200 520.0000 1.0000
39.1600 548.0000 1.0000
39.2000 512.0000 1.0000
39.2400 530.0000 1.0000
39.2800 481.0000 1.0000
39.3200 486.0000 1.0000
39.3600 486.0000 1.0000
39.4000 485.0000 1.0000
39.4400 495.0000 1.0000
39.4800 481.0000 1.0000
39.5200 515.0000 1.0000
39.5600 460.0000 1.0000
39.6000 518.0000 1.0000
39.6400 473.0000 1.0000
39.6800 494.0000 1.0000
39.7200 521.0000 1.0000
39.7600 504.0000 1.0000
39.8000 476.0000 1.0000
39.8400 497.0000 1.0000
39.8800 442.0000 1.0000
39.9200 532.0000 1.0000
39.9600 478.0000 1.0000
40.0000 507.0000 1.0000
40.0400 502.0000 1.0000
40.0800 449.0000 1.0000
40.1200 516.0000 1.0000
40.1600 522.0000 1.0000
40.2000 494.0000 1.0000
40.2400 489.0000 1.0000
40.2800 486.0000 1.0000
40.3200 462.0000 1.0000
40.3600 481.0000 1.0000
40.4000 445.0000 1.0000
40.4400 474.0000 1.0000
40.4800 488.0000 1.0000
40.5200 479.0000 1.0000
40.5600 517.0000 1.0000
40.6000 465.0000 1.0000
40.6400 476.0000 1.0000
40.6800 507.0000 1.0000
40.7200 549.0000 1.0000
40.7600 509.0000 1.0000
40.8000 518.0000 1.0000
40.8400 522.0000 1.0000
40.8800 522.0000 1.0000
40.9200 494.0000 1.0000
40.9600 520.0000 1.0000
41.0000 482.0000 1.0000
41.0400 475.0000 1.0000
41.0800 456.0000 1.0000
41.1200 506.0000 1.0000
41.1600 478.0000 1.0000
41.2000 481.0000 1.0000
41.2400 507.0000 1.0000
41.2800 497.0000 1.0000
41.3200 474.0000 1.0000
41.3600 471.0000 1.0000
41.4000 451.0000 1.0000
41.4400 515.0000 1.0000
41.4800 478.0000 1.0000
41.5200 464.0000 1.0000
41.5600 445.0000 1.0000
41.6000 454.0000 1.0000
41.6400 463.0000 1.0000
41.6800 454.0000 1.0000
41.7200 453.0000 1.0000
41.7600 482.0000 1.0000
41.8000 491.0000 1.0000
41.8400 443.0000 1.0000
41.8800 457.0000 1.0000
41.9200 434.0000 1.0000
41.9600 473.0000 1.0000
42.0000 469.0000 1.0000
42.0400 475.0000 1.0000
42.0800 475.0000 1.0000
42.1200 497.0000 1.0000
42.1600 443.0000 1.0000
42.2000 489.0000 1.0000
42.2400 481.0000 1.0000
42.2800 502.0000 1.0000
42.3200 503.0000 1.0000
42.3600 522.0000 1.0000
42.4000 467.0000 1.0000
42.4400 488.0000 1.0000
42.4800 523.0000 1.0000
42.5200 497.0000 1.0000
42.5600 522.0000 1.0000
42.6000 496.0000 1.0000
42.6400 460.0000 1.0000
42.6800 495.0000 1.0000
42.7200 474.0000 1.0000
42.7600 479.0000 1.0000
42.8000 417.0000 1.0000
42.8400 433.0000 1.0000
42.8800 488.0000 1.0000
42.9200 493.0000 1.0000
42.9600 424.0000 1.0000
43.0000 449.0000 1.0000
43.0400 489.0000 1.0000
43.0800 452.0000 1.0000
43.1200 461.0000 1.0000
43.1600 479.0000 1.0000
43.2000 474.0000 1.0000
43.2400 476.0000 1.0000
43.2800 453.0000 1.0000
43.3200 465.0000 1.0000
43.3600 450.0000 1.0000
43.4000 475.0000 1.0000
43.4400 485.0000 1.0000
43.4800 457.0000 1.0000
43.5200 471.0000 1.0000
43.5600 471.0000 1.0000
43.6000 485.0000 1.0000
43.6400 439.0000 1.0000
43.6800 486.0000 1.0000
43.7200 451.0000 1.0000
43.7600 440.0000 1.0000
43.8000 471.0000 1.0000
43.8400 462.0000 1.0000
43.8800 439.0000 1.0000
43.9200 462.0000 1.0000
43.9600 442.0000 1.0000
44.0000 442.0000 1.0000
44.0400 459.0000 1.0000
44.0800 450.0000 1.0000
44.1200 444.0000 1.0000
44.1600 461.0000 1.0000
44.2000 452.0000 1.0000
44.2400 443.0000 1.0000
44.2800 448.0000 1.0000
44.3200 464.0000 1.0000
44.3600 455.0000 1.0000
44.4000 450.0000 1.0000
44.4400 468.0000 1.0000
44.4800 434.0000 1.0000
44.5200 426.0000 1.0000
44.5600 472.0000 1.0000
44.6000 431.0000 1.0000
44.6400 439.0000 1.0000
44.6800 450.0000 1.0000
44.7200 475.0000 1.0000
44.7600 454.0000 1.0000
44.8000 453.0000 1.0000
44.8400 439.0000 1.0000
44.8800 440.0000 1.0000
44.9200 454.0000 1.0000
44.9600 387.0000 1.0000
45.0000 453.0000 1.0000
45.0400 445.0000 1.0000
45.0800 440.0000 1.0000
45.1200 414.0000 1.0000
45.1600 441.0000 1.0000
45.2000 449.0000 1.0000
45.2400 422.0000 1.0000
45.2800 440.0000 1.0000
45.3200 414.0000 1.0000
45.3600 459.0000 1.0000
45.4000 423.0000 1.0000
45.4400 421.0000 1.0000
45.4800 430.0000 1.0000
45.5200 395.0000 1.0000
45.5600 419.0000 1.0000
45.6000 436.0000 1.0000
45.6400 419.0000 1.0000
45.6800 411.0000 1.0000
45.7200 385.0000 1.0000
45.7600 432.0000 1.0000
45.8000 437.0000 1.0000
45.8400 390.0000 1.0000
45.8800 466.0000 1.0000
45.9200 435.0000 1.0000
45.9600 412.0000 1.0000
46.0000 395.0000 1.0000
46.0400 429.0000 1.0000
46.0800 435.0000 1.0000
46.1200 430.0000 1.0000
46.1600 437.0000 1.0000
46.2000 457.0000 1.0000
46.2400 429.0000 1.0000
46.2800 428.0000 1.0000
46.3200 387.0000 1.0000
46.3600 433.0000 1.0000
46.4000 420.0000 1.0000
46.4400 432.0000 1.0000
46.4800 434.0000 1.0000
46.5200 408.0000 1.0000
46.5600 430.0000 1.0000
46.6000 401.0000 1.0000
46.6400 423.0000 1.0000
46.6800 431.0000 1.0000
46.7200 419.0000 1.0000
46.7600 403.0000 1.0000
46.8000 415.0000 1.0000
46.8400 397.0000 1.0000
46.8800 428.0000 1.0000
46.9200 401.0000 1.0000
46.9600 393.0000 1.0000
47.0000 398.0000 1.0000
47.0400 402.0000 1.0000
47.0800 400.0000 1.0000
47.1200 415.0000 1.0000
47.1600 392.0000 1.0000
47.2000 424.0000 1.0000
47.2400 436.0000 1.0000
47.2800 428.0000 1.0000
47.3200 400.0000 1.0000
47.3600 399.0000 1.0000
47.4000 376.0000 1.0000
47.4400 393.0000 1.0000
47.4800 411.0000 1.0000
47.5200 438.0000 1.0000
47.5600 401.0000 1.0000
47.6000 423.0000 1.0000
47.6400 409.0000 1.0000
47.6800 407.0000 1.0000
47.7200 452.0000 1.0000
47.7600 398.0000 1.0000
47.8000 385.0000 1.0000
47.8400 445.0000 1.0000
47.8800 400.0000 1.0000
47.9200 412.0000 1.0000
47.9600 407.0000 1.0000
48.0000 415.0000 1.0000
48.0400 436.0000 1.0000
48.0800 394.0000 1.0000
48.1200 392.0000 1.0000
48.1600 404.0000 1.0000
48.2000 414.0000 1.0000
48.2400 426.0000 1.0000
48.2800 403.0000 1.0000
48.3200 414.0000 1.0000
48.3600 424.0000 1.0000
48.4000 403.0000 1.0000
48.4400 393.0000 1.0000
48.4800 399.0000 1.0000
48.5200 364.0000 1.0000
48.5600 385.0000 1.0000
48.6000 407.0000 1.0000
48.6400 389.0000 1.0000
48.6800 415.0000 1.0000
48.7200 401.0000 1.0000
48.7600 386.0000 1.0000
48.8000 413.0000 1.0000
48.8400 403.0000 1.0000
48.8800 377.0000 1.0000
48.9200 395.0000 1.0000
48.9600 430.0000 1.0000
49.0000 406.0000 1.0000
49.0400 367.0000 1.0000
49.0800 423.0000 1.0000
49.1200 396.0000 1.0000
49.1600 406.0000 1.0000
49.2000 392.0000 1.0000
49.2400 408.0000 1.0000
49.2800 418.0000 1.0000
49.3200 436.0000 1.0000
49.3600 441.0000 1.0000
49.4000 439.0000 1.0000
49.4400 414.0000 1.0000
49.4800 416.0000 1.0000
49.5200 386.0000 1.0000
49.5600 419.0000 1.0000
49.6000 409.0000 1.0000
49.6400 375.0000 1.0000
49.6800 426.0000 1.0000
49.7200 420.0000 1.0000
49.7600 414.0000 1.0000
49.8000 443.0000 1.0000
49.8400 409.0000 1.0000
49.8800 422.0000 1.0000
49.9200 411.0000 1.0000
49.9600 409.0000 1.0000
50.0000 362.0000 1.0000
50.0400 405.0000 1.0000
50.0800 366.0000 1.0000
50.1200 365.0000 1.0000
50.1600 413.0000 1.0000
50.2000 427.0000 1.0000
50.2400 397.0000 1.0000
50.2800 409.0000 1.0000
50.3200 395.0000 1.0000
50.3600 394.0000 1.0000
50.4000 399.0000 1.0000
50.4400 433.0000 1.0000
50.4800 425.0000 1.0000
50.5200 417.0000 1.0000
50.5600 419.0000 1.0000
50.6000 438.0000 1.0000
50.6400 407.0000 1.0000
50.6800 411.0000 1.0000
50.7200 416.0000 1.0000
50.7600 394.0000 1.0000
50.8000 394.0000 1.0000
50.8400 426.0000 1.0000
50.8800 439.0000 1.0000
50.9200 462.0000 1.0000
50.9600 432.0000 1.0000
51.0000 443.0000 1.0000
51.0400 467.0000 1.0000
51.0800 478.0000 1.0000
51.1200 513.0000 1.0000
51.1600 567.0000 1.0000
51.2000 665.0000 1.0000
51.2400 737.0000 1.0000
51.2800 904.0000 1.0000
51.3200 1127.0000 1.0000
51.3600 1557.0000 1.0000
51.4000 2113.0000 1.0000
51.4400 2647.0000 1.0000
51.4800 2827.0000 1.0000
51.5200 2621.0000 1.0000
51.5600 2267.0000 1.0000
51.6000 2026.0000 1.0000
51.6400 1774.0000 1.0000
51.6800 1268.0000 1.0000
51.7200 971.0000 1.0000
51.7600 800.0000 1.0000
51.8000 726.0000 1.0000
51.8400 653.0000 1.0000
51.8800 581.0000 1.0000
51.9200 524.0000 1.0000
51.9600 475.0000 1.0000
52.0000 515.0000 1.0000
52.0400 483.0000 1.0000
52.0800 456.0000 1.0000
52.1200 430.0000 1.0000
52.1600 472.0000 1.0000
52.2000 428.0000 1.0000
52.2400 420.0000 1.0000
52.2800 422.0000 1.0000
52.3200 426.0000 1.0000
52.3600 388.0000 1.0000
52.4000 361.0000 1.0000
52.4400 413.0000 1.0000
52.4800 418.0000 1.0000
52.5200 397.0000 1.0000
52.5600 405.0000 1.0000
52.6000 397.0000 1.0000
52.6400 408.0000 1.0000
52.6800 418.0000 1.0000
52.7200 402.0000 1.0000
52.7600 428.0000 1.0000
52.8000 400.0000 1.0000
52.8400 406.0000 1.0000
52.8800 395.0000 1.0000
52.9200 378.0000 1.0000
52.9600 413.0000 1.0000
53.0000 405.0000 1.0000
53.0400 394.0000 1.0000
53.0800 414.0000 1.0000
53.1200 378.0000 1.0000
53.1600 412.0000 1.0000
53.2000 393.0000 1.0000
53.2400 379.0000 1.0000
53.2800 395.0000 1.0000
53.3200 405.0000 1.0000
53.3600 362.0000 1.0000
53.4000 368.0000 1.0000
53.4400 395.0000 1.0000
53.4800 406.0000 1.0000
53.5200 377.0000 1.0000
53.5600 358.0000 1.0000
53.6000 410.0000 1.0000
53.6400 393.0000 1.0000
53.6800 372.0000 1.0000
53.7200 425.0000 1.0000
53.7600 411.0000 1.0000
53.8000 384.0000 1.0000
53.8400 419.0000 1.0000
53.8800 408.0000 1.0000
53.9200 431.0000 1.0000
53.9600 410.0000 1.0000
54.0000 488.0000 1.0000
54.0400 439.0000 1.0000
54.0800 442.0000 1.0000
54.1200 452.0000 1.0000
54.1600 464.0000 1.0000
54.2000 458.0000 1.0000
54.2400 417.0000 1.0000
54.2800 443.0000 1.0000
54.3200 447.0000 1.0000
54.3600 514.0000 1.0000
54.4000 534.0000 1.0000
54.4400 563.0000 1.0000
54.4800 590.0000 1.0000
54.5200 630.0000 1.0000
54.5600 604.0000 1.0000
54.6000 595.0000 1.0000
54.6400 572.0000 1.0000
54.6800 529.0000 1.0000
54.7200 469.0000 1.0000
54.7600 481.0000 1.0000
54.8000 471.0000 1.0000
54.8400 408.0000 1.0000
54.8800 431.0000 1.0000
54.9200 386.0000 1.0000
54.9600 389.0000 1.0000
55.0000 417.0000 1.0000
55.0400 418.0000 1.0000
55.0800 361.0000 1.0000
55.1200 435.0000 1.0000
55.1600 394.0000 1.0000
55.2000 402.0000 1.0000
55.2400 402.0000 1.0000
55.2800 393.0000 1.0000
55.3200 389.0000 1.0000
55.3600 368.0000 1.0000
55.4000 381.0000 1.0000
55.4400 345.0000 1.0000
55.4800 392.0000 1.0000
55.5200 362.0000 1.0000
55.5600 347.0000 1.0000
55.6000 374.0000 1.0000
55.6400 388.0000 1.0000
55.6800 389.0000 1.0000
55.7200 364.0000 1.0000
55.7600 364.0000 1.0000
55.8000 361.0000 1.0000
55.8400 357.0000 1.0000
55.8800 363.0000 1.0000
55.9200 371.0000 1.0000
55.9600 381.0000 1.0000
56.0000 332.0000 1.0000
56.0400 392.0000 1.0000
56.0800 405.0000 1.0000
56.1200 414.0000 1.0000
56.1600 361.0000 1.0000
56.2000 386.0000 1.0000
56.2400 367.0000 1.0000
56.2800 388.0000 1.0000
56.3200 388.0000 1.0000
56.3600 403.0000 1.0000
56.4000 368.0000 1.0000
56.4400 380.0000 1.0000
56.4800 376.0000 1.0000
56.5200 388.0000 1.0000
56.5600 391.0000 1.0000
56.6000 373.0000 1.0000
56.6400 364.0000 1.0000
56.6800 361.0000 1.0000
56.7200 386.0000 1.0000
56.7600 381.0000 1.0000
56.8000 377.0000 1.0000
56.8400 368.0000 1.0000
56.8800 372.0000 1.0000
56.9200 343.0000 1.0000
56.9600 353.0000 1.0000
57.0000 363.0000 1.0000
57.0400 377.0000 1.0000
57.0800 370.0000 1.0000
57.1200 338.0000 1.0000
57.1600 379.0000 1.0000
57.2000 371.0000 1.0000
57.2400 375.0000 1.0000
57.2800 364.0000 1.0000
57.3200 406.0000 1.0000
57.3600 379.0000 1.0000
57.4000 362.0000 1.0000
57.4400 378.0000 1.0000
57.4800 356.0000 1.0000
57.5200 346.0000 1.0000
57.5600 388.0000 1.0000
57.6000 356.0000 1.0000
57.6400 378.0000 1.0000
57.6800 387.0000 1.0000
57.7200 370.0000 1.0000
57.7600 341.0000 1.0000
57.8000 373.0000 1.0000
57.8400 357.0000 1.0000
57.8800 347.0000 1.0000
57.9200 378.0000 1.0000
57.9600 379.0000 1.0000
58.0000 342.0000 1.0000
58.0400 363.0000 1.0000
58.0800 387.0000 1.0000
58.1200 373.0000 1.0000
58.1600 355.0000 1.0000
58.2000 379.0000 1.0000
58.2400 358.0000 1.0000
58.2800 356.0000 1.0000
58.3200 360.0000 1.0000
58.3600 369.0000 1.0000
58.4000 357.0000 1.0000
58.4400 328.0000 1.0000
58.4800 327.0000 1.0000
58.5200 385.0000 1.0000
58.5600 361.0000 1.0000
58.6000 384.0000 1.0000
58.6400 378.0000 1.0000
58.6800 390.0000 1.0000
58.7200 370.0000 1.0000
58.7600 336.0000 1.0000
58.8000 356.0000 1.0000
58.8400 368.0000 1.0000
58.8800 337.0000 1.0000
58.9200 361.0000 1.0000
58.9600 345.0000 1.0000
59.0000 369.0000 1.0000
59.0400 390.0000 1.0000
59.0800 347.0000 1.0000
59.1200 366.0000 1.0000
59.1600 362.0000 1.0000
59.2000 367.0000 1.0000
59.2400 343.0000 1.0000
59.2800 313.0000 1.0000
59.3200 362.0000 1.0000
59.3600 352.0000 1.0000
59.4000 353.0000 1.0000
59.4400 347.0000 1.0000
59.4800 355.0000 1.0000
59.5200 356.0000 1.0000
59.5600 411.0000 1.0000
59.6000 359.0000 1.0000
59.6400 350.0000 1.0000
59.6800 384.0000 1.0000
59.7200 340.0000 1.0000
59.7600 367.0000 1.0000
59.8000 381.0000 1.0000
59.8400 323.0000 1.0000
59.8800 352.0000 1.0000
59.9200 362.0000 1.0000
59.9600 379.0000 1.0000
60.0000 372.0000 1.0000
60.0400 371.0000 1.0000
60.0800 359.0000 1.0000
60.1200 358.0000 1.0000
60.1600 353.0000 1.0000
60.2000 362.0000 1.0000
60.2400 350.0000 1.0000
60.2800 352.0000 1.0000
60.3200 355.0000 1.0000
60.3600 357.0000 1.0000
60.4000 355.0000 1.0000
60.4400 367.0000 1.0000
60.4800 365.0000 1.0000
60.5200 364.0000 1.0000
60.5600 342.0000 1.0000
60.6000 361.0000 1.0000
60.6400 358.0000 1.0000
60.6800 363.0000 1.0000
60.7200 341.0000 1.0000
60.7600 371.0000 1.0000
60.8000 374.0000 1.0000
60.8400 387.0000 1.0000
60.8800 361.0000 1.0000
60.9200 371.0000 1.0000
60.9600 376.0000 1.0000
61.0000 367.0000 1.0000
61.0400 384.0000 1.0000
61.0800 380.0000 1.0000
61.1200 409.0000 1.0000
61.1600 380.0000 1.0000
61.2000 427.0000 1.0000
61.2400 461.0000 1.0000
61.2800 440.0000 1.0000
61.3200 499.0000 1.0000
61.3600 559.0000 1.0000
61.4000 580.0000 1.0000
61.4400 656.0000 1.0000
61.4800 681.0000 1.0000
61.5200 742.0000 1.0000
61.5600 726.0000 1.0000
61.6000 727.0000 1.0000
61.6400 672.0000 1.0000
61.6800 661.0000 1.0000
61.7200 620.0000 1.0000
61.7600 606.0000 1.0000
61.8000 557.0000 1.0000
61.8400 481.0000 1.0000
61.8800 442.0000 1.0000
61.9200 456.0000 1.0000
61.9600 424.0000 1.0000
62.0000 432.0000 1.0000
62.0400 419.0000 1.0000
62.0800 418.0000 1.0000
62.1200 414.0000 1.0000
62.1600 414.0000 1.0000
62.2000 369.0000 1.0000
62.2400 376.0000 1.0000
62.2800 389.0000 1.0000
62.3200 403.0000 1.0000
62.3600 401.0000 1.0000
62.4000 395.0000 1.0000
62.4400 391.0000 1.0000
62.4800 368.0000 1.0000
62.5200 419.0000 1.0000
62.5600 362.0000 1.0000
62.6000 366.0000 1.0000
62.6400 372.0000 1.0000
62.6800 355.0000 1.0000
62.7200 383.0000 1.0000
62.7600 361.0000 1.0000
62.8000 373.0000 1.0000
62.8400 359.0000 1.0000
62.8800 343.0000 1.0000
62.9200 368.0000 1.0000
62.9600 379.0000 1.0000
63.0000 362.0000 1.0000
63.0400 379.0000 1.0000
63.0800 357.0000 1.0000
63.1200 357.0000 1.0000
63.1600 330.0000 1.0000
63.2000 361.0000 1.0000
63.2400 347.0000 1.0000
63.2800 359.0000 1.0000
63.3200 368.0000 1.0000
63.3600 343.0000 1.0000
63.4000 377.0000 1.0000
63.4400 362.0000 1.0000
63.4800 386.0000 1.0000
63.5200 358.0000 1.0000
63.5600 395.0000 1.0000
63.6000 408.0000 1.0000
63.6400 395.0000 1.0000
63.6800 380.0000 1.0000
63.7200 421.0000 1.0000
63.7600 438.0000 1.0000
63.8000 441.0000 1.0000
63.8400 501.0000 1.0000
63.8800 572.0000 1.0000
63.9200 593.0000 1.0000
63.9600 604.0000 1.0000
64.0000 523.0000 1.0000
64.0400 552.0000 1.0000
64.0800 512.0000 1.0000
64.1200 507.0000 1.0000
64.1600 472.0000 1.0000
64.2000 450.0000 1.0000
64.2400 455.0000 1.0000
64.2800 395.0000 1.0000
64.3200 410.0000 1.0000
64.3600 403.0000 1.0000
64.4000 391.0000 1.0000
64.4400 388.0000 1.0000
64.4800 386.0000 1.0000
64.5200 370.0000 1.0000
64.5600 418.0000 1.0000
64.6000 387.0000 1.0000
64.6400 395.0000 1.0000
64.6800 423.0000 1.0000
64.7200 374.0000 1.0000
64.7600 371.0000 1.0000
64.8000 403.0000 1.0000
64.8400 413.0000 1.0000
64.8800 342.0000 1.0000
64.9200 411.0000 1.0000
64.9600 414.0000 1.0000
65.0000 374.0000 1.0000
65.0400 418.0000 1.0000
65.0800 420.0000 1.0000
65.1200 438.0000 1.0000
65.1600 441.0000 1.0000
65.2000 469.0000 1.0000
65.2400 511.0000 1.0000
65.2800 634.0000 1.0000
65.3200 606.0000 1.0000
65.3600 814.0000 1.0000
65.4000 909.0000 1.0000
65.4400 1075.0000 1.0000
65.4800 1276.0000 1.0000
65.5200 1391.0000 1.0000
65.5600 1286.0000 1.0000
65.6000 1208.0000 1.0000
65.6400 1132.0000 1.0000
65.6800 1083.0000 1.0000
65.7200 952.0000 1.0000
65.7600 835.0000 1.0000
65.8000 696.0000 1.0000
65.8400 658.0000 1.0000
65.8800 634.0000 1.0000
65.9200 494.0000 1.0000
65.9600 457.0000 1.0000
66.0000 454.0000 1.0000
66.0400 404.0000 1.0000
66.0800 456.0000 1.0000
66.1200 387.0000 1.0000
66.1600 381.0000 1.0000
66.2000 386.0000 1.0000
66.2400 370.0000 1.0000
66.2800 369.0000 1.0000
66.3200 400.0000 1.0000
66.3600 371.0000 1.0000
66.4000 345.0000 1.0000
66.4400 349.0000 1.0000
66.4800 358.0000 1.0000
66.5200 362.0000 1.0000
66.5600 328.0000 1.0000
66.6000 345.0000 1.0000
66.6400 353.0000 1.0000
66.6800 332.0000 1.0000
66.7200 319.0000 1.0000
66.7600 331.0000 1.0000
66.8000 369.0000 1.0000
66.8400 346.0000 1.0000
66.8800 313.0000 1.0000
66.9200 334.0000 1.0000
66.9600 325.0000 1.0000
67.0000 306.0000 1.0000
67.0400 347.0000 1.0000
67.0800 342.0000 1.0000
67.1200 329.0000 1.0000
67.1600 309.0000 1.0000
67.2000 340.0000 1.0000
67.2400 319.0000 1.0000
67.2800 329.0000 1.0000
67.3200 342.0000 1.0000
67.3600 342.0000 1.0000
67.4000 332.0000 1.0000
67.4400 350.0000 1.0000
67.4800 333.0000 1.0000
67.5200 327.0000 1.0000
67.5600 360.0000 1.0000
67.6000 340.0000 1.0000
67.6400 315.0000 1.0000
67.6800 339.0000 1.0000
67.7200 325.0000 1.0000
67.7600 329.0000 1.0000
67.8000 353.0000 1.0000
67.8400 329.0000 1.0000
67.8800 326.0000 1.0000
67.9200 323.0000 1.0000
67.9600 314.0000 1.0000
68.0000 335.0000 1.0000
68.0400 320.0000 1.0000
68.0800 312.0000 1.0000
68.1200 320.0000 1.0000
68.1600 334.0000 1.0000
68.2000 303.0000 1.0000
68.2400 343.0000 1.0000
68.2800 334.0000 1.0000
68.3200 326.0000 1.0000
68.3600 330.0000 1.0000
68.4000 282.0000 1.0000
68.4400 327.0000 1.0000
68.4800 311.0000 1.0000
68.5200 330.0000 1.0000
68.5600 312.0000 1.0000
68.6000 332.0000 1.0000
68.6400 320.0000 1.0000
68.6800 327.0000 1.0000
68.7200 311.0000 1.0000
68.7600 350.0000 1.0000
68.8000 302.0000 1.0000
68.8400 324.0000 1.0000
68.8800 289.0000 1.0000
68.9200 320.0000 1.0000
68.9600 330.0000 1.0000
69.0000 324.0000 1.0000
69.0400 311.0000 1.0000
69.0800 323.0000 1.0000
69.1200 308.0000 1.0000
69.1600 334.0000 1.0000
69.2000 311.0000 1.0000
69.2400 307.0000 1.0000
69.2800 324.0000 1.0000
69.3200 311.0000 1.0000
69.3600 328.0000 1.0000
69.4000 288.0000 1.0000
69.4400 318.0000 1.0000
69.4800 312.0000 1.0000
69.5200 326.0000 1.0000
69.5600 314.0000 1.0000
69.6000 314.0000 1.0000
69.6400 291.0000 1.0000
69.6800 328.0000 1.0000
69.7200 297.0000 1.0000
69.7600 303.0000 1.0000
69.8000 324.0000 1.0000
69.8400 322.0000 1.0000
69.8800 312.0000 1.0000
69.9200 310.0000 1.0000
69.9600 287.0000 1.0000
70.0000 338.0000 1.0000
*RAS_INT_END
*RAS_TEMPERATURE_START
*RAS_TEMPERATURE_END
*RAS_DATA_END