File: Data/Dataset1_Only_water/5_XRD/No_006_FS2_2.ras
*RAS_DATA_START
*RAS_HEADER_START
*DISP_FMT_X "%.2f"
*DISP_FMT_Y "%.0f"
*DISP_FULLSCALE "14876.0000000000"
*DISP_LINE_COLOR "255.0000000000"
*DISP_LINE_STYLE "0.0000000000"
*DISP_LINE_WIDTH "0.2500000000"
*DISP_NOTE "測定データ-3"
*DISP_OFFSET_Y "0.0000000000"
*DISP_PEAKSEARCH_UNIT_Y "cps"
*DISP_RANGE_BOTTOM "0.0000000000"
*DISP_RANGE_LEFT "20.0000000000"
*DISP_RANGE_LOGCUTOFF "0.0100000000"
*DISP_RANGE_RIGHT "70.0000000000"
*DISP_RANGE_TOP "14876.0000000000"
*DISP_SCALE_MODE_Y "0.0000000000"
*DISP_TAB_NAME "2θ/θ"
*DISP_TITLE_Y "強度"
*DISP_UNIT_Y "cps"
*DISP_WINDOW_NAME "MSG_MACROENGINE"
*FILE_COMMENT " "
*FILE_MD5 ""
*FILE_MEMO " "
*FILE_OPERATOR "Administrator"
*FILE_SAMPLE " "
*FILE_TYPE "RAS_RAW"
*FILE_USERGROUP "システムマネージャ"
*FILE_VERSION "1.0000000000"
*HW_ATTACHMENT_ID "ATT0025"
*HW_ATTACHMENT_NAME "標準|Standard"
*HW_COUNTER_ID-0 "CUT0025"
*HW_COUNTER_ID-1 "CUT0020"
*HW_COUNTER_ID-2 "CUT0020"
*HW_COUNTER_ID-3 "CSL0021"
*HW_COUNTER_ID-4 "CMC0021"
*HW_COUNTER_NAME-0 "D/teX Ultra|D/teX Ultra"
*HW_COUNTER_NAME-1 "None|None"
*HW_COUNTER_NAME-2 "None|None"
*HW_COUNTER_NAME-3 "BBM|BBM"
*HW_COUNTER_NAME-4 "検出器モノクロメータ|Detector monochromator"
*HW_COUNTER_SELECT_NAME "D/teX Ultra|D/teX Ultra"
*HW_GONIOMETER_ID "GON0023"
*HW_GONIOMETER_NAME "SmartLab|SmartLab"
*HW_GONIOMETER_RADIUS-0 "90.0"
*HW_GONIOMETER_RADIUS-1 "114.0"
*HW_GONIOMETER_RADIUS-2 "190.0"
*HW_GONIOMETER_RADIUS-3 "300.0"
*HW_GONIOMETER_RADIUS-4 "187.0"
*HW_GONIOMETER_RADIUS-5 "300.0"
*HW_GONIOMETER_RADIUS-6 "113.0"
*HW_GONIOMETER_RADIUS-7 "331.0"
*HW_I_OPT_ID-0 "CBO0021"
*HW_I_OPT_ID-1 "ICR0023"
*HW_I_OPT_ID-2 "ISL0021"
*HW_I_OPT_ID-3 "ISO0021"
*HW_I_OPT_ID-4 "IAD0021"
*HW_I_OPT_ID-5 "IPR0001"
*HW_I_OPT_NAME-0 "CBOユニット|CBO unit"
*HW_I_OPT_NAME-1 "標準入射光学ユニット|Standard incident optical unit"
*HW_I_OPT_NAME-2 "標準入射スリットボックス|Standard incident slit box"
*HW_I_OPT_NAME-3 "入射平行スリット|Incident parallel slit"
*HW_I_OPT_NAME-4 "長手制限スリット|Length limiting slit"
*HW_I_OPT_NAME-5 "None|None"
*HW_R_ATTENUATER_AUTOMODE "0"
*HW_R_OPT_ID-0 "RSS0021"
*HW_R_OPT_ID-1 "RCR0023"
*HW_R_OPT_ID-2 "RSO0021"
*HW_R_OPT_ID-3 "RRS0021"
*HW_R_OPT_ID-4 "ATN0021"
*HW_R_OPT_ID-5 "RFL0021"
*HW_R_OPT_ID-6 "RAD0021"
*HW_R_OPT_NAME-0 "標準受光スリットボックス1|Standard receiving slit box # 1"
*HW_R_OPT_NAME-1 "標準受光光学ユニット1|Standard receiving unit # 1"
*HW_R_OPT_NAME-2 "標準受光光学ユニット2|Standard receiving optical unit # 2"
*HW_R_OPT_NAME-3 "標準受光スリットボックス2|Standard receiving slit box # 2"
*HW_R_OPT_NAME-4 "標準アッテネータ|Standard Attenuator"
*HW_R_OPT_NAME-5 "Cu Kβ|Cu K-beta"
*HW_R_OPT_NAME-6 "調整用受光スリット|Alignment receiving slit"
*HW_SAMPLE_HOLDER_ID "SMP0023"
*HW_SAMPLE_HOLDER_NAME "標準Zステージ|Standard Z stage"
*HW_XG_CURRENT_MAX "50"
*HW_XG_CURRENT_MIN "2"
*HW_XG_CURRENT_RESOLUTION "1"
*HW_XG_CURRENT_UNIT "mA"
*HW_XG_FOCUS "1mm x 10mm"
*HW_XG_FOCUS_TYPE "Normal"
*HW_XG_ID ""
*HW_XG_NAME "3kW 封入管(ID:1200)|3kW Sealed tube(ID:1200)"
*HW_XG_TARGET_ATOMIC_NUMBER "29.0000000000"
*HW_XG_TARGET_NAME "Cu"
*HW_XG_TYPE "Hermetic"
*HW_XG_VOLTAGE_MAX "60"
*HW_XG_VOLTAGE_MIN "20"
*HW_XG_VOLTAGE_RESOLUTION "1"
*HW_XG_VOLTAGE_UNIT "kV"
*HW_XG_WATT_MAX "1.500"
*HW_XG_WATT_UNIT "kW"
*HW_XG_WAVE_LENGTH_ALPHA1 "1.540593"
*HW_XG_WAVE_LENGTH_ALPHA2 "1.544414"
*HW_XG_WAVE_LENGTH_BETA "1.392250"
*MEAS_COND_AXIS_NAME-0 "2θ/θ"
*MEAS_COND_AXIS_NAME-1 "2θ"
*MEAS_COND_AXIS_NAME-2 "ω"
*MEAS_COND_AXIS_NAME-3 "Z"
*MEAS_COND_AXIS_NAME-4 "2θ/ω"
*MEAS_COND_AXIS_NAME-5 "θs"
*MEAS_COND_AXIS_NAME-6 "θd"
*MEAS_COND_AXIS_NAME-7 "Ts"
*MEAS_COND_AXIS_NAME-8 "CBO選択スリット"
*MEAS_COND_AXIS_NAME-9 "M"
*MEAS_COND_AXIS_NAME-10 "入射平行スリット"
*MEAS_COND_AXIS_NAME-11 "入射スリット"
*MEAS_COND_AXIS_NAME-12 ""
*MEAS_COND_AXIS_NAME-13 "Zs"
*MEAS_COND_AXIS_NAME-14 "入射光学素子"
*MEAS_COND_AXIS_NAME-15 "長手制限スリット"
*MEAS_COND_AXIS_NAME-16 "センタースリット"
*MEAS_COND_AXIS_NAME-17 "フィルター"
*MEAS_COND_AXIS_NAME-18 "受光スリット1"
*MEAS_COND_AXIS_NAME-19 "受光スリット2"
*MEAS_COND_AXIS_NAME-20 "受光光学素子"
*MEAS_COND_AXIS_NAME-21 "受光平行スリット"
*MEAS_COND_AXIS_NAME-22 "調整用受光スリット"
*MEAS_COND_AXIS_NAME-23 ""
*MEAS_COND_AXIS_NAME-24 ""
*MEAS_COND_AXIS_NAME-25 "Zd"
*MEAS_COND_AXIS_NAME-26 "アッテネータ"
*MEAS_COND_AXIS_NAME-27 "検出器モノクロメータ"
*MEAS_COND_AXIS_NAME-28 "モノクロメータスリット"
*MEAS_COND_AXIS_NAME-29 "プライマリビーム"
*MEAS_COND_AXIS_NAME-30 "PHA"
*MEAS_COND_AXIS_NAME_INTERNAL-0 "TwoThetaTheta"
*MEAS_COND_AXIS_NAME_INTERNAL-1 "TwoTheta"
*MEAS_COND_AXIS_NAME_INTERNAL-2 "Omega"
*MEAS_COND_AXIS_NAME_INTERNAL-3 "Z"
*MEAS_COND_AXIS_NAME_INTERNAL-4 "TwoThetaOmega"
*MEAS_COND_AXIS_NAME_INTERNAL-5 "ThetaS"
*MEAS_COND_AXIS_NAME_INTERNAL-6 "ThetaD"
*MEAS_COND_AXIS_NAME_INTERNAL-7 "Ts"
*MEAS_COND_AXIS_NAME_INTERNAL-8 "CBO"
*MEAS_COND_AXIS_NAME_INTERNAL-9 "CBO-M"
*MEAS_COND_AXIS_NAME_INTERNAL-10 "IncidentSollerSlit"
*MEAS_COND_AXIS_NAME_INTERNAL-11 "IncidentSlitBox"
*MEAS_COND_AXIS_NAME_INTERNAL-12 "IncidentSlitBox-_Axis"
*MEAS_COND_AXIS_NAME_INTERNAL-13 "Zs"
*MEAS_COND_AXIS_NAME_INTERNAL-14 "IncidentMonochromator"
*MEAS_COND_AXIS_NAME_INTERNAL-15 "IncidentAxdSlit"
*MEAS_COND_AXIS_NAME_INTERNAL-16 "CenterSlit"
*MEAS_COND_AXIS_NAME_INTERNAL-17 "Filter"
*MEAS_COND_AXIS_NAME_INTERNAL-18 "ReceivingSlitBox1"
*MEAS_COND_AXIS_NAME_INTERNAL-19 "ReceivingSlitBox2"
*MEAS_COND_AXIS_NAME_INTERNAL-20 "ReceivingOptics"
*MEAS_COND_AXIS_NAME_INTERNAL-21 "ReceivingSollerSlit"
*MEAS_COND_AXIS_NAME_INTERNAL-22 "ReceivingAxdSlit"
*MEAS_COND_AXIS_NAME_INTERNAL-23 "ReceivingSlitBox1-_Axis"
*MEAS_COND_AXIS_NAME_INTERNAL-24 "ReceivingSlitBox2-_Axis"
*MEAS_COND_AXIS_NAME_INTERNAL-25 "ReceivingSlitBox2-Zd"
*MEAS_COND_AXIS_NAME_INTERNAL-26 "Attenuator"
*MEAS_COND_AXIS_NAME_INTERNAL-27 "CounterMonochromator"
*MEAS_COND_AXIS_NAME_INTERNAL-28 "CounterSlit"
*MEAS_COND_AXIS_NAME_INTERNAL-29 "IncidentPrimary"
*MEAS_COND_AXIS_NAME_INTERNAL-30 "PHA"
*MEAS_COND_AXIS_NAME_MAGICNO-0 "83951616.0000000000"
*MEAS_COND_AXIS_NAME_MAGICNO-1 "268632064.0000000000"
*MEAS_COND_AXIS_NAME_MAGICNO-2 "268500992.0000000000"
*MEAS_COND_AXIS_NAME_MAGICNO-3 "285278208.0000000000"
*MEAS_COND_AXIS_NAME_MAGICNO-4 "83951616.0000000000"
*MEAS_COND_AXIS_NAME_MAGICNO-5 "131072.0000000000"
*MEAS_COND_AXIS_NAME_MAGICNO-6 "131072.0000000000"
*MEAS_COND_AXIS_NAME_MAGICNO-7 "318898176.0000000000"
*MEAS_COND_AXIS_NAME_MAGICNO-8 "20971521.0000000000"
*MEAS_COND_AXIS_NAME_MAGICNO-9 "285343744.0000000000"
*MEAS_COND_AXIS_NAME_MAGICNO-10 "20971521.0000000000"
*MEAS_COND_AXIS_NAME_MAGICNO-11 "22020097.0000000000"
*MEAS_COND_AXIS_NAME_MAGICNO-12 "25165824.0000000000"
*MEAS_COND_AXIS_NAME_MAGICNO-13 "318898176.0000000000"
*MEAS_COND_AXIS_NAME_MAGICNO-14 "1.0000000000"
*MEAS_COND_AXIS_NAME_MAGICNO-15 "20971521.0000000000"
*MEAS_COND_AXIS_NAME_MAGICNO-16 "20971521.0000000000"
*MEAS_COND_AXIS_NAME_MAGICNO-17 "20971521.0000000000"
*MEAS_COND_AXIS_NAME_MAGICNO-18 "23068673.0000000000"
*MEAS_COND_AXIS_NAME_MAGICNO-19 "23068673.0000000000"
*MEAS_COND_AXIS_NAME_MAGICNO-20 "20971521.0000000000"
*MEAS_COND_AXIS_NAME_MAGICNO-21 "20971521.0000000000"
*MEAS_COND_AXIS_NAME_MAGICNO-22 "20971521.0000000000"
*MEAS_COND_AXIS_NAME_MAGICNO-23 "25165824.0000000000"
*MEAS_COND_AXIS_NAME_MAGICNO-24 "25165824.0000000000"
*MEAS_COND_AXIS_NAME_MAGICNO-25 "285343744.0000000000"
*MEAS_COND_AXIS_NAME_MAGICNO-26 "17301505.0000000000"
*MEAS_COND_AXIS_NAME_MAGICNO-27 "20971521.0000000000"
*MEAS_COND_AXIS_NAME_MAGICNO-28 "20971521.0000000000"
*MEAS_COND_AXIS_NAME_MAGICNO-29 "20971521.0000000000"
*MEAS_COND_AXIS_NAME_MAGICNO-30 "0.0000000000"
*MEAS_COND_AXIS_OFFSET-0 "-"
*MEAS_COND_AXIS_OFFSET-1 "-0.1081000000"
*MEAS_COND_AXIS_OFFSET-2 "0.3758000000"
*MEAS_COND_AXIS_OFFSET-3 "-"
*MEAS_COND_AXIS_OFFSET-4 "-"
*MEAS_COND_AXIS_OFFSET-5 "0.3758000000"
*MEAS_COND_AXIS_OFFSET-6 "-0.4839000000"
*MEAS_COND_AXIS_OFFSET-7 "-"
*MEAS_COND_AXIS_OFFSET-8 "-"
*MEAS_COND_AXIS_OFFSET-9 "-"
*MEAS_COND_AXIS_OFFSET-10 "-"
*MEAS_COND_AXIS_OFFSET-11 "-"
*MEAS_COND_AXIS_OFFSET-12 "-"
*MEAS_COND_AXIS_OFFSET-13 "-"
*MEAS_COND_AXIS_OFFSET-14 "-"
*MEAS_COND_AXIS_OFFSET-15 "-"
*MEAS_COND_AXIS_OFFSET-16 "-"
*MEAS_COND_AXIS_OFFSET-17 "-"
*MEAS_COND_AXIS_OFFSET-18 "-"
*MEAS_COND_AXIS_OFFSET-19 "-"
*MEAS_COND_AXIS_OFFSET-20 "-"
*MEAS_COND_AXIS_OFFSET-21 "-"
*MEAS_COND_AXIS_OFFSET-22 "-"
*MEAS_COND_AXIS_OFFSET-23 "-"
*MEAS_COND_AXIS_OFFSET-24 "-"
*MEAS_COND_AXIS_OFFSET-25 "-"
*MEAS_COND_AXIS_OFFSET-26 "-"
*MEAS_COND_AXIS_OFFSET-27 "-"
*MEAS_COND_AXIS_OFFSET-28 "-"
*MEAS_COND_AXIS_OFFSET-29 "-"
*MEAS_COND_AXIS_OFFSET-30 "-"
*MEAS_COND_AXIS_POSITION-0 "0.0000000000"
*MEAS_COND_AXIS_POSITION-1 "0.0000000000"
*MEAS_COND_AXIS_POSITION-2 "0.0000000000"
*MEAS_COND_AXIS_POSITION-3 "-0.5500000000"
*MEAS_COND_AXIS_POSITION-4 "0.0000000000"
*MEAS_COND_AXIS_POSITION-5 "0.0000000000"
*MEAS_COND_AXIS_POSITION-6 "0.0000000000"
*MEAS_COND_AXIS_POSITION-7 "-0.4278800000"
*MEAS_COND_AXIS_POSITION-8 "BB"
*MEAS_COND_AXIS_POSITION-9 "0.0000000000"
*MEAS_COND_AXIS_POSITION-10 "Soller_slit_5.0deg"
*MEAS_COND_AXIS_POSITION-11 "2/3deg"
*MEAS_COND_AXIS_POSITION-12 "2.2088000000"
*MEAS_COND_AXIS_POSITION-13 "-0.4140600000"
*MEAS_COND_AXIS_POSITION-14 "0.0000000000"
*MEAS_COND_AXIS_POSITION-15 "10.0mm"
*MEAS_COND_AXIS_POSITION-16 "None"
*MEAS_COND_AXIS_POSITION-17 "Cu_K-beta"
*MEAS_COND_AXIS_POSITION-18 "13.000mm"
*MEAS_COND_AXIS_POSITION-19 "13.000mm"
*MEAS_COND_AXIS_POSITION-20 "No_unit"
*MEAS_COND_AXIS_POSITION-21 "Soller_slit_5.0deg"
*MEAS_COND_AXIS_POSITION-22 "None"
*MEAS_COND_AXIS_POSITION-23 "13.0000000000"
*MEAS_COND_AXIS_POSITION-24 "13.0000000000"
*MEAS_COND_AXIS_POSITION-25 "0.0109400000"
*MEAS_COND_AXIS_POSITION-26 "Open"
*MEAS_COND_AXIS_POSITION-27 "None"
*MEAS_COND_AXIS_POSITION-28 "None"
*MEAS_COND_AXIS_POSITION-29 "None"
*MEAS_COND_AXIS_POSITION-30 "38.0000000000"
*MEAS_COND_AXIS_UNIT-0 "deg"
*MEAS_COND_AXIS_UNIT-1 "deg"
*MEAS_COND_AXIS_UNIT-2 "deg"
*MEAS_COND_AXIS_UNIT-3 "mm"
*MEAS_COND_AXIS_UNIT-4 "deg"
*MEAS_COND_AXIS_UNIT-5 "deg"
*MEAS_COND_AXIS_UNIT-6 "deg"
*MEAS_COND_AXIS_UNIT-7 "mm"
*MEAS_COND_AXIS_UNIT-8 ""
*MEAS_COND_AXIS_UNIT-9 "pulse"
*MEAS_COND_AXIS_UNIT-10 ""
*MEAS_COND_AXIS_UNIT-11 ""
*MEAS_COND_AXIS_UNIT-12 "mm"
*MEAS_COND_AXIS_UNIT-13 "mm"
*MEAS_COND_AXIS_UNIT-14 ""
*MEAS_COND_AXIS_UNIT-15 ""
*MEAS_COND_AXIS_UNIT-16 ""
*MEAS_COND_AXIS_UNIT-17 ""
*MEAS_COND_AXIS_UNIT-18 ""
*MEAS_COND_AXIS_UNIT-19 ""
*MEAS_COND_AXIS_UNIT-20 ""
*MEAS_COND_AXIS_UNIT-21 ""
*MEAS_COND_AXIS_UNIT-22 ""
*MEAS_COND_AXIS_UNIT-23 "mm"
*MEAS_COND_AXIS_UNIT-24 "mm"
*MEAS_COND_AXIS_UNIT-25 "mm"
*MEAS_COND_AXIS_UNIT-26 ""
*MEAS_COND_AXIS_UNIT-27 ""
*MEAS_COND_AXIS_UNIT-28 ""
*MEAS_COND_AXIS_UNIT-29 ""
*MEAS_COND_AXIS_UNIT-30 "div"
*MEAS_COND_COUNTER_CNTLOSS_CORR "0.0000000000"
*MEAS_COND_COUNTER_PHABASE "38.0000000000"
*MEAS_COND_COUNTER_PHAWINDOW "16.0000000000"
*MEAS_COND_COUNTER_PHA_UNIT "div"
*MEAS_COND_COUNTER_TAUDIFF "30.0000000000"
*MEAS_COND_COUNTER_TAUINT "0.0000000000"
*MEAS_COND_IRRADIATION_MODE "OFF"
*MEAS_COND_IRRADIATION_WIDTH ""
*MEAS_COND_OPT_ATTR "集中法"
*MEAS_COND_OPT_NAME "@集中法"
*MEAS_COND_UNSYMMETRIC_MODE "OFF"
*MEAS_COND_XG_CURRENT "30.0000000000"
*MEAS_COND_XG_VOLTAGE "40.0000000000"
*MEAS_COND_XG_WAVE_TYPE "Ka"
*MEAS_DATA_COUNT "5001.0000000000"
*MEAS_SCAN_AXIS_X "2θ/θ"
*MEAS_SCAN_AXIS_X_INTERNAL "TwoThetaTheta"
*MEAS_SCAN_END_TIME "06/30/21 14:23:10"
*MEAS_SCAN_MODE "CONTINUOUS"
*MEAS_SCAN_MONITOR "0"
*MEAS_SCAN_RESOLUTION_X "0.0002"
*MEAS_SCAN_SPEED "1.0"
*MEAS_SCAN_SPEED_UNIT "deg/min"
*MEAS_SCAN_START "20.0000000000"
*MEAS_SCAN_START_TIME "06/30/21 13:30:18"
*MEAS_SCAN_STEP "0.0100000000"
*MEAS_SCAN_STOP "70.0000000000"
*MEAS_SCAN_UNIT_X "deg"
*MEAS_SCAN_UNIT_Y "counts"
*RAS_HEADER_END
*RAS_INT_START
20.0000 1645.0000 1.0000
20.0400 1620.0000 1.0000
20.0800 1609.0000 1.0000
20.1200 1532.0000 1.0000
20.1600 1604.0000 1.0000
20.2000 1618.0000 1.0000
20.2400 1602.0000 1.0000
20.2800 1581.0000 1.0000
20.3200 1569.0000 1.0000
20.3600 1583.0000 1.0000
20.4000 1579.0000 1.0000
20.4400 1537.0000 1.0000
20.4800 1524.0000 1.0000
20.5200 1592.0000 1.0000
20.5600 1556.0000 1.0000
20.6000 1579.0000 1.0000
20.6400 1541.0000 1.0000
20.6800 1632.0000 1.0000
20.7200 1507.0000 1.0000
20.7600 1576.0000 1.0000
20.8000 1534.0000 1.0000
20.8400 1555.0000 1.0000
20.8800 1645.0000 1.0000
20.9200 1541.0000 1.0000
20.9600 1510.0000 1.0000
21.0000 1568.0000 1.0000
21.0400 1546.0000 1.0000
21.0800 1565.0000 1.0000
21.1200 1579.0000 1.0000
21.1600 1588.0000 1.0000
21.2000 1582.0000 1.0000
21.2400 1539.0000 1.0000
21.2800 1548.0000 1.0000
21.3200 1563.0000 1.0000
21.3600 1593.0000 1.0000
21.4000 1577.0000 1.0000
21.4400 1503.0000 1.0000
21.4800 1591.0000 1.0000
21.5200 1582.0000 1.0000
21.5600 1552.0000 1.0000
21.6000 1535.0000 1.0000
21.6400 1615.0000 1.0000
21.6800 1588.0000 1.0000
21.7200 1606.0000 1.0000
21.7600 1614.0000 1.0000
21.8000 1546.0000 1.0000
21.8400 1585.0000 1.0000
21.8800 1599.0000 1.0000
21.9200 1578.0000 1.0000
21.9600 1566.0000 1.0000
22.0000 1596.0000 1.0000
22.0400 1566.0000 1.0000
22.0800 1554.0000 1.0000
22.1200 1570.0000 1.0000
22.1600 1539.0000 1.0000
22.2000 1561.0000 1.0000
22.2400 1542.0000 1.0000
22.2800 1551.0000 1.0000
22.3200 1637.0000 1.0000
22.3600 1592.0000 1.0000
22.4000 1632.0000 1.0000
22.4400 1577.0000 1.0000
22.4800 1604.0000 1.0000
22.5200 1641.0000 1.0000
22.5600 1607.0000 1.0000
22.6000 1589.0000 1.0000
22.6400 1565.0000 1.0000
22.6800 1633.0000 1.0000
22.7200 1554.0000 1.0000
22.7600 1588.0000 1.0000
22.8000 1596.0000 1.0000
22.8400 1542.0000 1.0000
22.8800 1632.0000 1.0000
22.9200 1589.0000 1.0000
22.9600 1573.0000 1.0000
23.0000 1594.0000 1.0000
23.0400 1579.0000 1.0000
23.0800 1549.0000 1.0000
23.1200 1612.0000 1.0000
23.1600 1616.0000 1.0000
23.2000 1567.0000 1.0000
23.2400 1628.0000 1.0000
23.2800 1618.0000 1.0000
23.3200 1592.0000 1.0000
23.3600 1581.0000 1.0000
23.4000 1594.0000 1.0000
23.4400 1595.0000 1.0000
23.4800 1608.0000 1.0000
23.5200 1608.0000 1.0000
23.5600 1656.0000 1.0000
23.6000 1610.0000 1.0000
23.6400 1530.0000 1.0000
23.6800 1652.0000 1.0000
23.7200 1582.0000 1.0000
23.7600 1657.0000 1.0000
23.8000 1575.0000 1.0000
23.8400 1568.0000 1.0000
23.8800 1601.0000 1.0000
23.9200 1586.0000 1.0000
23.9600 1641.0000 1.0000
24.0000 1615.0000 1.0000
24.0400 1583.0000 1.0000
24.0800 1623.0000 1.0000
24.1200 1639.0000 1.0000
24.1600 1673.0000 1.0000
24.2000 1563.0000 1.0000
24.2400 1581.0000 1.0000
24.2800 1606.0000 1.0000
24.3200 1537.0000 1.0000
24.3600 1568.0000 1.0000
24.4000 1612.0000 1.0000
24.4400 1700.0000 1.0000
24.4800 1617.0000 1.0000
24.5200 1637.0000 1.0000
24.5600 1536.0000 1.0000
24.6000 1570.0000 1.0000
24.6400 1664.0000 1.0000
24.6800 1678.0000 1.0000
24.7200 1628.0000 1.0000
24.7600 1614.0000 1.0000
24.8000 1607.0000 1.0000
24.8400 1645.0000 1.0000
24.8800 1669.0000 1.0000
24.9200 1719.0000 1.0000
24.9600 1709.0000 1.0000
25.0000 1718.0000 1.0000
25.0400 1727.0000 1.0000
25.0800 1676.0000 1.0000
25.1200 1679.0000 1.0000
25.1600 1696.0000 1.0000
25.2000 1657.0000 1.0000
25.2400 1659.0000 1.0000
25.2800 1594.0000 1.0000
25.3200 1642.0000 1.0000
25.3600 1693.0000 1.0000
25.4000 1678.0000 1.0000
25.4400 1668.0000 1.0000
25.4800 1663.0000 1.0000
25.5200 1630.0000 1.0000
25.5600 1649.0000 1.0000
25.6000 1688.0000 1.0000
25.6400 1636.0000 1.0000
25.6800 1630.0000 1.0000
25.7200 1694.0000 1.0000
25.7600 1623.0000 1.0000
25.8000 1668.0000 1.0000
25.8400 1612.0000 1.0000
25.8800 1583.0000 1.0000
25.9200 1649.0000 1.0000
25.9600 1648.0000 1.0000
26.0000 1661.0000 1.0000
26.0400 1638.0000 1.0000
26.0800 1706.0000 1.0000
26.1200 1622.0000 1.0000
26.1600 1599.0000 1.0000
26.2000 1680.0000 1.0000
26.2400 1628.0000 1.0000
26.2800 1752.0000 1.0000
26.3200 1681.0000 1.0000
26.3600 1694.0000 1.0000
26.4000 1637.0000 1.0000
26.4400 1749.0000 1.0000
26.4800 1764.0000 1.0000
26.5200 1699.0000 1.0000
26.5600 1791.0000 1.0000
26.6000 1752.0000 1.0000
26.6400 1809.0000 1.0000
26.6800 1677.0000 1.0000
26.7200 1815.0000 1.0000
26.7600 1788.0000 1.0000
26.8000 1818.0000 1.0000
26.8400 1804.0000 1.0000
26.8800 1830.0000 1.0000
26.9200 1891.0000 1.0000
26.9600 1939.0000 1.0000
27.0000 2095.0000 1.0000
27.0400 2162.0000 1.0000
27.0800 2272.0000 1.0000
27.1200 2540.0000 1.0000
27.1600 2830.0000 1.0000
27.2000 3295.0000 1.0000
27.2400 3925.0000 1.0000
27.2800 4876.0000 1.0000
27.3200 5826.0000 1.0000
27.3600 6274.0000 1.0000
27.4000 5912.0000 1.0000
27.4400 5025.0000 1.0000
27.4800 4044.0000 1.0000
27.5200 3415.0000 1.0000
27.5600 2891.0000 1.0000
27.6000 2543.0000 1.0000
27.6400 2448.0000 1.0000
27.6800 2237.0000 1.0000
27.7200 1986.0000 1.0000
27.7600 2045.0000 1.0000
27.8000 1836.0000 1.0000
27.8400 1846.0000 1.0000
27.8800 1826.0000 1.0000
27.9200 1832.0000 1.0000
27.9600 1733.0000 1.0000
28.0000 1752.0000 1.0000
28.0400 1744.0000 1.0000
28.0800 1702.0000 1.0000
28.1200 1732.0000 1.0000
28.1600 1704.0000 1.0000
28.2000 1706.0000 1.0000
28.2400 1749.0000 1.0000
28.2800 1595.0000 1.0000
28.3200 1657.0000 1.0000
28.3600 1647.0000 1.0000
28.4000 1667.0000 1.0000
28.4400 1689.0000 1.0000
28.4800 1658.0000 1.0000
28.5200 1649.0000 1.0000
28.5600 1611.0000 1.0000
28.6000 1674.0000 1.0000
28.6400 1651.0000 1.0000
28.6800 1556.0000 1.0000
28.7200 1595.0000 1.0000
28.7600 1654.0000 1.0000
28.8000 1671.0000 1.0000
28.8400 1579.0000 1.0000
28.8800 1589.0000 1.0000
28.9200 1572.0000 1.0000
28.9600 1564.0000 1.0000
29.0000 1616.0000 1.0000
29.0400 1601.0000 1.0000
29.0800 1606.0000 1.0000
29.1200 1641.0000 1.0000
29.1600 1643.0000 1.0000
29.2000 1559.0000 1.0000
29.2400 1563.0000 1.0000
29.2800 1554.0000 1.0000
29.3200 1522.0000 1.0000
29.3600 1608.0000 1.0000
29.4000 1622.0000 1.0000
29.4400 1533.0000 1.0000
29.4800 1587.0000 1.0000
29.5200 1531.0000 1.0000
29.5600 1542.0000 1.0000
29.6000 1651.0000 1.0000
29.6400 1568.0000 1.0000
29.6800 1538.0000 1.0000
29.7200 1626.0000 1.0000
29.7600 1552.0000 1.0000
29.8000 1605.0000 1.0000
29.8400 1556.0000 1.0000
29.8800 1552.0000 1.0000
29.9200 1592.0000 1.0000
29.9600 1613.0000 1.0000
30.0000 1551.0000 1.0000
30.0400 1601.0000 1.0000
30.0800 1554.0000 1.0000
30.1200 1554.0000 1.0000
30.1600 1555.0000 1.0000
30.2000 1535.0000 1.0000
30.2400 1554.0000 1.0000
30.2800 1549.0000 1.0000
30.3200 1512.0000 1.0000
30.3600 1554.0000 1.0000
30.4000 1588.0000 1.0000
30.4400 1488.0000 1.0000
30.4800 1533.0000 1.0000
30.5200 1511.0000 1.0000
30.5600 1507.0000 1.0000
30.6000 1546.0000 1.0000
30.6400 1470.0000 1.0000
30.6800 1510.0000 1.0000
30.7200 1557.0000 1.0000
30.7600 1529.0000 1.0000
30.8000 1562.0000 1.0000
30.8400 1541.0000 1.0000
30.8800 1550.0000 1.0000
30.9200 1480.0000 1.0000
30.9600 1522.0000 1.0000
31.0000 1515.0000 1.0000
31.0400 1505.0000 1.0000
31.0800 1515.0000 1.0000
31.1200 1514.0000 1.0000
31.1600 1501.0000 1.0000
31.2000 1469.0000 1.0000
31.2400 1531.0000 1.0000
31.2800 1567.0000 1.0000
31.3200 1511.0000 1.0000
31.3600 1531.0000 1.0000
31.4000 1496.0000 1.0000
31.4400 1448.0000 1.0000
31.4800 1511.0000 1.0000
31.5200 1541.0000 1.0000
31.5600 1482.0000 1.0000
31.6000 1419.0000 1.0000
31.6400 1468.0000 1.0000
31.6800 1461.0000 1.0000
31.7200 1469.0000 1.0000
31.7600 1459.0000 1.0000
31.8000 1495.0000 1.0000
31.8400 1430.0000 1.0000
31.8800 1463.0000 1.0000
31.9200 1431.0000 1.0000
31.9600 1470.0000 1.0000
32.0000 1482.0000 1.0000
32.0400 1502.0000 1.0000
32.0800 1508.0000 1.0000
32.1200 1496.0000 1.0000
32.1600 1495.0000 1.0000
32.2000 1472.0000 1.0000
32.2400 1499.0000 1.0000
32.2800 1496.0000 1.0000
32.3200 1433.0000 1.0000
32.3600 1448.0000 1.0000
32.4000 1383.0000 1.0000
32.4400 1432.0000 1.0000
32.4800 1440.0000 1.0000
32.5200 1443.0000 1.0000
32.5600 1461.0000 1.0000
32.6000 1406.0000 1.0000
32.6400 1434.0000 1.0000
32.6800 1435.0000 1.0000
32.7200 1331.0000 1.0000
32.7600 1356.0000 1.0000
32.8000 1424.0000 1.0000
32.8400 1408.0000 1.0000
32.8800 1413.0000 1.0000
32.9200 1411.0000 1.0000
32.9600 1441.0000 1.0000
33.0000 1368.0000 1.0000
33.0400 1411.0000 1.0000
33.0800 1450.0000 1.0000
33.1200 1386.0000 1.0000
33.1600 1433.0000 1.0000
33.2000 1436.0000 1.0000
33.2400 1426.0000 1.0000
33.2800 1371.0000 1.0000
33.3200 1405.0000 1.0000
33.3600 1411.0000 1.0000
33.4000 1379.0000 1.0000
33.4400 1393.0000 1.0000
33.4800 1419.0000 1.0000
33.5200 1392.0000 1.0000
33.5600 1395.0000 1.0000
33.6000 1489.0000 1.0000
33.6400 1352.0000 1.0000
33.6800 1426.0000 1.0000
33.7200 1435.0000 1.0000
33.7600 1393.0000 1.0000
33.8000 1460.0000 1.0000
33.8400 1493.0000 1.0000
33.8800 1503.0000 1.0000
33.9200 1585.0000 1.0000
33.9600 1683.0000 1.0000
34.0000 1644.0000 1.0000
34.0400 1577.0000 1.0000
34.0800 1535.0000 1.0000
34.1200 1663.0000 1.0000
34.1600 1553.0000 1.0000
34.2000 1570.0000 1.0000
34.2400 1557.0000 1.0000
34.2800 1658.0000 1.0000
34.3200 1738.0000 1.0000
34.3600 1855.0000 1.0000
34.4000 2053.0000 1.0000
34.4400 2451.0000 1.0000
34.4800 2771.0000 1.0000
34.5200 3145.0000 1.0000
34.5600 3166.0000 1.0000
34.6000 3105.0000 1.0000
34.6400 2805.0000 1.0000
34.6800 2430.0000 1.0000
34.7200 2160.0000 1.0000
34.7600 1898.0000 1.0000
34.8000 1727.0000 1.0000
34.8400 1724.0000 1.0000
34.8800 1609.0000 1.0000
34.9200 1549.0000 1.0000
34.9600 1507.0000 1.0000
35.0000 1433.0000 1.0000
35.0400 1387.0000 1.0000
35.0800 1359.0000 1.0000
35.1200 1337.0000 1.0000
35.1600 1306.0000 1.0000
35.2000 1330.0000 1.0000
35.2400 1279.0000 1.0000
35.2800 1302.0000 1.0000
35.3200 1235.0000 1.0000
35.3600 1285.0000 1.0000
35.4000 1225.0000 1.0000
35.4400 1268.0000 1.0000
35.4800 1276.0000 1.0000
35.5200 1253.0000 1.0000
35.5600 1246.0000 1.0000
35.6000 1212.0000 1.0000
35.6400 1235.0000 1.0000
35.6800 1172.0000 1.0000
35.7200 1219.0000 1.0000
35.7600 1209.0000 1.0000
35.8000 1202.0000 1.0000
35.8400 1277.0000 1.0000
35.8800 1201.0000 1.0000
35.9200 1197.0000 1.0000
35.9600 1215.0000 1.0000
36.0000 1140.0000 1.0000
36.0400 1220.0000 1.0000
36.0800 1198.0000 1.0000
36.1200 1172.0000 1.0000
36.1600 1262.0000 1.0000
36.2000 1276.0000 1.0000
36.2400 1323.0000 1.0000
36.2800 1403.0000 1.0000
36.3200 1412.0000 1.0000
36.3600 1608.0000 1.0000
36.4000 1876.0000 1.0000
36.4400 2048.0000 1.0000
36.4800 2134.0000 1.0000
36.5200 1947.0000 1.0000
36.5600 1751.0000 1.0000
36.6000 1614.0000 1.0000
36.6400 1477.0000 1.0000
36.6800 1341.0000 1.0000
36.7200 1247.0000 1.0000
36.7600 1238.0000 1.0000
36.8000 1116.0000 1.0000
36.8400 1112.0000 1.0000
36.8800 1155.0000 1.0000
36.9200 1145.0000 1.0000
36.9600 1111.0000 1.0000
37.0000 1165.0000 1.0000
37.0400 1100.0000 1.0000
37.0800 1104.0000 1.0000
37.1200 1108.0000 1.0000
37.1600 1130.0000 1.0000
37.2000 1076.0000 1.0000
37.2400 1075.0000 1.0000
37.2800 1123.0000 1.0000
37.3200 1094.0000 1.0000
37.3600 1105.0000 1.0000
37.4000 1149.0000 1.0000
37.4400 1082.0000 1.0000
37.4800 1113.0000 1.0000
37.5200 1077.0000 1.0000
37.5600 1124.0000 1.0000
37.6000 1091.0000 1.0000
37.6400 1133.0000 1.0000
37.6800 1149.0000 1.0000
37.7200 1061.0000 1.0000
37.7600 1071.0000 1.0000
37.8000 1102.0000 1.0000
37.8400 1165.0000 1.0000
37.8800 1163.0000 1.0000
37.9200 1167.0000 1.0000
37.9600 1168.0000 1.0000
38.0000 1113.0000 1.0000
38.0400 1184.0000 1.0000
38.0800 1182.0000 1.0000
38.1200 1219.0000 1.0000
38.1600 1296.0000 1.0000
38.2000 1297.0000 1.0000
38.2400 1422.0000 1.0000
38.2800 1616.0000 1.0000
38.3200 1788.0000 1.0000
38.3600 2066.0000 1.0000
38.4000 2444.0000 1.0000
38.4400 3083.0000 1.0000
38.4800 4008.0000 1.0000
38.5200 5357.0000 1.0000
38.5600 6576.0000 1.0000
38.6000 7415.0000 1.0000
38.6400 7155.0000 1.0000
38.6800 6400.0000 1.0000
38.7200 5098.0000 1.0000
38.7600 4043.0000 1.0000
38.8000 3099.0000 1.0000
38.8400 2376.0000 1.0000
38.8800 1977.0000 1.0000
38.9200 1663.0000 1.0000
38.9600 1456.0000 1.0000
39.0000 1310.0000 1.0000
39.0400 1213.0000 1.0000
39.0800 1226.0000 1.0000
39.1200 1163.0000 1.0000
39.1600 1085.0000 1.0000
39.2000 1092.0000 1.0000
39.2400 1082.0000 1.0000
39.2800 1059.0000 1.0000
39.3200 1016.0000 1.0000
39.3600 1039.0000 1.0000
39.4000 1038.0000 1.0000
39.4400 1057.0000 1.0000
39.4800 1053.0000 1.0000
39.5200 1020.0000 1.0000
39.5600 1013.0000 1.0000
39.6000 1076.0000 1.0000
39.6400 1077.0000 1.0000
39.6800 1044.0000 1.0000
39.7200 1057.0000 1.0000
39.7600 1068.0000 1.0000
39.8000 1021.0000 1.0000
39.8400 1035.0000 1.0000
39.8800 983.0000 1.0000
39.9200 967.0000 1.0000
39.9600 929.0000 1.0000
40.0000 934.0000 1.0000
40.0400 976.0000 1.0000
40.0800 924.0000 1.0000
40.1200 941.0000 1.0000
40.1600 943.0000 1.0000
40.2000 949.0000 1.0000
40.2400 931.0000 1.0000
40.2800 972.0000 1.0000
40.3200 925.0000 1.0000
40.3600 930.0000 1.0000
40.4000 900.0000 1.0000
40.4400 912.0000 1.0000
40.4800 868.0000 1.0000
40.5200 914.0000 1.0000
40.5600 899.0000 1.0000
40.6000 916.0000 1.0000
40.6400 922.0000 1.0000
40.6800 990.0000 1.0000
40.7200 920.0000 1.0000
40.7600 921.0000 1.0000
40.8000 933.0000 1.0000
40.8400 1004.0000 1.0000
40.8800 924.0000 1.0000
40.9200 913.0000 1.0000
40.9600 918.0000 1.0000
41.0000 897.0000 1.0000
41.0400 928.0000 1.0000
41.0800 916.0000 1.0000
41.1200 890.0000 1.0000
41.1600 885.0000 1.0000
41.2000 922.0000 1.0000
41.2400 901.0000 1.0000
41.2800 916.0000 1.0000
41.3200 921.0000 1.0000
41.3600 925.0000 1.0000
41.4000 896.0000 1.0000
41.4400 957.0000 1.0000
41.4800 843.0000 1.0000
41.5200 895.0000 1.0000
41.5600 891.0000 1.0000
41.6000 917.0000 1.0000
41.6400 946.0000 1.0000
41.6800 992.0000 1.0000
41.7200 951.0000 1.0000
41.7600 936.0000 1.0000
41.8000 893.0000 1.0000
41.8400 886.0000 1.0000
41.8800 885.0000 1.0000
41.9200 937.0000 1.0000
41.9600 931.0000 1.0000
42.0000 910.0000 1.0000
42.0400 892.0000 1.0000
42.0800 930.0000 1.0000
42.1200 902.0000 1.0000
42.1600 920.0000 1.0000
42.2000 871.0000 1.0000
42.2400 826.0000 1.0000
42.2800 876.0000 1.0000
42.3200 877.0000 1.0000
42.3600 893.0000 1.0000
42.4000 832.0000 1.0000
42.4400 926.0000 1.0000
42.4800 878.0000 1.0000
42.5200 865.0000 1.0000
42.5600 855.0000 1.0000
42.6000 836.0000 1.0000
42.6400 887.0000 1.0000
42.6800 922.0000 1.0000
42.7200 918.0000 1.0000
42.7600 905.0000 1.0000
42.8000 889.0000 1.0000
42.8400 918.0000 1.0000
42.8800 913.0000 1.0000
42.9200 897.0000 1.0000
42.9600 849.0000 1.0000
43.0000 879.0000 1.0000
43.0400 872.0000 1.0000
43.0800 919.0000 1.0000
43.1200 888.0000 1.0000
43.1600 938.0000 1.0000
43.2000 917.0000 1.0000
43.2400 967.0000 1.0000
43.2800 987.0000 1.0000
43.3200 985.0000 1.0000
43.3600 981.0000 1.0000
43.4000 950.0000 1.0000
43.4400 928.0000 1.0000
43.4800 950.0000 1.0000
43.5200 892.0000 1.0000
43.5600 842.0000 1.0000
43.6000 904.0000 1.0000
43.6400 829.0000 1.0000
43.6800 877.0000 1.0000
43.7200 843.0000 1.0000
43.7600 934.0000 1.0000
43.8000 901.0000 1.0000
43.8400 874.0000 1.0000
43.8800 868.0000 1.0000
43.9200 847.0000 1.0000
43.9600 851.0000 1.0000
44.0000 845.0000 1.0000
44.0400 859.0000 1.0000
44.0800 867.0000 1.0000
44.1200 901.0000 1.0000
44.1600 855.0000 1.0000
44.2000 857.0000 1.0000
44.2400 869.0000 1.0000
44.2800 886.0000 1.0000
44.3200 901.0000 1.0000
44.3600 861.0000 1.0000
44.4000 912.0000 1.0000
44.4400 849.0000 1.0000
44.4800 921.0000 1.0000
44.5200 909.0000 1.0000
44.5600 853.0000 1.0000
44.6000 845.0000 1.0000
44.6400 797.0000 1.0000
44.6800 887.0000 1.0000
44.7200 794.0000 1.0000
44.7600 884.0000 1.0000
44.8000 848.0000 1.0000
44.8400 815.0000 1.0000
44.8800 792.0000 1.0000
44.9200 877.0000 1.0000
44.9600 865.0000 1.0000
45.0000 808.0000 1.0000
45.0400 860.0000 1.0000
45.0800 821.0000 1.0000
45.1200 833.0000 1.0000
45.1600 855.0000 1.0000
45.2000 864.0000 1.0000
45.2400 804.0000 1.0000
45.2800 840.0000 1.0000
45.3200 822.0000 1.0000
45.3600 799.0000 1.0000
45.4000 831.0000 1.0000
45.4400 833.0000 1.0000
45.4800 856.0000 1.0000
45.5200 780.0000 1.0000
45.5600 860.0000 1.0000
45.6000 837.0000 1.0000
45.6400 864.0000 1.0000
45.6800 860.0000 1.0000
45.7200 800.0000 1.0000
45.7600 826.0000 1.0000
45.8000 803.0000 1.0000
45.8400 815.0000 1.0000
45.8800 819.0000 1.0000
45.9200 845.0000 1.0000
45.9600 816.0000 1.0000
46.0000 831.0000 1.0000
46.0400 778.0000 1.0000
46.0800 817.0000 1.0000
46.1200 833.0000 1.0000
46.1600 813.0000 1.0000
46.2000 817.0000 1.0000
46.2400 821.0000 1.0000
46.2800 777.0000 1.0000
46.3200 820.0000 1.0000
46.3600 789.0000 1.0000
46.4000 806.0000 1.0000
46.4400 821.0000 1.0000
46.4800 822.0000 1.0000
46.5200 751.0000 1.0000
46.5600 751.0000 1.0000
46.6000 832.0000 1.0000
46.6400 821.0000 1.0000
46.6800 751.0000 1.0000
46.7200 821.0000 1.0000
46.7600 778.0000 1.0000
46.8000 818.0000 1.0000
46.8400 816.0000 1.0000
46.8800 763.0000 1.0000
46.9200 781.0000 1.0000
46.9600 806.0000 1.0000
47.0000 792.0000 1.0000
47.0400 839.0000 1.0000
47.0800 864.0000 1.0000
47.1200 803.0000 1.0000
47.1600 813.0000 1.0000
47.2000 810.0000 1.0000
47.2400 860.0000 1.0000
47.2800 827.0000 1.0000
47.3200 789.0000 1.0000
47.3600 782.0000 1.0000
47.4000 810.0000 1.0000
47.4400 801.0000 1.0000
47.4800 818.0000 1.0000
47.5200 764.0000 1.0000
47.5600 774.0000 1.0000
47.6000 778.0000 1.0000
47.6400 774.0000 1.0000
47.6800 779.0000 1.0000
47.7200 801.0000 1.0000
47.7600 764.0000 1.0000
47.8000 811.0000 1.0000
47.8400 772.0000 1.0000
47.8800 803.0000 1.0000
47.9200 767.0000 1.0000
47.9600 770.0000 1.0000
48.0000 789.0000 1.0000
48.0400 733.0000 1.0000
48.0800 767.0000 1.0000
48.1200 817.0000 1.0000
48.1600 794.0000 1.0000
48.2000 764.0000 1.0000
48.2400 757.0000 1.0000
48.2800 774.0000 1.0000
48.3200 731.0000 1.0000
48.3600 722.0000 1.0000
48.4000 745.0000 1.0000
48.4400 745.0000 1.0000
48.4800 785.0000 1.0000
48.5200 762.0000 1.0000
48.5600 785.0000 1.0000
48.6000 730.0000 1.0000
48.6400 774.0000 1.0000
48.6800 765.0000 1.0000
48.7200 709.0000 1.0000
48.7600 715.0000 1.0000
48.8000 780.0000 1.0000
48.8400 756.0000 1.0000
48.8800 724.0000 1.0000
48.9200 725.0000 1.0000
48.9600 800.0000 1.0000
49.0000 749.0000 1.0000
49.0400 702.0000 1.0000
49.0800 765.0000 1.0000
49.1200 764.0000 1.0000
49.1600 780.0000 1.0000
49.2000 774.0000 1.0000
49.2400 752.0000 1.0000
49.2800 731.0000 1.0000
49.3200 693.0000 1.0000
49.3600 783.0000 1.0000
49.4000 749.0000 1.0000
49.4400 744.0000 1.0000
49.4800 739.0000 1.0000
49.5200 732.0000 1.0000
49.5600 777.0000 1.0000
49.6000 760.0000 1.0000
49.6400 733.0000 1.0000
49.6800 733.0000 1.0000
49.7200 776.0000 1.0000
49.7600 772.0000 1.0000
49.8000 787.0000 1.0000
49.8400 729.0000 1.0000
49.8800 711.0000 1.0000
49.9200 738.0000 1.0000
49.9600 714.0000 1.0000
50.0000 765.0000 1.0000
50.0400 745.0000 1.0000
50.0800 761.0000 1.0000
50.1200 732.0000 1.0000
50.1600 765.0000 1.0000
50.2000 794.0000 1.0000
50.2400 782.0000 1.0000
50.2800 731.0000 1.0000
50.3200 810.0000 1.0000
50.3600 835.0000 1.0000
50.4000 778.0000 1.0000
50.4400 827.0000 1.0000
50.4800 776.0000 1.0000
50.5200 757.0000 1.0000
50.5600 773.0000 1.0000
50.6000 757.0000 1.0000
50.6400 748.0000 1.0000
50.6800 759.0000 1.0000
50.7200 746.0000 1.0000
50.7600 779.0000 1.0000
50.8000 727.0000 1.0000
50.8400 746.0000 1.0000
50.8800 801.0000 1.0000
50.9200 772.0000 1.0000
50.9600 765.0000 1.0000
51.0000 805.0000 1.0000
51.0400 776.0000 1.0000
51.0800 764.0000 1.0000
51.1200 735.0000 1.0000
51.1600 775.0000 1.0000
51.2000 745.0000 1.0000
51.2400 749.0000 1.0000
51.2800 738.0000 1.0000
51.3200 771.0000 1.0000
51.3600 824.0000 1.0000
51.4000 750.0000 1.0000
51.4400 769.0000 1.0000
51.4800 765.0000 1.0000
51.5200 843.0000 1.0000
51.5600 828.0000 1.0000
51.6000 751.0000 1.0000
51.6400 832.0000 1.0000
51.6800 785.0000 1.0000
51.7200 772.0000 1.0000
51.7600 777.0000 1.0000
51.8000 804.0000 1.0000
51.8400 824.0000 1.0000
51.8800 882.0000 1.0000
51.9200 909.0000 1.0000
51.9600 952.0000 1.0000
52.0000 1030.0000 1.0000
52.0400 1108.0000 1.0000
52.0800 1294.0000 1.0000
52.1200 1515.0000 1.0000
52.1600 1829.0000 1.0000
52.2000 2358.0000 1.0000
52.2400 3217.0000 1.0000
52.2800 4316.0000 1.0000
52.3200 5326.0000 1.0000
52.3600 5170.0000 1.0000
52.4000 4541.0000 1.0000
52.4400 4011.0000 1.0000
52.4800 3640.0000 1.0000
52.5200 2877.0000 1.0000
52.5600 2175.0000 1.0000
52.6000 1685.0000 1.0000
52.6400 1457.0000 1.0000
52.6800 1243.0000 1.0000
52.7200 1149.0000 1.0000
52.7600 1031.0000 1.0000
52.8000 943.0000 1.0000
52.8400 866.0000 1.0000
52.8800 898.0000 1.0000
52.9200 841.0000 1.0000
52.9600 824.0000 1.0000
53.0000 815.0000 1.0000
53.0400 817.0000 1.0000
53.0800 811.0000 1.0000
53.1200 787.0000 1.0000
53.1600 784.0000 1.0000
53.2000 790.0000 1.0000
53.2400 812.0000 1.0000
53.2800 752.0000 1.0000
53.3200 766.0000 1.0000
53.3600 762.0000 1.0000
53.4000 773.0000 1.0000
53.4400 771.0000 1.0000
53.4800 771.0000 1.0000
53.5200 755.0000 1.0000
53.5600 731.0000 1.0000
53.6000 776.0000 1.0000
53.6400 734.0000 1.0000
53.6800 765.0000 1.0000
53.7200 736.0000 1.0000
53.7600 720.0000 1.0000
53.8000 747.0000 1.0000
53.8400 736.0000 1.0000
53.8800 732.0000 1.0000
53.9200 724.0000 1.0000
53.9600 760.0000 1.0000
54.0000 773.0000 1.0000
54.0400 758.0000 1.0000
54.0800 766.0000 1.0000
54.1200 739.0000 1.0000
54.1600 787.0000 1.0000
54.2000 728.0000 1.0000
54.2400 773.0000 1.0000
54.2800 777.0000 1.0000
54.3200 733.0000 1.0000
54.3600 752.0000 1.0000
54.4000 751.0000 1.0000
54.4400 747.0000 1.0000
54.4800 779.0000 1.0000
54.5200 758.0000 1.0000
54.5600 768.0000 1.0000
54.6000 776.0000 1.0000
54.6400 749.0000 1.0000
54.6800 735.0000 1.0000
54.7200 825.0000 1.0000
54.7600 796.0000 1.0000
54.8000 752.0000 1.0000
54.8400 815.0000 1.0000
54.8800 797.0000 1.0000
54.9200 801.0000 1.0000
54.9600 839.0000 1.0000
55.0000 802.0000 1.0000
55.0400 841.0000 1.0000
55.0800 822.0000 1.0000
55.1200 824.0000 1.0000
55.1600 877.0000 1.0000
55.2000 980.0000 1.0000
55.2400 959.0000 1.0000
55.2800 1028.0000 1.0000
55.3200 1143.0000 1.0000
55.3600 1122.0000 1.0000
55.4000 1055.0000 1.0000
55.4400 1060.0000 1.0000
55.4800 1053.0000 1.0000
55.5200 945.0000 1.0000
55.5600 926.0000 1.0000
55.6000 912.0000 1.0000
55.6400 866.0000 1.0000
55.6800 803.0000 1.0000
55.7200 800.0000 1.0000
55.7600 781.0000 1.0000
55.8000 730.0000 1.0000
55.8400 775.0000 1.0000
55.8800 705.0000 1.0000
55.9200 781.0000 1.0000
55.9600 723.0000 1.0000
56.0000 743.0000 1.0000
56.0400 780.0000 1.0000
56.0800 755.0000 1.0000
56.1200 763.0000 1.0000
56.1600 717.0000 1.0000
56.2000 732.0000 1.0000
56.2400 720.0000 1.0000
56.2800 699.0000 1.0000
56.3200 717.0000 1.0000
56.3600 680.0000 1.0000
56.4000 675.0000 1.0000
56.4400 721.0000 1.0000
56.4800 688.0000 1.0000
56.5200 773.0000 1.0000
56.5600 696.0000 1.0000
56.6000 735.0000 1.0000
56.6400 729.0000 1.0000
56.6800 686.0000 1.0000
56.7200 722.0000 1.0000
56.7600 673.0000 1.0000
56.8000 735.0000 1.0000
56.8400 694.0000 1.0000
56.8800 711.0000 1.0000
56.9200 686.0000 1.0000
56.9600 699.0000 1.0000
57.0000 674.0000 1.0000
57.0400 699.0000 1.0000
57.0800 679.0000 1.0000
57.1200 693.0000 1.0000
57.1600 680.0000 1.0000
57.2000 735.0000 1.0000
57.2400 711.0000 1.0000
57.2800 767.0000 1.0000
57.3200 720.0000 1.0000
57.3600 745.0000 1.0000
57.4000 702.0000 1.0000
57.4400 716.0000 1.0000
57.4800 734.0000 1.0000
57.5200 710.0000 1.0000
57.5600 728.0000 1.0000
57.6000 693.0000 1.0000
57.6400 713.0000 1.0000
57.6800 736.0000 1.0000
57.7200 677.0000 1.0000
57.7600 683.0000 1.0000
57.8000 733.0000 1.0000
57.8400 717.0000 1.0000
57.8800 699.0000 1.0000
57.9200 791.0000 1.0000
57.9600 699.0000 1.0000
58.0000 725.0000 1.0000
58.0400 752.0000 1.0000
58.0800 712.0000 1.0000
58.1200 701.0000 1.0000
58.1600 710.0000 1.0000
58.2000 748.0000 1.0000
58.2400 732.0000 1.0000
58.2800 775.0000 1.0000
58.3200 716.0000 1.0000
58.3600 686.0000 1.0000
58.4000 704.0000 1.0000
58.4400 743.0000 1.0000
58.4800 681.0000 1.0000
58.5200 743.0000 1.0000
58.5600 697.0000 1.0000
58.6000 681.0000 1.0000
58.6400 710.0000 1.0000
58.6800 690.0000 1.0000
58.7200 692.0000 1.0000
58.7600 686.0000 1.0000
58.8000 727.0000 1.0000
58.8400 709.0000 1.0000
58.8800 691.0000 1.0000
58.9200 714.0000 1.0000
58.9600 692.0000 1.0000
59.0000 747.0000 1.0000
59.0400 716.0000 1.0000
59.0800 687.0000 1.0000
59.1200 688.0000 1.0000
59.1600 706.0000 1.0000
59.2000 716.0000 1.0000
59.2400 751.0000 1.0000
59.2800 715.0000 1.0000
59.3200 689.0000 1.0000
59.3600 712.0000 1.0000
59.4000 705.0000 1.0000
59.4400 755.0000 1.0000
59.4800 708.0000 1.0000
59.5200 723.0000 1.0000
59.5600 690.0000 1.0000
59.6000 723.0000 1.0000
59.6400 697.0000 1.0000
59.6800 694.0000 1.0000
59.7200 736.0000 1.0000
59.7600 711.0000 1.0000
59.8000 703.0000 1.0000
59.8400 740.0000 1.0000
59.8800 665.0000 1.0000
59.9200 662.0000 1.0000
59.9600 683.0000 1.0000
60.0000 703.0000 1.0000
60.0400 767.0000 1.0000
60.0800 731.0000 1.0000
60.1200 734.0000 1.0000
60.1600 750.0000 1.0000
60.2000 705.0000 1.0000
60.2400 695.0000 1.0000
60.2800 697.0000 1.0000
60.3200 704.0000 1.0000
60.3600 738.0000 1.0000
60.4000 674.0000 1.0000
60.4400 692.0000 1.0000
60.4800 705.0000 1.0000
60.5200 698.0000 1.0000
60.5600 690.0000 1.0000
60.6000 690.0000 1.0000
60.6400 714.0000 1.0000
60.6800 723.0000 1.0000
60.7200 768.0000 1.0000
60.7600 712.0000 1.0000
60.8000 721.0000 1.0000
60.8400 688.0000 1.0000
60.8800 695.0000 1.0000
60.9200 710.0000 1.0000
60.9600 696.0000 1.0000
61.0000 688.0000 1.0000
61.0400 755.0000 1.0000
61.0800 705.0000 1.0000
61.1200 737.0000 1.0000
61.1600 725.0000 1.0000
61.2000 722.0000 1.0000
61.2400 716.0000 1.0000
61.2800 710.0000 1.0000
61.3200 703.0000 1.0000
61.3600 683.0000 1.0000
61.4000 723.0000 1.0000
61.4400 765.0000 1.0000
61.4800 691.0000 1.0000
61.5200 734.0000 1.0000
61.5600 762.0000 1.0000
61.6000 738.0000 1.0000
61.6400 727.0000 1.0000
61.6800 755.0000 1.0000
61.7200 779.0000 1.0000
61.7600 698.0000 1.0000
61.8000 720.0000 1.0000
61.8400 779.0000 1.0000
61.8800 777.0000 1.0000
61.9200 799.0000 1.0000
61.9600 855.0000 1.0000
62.0000 860.0000 1.0000
62.0400 954.0000 1.0000
62.0800 899.0000 1.0000
62.1200 987.0000 1.0000
62.1600 1122.0000 1.0000
62.2000 1236.0000 1.0000
62.2400 1395.0000 1.0000
62.2800 1534.0000 1.0000
62.3200 1640.0000 1.0000
62.3600 1685.0000 1.0000
62.4000 1669.0000 1.0000
62.4400 1614.0000 1.0000
62.4800 1541.0000 1.0000
62.5200 1370.0000 1.0000
62.5600 1404.0000 1.0000
62.6000 1253.0000 1.0000
62.6400 1129.0000 1.0000
62.6800 981.0000 1.0000
62.7200 1017.0000 1.0000
62.7600 924.0000 1.0000
62.8000 869.0000 1.0000
62.8400 845.0000 1.0000
62.8800 803.0000 1.0000
62.9200 812.0000 1.0000
62.9600 774.0000 1.0000
63.0000 780.0000 1.0000
63.0400 775.0000 1.0000
63.0800 805.0000 1.0000
63.1200 805.0000 1.0000
63.1600 803.0000 1.0000
63.2000 746.0000 1.0000
63.2400 718.0000 1.0000
63.2800 791.0000 1.0000
63.3200 781.0000 1.0000
63.3600 740.0000 1.0000
63.4000 719.0000 1.0000
63.4400 728.0000 1.0000
63.4800 703.0000 1.0000
63.5200 731.0000 1.0000
63.5600 735.0000 1.0000
63.6000 732.0000 1.0000
63.6400 720.0000 1.0000
63.6800 707.0000 1.0000
63.7200 729.0000 1.0000
63.7600 719.0000 1.0000
63.8000 744.0000 1.0000
63.8400 736.0000 1.0000
63.8800 701.0000 1.0000
63.9200 712.0000 1.0000
63.9600 681.0000 1.0000
64.0000 706.0000 1.0000
64.0400 713.0000 1.0000
64.0800 703.0000 1.0000
64.1200 728.0000 1.0000
64.1600 687.0000 1.0000
64.2000 716.0000 1.0000
64.2400 729.0000 1.0000
64.2800 739.0000 1.0000
64.3200 723.0000 1.0000
64.3600 726.0000 1.0000
64.4000 661.0000 1.0000
64.4400 698.0000 1.0000
64.4800 709.0000 1.0000
64.5200 773.0000 1.0000
64.5600 791.0000 1.0000
64.6000 792.0000 1.0000
64.6400 816.0000 1.0000
64.6800 834.0000 1.0000
64.7200 903.0000 1.0000
64.7600 898.0000 1.0000
64.8000 880.0000 1.0000
64.8400 870.0000 1.0000
64.8800 861.0000 1.0000
64.9200 866.0000 1.0000
64.9600 785.0000 1.0000
65.0000 847.0000 1.0000
65.0400 781.0000 1.0000
65.0800 817.0000 1.0000
65.1200 769.0000 1.0000
65.1600 807.0000 1.0000
65.2000 803.0000 1.0000
65.2400 699.0000 1.0000
65.2800 715.0000 1.0000
65.3200 726.0000 1.0000
65.3600 770.0000 1.0000
65.4000 773.0000 1.0000
65.4400 674.0000 1.0000
65.4800 707.0000 1.0000
65.5200 784.0000 1.0000
65.5600 721.0000 1.0000
65.6000 713.0000 1.0000
65.6400 756.0000 1.0000
65.6800 749.0000 1.0000
65.7200 772.0000 1.0000
65.7600 744.0000 1.0000
65.8000 820.0000 1.0000
65.8400 872.0000 1.0000
65.8800 794.0000 1.0000
65.9200 848.0000 1.0000
65.9600 883.0000 1.0000
66.0000 991.0000 1.0000
66.0400 1003.0000 1.0000
66.0800 1175.0000 1.0000
66.1200 1328.0000 1.0000
66.1600 1429.0000 1.0000
66.2000 1854.0000 1.0000
66.2400 2196.0000 1.0000
66.2800 2652.0000 1.0000
66.3200 2833.0000 1.0000
66.3600 2816.0000 1.0000
66.4000 2469.0000 1.0000
66.4400 2383.0000 1.0000
66.4800 2248.0000 1.0000
66.5200 2117.0000 1.0000
66.5600 1836.0000 1.0000
66.6000 1522.0000 1.0000
66.6400 1359.0000 1.0000
66.6800 1213.0000 1.0000
66.7200 1089.0000 1.0000
66.7600 949.0000 1.0000
66.8000 877.0000 1.0000
66.8400 840.0000 1.0000
66.8800 861.0000 1.0000
66.9200 819.0000 1.0000
66.9600 797.0000 1.0000
67.0000 789.0000 1.0000
67.0400 737.0000 1.0000
67.0800 723.0000 1.0000
67.1200 657.0000 1.0000
67.1600 702.0000 1.0000
67.2000 722.0000 1.0000
67.2400 699.0000 1.0000
67.2800 691.0000 1.0000
67.3200 722.0000 1.0000
67.3600 719.0000 1.0000
67.4000 684.0000 1.0000
67.4400 708.0000 1.0000
67.4800 707.0000 1.0000
67.5200 711.0000 1.0000
67.5600 634.0000 1.0000
67.6000 653.0000 1.0000
67.6400 658.0000 1.0000
67.6800 652.0000 1.0000
67.7200 675.0000 1.0000
67.7600 667.0000 1.0000
67.8000 666.0000 1.0000
67.8400 646.0000 1.0000
67.8800 629.0000 1.0000
67.9200 636.0000 1.0000
67.9600 610.0000 1.0000
68.0000 668.0000 1.0000
68.0400 665.0000 1.0000
68.0800 644.0000 1.0000
68.1200 623.0000 1.0000
68.1600 647.0000 1.0000
68.2000 622.0000 1.0000
68.2400 662.0000 1.0000
68.2800 702.0000 1.0000
68.3200 675.0000 1.0000
68.3600 658.0000 1.0000
68.4000 676.0000 1.0000
68.4400 653.0000 1.0000
68.4800 688.0000 1.0000
68.5200 604.0000 1.0000
68.5600 616.0000 1.0000
68.6000 640.0000 1.0000
68.6400 619.0000 1.0000
68.6800 625.0000 1.0000
68.7200 673.0000 1.0000
68.7600 620.0000 1.0000
68.8000 628.0000 1.0000
68.8400 630.0000 1.0000
68.8800 623.0000 1.0000
68.9200 637.0000 1.0000
68.9600 653.0000 1.0000
69.0000 615.0000 1.0000
69.0400 605.0000 1.0000
69.0800 640.0000 1.0000
69.1200 663.0000 1.0000
69.1600 678.0000 1.0000
69.2000 622.0000 1.0000
69.2400 689.0000 1.0000
69.2800 647.0000 1.0000
69.3200 616.0000 1.0000
69.3600 641.0000 1.0000
69.4000 612.0000 1.0000
69.4400 641.0000 1.0000
69.4800 585.0000 1.0000
69.5200 659.0000 1.0000
69.5600 605.0000 1.0000
69.6000 637.0000 1.0000
69.6400 666.0000 1.0000
69.6800 630.0000 1.0000
69.7200 623.0000 1.0000
69.7600 622.0000 1.0000
69.8000 588.0000 1.0000
69.8400 635.0000 1.0000
69.8800 601.0000 1.0000
69.9200 632.0000 1.0000
69.9600 630.0000 1.0000
70.0000 556.0000 1.0000
*RAS_INT_END
*RAS_TEMPERATURE_START
*RAS_TEMPERATURE_END
*RAS_DATA_END