File: Data/Dataset1_Only_water/5_XRD/No_018_FS5_2.ras
*RAS_DATA_START
*RAS_HEADER_START
*DISP_FMT_X "%.2f"
*DISP_FMT_Y "%.0f"
*DISP_FULLSCALE "13736.0000000000"
*DISP_LINE_COLOR "255.0000000000"
*DISP_LINE_STYLE "0.0000000000"
*DISP_LINE_WIDTH "0.2500000000"
*DISP_NOTE "測定データ-2"
*DISP_OFFSET_Y "0.0000000000"
*DISP_PEAKSEARCH_UNIT_Y "cps"
*DISP_RANGE_BOTTOM "0.0000000000"
*DISP_RANGE_LEFT "20.0000000000"
*DISP_RANGE_LOGCUTOFF "0.0100000000"
*DISP_RANGE_RIGHT "70.0000000000"
*DISP_RANGE_TOP "13736.0000000000"
*DISP_SCALE_MODE_Y "0.0000000000"
*DISP_TAB_NAME "2θ/θ"
*DISP_TITLE_Y "強度"
*DISP_UNIT_Y "cps"
*DISP_WINDOW_NAME "MSG_MACROENGINE"
*FILE_COMMENT " "
*FILE_MD5 ""
*FILE_MEMO " "
*FILE_OPERATOR "Administrator"
*FILE_SAMPLE " "
*FILE_TYPE "RAS_RAW"
*FILE_USERGROUP "システムマネージャ"
*FILE_VERSION "1.0000000000"
*HW_ATTACHMENT_ID "ATT0025"
*HW_ATTACHMENT_NAME "標準|Standard"
*HW_COUNTER_ID-0 "CUT0025"
*HW_COUNTER_ID-1 "CUT0020"
*HW_COUNTER_ID-2 "CUT0020"
*HW_COUNTER_ID-3 "CSL0021"
*HW_COUNTER_ID-4 "CMC0021"
*HW_COUNTER_NAME-0 "D/teX Ultra|D/teX Ultra"
*HW_COUNTER_NAME-1 "None|None"
*HW_COUNTER_NAME-2 "None|None"
*HW_COUNTER_NAME-3 "BBM|BBM"
*HW_COUNTER_NAME-4 "検出器モノクロメータ|Detector monochromator"
*HW_COUNTER_SELECT_NAME "D/teX Ultra|D/teX Ultra"
*HW_GONIOMETER_ID "GON0023"
*HW_GONIOMETER_NAME "SmartLab|SmartLab"
*HW_GONIOMETER_RADIUS-0 "90.0"
*HW_GONIOMETER_RADIUS-1 "114.0"
*HW_GONIOMETER_RADIUS-2 "190.0"
*HW_GONIOMETER_RADIUS-3 "300.0"
*HW_GONIOMETER_RADIUS-4 "187.0"
*HW_GONIOMETER_RADIUS-5 "300.0"
*HW_GONIOMETER_RADIUS-6 "113.0"
*HW_GONIOMETER_RADIUS-7 "331.0"
*HW_I_OPT_ID-0 "CBO0021"
*HW_I_OPT_ID-1 "ICR0023"
*HW_I_OPT_ID-2 "ISL0021"
*HW_I_OPT_ID-3 "ISO0021"
*HW_I_OPT_ID-4 "IAD0021"
*HW_I_OPT_ID-5 "IPR0001"
*HW_I_OPT_NAME-0 "CBOユニット|CBO unit"
*HW_I_OPT_NAME-1 "標準入射光学ユニット|Standard incident optical unit"
*HW_I_OPT_NAME-2 "標準入射スリットボックス|Standard incident slit box"
*HW_I_OPT_NAME-3 "入射平行スリット|Incident parallel slit"
*HW_I_OPT_NAME-4 "長手制限スリット|Length limiting slit"
*HW_I_OPT_NAME-5 "None|None"
*HW_R_ATTENUATER_AUTOMODE "0"
*HW_R_OPT_ID-0 "RSS0021"
*HW_R_OPT_ID-1 "RCR0023"
*HW_R_OPT_ID-2 "RSO0021"
*HW_R_OPT_ID-3 "RRS0021"
*HW_R_OPT_ID-4 "ATN0021"
*HW_R_OPT_ID-5 "RFL0021"
*HW_R_OPT_ID-6 "RAD0021"
*HW_R_OPT_NAME-0 "標準受光スリットボックス1|Standard receiving slit box # 1"
*HW_R_OPT_NAME-1 "標準受光光学ユニット1|Standard receiving unit # 1"
*HW_R_OPT_NAME-2 "標準受光光学ユニット2|Standard receiving optical unit # 2"
*HW_R_OPT_NAME-3 "標準受光スリットボックス2|Standard receiving slit box # 2"
*HW_R_OPT_NAME-4 "標準アッテネータ|Standard Attenuator"
*HW_R_OPT_NAME-5 "Cu Kβ|Cu K-beta"
*HW_R_OPT_NAME-6 "調整用受光スリット|Alignment receiving slit"
*HW_SAMPLE_HOLDER_ID "SMP0023"
*HW_SAMPLE_HOLDER_NAME "標準Zステージ|Standard Z stage"
*HW_XG_CURRENT_MAX "50"
*HW_XG_CURRENT_MIN "2"
*HW_XG_CURRENT_RESOLUTION "1"
*HW_XG_CURRENT_UNIT "mA"
*HW_XG_FOCUS "1mm x 10mm"
*HW_XG_FOCUS_TYPE "Normal"
*HW_XG_ID ""
*HW_XG_NAME "3kW 封入管(ID:1200)|3kW Sealed tube(ID:1200)"
*HW_XG_TARGET_ATOMIC_NUMBER "29.0000000000"
*HW_XG_TARGET_NAME "Cu"
*HW_XG_TYPE "Hermetic"
*HW_XG_VOLTAGE_MAX "60"
*HW_XG_VOLTAGE_MIN "20"
*HW_XG_VOLTAGE_RESOLUTION "1"
*HW_XG_VOLTAGE_UNIT "kV"
*HW_XG_WATT_MAX "1.500"
*HW_XG_WATT_UNIT "kW"
*HW_XG_WAVE_LENGTH_ALPHA1 "1.540593"
*HW_XG_WAVE_LENGTH_ALPHA2 "1.544414"
*HW_XG_WAVE_LENGTH_BETA "1.392250"
*MEAS_COND_AXIS_NAME-0 "2θ/θ"
*MEAS_COND_AXIS_NAME-1 "2θ"
*MEAS_COND_AXIS_NAME-2 "ω"
*MEAS_COND_AXIS_NAME-3 "Z"
*MEAS_COND_AXIS_NAME-4 "2θ/ω"
*MEAS_COND_AXIS_NAME-5 "θs"
*MEAS_COND_AXIS_NAME-6 "θd"
*MEAS_COND_AXIS_NAME-7 "Ts"
*MEAS_COND_AXIS_NAME-8 "CBO選択スリット"
*MEAS_COND_AXIS_NAME-9 "M"
*MEAS_COND_AXIS_NAME-10 "入射平行スリット"
*MEAS_COND_AXIS_NAME-11 "入射スリット"
*MEAS_COND_AXIS_NAME-12 ""
*MEAS_COND_AXIS_NAME-13 "Zs"
*MEAS_COND_AXIS_NAME-14 "入射光学素子"
*MEAS_COND_AXIS_NAME-15 "長手制限スリット"
*MEAS_COND_AXIS_NAME-16 "センタースリット"
*MEAS_COND_AXIS_NAME-17 "フィルター"
*MEAS_COND_AXIS_NAME-18 "受光スリット1"
*MEAS_COND_AXIS_NAME-19 "受光スリット2"
*MEAS_COND_AXIS_NAME-20 "受光光学素子"
*MEAS_COND_AXIS_NAME-21 "受光平行スリット"
*MEAS_COND_AXIS_NAME-22 "調整用受光スリット"
*MEAS_COND_AXIS_NAME-23 ""
*MEAS_COND_AXIS_NAME-24 ""
*MEAS_COND_AXIS_NAME-25 "Zd"
*MEAS_COND_AXIS_NAME-26 "アッテネータ"
*MEAS_COND_AXIS_NAME-27 "検出器モノクロメータ"
*MEAS_COND_AXIS_NAME-28 "モノクロメータスリット"
*MEAS_COND_AXIS_NAME-29 "プライマリビーム"
*MEAS_COND_AXIS_NAME-30 "PHA"
*MEAS_COND_AXIS_NAME_INTERNAL-0 "TwoThetaTheta"
*MEAS_COND_AXIS_NAME_INTERNAL-1 "TwoTheta"
*MEAS_COND_AXIS_NAME_INTERNAL-2 "Omega"
*MEAS_COND_AXIS_NAME_INTERNAL-3 "Z"
*MEAS_COND_AXIS_NAME_INTERNAL-4 "TwoThetaOmega"
*MEAS_COND_AXIS_NAME_INTERNAL-5 "ThetaS"
*MEAS_COND_AXIS_NAME_INTERNAL-6 "ThetaD"
*MEAS_COND_AXIS_NAME_INTERNAL-7 "Ts"
*MEAS_COND_AXIS_NAME_INTERNAL-8 "CBO"
*MEAS_COND_AXIS_NAME_INTERNAL-9 "CBO-M"
*MEAS_COND_AXIS_NAME_INTERNAL-10 "IncidentSollerSlit"
*MEAS_COND_AXIS_NAME_INTERNAL-11 "IncidentSlitBox"
*MEAS_COND_AXIS_NAME_INTERNAL-12 "IncidentSlitBox-_Axis"
*MEAS_COND_AXIS_NAME_INTERNAL-13 "Zs"
*MEAS_COND_AXIS_NAME_INTERNAL-14 "IncidentMonochromator"
*MEAS_COND_AXIS_NAME_INTERNAL-15 "IncidentAxdSlit"
*MEAS_COND_AXIS_NAME_INTERNAL-16 "CenterSlit"
*MEAS_COND_AXIS_NAME_INTERNAL-17 "Filter"
*MEAS_COND_AXIS_NAME_INTERNAL-18 "ReceivingSlitBox1"
*MEAS_COND_AXIS_NAME_INTERNAL-19 "ReceivingSlitBox2"
*MEAS_COND_AXIS_NAME_INTERNAL-20 "ReceivingOptics"
*MEAS_COND_AXIS_NAME_INTERNAL-21 "ReceivingSollerSlit"
*MEAS_COND_AXIS_NAME_INTERNAL-22 "ReceivingAxdSlit"
*MEAS_COND_AXIS_NAME_INTERNAL-23 "ReceivingSlitBox1-_Axis"
*MEAS_COND_AXIS_NAME_INTERNAL-24 "ReceivingSlitBox2-_Axis"
*MEAS_COND_AXIS_NAME_INTERNAL-25 "ReceivingSlitBox2-Zd"
*MEAS_COND_AXIS_NAME_INTERNAL-26 "Attenuator"
*MEAS_COND_AXIS_NAME_INTERNAL-27 "CounterMonochromator"
*MEAS_COND_AXIS_NAME_INTERNAL-28 "CounterSlit"
*MEAS_COND_AXIS_NAME_INTERNAL-29 "IncidentPrimary"
*MEAS_COND_AXIS_NAME_INTERNAL-30 "PHA"
*MEAS_COND_AXIS_NAME_MAGICNO-0 "83951616.0000000000"
*MEAS_COND_AXIS_NAME_MAGICNO-1 "268632064.0000000000"
*MEAS_COND_AXIS_NAME_MAGICNO-2 "268500992.0000000000"
*MEAS_COND_AXIS_NAME_MAGICNO-3 "285278208.0000000000"
*MEAS_COND_AXIS_NAME_MAGICNO-4 "83951616.0000000000"
*MEAS_COND_AXIS_NAME_MAGICNO-5 "131072.0000000000"
*MEAS_COND_AXIS_NAME_MAGICNO-6 "131072.0000000000"
*MEAS_COND_AXIS_NAME_MAGICNO-7 "318898176.0000000000"
*MEAS_COND_AXIS_NAME_MAGICNO-8 "20971521.0000000000"
*MEAS_COND_AXIS_NAME_MAGICNO-9 "285343744.0000000000"
*MEAS_COND_AXIS_NAME_MAGICNO-10 "20971521.0000000000"
*MEAS_COND_AXIS_NAME_MAGICNO-11 "22020097.0000000000"
*MEAS_COND_AXIS_NAME_MAGICNO-12 "25165824.0000000000"
*MEAS_COND_AXIS_NAME_MAGICNO-13 "318898176.0000000000"
*MEAS_COND_AXIS_NAME_MAGICNO-14 "1.0000000000"
*MEAS_COND_AXIS_NAME_MAGICNO-15 "20971521.0000000000"
*MEAS_COND_AXIS_NAME_MAGICNO-16 "20971521.0000000000"
*MEAS_COND_AXIS_NAME_MAGICNO-17 "20971521.0000000000"
*MEAS_COND_AXIS_NAME_MAGICNO-18 "23068673.0000000000"
*MEAS_COND_AXIS_NAME_MAGICNO-19 "23068673.0000000000"
*MEAS_COND_AXIS_NAME_MAGICNO-20 "20971521.0000000000"
*MEAS_COND_AXIS_NAME_MAGICNO-21 "20971521.0000000000"
*MEAS_COND_AXIS_NAME_MAGICNO-22 "20971521.0000000000"
*MEAS_COND_AXIS_NAME_MAGICNO-23 "25165824.0000000000"
*MEAS_COND_AXIS_NAME_MAGICNO-24 "25165824.0000000000"
*MEAS_COND_AXIS_NAME_MAGICNO-25 "285343744.0000000000"
*MEAS_COND_AXIS_NAME_MAGICNO-26 "17301505.0000000000"
*MEAS_COND_AXIS_NAME_MAGICNO-27 "20971521.0000000000"
*MEAS_COND_AXIS_NAME_MAGICNO-28 "20971521.0000000000"
*MEAS_COND_AXIS_NAME_MAGICNO-29 "20971521.0000000000"
*MEAS_COND_AXIS_NAME_MAGICNO-30 "0.0000000000"
*MEAS_COND_AXIS_OFFSET-0 "-"
*MEAS_COND_AXIS_OFFSET-1 "-0.1081000000"
*MEAS_COND_AXIS_OFFSET-2 "0.3758000000"
*MEAS_COND_AXIS_OFFSET-3 "-"
*MEAS_COND_AXIS_OFFSET-4 "-"
*MEAS_COND_AXIS_OFFSET-5 "0.3758000000"
*MEAS_COND_AXIS_OFFSET-6 "-0.4839000000"
*MEAS_COND_AXIS_OFFSET-7 "-"
*MEAS_COND_AXIS_OFFSET-8 "-"
*MEAS_COND_AXIS_OFFSET-9 "-"
*MEAS_COND_AXIS_OFFSET-10 "-"
*MEAS_COND_AXIS_OFFSET-11 "-"
*MEAS_COND_AXIS_OFFSET-12 "-"
*MEAS_COND_AXIS_OFFSET-13 "-"
*MEAS_COND_AXIS_OFFSET-14 "-"
*MEAS_COND_AXIS_OFFSET-15 "-"
*MEAS_COND_AXIS_OFFSET-16 "-"
*MEAS_COND_AXIS_OFFSET-17 "-"
*MEAS_COND_AXIS_OFFSET-18 "-"
*MEAS_COND_AXIS_OFFSET-19 "-"
*MEAS_COND_AXIS_OFFSET-20 "-"
*MEAS_COND_AXIS_OFFSET-21 "-"
*MEAS_COND_AXIS_OFFSET-22 "-"
*MEAS_COND_AXIS_OFFSET-23 "-"
*MEAS_COND_AXIS_OFFSET-24 "-"
*MEAS_COND_AXIS_OFFSET-25 "-"
*MEAS_COND_AXIS_OFFSET-26 "-"
*MEAS_COND_AXIS_OFFSET-27 "-"
*MEAS_COND_AXIS_OFFSET-28 "-"
*MEAS_COND_AXIS_OFFSET-29 "-"
*MEAS_COND_AXIS_OFFSET-30 "-"
*MEAS_COND_AXIS_POSITION-0 "0.0000000000"
*MEAS_COND_AXIS_POSITION-1 "0.0000000000"
*MEAS_COND_AXIS_POSITION-2 "0.0000000000"
*MEAS_COND_AXIS_POSITION-3 "-0.5500000000"
*MEAS_COND_AXIS_POSITION-4 "0.0000000000"
*MEAS_COND_AXIS_POSITION-5 "0.0000000000"
*MEAS_COND_AXIS_POSITION-6 "0.0000000000"
*MEAS_COND_AXIS_POSITION-7 "-0.4278800000"
*MEAS_COND_AXIS_POSITION-8 "BB"
*MEAS_COND_AXIS_POSITION-9 "0.0000000000"
*MEAS_COND_AXIS_POSITION-10 "Soller_slit_5.0deg"
*MEAS_COND_AXIS_POSITION-11 "2/3deg"
*MEAS_COND_AXIS_POSITION-12 "2.2088000000"
*MEAS_COND_AXIS_POSITION-13 "-0.4140600000"
*MEAS_COND_AXIS_POSITION-14 "0.0000000000"
*MEAS_COND_AXIS_POSITION-15 "10.0mm"
*MEAS_COND_AXIS_POSITION-16 "None"
*MEAS_COND_AXIS_POSITION-17 "Cu_K-beta"
*MEAS_COND_AXIS_POSITION-18 "13.000mm"
*MEAS_COND_AXIS_POSITION-19 "13.000mm"
*MEAS_COND_AXIS_POSITION-20 "No_unit"
*MEAS_COND_AXIS_POSITION-21 "Soller_slit_5.0deg"
*MEAS_COND_AXIS_POSITION-22 "None"
*MEAS_COND_AXIS_POSITION-23 "13.0000000000"
*MEAS_COND_AXIS_POSITION-24 "13.0000000000"
*MEAS_COND_AXIS_POSITION-25 "0.0109400000"
*MEAS_COND_AXIS_POSITION-26 "Open"
*MEAS_COND_AXIS_POSITION-27 "None"
*MEAS_COND_AXIS_POSITION-28 "None"
*MEAS_COND_AXIS_POSITION-29 "None"
*MEAS_COND_AXIS_POSITION-30 "38.0000000000"
*MEAS_COND_AXIS_UNIT-0 "deg"
*MEAS_COND_AXIS_UNIT-1 "deg"
*MEAS_COND_AXIS_UNIT-2 "deg"
*MEAS_COND_AXIS_UNIT-3 "mm"
*MEAS_COND_AXIS_UNIT-4 "deg"
*MEAS_COND_AXIS_UNIT-5 "deg"
*MEAS_COND_AXIS_UNIT-6 "deg"
*MEAS_COND_AXIS_UNIT-7 "mm"
*MEAS_COND_AXIS_UNIT-8 ""
*MEAS_COND_AXIS_UNIT-9 "pulse"
*MEAS_COND_AXIS_UNIT-10 ""
*MEAS_COND_AXIS_UNIT-11 ""
*MEAS_COND_AXIS_UNIT-12 "mm"
*MEAS_COND_AXIS_UNIT-13 "mm"
*MEAS_COND_AXIS_UNIT-14 ""
*MEAS_COND_AXIS_UNIT-15 ""
*MEAS_COND_AXIS_UNIT-16 ""
*MEAS_COND_AXIS_UNIT-17 ""
*MEAS_COND_AXIS_UNIT-18 ""
*MEAS_COND_AXIS_UNIT-19 ""
*MEAS_COND_AXIS_UNIT-20 ""
*MEAS_COND_AXIS_UNIT-21 ""
*MEAS_COND_AXIS_UNIT-22 ""
*MEAS_COND_AXIS_UNIT-23 "mm"
*MEAS_COND_AXIS_UNIT-24 "mm"
*MEAS_COND_AXIS_UNIT-25 "mm"
*MEAS_COND_AXIS_UNIT-26 ""
*MEAS_COND_AXIS_UNIT-27 ""
*MEAS_COND_AXIS_UNIT-28 ""
*MEAS_COND_AXIS_UNIT-29 ""
*MEAS_COND_AXIS_UNIT-30 "div"
*MEAS_COND_COUNTER_CNTLOSS_CORR "0.0000000000"
*MEAS_COND_COUNTER_PHABASE "38.0000000000"
*MEAS_COND_COUNTER_PHAWINDOW "16.0000000000"
*MEAS_COND_COUNTER_PHA_UNIT "div"
*MEAS_COND_COUNTER_TAUDIFF "30.0000000000"
*MEAS_COND_COUNTER_TAUINT "0.0000000000"
*MEAS_COND_IRRADIATION_MODE "OFF"
*MEAS_COND_IRRADIATION_WIDTH ""
*MEAS_COND_OPT_ATTR "集中法"
*MEAS_COND_OPT_NAME "@集中法"
*MEAS_COND_UNSYMMETRIC_MODE "OFF"
*MEAS_COND_XG_CURRENT "30.0000000000"
*MEAS_COND_XG_VOLTAGE "40.0000000000"
*MEAS_COND_XG_WAVE_TYPE "Ka"
*MEAS_DATA_COUNT "5001.0000000000"
*MEAS_SCAN_AXIS_X "2θ/θ"
*MEAS_SCAN_AXIS_X_INTERNAL "TwoThetaTheta"
*MEAS_SCAN_END_TIME "07/08/21 12:43:08"
*MEAS_SCAN_MODE "CONTINUOUS"
*MEAS_SCAN_MONITOR "0"
*MEAS_SCAN_RESOLUTION_X "0.0002"
*MEAS_SCAN_SPEED "1.0"
*MEAS_SCAN_SPEED_UNIT "deg/min"
*MEAS_SCAN_START "20.0000000000"
*MEAS_SCAN_START_TIME "07/08/21 11:50:14"
*MEAS_SCAN_STEP "0.0100000000"
*MEAS_SCAN_STOP "70.0000000000"
*MEAS_SCAN_UNIT_X "deg"
*MEAS_SCAN_UNIT_Y "counts"
*RAS_HEADER_END
*RAS_INT_START
20.0000 1523.0000 1.0000
20.0400 1540.0000 1.0000
20.0800 1490.0000 1.0000
20.1200 1576.0000 1.0000
20.1600 1568.0000 1.0000
20.2000 1561.0000 1.0000
20.2400 1564.0000 1.0000
20.2800 1540.0000 1.0000
20.3200 1565.0000 1.0000
20.3600 1581.0000 1.0000
20.4000 1596.0000 1.0000
20.4400 1625.0000 1.0000
20.4800 1602.0000 1.0000
20.5200 1588.0000 1.0000
20.5600 1578.0000 1.0000
20.6000 1593.0000 1.0000
20.6400 1505.0000 1.0000
20.6800 1598.0000 1.0000
20.7200 1608.0000 1.0000
20.7600 1564.0000 1.0000
20.8000 1585.0000 1.0000
20.8400 1540.0000 1.0000
20.8800 1501.0000 1.0000
20.9200 1559.0000 1.0000
20.9600 1538.0000 1.0000
21.0000 1562.0000 1.0000
21.0400 1534.0000 1.0000
21.0800 1555.0000 1.0000
21.1200 1589.0000 1.0000
21.1600 1631.0000 1.0000
21.2000 1570.0000 1.0000
21.2400 1609.0000 1.0000
21.2800 1560.0000 1.0000
21.3200 1559.0000 1.0000
21.3600 1605.0000 1.0000
21.4000 1558.0000 1.0000
21.4400 1569.0000 1.0000
21.4800 1628.0000 1.0000
21.5200 1583.0000 1.0000
21.5600 1568.0000 1.0000
21.6000 1562.0000 1.0000
21.6400 1595.0000 1.0000
21.6800 1586.0000 1.0000
21.7200 1624.0000 1.0000
21.7600 1574.0000 1.0000
21.8000 1575.0000 1.0000
21.8400 1651.0000 1.0000
21.8800 1508.0000 1.0000
21.9200 1571.0000 1.0000
21.9600 1587.0000 1.0000
22.0000 1616.0000 1.0000
22.0400 1571.0000 1.0000
22.0800 1680.0000 1.0000
22.1200 1619.0000 1.0000
22.1600 1574.0000 1.0000
22.2000 1576.0000 1.0000
22.2400 1584.0000 1.0000
22.2800 1646.0000 1.0000
22.3200 1620.0000 1.0000
22.3600 1571.0000 1.0000
22.4000 1546.0000 1.0000
22.4400 1551.0000 1.0000
22.4800 1636.0000 1.0000
22.5200 1612.0000 1.0000
22.5600 1604.0000 1.0000
22.6000 1609.0000 1.0000
22.6400 1607.0000 1.0000
22.6800 1641.0000 1.0000
22.7200 1659.0000 1.0000
22.7600 1596.0000 1.0000
22.8000 1667.0000 1.0000
22.8400 1640.0000 1.0000
22.8800 1647.0000 1.0000
22.9200 1615.0000 1.0000
22.9600 1616.0000 1.0000
23.0000 1587.0000 1.0000
23.0400 1614.0000 1.0000
23.0800 1603.0000 1.0000
23.1200 1659.0000 1.0000
23.1600 1614.0000 1.0000
23.2000 1620.0000 1.0000
23.2400 1643.0000 1.0000
23.2800 1582.0000 1.0000
23.3200 1619.0000 1.0000
23.3600 1632.0000 1.0000
23.4000 1657.0000 1.0000
23.4400 1587.0000 1.0000
23.4800 1606.0000 1.0000
23.5200 1618.0000 1.0000
23.5600 1580.0000 1.0000
23.6000 1633.0000 1.0000
23.6400 1629.0000 1.0000
23.6800 1607.0000 1.0000
23.7200 1567.0000 1.0000
23.7600 1626.0000 1.0000
23.8000 1666.0000 1.0000
23.8400 1650.0000 1.0000
23.8800 1625.0000 1.0000
23.9200 1643.0000 1.0000
23.9600 1649.0000 1.0000
24.0000 1684.0000 1.0000
24.0400 1592.0000 1.0000
24.0800 1688.0000 1.0000
24.1200 1676.0000 1.0000
24.1600 1616.0000 1.0000
24.2000 1730.0000 1.0000
24.2400 1618.0000 1.0000
24.2800 1720.0000 1.0000
24.3200 1696.0000 1.0000
24.3600 1660.0000 1.0000
24.4000 1674.0000 1.0000
24.4400 1622.0000 1.0000
24.4800 1664.0000 1.0000
24.5200 1610.0000 1.0000
24.5600 1731.0000 1.0000
24.6000 1660.0000 1.0000
24.6400 1759.0000 1.0000
24.6800 1705.0000 1.0000
24.7200 1694.0000 1.0000
24.7600 1639.0000 1.0000
24.8000 1752.0000 1.0000
24.8400 1745.0000 1.0000
24.8800 1731.0000 1.0000
24.9200 1804.0000 1.0000
24.9600 1777.0000 1.0000
25.0000 1766.0000 1.0000
25.0400 1733.0000 1.0000
25.0800 1732.0000 1.0000
25.1200 1773.0000 1.0000
25.1600 1701.0000 1.0000
25.2000 1718.0000 1.0000
25.2400 1651.0000 1.0000
25.2800 1702.0000 1.0000
25.3200 1710.0000 1.0000
25.3600 1683.0000 1.0000
25.4000 1654.0000 1.0000
25.4400 1676.0000 1.0000
25.4800 1691.0000 1.0000
25.5200 1612.0000 1.0000
25.5600 1705.0000 1.0000
25.6000 1689.0000 1.0000
25.6400 1666.0000 1.0000
25.6800 1690.0000 1.0000
25.7200 1719.0000 1.0000
25.7600 1711.0000 1.0000
25.8000 1716.0000 1.0000
25.8400 1624.0000 1.0000
25.8800 1645.0000 1.0000
25.9200 1710.0000 1.0000
25.9600 1674.0000 1.0000
26.0000 1730.0000 1.0000
26.0400 1664.0000 1.0000
26.0800 1677.0000 1.0000
26.1200 1666.0000 1.0000
26.1600 1719.0000 1.0000
26.2000 1745.0000 1.0000
26.2400 1706.0000 1.0000
26.2800 1812.0000 1.0000
26.3200 1738.0000 1.0000
26.3600 1758.0000 1.0000
26.4000 1780.0000 1.0000
26.4400 1841.0000 1.0000
26.4800 1764.0000 1.0000
26.5200 1735.0000 1.0000
26.5600 1749.0000 1.0000
26.6000 1750.0000 1.0000
26.6400 1870.0000 1.0000
26.6800 1765.0000 1.0000
26.7200 1850.0000 1.0000
26.7600 1857.0000 1.0000
26.8000 1901.0000 1.0000
26.8400 1937.0000 1.0000
26.8800 2005.0000 1.0000
26.9200 2020.0000 1.0000
26.9600 2150.0000 1.0000
27.0000 2313.0000 1.0000
27.0400 2553.0000 1.0000
27.0800 2752.0000 1.0000
27.1200 3236.0000 1.0000
27.1600 3779.0000 1.0000
27.2000 4655.0000 1.0000
27.2400 5649.0000 1.0000
27.2800 6445.0000 1.0000
27.3200 6868.0000 1.0000
27.3600 5970.0000 1.0000
27.4000 4933.0000 1.0000
27.4400 3949.0000 1.0000
27.4800 3272.0000 1.0000
27.5200 2853.0000 1.0000
27.5600 2536.0000 1.0000
27.6000 2338.0000 1.0000
27.6400 2198.0000 1.0000
27.6800 2083.0000 1.0000
27.7200 1935.0000 1.0000
27.7600 1948.0000 1.0000
27.8000 1856.0000 1.0000
27.8400 1843.0000 1.0000
27.8800 1763.0000 1.0000
27.9200 1781.0000 1.0000
27.9600 1790.0000 1.0000
28.0000 1789.0000 1.0000
28.0400 1786.0000 1.0000
28.0800 1670.0000 1.0000
28.1200 1732.0000 1.0000
28.1600 1728.0000 1.0000
28.2000 1694.0000 1.0000
28.2400 1741.0000 1.0000
28.2800 1647.0000 1.0000
28.3200 1669.0000 1.0000
28.3600 1637.0000 1.0000
28.4000 1623.0000 1.0000
28.4400 1671.0000 1.0000
28.4800 1611.0000 1.0000
28.5200 1618.0000 1.0000
28.5600 1599.0000 1.0000
28.6000 1589.0000 1.0000
28.6400 1590.0000 1.0000
28.6800 1617.0000 1.0000
28.7200 1626.0000 1.0000
28.7600 1641.0000 1.0000
28.8000 1559.0000 1.0000
28.8400 1603.0000 1.0000
28.8800 1672.0000 1.0000
28.9200 1545.0000 1.0000
28.9600 1574.0000 1.0000
29.0000 1588.0000 1.0000
29.0400 1629.0000 1.0000
29.0800 1569.0000 1.0000
29.1200 1542.0000 1.0000
29.1600 1550.0000 1.0000
29.2000 1557.0000 1.0000
29.2400 1564.0000 1.0000
29.2800 1562.0000 1.0000
29.3200 1559.0000 1.0000
29.3600 1520.0000 1.0000
29.4000 1567.0000 1.0000
29.4400 1538.0000 1.0000
29.4800 1595.0000 1.0000
29.5200 1519.0000 1.0000
29.5600 1511.0000 1.0000
29.6000 1501.0000 1.0000
29.6400 1511.0000 1.0000
29.6800 1556.0000 1.0000
29.7200 1520.0000 1.0000
29.7600 1552.0000 1.0000
29.8000 1472.0000 1.0000
29.8400 1541.0000 1.0000
29.8800 1481.0000 1.0000
29.9200 1461.0000 1.0000
29.9600 1493.0000 1.0000
30.0000 1479.0000 1.0000
30.0400 1494.0000 1.0000
30.0800 1489.0000 1.0000
30.1200 1483.0000 1.0000
30.1600 1556.0000 1.0000
30.2000 1504.0000 1.0000
30.2400 1487.0000 1.0000
30.2800 1506.0000 1.0000
30.3200 1513.0000 1.0000
30.3600 1457.0000 1.0000
30.4000 1437.0000 1.0000
30.4400 1513.0000 1.0000
30.4800 1403.0000 1.0000
30.5200 1450.0000 1.0000
30.5600 1507.0000 1.0000
30.6000 1489.0000 1.0000
30.6400 1500.0000 1.0000
30.6800 1509.0000 1.0000
30.7200 1436.0000 1.0000
30.7600 1480.0000 1.0000
30.8000 1450.0000 1.0000
30.8400 1460.0000 1.0000
30.8800 1399.0000 1.0000
30.9200 1427.0000 1.0000
30.9600 1436.0000 1.0000
31.0000 1475.0000 1.0000
31.0400 1436.0000 1.0000
31.0800 1459.0000 1.0000
31.1200 1485.0000 1.0000
31.1600 1438.0000 1.0000
31.2000 1446.0000 1.0000
31.2400 1471.0000 1.0000
31.2800 1428.0000 1.0000
31.3200 1413.0000 1.0000
31.3600 1389.0000 1.0000
31.4000 1423.0000 1.0000
31.4400 1396.0000 1.0000
31.4800 1441.0000 1.0000
31.5200 1418.0000 1.0000
31.5600 1344.0000 1.0000
31.6000 1387.0000 1.0000
31.6400 1481.0000 1.0000
31.6800 1312.0000 1.0000
31.7200 1379.0000 1.0000
31.7600 1393.0000 1.0000
31.8000 1463.0000 1.0000
31.8400 1395.0000 1.0000
31.8800 1383.0000 1.0000
31.9200 1408.0000 1.0000
31.9600 1453.0000 1.0000
32.0000 1430.0000 1.0000
32.0400 1430.0000 1.0000
32.0800 1352.0000 1.0000
32.1200 1385.0000 1.0000
32.1600 1415.0000 1.0000
32.2000 1386.0000 1.0000
32.2400 1345.0000 1.0000
32.2800 1430.0000 1.0000
32.3200 1481.0000 1.0000
32.3600 1393.0000 1.0000
32.4000 1351.0000 1.0000
32.4400 1349.0000 1.0000
32.4800 1334.0000 1.0000
32.5200 1356.0000 1.0000
32.5600 1393.0000 1.0000
32.6000 1329.0000 1.0000
32.6400 1302.0000 1.0000
32.6800 1384.0000 1.0000
32.7200 1340.0000 1.0000
32.7600 1314.0000 1.0000
32.8000 1383.0000 1.0000
32.8400 1334.0000 1.0000
32.8800 1340.0000 1.0000
32.9200 1286.0000 1.0000
32.9600 1333.0000 1.0000
33.0000 1323.0000 1.0000
33.0400 1340.0000 1.0000
33.0800 1309.0000 1.0000
33.1200 1317.0000 1.0000
33.1600 1304.0000 1.0000
33.2000 1357.0000 1.0000
33.2400 1303.0000 1.0000
33.2800 1327.0000 1.0000
33.3200 1292.0000 1.0000
33.3600 1360.0000 1.0000
33.4000 1339.0000 1.0000
33.4400 1359.0000 1.0000
33.4800 1329.0000 1.0000
33.5200 1285.0000 1.0000
33.5600 1323.0000 1.0000
33.6000 1330.0000 1.0000
33.6400 1322.0000 1.0000
33.6800 1279.0000 1.0000
33.7200 1338.0000 1.0000
33.7600 1380.0000 1.0000
33.8000 1351.0000 1.0000
33.8400 1352.0000 1.0000
33.8800 1477.0000 1.0000
33.9200 1581.0000 1.0000
33.9600 1551.0000 1.0000
34.0000 1529.0000 1.0000
34.0400 1515.0000 1.0000
34.0800 1506.0000 1.0000
34.1200 1511.0000 1.0000
34.1600 1519.0000 1.0000
34.2000 1584.0000 1.0000
34.2400 1655.0000 1.0000
34.2800 1761.0000 1.0000
34.3200 1985.0000 1.0000
34.3600 2177.0000 1.0000
34.4000 2520.0000 1.0000
34.4400 2977.0000 1.0000
34.4800 3312.0000 1.0000
34.5200 3362.0000 1.0000
34.5600 3005.0000 1.0000
34.6000 2649.0000 1.0000
34.6400 2317.0000 1.0000
34.6800 1976.0000 1.0000
34.7200 1760.0000 1.0000
34.7600 1644.0000 1.0000
34.8000 1620.0000 1.0000
34.8400 1471.0000 1.0000
34.8800 1441.0000 1.0000
34.9200 1420.0000 1.0000
34.9600 1344.0000 1.0000
35.0000 1323.0000 1.0000
35.0400 1295.0000 1.0000
35.0800 1250.0000 1.0000
35.1200 1299.0000 1.0000
35.1600 1207.0000 1.0000
35.2000 1253.0000 1.0000
35.2400 1224.0000 1.0000
35.2800 1279.0000 1.0000
35.3200 1203.0000 1.0000
35.3600 1161.0000 1.0000
35.4000 1161.0000 1.0000
35.4400 1186.0000 1.0000
35.4800 1175.0000 1.0000
35.5200 1167.0000 1.0000
35.5600 1152.0000 1.0000
35.6000 1147.0000 1.0000
35.6400 1142.0000 1.0000
35.6800 1159.0000 1.0000
35.7200 1161.0000 1.0000
35.7600 1138.0000 1.0000
35.8000 1190.0000 1.0000
35.8400 1140.0000 1.0000
35.8800 1080.0000 1.0000
35.9200 1146.0000 1.0000
35.9600 1134.0000 1.0000
36.0000 1077.0000 1.0000
36.0400 1116.0000 1.0000
36.0800 1181.0000 1.0000
36.1200 1187.0000 1.0000
36.1600 1218.0000 1.0000
36.2000 1205.0000 1.0000
36.2400 1315.0000 1.0000
36.2800 1433.0000 1.0000
36.3200 1526.0000 1.0000
36.3600 1835.0000 1.0000
36.4000 2209.0000 1.0000
36.4400 1979.0000 1.0000
36.4800 1765.0000 1.0000
36.5200 1646.0000 1.0000
36.5600 1362.0000 1.0000
36.6000 1179.0000 1.0000
36.6400 1143.0000 1.0000
36.6800 1131.0000 1.0000
36.7200 1087.0000 1.0000
36.7600 1085.0000 1.0000
36.8000 1093.0000 1.0000
36.8400 1050.0000 1.0000
36.8800 1130.0000 1.0000
36.9200 1019.0000 1.0000
36.9600 1121.0000 1.0000
37.0000 991.0000 1.0000
37.0400 1002.0000 1.0000
37.0800 1042.0000 1.0000
37.1200 1053.0000 1.0000
37.1600 1030.0000 1.0000
37.2000 1082.0000 1.0000
37.2400 1049.0000 1.0000
37.2800 1085.0000 1.0000
37.3200 1025.0000 1.0000
37.3600 989.0000 1.0000
37.4000 1032.0000 1.0000
37.4400 1026.0000 1.0000
37.4800 1044.0000 1.0000
37.5200 1103.0000 1.0000
37.5600 1084.0000 1.0000
37.6000 1065.0000 1.0000
37.6400 1007.0000 1.0000
37.6800 1018.0000 1.0000
37.7200 1050.0000 1.0000
37.7600 1063.0000 1.0000
37.8000 1007.0000 1.0000
37.8400 1026.0000 1.0000
37.8800 1070.0000 1.0000
37.9200 1041.0000 1.0000
37.9600 1087.0000 1.0000
38.0000 1089.0000 1.0000
38.0400 1094.0000 1.0000
38.0800 1124.0000 1.0000
38.1200 1242.0000 1.0000
38.1600 1337.0000 1.0000
38.2000 1405.0000 1.0000
38.2400 1495.0000 1.0000
38.2800 1673.0000 1.0000
38.3200 2004.0000 1.0000
38.3600 2519.0000 1.0000
38.4000 3298.0000 1.0000
38.4400 4234.0000 1.0000
38.4800 5227.0000 1.0000
38.5200 6076.0000 1.0000
38.5600 6165.0000 1.0000
38.6000 5623.0000 1.0000
38.6400 4681.0000 1.0000
38.6800 3852.0000 1.0000
38.7200 2849.0000 1.0000
38.7600 2298.0000 1.0000
38.8000 1851.0000 1.0000
38.8400 1562.0000 1.0000
38.8800 1386.0000 1.0000
38.9200 1224.0000 1.0000
38.9600 1191.0000 1.0000
39.0000 1122.0000 1.0000
39.0400 1096.0000 1.0000
39.0800 1013.0000 1.0000
39.1200 1027.0000 1.0000
39.1600 995.0000 1.0000
39.2000 1019.0000 1.0000
39.2400 960.0000 1.0000
39.2800 941.0000 1.0000
39.3200 969.0000 1.0000
39.3600 977.0000 1.0000
39.4000 933.0000 1.0000
39.4400 968.0000 1.0000
39.4800 996.0000 1.0000
39.5200 1007.0000 1.0000
39.5600 1018.0000 1.0000
39.6000 1011.0000 1.0000
39.6400 1019.0000 1.0000
39.6800 1010.0000 1.0000
39.7200 915.0000 1.0000
39.7600 966.0000 1.0000
39.8000 979.0000 1.0000
39.8400 969.0000 1.0000
39.8800 924.0000 1.0000
39.9200 904.0000 1.0000
39.9600 907.0000 1.0000
40.0000 902.0000 1.0000
40.0400 884.0000 1.0000
40.0800 940.0000 1.0000
40.1200 917.0000 1.0000
40.1600 874.0000 1.0000
40.2000 869.0000 1.0000
40.2400 926.0000 1.0000
40.2800 878.0000 1.0000
40.3200 873.0000 1.0000
40.3600 876.0000 1.0000
40.4000 897.0000 1.0000
40.4400 853.0000 1.0000
40.4800 967.0000 1.0000
40.5200 873.0000 1.0000
40.5600 891.0000 1.0000
40.6000 858.0000 1.0000
40.6400 826.0000 1.0000
40.6800 868.0000 1.0000
40.7200 886.0000 1.0000
40.7600 870.0000 1.0000
40.8000 827.0000 1.0000
40.8400 876.0000 1.0000
40.8800 882.0000 1.0000
40.9200 818.0000 1.0000
40.9600 884.0000 1.0000
41.0000 850.0000 1.0000
41.0400 864.0000 1.0000
41.0800 872.0000 1.0000
41.1200 835.0000 1.0000
41.1600 815.0000 1.0000
41.2000 825.0000 1.0000
41.2400 849.0000 1.0000
41.2800 861.0000 1.0000
41.3200 825.0000 1.0000
41.3600 859.0000 1.0000
41.4000 848.0000 1.0000
41.4400 924.0000 1.0000
41.4800 862.0000 1.0000
41.5200 875.0000 1.0000
41.5600 855.0000 1.0000
41.6000 846.0000 1.0000
41.6400 951.0000 1.0000
41.6800 901.0000 1.0000
41.7200 856.0000 1.0000
41.7600 855.0000 1.0000
41.8000 873.0000 1.0000
41.8400 850.0000 1.0000
41.8800 845.0000 1.0000
41.9200 883.0000 1.0000
41.9600 842.0000 1.0000
42.0000 844.0000 1.0000
42.0400 866.0000 1.0000
42.0800 822.0000 1.0000
42.1200 882.0000 1.0000
42.1600 842.0000 1.0000
42.2000 880.0000 1.0000
42.2400 896.0000 1.0000
42.2800 845.0000 1.0000
42.3200 835.0000 1.0000
42.3600 857.0000 1.0000
42.4000 872.0000 1.0000
42.4400 805.0000 1.0000
42.4800 811.0000 1.0000
42.5200 852.0000 1.0000
42.5600 819.0000 1.0000
42.6000 840.0000 1.0000
42.6400 816.0000 1.0000
42.6800 861.0000 1.0000
42.7200 843.0000 1.0000
42.7600 883.0000 1.0000
42.8000 852.0000 1.0000
42.8400 870.0000 1.0000
42.8800 863.0000 1.0000
42.9200 811.0000 1.0000
42.9600 832.0000 1.0000
43.0000 892.0000 1.0000
43.0400 864.0000 1.0000
43.0800 922.0000 1.0000
43.1200 857.0000 1.0000
43.1600 904.0000 1.0000
43.2000 944.0000 1.0000
43.2400 920.0000 1.0000
43.2800 874.0000 1.0000
43.3200 867.0000 1.0000
43.3600 870.0000 1.0000
43.4000 857.0000 1.0000
43.4400 824.0000 1.0000
43.4800 871.0000 1.0000
43.5200 836.0000 1.0000
43.5600 809.0000 1.0000
43.6000 809.0000 1.0000
43.6400 811.0000 1.0000
43.6800 817.0000 1.0000
43.7200 844.0000 1.0000
43.7600 825.0000 1.0000
43.8000 809.0000 1.0000
43.8400 845.0000 1.0000
43.8800 800.0000 1.0000
43.9200 854.0000 1.0000
43.9600 834.0000 1.0000
44.0000 781.0000 1.0000
44.0400 772.0000 1.0000
44.0800 839.0000 1.0000
44.1200 818.0000 1.0000
44.1600 800.0000 1.0000
44.2000 834.0000 1.0000
44.2400 799.0000 1.0000
44.2800 796.0000 1.0000
44.3200 803.0000 1.0000
44.3600 779.0000 1.0000
44.4000 783.0000 1.0000
44.4400 810.0000 1.0000
44.4800 764.0000 1.0000
44.5200 780.0000 1.0000
44.5600 774.0000 1.0000
44.6000 801.0000 1.0000
44.6400 819.0000 1.0000
44.6800 806.0000 1.0000
44.7200 786.0000 1.0000
44.7600 820.0000 1.0000
44.8000 858.0000 1.0000
44.8400 824.0000 1.0000
44.8800 805.0000 1.0000
44.9200 794.0000 1.0000
44.9600 812.0000 1.0000
45.0000 802.0000 1.0000
45.0400 862.0000 1.0000
45.0800 765.0000 1.0000
45.1200 787.0000 1.0000
45.1600 804.0000 1.0000
45.2000 757.0000 1.0000
45.2400 782.0000 1.0000
45.2800 797.0000 1.0000
45.3200 780.0000 1.0000
45.3600 802.0000 1.0000
45.4000 767.0000 1.0000
45.4400 781.0000 1.0000
45.4800 775.0000 1.0000
45.5200 773.0000 1.0000
45.5600 800.0000 1.0000
45.6000 811.0000 1.0000
45.6400 800.0000 1.0000
45.6800 767.0000 1.0000
45.7200 784.0000 1.0000
45.7600 771.0000 1.0000
45.8000 767.0000 1.0000
45.8400 796.0000 1.0000
45.8800 789.0000 1.0000
45.9200 747.0000 1.0000
45.9600 797.0000 1.0000
46.0000 783.0000 1.0000
46.0400 738.0000 1.0000
46.0800 770.0000 1.0000
46.1200 786.0000 1.0000
46.1600 777.0000 1.0000
46.2000 809.0000 1.0000
46.2400 777.0000 1.0000
46.2800 759.0000 1.0000
46.3200 743.0000 1.0000
46.3600 752.0000 1.0000
46.4000 785.0000 1.0000
46.4400 780.0000 1.0000
46.4800 734.0000 1.0000
46.5200 757.0000 1.0000
46.5600 751.0000 1.0000
46.6000 772.0000 1.0000
46.6400 750.0000 1.0000
46.6800 751.0000 1.0000
46.7200 763.0000 1.0000
46.7600 795.0000 1.0000
46.8000 762.0000 1.0000
46.8400 750.0000 1.0000
46.8800 780.0000 1.0000
46.9200 783.0000 1.0000
46.9600 774.0000 1.0000
47.0000 820.0000 1.0000
47.0400 805.0000 1.0000
47.0800 794.0000 1.0000
47.1200 769.0000 1.0000
47.1600 726.0000 1.0000
47.2000 786.0000 1.0000
47.2400 781.0000 1.0000
47.2800 767.0000 1.0000
47.3200 763.0000 1.0000
47.3600 806.0000 1.0000
47.4000 729.0000 1.0000
47.4400 729.0000 1.0000
47.4800 743.0000 1.0000
47.5200 698.0000 1.0000
47.5600 731.0000 1.0000
47.6000 745.0000 1.0000
47.6400 727.0000 1.0000
47.6800 736.0000 1.0000
47.7200 755.0000 1.0000
47.7600 716.0000 1.0000
47.8000 770.0000 1.0000
47.8400 752.0000 1.0000
47.8800 730.0000 1.0000
47.9200 751.0000 1.0000
47.9600 746.0000 1.0000
48.0000 733.0000 1.0000
48.0400 785.0000 1.0000
48.0800 767.0000 1.0000
48.1200 759.0000 1.0000
48.1600 741.0000 1.0000
48.2000 695.0000 1.0000
48.2400 721.0000 1.0000
48.2800 781.0000 1.0000
48.3200 755.0000 1.0000
48.3600 719.0000 1.0000
48.4000 722.0000 1.0000
48.4400 702.0000 1.0000
48.4800 751.0000 1.0000
48.5200 730.0000 1.0000
48.5600 731.0000 1.0000
48.6000 709.0000 1.0000
48.6400 731.0000 1.0000
48.6800 703.0000 1.0000
48.7200 736.0000 1.0000
48.7600 721.0000 1.0000
48.8000 763.0000 1.0000
48.8400 739.0000 1.0000
48.8800 745.0000 1.0000
48.9200 717.0000 1.0000
48.9600 735.0000 1.0000
49.0000 696.0000 1.0000
49.0400 688.0000 1.0000
49.0800 736.0000 1.0000
49.1200 706.0000 1.0000
49.1600 735.0000 1.0000
49.2000 674.0000 1.0000
49.2400 697.0000 1.0000
49.2800 776.0000 1.0000
49.3200 724.0000 1.0000
49.3600 739.0000 1.0000
49.4000 730.0000 1.0000
49.4400 734.0000 1.0000
49.4800 703.0000 1.0000
49.5200 696.0000 1.0000
49.5600 744.0000 1.0000
49.6000 689.0000 1.0000
49.6400 691.0000 1.0000
49.6800 725.0000 1.0000
49.7200 769.0000 1.0000
49.7600 714.0000 1.0000
49.8000 726.0000 1.0000
49.8400 723.0000 1.0000
49.8800 734.0000 1.0000
49.9200 734.0000 1.0000
49.9600 724.0000 1.0000
50.0000 775.0000 1.0000
50.0400 715.0000 1.0000
50.0800 704.0000 1.0000
50.1200 736.0000 1.0000
50.1600 738.0000 1.0000
50.2000 746.0000 1.0000
50.2400 762.0000 1.0000
50.2800 748.0000 1.0000
50.3200 746.0000 1.0000
50.3600 766.0000 1.0000
50.4000 734.0000 1.0000
50.4400 725.0000 1.0000
50.4800 755.0000 1.0000
50.5200 729.0000 1.0000
50.5600 724.0000 1.0000
50.6000 725.0000 1.0000
50.6400 739.0000 1.0000
50.6800 748.0000 1.0000
50.7200 761.0000 1.0000
50.7600 722.0000 1.0000
50.8000 703.0000 1.0000
50.8400 744.0000 1.0000
50.8800 753.0000 1.0000
50.9200 739.0000 1.0000
50.9600 701.0000 1.0000
51.0000 732.0000 1.0000
51.0400 734.0000 1.0000
51.0800 744.0000 1.0000
51.1200 761.0000 1.0000
51.1600 711.0000 1.0000
51.2000 730.0000 1.0000
51.2400 728.0000 1.0000
51.2800 730.0000 1.0000
51.3200 726.0000 1.0000
51.3600 756.0000 1.0000
51.4000 712.0000 1.0000
51.4400 760.0000 1.0000
51.4800 751.0000 1.0000
51.5200 790.0000 1.0000
51.5600 732.0000 1.0000
51.6000 756.0000 1.0000
51.6400 796.0000 1.0000
51.6800 758.0000 1.0000
51.7200 848.0000 1.0000
51.7600 811.0000 1.0000
51.8000 838.0000 1.0000
51.8400 794.0000 1.0000
51.8800 879.0000 1.0000
51.9200 964.0000 1.0000
51.9600 1081.0000 1.0000
52.0000 1197.0000 1.0000
52.0400 1311.0000 1.0000
52.0800 1576.0000 1.0000
52.1200 2059.0000 1.0000
52.1600 2842.0000 1.0000
52.2000 3810.0000 1.0000
52.2400 4927.0000 1.0000
52.2800 5415.0000 1.0000
52.3200 5000.0000 1.0000
52.3600 4441.0000 1.0000
52.4000 3960.0000 1.0000
52.4400 3353.0000 1.0000
52.4800 2533.0000 1.0000
52.5200 1923.0000 1.0000
52.5600 1520.0000 1.0000
52.6000 1317.0000 1.0000
52.6400 1169.0000 1.0000
52.6800 982.0000 1.0000
52.7200 925.0000 1.0000
52.7600 910.0000 1.0000
52.8000 850.0000 1.0000
52.8400 838.0000 1.0000
52.8800 786.0000 1.0000
52.9200 834.0000 1.0000
52.9600 764.0000 1.0000
53.0000 800.0000 1.0000
53.0400 815.0000 1.0000
53.0800 743.0000 1.0000
53.1200 766.0000 1.0000
53.1600 768.0000 1.0000
53.2000 753.0000 1.0000
53.2400 749.0000 1.0000
53.2800 745.0000 1.0000
53.3200 767.0000 1.0000
53.3600 735.0000 1.0000
53.4000 743.0000 1.0000
53.4400 756.0000 1.0000
53.4800 726.0000 1.0000
53.5200 737.0000 1.0000
53.5600 728.0000 1.0000
53.6000 719.0000 1.0000
53.6400 699.0000 1.0000
53.6800 682.0000 1.0000
53.7200 704.0000 1.0000
53.7600 749.0000 1.0000
53.8000 747.0000 1.0000
53.8400 732.0000 1.0000
53.8800 738.0000 1.0000
53.9200 692.0000 1.0000
53.9600 735.0000 1.0000
54.0000 717.0000 1.0000
54.0400 672.0000 1.0000
54.0800 744.0000 1.0000
54.1200 704.0000 1.0000
54.1600 665.0000 1.0000
54.2000 704.0000 1.0000
54.2400 731.0000 1.0000
54.2800 701.0000 1.0000
54.3200 715.0000 1.0000
54.3600 741.0000 1.0000
54.4000 740.0000 1.0000
54.4400 713.0000 1.0000
54.4800 717.0000 1.0000
54.5200 726.0000 1.0000
54.5600 737.0000 1.0000
54.6000 676.0000 1.0000
54.6400 710.0000 1.0000
54.6800 717.0000 1.0000
54.7200 747.0000 1.0000
54.7600 719.0000 1.0000
54.8000 781.0000 1.0000
54.8400 760.0000 1.0000
54.8800 754.0000 1.0000
54.9200 741.0000 1.0000
54.9600 745.0000 1.0000
55.0000 775.0000 1.0000
55.0400 818.0000 1.0000
55.0800 832.0000 1.0000
55.1200 863.0000 1.0000
55.1600 941.0000 1.0000
55.2000 947.0000 1.0000
55.2400 1070.0000 1.0000
55.2800 1128.0000 1.0000
55.3200 1071.0000 1.0000
55.3600 1048.0000 1.0000
55.4000 1107.0000 1.0000
55.4400 967.0000 1.0000
55.4800 930.0000 1.0000
55.5200 879.0000 1.0000
55.5600 818.0000 1.0000
55.6000 813.0000 1.0000
55.6400 759.0000 1.0000
55.6800 746.0000 1.0000
55.7200 714.0000 1.0000
55.7600 774.0000 1.0000
55.8000 675.0000 1.0000
55.8400 696.0000 1.0000
55.8800 731.0000 1.0000
55.9200 673.0000 1.0000
55.9600 694.0000 1.0000
56.0000 691.0000 1.0000
56.0400 666.0000 1.0000
56.0800 718.0000 1.0000
56.1200 702.0000 1.0000
56.1600 694.0000 1.0000
56.2000 703.0000 1.0000
56.2400 666.0000 1.0000
56.2800 688.0000 1.0000
56.3200 697.0000 1.0000
56.3600 707.0000 1.0000
56.4000 646.0000 1.0000
56.4400 708.0000 1.0000
56.4800 685.0000 1.0000
56.5200 648.0000 1.0000
56.5600 678.0000 1.0000
56.6000 711.0000 1.0000
56.6400 669.0000 1.0000
56.6800 644.0000 1.0000
56.7200 729.0000 1.0000
56.7600 678.0000 1.0000
56.8000 673.0000 1.0000
56.8400 694.0000 1.0000
56.8800 711.0000 1.0000
56.9200 687.0000 1.0000
56.9600 701.0000 1.0000
57.0000 691.0000 1.0000
57.0400 745.0000 1.0000
57.0800 689.0000 1.0000
57.1200 682.0000 1.0000
57.1600 721.0000 1.0000
57.2000 692.0000 1.0000
57.2400 690.0000 1.0000
57.2800 701.0000 1.0000
57.3200 666.0000 1.0000
57.3600 693.0000 1.0000
57.4000 688.0000 1.0000
57.4400 681.0000 1.0000
57.4800 738.0000 1.0000
57.5200 672.0000 1.0000
57.5600 643.0000 1.0000
57.6000 671.0000 1.0000
57.6400 670.0000 1.0000
57.6800 673.0000 1.0000
57.7200 674.0000 1.0000
57.7600 684.0000 1.0000
57.8000 672.0000 1.0000
57.8400 663.0000 1.0000
57.8800 655.0000 1.0000
57.9200 686.0000 1.0000
57.9600 677.0000 1.0000
58.0000 677.0000 1.0000
58.0400 710.0000 1.0000
58.0800 675.0000 1.0000
58.1200 673.0000 1.0000
58.1600 699.0000 1.0000
58.2000 667.0000 1.0000
58.2400 700.0000 1.0000
58.2800 735.0000 1.0000
58.3200 685.0000 1.0000
58.3600 683.0000 1.0000
58.4000 700.0000 1.0000
58.4400 721.0000 1.0000
58.4800 674.0000 1.0000
58.5200 686.0000 1.0000
58.5600 673.0000 1.0000
58.6000 675.0000 1.0000
58.6400 650.0000 1.0000
58.6800 692.0000 1.0000
58.7200 642.0000 1.0000
58.7600 699.0000 1.0000
58.8000 674.0000 1.0000
58.8400 696.0000 1.0000
58.8800 705.0000 1.0000
58.9200 660.0000 1.0000
58.9600 669.0000 1.0000
59.0000 698.0000 1.0000
59.0400 689.0000 1.0000
59.0800 640.0000 1.0000
59.1200 713.0000 1.0000
59.1600 634.0000 1.0000
59.2000 727.0000 1.0000
59.2400 709.0000 1.0000
59.2800 702.0000 1.0000
59.3200 664.0000 1.0000
59.3600 712.0000 1.0000
59.4000 702.0000 1.0000
59.4400 654.0000 1.0000
59.4800 736.0000 1.0000
59.5200 699.0000 1.0000
59.5600 659.0000 1.0000
59.6000 654.0000 1.0000
59.6400 682.0000 1.0000
59.6800 692.0000 1.0000
59.7200 635.0000 1.0000
59.7600 700.0000 1.0000
59.8000 673.0000 1.0000
59.8400 685.0000 1.0000
59.8800 717.0000 1.0000
59.9200 677.0000 1.0000
59.9600 656.0000 1.0000
60.0000 691.0000 1.0000
60.0400 627.0000 1.0000
60.0800 683.0000 1.0000
60.1200 648.0000 1.0000
60.1600 650.0000 1.0000
60.2000 678.0000 1.0000
60.2400 666.0000 1.0000
60.2800 667.0000 1.0000
60.3200 668.0000 1.0000
60.3600 644.0000 1.0000
60.4000 637.0000 1.0000
60.4400 674.0000 1.0000
60.4800 672.0000 1.0000
60.5200 658.0000 1.0000
60.5600 697.0000 1.0000
60.6000 681.0000 1.0000
60.6400 698.0000 1.0000
60.6800 680.0000 1.0000
60.7200 690.0000 1.0000
60.7600 700.0000 1.0000
60.8000 675.0000 1.0000
60.8400 666.0000 1.0000
60.8800 698.0000 1.0000
60.9200 706.0000 1.0000
60.9600 693.0000 1.0000
61.0000 686.0000 1.0000
61.0400 670.0000 1.0000
61.0800 712.0000 1.0000
61.1200 669.0000 1.0000
61.1600 676.0000 1.0000
61.2000 673.0000 1.0000
61.2400 655.0000 1.0000
61.2800 662.0000 1.0000
61.3200 709.0000 1.0000
61.3600 654.0000 1.0000
61.4000 691.0000 1.0000
61.4400 688.0000 1.0000
61.4800 692.0000 1.0000
61.5200 679.0000 1.0000
61.5600 693.0000 1.0000
61.6000 694.0000 1.0000
61.6400 645.0000 1.0000
61.6800 719.0000 1.0000
61.7200 707.0000 1.0000
61.7600 721.0000 1.0000
61.8000 747.0000 1.0000
61.8400 687.0000 1.0000
61.8800 749.0000 1.0000
61.9200 757.0000 1.0000
61.9600 815.0000 1.0000
62.0000 848.0000 1.0000
62.0400 921.0000 1.0000
62.0800 1008.0000 1.0000
62.1200 1109.0000 1.0000
62.1600 1243.0000 1.0000
62.2000 1417.0000 1.0000
62.2400 1546.0000 1.0000
62.2800 1591.0000 1.0000
62.3200 1569.0000 1.0000
62.3600 1523.0000 1.0000
62.4000 1496.0000 1.0000
62.4400 1372.0000 1.0000
62.4800 1285.0000 1.0000
62.5200 1161.0000 1.0000
62.5600 1124.0000 1.0000
62.6000 983.0000 1.0000
62.6400 938.0000 1.0000
62.6800 898.0000 1.0000
62.7200 850.0000 1.0000
62.7600 817.0000 1.0000
62.8000 811.0000 1.0000
62.8400 806.0000 1.0000
62.8800 740.0000 1.0000
62.9200 774.0000 1.0000
62.9600 766.0000 1.0000
63.0000 734.0000 1.0000
63.0400 730.0000 1.0000
63.0800 726.0000 1.0000
63.1200 753.0000 1.0000
63.1600 738.0000 1.0000
63.2000 723.0000 1.0000
63.2400 786.0000 1.0000
63.2800 717.0000 1.0000
63.3200 726.0000 1.0000
63.3600 705.0000 1.0000
63.4000 691.0000 1.0000
63.4400 707.0000 1.0000
63.4800 686.0000 1.0000
63.5200 684.0000 1.0000
63.5600 683.0000 1.0000
63.6000 639.0000 1.0000
63.6400 681.0000 1.0000
63.6800 699.0000 1.0000
63.7200 691.0000 1.0000
63.7600 682.0000 1.0000
63.8000 703.0000 1.0000
63.8400 656.0000 1.0000
63.8800 684.0000 1.0000
63.9200 674.0000 1.0000
63.9600 664.0000 1.0000
64.0000 634.0000 1.0000
64.0400 678.0000 1.0000
64.0800 706.0000 1.0000
64.1200 712.0000 1.0000
64.1600 662.0000 1.0000
64.2000 728.0000 1.0000
64.2400 718.0000 1.0000
64.2800 726.0000 1.0000
64.3200 686.0000 1.0000
64.3600 680.0000 1.0000
64.4000 711.0000 1.0000
64.4400 772.0000 1.0000
64.4800 718.0000 1.0000
64.5200 776.0000 1.0000
64.5600 757.0000 1.0000
64.6000 818.0000 1.0000
64.6400 868.0000 1.0000
64.6800 921.0000 1.0000
64.7200 923.0000 1.0000
64.7600 862.0000 1.0000
64.8000 845.0000 1.0000
64.8400 872.0000 1.0000
64.8800 824.0000 1.0000
64.9200 819.0000 1.0000
64.9600 778.0000 1.0000
65.0000 723.0000 1.0000
65.0400 728.0000 1.0000
65.0800 724.0000 1.0000
65.1200 730.0000 1.0000
65.1600 723.0000 1.0000
65.2000 726.0000 1.0000
65.2400 731.0000 1.0000
65.2800 704.0000 1.0000
65.3200 670.0000 1.0000
65.3600 695.0000 1.0000
65.4000 706.0000 1.0000
65.4400 695.0000 1.0000
65.4800 727.0000 1.0000
65.5200 789.0000 1.0000
65.5600 732.0000 1.0000
65.6000 758.0000 1.0000
65.6400 766.0000 1.0000
65.6800 712.0000 1.0000
65.7200 760.0000 1.0000
65.7600 731.0000 1.0000
65.8000 782.0000 1.0000
65.8400 854.0000 1.0000
65.8800 840.0000 1.0000
65.9200 875.0000 1.0000
65.9600 995.0000 1.0000
66.0000 1051.0000 1.0000
66.0400 1166.0000 1.0000
66.0800 1391.0000 1.0000
66.1200 1565.0000 1.0000
66.1600 1936.0000 1.0000
66.2000 2414.0000 1.0000
66.2400 2657.0000 1.0000
66.2800 2788.0000 1.0000
66.3200 2655.0000 1.0000
66.3600 2429.0000 1.0000
66.4000 2336.0000 1.0000
66.4400 2211.0000 1.0000
66.4800 1983.0000 1.0000
66.5200 1739.0000 1.0000
66.5600 1487.0000 1.0000
66.6000 1316.0000 1.0000
66.6400 1109.0000 1.0000
66.6800 1031.0000 1.0000
66.7200 954.0000 1.0000
66.7600 846.0000 1.0000
66.8000 804.0000 1.0000
66.8400 774.0000 1.0000
66.8800 724.0000 1.0000
66.9200 744.0000 1.0000
66.9600 732.0000 1.0000
67.0000 713.0000 1.0000
67.0400 705.0000 1.0000
67.0800 683.0000 1.0000
67.1200 649.0000 1.0000
67.1600 694.0000 1.0000
67.2000 697.0000 1.0000
67.2400 644.0000 1.0000
67.2800 680.0000 1.0000
67.3200 686.0000 1.0000
67.3600 649.0000 1.0000
67.4000 669.0000 1.0000
67.4400 611.0000 1.0000
67.4800 654.0000 1.0000
67.5200 653.0000 1.0000
67.5600 671.0000 1.0000
67.6000 661.0000 1.0000
67.6400 621.0000 1.0000
67.6800 639.0000 1.0000
67.7200 618.0000 1.0000
67.7600 679.0000 1.0000
67.8000 662.0000 1.0000
67.8400 652.0000 1.0000
67.8800 596.0000 1.0000
67.9200 615.0000 1.0000
67.9600 612.0000 1.0000
68.0000 620.0000 1.0000
68.0400 628.0000 1.0000
68.0800 628.0000 1.0000
68.1200 604.0000 1.0000
68.1600 633.0000 1.0000
68.2000 649.0000 1.0000
68.2400 659.0000 1.0000
68.2800 625.0000 1.0000
68.3200 661.0000 1.0000
68.3600 664.0000 1.0000
68.4000 609.0000 1.0000
68.4400 621.0000 1.0000
68.4800 571.0000 1.0000
68.5200 630.0000 1.0000
68.5600 590.0000 1.0000
68.6000 605.0000 1.0000
68.6400 617.0000 1.0000
68.6800 635.0000 1.0000
68.7200 611.0000 1.0000
68.7600 576.0000 1.0000
68.8000 589.0000 1.0000
68.8400 641.0000 1.0000
68.8800 630.0000 1.0000
68.9200 612.0000 1.0000
68.9600 624.0000 1.0000
69.0000 630.0000 1.0000
69.0400 589.0000 1.0000
69.0800 619.0000 1.0000
69.1200 607.0000 1.0000
69.1600 622.0000 1.0000
69.2000 592.0000 1.0000
69.2400 591.0000 1.0000
69.2800 622.0000 1.0000
69.3200 622.0000 1.0000
69.3600 591.0000 1.0000
69.4000 607.0000 1.0000
69.4400 602.0000 1.0000
69.4800 603.0000 1.0000
69.5200 632.0000 1.0000
69.5600 619.0000 1.0000
69.6000 666.0000 1.0000
69.6400 626.0000 1.0000
69.6800 612.0000 1.0000
69.7200 607.0000 1.0000
69.7600 613.0000 1.0000
69.8000 649.0000 1.0000
69.8400 585.0000 1.0000
69.8800 604.0000 1.0000
69.9200 633.0000 1.0000
69.9600 602.0000 1.0000
70.0000 550.0000 1.0000
*RAS_INT_END
*RAS_TEMPERATURE_START
*RAS_TEMPERATURE_END
*RAS_DATA_END