File: Data/Dataset1_Only_water/5_XRD/No_017_FS5_1.ras
*RAS_DATA_START
*RAS_HEADER_START
*DISP_FMT_X "%.2f"
*DISP_FMT_Y "%.0f"
*DISP_FULLSCALE "14492.0000000000"
*DISP_LINE_COLOR "255.0000000000"
*DISP_LINE_STYLE "0.0000000000"
*DISP_LINE_WIDTH "0.2500000000"
*DISP_NOTE "測定データ-1"
*DISP_OFFSET_Y "0.0000000000"
*DISP_PEAKSEARCH_UNIT_Y "cps"
*DISP_RANGE_BOTTOM "0.0000000000"
*DISP_RANGE_LEFT "20.0000000000"
*DISP_RANGE_LOGCUTOFF "0.0100000000"
*DISP_RANGE_RIGHT "70.0000000000"
*DISP_RANGE_TOP "14492.0000000000"
*DISP_SCALE_MODE_Y "0.0000000000"
*DISP_TAB_NAME "2θ/θ"
*DISP_TITLE_Y "強度"
*DISP_UNIT_Y "cps"
*DISP_WINDOW_NAME "MSG_MACROENGINE"
*FILE_COMMENT " "
*FILE_MD5 ""
*FILE_MEMO " "
*FILE_OPERATOR "Administrator"
*FILE_SAMPLE " "
*FILE_TYPE "RAS_RAW"
*FILE_USERGROUP "システムマネージャ"
*FILE_VERSION "1.0000000000"
*HW_ATTACHMENT_ID "ATT0025"
*HW_ATTACHMENT_NAME "標準|Standard"
*HW_COUNTER_ID-0 "CUT0025"
*HW_COUNTER_ID-1 "CUT0020"
*HW_COUNTER_ID-2 "CUT0020"
*HW_COUNTER_ID-3 "CSL0021"
*HW_COUNTER_ID-4 "CMC0021"
*HW_COUNTER_NAME-0 "D/teX Ultra|D/teX Ultra"
*HW_COUNTER_NAME-1 "None|None"
*HW_COUNTER_NAME-2 "None|None"
*HW_COUNTER_NAME-3 "BBM|BBM"
*HW_COUNTER_NAME-4 "検出器モノクロメータ|Detector monochromator"
*HW_COUNTER_SELECT_NAME "D/teX Ultra|D/teX Ultra"
*HW_GONIOMETER_ID "GON0023"
*HW_GONIOMETER_NAME "SmartLab|SmartLab"
*HW_GONIOMETER_RADIUS-0 "90.0"
*HW_GONIOMETER_RADIUS-1 "114.0"
*HW_GONIOMETER_RADIUS-2 "190.0"
*HW_GONIOMETER_RADIUS-3 "300.0"
*HW_GONIOMETER_RADIUS-4 "187.0"
*HW_GONIOMETER_RADIUS-5 "300.0"
*HW_GONIOMETER_RADIUS-6 "113.0"
*HW_GONIOMETER_RADIUS-7 "331.0"
*HW_I_OPT_ID-0 "CBO0021"
*HW_I_OPT_ID-1 "ICR0023"
*HW_I_OPT_ID-2 "ISL0021"
*HW_I_OPT_ID-3 "ISO0021"
*HW_I_OPT_ID-4 "IAD0021"
*HW_I_OPT_ID-5 "IPR0001"
*HW_I_OPT_NAME-0 "CBOユニット|CBO unit"
*HW_I_OPT_NAME-1 "標準入射光学ユニット|Standard incident optical unit"
*HW_I_OPT_NAME-2 "標準入射スリットボックス|Standard incident slit box"
*HW_I_OPT_NAME-3 "入射平行スリット|Incident parallel slit"
*HW_I_OPT_NAME-4 "長手制限スリット|Length limiting slit"
*HW_I_OPT_NAME-5 "None|None"
*HW_R_ATTENUATER_AUTOMODE "0"
*HW_R_OPT_ID-0 "RSS0021"
*HW_R_OPT_ID-1 "RCR0023"
*HW_R_OPT_ID-2 "RSO0021"
*HW_R_OPT_ID-3 "RRS0021"
*HW_R_OPT_ID-4 "ATN0021"
*HW_R_OPT_ID-5 "RFL0021"
*HW_R_OPT_ID-6 "RAD0021"
*HW_R_OPT_NAME-0 "標準受光スリットボックス1|Standard receiving slit box # 1"
*HW_R_OPT_NAME-1 "標準受光光学ユニット1|Standard receiving unit # 1"
*HW_R_OPT_NAME-2 "標準受光光学ユニット2|Standard receiving optical unit # 2"
*HW_R_OPT_NAME-3 "標準受光スリットボックス2|Standard receiving slit box # 2"
*HW_R_OPT_NAME-4 "標準アッテネータ|Standard Attenuator"
*HW_R_OPT_NAME-5 "Cu Kβ|Cu K-beta"
*HW_R_OPT_NAME-6 "調整用受光スリット|Alignment receiving slit"
*HW_SAMPLE_HOLDER_ID "SMP0023"
*HW_SAMPLE_HOLDER_NAME "標準Zステージ|Standard Z stage"
*HW_XG_CURRENT_MAX "50"
*HW_XG_CURRENT_MIN "2"
*HW_XG_CURRENT_RESOLUTION "1"
*HW_XG_CURRENT_UNIT "mA"
*HW_XG_FOCUS "1mm x 10mm"
*HW_XG_FOCUS_TYPE "Normal"
*HW_XG_ID ""
*HW_XG_NAME "3kW 封入管(ID:1200)|3kW Sealed tube(ID:1200)"
*HW_XG_TARGET_ATOMIC_NUMBER "29.0000000000"
*HW_XG_TARGET_NAME "Cu"
*HW_XG_TYPE "Hermetic"
*HW_XG_VOLTAGE_MAX "60"
*HW_XG_VOLTAGE_MIN "20"
*HW_XG_VOLTAGE_RESOLUTION "1"
*HW_XG_VOLTAGE_UNIT "kV"
*HW_XG_WATT_MAX "1.500"
*HW_XG_WATT_UNIT "kW"
*HW_XG_WAVE_LENGTH_ALPHA1 "1.540593"
*HW_XG_WAVE_LENGTH_ALPHA2 "1.544414"
*HW_XG_WAVE_LENGTH_BETA "1.392250"
*MEAS_COND_AXIS_NAME-0 "2θ/θ"
*MEAS_COND_AXIS_NAME-1 "2θ"
*MEAS_COND_AXIS_NAME-2 "ω"
*MEAS_COND_AXIS_NAME-3 "Z"
*MEAS_COND_AXIS_NAME-4 "2θ/ω"
*MEAS_COND_AXIS_NAME-5 "θs"
*MEAS_COND_AXIS_NAME-6 "θd"
*MEAS_COND_AXIS_NAME-7 "Ts"
*MEAS_COND_AXIS_NAME-8 "CBO選択スリット"
*MEAS_COND_AXIS_NAME-9 "M"
*MEAS_COND_AXIS_NAME-10 "入射平行スリット"
*MEAS_COND_AXIS_NAME-11 "入射スリット"
*MEAS_COND_AXIS_NAME-12 ""
*MEAS_COND_AXIS_NAME-13 "Zs"
*MEAS_COND_AXIS_NAME-14 "入射光学素子"
*MEAS_COND_AXIS_NAME-15 "長手制限スリット"
*MEAS_COND_AXIS_NAME-16 "センタースリット"
*MEAS_COND_AXIS_NAME-17 "フィルター"
*MEAS_COND_AXIS_NAME-18 "受光スリット1"
*MEAS_COND_AXIS_NAME-19 "受光スリット2"
*MEAS_COND_AXIS_NAME-20 "受光光学素子"
*MEAS_COND_AXIS_NAME-21 "受光平行スリット"
*MEAS_COND_AXIS_NAME-22 "調整用受光スリット"
*MEAS_COND_AXIS_NAME-23 ""
*MEAS_COND_AXIS_NAME-24 ""
*MEAS_COND_AXIS_NAME-25 "Zd"
*MEAS_COND_AXIS_NAME-26 "アッテネータ"
*MEAS_COND_AXIS_NAME-27 "検出器モノクロメータ"
*MEAS_COND_AXIS_NAME-28 "モノクロメータスリット"
*MEAS_COND_AXIS_NAME-29 "プライマリビーム"
*MEAS_COND_AXIS_NAME-30 "PHA"
*MEAS_COND_AXIS_NAME_INTERNAL-0 "TwoThetaTheta"
*MEAS_COND_AXIS_NAME_INTERNAL-1 "TwoTheta"
*MEAS_COND_AXIS_NAME_INTERNAL-2 "Omega"
*MEAS_COND_AXIS_NAME_INTERNAL-3 "Z"
*MEAS_COND_AXIS_NAME_INTERNAL-4 "TwoThetaOmega"
*MEAS_COND_AXIS_NAME_INTERNAL-5 "ThetaS"
*MEAS_COND_AXIS_NAME_INTERNAL-6 "ThetaD"
*MEAS_COND_AXIS_NAME_INTERNAL-7 "Ts"
*MEAS_COND_AXIS_NAME_INTERNAL-8 "CBO"
*MEAS_COND_AXIS_NAME_INTERNAL-9 "CBO-M"
*MEAS_COND_AXIS_NAME_INTERNAL-10 "IncidentSollerSlit"
*MEAS_COND_AXIS_NAME_INTERNAL-11 "IncidentSlitBox"
*MEAS_COND_AXIS_NAME_INTERNAL-12 "IncidentSlitBox-_Axis"
*MEAS_COND_AXIS_NAME_INTERNAL-13 "Zs"
*MEAS_COND_AXIS_NAME_INTERNAL-14 "IncidentMonochromator"
*MEAS_COND_AXIS_NAME_INTERNAL-15 "IncidentAxdSlit"
*MEAS_COND_AXIS_NAME_INTERNAL-16 "CenterSlit"
*MEAS_COND_AXIS_NAME_INTERNAL-17 "Filter"
*MEAS_COND_AXIS_NAME_INTERNAL-18 "ReceivingSlitBox1"
*MEAS_COND_AXIS_NAME_INTERNAL-19 "ReceivingSlitBox2"
*MEAS_COND_AXIS_NAME_INTERNAL-20 "ReceivingOptics"
*MEAS_COND_AXIS_NAME_INTERNAL-21 "ReceivingSollerSlit"
*MEAS_COND_AXIS_NAME_INTERNAL-22 "ReceivingAxdSlit"
*MEAS_COND_AXIS_NAME_INTERNAL-23 "ReceivingSlitBox1-_Axis"
*MEAS_COND_AXIS_NAME_INTERNAL-24 "ReceivingSlitBox2-_Axis"
*MEAS_COND_AXIS_NAME_INTERNAL-25 "ReceivingSlitBox2-Zd"
*MEAS_COND_AXIS_NAME_INTERNAL-26 "Attenuator"
*MEAS_COND_AXIS_NAME_INTERNAL-27 "CounterMonochromator"
*MEAS_COND_AXIS_NAME_INTERNAL-28 "CounterSlit"
*MEAS_COND_AXIS_NAME_INTERNAL-29 "IncidentPrimary"
*MEAS_COND_AXIS_NAME_INTERNAL-30 "PHA"
*MEAS_COND_AXIS_NAME_MAGICNO-0 "83951616.0000000000"
*MEAS_COND_AXIS_NAME_MAGICNO-1 "268632064.0000000000"
*MEAS_COND_AXIS_NAME_MAGICNO-2 "268500992.0000000000"
*MEAS_COND_AXIS_NAME_MAGICNO-3 "285278208.0000000000"
*MEAS_COND_AXIS_NAME_MAGICNO-4 "83951616.0000000000"
*MEAS_COND_AXIS_NAME_MAGICNO-5 "131072.0000000000"
*MEAS_COND_AXIS_NAME_MAGICNO-6 "131072.0000000000"
*MEAS_COND_AXIS_NAME_MAGICNO-7 "318898176.0000000000"
*MEAS_COND_AXIS_NAME_MAGICNO-8 "20971521.0000000000"
*MEAS_COND_AXIS_NAME_MAGICNO-9 "285343744.0000000000"
*MEAS_COND_AXIS_NAME_MAGICNO-10 "20971521.0000000000"
*MEAS_COND_AXIS_NAME_MAGICNO-11 "22020097.0000000000"
*MEAS_COND_AXIS_NAME_MAGICNO-12 "25165824.0000000000"
*MEAS_COND_AXIS_NAME_MAGICNO-13 "318898176.0000000000"
*MEAS_COND_AXIS_NAME_MAGICNO-14 "1.0000000000"
*MEAS_COND_AXIS_NAME_MAGICNO-15 "20971521.0000000000"
*MEAS_COND_AXIS_NAME_MAGICNO-16 "20971521.0000000000"
*MEAS_COND_AXIS_NAME_MAGICNO-17 "20971521.0000000000"
*MEAS_COND_AXIS_NAME_MAGICNO-18 "23068673.0000000000"
*MEAS_COND_AXIS_NAME_MAGICNO-19 "23068673.0000000000"
*MEAS_COND_AXIS_NAME_MAGICNO-20 "20971521.0000000000"
*MEAS_COND_AXIS_NAME_MAGICNO-21 "20971521.0000000000"
*MEAS_COND_AXIS_NAME_MAGICNO-22 "20971521.0000000000"
*MEAS_COND_AXIS_NAME_MAGICNO-23 "25165824.0000000000"
*MEAS_COND_AXIS_NAME_MAGICNO-24 "25165824.0000000000"
*MEAS_COND_AXIS_NAME_MAGICNO-25 "285343744.0000000000"
*MEAS_COND_AXIS_NAME_MAGICNO-26 "17301505.0000000000"
*MEAS_COND_AXIS_NAME_MAGICNO-27 "20971521.0000000000"
*MEAS_COND_AXIS_NAME_MAGICNO-28 "20971521.0000000000"
*MEAS_COND_AXIS_NAME_MAGICNO-29 "20971521.0000000000"
*MEAS_COND_AXIS_NAME_MAGICNO-30 "0.0000000000"
*MEAS_COND_AXIS_OFFSET-0 "-"
*MEAS_COND_AXIS_OFFSET-1 "-0.1081000000"
*MEAS_COND_AXIS_OFFSET-2 "0.3758000000"
*MEAS_COND_AXIS_OFFSET-3 "-"
*MEAS_COND_AXIS_OFFSET-4 "-"
*MEAS_COND_AXIS_OFFSET-5 "0.3758000000"
*MEAS_COND_AXIS_OFFSET-6 "-0.4839000000"
*MEAS_COND_AXIS_OFFSET-7 "-"
*MEAS_COND_AXIS_OFFSET-8 "-"
*MEAS_COND_AXIS_OFFSET-9 "-"
*MEAS_COND_AXIS_OFFSET-10 "-"
*MEAS_COND_AXIS_OFFSET-11 "-"
*MEAS_COND_AXIS_OFFSET-12 "-"
*MEAS_COND_AXIS_OFFSET-13 "-"
*MEAS_COND_AXIS_OFFSET-14 "-"
*MEAS_COND_AXIS_OFFSET-15 "-"
*MEAS_COND_AXIS_OFFSET-16 "-"
*MEAS_COND_AXIS_OFFSET-17 "-"
*MEAS_COND_AXIS_OFFSET-18 "-"
*MEAS_COND_AXIS_OFFSET-19 "-"
*MEAS_COND_AXIS_OFFSET-20 "-"
*MEAS_COND_AXIS_OFFSET-21 "-"
*MEAS_COND_AXIS_OFFSET-22 "-"
*MEAS_COND_AXIS_OFFSET-23 "-"
*MEAS_COND_AXIS_OFFSET-24 "-"
*MEAS_COND_AXIS_OFFSET-25 "-"
*MEAS_COND_AXIS_OFFSET-26 "-"
*MEAS_COND_AXIS_OFFSET-27 "-"
*MEAS_COND_AXIS_OFFSET-28 "-"
*MEAS_COND_AXIS_OFFSET-29 "-"
*MEAS_COND_AXIS_OFFSET-30 "-"
*MEAS_COND_AXIS_POSITION-0 "0.0000000000"
*MEAS_COND_AXIS_POSITION-1 "0.0000000000"
*MEAS_COND_AXIS_POSITION-2 "0.0000000000"
*MEAS_COND_AXIS_POSITION-3 "-0.5500000000"
*MEAS_COND_AXIS_POSITION-4 "0.0000000000"
*MEAS_COND_AXIS_POSITION-5 "0.0000000000"
*MEAS_COND_AXIS_POSITION-6 "0.0000000000"
*MEAS_COND_AXIS_POSITION-7 "-0.4278800000"
*MEAS_COND_AXIS_POSITION-8 "BB"
*MEAS_COND_AXIS_POSITION-9 "0.0000000000"
*MEAS_COND_AXIS_POSITION-10 "Soller_slit_5.0deg"
*MEAS_COND_AXIS_POSITION-11 "2/3deg"
*MEAS_COND_AXIS_POSITION-12 "2.2088000000"
*MEAS_COND_AXIS_POSITION-13 "-0.4140600000"
*MEAS_COND_AXIS_POSITION-14 "0.0000000000"
*MEAS_COND_AXIS_POSITION-15 "10.0mm"
*MEAS_COND_AXIS_POSITION-16 "None"
*MEAS_COND_AXIS_POSITION-17 "Cu_K-beta"
*MEAS_COND_AXIS_POSITION-18 "13.000mm"
*MEAS_COND_AXIS_POSITION-19 "13.000mm"
*MEAS_COND_AXIS_POSITION-20 "No_unit"
*MEAS_COND_AXIS_POSITION-21 "Soller_slit_5.0deg"
*MEAS_COND_AXIS_POSITION-22 "None"
*MEAS_COND_AXIS_POSITION-23 "13.0000000000"
*MEAS_COND_AXIS_POSITION-24 "13.0000000000"
*MEAS_COND_AXIS_POSITION-25 "0.0109400000"
*MEAS_COND_AXIS_POSITION-26 "Open"
*MEAS_COND_AXIS_POSITION-27 "None"
*MEAS_COND_AXIS_POSITION-28 "None"
*MEAS_COND_AXIS_POSITION-29 "None"
*MEAS_COND_AXIS_POSITION-30 "38.0000000000"
*MEAS_COND_AXIS_UNIT-0 "deg"
*MEAS_COND_AXIS_UNIT-1 "deg"
*MEAS_COND_AXIS_UNIT-2 "deg"
*MEAS_COND_AXIS_UNIT-3 "mm"
*MEAS_COND_AXIS_UNIT-4 "deg"
*MEAS_COND_AXIS_UNIT-5 "deg"
*MEAS_COND_AXIS_UNIT-6 "deg"
*MEAS_COND_AXIS_UNIT-7 "mm"
*MEAS_COND_AXIS_UNIT-8 ""
*MEAS_COND_AXIS_UNIT-9 "pulse"
*MEAS_COND_AXIS_UNIT-10 ""
*MEAS_COND_AXIS_UNIT-11 ""
*MEAS_COND_AXIS_UNIT-12 "mm"
*MEAS_COND_AXIS_UNIT-13 "mm"
*MEAS_COND_AXIS_UNIT-14 ""
*MEAS_COND_AXIS_UNIT-15 ""
*MEAS_COND_AXIS_UNIT-16 ""
*MEAS_COND_AXIS_UNIT-17 ""
*MEAS_COND_AXIS_UNIT-18 ""
*MEAS_COND_AXIS_UNIT-19 ""
*MEAS_COND_AXIS_UNIT-20 ""
*MEAS_COND_AXIS_UNIT-21 ""
*MEAS_COND_AXIS_UNIT-22 ""
*MEAS_COND_AXIS_UNIT-23 "mm"
*MEAS_COND_AXIS_UNIT-24 "mm"
*MEAS_COND_AXIS_UNIT-25 "mm"
*MEAS_COND_AXIS_UNIT-26 ""
*MEAS_COND_AXIS_UNIT-27 ""
*MEAS_COND_AXIS_UNIT-28 ""
*MEAS_COND_AXIS_UNIT-29 ""
*MEAS_COND_AXIS_UNIT-30 "div"
*MEAS_COND_COUNTER_CNTLOSS_CORR "0.0000000000"
*MEAS_COND_COUNTER_PHABASE "38.0000000000"
*MEAS_COND_COUNTER_PHAWINDOW "16.0000000000"
*MEAS_COND_COUNTER_PHA_UNIT "div"
*MEAS_COND_COUNTER_TAUDIFF "30.0000000000"
*MEAS_COND_COUNTER_TAUINT "0.0000000000"
*MEAS_COND_IRRADIATION_MODE "OFF"
*MEAS_COND_IRRADIATION_WIDTH ""
*MEAS_COND_OPT_ATTR "集中法"
*MEAS_COND_OPT_NAME "@集中法"
*MEAS_COND_UNSYMMETRIC_MODE "OFF"
*MEAS_COND_XG_CURRENT "30.0000000000"
*MEAS_COND_XG_VOLTAGE "40.0000000000"
*MEAS_COND_XG_WAVE_TYPE "Ka"
*MEAS_DATA_COUNT "5001.0000000000"
*MEAS_SCAN_AXIS_X "2θ/θ"
*MEAS_SCAN_AXIS_X_INTERNAL "TwoThetaTheta"
*MEAS_SCAN_END_TIME "07/08/21 11:46:33"
*MEAS_SCAN_MODE "CONTINUOUS"
*MEAS_SCAN_MONITOR "0"
*MEAS_SCAN_RESOLUTION_X "0.0002"
*MEAS_SCAN_SPEED "1.0"
*MEAS_SCAN_SPEED_UNIT "deg/min"
*MEAS_SCAN_START "20.0000000000"
*MEAS_SCAN_START_TIME "07/08/21 10:53:40"
*MEAS_SCAN_STEP "0.0100000000"
*MEAS_SCAN_STOP "70.0000000000"
*MEAS_SCAN_UNIT_X "deg"
*MEAS_SCAN_UNIT_Y "counts"
*RAS_HEADER_END
*RAS_INT_START
20.0000 1757.0000 1.0000
20.0400 1730.0000 1.0000
20.0800 1764.0000 1.0000
20.1200 1791.0000 1.0000
20.1600 1851.0000 1.0000
20.2000 1803.0000 1.0000
20.2400 1775.0000 1.0000
20.2800 1717.0000 1.0000
20.3200 1809.0000 1.0000
20.3600 1701.0000 1.0000
20.4000 1775.0000 1.0000
20.4400 1772.0000 1.0000
20.4800 1736.0000 1.0000
20.5200 1782.0000 1.0000
20.5600 1805.0000 1.0000
20.6000 1763.0000 1.0000
20.6400 1828.0000 1.0000
20.6800 1788.0000 1.0000
20.7200 1724.0000 1.0000
20.7600 1729.0000 1.0000
20.8000 1788.0000 1.0000
20.8400 1802.0000 1.0000
20.8800 1773.0000 1.0000
20.9200 1712.0000 1.0000
20.9600 1747.0000 1.0000
21.0000 1713.0000 1.0000
21.0400 1736.0000 1.0000
21.0800 1735.0000 1.0000
21.1200 1790.0000 1.0000
21.1600 1746.0000 1.0000
21.2000 1780.0000 1.0000
21.2400 1703.0000 1.0000
21.2800 1753.0000 1.0000
21.3200 1754.0000 1.0000
21.3600 1752.0000 1.0000
21.4000 1777.0000 1.0000
21.4400 1745.0000 1.0000
21.4800 1768.0000 1.0000
21.5200 1758.0000 1.0000
21.5600 1767.0000 1.0000
21.6000 1833.0000 1.0000
21.6400 1760.0000 1.0000
21.6800 1712.0000 1.0000
21.7200 1738.0000 1.0000
21.7600 1783.0000 1.0000
21.8000 1770.0000 1.0000
21.8400 1758.0000 1.0000
21.8800 1751.0000 1.0000
21.9200 1798.0000 1.0000
21.9600 1818.0000 1.0000
22.0000 1727.0000 1.0000
22.0400 1765.0000 1.0000
22.0800 1830.0000 1.0000
22.1200 1782.0000 1.0000
22.1600 1793.0000 1.0000
22.2000 1805.0000 1.0000
22.2400 1802.0000 1.0000
22.2800 1788.0000 1.0000
22.3200 1792.0000 1.0000
22.3600 1792.0000 1.0000
22.4000 1715.0000 1.0000
22.4400 1750.0000 1.0000
22.4800 1740.0000 1.0000
22.5200 1728.0000 1.0000
22.5600 1733.0000 1.0000
22.6000 1755.0000 1.0000
22.6400 1824.0000 1.0000
22.6800 1755.0000 1.0000
22.7200 1795.0000 1.0000
22.7600 1776.0000 1.0000
22.8000 1827.0000 1.0000
22.8400 1776.0000 1.0000
22.8800 1783.0000 1.0000
22.9200 1781.0000 1.0000
22.9600 1789.0000 1.0000
23.0000 1772.0000 1.0000
23.0400 1797.0000 1.0000
23.0800 1758.0000 1.0000
23.1200 1804.0000 1.0000
23.1600 1756.0000 1.0000
23.2000 1793.0000 1.0000
23.2400 1727.0000 1.0000
23.2800 1800.0000 1.0000
23.3200 1786.0000 1.0000
23.3600 1803.0000 1.0000
23.4000 1802.0000 1.0000
23.4400 1787.0000 1.0000
23.4800 1755.0000 1.0000
23.5200 1728.0000 1.0000
23.5600 1784.0000 1.0000
23.6000 1824.0000 1.0000
23.6400 1729.0000 1.0000
23.6800 1867.0000 1.0000
23.7200 1797.0000 1.0000
23.7600 1820.0000 1.0000
23.8000 1839.0000 1.0000
23.8400 1795.0000 1.0000
23.8800 1802.0000 1.0000
23.9200 1759.0000 1.0000
23.9600 1809.0000 1.0000
24.0000 1853.0000 1.0000
24.0400 1774.0000 1.0000
24.0800 1804.0000 1.0000
24.1200 1811.0000 1.0000
24.1600 1754.0000 1.0000
24.2000 1860.0000 1.0000
24.2400 1752.0000 1.0000
24.2800 1756.0000 1.0000
24.3200 1802.0000 1.0000
24.3600 1884.0000 1.0000
24.4000 1722.0000 1.0000
24.4400 1822.0000 1.0000
24.4800 1814.0000 1.0000
24.5200 1767.0000 1.0000
24.5600 1786.0000 1.0000
24.6000 1825.0000 1.0000
24.6400 1837.0000 1.0000
24.6800 1822.0000 1.0000
24.7200 1829.0000 1.0000
24.7600 1852.0000 1.0000
24.8000 1870.0000 1.0000
24.8400 1818.0000 1.0000
24.8800 1874.0000 1.0000
24.9200 1857.0000 1.0000
24.9600 1875.0000 1.0000
25.0000 1966.0000 1.0000
25.0400 1913.0000 1.0000
25.0800 1856.0000 1.0000
25.1200 1872.0000 1.0000
25.1600 1922.0000 1.0000
25.2000 1813.0000 1.0000
25.2400 1852.0000 1.0000
25.2800 1905.0000 1.0000
25.3200 1832.0000 1.0000
25.3600 1894.0000 1.0000
25.4000 1825.0000 1.0000
25.4400 1898.0000 1.0000
25.4800 1764.0000 1.0000
25.5200 1860.0000 1.0000
25.5600 1911.0000 1.0000
25.6000 1822.0000 1.0000
25.6400 1828.0000 1.0000
25.6800 1897.0000 1.0000
25.7200 1859.0000 1.0000
25.7600 1822.0000 1.0000
25.8000 1830.0000 1.0000
25.8400 1875.0000 1.0000
25.8800 1845.0000 1.0000
25.9200 1824.0000 1.0000
25.9600 1786.0000 1.0000
26.0000 1793.0000 1.0000
26.0400 1852.0000 1.0000
26.0800 1810.0000 1.0000
26.1200 1775.0000 1.0000
26.1600 1829.0000 1.0000
26.2000 1768.0000 1.0000
26.2400 1818.0000 1.0000
26.2800 1806.0000 1.0000
26.3200 1885.0000 1.0000
26.3600 1871.0000 1.0000
26.4000 1873.0000 1.0000
26.4400 1811.0000 1.0000
26.4800 1877.0000 1.0000
26.5200 1841.0000 1.0000
26.5600 1873.0000 1.0000
26.6000 1879.0000 1.0000
26.6400 1921.0000 1.0000
26.6800 1845.0000 1.0000
26.7200 1902.0000 1.0000
26.7600 1925.0000 1.0000
26.8000 1969.0000 1.0000
26.8400 1983.0000 1.0000
26.8800 2053.0000 1.0000
26.9200 2139.0000 1.0000
26.9600 2159.0000 1.0000
27.0000 2458.0000 1.0000
27.0400 2601.0000 1.0000
27.0800 2889.0000 1.0000
27.1200 3228.0000 1.0000
27.1600 3972.0000 1.0000
27.2000 4790.0000 1.0000
27.2400 6001.0000 1.0000
27.2800 6899.0000 1.0000
27.3200 7140.0000 1.0000
27.3600 6148.0000 1.0000
27.4000 5031.0000 1.0000
27.4400 4057.0000 1.0000
27.4800 3410.0000 1.0000
27.5200 2947.0000 1.0000
27.5600 2578.0000 1.0000
27.6000 2438.0000 1.0000
27.6400 2226.0000 1.0000
27.6800 2109.0000 1.0000
27.7200 2075.0000 1.0000
27.7600 1995.0000 1.0000
27.8000 1998.0000 1.0000
27.8400 1923.0000 1.0000
27.8800 1883.0000 1.0000
27.9200 1876.0000 1.0000
27.9600 1866.0000 1.0000
28.0000 1772.0000 1.0000
28.0400 1761.0000 1.0000
28.0800 1743.0000 1.0000
28.1200 1761.0000 1.0000
28.1600 1731.0000 1.0000
28.2000 1815.0000 1.0000
28.2400 1730.0000 1.0000
28.2800 1712.0000 1.0000
28.3200 1725.0000 1.0000
28.3600 1751.0000 1.0000
28.4000 1695.0000 1.0000
28.4400 1722.0000 1.0000
28.4800 1715.0000 1.0000
28.5200 1660.0000 1.0000
28.5600 1714.0000 1.0000
28.6000 1660.0000 1.0000
28.6400 1671.0000 1.0000
28.6800 1607.0000 1.0000
28.7200 1724.0000 1.0000
28.7600 1639.0000 1.0000
28.8000 1687.0000 1.0000
28.8400 1688.0000 1.0000
28.8800 1647.0000 1.0000
28.9200 1660.0000 1.0000
28.9600 1631.0000 1.0000
29.0000 1619.0000 1.0000
29.0400 1620.0000 1.0000
29.0800 1653.0000 1.0000
29.1200 1644.0000 1.0000
29.1600 1641.0000 1.0000
29.2000 1644.0000 1.0000
29.2400 1598.0000 1.0000
29.2800 1614.0000 1.0000
29.3200 1655.0000 1.0000
29.3600 1688.0000 1.0000
29.4000 1634.0000 1.0000
29.4400 1534.0000 1.0000
29.4800 1599.0000 1.0000
29.5200 1574.0000 1.0000
29.5600 1608.0000 1.0000
29.6000 1584.0000 1.0000
29.6400 1555.0000 1.0000
29.6800 1616.0000 1.0000
29.7200 1575.0000 1.0000
29.7600 1596.0000 1.0000
29.8000 1561.0000 1.0000
29.8400 1563.0000 1.0000
29.8800 1647.0000 1.0000
29.9200 1555.0000 1.0000
29.9600 1564.0000 1.0000
30.0000 1621.0000 1.0000
30.0400 1554.0000 1.0000
30.0800 1534.0000 1.0000
30.1200 1582.0000 1.0000
30.1600 1508.0000 1.0000
30.2000 1496.0000 1.0000
30.2400 1562.0000 1.0000
30.2800 1580.0000 1.0000
30.3200 1603.0000 1.0000
30.3600 1593.0000 1.0000
30.4000 1559.0000 1.0000
30.4400 1528.0000 1.0000
30.4800 1576.0000 1.0000
30.5200 1482.0000 1.0000
30.5600 1607.0000 1.0000
30.6000 1507.0000 1.0000
30.6400 1478.0000 1.0000
30.6800 1520.0000 1.0000
30.7200 1514.0000 1.0000
30.7600 1470.0000 1.0000
30.8000 1469.0000 1.0000
30.8400 1517.0000 1.0000
30.8800 1548.0000 1.0000
30.9200 1499.0000 1.0000
30.9600 1478.0000 1.0000
31.0000 1486.0000 1.0000
31.0400 1513.0000 1.0000
31.0800 1511.0000 1.0000
31.1200 1486.0000 1.0000
31.1600 1453.0000 1.0000
31.2000 1507.0000 1.0000
31.2400 1460.0000 1.0000
31.2800 1480.0000 1.0000
31.3200 1493.0000 1.0000
31.3600 1501.0000 1.0000
31.4000 1484.0000 1.0000
31.4400 1464.0000 1.0000
31.4800 1430.0000 1.0000
31.5200 1496.0000 1.0000
31.5600 1436.0000 1.0000
31.6000 1498.0000 1.0000
31.6400 1490.0000 1.0000
31.6800 1447.0000 1.0000
31.7200 1526.0000 1.0000
31.7600 1434.0000 1.0000
31.8000 1469.0000 1.0000
31.8400 1433.0000 1.0000
31.8800 1385.0000 1.0000
31.9200 1487.0000 1.0000
31.9600 1471.0000 1.0000
32.0000 1501.0000 1.0000
32.0400 1546.0000 1.0000
32.0800 1507.0000 1.0000
32.1200 1418.0000 1.0000
32.1600 1407.0000 1.0000
32.2000 1427.0000 1.0000
32.2400 1431.0000 1.0000
32.2800 1390.0000 1.0000
32.3200 1363.0000 1.0000
32.3600 1391.0000 1.0000
32.4000 1390.0000 1.0000
32.4400 1406.0000 1.0000
32.4800 1398.0000 1.0000
32.5200 1357.0000 1.0000
32.5600 1432.0000 1.0000
32.6000 1393.0000 1.0000
32.6400 1402.0000 1.0000
32.6800 1368.0000 1.0000
32.7200 1343.0000 1.0000
32.7600 1438.0000 1.0000
32.8000 1320.0000 1.0000
32.8400 1354.0000 1.0000
32.8800 1410.0000 1.0000
32.9200 1394.0000 1.0000
32.9600 1427.0000 1.0000
33.0000 1373.0000 1.0000
33.0400 1321.0000 1.0000
33.0800 1340.0000 1.0000
33.1200 1352.0000 1.0000
33.1600 1369.0000 1.0000
33.2000 1304.0000 1.0000
33.2400 1339.0000 1.0000
33.2800 1326.0000 1.0000
33.3200 1389.0000 1.0000
33.3600 1355.0000 1.0000
33.4000 1336.0000 1.0000
33.4400 1309.0000 1.0000
33.4800 1325.0000 1.0000
33.5200 1376.0000 1.0000
33.5600 1349.0000 1.0000
33.6000 1344.0000 1.0000
33.6400 1332.0000 1.0000
33.6800 1375.0000 1.0000
33.7200 1322.0000 1.0000
33.7600 1376.0000 1.0000
33.8000 1461.0000 1.0000
33.8400 1483.0000 1.0000
33.8800 1505.0000 1.0000
33.9200 1572.0000 1.0000
33.9600 1503.0000 1.0000
34.0000 1585.0000 1.0000
34.0400 1527.0000 1.0000
34.0800 1507.0000 1.0000
34.1200 1504.0000 1.0000
34.1600 1528.0000 1.0000
34.2000 1557.0000 1.0000
34.2400 1685.0000 1.0000
34.2800 1749.0000 1.0000
34.3200 1884.0000 1.0000
34.3600 2234.0000 1.0000
34.4000 2624.0000 1.0000
34.4400 3076.0000 1.0000
34.4800 3514.0000 1.0000
34.5200 3359.0000 1.0000
34.5600 3157.0000 1.0000
34.6000 2658.0000 1.0000
34.6400 2287.0000 1.0000
34.6800 1897.0000 1.0000
34.7200 1797.0000 1.0000
34.7600 1657.0000 1.0000
34.8000 1536.0000 1.0000
34.8400 1490.0000 1.0000
34.8800 1375.0000 1.0000
34.9200 1388.0000 1.0000
34.9600 1348.0000 1.0000
35.0000 1260.0000 1.0000
35.0400 1325.0000 1.0000
35.0800 1289.0000 1.0000
35.1200 1254.0000 1.0000
35.1600 1212.0000 1.0000
35.2000 1273.0000 1.0000
35.2400 1230.0000 1.0000
35.2800 1193.0000 1.0000
35.3200 1230.0000 1.0000
35.3600 1204.0000 1.0000
35.4000 1215.0000 1.0000
35.4400 1188.0000 1.0000
35.4800 1187.0000 1.0000
35.5200 1180.0000 1.0000
35.5600 1148.0000 1.0000
35.6000 1161.0000 1.0000
35.6400 1158.0000 1.0000
35.6800 1136.0000 1.0000
35.7200 1127.0000 1.0000
35.7600 1154.0000 1.0000
35.8000 1199.0000 1.0000
35.8400 1148.0000 1.0000
35.8800 1099.0000 1.0000
35.9200 1139.0000 1.0000
35.9600 1097.0000 1.0000
36.0000 1131.0000 1.0000
36.0400 1122.0000 1.0000
36.0800 1135.0000 1.0000
36.1200 1199.0000 1.0000
36.1600 1251.0000 1.0000
36.2000 1183.0000 1.0000
36.2400 1231.0000 1.0000
36.2800 1410.0000 1.0000
36.3200 1603.0000 1.0000
36.3600 1884.0000 1.0000
36.4000 2132.0000 1.0000
36.4400 1950.0000 1.0000
36.4800 1823.0000 1.0000
36.5200 1582.0000 1.0000
36.5600 1363.0000 1.0000
36.6000 1184.0000 1.0000
36.6400 1175.0000 1.0000
36.6800 1127.0000 1.0000
36.7200 1126.0000 1.0000
36.7600 1045.0000 1.0000
36.8000 1070.0000 1.0000
36.8400 1109.0000 1.0000
36.8800 1093.0000 1.0000
36.9200 1070.0000 1.0000
36.9600 1029.0000 1.0000
37.0000 1099.0000 1.0000
37.0400 1036.0000 1.0000
37.0800 1097.0000 1.0000
37.1200 1051.0000 1.0000
37.1600 1065.0000 1.0000
37.2000 1077.0000 1.0000
37.2400 1112.0000 1.0000
37.2800 1063.0000 1.0000
37.3200 1069.0000 1.0000
37.3600 1058.0000 1.0000
37.4000 1089.0000 1.0000
37.4400 1024.0000 1.0000
37.4800 1034.0000 1.0000
37.5200 1098.0000 1.0000
37.5600 1014.0000 1.0000
37.6000 1061.0000 1.0000
37.6400 1070.0000 1.0000
37.6800 991.0000 1.0000
37.7200 1063.0000 1.0000
37.7600 1047.0000 1.0000
37.8000 1065.0000 1.0000
37.8400 1119.0000 1.0000
37.8800 1046.0000 1.0000
37.9200 1091.0000 1.0000
37.9600 1079.0000 1.0000
38.0000 1151.0000 1.0000
38.0400 1145.0000 1.0000
38.0800 1178.0000 1.0000
38.1200 1224.0000 1.0000
38.1600 1304.0000 1.0000
38.2000 1382.0000 1.0000
38.2400 1560.0000 1.0000
38.2800 1742.0000 1.0000
38.3200 2110.0000 1.0000
38.3600 2609.0000 1.0000
38.4000 3316.0000 1.0000
38.4400 4338.0000 1.0000
38.4800 5504.0000 1.0000
38.5200 6177.0000 1.0000
38.5600 6121.0000 1.0000
38.6000 5605.0000 1.0000
38.6400 4715.0000 1.0000
38.6800 3730.0000 1.0000
38.7200 2890.0000 1.0000
38.7600 2185.0000 1.0000
38.8000 1861.0000 1.0000
38.8400 1483.0000 1.0000
38.8800 1304.0000 1.0000
38.9200 1230.0000 1.0000
38.9600 1197.0000 1.0000
39.0000 1096.0000 1.0000
39.0400 1063.0000 1.0000
39.0800 1066.0000 1.0000
39.1200 1039.0000 1.0000
39.1600 985.0000 1.0000
39.2000 1026.0000 1.0000
39.2400 927.0000 1.0000
39.2800 973.0000 1.0000
39.3200 953.0000 1.0000
39.3600 923.0000 1.0000
39.4000 1011.0000 1.0000
39.4400 979.0000 1.0000
39.4800 992.0000 1.0000
39.5200 963.0000 1.0000
39.5600 1046.0000 1.0000
39.6000 926.0000 1.0000
39.6400 985.0000 1.0000
39.6800 991.0000 1.0000
39.7200 983.0000 1.0000
39.7600 945.0000 1.0000
39.8000 937.0000 1.0000
39.8400 897.0000 1.0000
39.8800 934.0000 1.0000
39.9200 865.0000 1.0000
39.9600 881.0000 1.0000
40.0000 893.0000 1.0000
40.0400 924.0000 1.0000
40.0800 925.0000 1.0000
40.1200 892.0000 1.0000
40.1600 861.0000 1.0000
40.2000 870.0000 1.0000
40.2400 901.0000 1.0000
40.2800 887.0000 1.0000
40.3200 863.0000 1.0000
40.3600 901.0000 1.0000
40.4000 888.0000 1.0000
40.4400 868.0000 1.0000
40.4800 904.0000 1.0000
40.5200 889.0000 1.0000
40.5600 859.0000 1.0000
40.6000 835.0000 1.0000
40.6400 914.0000 1.0000
40.6800 826.0000 1.0000
40.7200 902.0000 1.0000
40.7600 885.0000 1.0000
40.8000 822.0000 1.0000
40.8400 853.0000 1.0000
40.8800 842.0000 1.0000
40.9200 849.0000 1.0000
40.9600 860.0000 1.0000
41.0000 862.0000 1.0000
41.0400 855.0000 1.0000
41.0800 849.0000 1.0000
41.1200 864.0000 1.0000
41.1600 836.0000 1.0000
41.2000 858.0000 1.0000
41.2400 858.0000 1.0000
41.2800 871.0000 1.0000
41.3200 843.0000 1.0000
41.3600 842.0000 1.0000
41.4000 836.0000 1.0000
41.4400 806.0000 1.0000
41.4800 817.0000 1.0000
41.5200 900.0000 1.0000
41.5600 857.0000 1.0000
41.6000 843.0000 1.0000
41.6400 933.0000 1.0000
41.6800 882.0000 1.0000
41.7200 850.0000 1.0000
41.7600 802.0000 1.0000
41.8000 832.0000 1.0000
41.8400 881.0000 1.0000
41.8800 856.0000 1.0000
41.9200 881.0000 1.0000
41.9600 875.0000 1.0000
42.0000 845.0000 1.0000
42.0400 848.0000 1.0000
42.0800 907.0000 1.0000
42.1200 838.0000 1.0000
42.1600 809.0000 1.0000
42.2000 865.0000 1.0000
42.2400 831.0000 1.0000
42.2800 808.0000 1.0000
42.3200 873.0000 1.0000
42.3600 829.0000 1.0000
42.4000 852.0000 1.0000
42.4400 850.0000 1.0000
42.4800 875.0000 1.0000
42.5200 864.0000 1.0000
42.5600 859.0000 1.0000
42.6000 869.0000 1.0000
42.6400 812.0000 1.0000
42.6800 835.0000 1.0000
42.7200 840.0000 1.0000
42.7600 869.0000 1.0000
42.8000 838.0000 1.0000
42.8400 824.0000 1.0000
42.8800 881.0000 1.0000
42.9200 862.0000 1.0000
42.9600 902.0000 1.0000
43.0000 845.0000 1.0000
43.0400 867.0000 1.0000
43.0800 839.0000 1.0000
43.1200 916.0000 1.0000
43.1600 884.0000 1.0000
43.2000 953.0000 1.0000
43.2400 898.0000 1.0000
43.2800 927.0000 1.0000
43.3200 867.0000 1.0000
43.3600 883.0000 1.0000
43.4000 869.0000 1.0000
43.4400 854.0000 1.0000
43.4800 834.0000 1.0000
43.5200 857.0000 1.0000
43.5600 829.0000 1.0000
43.6000 865.0000 1.0000
43.6400 836.0000 1.0000
43.6800 885.0000 1.0000
43.7200 853.0000 1.0000
43.7600 803.0000 1.0000
43.8000 837.0000 1.0000
43.8400 782.0000 1.0000
43.8800 812.0000 1.0000
43.9200 790.0000 1.0000
43.9600 849.0000 1.0000
44.0000 799.0000 1.0000
44.0400 861.0000 1.0000
44.0800 807.0000 1.0000
44.1200 840.0000 1.0000
44.1600 829.0000 1.0000
44.2000 835.0000 1.0000
44.2400 833.0000 1.0000
44.2800 857.0000 1.0000
44.3200 820.0000 1.0000
44.3600 817.0000 1.0000
44.4000 807.0000 1.0000
44.4400 823.0000 1.0000
44.4800 810.0000 1.0000
44.5200 835.0000 1.0000
44.5600 779.0000 1.0000
44.6000 804.0000 1.0000
44.6400 819.0000 1.0000
44.6800 793.0000 1.0000
44.7200 818.0000 1.0000
44.7600 792.0000 1.0000
44.8000 785.0000 1.0000
44.8400 784.0000 1.0000
44.8800 798.0000 1.0000
44.9200 812.0000 1.0000
44.9600 788.0000 1.0000
45.0000 802.0000 1.0000
45.0400 761.0000 1.0000
45.0800 801.0000 1.0000
45.1200 775.0000 1.0000
45.1600 811.0000 1.0000
45.2000 776.0000 1.0000
45.2400 771.0000 1.0000
45.2800 793.0000 1.0000
45.3200 798.0000 1.0000
45.3600 805.0000 1.0000
45.4000 801.0000 1.0000
45.4400 828.0000 1.0000
45.4800 773.0000 1.0000
45.5200 787.0000 1.0000
45.5600 834.0000 1.0000
45.6000 777.0000 1.0000
45.6400 747.0000 1.0000
45.6800 775.0000 1.0000
45.7200 780.0000 1.0000
45.7600 778.0000 1.0000
45.8000 747.0000 1.0000
45.8400 777.0000 1.0000
45.8800 721.0000 1.0000
45.9200 752.0000 1.0000
45.9600 773.0000 1.0000
46.0000 794.0000 1.0000
46.0400 759.0000 1.0000
46.0800 765.0000 1.0000
46.1200 766.0000 1.0000
46.1600 749.0000 1.0000
46.2000 767.0000 1.0000
46.2400 779.0000 1.0000
46.2800 794.0000 1.0000
46.3200 731.0000 1.0000
46.3600 799.0000 1.0000
46.4000 762.0000 1.0000
46.4400 776.0000 1.0000
46.4800 776.0000 1.0000
46.5200 739.0000 1.0000
46.5600 812.0000 1.0000
46.6000 771.0000 1.0000
46.6400 783.0000 1.0000
46.6800 739.0000 1.0000
46.7200 772.0000 1.0000
46.7600 763.0000 1.0000
46.8000 744.0000 1.0000
46.8400 801.0000 1.0000
46.8800 763.0000 1.0000
46.9200 810.0000 1.0000
46.9600 814.0000 1.0000
47.0000 800.0000 1.0000
47.0400 814.0000 1.0000
47.0800 805.0000 1.0000
47.1200 798.0000 1.0000
47.1600 733.0000 1.0000
47.2000 772.0000 1.0000
47.2400 787.0000 1.0000
47.2800 783.0000 1.0000
47.3200 754.0000 1.0000
47.3600 757.0000 1.0000
47.4000 699.0000 1.0000
47.4400 769.0000 1.0000
47.4800 730.0000 1.0000
47.5200 755.0000 1.0000
47.5600 715.0000 1.0000
47.6000 780.0000 1.0000
47.6400 739.0000 1.0000
47.6800 757.0000 1.0000
47.7200 742.0000 1.0000
47.7600 760.0000 1.0000
47.8000 729.0000 1.0000
47.8400 750.0000 1.0000
47.8800 713.0000 1.0000
47.9200 762.0000 1.0000
47.9600 815.0000 1.0000
48.0000 759.0000 1.0000
48.0400 753.0000 1.0000
48.0800 736.0000 1.0000
48.1200 733.0000 1.0000
48.1600 735.0000 1.0000
48.2000 728.0000 1.0000
48.2400 774.0000 1.0000
48.2800 753.0000 1.0000
48.3200 714.0000 1.0000
48.3600 778.0000 1.0000
48.4000 772.0000 1.0000
48.4400 696.0000 1.0000
48.4800 721.0000 1.0000
48.5200 733.0000 1.0000
48.5600 733.0000 1.0000
48.6000 731.0000 1.0000
48.6400 724.0000 1.0000
48.6800 730.0000 1.0000
48.7200 742.0000 1.0000
48.7600 725.0000 1.0000
48.8000 754.0000 1.0000
48.8400 770.0000 1.0000
48.8800 728.0000 1.0000
48.9200 729.0000 1.0000
48.9600 687.0000 1.0000
49.0000 732.0000 1.0000
49.0400 748.0000 1.0000
49.0800 734.0000 1.0000
49.1200 733.0000 1.0000
49.1600 727.0000 1.0000
49.2000 702.0000 1.0000
49.2400 730.0000 1.0000
49.2800 762.0000 1.0000
49.3200 730.0000 1.0000
49.3600 738.0000 1.0000
49.4000 718.0000 1.0000
49.4400 705.0000 1.0000
49.4800 734.0000 1.0000
49.5200 712.0000 1.0000
49.5600 674.0000 1.0000
49.6000 752.0000 1.0000
49.6400 705.0000 1.0000
49.6800 717.0000 1.0000
49.7200 703.0000 1.0000
49.7600 725.0000 1.0000
49.8000 739.0000 1.0000
49.8400 689.0000 1.0000
49.8800 687.0000 1.0000
49.9200 724.0000 1.0000
49.9600 727.0000 1.0000
50.0000 720.0000 1.0000
50.0400 784.0000 1.0000
50.0800 766.0000 1.0000
50.1200 780.0000 1.0000
50.1600 731.0000 1.0000
50.2000 790.0000 1.0000
50.2400 755.0000 1.0000
50.2800 753.0000 1.0000
50.3200 754.0000 1.0000
50.3600 775.0000 1.0000
50.4000 754.0000 1.0000
50.4400 740.0000 1.0000
50.4800 733.0000 1.0000
50.5200 705.0000 1.0000
50.5600 772.0000 1.0000
50.6000 695.0000 1.0000
50.6400 743.0000 1.0000
50.6800 715.0000 1.0000
50.7200 745.0000 1.0000
50.7600 714.0000 1.0000
50.8000 720.0000 1.0000
50.8400 699.0000 1.0000
50.8800 736.0000 1.0000
50.9200 697.0000 1.0000
50.9600 688.0000 1.0000
51.0000 775.0000 1.0000
51.0400 713.0000 1.0000
51.0800 727.0000 1.0000
51.1200 760.0000 1.0000
51.1600 741.0000 1.0000
51.2000 729.0000 1.0000
51.2400 700.0000 1.0000
51.2800 703.0000 1.0000
51.3200 724.0000 1.0000
51.3600 731.0000 1.0000
51.4000 729.0000 1.0000
51.4400 763.0000 1.0000
51.4800 740.0000 1.0000
51.5200 718.0000 1.0000
51.5600 768.0000 1.0000
51.6000 753.0000 1.0000
51.6400 761.0000 1.0000
51.6800 779.0000 1.0000
51.7200 758.0000 1.0000
51.7600 827.0000 1.0000
51.8000 796.0000 1.0000
51.8400 841.0000 1.0000
51.8800 877.0000 1.0000
51.9200 950.0000 1.0000
51.9600 1035.0000 1.0000
52.0000 1216.0000 1.0000
52.0400 1372.0000 1.0000
52.0800 1714.0000 1.0000
52.1200 2106.0000 1.0000
52.1600 2938.0000 1.0000
52.2000 4030.0000 1.0000
52.2400 5056.0000 1.0000
52.2800 5394.0000 1.0000
52.3200 4889.0000 1.0000
52.3600 4226.0000 1.0000
52.4000 3868.0000 1.0000
52.4400 3217.0000 1.0000
52.4800 2469.0000 1.0000
52.5200 1832.0000 1.0000
52.5600 1530.0000 1.0000
52.6000 1277.0000 1.0000
52.6400 1087.0000 1.0000
52.6800 1061.0000 1.0000
52.7200 963.0000 1.0000
52.7600 879.0000 1.0000
52.8000 856.0000 1.0000
52.8400 826.0000 1.0000
52.8800 818.0000 1.0000
52.9200 761.0000 1.0000
52.9600 816.0000 1.0000
53.0000 764.0000 1.0000
53.0400 788.0000 1.0000
53.0800 757.0000 1.0000
53.1200 753.0000 1.0000
53.1600 764.0000 1.0000
53.2000 758.0000 1.0000
53.2400 720.0000 1.0000
53.2800 764.0000 1.0000
53.3200 723.0000 1.0000
53.3600 761.0000 1.0000
53.4000 740.0000 1.0000
53.4400 730.0000 1.0000
53.4800 722.0000 1.0000
53.5200 738.0000 1.0000
53.5600 751.0000 1.0000
53.6000 769.0000 1.0000
53.6400 719.0000 1.0000
53.6800 710.0000 1.0000
53.7200 742.0000 1.0000
53.7600 683.0000 1.0000
53.8000 660.0000 1.0000
53.8400 723.0000 1.0000
53.8800 688.0000 1.0000
53.9200 691.0000 1.0000
53.9600 699.0000 1.0000
54.0000 695.0000 1.0000
54.0400 687.0000 1.0000
54.0800 705.0000 1.0000
54.1200 685.0000 1.0000
54.1600 755.0000 1.0000
54.2000 680.0000 1.0000
54.2400 743.0000 1.0000
54.2800 750.0000 1.0000
54.3200 703.0000 1.0000
54.3600 727.0000 1.0000
54.4000 721.0000 1.0000
54.4400 686.0000 1.0000
54.4800 721.0000 1.0000
54.5200 708.0000 1.0000
54.5600 711.0000 1.0000
54.6000 723.0000 1.0000
54.6400 700.0000 1.0000
54.6800 764.0000 1.0000
54.7200 772.0000 1.0000
54.7600 772.0000 1.0000
54.8000 759.0000 1.0000
54.8400 759.0000 1.0000
54.8800 779.0000 1.0000
54.9200 797.0000 1.0000
54.9600 751.0000 1.0000
55.0000 783.0000 1.0000
55.0400 837.0000 1.0000
55.0800 853.0000 1.0000
55.1200 886.0000 1.0000
55.1600 940.0000 1.0000
55.2000 1018.0000 1.0000
55.2400 1064.0000 1.0000
55.2800 1082.0000 1.0000
55.3200 1132.0000 1.0000
55.3600 1071.0000 1.0000
55.4000 1046.0000 1.0000
55.4400 1013.0000 1.0000
55.4800 900.0000 1.0000
55.5200 876.0000 1.0000
55.5600 869.0000 1.0000
55.6000 768.0000 1.0000
55.6400 816.0000 1.0000
55.6800 774.0000 1.0000
55.7200 737.0000 1.0000
55.7600 738.0000 1.0000
55.8000 719.0000 1.0000
55.8400 703.0000 1.0000
55.8800 692.0000 1.0000
55.9200 709.0000 1.0000
55.9600 656.0000 1.0000
56.0000 693.0000 1.0000
56.0400 682.0000 1.0000
56.0800 668.0000 1.0000
56.1200 662.0000 1.0000
56.1600 667.0000 1.0000
56.2000 659.0000 1.0000
56.2400 678.0000 1.0000
56.2800 695.0000 1.0000
56.3200 665.0000 1.0000
56.3600 653.0000 1.0000
56.4000 654.0000 1.0000
56.4400 684.0000 1.0000
56.4800 657.0000 1.0000
56.5200 668.0000 1.0000
56.5600 681.0000 1.0000
56.6000 687.0000 1.0000
56.6400 672.0000 1.0000
56.6800 682.0000 1.0000
56.7200 676.0000 1.0000
56.7600 701.0000 1.0000
56.8000 739.0000 1.0000
56.8400 653.0000 1.0000
56.8800 689.0000 1.0000
56.9200 706.0000 1.0000
56.9600 664.0000 1.0000
57.0000 650.0000 1.0000
57.0400 699.0000 1.0000
57.0800 686.0000 1.0000
57.1200 670.0000 1.0000
57.1600 653.0000 1.0000
57.2000 682.0000 1.0000
57.2400 690.0000 1.0000
57.2800 719.0000 1.0000
57.3200 701.0000 1.0000
57.3600 669.0000 1.0000
57.4000 650.0000 1.0000
57.4400 702.0000 1.0000
57.4800 693.0000 1.0000
57.5200 714.0000 1.0000
57.5600 672.0000 1.0000
57.6000 665.0000 1.0000
57.6400 678.0000 1.0000
57.6800 690.0000 1.0000
57.7200 689.0000 1.0000
57.7600 693.0000 1.0000
57.8000 690.0000 1.0000
57.8400 687.0000 1.0000
57.8800 674.0000 1.0000
57.9200 669.0000 1.0000
57.9600 682.0000 1.0000
58.0000 667.0000 1.0000
58.0400 627.0000 1.0000
58.0800 663.0000 1.0000
58.1200 719.0000 1.0000
58.1600 679.0000 1.0000
58.2000 705.0000 1.0000
58.2400 677.0000 1.0000
58.2800 755.0000 1.0000
58.3200 705.0000 1.0000
58.3600 692.0000 1.0000
58.4000 678.0000 1.0000
58.4400 675.0000 1.0000
58.4800 686.0000 1.0000
58.5200 687.0000 1.0000
58.5600 695.0000 1.0000
58.6000 675.0000 1.0000
58.6400 705.0000 1.0000
58.6800 653.0000 1.0000
58.7200 659.0000 1.0000
58.7600 740.0000 1.0000
58.8000 681.0000 1.0000
58.8400 673.0000 1.0000
58.8800 626.0000 1.0000
58.9200 665.0000 1.0000
58.9600 671.0000 1.0000
59.0000 677.0000 1.0000
59.0400 655.0000 1.0000
59.0800 664.0000 1.0000
59.1200 698.0000 1.0000
59.1600 667.0000 1.0000
59.2000 682.0000 1.0000
59.2400 740.0000 1.0000
59.2800 696.0000 1.0000
59.3200 651.0000 1.0000
59.3600 676.0000 1.0000
59.4000 700.0000 1.0000
59.4400 700.0000 1.0000
59.4800 682.0000 1.0000
59.5200 668.0000 1.0000
59.5600 669.0000 1.0000
59.6000 687.0000 1.0000
59.6400 675.0000 1.0000
59.6800 621.0000 1.0000
59.7200 656.0000 1.0000
59.7600 717.0000 1.0000
59.8000 640.0000 1.0000
59.8400 643.0000 1.0000
59.8800 685.0000 1.0000
59.9200 672.0000 1.0000
59.9600 681.0000 1.0000
60.0000 720.0000 1.0000
60.0400 704.0000 1.0000
60.0800 661.0000 1.0000
60.1200 639.0000 1.0000
60.1600 686.0000 1.0000
60.2000 686.0000 1.0000
60.2400 691.0000 1.0000
60.2800 657.0000 1.0000
60.3200 644.0000 1.0000
60.3600 682.0000 1.0000
60.4000 656.0000 1.0000
60.4400 693.0000 1.0000
60.4800 677.0000 1.0000
60.5200 653.0000 1.0000
60.5600 664.0000 1.0000
60.6000 694.0000 1.0000
60.6400 669.0000 1.0000
60.6800 660.0000 1.0000
60.7200 669.0000 1.0000
60.7600 671.0000 1.0000
60.8000 659.0000 1.0000
60.8400 681.0000 1.0000
60.8800 661.0000 1.0000
60.9200 650.0000 1.0000
60.9600 719.0000 1.0000
61.0000 672.0000 1.0000
61.0400 641.0000 1.0000
61.0800 681.0000 1.0000
61.1200 658.0000 1.0000
61.1600 698.0000 1.0000
61.2000 632.0000 1.0000
61.2400 684.0000 1.0000
61.2800 689.0000 1.0000
61.3200 671.0000 1.0000
61.3600 664.0000 1.0000
61.4000 673.0000 1.0000
61.4400 650.0000 1.0000
61.4800 662.0000 1.0000
61.5200 730.0000 1.0000
61.5600 690.0000 1.0000
61.6000 670.0000 1.0000
61.6400 703.0000 1.0000
61.6800 693.0000 1.0000
61.7200 720.0000 1.0000
61.7600 695.0000 1.0000
61.8000 709.0000 1.0000
61.8400 742.0000 1.0000
61.8800 737.0000 1.0000
61.9200 800.0000 1.0000
61.9600 805.0000 1.0000
62.0000 886.0000 1.0000
62.0400 869.0000 1.0000
62.0800 1042.0000 1.0000
62.1200 1105.0000 1.0000
62.1600 1242.0000 1.0000
62.2000 1409.0000 1.0000
62.2400 1471.0000 1.0000
62.2800 1456.0000 1.0000
62.3200 1515.0000 1.0000
62.3600 1497.0000 1.0000
62.4000 1418.0000 1.0000
62.4400 1315.0000 1.0000
62.4800 1269.0000 1.0000
62.5200 1140.0000 1.0000
62.5600 1008.0000 1.0000
62.6000 987.0000 1.0000
62.6400 903.0000 1.0000
62.6800 905.0000 1.0000
62.7200 832.0000 1.0000
62.7600 803.0000 1.0000
62.8000 787.0000 1.0000
62.8400 749.0000 1.0000
62.8800 754.0000 1.0000
62.9200 705.0000 1.0000
62.9600 677.0000 1.0000
63.0000 769.0000 1.0000
63.0400 732.0000 1.0000
63.0800 708.0000 1.0000
63.1200 716.0000 1.0000
63.1600 751.0000 1.0000
63.2000 749.0000 1.0000
63.2400 726.0000 1.0000
63.2800 682.0000 1.0000
63.3200 751.0000 1.0000
63.3600 669.0000 1.0000
63.4000 690.0000 1.0000
63.4400 668.0000 1.0000
63.4800 677.0000 1.0000
63.5200 675.0000 1.0000
63.5600 678.0000 1.0000
63.6000 681.0000 1.0000
63.6400 640.0000 1.0000
63.6800 684.0000 1.0000
63.7200 682.0000 1.0000
63.7600 702.0000 1.0000
63.8000 660.0000 1.0000
63.8400 684.0000 1.0000
63.8800 669.0000 1.0000
63.9200 657.0000 1.0000
63.9600 697.0000 1.0000
64.0000 631.0000 1.0000
64.0400 661.0000 1.0000
64.0800 679.0000 1.0000
64.1200 639.0000 1.0000
64.1600 666.0000 1.0000
64.2000 648.0000 1.0000
64.2400 699.0000 1.0000
64.2800 670.0000 1.0000
64.3200 725.0000 1.0000
64.3600 665.0000 1.0000
64.4000 700.0000 1.0000
64.4400 698.0000 1.0000
64.4800 763.0000 1.0000
64.5200 723.0000 1.0000
64.5600 774.0000 1.0000
64.6000 854.0000 1.0000
64.6400 860.0000 1.0000
64.6800 955.0000 1.0000
64.7200 890.0000 1.0000
64.7600 846.0000 1.0000
64.8000 849.0000 1.0000
64.8400 835.0000 1.0000
64.8800 846.0000 1.0000
64.9200 833.0000 1.0000
64.9600 748.0000 1.0000
65.0000 722.0000 1.0000
65.0400 737.0000 1.0000
65.0800 751.0000 1.0000
65.1200 762.0000 1.0000
65.1600 673.0000 1.0000
65.2000 708.0000 1.0000
65.2400 671.0000 1.0000
65.2800 687.0000 1.0000
65.3200 687.0000 1.0000
65.3600 726.0000 1.0000
65.4000 699.0000 1.0000
65.4400 671.0000 1.0000
65.4800 743.0000 1.0000
65.5200 716.0000 1.0000
65.5600 701.0000 1.0000
65.6000 678.0000 1.0000
65.6400 738.0000 1.0000
65.6800 756.0000 1.0000
65.7200 737.0000 1.0000
65.7600 730.0000 1.0000
65.8000 771.0000 1.0000
65.8400 845.0000 1.0000
65.8800 883.0000 1.0000
65.9200 890.0000 1.0000
65.9600 979.0000 1.0000
66.0000 1062.0000 1.0000
66.0400 1162.0000 1.0000
66.0800 1340.0000 1.0000
66.1200 1580.0000 1.0000
66.1600 1974.0000 1.0000
66.2000 2353.0000 1.0000
66.2400 2673.0000 1.0000
66.2800 2636.0000 1.0000
66.3200 2550.0000 1.0000
66.3600 2370.0000 1.0000
66.4000 2258.0000 1.0000
66.4400 2063.0000 1.0000
66.4800 1952.0000 1.0000
66.5200 1642.0000 1.0000
66.5600 1379.0000 1.0000
66.6000 1221.0000 1.0000
66.6400 1007.0000 1.0000
66.6800 976.0000 1.0000
66.7200 819.0000 1.0000
66.7600 847.0000 1.0000
66.8000 739.0000 1.0000
66.8400 743.0000 1.0000
66.8800 766.0000 1.0000
66.9200 719.0000 1.0000
66.9600 751.0000 1.0000
67.0000 684.0000 1.0000
67.0400 684.0000 1.0000
67.0800 712.0000 1.0000
67.1200 686.0000 1.0000
67.1600 628.0000 1.0000
67.2000 646.0000 1.0000
67.2400 643.0000 1.0000
67.2800 642.0000 1.0000
67.3200 683.0000 1.0000
67.3600 633.0000 1.0000
67.4000 600.0000 1.0000
67.4400 637.0000 1.0000
67.4800 640.0000 1.0000
67.5200 657.0000 1.0000
67.5600 657.0000 1.0000
67.6000 663.0000 1.0000
67.6400 599.0000 1.0000
67.6800 587.0000 1.0000
67.7200 648.0000 1.0000
67.7600 622.0000 1.0000
67.8000 601.0000 1.0000
67.8400 634.0000 1.0000
67.8800 615.0000 1.0000
67.9200 628.0000 1.0000
67.9600 621.0000 1.0000
68.0000 623.0000 1.0000
68.0400 585.0000 1.0000
68.0800 598.0000 1.0000
68.1200 623.0000 1.0000
68.1600 632.0000 1.0000
68.2000 628.0000 1.0000
68.2400 586.0000 1.0000
68.2800 604.0000 1.0000
68.3200 615.0000 1.0000
68.3600 598.0000 1.0000
68.4000 600.0000 1.0000
68.4400 545.0000 1.0000
68.4800 590.0000 1.0000
68.5200 602.0000 1.0000
68.5600 622.0000 1.0000
68.6000 585.0000 1.0000
68.6400 600.0000 1.0000
68.6800 578.0000 1.0000
68.7200 580.0000 1.0000
68.7600 612.0000 1.0000
68.8000 595.0000 1.0000
68.8400 594.0000 1.0000
68.8800 640.0000 1.0000
68.9200 596.0000 1.0000
68.9600 536.0000 1.0000
69.0000 593.0000 1.0000
69.0400 575.0000 1.0000
69.0800 634.0000 1.0000
69.1200 551.0000 1.0000
69.1600 628.0000 1.0000
69.2000 626.0000 1.0000
69.2400 593.0000 1.0000
69.2800 620.0000 1.0000
69.3200 620.0000 1.0000
69.3600 635.0000 1.0000
69.4000 644.0000 1.0000
69.4400 627.0000 1.0000
69.4800 604.0000 1.0000
69.5200 612.0000 1.0000
69.5600 626.0000 1.0000
69.6000 587.0000 1.0000
69.6400 573.0000 1.0000
69.6800 603.0000 1.0000
69.7200 627.0000 1.0000
69.7600 563.0000 1.0000
69.8000 602.0000 1.0000
69.8400 659.0000 1.0000
69.8800 585.0000 1.0000
69.9200 577.0000 1.0000
69.9600 547.0000 1.0000
70.0000 609.0000 1.0000
*RAS_INT_END
*RAS_TEMPERATURE_START
*RAS_TEMPERATURE_END
*RAS_DATA_END