File: Data/Dataset1_Only_water/5_XRD/No_020_FS5_4.ras
*RAS_DATA_START
*RAS_HEADER_START
*DISP_FMT_X "%.2f"
*DISP_FMT_Y "%.0f"
*DISP_FULLSCALE "13848.0000000000"
*DISP_LINE_COLOR "255.0000000000"
*DISP_LINE_STYLE "0.0000000000"
*DISP_LINE_WIDTH "0.2500000000"
*DISP_NOTE "測定データ-4"
*DISP_OFFSET_Y "0.0000000000"
*DISP_PEAKSEARCH_UNIT_Y "cps"
*DISP_RANGE_BOTTOM "0.0000000000"
*DISP_RANGE_LEFT "20.0000000000"
*DISP_RANGE_LOGCUTOFF "0.0100000000"
*DISP_RANGE_RIGHT "70.0000000000"
*DISP_RANGE_TOP "13848.0000000000"
*DISP_SCALE_MODE_Y "0.0000000000"
*DISP_TAB_NAME "2θ/θ"
*DISP_TITLE_Y "強度"
*DISP_UNIT_Y "cps"
*DISP_WINDOW_NAME "MSG_MACROENGINE"
*FILE_COMMENT " "
*FILE_MD5 ""
*FILE_MEMO " "
*FILE_OPERATOR "Administrator"
*FILE_SAMPLE " "
*FILE_TYPE "RAS_RAW"
*FILE_USERGROUP "システムマネージャ"
*FILE_VERSION "1.0000000000"
*HW_ATTACHMENT_ID "ATT0025"
*HW_ATTACHMENT_NAME "標準|Standard"
*HW_COUNTER_ID-0 "CUT0025"
*HW_COUNTER_ID-1 "CUT0020"
*HW_COUNTER_ID-2 "CUT0020"
*HW_COUNTER_ID-3 "CSL0021"
*HW_COUNTER_ID-4 "CMC0021"
*HW_COUNTER_NAME-0 "D/teX Ultra|D/teX Ultra"
*HW_COUNTER_NAME-1 "None|None"
*HW_COUNTER_NAME-2 "None|None"
*HW_COUNTER_NAME-3 "BBM|BBM"
*HW_COUNTER_NAME-4 "検出器モノクロメータ|Detector monochromator"
*HW_COUNTER_SELECT_NAME "D/teX Ultra|D/teX Ultra"
*HW_GONIOMETER_ID "GON0023"
*HW_GONIOMETER_NAME "SmartLab|SmartLab"
*HW_GONIOMETER_RADIUS-0 "90.0"
*HW_GONIOMETER_RADIUS-1 "114.0"
*HW_GONIOMETER_RADIUS-2 "190.0"
*HW_GONIOMETER_RADIUS-3 "300.0"
*HW_GONIOMETER_RADIUS-4 "187.0"
*HW_GONIOMETER_RADIUS-5 "300.0"
*HW_GONIOMETER_RADIUS-6 "113.0"
*HW_GONIOMETER_RADIUS-7 "331.0"
*HW_I_OPT_ID-0 "CBO0021"
*HW_I_OPT_ID-1 "ICR0023"
*HW_I_OPT_ID-2 "ISL0021"
*HW_I_OPT_ID-3 "ISO0021"
*HW_I_OPT_ID-4 "IAD0021"
*HW_I_OPT_ID-5 "IPR0001"
*HW_I_OPT_NAME-0 "CBOユニット|CBO unit"
*HW_I_OPT_NAME-1 "標準入射光学ユニット|Standard incident optical unit"
*HW_I_OPT_NAME-2 "標準入射スリットボックス|Standard incident slit box"
*HW_I_OPT_NAME-3 "入射平行スリット|Incident parallel slit"
*HW_I_OPT_NAME-4 "長手制限スリット|Length limiting slit"
*HW_I_OPT_NAME-5 "None|None"
*HW_R_ATTENUATER_AUTOMODE "0"
*HW_R_OPT_ID-0 "RSS0021"
*HW_R_OPT_ID-1 "RCR0023"
*HW_R_OPT_ID-2 "RSO0021"
*HW_R_OPT_ID-3 "RRS0021"
*HW_R_OPT_ID-4 "ATN0021"
*HW_R_OPT_ID-5 "RFL0021"
*HW_R_OPT_ID-6 "RAD0021"
*HW_R_OPT_NAME-0 "標準受光スリットボックス1|Standard receiving slit box # 1"
*HW_R_OPT_NAME-1 "標準受光光学ユニット1|Standard receiving unit # 1"
*HW_R_OPT_NAME-2 "標準受光光学ユニット2|Standard receiving optical unit # 2"
*HW_R_OPT_NAME-3 "標準受光スリットボックス2|Standard receiving slit box # 2"
*HW_R_OPT_NAME-4 "標準アッテネータ|Standard Attenuator"
*HW_R_OPT_NAME-5 "Cu Kβ|Cu K-beta"
*HW_R_OPT_NAME-6 "調整用受光スリット|Alignment receiving slit"
*HW_SAMPLE_HOLDER_ID "SMP0023"
*HW_SAMPLE_HOLDER_NAME "標準Zステージ|Standard Z stage"
*HW_XG_CURRENT_MAX "50"
*HW_XG_CURRENT_MIN "2"
*HW_XG_CURRENT_RESOLUTION "1"
*HW_XG_CURRENT_UNIT "mA"
*HW_XG_FOCUS "1mm x 10mm"
*HW_XG_FOCUS_TYPE "Normal"
*HW_XG_ID ""
*HW_XG_NAME "3kW 封入管(ID:1200)|3kW Sealed tube(ID:1200)"
*HW_XG_TARGET_ATOMIC_NUMBER "29.0000000000"
*HW_XG_TARGET_NAME "Cu"
*HW_XG_TYPE "Hermetic"
*HW_XG_VOLTAGE_MAX "60"
*HW_XG_VOLTAGE_MIN "20"
*HW_XG_VOLTAGE_RESOLUTION "1"
*HW_XG_VOLTAGE_UNIT "kV"
*HW_XG_WATT_MAX "1.500"
*HW_XG_WATT_UNIT "kW"
*HW_XG_WAVE_LENGTH_ALPHA1 "1.540593"
*HW_XG_WAVE_LENGTH_ALPHA2 "1.544414"
*HW_XG_WAVE_LENGTH_BETA "1.392250"
*MEAS_COND_AXIS_NAME-0 "2θ/θ"
*MEAS_COND_AXIS_NAME-1 "2θ"
*MEAS_COND_AXIS_NAME-2 "ω"
*MEAS_COND_AXIS_NAME-3 "Z"
*MEAS_COND_AXIS_NAME-4 "2θ/ω"
*MEAS_COND_AXIS_NAME-5 "θs"
*MEAS_COND_AXIS_NAME-6 "θd"
*MEAS_COND_AXIS_NAME-7 "Ts"
*MEAS_COND_AXIS_NAME-8 "CBO選択スリット"
*MEAS_COND_AXIS_NAME-9 "M"
*MEAS_COND_AXIS_NAME-10 "入射平行スリット"
*MEAS_COND_AXIS_NAME-11 "入射スリット"
*MEAS_COND_AXIS_NAME-12 ""
*MEAS_COND_AXIS_NAME-13 "Zs"
*MEAS_COND_AXIS_NAME-14 "入射光学素子"
*MEAS_COND_AXIS_NAME-15 "長手制限スリット"
*MEAS_COND_AXIS_NAME-16 "センタースリット"
*MEAS_COND_AXIS_NAME-17 "フィルター"
*MEAS_COND_AXIS_NAME-18 "受光スリット1"
*MEAS_COND_AXIS_NAME-19 "受光スリット2"
*MEAS_COND_AXIS_NAME-20 "受光光学素子"
*MEAS_COND_AXIS_NAME-21 "受光平行スリット"
*MEAS_COND_AXIS_NAME-22 "調整用受光スリット"
*MEAS_COND_AXIS_NAME-23 ""
*MEAS_COND_AXIS_NAME-24 ""
*MEAS_COND_AXIS_NAME-25 "Zd"
*MEAS_COND_AXIS_NAME-26 "アッテネータ"
*MEAS_COND_AXIS_NAME-27 "検出器モノクロメータ"
*MEAS_COND_AXIS_NAME-28 "モノクロメータスリット"
*MEAS_COND_AXIS_NAME-29 "プライマリビーム"
*MEAS_COND_AXIS_NAME-30 "PHA"
*MEAS_COND_AXIS_NAME_INTERNAL-0 "TwoThetaTheta"
*MEAS_COND_AXIS_NAME_INTERNAL-1 "TwoTheta"
*MEAS_COND_AXIS_NAME_INTERNAL-2 "Omega"
*MEAS_COND_AXIS_NAME_INTERNAL-3 "Z"
*MEAS_COND_AXIS_NAME_INTERNAL-4 "TwoThetaOmega"
*MEAS_COND_AXIS_NAME_INTERNAL-5 "ThetaS"
*MEAS_COND_AXIS_NAME_INTERNAL-6 "ThetaD"
*MEAS_COND_AXIS_NAME_INTERNAL-7 "Ts"
*MEAS_COND_AXIS_NAME_INTERNAL-8 "CBO"
*MEAS_COND_AXIS_NAME_INTERNAL-9 "CBO-M"
*MEAS_COND_AXIS_NAME_INTERNAL-10 "IncidentSollerSlit"
*MEAS_COND_AXIS_NAME_INTERNAL-11 "IncidentSlitBox"
*MEAS_COND_AXIS_NAME_INTERNAL-12 "IncidentSlitBox-_Axis"
*MEAS_COND_AXIS_NAME_INTERNAL-13 "Zs"
*MEAS_COND_AXIS_NAME_INTERNAL-14 "IncidentMonochromator"
*MEAS_COND_AXIS_NAME_INTERNAL-15 "IncidentAxdSlit"
*MEAS_COND_AXIS_NAME_INTERNAL-16 "CenterSlit"
*MEAS_COND_AXIS_NAME_INTERNAL-17 "Filter"
*MEAS_COND_AXIS_NAME_INTERNAL-18 "ReceivingSlitBox1"
*MEAS_COND_AXIS_NAME_INTERNAL-19 "ReceivingSlitBox2"
*MEAS_COND_AXIS_NAME_INTERNAL-20 "ReceivingOptics"
*MEAS_COND_AXIS_NAME_INTERNAL-21 "ReceivingSollerSlit"
*MEAS_COND_AXIS_NAME_INTERNAL-22 "ReceivingAxdSlit"
*MEAS_COND_AXIS_NAME_INTERNAL-23 "ReceivingSlitBox1-_Axis"
*MEAS_COND_AXIS_NAME_INTERNAL-24 "ReceivingSlitBox2-_Axis"
*MEAS_COND_AXIS_NAME_INTERNAL-25 "ReceivingSlitBox2-Zd"
*MEAS_COND_AXIS_NAME_INTERNAL-26 "Attenuator"
*MEAS_COND_AXIS_NAME_INTERNAL-27 "CounterMonochromator"
*MEAS_COND_AXIS_NAME_INTERNAL-28 "CounterSlit"
*MEAS_COND_AXIS_NAME_INTERNAL-29 "IncidentPrimary"
*MEAS_COND_AXIS_NAME_INTERNAL-30 "PHA"
*MEAS_COND_AXIS_NAME_MAGICNO-0 "83951616.0000000000"
*MEAS_COND_AXIS_NAME_MAGICNO-1 "268632064.0000000000"
*MEAS_COND_AXIS_NAME_MAGICNO-2 "268500992.0000000000"
*MEAS_COND_AXIS_NAME_MAGICNO-3 "285278208.0000000000"
*MEAS_COND_AXIS_NAME_MAGICNO-4 "83951616.0000000000"
*MEAS_COND_AXIS_NAME_MAGICNO-5 "131072.0000000000"
*MEAS_COND_AXIS_NAME_MAGICNO-6 "131072.0000000000"
*MEAS_COND_AXIS_NAME_MAGICNO-7 "318898176.0000000000"
*MEAS_COND_AXIS_NAME_MAGICNO-8 "20971521.0000000000"
*MEAS_COND_AXIS_NAME_MAGICNO-9 "285343744.0000000000"
*MEAS_COND_AXIS_NAME_MAGICNO-10 "20971521.0000000000"
*MEAS_COND_AXIS_NAME_MAGICNO-11 "22020097.0000000000"
*MEAS_COND_AXIS_NAME_MAGICNO-12 "25165824.0000000000"
*MEAS_COND_AXIS_NAME_MAGICNO-13 "318898176.0000000000"
*MEAS_COND_AXIS_NAME_MAGICNO-14 "1.0000000000"
*MEAS_COND_AXIS_NAME_MAGICNO-15 "20971521.0000000000"
*MEAS_COND_AXIS_NAME_MAGICNO-16 "20971521.0000000000"
*MEAS_COND_AXIS_NAME_MAGICNO-17 "20971521.0000000000"
*MEAS_COND_AXIS_NAME_MAGICNO-18 "23068673.0000000000"
*MEAS_COND_AXIS_NAME_MAGICNO-19 "23068673.0000000000"
*MEAS_COND_AXIS_NAME_MAGICNO-20 "20971521.0000000000"
*MEAS_COND_AXIS_NAME_MAGICNO-21 "20971521.0000000000"
*MEAS_COND_AXIS_NAME_MAGICNO-22 "20971521.0000000000"
*MEAS_COND_AXIS_NAME_MAGICNO-23 "25165824.0000000000"
*MEAS_COND_AXIS_NAME_MAGICNO-24 "25165824.0000000000"
*MEAS_COND_AXIS_NAME_MAGICNO-25 "285343744.0000000000"
*MEAS_COND_AXIS_NAME_MAGICNO-26 "17301505.0000000000"
*MEAS_COND_AXIS_NAME_MAGICNO-27 "20971521.0000000000"
*MEAS_COND_AXIS_NAME_MAGICNO-28 "20971521.0000000000"
*MEAS_COND_AXIS_NAME_MAGICNO-29 "20971521.0000000000"
*MEAS_COND_AXIS_NAME_MAGICNO-30 "0.0000000000"
*MEAS_COND_AXIS_OFFSET-0 "-"
*MEAS_COND_AXIS_OFFSET-1 "-0.1081000000"
*MEAS_COND_AXIS_OFFSET-2 "0.3758000000"
*MEAS_COND_AXIS_OFFSET-3 "-"
*MEAS_COND_AXIS_OFFSET-4 "-"
*MEAS_COND_AXIS_OFFSET-5 "0.3758000000"
*MEAS_COND_AXIS_OFFSET-6 "-0.4839000000"
*MEAS_COND_AXIS_OFFSET-7 "-"
*MEAS_COND_AXIS_OFFSET-8 "-"
*MEAS_COND_AXIS_OFFSET-9 "-"
*MEAS_COND_AXIS_OFFSET-10 "-"
*MEAS_COND_AXIS_OFFSET-11 "-"
*MEAS_COND_AXIS_OFFSET-12 "-"
*MEAS_COND_AXIS_OFFSET-13 "-"
*MEAS_COND_AXIS_OFFSET-14 "-"
*MEAS_COND_AXIS_OFFSET-15 "-"
*MEAS_COND_AXIS_OFFSET-16 "-"
*MEAS_COND_AXIS_OFFSET-17 "-"
*MEAS_COND_AXIS_OFFSET-18 "-"
*MEAS_COND_AXIS_OFFSET-19 "-"
*MEAS_COND_AXIS_OFFSET-20 "-"
*MEAS_COND_AXIS_OFFSET-21 "-"
*MEAS_COND_AXIS_OFFSET-22 "-"
*MEAS_COND_AXIS_OFFSET-23 "-"
*MEAS_COND_AXIS_OFFSET-24 "-"
*MEAS_COND_AXIS_OFFSET-25 "-"
*MEAS_COND_AXIS_OFFSET-26 "-"
*MEAS_COND_AXIS_OFFSET-27 "-"
*MEAS_COND_AXIS_OFFSET-28 "-"
*MEAS_COND_AXIS_OFFSET-29 "-"
*MEAS_COND_AXIS_OFFSET-30 "-"
*MEAS_COND_AXIS_POSITION-0 "0.0000000000"
*MEAS_COND_AXIS_POSITION-1 "0.0000000000"
*MEAS_COND_AXIS_POSITION-2 "0.0000000000"
*MEAS_COND_AXIS_POSITION-3 "-0.5500000000"
*MEAS_COND_AXIS_POSITION-4 "0.0000000000"
*MEAS_COND_AXIS_POSITION-5 "0.0000000000"
*MEAS_COND_AXIS_POSITION-6 "0.0000000000"
*MEAS_COND_AXIS_POSITION-7 "-0.4278800000"
*MEAS_COND_AXIS_POSITION-8 "BB"
*MEAS_COND_AXIS_POSITION-9 "0.0000000000"
*MEAS_COND_AXIS_POSITION-10 "Soller_slit_5.0deg"
*MEAS_COND_AXIS_POSITION-11 "2/3deg"
*MEAS_COND_AXIS_POSITION-12 "2.2088000000"
*MEAS_COND_AXIS_POSITION-13 "-0.4140600000"
*MEAS_COND_AXIS_POSITION-14 "0.0000000000"
*MEAS_COND_AXIS_POSITION-15 "10.0mm"
*MEAS_COND_AXIS_POSITION-16 "None"
*MEAS_COND_AXIS_POSITION-17 "Cu_K-beta"
*MEAS_COND_AXIS_POSITION-18 "13.000mm"
*MEAS_COND_AXIS_POSITION-19 "13.000mm"
*MEAS_COND_AXIS_POSITION-20 "No_unit"
*MEAS_COND_AXIS_POSITION-21 "Soller_slit_5.0deg"
*MEAS_COND_AXIS_POSITION-22 "None"
*MEAS_COND_AXIS_POSITION-23 "13.0000000000"
*MEAS_COND_AXIS_POSITION-24 "13.0000000000"
*MEAS_COND_AXIS_POSITION-25 "0.0109400000"
*MEAS_COND_AXIS_POSITION-26 "Open"
*MEAS_COND_AXIS_POSITION-27 "None"
*MEAS_COND_AXIS_POSITION-28 "None"
*MEAS_COND_AXIS_POSITION-29 "None"
*MEAS_COND_AXIS_POSITION-30 "38.0000000000"
*MEAS_COND_AXIS_UNIT-0 "deg"
*MEAS_COND_AXIS_UNIT-1 "deg"
*MEAS_COND_AXIS_UNIT-2 "deg"
*MEAS_COND_AXIS_UNIT-3 "mm"
*MEAS_COND_AXIS_UNIT-4 "deg"
*MEAS_COND_AXIS_UNIT-5 "deg"
*MEAS_COND_AXIS_UNIT-6 "deg"
*MEAS_COND_AXIS_UNIT-7 "mm"
*MEAS_COND_AXIS_UNIT-8 ""
*MEAS_COND_AXIS_UNIT-9 "pulse"
*MEAS_COND_AXIS_UNIT-10 ""
*MEAS_COND_AXIS_UNIT-11 ""
*MEAS_COND_AXIS_UNIT-12 "mm"
*MEAS_COND_AXIS_UNIT-13 "mm"
*MEAS_COND_AXIS_UNIT-14 ""
*MEAS_COND_AXIS_UNIT-15 ""
*MEAS_COND_AXIS_UNIT-16 ""
*MEAS_COND_AXIS_UNIT-17 ""
*MEAS_COND_AXIS_UNIT-18 ""
*MEAS_COND_AXIS_UNIT-19 ""
*MEAS_COND_AXIS_UNIT-20 ""
*MEAS_COND_AXIS_UNIT-21 ""
*MEAS_COND_AXIS_UNIT-22 ""
*MEAS_COND_AXIS_UNIT-23 "mm"
*MEAS_COND_AXIS_UNIT-24 "mm"
*MEAS_COND_AXIS_UNIT-25 "mm"
*MEAS_COND_AXIS_UNIT-26 ""
*MEAS_COND_AXIS_UNIT-27 ""
*MEAS_COND_AXIS_UNIT-28 ""
*MEAS_COND_AXIS_UNIT-29 ""
*MEAS_COND_AXIS_UNIT-30 "div"
*MEAS_COND_COUNTER_CNTLOSS_CORR "0.0000000000"
*MEAS_COND_COUNTER_PHABASE "38.0000000000"
*MEAS_COND_COUNTER_PHAWINDOW "16.0000000000"
*MEAS_COND_COUNTER_PHA_UNIT "div"
*MEAS_COND_COUNTER_TAUDIFF "30.0000000000"
*MEAS_COND_COUNTER_TAUINT "0.0000000000"
*MEAS_COND_IRRADIATION_MODE "OFF"
*MEAS_COND_IRRADIATION_WIDTH ""
*MEAS_COND_OPT_ATTR "集中法"
*MEAS_COND_OPT_NAME "@集中法"
*MEAS_COND_UNSYMMETRIC_MODE "OFF"
*MEAS_COND_XG_CURRENT "30.0000000000"
*MEAS_COND_XG_VOLTAGE "40.0000000000"
*MEAS_COND_XG_WAVE_TYPE "Ka"
*MEAS_DATA_COUNT "5001.0000000000"
*MEAS_SCAN_AXIS_X "2θ/θ"
*MEAS_SCAN_AXIS_X_INTERNAL "TwoThetaTheta"
*MEAS_SCAN_END_TIME "07/08/21 14:35:03"
*MEAS_SCAN_MODE "CONTINUOUS"
*MEAS_SCAN_MONITOR "0"
*MEAS_SCAN_RESOLUTION_X "0.0002"
*MEAS_SCAN_SPEED "1.0"
*MEAS_SCAN_SPEED_UNIT "deg/min"
*MEAS_SCAN_START "20.0000000000"
*MEAS_SCAN_START_TIME "07/08/21 13:42:09"
*MEAS_SCAN_STEP "0.0100000000"
*MEAS_SCAN_STOP "70.0000000000"
*MEAS_SCAN_UNIT_X "deg"
*MEAS_SCAN_UNIT_Y "counts"
*RAS_HEADER_END
*RAS_INT_START
20.0000 1616.0000 1.0000
20.0400 1559.0000 1.0000
20.0800 1591.0000 1.0000
20.1200 1640.0000 1.0000
20.1600 1580.0000 1.0000
20.2000 1603.0000 1.0000
20.2400 1577.0000 1.0000
20.2800 1601.0000 1.0000
20.3200 1609.0000 1.0000
20.3600 1659.0000 1.0000
20.4000 1583.0000 1.0000
20.4400 1626.0000 1.0000
20.4800 1699.0000 1.0000
20.5200 1592.0000 1.0000
20.5600 1631.0000 1.0000
20.6000 1606.0000 1.0000
20.6400 1564.0000 1.0000
20.6800 1590.0000 1.0000
20.7200 1643.0000 1.0000
20.7600 1627.0000 1.0000
20.8000 1662.0000 1.0000
20.8400 1582.0000 1.0000
20.8800 1598.0000 1.0000
20.9200 1561.0000 1.0000
20.9600 1652.0000 1.0000
21.0000 1607.0000 1.0000
21.0400 1603.0000 1.0000
21.0800 1551.0000 1.0000
21.1200 1619.0000 1.0000
21.1600 1608.0000 1.0000
21.2000 1679.0000 1.0000
21.2400 1618.0000 1.0000
21.2800 1558.0000 1.0000
21.3200 1632.0000 1.0000
21.3600 1613.0000 1.0000
21.4000 1576.0000 1.0000
21.4400 1659.0000 1.0000
21.4800 1593.0000 1.0000
21.5200 1639.0000 1.0000
21.5600 1616.0000 1.0000
21.6000 1638.0000 1.0000
21.6400 1595.0000 1.0000
21.6800 1566.0000 1.0000
21.7200 1614.0000 1.0000
21.7600 1609.0000 1.0000
21.8000 1603.0000 1.0000
21.8400 1617.0000 1.0000
21.8800 1609.0000 1.0000
21.9200 1614.0000 1.0000
21.9600 1584.0000 1.0000
22.0000 1599.0000 1.0000
22.0400 1612.0000 1.0000
22.0800 1647.0000 1.0000
22.1200 1622.0000 1.0000
22.1600 1657.0000 1.0000
22.2000 1617.0000 1.0000
22.2400 1629.0000 1.0000
22.2800 1631.0000 1.0000
22.3200 1620.0000 1.0000
22.3600 1624.0000 1.0000
22.4000 1661.0000 1.0000
22.4400 1614.0000 1.0000
22.4800 1645.0000 1.0000
22.5200 1677.0000 1.0000
22.5600 1627.0000 1.0000
22.6000 1665.0000 1.0000
22.6400 1661.0000 1.0000
22.6800 1613.0000 1.0000
22.7200 1729.0000 1.0000
22.7600 1617.0000 1.0000
22.8000 1618.0000 1.0000
22.8400 1644.0000 1.0000
22.8800 1659.0000 1.0000
22.9200 1609.0000 1.0000
22.9600 1621.0000 1.0000
23.0000 1604.0000 1.0000
23.0400 1662.0000 1.0000
23.0800 1636.0000 1.0000
23.1200 1595.0000 1.0000
23.1600 1615.0000 1.0000
23.2000 1665.0000 1.0000
23.2400 1679.0000 1.0000
23.2800 1643.0000 1.0000
23.3200 1642.0000 1.0000
23.3600 1636.0000 1.0000
23.4000 1663.0000 1.0000
23.4400 1636.0000 1.0000
23.4800 1612.0000 1.0000
23.5200 1629.0000 1.0000
23.5600 1587.0000 1.0000
23.6000 1667.0000 1.0000
23.6400 1623.0000 1.0000
23.6800 1640.0000 1.0000
23.7200 1710.0000 1.0000
23.7600 1706.0000 1.0000
23.8000 1672.0000 1.0000
23.8400 1653.0000 1.0000
23.8800 1666.0000 1.0000
23.9200 1684.0000 1.0000
23.9600 1699.0000 1.0000
24.0000 1660.0000 1.0000
24.0400 1631.0000 1.0000
24.0800 1602.0000 1.0000
24.1200 1638.0000 1.0000
24.1600 1641.0000 1.0000
24.2000 1671.0000 1.0000
24.2400 1590.0000 1.0000
24.2800 1659.0000 1.0000
24.3200 1671.0000 1.0000
24.3600 1686.0000 1.0000
24.4000 1675.0000 1.0000
24.4400 1705.0000 1.0000
24.4800 1688.0000 1.0000
24.5200 1707.0000 1.0000
24.5600 1712.0000 1.0000
24.6000 1615.0000 1.0000
24.6400 1646.0000 1.0000
24.6800 1713.0000 1.0000
24.7200 1731.0000 1.0000
24.7600 1697.0000 1.0000
24.8000 1649.0000 1.0000
24.8400 1686.0000 1.0000
24.8800 1718.0000 1.0000
24.9200 1754.0000 1.0000
24.9600 1766.0000 1.0000
25.0000 1759.0000 1.0000
25.0400 1723.0000 1.0000
25.0800 1717.0000 1.0000
25.1200 1774.0000 1.0000
25.1600 1708.0000 1.0000
25.2000 1780.0000 1.0000
25.2400 1709.0000 1.0000
25.2800 1803.0000 1.0000
25.3200 1713.0000 1.0000
25.3600 1707.0000 1.0000
25.4000 1699.0000 1.0000
25.4400 1631.0000 1.0000
25.4800 1751.0000 1.0000
25.5200 1664.0000 1.0000
25.5600 1618.0000 1.0000
25.6000 1665.0000 1.0000
25.6400 1685.0000 1.0000
25.6800 1671.0000 1.0000
25.7200 1754.0000 1.0000
25.7600 1673.0000 1.0000
25.8000 1745.0000 1.0000
25.8400 1688.0000 1.0000
25.8800 1657.0000 1.0000
25.9200 1684.0000 1.0000
25.9600 1700.0000 1.0000
26.0000 1714.0000 1.0000
26.0400 1722.0000 1.0000
26.0800 1625.0000 1.0000
26.1200 1653.0000 1.0000
26.1600 1725.0000 1.0000
26.2000 1761.0000 1.0000
26.2400 1757.0000 1.0000
26.2800 1694.0000 1.0000
26.3200 1701.0000 1.0000
26.3600 1780.0000 1.0000
26.4000 1761.0000 1.0000
26.4400 1735.0000 1.0000
26.4800 1846.0000 1.0000
26.5200 1813.0000 1.0000
26.5600 1808.0000 1.0000
26.6000 1864.0000 1.0000
26.6400 1811.0000 1.0000
26.6800 1896.0000 1.0000
26.7200 1883.0000 1.0000
26.7600 1928.0000 1.0000
26.8000 1893.0000 1.0000
26.8400 1955.0000 1.0000
26.8800 2038.0000 1.0000
26.9200 2061.0000 1.0000
26.9600 2183.0000 1.0000
27.0000 2352.0000 1.0000
27.0400 2530.0000 1.0000
27.0800 2967.0000 1.0000
27.1200 3426.0000 1.0000
27.1600 4028.0000 1.0000
27.2000 5048.0000 1.0000
27.2400 6090.0000 1.0000
27.2800 6910.0000 1.0000
27.3200 6443.0000 1.0000
27.3600 5477.0000 1.0000
27.4000 4589.0000 1.0000
27.4400 3736.0000 1.0000
27.4800 3192.0000 1.0000
27.5200 2744.0000 1.0000
27.5600 2486.0000 1.0000
27.6000 2254.0000 1.0000
27.6400 2086.0000 1.0000
27.6800 2121.0000 1.0000
27.7200 1945.0000 1.0000
27.7600 1933.0000 1.0000
27.8000 1967.0000 1.0000
27.8400 1885.0000 1.0000
27.8800 1878.0000 1.0000
27.9200 1858.0000 1.0000
27.9600 1745.0000 1.0000
28.0000 1810.0000 1.0000
28.0400 1710.0000 1.0000
28.0800 1751.0000 1.0000
28.1200 1773.0000 1.0000
28.1600 1766.0000 1.0000
28.2000 1756.0000 1.0000
28.2400 1769.0000 1.0000
28.2800 1715.0000 1.0000
28.3200 1731.0000 1.0000
28.3600 1695.0000 1.0000
28.4000 1701.0000 1.0000
28.4400 1695.0000 1.0000
28.4800 1711.0000 1.0000
28.5200 1648.0000 1.0000
28.5600 1744.0000 1.0000
28.6000 1637.0000 1.0000
28.6400 1721.0000 1.0000
28.6800 1682.0000 1.0000
28.7200 1701.0000 1.0000
28.7600 1707.0000 1.0000
28.8000 1584.0000 1.0000
28.8400 1682.0000 1.0000
28.8800 1704.0000 1.0000
28.9200 1673.0000 1.0000
28.9600 1665.0000 1.0000
29.0000 1611.0000 1.0000
29.0400 1608.0000 1.0000
29.0800 1558.0000 1.0000
29.1200 1639.0000 1.0000
29.1600 1612.0000 1.0000
29.2000 1587.0000 1.0000
29.2400 1675.0000 1.0000
29.2800 1627.0000 1.0000
29.3200 1661.0000 1.0000
29.3600 1660.0000 1.0000
29.4000 1704.0000 1.0000
29.4400 1529.0000 1.0000
29.4800 1612.0000 1.0000
29.5200 1620.0000 1.0000
29.5600 1650.0000 1.0000
29.6000 1644.0000 1.0000
29.6400 1611.0000 1.0000
29.6800 1582.0000 1.0000
29.7200 1625.0000 1.0000
29.7600 1687.0000 1.0000
29.8000 1587.0000 1.0000
29.8400 1590.0000 1.0000
29.8800 1652.0000 1.0000
29.9200 1525.0000 1.0000
29.9600 1585.0000 1.0000
30.0000 1608.0000 1.0000
30.0400 1629.0000 1.0000
30.0800 1627.0000 1.0000
30.1200 1556.0000 1.0000
30.1600 1550.0000 1.0000
30.2000 1576.0000 1.0000
30.2400 1584.0000 1.0000
30.2800 1645.0000 1.0000
30.3200 1578.0000 1.0000
30.3600 1631.0000 1.0000
30.4000 1567.0000 1.0000
30.4400 1543.0000 1.0000
30.4800 1583.0000 1.0000
30.5200 1553.0000 1.0000
30.5600 1558.0000 1.0000
30.6000 1537.0000 1.0000
30.6400 1594.0000 1.0000
30.6800 1574.0000 1.0000
30.7200 1522.0000 1.0000
30.7600 1542.0000 1.0000
30.8000 1624.0000 1.0000
30.8400 1582.0000 1.0000
30.8800 1566.0000 1.0000
30.9200 1594.0000 1.0000
30.9600 1587.0000 1.0000
31.0000 1596.0000 1.0000
31.0400 1564.0000 1.0000
31.0800 1579.0000 1.0000
31.1200 1526.0000 1.0000
31.1600 1535.0000 1.0000
31.2000 1552.0000 1.0000
31.2400 1534.0000 1.0000
31.2800 1498.0000 1.0000
31.3200 1493.0000 1.0000
31.3600 1623.0000 1.0000
31.4000 1470.0000 1.0000
31.4400 1555.0000 1.0000
31.4800 1512.0000 1.0000
31.5200 1480.0000 1.0000
31.5600 1542.0000 1.0000
31.6000 1570.0000 1.0000
31.6400 1491.0000 1.0000
31.6800 1506.0000 1.0000
31.7200 1547.0000 1.0000
31.7600 1558.0000 1.0000
31.8000 1473.0000 1.0000
31.8400 1518.0000 1.0000
31.8800 1533.0000 1.0000
31.9200 1543.0000 1.0000
31.9600 1604.0000 1.0000
32.0000 1606.0000 1.0000
32.0400 1611.0000 1.0000
32.0800 1563.0000 1.0000
32.1200 1548.0000 1.0000
32.1600 1513.0000 1.0000
32.2000 1492.0000 1.0000
32.2400 1505.0000 1.0000
32.2800 1528.0000 1.0000
32.3200 1501.0000 1.0000
32.3600 1529.0000 1.0000
32.4000 1450.0000 1.0000
32.4400 1458.0000 1.0000
32.4800 1506.0000 1.0000
32.5200 1454.0000 1.0000
32.5600 1416.0000 1.0000
32.6000 1483.0000 1.0000
32.6400 1445.0000 1.0000
32.6800 1504.0000 1.0000
32.7200 1423.0000 1.0000
32.7600 1476.0000 1.0000
32.8000 1425.0000 1.0000
32.8400 1486.0000 1.0000
32.8800 1464.0000 1.0000
32.9200 1432.0000 1.0000
32.9600 1489.0000 1.0000
33.0000 1462.0000 1.0000
33.0400 1397.0000 1.0000
33.0800 1463.0000 1.0000
33.1200 1418.0000 1.0000
33.1600 1443.0000 1.0000
33.2000 1387.0000 1.0000
33.2400 1479.0000 1.0000
33.2800 1437.0000 1.0000
33.3200 1426.0000 1.0000
33.3600 1450.0000 1.0000
33.4000 1436.0000 1.0000
33.4400 1430.0000 1.0000
33.4800 1409.0000 1.0000
33.5200 1389.0000 1.0000
33.5600 1480.0000 1.0000
33.6000 1413.0000 1.0000
33.6400 1433.0000 1.0000
33.6800 1479.0000 1.0000
33.7200 1507.0000 1.0000
33.7600 1445.0000 1.0000
33.8000 1560.0000 1.0000
33.8400 1503.0000 1.0000
33.8800 1727.0000 1.0000
33.9200 1683.0000 1.0000
33.9600 1704.0000 1.0000
34.0000 1670.0000 1.0000
34.0400 1615.0000 1.0000
34.0800 1640.0000 1.0000
34.1200 1591.0000 1.0000
34.1600 1644.0000 1.0000
34.2000 1711.0000 1.0000
34.2400 1813.0000 1.0000
34.2800 1924.0000 1.0000
34.3200 2179.0000 1.0000
34.3600 2618.0000 1.0000
34.4000 3094.0000 1.0000
34.4400 3445.0000 1.0000
34.4800 3622.0000 1.0000
34.5200 3499.0000 1.0000
34.5600 3143.0000 1.0000
34.6000 2718.0000 1.0000
34.6400 2322.0000 1.0000
34.6800 2058.0000 1.0000
34.7200 1915.0000 1.0000
34.7600 1713.0000 1.0000
34.8000 1684.0000 1.0000
34.8400 1621.0000 1.0000
34.8800 1455.0000 1.0000
34.9200 1444.0000 1.0000
34.9600 1421.0000 1.0000
35.0000 1401.0000 1.0000
35.0400 1356.0000 1.0000
35.0800 1381.0000 1.0000
35.1200 1366.0000 1.0000
35.1600 1316.0000 1.0000
35.2000 1276.0000 1.0000
35.2400 1322.0000 1.0000
35.2800 1334.0000 1.0000
35.3200 1281.0000 1.0000
35.3600 1298.0000 1.0000
35.4000 1278.0000 1.0000
35.4400 1281.0000 1.0000
35.4800 1270.0000 1.0000
35.5200 1227.0000 1.0000
35.5600 1303.0000 1.0000
35.6000 1237.0000 1.0000
35.6400 1251.0000 1.0000
35.6800 1323.0000 1.0000
35.7200 1296.0000 1.0000
35.7600 1170.0000 1.0000
35.8000 1244.0000 1.0000
35.8400 1230.0000 1.0000
35.8800 1228.0000 1.0000
35.9200 1229.0000 1.0000
35.9600 1274.0000 1.0000
36.0000 1252.0000 1.0000
36.0400 1214.0000 1.0000
36.0800 1214.0000 1.0000
36.1200 1352.0000 1.0000
36.1600 1324.0000 1.0000
36.2000 1349.0000 1.0000
36.2400 1458.0000 1.0000
36.2800 1639.0000 1.0000
36.3200 1918.0000 1.0000
36.3600 2137.0000 1.0000
36.4000 2292.0000 1.0000
36.4400 2104.0000 1.0000
36.4800 1836.0000 1.0000
36.5200 1641.0000 1.0000
36.5600 1345.0000 1.0000
36.6000 1316.0000 1.0000
36.6400 1248.0000 1.0000
36.6800 1181.0000 1.0000
36.7200 1173.0000 1.0000
36.7600 1129.0000 1.0000
36.8000 1196.0000 1.0000
36.8400 1136.0000 1.0000
36.8800 1126.0000 1.0000
36.9200 1126.0000 1.0000
36.9600 1142.0000 1.0000
37.0000 1172.0000 1.0000
37.0400 1146.0000 1.0000
37.0800 1142.0000 1.0000
37.1200 1130.0000 1.0000
37.1600 1150.0000 1.0000
37.2000 1128.0000 1.0000
37.2400 1080.0000 1.0000
37.2800 1113.0000 1.0000
37.3200 1112.0000 1.0000
37.3600 1097.0000 1.0000
37.4000 1177.0000 1.0000
37.4400 1096.0000 1.0000
37.4800 1122.0000 1.0000
37.5200 1143.0000 1.0000
37.5600 1118.0000 1.0000
37.6000 1121.0000 1.0000
37.6400 1165.0000 1.0000
37.6800 1131.0000 1.0000
37.7200 1119.0000 1.0000
37.7600 1143.0000 1.0000
37.8000 1121.0000 1.0000
37.8400 1153.0000 1.0000
37.8800 1150.0000 1.0000
37.9200 1211.0000 1.0000
37.9600 1217.0000 1.0000
38.0000 1249.0000 1.0000
38.0400 1243.0000 1.0000
38.0800 1202.0000 1.0000
38.1200 1357.0000 1.0000
38.1600 1412.0000 1.0000
38.2000 1605.0000 1.0000
38.2400 1834.0000 1.0000
38.2800 2085.0000 1.0000
38.3200 2470.0000 1.0000
38.3600 3034.0000 1.0000
38.4000 4045.0000 1.0000
38.4400 5123.0000 1.0000
38.4800 6280.0000 1.0000
38.5200 6834.0000 1.0000
38.5600 6563.0000 1.0000
38.6000 5636.0000 1.0000
38.6400 4608.0000 1.0000
38.6800 3483.0000 1.0000
38.7200 2734.0000 1.0000
38.7600 2094.0000 1.0000
38.8000 1862.0000 1.0000
38.8400 1578.0000 1.0000
38.8800 1444.0000 1.0000
38.9200 1329.0000 1.0000
38.9600 1284.0000 1.0000
39.0000 1211.0000 1.0000
39.0400 1187.0000 1.0000
39.0800 1133.0000 1.0000
39.1200 1086.0000 1.0000
39.1600 1070.0000 1.0000
39.2000 1077.0000 1.0000
39.2400 1058.0000 1.0000
39.2800 1021.0000 1.0000
39.3200 1018.0000 1.0000
39.3600 1062.0000 1.0000
39.4000 1003.0000 1.0000
39.4400 1072.0000 1.0000
39.4800 1076.0000 1.0000
39.5200 1111.0000 1.0000
39.5600 1131.0000 1.0000
39.6000 1097.0000 1.0000
39.6400 1043.0000 1.0000
39.6800 1033.0000 1.0000
39.7200 1029.0000 1.0000
39.7600 996.0000 1.0000
39.8000 1030.0000 1.0000
39.8400 1041.0000 1.0000
39.8800 986.0000 1.0000
39.9200 955.0000 1.0000
39.9600 958.0000 1.0000
40.0000 987.0000 1.0000
40.0400 939.0000 1.0000
40.0800 940.0000 1.0000
40.1200 951.0000 1.0000
40.1600 991.0000 1.0000
40.2000 950.0000 1.0000
40.2400 998.0000 1.0000
40.2800 944.0000 1.0000
40.3200 972.0000 1.0000
40.3600 1024.0000 1.0000
40.4000 965.0000 1.0000
40.4400 919.0000 1.0000
40.4800 962.0000 1.0000
40.5200 954.0000 1.0000
40.5600 915.0000 1.0000
40.6000 977.0000 1.0000
40.6400 984.0000 1.0000
40.6800 940.0000 1.0000
40.7200 954.0000 1.0000
40.7600 918.0000 1.0000
40.8000 955.0000 1.0000
40.8400 926.0000 1.0000
40.8800 902.0000 1.0000
40.9200 951.0000 1.0000
40.9600 932.0000 1.0000
41.0000 897.0000 1.0000
41.0400 955.0000 1.0000
41.0800 972.0000 1.0000
41.1200 952.0000 1.0000
41.1600 911.0000 1.0000
41.2000 947.0000 1.0000
41.2400 946.0000 1.0000
41.2800 915.0000 1.0000
41.3200 939.0000 1.0000
41.3600 929.0000 1.0000
41.4000 948.0000 1.0000
41.4400 964.0000 1.0000
41.4800 941.0000 1.0000
41.5200 940.0000 1.0000
41.5600 955.0000 1.0000
41.6000 893.0000 1.0000
41.6400 1024.0000 1.0000
41.6800 909.0000 1.0000
41.7200 937.0000 1.0000
41.7600 965.0000 1.0000
41.8000 987.0000 1.0000
41.8400 936.0000 1.0000
41.8800 938.0000 1.0000
41.9200 879.0000 1.0000
41.9600 956.0000 1.0000
42.0000 927.0000 1.0000
42.0400 924.0000 1.0000
42.0800 911.0000 1.0000
42.1200 877.0000 1.0000
42.1600 916.0000 1.0000
42.2000 915.0000 1.0000
42.2400 898.0000 1.0000
42.2800 900.0000 1.0000
42.3200 903.0000 1.0000
42.3600 854.0000 1.0000
42.4000 946.0000 1.0000
42.4400 915.0000 1.0000
42.4800 914.0000 1.0000
42.5200 920.0000 1.0000
42.5600 920.0000 1.0000
42.6000 919.0000 1.0000
42.6400 919.0000 1.0000
42.6800 895.0000 1.0000
42.7200 922.0000 1.0000
42.7600 908.0000 1.0000
42.8000 909.0000 1.0000
42.8400 947.0000 1.0000
42.8800 903.0000 1.0000
42.9200 925.0000 1.0000
42.9600 902.0000 1.0000
43.0000 891.0000 1.0000
43.0400 953.0000 1.0000
43.0800 907.0000 1.0000
43.1200 968.0000 1.0000
43.1600 1030.0000 1.0000
43.2000 1026.0000 1.0000
43.2400 962.0000 1.0000
43.2800 1031.0000 1.0000
43.3200 981.0000 1.0000
43.3600 948.0000 1.0000
43.4000 942.0000 1.0000
43.4400 949.0000 1.0000
43.4800 933.0000 1.0000
43.5200 926.0000 1.0000
43.5600 887.0000 1.0000
43.6000 863.0000 1.0000
43.6400 925.0000 1.0000
43.6800 891.0000 1.0000
43.7200 888.0000 1.0000
43.7600 919.0000 1.0000
43.8000 909.0000 1.0000
43.8400 907.0000 1.0000
43.8800 935.0000 1.0000
43.9200 893.0000 1.0000
43.9600 904.0000 1.0000
44.0000 916.0000 1.0000
44.0400 933.0000 1.0000
44.0800 880.0000 1.0000
44.1200 869.0000 1.0000
44.1600 886.0000 1.0000
44.2000 877.0000 1.0000
44.2400 933.0000 1.0000
44.2800 896.0000 1.0000
44.3200 957.0000 1.0000
44.3600 934.0000 1.0000
44.4000 889.0000 1.0000
44.4400 933.0000 1.0000
44.4800 855.0000 1.0000
44.5200 861.0000 1.0000
44.5600 850.0000 1.0000
44.6000 940.0000 1.0000
44.6400 849.0000 1.0000
44.6800 893.0000 1.0000
44.7200 928.0000 1.0000
44.7600 869.0000 1.0000
44.8000 902.0000 1.0000
44.8400 897.0000 1.0000
44.8800 867.0000 1.0000
44.9200 862.0000 1.0000
44.9600 894.0000 1.0000
45.0000 898.0000 1.0000
45.0400 843.0000 1.0000
45.0800 828.0000 1.0000
45.1200 928.0000 1.0000
45.1600 813.0000 1.0000
45.2000 868.0000 1.0000
45.2400 851.0000 1.0000
45.2800 823.0000 1.0000
45.3200 874.0000 1.0000
45.3600 877.0000 1.0000
45.4000 832.0000 1.0000
45.4400 849.0000 1.0000
45.4800 867.0000 1.0000
45.5200 850.0000 1.0000
45.5600 839.0000 1.0000
45.6000 861.0000 1.0000
45.6400 837.0000 1.0000
45.6800 842.0000 1.0000
45.7200 873.0000 1.0000
45.7600 872.0000 1.0000
45.8000 825.0000 1.0000
45.8400 821.0000 1.0000
45.8800 866.0000 1.0000
45.9200 848.0000 1.0000
45.9600 843.0000 1.0000
46.0000 835.0000 1.0000
46.0400 840.0000 1.0000
46.0800 851.0000 1.0000
46.1200 848.0000 1.0000
46.1600 851.0000 1.0000
46.2000 845.0000 1.0000
46.2400 804.0000 1.0000
46.2800 851.0000 1.0000
46.3200 863.0000 1.0000
46.3600 818.0000 1.0000
46.4000 818.0000 1.0000
46.4400 790.0000 1.0000
46.4800 826.0000 1.0000
46.5200 823.0000 1.0000
46.5600 809.0000 1.0000
46.6000 856.0000 1.0000
46.6400 851.0000 1.0000
46.6800 850.0000 1.0000
46.7200 820.0000 1.0000
46.7600 831.0000 1.0000
46.8000 858.0000 1.0000
46.8400 838.0000 1.0000
46.8800 822.0000 1.0000
46.9200 829.0000 1.0000
46.9600 791.0000 1.0000
47.0000 881.0000 1.0000
47.0400 874.0000 1.0000
47.0800 820.0000 1.0000
47.1200 876.0000 1.0000
47.1600 841.0000 1.0000
47.2000 833.0000 1.0000
47.2400 800.0000 1.0000
47.2800 851.0000 1.0000
47.3200 825.0000 1.0000
47.3600 817.0000 1.0000
47.4000 828.0000 1.0000
47.4400 813.0000 1.0000
47.4800 833.0000 1.0000
47.5200 800.0000 1.0000
47.5600 832.0000 1.0000
47.6000 789.0000 1.0000
47.6400 825.0000 1.0000
47.6800 799.0000 1.0000
47.7200 841.0000 1.0000
47.7600 776.0000 1.0000
47.8000 794.0000 1.0000
47.8400 840.0000 1.0000
47.8800 786.0000 1.0000
47.9200 778.0000 1.0000
47.9600 797.0000 1.0000
48.0000 758.0000 1.0000
48.0400 791.0000 1.0000
48.0800 769.0000 1.0000
48.1200 815.0000 1.0000
48.1600 785.0000 1.0000
48.2000 828.0000 1.0000
48.2400 785.0000 1.0000
48.2800 788.0000 1.0000
48.3200 815.0000 1.0000
48.3600 788.0000 1.0000
48.4000 831.0000 1.0000
48.4400 784.0000 1.0000
48.4800 795.0000 1.0000
48.5200 790.0000 1.0000
48.5600 767.0000 1.0000
48.6000 776.0000 1.0000
48.6400 814.0000 1.0000
48.6800 800.0000 1.0000
48.7200 809.0000 1.0000
48.7600 791.0000 1.0000
48.8000 777.0000 1.0000
48.8400 737.0000 1.0000
48.8800 779.0000 1.0000
48.9200 803.0000 1.0000
48.9600 791.0000 1.0000
49.0000 822.0000 1.0000
49.0400 791.0000 1.0000
49.0800 766.0000 1.0000
49.1200 810.0000 1.0000
49.1600 795.0000 1.0000
49.2000 774.0000 1.0000
49.2400 771.0000 1.0000
49.2800 812.0000 1.0000
49.3200 843.0000 1.0000
49.3600 741.0000 1.0000
49.4000 777.0000 1.0000
49.4400 810.0000 1.0000
49.4800 764.0000 1.0000
49.5200 775.0000 1.0000
49.5600 773.0000 1.0000
49.6000 781.0000 1.0000
49.6400 815.0000 1.0000
49.6800 722.0000 1.0000
49.7200 795.0000 1.0000
49.7600 803.0000 1.0000
49.8000 791.0000 1.0000
49.8400 765.0000 1.0000
49.8800 738.0000 1.0000
49.9200 776.0000 1.0000
49.9600 736.0000 1.0000
50.0000 790.0000 1.0000
50.0400 797.0000 1.0000
50.0800 797.0000 1.0000
50.1200 796.0000 1.0000
50.1600 861.0000 1.0000
50.2000 829.0000 1.0000
50.2400 835.0000 1.0000
50.2800 809.0000 1.0000
50.3200 821.0000 1.0000
50.3600 773.0000 1.0000
50.4000 830.0000 1.0000
50.4400 803.0000 1.0000
50.4800 807.0000 1.0000
50.5200 733.0000 1.0000
50.5600 790.0000 1.0000
50.6000 792.0000 1.0000
50.6400 827.0000 1.0000
50.6800 804.0000 1.0000
50.7200 793.0000 1.0000
50.7600 807.0000 1.0000
50.8000 789.0000 1.0000
50.8400 791.0000 1.0000
50.8800 784.0000 1.0000
50.9200 813.0000 1.0000
50.9600 785.0000 1.0000
51.0000 831.0000 1.0000
51.0400 780.0000 1.0000
51.0800 778.0000 1.0000
51.1200 817.0000 1.0000
51.1600 809.0000 1.0000
51.2000 832.0000 1.0000
51.2400 807.0000 1.0000
51.2800 754.0000 1.0000
51.3200 785.0000 1.0000
51.3600 793.0000 1.0000
51.4000 816.0000 1.0000
51.4400 817.0000 1.0000
51.4800 789.0000 1.0000
51.5200 807.0000 1.0000
51.5600 814.0000 1.0000
51.6000 780.0000 1.0000
51.6400 837.0000 1.0000
51.6800 858.0000 1.0000
51.7200 869.0000 1.0000
51.7600 865.0000 1.0000
51.8000 906.0000 1.0000
51.8400 905.0000 1.0000
51.8800 955.0000 1.0000
51.9200 1097.0000 1.0000
51.9600 1176.0000 1.0000
52.0000 1340.0000 1.0000
52.0400 1562.0000 1.0000
52.0800 1935.0000 1.0000
52.1200 2552.0000 1.0000
52.1600 3625.0000 1.0000
52.2000 4920.0000 1.0000
52.2400 5822.0000 1.0000
52.2800 5634.0000 1.0000
52.3200 5105.0000 1.0000
52.3600 4543.0000 1.0000
52.4000 4015.0000 1.0000
52.4400 3064.0000 1.0000
52.4800 2326.0000 1.0000
52.5200 1865.0000 1.0000
52.5600 1566.0000 1.0000
52.6000 1260.0000 1.0000
52.6400 1158.0000 1.0000
52.6800 1074.0000 1.0000
52.7200 1015.0000 1.0000
52.7600 964.0000 1.0000
52.8000 949.0000 1.0000
52.8400 899.0000 1.0000
52.8800 882.0000 1.0000
52.9200 866.0000 1.0000
52.9600 888.0000 1.0000
53.0000 808.0000 1.0000
53.0400 852.0000 1.0000
53.0800 844.0000 1.0000
53.1200 788.0000 1.0000
53.1600 873.0000 1.0000
53.2000 849.0000 1.0000
53.2400 817.0000 1.0000
53.2800 822.0000 1.0000
53.3200 786.0000 1.0000
53.3600 781.0000 1.0000
53.4000 800.0000 1.0000
53.4400 759.0000 1.0000
53.4800 825.0000 1.0000
53.5200 799.0000 1.0000
53.5600 792.0000 1.0000
53.6000 822.0000 1.0000
53.6400 746.0000 1.0000
53.6800 775.0000 1.0000
53.7200 762.0000 1.0000
53.7600 777.0000 1.0000
53.8000 768.0000 1.0000
53.8400 744.0000 1.0000
53.8800 817.0000 1.0000
53.9200 744.0000 1.0000
53.9600 754.0000 1.0000
54.0000 779.0000 1.0000
54.0400 766.0000 1.0000
54.0800 748.0000 1.0000
54.1200 759.0000 1.0000
54.1600 783.0000 1.0000
54.2000 772.0000 1.0000
54.2400 739.0000 1.0000
54.2800 775.0000 1.0000
54.3200 730.0000 1.0000
54.3600 740.0000 1.0000
54.4000 779.0000 1.0000
54.4400 752.0000 1.0000
54.4800 793.0000 1.0000
54.5200 818.0000 1.0000
54.5600 762.0000 1.0000
54.6000 767.0000 1.0000
54.6400 778.0000 1.0000
54.6800 810.0000 1.0000
54.7200 811.0000 1.0000
54.7600 867.0000 1.0000
54.8000 806.0000 1.0000
54.8400 834.0000 1.0000
54.8800 830.0000 1.0000
54.9200 827.0000 1.0000
54.9600 809.0000 1.0000
55.0000 874.0000 1.0000
55.0400 900.0000 1.0000
55.0800 886.0000 1.0000
55.1200 936.0000 1.0000
55.1600 999.0000 1.0000
55.2000 998.0000 1.0000
55.2400 1125.0000 1.0000
55.2800 1131.0000 1.0000
55.3200 1130.0000 1.0000
55.3600 1066.0000 1.0000
55.4000 1176.0000 1.0000
55.4400 1011.0000 1.0000
55.4800 977.0000 1.0000
55.5200 925.0000 1.0000
55.5600 908.0000 1.0000
55.6000 857.0000 1.0000
55.6400 811.0000 1.0000
55.6800 777.0000 1.0000
55.7200 787.0000 1.0000
55.7600 766.0000 1.0000
55.8000 783.0000 1.0000
55.8400 786.0000 1.0000
55.8800 709.0000 1.0000
55.9200 786.0000 1.0000
55.9600 768.0000 1.0000
56.0000 743.0000 1.0000
56.0400 792.0000 1.0000
56.0800 720.0000 1.0000
56.1200 745.0000 1.0000
56.1600 752.0000 1.0000
56.2000 703.0000 1.0000
56.2400 738.0000 1.0000
56.2800 761.0000 1.0000
56.3200 701.0000 1.0000
56.3600 758.0000 1.0000
56.4000 739.0000 1.0000
56.4400 716.0000 1.0000
56.4800 753.0000 1.0000
56.5200 752.0000 1.0000
56.5600 741.0000 1.0000
56.6000 735.0000 1.0000
56.6400 710.0000 1.0000
56.6800 676.0000 1.0000
56.7200 757.0000 1.0000
56.7600 733.0000 1.0000
56.8000 756.0000 1.0000
56.8400 761.0000 1.0000
56.8800 722.0000 1.0000
56.9200 730.0000 1.0000
56.9600 724.0000 1.0000
57.0000 734.0000 1.0000
57.0400 739.0000 1.0000
57.0800 764.0000 1.0000
57.1200 729.0000 1.0000
57.1600 710.0000 1.0000
57.2000 733.0000 1.0000
57.2400 767.0000 1.0000
57.2800 700.0000 1.0000
57.3200 775.0000 1.0000
57.3600 723.0000 1.0000
57.4000 666.0000 1.0000
57.4400 733.0000 1.0000
57.4800 738.0000 1.0000
57.5200 718.0000 1.0000
57.5600 756.0000 1.0000
57.6000 774.0000 1.0000
57.6400 745.0000 1.0000
57.6800 742.0000 1.0000
57.7200 748.0000 1.0000
57.7600 675.0000 1.0000
57.8000 710.0000 1.0000
57.8400 714.0000 1.0000
57.8800 731.0000 1.0000
57.9200 742.0000 1.0000
57.9600 776.0000 1.0000
58.0000 744.0000 1.0000
58.0400 743.0000 1.0000
58.0800 743.0000 1.0000
58.1200 739.0000 1.0000
58.1600 721.0000 1.0000
58.2000 795.0000 1.0000
58.2400 758.0000 1.0000
58.2800 731.0000 1.0000
58.3200 762.0000 1.0000
58.3600 728.0000 1.0000
58.4000 733.0000 1.0000
58.4400 765.0000 1.0000
58.4800 728.0000 1.0000
58.5200 737.0000 1.0000
58.5600 701.0000 1.0000
58.6000 747.0000 1.0000
58.6400 742.0000 1.0000
58.6800 733.0000 1.0000
58.7200 713.0000 1.0000
58.7600 752.0000 1.0000
58.8000 728.0000 1.0000
58.8400 772.0000 1.0000
58.8800 700.0000 1.0000
58.9200 707.0000 1.0000
58.9600 757.0000 1.0000
59.0000 755.0000 1.0000
59.0400 756.0000 1.0000
59.0800 748.0000 1.0000
59.1200 703.0000 1.0000
59.1600 736.0000 1.0000
59.2000 752.0000 1.0000
59.2400 786.0000 1.0000
59.2800 708.0000 1.0000
59.3200 701.0000 1.0000
59.3600 712.0000 1.0000
59.4000 743.0000 1.0000
59.4400 760.0000 1.0000
59.4800 705.0000 1.0000
59.5200 705.0000 1.0000
59.5600 712.0000 1.0000
59.6000 738.0000 1.0000
59.6400 748.0000 1.0000
59.6800 732.0000 1.0000
59.7200 716.0000 1.0000
59.7600 732.0000 1.0000
59.8000 724.0000 1.0000
59.8400 751.0000 1.0000
59.8800 713.0000 1.0000
59.9200 735.0000 1.0000
59.9600 730.0000 1.0000
60.0000 750.0000 1.0000
60.0400 718.0000 1.0000
60.0800 784.0000 1.0000
60.1200 708.0000 1.0000
60.1600 755.0000 1.0000
60.2000 711.0000 1.0000
60.2400 740.0000 1.0000
60.2800 703.0000 1.0000
60.3200 710.0000 1.0000
60.3600 685.0000 1.0000
60.4000 743.0000 1.0000
60.4400 736.0000 1.0000
60.4800 707.0000 1.0000
60.5200 747.0000 1.0000
60.5600 686.0000 1.0000
60.6000 740.0000 1.0000
60.6400 728.0000 1.0000
60.6800 749.0000 1.0000
60.7200 765.0000 1.0000
60.7600 705.0000 1.0000
60.8000 729.0000 1.0000
60.8400 659.0000 1.0000
60.8800 732.0000 1.0000
60.9200 713.0000 1.0000
60.9600 688.0000 1.0000
61.0000 728.0000 1.0000
61.0400 740.0000 1.0000
61.0800 708.0000 1.0000
61.1200 715.0000 1.0000
61.1600 744.0000 1.0000
61.2000 693.0000 1.0000
61.2400 722.0000 1.0000
61.2800 698.0000 1.0000
61.3200 734.0000 1.0000
61.3600 729.0000 1.0000
61.4000 728.0000 1.0000
61.4400 710.0000 1.0000
61.4800 718.0000 1.0000
61.5200 767.0000 1.0000
61.5600 701.0000 1.0000
61.6000 750.0000 1.0000
61.6400 788.0000 1.0000
61.6800 790.0000 1.0000
61.7200 737.0000 1.0000
61.7600 777.0000 1.0000
61.8000 749.0000 1.0000
61.8400 826.0000 1.0000
61.8800 763.0000 1.0000
61.9200 817.0000 1.0000
61.9600 841.0000 1.0000
62.0000 925.0000 1.0000
62.0400 1045.0000 1.0000
62.0800 1146.0000 1.0000
62.1200 1220.0000 1.0000
62.1600 1440.0000 1.0000
62.2000 1559.0000 1.0000
62.2400 1717.0000 1.0000
62.2800 1607.0000 1.0000
62.3200 1617.0000 1.0000
62.3600 1562.0000 1.0000
62.4000 1532.0000 1.0000
62.4400 1426.0000 1.0000
62.4800 1359.0000 1.0000
62.5200 1184.0000 1.0000
62.5600 1121.0000 1.0000
62.6000 966.0000 1.0000
62.6400 995.0000 1.0000
62.6800 879.0000 1.0000
62.7200 826.0000 1.0000
62.7600 807.0000 1.0000
62.8000 851.0000 1.0000
62.8400 774.0000 1.0000
62.8800 798.0000 1.0000
62.9200 794.0000 1.0000
62.9600 842.0000 1.0000
63.0000 792.0000 1.0000
63.0400 803.0000 1.0000
63.0800 817.0000 1.0000
63.1200 793.0000 1.0000
63.1600 739.0000 1.0000
63.2000 804.0000 1.0000
63.2400 800.0000 1.0000
63.2800 764.0000 1.0000
63.3200 788.0000 1.0000
63.3600 753.0000 1.0000
63.4000 715.0000 1.0000
63.4400 783.0000 1.0000
63.4800 724.0000 1.0000
63.5200 720.0000 1.0000
63.5600 722.0000 1.0000
63.6000 742.0000 1.0000
63.6400 747.0000 1.0000
63.6800 757.0000 1.0000
63.7200 739.0000 1.0000
63.7600 715.0000 1.0000
63.8000 739.0000 1.0000
63.8400 712.0000 1.0000
63.8800 747.0000 1.0000
63.9200 712.0000 1.0000
63.9600 751.0000 1.0000
64.0000 730.0000 1.0000
64.0400 750.0000 1.0000
64.0800 722.0000 1.0000
64.1200 758.0000 1.0000
64.1600 741.0000 1.0000
64.2000 751.0000 1.0000
64.2400 726.0000 1.0000
64.2800 722.0000 1.0000
64.3200 764.0000 1.0000
64.3600 714.0000 1.0000
64.4000 729.0000 1.0000
64.4400 800.0000 1.0000
64.4800 765.0000 1.0000
64.5200 803.0000 1.0000
64.5600 844.0000 1.0000
64.6000 960.0000 1.0000
64.6400 981.0000 1.0000
64.6800 963.0000 1.0000
64.7200 1017.0000 1.0000
64.7600 943.0000 1.0000
64.8000 917.0000 1.0000
64.8400 891.0000 1.0000
64.8800 859.0000 1.0000
64.9200 829.0000 1.0000
64.9600 800.0000 1.0000
65.0000 771.0000 1.0000
65.0400 758.0000 1.0000
65.0800 795.0000 1.0000
65.1200 805.0000 1.0000
65.1600 769.0000 1.0000
65.2000 797.0000 1.0000
65.2400 721.0000 1.0000
65.2800 766.0000 1.0000
65.3200 767.0000 1.0000
65.3600 775.0000 1.0000
65.4000 749.0000 1.0000
65.4400 748.0000 1.0000
65.4800 749.0000 1.0000
65.5200 771.0000 1.0000
65.5600 747.0000 1.0000
65.6000 774.0000 1.0000
65.6400 792.0000 1.0000
65.6800 808.0000 1.0000
65.7200 742.0000 1.0000
65.7600 816.0000 1.0000
65.8000 834.0000 1.0000
65.8400 895.0000 1.0000
65.8800 907.0000 1.0000
65.9200 1003.0000 1.0000
65.9600 1086.0000 1.0000
66.0000 1124.0000 1.0000
66.0400 1342.0000 1.0000
66.0800 1529.0000 1.0000
66.1200 1984.0000 1.0000
66.1600 2312.0000 1.0000
66.2000 2751.0000 1.0000
66.2400 3060.0000 1.0000
66.2800 2850.0000 1.0000
66.3200 2706.0000 1.0000
66.3600 2501.0000 1.0000
66.4000 2394.0000 1.0000
66.4400 2231.0000 1.0000
66.4800 1945.0000 1.0000
66.5200 1656.0000 1.0000
66.5600 1382.0000 1.0000
66.6000 1238.0000 1.0000
66.6400 1132.0000 1.0000
66.6800 1037.0000 1.0000
66.7200 920.0000 1.0000
66.7600 936.0000 1.0000
66.8000 863.0000 1.0000
66.8400 846.0000 1.0000
66.8800 775.0000 1.0000
66.9200 726.0000 1.0000
66.9600 752.0000 1.0000
67.0000 745.0000 1.0000
67.0400 741.0000 1.0000
67.0800 722.0000 1.0000
67.1200 707.0000 1.0000
67.1600 739.0000 1.0000
67.2000 738.0000 1.0000
67.2400 747.0000 1.0000
67.2800 711.0000 1.0000
67.3200 683.0000 1.0000
67.3600 746.0000 1.0000
67.4000 671.0000 1.0000
67.4400 616.0000 1.0000
67.4800 691.0000 1.0000
67.5200 684.0000 1.0000
67.5600 687.0000 1.0000
67.6000 707.0000 1.0000
67.6400 681.0000 1.0000
67.6800 630.0000 1.0000
67.7200 647.0000 1.0000
67.7600 645.0000 1.0000
67.8000 662.0000 1.0000
67.8400 697.0000 1.0000
67.8800 671.0000 1.0000
67.9200 662.0000 1.0000
67.9600 658.0000 1.0000
68.0000 686.0000 1.0000
68.0400 677.0000 1.0000
68.0800 687.0000 1.0000
68.1200 663.0000 1.0000
68.1600 664.0000 1.0000
68.2000 673.0000 1.0000
68.2400 667.0000 1.0000
68.2800 662.0000 1.0000
68.3200 675.0000 1.0000
68.3600 661.0000 1.0000
68.4000 667.0000 1.0000
68.4400 631.0000 1.0000
68.4800 653.0000 1.0000
68.5200 666.0000 1.0000
68.5600 636.0000 1.0000
68.6000 652.0000 1.0000
68.6400 657.0000 1.0000
68.6800 680.0000 1.0000
68.7200 684.0000 1.0000
68.7600 653.0000 1.0000
68.8000 589.0000 1.0000
68.8400 630.0000 1.0000
68.8800 690.0000 1.0000
68.9200 668.0000 1.0000
68.9600 646.0000 1.0000
69.0000 661.0000 1.0000
69.0400 658.0000 1.0000
69.0800 652.0000 1.0000
69.1200 672.0000 1.0000
69.1600 607.0000 1.0000
69.2000 656.0000 1.0000
69.2400 670.0000 1.0000
69.2800 661.0000 1.0000
69.3200 642.0000 1.0000
69.3600 628.0000 1.0000
69.4000 619.0000 1.0000
69.4400 658.0000 1.0000
69.4800 693.0000 1.0000
69.5200 622.0000 1.0000
69.5600 645.0000 1.0000
69.6000 674.0000 1.0000
69.6400 664.0000 1.0000
69.6800 604.0000 1.0000
69.7200 655.0000 1.0000
69.7600 686.0000 1.0000
69.8000 616.0000 1.0000
69.8400 600.0000 1.0000
69.8800 648.0000 1.0000
69.9200 615.0000 1.0000
69.9600 619.0000 1.0000
70.0000 629.0000 1.0000
*RAS_INT_END
*RAS_TEMPERATURE_START
*RAS_TEMPERATURE_END
*RAS_DATA_END