File: Data/Dataset1_Only_water/5_XRD/No_009_FS3_1.ras
*RAS_DATA_START
*RAS_HEADER_START
*DISP_FMT_X "%.2f"
*DISP_FMT_Y "%.0f"
*DISP_FULLSCALE "15176.0000000000"
*DISP_LINE_COLOR "255.0000000000"
*DISP_LINE_STYLE "0.0000000000"
*DISP_LINE_WIDTH "0.2500000000"
*DISP_NOTE "測定データ-6"
*DISP_OFFSET_Y "0.0000000000"
*DISP_PEAKSEARCH_UNIT_Y "cps"
*DISP_RANGE_BOTTOM "0.0000000000"
*DISP_RANGE_LEFT "20.0000000000"
*DISP_RANGE_LOGCUTOFF "0.0100000000"
*DISP_RANGE_RIGHT "70.0000000000"
*DISP_RANGE_TOP "15176.0000000000"
*DISP_SCALE_MODE_Y "0.0000000000"
*DISP_TAB_NAME "2θ/θ"
*DISP_TITLE_Y "強度"
*DISP_UNIT_Y "cps"
*DISP_WINDOW_NAME "MSG_MACROENGINE"
*FILE_COMMENT " "
*FILE_MD5 ""
*FILE_MEMO " "
*FILE_OPERATOR "Administrator"
*FILE_SAMPLE " "
*FILE_TYPE "RAS_RAW"
*FILE_USERGROUP "システムマネージャ"
*FILE_VERSION "1.0000000000"
*HW_ATTACHMENT_ID "ATT0025"
*HW_ATTACHMENT_NAME "標準|Standard"
*HW_COUNTER_ID-0 "CUT0025"
*HW_COUNTER_ID-1 "CUT0020"
*HW_COUNTER_ID-2 "CUT0020"
*HW_COUNTER_ID-3 "CSL0021"
*HW_COUNTER_ID-4 "CMC0021"
*HW_COUNTER_NAME-0 "D/teX Ultra|D/teX Ultra"
*HW_COUNTER_NAME-1 "None|None"
*HW_COUNTER_NAME-2 "None|None"
*HW_COUNTER_NAME-3 "BBM|BBM"
*HW_COUNTER_NAME-4 "検出器モノクロメータ|Detector monochromator"
*HW_COUNTER_SELECT_NAME "D/teX Ultra|D/teX Ultra"
*HW_GONIOMETER_ID "GON0023"
*HW_GONIOMETER_NAME "SmartLab|SmartLab"
*HW_GONIOMETER_RADIUS-0 "90.0"
*HW_GONIOMETER_RADIUS-1 "114.0"
*HW_GONIOMETER_RADIUS-2 "190.0"
*HW_GONIOMETER_RADIUS-3 "300.0"
*HW_GONIOMETER_RADIUS-4 "187.0"
*HW_GONIOMETER_RADIUS-5 "300.0"
*HW_GONIOMETER_RADIUS-6 "113.0"
*HW_GONIOMETER_RADIUS-7 "331.0"
*HW_I_OPT_ID-0 "CBO0021"
*HW_I_OPT_ID-1 "ICR0023"
*HW_I_OPT_ID-2 "ISL0021"
*HW_I_OPT_ID-3 "ISO0021"
*HW_I_OPT_ID-4 "IAD0021"
*HW_I_OPT_ID-5 "IPR0001"
*HW_I_OPT_NAME-0 "CBOユニット|CBO unit"
*HW_I_OPT_NAME-1 "標準入射光学ユニット|Standard incident optical unit"
*HW_I_OPT_NAME-2 "標準入射スリットボックス|Standard incident slit box"
*HW_I_OPT_NAME-3 "入射平行スリット|Incident parallel slit"
*HW_I_OPT_NAME-4 "長手制限スリット|Length limiting slit"
*HW_I_OPT_NAME-5 "None|None"
*HW_R_ATTENUATER_AUTOMODE "0"
*HW_R_OPT_ID-0 "RSS0021"
*HW_R_OPT_ID-1 "RCR0023"
*HW_R_OPT_ID-2 "RSO0021"
*HW_R_OPT_ID-3 "RRS0021"
*HW_R_OPT_ID-4 "ATN0021"
*HW_R_OPT_ID-5 "RFL0021"
*HW_R_OPT_ID-6 "RAD0021"
*HW_R_OPT_NAME-0 "標準受光スリットボックス1|Standard receiving slit box # 1"
*HW_R_OPT_NAME-1 "標準受光光学ユニット1|Standard receiving unit # 1"
*HW_R_OPT_NAME-2 "標準受光光学ユニット2|Standard receiving optical unit # 2"
*HW_R_OPT_NAME-3 "標準受光スリットボックス2|Standard receiving slit box # 2"
*HW_R_OPT_NAME-4 "標準アッテネータ|Standard Attenuator"
*HW_R_OPT_NAME-5 "Cu Kβ|Cu K-beta"
*HW_R_OPT_NAME-6 "調整用受光スリット|Alignment receiving slit"
*HW_SAMPLE_HOLDER_ID "SMP0023"
*HW_SAMPLE_HOLDER_NAME "標準Zステージ|Standard Z stage"
*HW_XG_CURRENT_MAX "50"
*HW_XG_CURRENT_MIN "2"
*HW_XG_CURRENT_RESOLUTION "1"
*HW_XG_CURRENT_UNIT "mA"
*HW_XG_FOCUS "1mm x 10mm"
*HW_XG_FOCUS_TYPE "Normal"
*HW_XG_ID ""
*HW_XG_NAME "3kW 封入管(ID:1200)|3kW Sealed tube(ID:1200)"
*HW_XG_TARGET_ATOMIC_NUMBER "29.0000000000"
*HW_XG_TARGET_NAME "Cu"
*HW_XG_TYPE "Hermetic"
*HW_XG_VOLTAGE_MAX "60"
*HW_XG_VOLTAGE_MIN "20"
*HW_XG_VOLTAGE_RESOLUTION "1"
*HW_XG_VOLTAGE_UNIT "kV"
*HW_XG_WATT_MAX "1.500"
*HW_XG_WATT_UNIT "kW"
*HW_XG_WAVE_LENGTH_ALPHA1 "1.540593"
*HW_XG_WAVE_LENGTH_ALPHA2 "1.544414"
*HW_XG_WAVE_LENGTH_BETA "1.392250"
*MEAS_COND_AXIS_NAME-0 "2θ/θ"
*MEAS_COND_AXIS_NAME-1 "2θ"
*MEAS_COND_AXIS_NAME-2 "ω"
*MEAS_COND_AXIS_NAME-3 "Z"
*MEAS_COND_AXIS_NAME-4 "2θ/ω"
*MEAS_COND_AXIS_NAME-5 "θs"
*MEAS_COND_AXIS_NAME-6 "θd"
*MEAS_COND_AXIS_NAME-7 "Ts"
*MEAS_COND_AXIS_NAME-8 "CBO選択スリット"
*MEAS_COND_AXIS_NAME-9 "M"
*MEAS_COND_AXIS_NAME-10 "入射平行スリット"
*MEAS_COND_AXIS_NAME-11 "入射スリット"
*MEAS_COND_AXIS_NAME-12 ""
*MEAS_COND_AXIS_NAME-13 "Zs"
*MEAS_COND_AXIS_NAME-14 "入射光学素子"
*MEAS_COND_AXIS_NAME-15 "長手制限スリット"
*MEAS_COND_AXIS_NAME-16 "センタースリット"
*MEAS_COND_AXIS_NAME-17 "フィルター"
*MEAS_COND_AXIS_NAME-18 "受光スリット1"
*MEAS_COND_AXIS_NAME-19 "受光スリット2"
*MEAS_COND_AXIS_NAME-20 "受光光学素子"
*MEAS_COND_AXIS_NAME-21 "受光平行スリット"
*MEAS_COND_AXIS_NAME-22 "調整用受光スリット"
*MEAS_COND_AXIS_NAME-23 ""
*MEAS_COND_AXIS_NAME-24 ""
*MEAS_COND_AXIS_NAME-25 "Zd"
*MEAS_COND_AXIS_NAME-26 "アッテネータ"
*MEAS_COND_AXIS_NAME-27 "検出器モノクロメータ"
*MEAS_COND_AXIS_NAME-28 "モノクロメータスリット"
*MEAS_COND_AXIS_NAME-29 "プライマリビーム"
*MEAS_COND_AXIS_NAME-30 "PHA"
*MEAS_COND_AXIS_NAME_INTERNAL-0 "TwoThetaTheta"
*MEAS_COND_AXIS_NAME_INTERNAL-1 "TwoTheta"
*MEAS_COND_AXIS_NAME_INTERNAL-2 "Omega"
*MEAS_COND_AXIS_NAME_INTERNAL-3 "Z"
*MEAS_COND_AXIS_NAME_INTERNAL-4 "TwoThetaOmega"
*MEAS_COND_AXIS_NAME_INTERNAL-5 "ThetaS"
*MEAS_COND_AXIS_NAME_INTERNAL-6 "ThetaD"
*MEAS_COND_AXIS_NAME_INTERNAL-7 "Ts"
*MEAS_COND_AXIS_NAME_INTERNAL-8 "CBO"
*MEAS_COND_AXIS_NAME_INTERNAL-9 "CBO-M"
*MEAS_COND_AXIS_NAME_INTERNAL-10 "IncidentSollerSlit"
*MEAS_COND_AXIS_NAME_INTERNAL-11 "IncidentSlitBox"
*MEAS_COND_AXIS_NAME_INTERNAL-12 "IncidentSlitBox-_Axis"
*MEAS_COND_AXIS_NAME_INTERNAL-13 "Zs"
*MEAS_COND_AXIS_NAME_INTERNAL-14 "IncidentMonochromator"
*MEAS_COND_AXIS_NAME_INTERNAL-15 "IncidentAxdSlit"
*MEAS_COND_AXIS_NAME_INTERNAL-16 "CenterSlit"
*MEAS_COND_AXIS_NAME_INTERNAL-17 "Filter"
*MEAS_COND_AXIS_NAME_INTERNAL-18 "ReceivingSlitBox1"
*MEAS_COND_AXIS_NAME_INTERNAL-19 "ReceivingSlitBox2"
*MEAS_COND_AXIS_NAME_INTERNAL-20 "ReceivingOptics"
*MEAS_COND_AXIS_NAME_INTERNAL-21 "ReceivingSollerSlit"
*MEAS_COND_AXIS_NAME_INTERNAL-22 "ReceivingAxdSlit"
*MEAS_COND_AXIS_NAME_INTERNAL-23 "ReceivingSlitBox1-_Axis"
*MEAS_COND_AXIS_NAME_INTERNAL-24 "ReceivingSlitBox2-_Axis"
*MEAS_COND_AXIS_NAME_INTERNAL-25 "ReceivingSlitBox2-Zd"
*MEAS_COND_AXIS_NAME_INTERNAL-26 "Attenuator"
*MEAS_COND_AXIS_NAME_INTERNAL-27 "CounterMonochromator"
*MEAS_COND_AXIS_NAME_INTERNAL-28 "CounterSlit"
*MEAS_COND_AXIS_NAME_INTERNAL-29 "IncidentPrimary"
*MEAS_COND_AXIS_NAME_INTERNAL-30 "PHA"
*MEAS_COND_AXIS_NAME_MAGICNO-0 "83951616.0000000000"
*MEAS_COND_AXIS_NAME_MAGICNO-1 "268632064.0000000000"
*MEAS_COND_AXIS_NAME_MAGICNO-2 "268500992.0000000000"
*MEAS_COND_AXIS_NAME_MAGICNO-3 "285278208.0000000000"
*MEAS_COND_AXIS_NAME_MAGICNO-4 "83951616.0000000000"
*MEAS_COND_AXIS_NAME_MAGICNO-5 "131072.0000000000"
*MEAS_COND_AXIS_NAME_MAGICNO-6 "131072.0000000000"
*MEAS_COND_AXIS_NAME_MAGICNO-7 "318898176.0000000000"
*MEAS_COND_AXIS_NAME_MAGICNO-8 "20971521.0000000000"
*MEAS_COND_AXIS_NAME_MAGICNO-9 "285343744.0000000000"
*MEAS_COND_AXIS_NAME_MAGICNO-10 "20971521.0000000000"
*MEAS_COND_AXIS_NAME_MAGICNO-11 "22020097.0000000000"
*MEAS_COND_AXIS_NAME_MAGICNO-12 "25165824.0000000000"
*MEAS_COND_AXIS_NAME_MAGICNO-13 "318898176.0000000000"
*MEAS_COND_AXIS_NAME_MAGICNO-14 "1.0000000000"
*MEAS_COND_AXIS_NAME_MAGICNO-15 "20971521.0000000000"
*MEAS_COND_AXIS_NAME_MAGICNO-16 "20971521.0000000000"
*MEAS_COND_AXIS_NAME_MAGICNO-17 "20971521.0000000000"
*MEAS_COND_AXIS_NAME_MAGICNO-18 "23068673.0000000000"
*MEAS_COND_AXIS_NAME_MAGICNO-19 "23068673.0000000000"
*MEAS_COND_AXIS_NAME_MAGICNO-20 "20971521.0000000000"
*MEAS_COND_AXIS_NAME_MAGICNO-21 "20971521.0000000000"
*MEAS_COND_AXIS_NAME_MAGICNO-22 "20971521.0000000000"
*MEAS_COND_AXIS_NAME_MAGICNO-23 "25165824.0000000000"
*MEAS_COND_AXIS_NAME_MAGICNO-24 "25165824.0000000000"
*MEAS_COND_AXIS_NAME_MAGICNO-25 "285343744.0000000000"
*MEAS_COND_AXIS_NAME_MAGICNO-26 "17301505.0000000000"
*MEAS_COND_AXIS_NAME_MAGICNO-27 "20971521.0000000000"
*MEAS_COND_AXIS_NAME_MAGICNO-28 "20971521.0000000000"
*MEAS_COND_AXIS_NAME_MAGICNO-29 "20971521.0000000000"
*MEAS_COND_AXIS_NAME_MAGICNO-30 "0.0000000000"
*MEAS_COND_AXIS_OFFSET-0 "-"
*MEAS_COND_AXIS_OFFSET-1 "-0.1081000000"
*MEAS_COND_AXIS_OFFSET-2 "0.3758000000"
*MEAS_COND_AXIS_OFFSET-3 "-"
*MEAS_COND_AXIS_OFFSET-4 "-"
*MEAS_COND_AXIS_OFFSET-5 "0.3758000000"
*MEAS_COND_AXIS_OFFSET-6 "-0.4839000000"
*MEAS_COND_AXIS_OFFSET-7 "-"
*MEAS_COND_AXIS_OFFSET-8 "-"
*MEAS_COND_AXIS_OFFSET-9 "-"
*MEAS_COND_AXIS_OFFSET-10 "-"
*MEAS_COND_AXIS_OFFSET-11 "-"
*MEAS_COND_AXIS_OFFSET-12 "-"
*MEAS_COND_AXIS_OFFSET-13 "-"
*MEAS_COND_AXIS_OFFSET-14 "-"
*MEAS_COND_AXIS_OFFSET-15 "-"
*MEAS_COND_AXIS_OFFSET-16 "-"
*MEAS_COND_AXIS_OFFSET-17 "-"
*MEAS_COND_AXIS_OFFSET-18 "-"
*MEAS_COND_AXIS_OFFSET-19 "-"
*MEAS_COND_AXIS_OFFSET-20 "-"
*MEAS_COND_AXIS_OFFSET-21 "-"
*MEAS_COND_AXIS_OFFSET-22 "-"
*MEAS_COND_AXIS_OFFSET-23 "-"
*MEAS_COND_AXIS_OFFSET-24 "-"
*MEAS_COND_AXIS_OFFSET-25 "-"
*MEAS_COND_AXIS_OFFSET-26 "-"
*MEAS_COND_AXIS_OFFSET-27 "-"
*MEAS_COND_AXIS_OFFSET-28 "-"
*MEAS_COND_AXIS_OFFSET-29 "-"
*MEAS_COND_AXIS_OFFSET-30 "-"
*MEAS_COND_AXIS_POSITION-0 "0.0000000000"
*MEAS_COND_AXIS_POSITION-1 "0.0000000000"
*MEAS_COND_AXIS_POSITION-2 "0.0000000000"
*MEAS_COND_AXIS_POSITION-3 "-0.5500000000"
*MEAS_COND_AXIS_POSITION-4 "0.0000000000"
*MEAS_COND_AXIS_POSITION-5 "0.0000000000"
*MEAS_COND_AXIS_POSITION-6 "0.0000000000"
*MEAS_COND_AXIS_POSITION-7 "-0.4278800000"
*MEAS_COND_AXIS_POSITION-8 "BB"
*MEAS_COND_AXIS_POSITION-9 "0.0000000000"
*MEAS_COND_AXIS_POSITION-10 "Soller_slit_5.0deg"
*MEAS_COND_AXIS_POSITION-11 "2/3deg"
*MEAS_COND_AXIS_POSITION-12 "2.2088000000"
*MEAS_COND_AXIS_POSITION-13 "-0.4140600000"
*MEAS_COND_AXIS_POSITION-14 "0.0000000000"
*MEAS_COND_AXIS_POSITION-15 "10.0mm"
*MEAS_COND_AXIS_POSITION-16 "None"
*MEAS_COND_AXIS_POSITION-17 "Cu_K-beta"
*MEAS_COND_AXIS_POSITION-18 "13.000mm"
*MEAS_COND_AXIS_POSITION-19 "13.000mm"
*MEAS_COND_AXIS_POSITION-20 "No_unit"
*MEAS_COND_AXIS_POSITION-21 "Soller_slit_5.0deg"
*MEAS_COND_AXIS_POSITION-22 "None"
*MEAS_COND_AXIS_POSITION-23 "13.0000000000"
*MEAS_COND_AXIS_POSITION-24 "13.0000000000"
*MEAS_COND_AXIS_POSITION-25 "0.0109400000"
*MEAS_COND_AXIS_POSITION-26 "Open"
*MEAS_COND_AXIS_POSITION-27 "None"
*MEAS_COND_AXIS_POSITION-28 "None"
*MEAS_COND_AXIS_POSITION-29 "None"
*MEAS_COND_AXIS_POSITION-30 "38.0000000000"
*MEAS_COND_AXIS_UNIT-0 "deg"
*MEAS_COND_AXIS_UNIT-1 "deg"
*MEAS_COND_AXIS_UNIT-2 "deg"
*MEAS_COND_AXIS_UNIT-3 "mm"
*MEAS_COND_AXIS_UNIT-4 "deg"
*MEAS_COND_AXIS_UNIT-5 "deg"
*MEAS_COND_AXIS_UNIT-6 "deg"
*MEAS_COND_AXIS_UNIT-7 "mm"
*MEAS_COND_AXIS_UNIT-8 ""
*MEAS_COND_AXIS_UNIT-9 "pulse"
*MEAS_COND_AXIS_UNIT-10 ""
*MEAS_COND_AXIS_UNIT-11 ""
*MEAS_COND_AXIS_UNIT-12 "mm"
*MEAS_COND_AXIS_UNIT-13 "mm"
*MEAS_COND_AXIS_UNIT-14 ""
*MEAS_COND_AXIS_UNIT-15 ""
*MEAS_COND_AXIS_UNIT-16 ""
*MEAS_COND_AXIS_UNIT-17 ""
*MEAS_COND_AXIS_UNIT-18 ""
*MEAS_COND_AXIS_UNIT-19 ""
*MEAS_COND_AXIS_UNIT-20 ""
*MEAS_COND_AXIS_UNIT-21 ""
*MEAS_COND_AXIS_UNIT-22 ""
*MEAS_COND_AXIS_UNIT-23 "mm"
*MEAS_COND_AXIS_UNIT-24 "mm"
*MEAS_COND_AXIS_UNIT-25 "mm"
*MEAS_COND_AXIS_UNIT-26 ""
*MEAS_COND_AXIS_UNIT-27 ""
*MEAS_COND_AXIS_UNIT-28 ""
*MEAS_COND_AXIS_UNIT-29 ""
*MEAS_COND_AXIS_UNIT-30 "div"
*MEAS_COND_COUNTER_CNTLOSS_CORR "0.0000000000"
*MEAS_COND_COUNTER_PHABASE "38.0000000000"
*MEAS_COND_COUNTER_PHAWINDOW "16.0000000000"
*MEAS_COND_COUNTER_PHA_UNIT "div"
*MEAS_COND_COUNTER_TAUDIFF "30.0000000000"
*MEAS_COND_COUNTER_TAUINT "0.0000000000"
*MEAS_COND_IRRADIATION_MODE "OFF"
*MEAS_COND_IRRADIATION_WIDTH ""
*MEAS_COND_OPT_ATTR "集中法"
*MEAS_COND_OPT_NAME "@集中法"
*MEAS_COND_UNSYMMETRIC_MODE "OFF"
*MEAS_COND_XG_CURRENT "30.0000000000"
*MEAS_COND_XG_VOLTAGE "40.0000000000"
*MEAS_COND_XG_WAVE_TYPE "Ka"
*MEAS_DATA_COUNT "5001.0000000000"
*MEAS_SCAN_AXIS_X "2θ/θ"
*MEAS_SCAN_AXIS_X_INTERNAL "TwoThetaTheta"
*MEAS_SCAN_END_TIME "06/30/21 17:09:56"
*MEAS_SCAN_MODE "CONTINUOUS"
*MEAS_SCAN_MONITOR "0"
*MEAS_SCAN_RESOLUTION_X "0.0002"
*MEAS_SCAN_SPEED "1.0"
*MEAS_SCAN_SPEED_UNIT "deg/min"
*MEAS_SCAN_START "20.0000000000"
*MEAS_SCAN_START_TIME "06/30/21 16:17:03"
*MEAS_SCAN_STEP "0.0100000000"
*MEAS_SCAN_STOP "70.0000000000"
*MEAS_SCAN_UNIT_X "deg"
*MEAS_SCAN_UNIT_Y "counts"
*RAS_HEADER_END
*RAS_INT_START
20.0000 1498.0000 1.0000
20.0400 1504.0000 1.0000
20.0800 1546.0000 1.0000
20.1200 1558.0000 1.0000
20.1600 1555.0000 1.0000
20.2000 1597.0000 1.0000
20.2400 1491.0000 1.0000
20.2800 1527.0000 1.0000
20.3200 1510.0000 1.0000
20.3600 1546.0000 1.0000
20.4000 1501.0000 1.0000
20.4400 1590.0000 1.0000
20.4800 1543.0000 1.0000
20.5200 1508.0000 1.0000
20.5600 1549.0000 1.0000
20.6000 1502.0000 1.0000
20.6400 1477.0000 1.0000
20.6800 1559.0000 1.0000
20.7200 1435.0000 1.0000
20.7600 1515.0000 1.0000
20.8000 1563.0000 1.0000
20.8400 1591.0000 1.0000
20.8800 1557.0000 1.0000
20.9200 1562.0000 1.0000
20.9600 1520.0000 1.0000
21.0000 1516.0000 1.0000
21.0400 1560.0000 1.0000
21.0800 1547.0000 1.0000
21.1200 1496.0000 1.0000
21.1600 1496.0000 1.0000
21.2000 1516.0000 1.0000
21.2400 1591.0000 1.0000
21.2800 1503.0000 1.0000
21.3200 1523.0000 1.0000
21.3600 1514.0000 1.0000
21.4000 1492.0000 1.0000
21.4400 1570.0000 1.0000
21.4800 1518.0000 1.0000
21.5200 1581.0000 1.0000
21.5600 1540.0000 1.0000
21.6000 1555.0000 1.0000
21.6400 1562.0000 1.0000
21.6800 1524.0000 1.0000
21.7200 1536.0000 1.0000
21.7600 1566.0000 1.0000
21.8000 1544.0000 1.0000
21.8400 1548.0000 1.0000
21.8800 1564.0000 1.0000
21.9200 1538.0000 1.0000
21.9600 1487.0000 1.0000
22.0000 1497.0000 1.0000
22.0400 1522.0000 1.0000
22.0800 1566.0000 1.0000
22.1200 1532.0000 1.0000
22.1600 1537.0000 1.0000
22.2000 1568.0000 1.0000
22.2400 1556.0000 1.0000
22.2800 1582.0000 1.0000
22.3200 1582.0000 1.0000
22.3600 1535.0000 1.0000
22.4000 1551.0000 1.0000
22.4400 1539.0000 1.0000
22.4800 1571.0000 1.0000
22.5200 1578.0000 1.0000
22.5600 1554.0000 1.0000
22.6000 1507.0000 1.0000
22.6400 1530.0000 1.0000
22.6800 1595.0000 1.0000
22.7200 1537.0000 1.0000
22.7600 1579.0000 1.0000
22.8000 1558.0000 1.0000
22.8400 1630.0000 1.0000
22.8800 1594.0000 1.0000
22.9200 1612.0000 1.0000
22.9600 1594.0000 1.0000
23.0000 1503.0000 1.0000
23.0400 1555.0000 1.0000
23.0800 1623.0000 1.0000
23.1200 1549.0000 1.0000
23.1600 1563.0000 1.0000
23.2000 1516.0000 1.0000
23.2400 1517.0000 1.0000
23.2800 1559.0000 1.0000
23.3200 1482.0000 1.0000
23.3600 1529.0000 1.0000
23.4000 1684.0000 1.0000
23.4400 1645.0000 1.0000
23.4800 1598.0000 1.0000
23.5200 1597.0000 1.0000
23.5600 1550.0000 1.0000
23.6000 1528.0000 1.0000
23.6400 1556.0000 1.0000
23.6800 1602.0000 1.0000
23.7200 1491.0000 1.0000
23.7600 1567.0000 1.0000
23.8000 1627.0000 1.0000
23.8400 1554.0000 1.0000
23.8800 1613.0000 1.0000
23.9200 1650.0000 1.0000
23.9600 1509.0000 1.0000
24.0000 1570.0000 1.0000
24.0400 1593.0000 1.0000
24.0800 1580.0000 1.0000
24.1200 1583.0000 1.0000
24.1600 1560.0000 1.0000
24.2000 1607.0000 1.0000
24.2400 1574.0000 1.0000
24.2800 1566.0000 1.0000
24.3200 1585.0000 1.0000
24.3600 1587.0000 1.0000
24.4000 1587.0000 1.0000
24.4400 1616.0000 1.0000
24.4800 1628.0000 1.0000
24.5200 1632.0000 1.0000
24.5600 1588.0000 1.0000
24.6000 1531.0000 1.0000
24.6400 1618.0000 1.0000
24.6800 1643.0000 1.0000
24.7200 1669.0000 1.0000
24.7600 1630.0000 1.0000
24.8000 1629.0000 1.0000
24.8400 1652.0000 1.0000
24.8800 1733.0000 1.0000
24.9200 1668.0000 1.0000
24.9600 1651.0000 1.0000
25.0000 1647.0000 1.0000
25.0400 1653.0000 1.0000
25.0800 1647.0000 1.0000
25.1200 1670.0000 1.0000
25.1600 1666.0000 1.0000
25.2000 1626.0000 1.0000
25.2400 1611.0000 1.0000
25.2800 1641.0000 1.0000
25.3200 1632.0000 1.0000
25.3600 1590.0000 1.0000
25.4000 1602.0000 1.0000
25.4400 1676.0000 1.0000
25.4800 1604.0000 1.0000
25.5200 1588.0000 1.0000
25.5600 1635.0000 1.0000
25.6000 1636.0000 1.0000
25.6400 1589.0000 1.0000
25.6800 1631.0000 1.0000
25.7200 1640.0000 1.0000
25.7600 1673.0000 1.0000
25.8000 1581.0000 1.0000
25.8400 1654.0000 1.0000
25.8800 1616.0000 1.0000
25.9200 1642.0000 1.0000
25.9600 1685.0000 1.0000
26.0000 1626.0000 1.0000
26.0400 1660.0000 1.0000
26.0800 1614.0000 1.0000
26.1200 1593.0000 1.0000
26.1600 1610.0000 1.0000
26.2000 1735.0000 1.0000
26.2400 1709.0000 1.0000
26.2800 1633.0000 1.0000
26.3200 1641.0000 1.0000
26.3600 1645.0000 1.0000
26.4000 1633.0000 1.0000
26.4400 1709.0000 1.0000
26.4800 1626.0000 1.0000
26.5200 1702.0000 1.0000
26.5600 1718.0000 1.0000
26.6000 1717.0000 1.0000
26.6400 1695.0000 1.0000
26.6800 1754.0000 1.0000
26.7200 1746.0000 1.0000
26.7600 1784.0000 1.0000
26.8000 1835.0000 1.0000
26.8400 1793.0000 1.0000
26.8800 1897.0000 1.0000
26.9200 1856.0000 1.0000
26.9600 2055.0000 1.0000
27.0000 2114.0000 1.0000
27.0400 2289.0000 1.0000
27.0800 2466.0000 1.0000
27.1200 2758.0000 1.0000
27.1600 3216.0000 1.0000
27.2000 3857.0000 1.0000
27.2400 4607.0000 1.0000
27.2800 5421.0000 1.0000
27.3200 5988.0000 1.0000
27.3600 5963.0000 1.0000
27.4000 5135.0000 1.0000
27.4400 4318.0000 1.0000
27.4800 3508.0000 1.0000
27.5200 3045.0000 1.0000
27.5600 2684.0000 1.0000
27.6000 2406.0000 1.0000
27.6400 2202.0000 1.0000
27.6800 2039.0000 1.0000
27.7200 2064.0000 1.0000
27.7600 1898.0000 1.0000
27.8000 1885.0000 1.0000
27.8400 1761.0000 1.0000
27.8800 1795.0000 1.0000
27.9200 1815.0000 1.0000
27.9600 1705.0000 1.0000
28.0000 1678.0000 1.0000
28.0400 1768.0000 1.0000
28.0800 1691.0000 1.0000
28.1200 1629.0000 1.0000
28.1600 1699.0000 1.0000
28.2000 1600.0000 1.0000
28.2400 1638.0000 1.0000
28.2800 1644.0000 1.0000
28.3200 1626.0000 1.0000
28.3600 1597.0000 1.0000
28.4000 1550.0000 1.0000
28.4400 1597.0000 1.0000
28.4800 1577.0000 1.0000
28.5200 1559.0000 1.0000
28.5600 1621.0000 1.0000
28.6000 1593.0000 1.0000
28.6400 1551.0000 1.0000
28.6800 1609.0000 1.0000
28.7200 1554.0000 1.0000
28.7600 1608.0000 1.0000
28.8000 1553.0000 1.0000
28.8400 1536.0000 1.0000
28.8800 1546.0000 1.0000
28.9200 1564.0000 1.0000
28.9600 1580.0000 1.0000
29.0000 1485.0000 1.0000
29.0400 1522.0000 1.0000
29.0800 1535.0000 1.0000
29.1200 1562.0000 1.0000
29.1600 1517.0000 1.0000
29.2000 1558.0000 1.0000
29.2400 1469.0000 1.0000
29.2800 1486.0000 1.0000
29.3200 1515.0000 1.0000
29.3600 1507.0000 1.0000
29.4000 1510.0000 1.0000
29.4400 1564.0000 1.0000
29.4800 1483.0000 1.0000
29.5200 1514.0000 1.0000
29.5600 1551.0000 1.0000
29.6000 1524.0000 1.0000
29.6400 1496.0000 1.0000
29.6800 1475.0000 1.0000
29.7200 1573.0000 1.0000
29.7600 1516.0000 1.0000
29.8000 1462.0000 1.0000
29.8400 1498.0000 1.0000
29.8800 1528.0000 1.0000
29.9200 1503.0000 1.0000
29.9600 1466.0000 1.0000
30.0000 1479.0000 1.0000
30.0400 1474.0000 1.0000
30.0800 1432.0000 1.0000
30.1200 1477.0000 1.0000
30.1600 1475.0000 1.0000
30.2000 1442.0000 1.0000
30.2400 1430.0000 1.0000
30.2800 1466.0000 1.0000
30.3200 1486.0000 1.0000
30.3600 1420.0000 1.0000
30.4000 1495.0000 1.0000
30.4400 1508.0000 1.0000
30.4800 1530.0000 1.0000
30.5200 1476.0000 1.0000
30.5600 1401.0000 1.0000
30.6000 1412.0000 1.0000
30.6400 1473.0000 1.0000
30.6800 1441.0000 1.0000
30.7200 1418.0000 1.0000
30.7600 1412.0000 1.0000
30.8000 1390.0000 1.0000
30.8400 1410.0000 1.0000
30.8800 1437.0000 1.0000
30.9200 1447.0000 1.0000
30.9600 1484.0000 1.0000
31.0000 1411.0000 1.0000
31.0400 1418.0000 1.0000
31.0800 1380.0000 1.0000
31.1200 1400.0000 1.0000
31.1600 1404.0000 1.0000
31.2000 1437.0000 1.0000
31.2400 1391.0000 1.0000
31.2800 1427.0000 1.0000
31.3200 1468.0000 1.0000
31.3600 1481.0000 1.0000
31.4000 1415.0000 1.0000
31.4400 1449.0000 1.0000
31.4800 1397.0000 1.0000
31.5200 1397.0000 1.0000
31.5600 1402.0000 1.0000
31.6000 1376.0000 1.0000
31.6400 1407.0000 1.0000
31.6800 1379.0000 1.0000
31.7200 1403.0000 1.0000
31.7600 1417.0000 1.0000
31.8000 1363.0000 1.0000
31.8400 1375.0000 1.0000
31.8800 1404.0000 1.0000
31.9200 1382.0000 1.0000
31.9600 1388.0000 1.0000
32.0000 1433.0000 1.0000
32.0400 1442.0000 1.0000
32.0800 1433.0000 1.0000
32.1200 1399.0000 1.0000
32.1600 1366.0000 1.0000
32.2000 1393.0000 1.0000
32.2400 1342.0000 1.0000
32.2800 1421.0000 1.0000
32.3200 1369.0000 1.0000
32.3600 1389.0000 1.0000
32.4000 1389.0000 1.0000
32.4400 1395.0000 1.0000
32.4800 1341.0000 1.0000
32.5200 1342.0000 1.0000
32.5600 1352.0000 1.0000
32.6000 1309.0000 1.0000
32.6400 1338.0000 1.0000
32.6800 1362.0000 1.0000
32.7200 1405.0000 1.0000
32.7600 1285.0000 1.0000
32.8000 1279.0000 1.0000
32.8400 1337.0000 1.0000
32.8800 1350.0000 1.0000
32.9200 1332.0000 1.0000
32.9600 1294.0000 1.0000
33.0000 1327.0000 1.0000
33.0400 1333.0000 1.0000
33.0800 1288.0000 1.0000
33.1200 1289.0000 1.0000
33.1600 1397.0000 1.0000
33.2000 1308.0000 1.0000
33.2400 1298.0000 1.0000
33.2800 1287.0000 1.0000
33.3200 1382.0000 1.0000
33.3600 1246.0000 1.0000
33.4000 1306.0000 1.0000
33.4400 1300.0000 1.0000
33.4800 1298.0000 1.0000
33.5200 1353.0000 1.0000
33.5600 1321.0000 1.0000
33.6000 1275.0000 1.0000
33.6400 1272.0000 1.0000
33.6800 1349.0000 1.0000
33.7200 1306.0000 1.0000
33.7600 1310.0000 1.0000
33.8000 1339.0000 1.0000
33.8400 1418.0000 1.0000
33.8800 1357.0000 1.0000
33.9200 1469.0000 1.0000
33.9600 1526.0000 1.0000
34.0000 1544.0000 1.0000
34.0400 1430.0000 1.0000
34.0800 1432.0000 1.0000
34.1200 1423.0000 1.0000
34.1600 1493.0000 1.0000
34.2000 1489.0000 1.0000
34.2400 1559.0000 1.0000
34.2800 1626.0000 1.0000
34.3200 1705.0000 1.0000
34.3600 1884.0000 1.0000
34.4000 2048.0000 1.0000
34.4400 2424.0000 1.0000
34.4800 2731.0000 1.0000
34.5200 2974.0000 1.0000
34.5600 2781.0000 1.0000
34.6000 2607.0000 1.0000
34.6400 2282.0000 1.0000
34.6800 1971.0000 1.0000
34.7200 1842.0000 1.0000
34.7600 1704.0000 1.0000
34.8000 1590.0000 1.0000
34.8400 1484.0000 1.0000
34.8800 1422.0000 1.0000
34.9200 1347.0000 1.0000
34.9600 1346.0000 1.0000
35.0000 1296.0000 1.0000
35.0400 1289.0000 1.0000
35.0800 1305.0000 1.0000
35.1200 1294.0000 1.0000
35.1600 1222.0000 1.0000
35.2000 1266.0000 1.0000
35.2400 1213.0000 1.0000
35.2800 1214.0000 1.0000
35.3200 1202.0000 1.0000
35.3600 1246.0000 1.0000
35.4000 1173.0000 1.0000
35.4400 1167.0000 1.0000
35.4800 1122.0000 1.0000
35.5200 1103.0000 1.0000
35.5600 1111.0000 1.0000
35.6000 1107.0000 1.0000
35.6400 1143.0000 1.0000
35.6800 1117.0000 1.0000
35.7200 1157.0000 1.0000
35.7600 1100.0000 1.0000
35.8000 1114.0000 1.0000
35.8400 1156.0000 1.0000
35.8800 1130.0000 1.0000
35.9200 1096.0000 1.0000
35.9600 1129.0000 1.0000
36.0000 1081.0000 1.0000
36.0400 1092.0000 1.0000
36.0800 1156.0000 1.0000
36.1200 1078.0000 1.0000
36.1600 1220.0000 1.0000
36.2000 1241.0000 1.0000
36.2400 1243.0000 1.0000
36.2800 1326.0000 1.0000
36.3200 1504.0000 1.0000
36.3600 1693.0000 1.0000
36.4000 2042.0000 1.0000
36.4400 2252.0000 1.0000
36.4800 2073.0000 1.0000
36.5200 1860.0000 1.0000
36.5600 1625.0000 1.0000
36.6000 1323.0000 1.0000
36.6400 1203.0000 1.0000
36.6800 1153.0000 1.0000
36.7200 1125.0000 1.0000
36.7600 1094.0000 1.0000
36.8000 1056.0000 1.0000
36.8400 1048.0000 1.0000
36.8800 1072.0000 1.0000
36.9200 1092.0000 1.0000
36.9600 1030.0000 1.0000
37.0000 984.0000 1.0000
37.0400 1031.0000 1.0000
37.0800 1030.0000 1.0000
37.1200 1053.0000 1.0000
37.1600 976.0000 1.0000
37.2000 1051.0000 1.0000
37.2400 1025.0000 1.0000
37.2800 1006.0000 1.0000
37.3200 1029.0000 1.0000
37.3600 1026.0000 1.0000
37.4000 1030.0000 1.0000
37.4400 1059.0000 1.0000
37.4800 996.0000 1.0000
37.5200 1071.0000 1.0000
37.5600 997.0000 1.0000
37.6000 1031.0000 1.0000
37.6400 1015.0000 1.0000
37.6800 1052.0000 1.0000
37.7200 1026.0000 1.0000
37.7600 1020.0000 1.0000
37.8000 1068.0000 1.0000
37.8400 1049.0000 1.0000
37.8800 1036.0000 1.0000
37.9200 1061.0000 1.0000
37.9600 1057.0000 1.0000
38.0000 1143.0000 1.0000
38.0400 1086.0000 1.0000
38.0800 1125.0000 1.0000
38.1200 1136.0000 1.0000
38.1600 1317.0000 1.0000
38.2000 1367.0000 1.0000
38.2400 1427.0000 1.0000
38.2800 1643.0000 1.0000
38.3200 2034.0000 1.0000
38.3600 2245.0000 1.0000
38.4000 2827.0000 1.0000
38.4400 3645.0000 1.0000
38.4800 4751.0000 1.0000
38.5200 6179.0000 1.0000
38.5600 7199.0000 1.0000
38.6000 7472.0000 1.0000
38.6400 6807.0000 1.0000
38.6800 5848.0000 1.0000
38.7200 4537.0000 1.0000
38.7600 3418.0000 1.0000
38.8000 2607.0000 1.0000
38.8400 2076.0000 1.0000
38.8800 1748.0000 1.0000
38.9200 1495.0000 1.0000
38.9600 1289.0000 1.0000
39.0000 1197.0000 1.0000
39.0400 1136.0000 1.0000
39.0800 1153.0000 1.0000
39.1200 1080.0000 1.0000
39.1600 1041.0000 1.0000
39.2000 1042.0000 1.0000
39.2400 982.0000 1.0000
39.2800 997.0000 1.0000
39.3200 1002.0000 1.0000
39.3600 1032.0000 1.0000
39.4000 968.0000 1.0000
39.4400 996.0000 1.0000
39.4800 968.0000 1.0000
39.5200 962.0000 1.0000
39.5600 974.0000 1.0000
39.6000 923.0000 1.0000
39.6400 1000.0000 1.0000
39.6800 923.0000 1.0000
39.7200 925.0000 1.0000
39.7600 966.0000 1.0000
39.8000 943.0000 1.0000
39.8400 898.0000 1.0000
39.8800 909.0000 1.0000
39.9200 873.0000 1.0000
39.9600 895.0000 1.0000
40.0000 925.0000 1.0000
40.0400 869.0000 1.0000
40.0800 915.0000 1.0000
40.1200 890.0000 1.0000
40.1600 901.0000 1.0000
40.2000 907.0000 1.0000
40.2400 898.0000 1.0000
40.2800 880.0000 1.0000
40.3200 864.0000 1.0000
40.3600 890.0000 1.0000
40.4000 898.0000 1.0000
40.4400 877.0000 1.0000
40.4800 862.0000 1.0000
40.5200 882.0000 1.0000
40.5600 841.0000 1.0000
40.6000 832.0000 1.0000
40.6400 888.0000 1.0000
40.6800 868.0000 1.0000
40.7200 853.0000 1.0000
40.7600 851.0000 1.0000
40.8000 803.0000 1.0000
40.8400 914.0000 1.0000
40.8800 876.0000 1.0000
40.9200 808.0000 1.0000
40.9600 846.0000 1.0000
41.0000 817.0000 1.0000
41.0400 858.0000 1.0000
41.0800 864.0000 1.0000
41.1200 828.0000 1.0000
41.1600 842.0000 1.0000
41.2000 829.0000 1.0000
41.2400 869.0000 1.0000
41.2800 868.0000 1.0000
41.3200 869.0000 1.0000
41.3600 800.0000 1.0000
41.4000 824.0000 1.0000
41.4400 815.0000 1.0000
41.4800 833.0000 1.0000
41.5200 852.0000 1.0000
41.5600 825.0000 1.0000
41.6000 831.0000 1.0000
41.6400 916.0000 1.0000
41.6800 907.0000 1.0000
41.7200 853.0000 1.0000
41.7600 871.0000 1.0000
41.8000 800.0000 1.0000
41.8400 852.0000 1.0000
41.8800 866.0000 1.0000
41.9200 866.0000 1.0000
41.9600 836.0000 1.0000
42.0000 814.0000 1.0000
42.0400 819.0000 1.0000
42.0800 798.0000 1.0000
42.1200 851.0000 1.0000
42.1600 835.0000 1.0000
42.2000 846.0000 1.0000
42.2400 866.0000 1.0000
42.2800 813.0000 1.0000
42.3200 851.0000 1.0000
42.3600 823.0000 1.0000
42.4000 859.0000 1.0000
42.4400 832.0000 1.0000
42.4800 829.0000 1.0000
42.5200 823.0000 1.0000
42.5600 835.0000 1.0000
42.6000 892.0000 1.0000
42.6400 844.0000 1.0000
42.6800 823.0000 1.0000
42.7200 788.0000 1.0000
42.7600 845.0000 1.0000
42.8000 796.0000 1.0000
42.8400 813.0000 1.0000
42.8800 855.0000 1.0000
42.9200 817.0000 1.0000
42.9600 861.0000 1.0000
43.0000 844.0000 1.0000
43.0400 813.0000 1.0000
43.0800 884.0000 1.0000
43.1200 847.0000 1.0000
43.1600 918.0000 1.0000
43.2000 890.0000 1.0000
43.2400 923.0000 1.0000
43.2800 943.0000 1.0000
43.3200 900.0000 1.0000
43.3600 893.0000 1.0000
43.4000 891.0000 1.0000
43.4400 870.0000 1.0000
43.4800 852.0000 1.0000
43.5200 841.0000 1.0000
43.5600 826.0000 1.0000
43.6000 812.0000 1.0000
43.6400 797.0000 1.0000
43.6800 819.0000 1.0000
43.7200 814.0000 1.0000
43.7600 787.0000 1.0000
43.8000 798.0000 1.0000
43.8400 774.0000 1.0000
43.8800 825.0000 1.0000
43.9200 842.0000 1.0000
43.9600 785.0000 1.0000
44.0000 831.0000 1.0000
44.0400 800.0000 1.0000
44.0800 831.0000 1.0000
44.1200 843.0000 1.0000
44.1600 809.0000 1.0000
44.2000 819.0000 1.0000
44.2400 795.0000 1.0000
44.2800 812.0000 1.0000
44.3200 785.0000 1.0000
44.3600 800.0000 1.0000
44.4000 774.0000 1.0000
44.4400 815.0000 1.0000
44.4800 805.0000 1.0000
44.5200 810.0000 1.0000
44.5600 788.0000 1.0000
44.6000 748.0000 1.0000
44.6400 817.0000 1.0000
44.6800 798.0000 1.0000
44.7200 787.0000 1.0000
44.7600 787.0000 1.0000
44.8000 808.0000 1.0000
44.8400 822.0000 1.0000
44.8800 816.0000 1.0000
44.9200 785.0000 1.0000
44.9600 748.0000 1.0000
45.0000 821.0000 1.0000
45.0400 764.0000 1.0000
45.0800 808.0000 1.0000
45.1200 794.0000 1.0000
45.1600 753.0000 1.0000
45.2000 803.0000 1.0000
45.2400 790.0000 1.0000
45.2800 812.0000 1.0000
45.3200 739.0000 1.0000
45.3600 751.0000 1.0000
45.4000 777.0000 1.0000
45.4400 762.0000 1.0000
45.4800 838.0000 1.0000
45.5200 782.0000 1.0000
45.5600 751.0000 1.0000
45.6000 789.0000 1.0000
45.6400 757.0000 1.0000
45.6800 752.0000 1.0000
45.7200 744.0000 1.0000
45.7600 740.0000 1.0000
45.8000 758.0000 1.0000
45.8400 718.0000 1.0000
45.8800 764.0000 1.0000
45.9200 760.0000 1.0000
45.9600 745.0000 1.0000
46.0000 723.0000 1.0000
46.0400 775.0000 1.0000
46.0800 806.0000 1.0000
46.1200 729.0000 1.0000
46.1600 745.0000 1.0000
46.2000 785.0000 1.0000
46.2400 746.0000 1.0000
46.2800 723.0000 1.0000
46.3200 754.0000 1.0000
46.3600 741.0000 1.0000
46.4000 775.0000 1.0000
46.4400 735.0000 1.0000
46.4800 723.0000 1.0000
46.5200 747.0000 1.0000
46.5600 791.0000 1.0000
46.6000 800.0000 1.0000
46.6400 756.0000 1.0000
46.6800 712.0000 1.0000
46.7200 762.0000 1.0000
46.7600 749.0000 1.0000
46.8000 710.0000 1.0000
46.8400 725.0000 1.0000
46.8800 811.0000 1.0000
46.9200 767.0000 1.0000
46.9600 739.0000 1.0000
47.0000 787.0000 1.0000
47.0400 749.0000 1.0000
47.0800 802.0000 1.0000
47.1200 759.0000 1.0000
47.1600 778.0000 1.0000
47.2000 769.0000 1.0000
47.2400 748.0000 1.0000
47.2800 775.0000 1.0000
47.3200 733.0000 1.0000
47.3600 766.0000 1.0000
47.4000 736.0000 1.0000
47.4400 766.0000 1.0000
47.4800 723.0000 1.0000
47.5200 760.0000 1.0000
47.5600 731.0000 1.0000
47.6000 751.0000 1.0000
47.6400 778.0000 1.0000
47.6800 722.0000 1.0000
47.7200 741.0000 1.0000
47.7600 757.0000 1.0000
47.8000 695.0000 1.0000
47.8400 690.0000 1.0000
47.8800 763.0000 1.0000
47.9200 755.0000 1.0000
47.9600 749.0000 1.0000
48.0000 708.0000 1.0000
48.0400 711.0000 1.0000
48.0800 728.0000 1.0000
48.1200 724.0000 1.0000
48.1600 719.0000 1.0000
48.2000 769.0000 1.0000
48.2400 742.0000 1.0000
48.2800 723.0000 1.0000
48.3200 733.0000 1.0000
48.3600 705.0000 1.0000
48.4000 730.0000 1.0000
48.4400 758.0000 1.0000
48.4800 728.0000 1.0000
48.5200 749.0000 1.0000
48.5600 694.0000 1.0000
48.6000 766.0000 1.0000
48.6400 711.0000 1.0000
48.6800 715.0000 1.0000
48.7200 727.0000 1.0000
48.7600 708.0000 1.0000
48.8000 695.0000 1.0000
48.8400 677.0000 1.0000
48.8800 682.0000 1.0000
48.9200 724.0000 1.0000
48.9600 751.0000 1.0000
49.0000 789.0000 1.0000
49.0400 722.0000 1.0000
49.0800 716.0000 1.0000
49.1200 699.0000 1.0000
49.1600 717.0000 1.0000
49.2000 680.0000 1.0000
49.2400 703.0000 1.0000
49.2800 725.0000 1.0000
49.3200 717.0000 1.0000
49.3600 692.0000 1.0000
49.4000 714.0000 1.0000
49.4400 700.0000 1.0000
49.4800 707.0000 1.0000
49.5200 701.0000 1.0000
49.5600 720.0000 1.0000
49.6000 710.0000 1.0000
49.6400 695.0000 1.0000
49.6800 675.0000 1.0000
49.7200 690.0000 1.0000
49.7600 749.0000 1.0000
49.8000 711.0000 1.0000
49.8400 712.0000 1.0000
49.8800 712.0000 1.0000
49.9200 701.0000 1.0000
49.9600 722.0000 1.0000
50.0000 685.0000 1.0000
50.0400 710.0000 1.0000
50.0800 705.0000 1.0000
50.1200 768.0000 1.0000
50.1600 704.0000 1.0000
50.2000 735.0000 1.0000
50.2400 770.0000 1.0000
50.2800 737.0000 1.0000
50.3200 745.0000 1.0000
50.3600 674.0000 1.0000
50.4000 728.0000 1.0000
50.4400 732.0000 1.0000
50.4800 742.0000 1.0000
50.5200 718.0000 1.0000
50.5600 726.0000 1.0000
50.6000 743.0000 1.0000
50.6400 788.0000 1.0000
50.6800 717.0000 1.0000
50.7200 712.0000 1.0000
50.7600 684.0000 1.0000
50.8000 681.0000 1.0000
50.8400 688.0000 1.0000
50.8800 732.0000 1.0000
50.9200 725.0000 1.0000
50.9600 706.0000 1.0000
51.0000 649.0000 1.0000
51.0400 741.0000 1.0000
51.0800 720.0000 1.0000
51.1200 707.0000 1.0000
51.1600 735.0000 1.0000
51.2000 716.0000 1.0000
51.2400 705.0000 1.0000
51.2800 721.0000 1.0000
51.3200 720.0000 1.0000
51.3600 691.0000 1.0000
51.4000 736.0000 1.0000
51.4400 748.0000 1.0000
51.4800 734.0000 1.0000
51.5200 728.0000 1.0000
51.5600 746.0000 1.0000
51.6000 726.0000 1.0000
51.6400 768.0000 1.0000
51.6800 744.0000 1.0000
51.7200 754.0000 1.0000
51.7600 792.0000 1.0000
51.8000 785.0000 1.0000
51.8400 772.0000 1.0000
51.8800 796.0000 1.0000
51.9200 830.0000 1.0000
51.9600 949.0000 1.0000
52.0000 1031.0000 1.0000
52.0400 1140.0000 1.0000
52.0800 1248.0000 1.0000
52.1200 1526.0000 1.0000
52.1600 1986.0000 1.0000
52.2000 2645.0000 1.0000
52.2400 3510.0000 1.0000
52.2800 4448.0000 1.0000
52.3200 4938.0000 1.0000
52.3600 4282.0000 1.0000
52.4000 3834.0000 1.0000
52.4400 3461.0000 1.0000
52.4800 2915.0000 1.0000
52.5200 2224.0000 1.0000
52.5600 1659.0000 1.0000
52.6000 1434.0000 1.0000
52.6400 1145.0000 1.0000
52.6800 1060.0000 1.0000
52.7200 993.0000 1.0000
52.7600 966.0000 1.0000
52.8000 893.0000 1.0000
52.8400 821.0000 1.0000
52.8800 797.0000 1.0000
52.9200 833.0000 1.0000
52.9600 758.0000 1.0000
53.0000 756.0000 1.0000
53.0400 791.0000 1.0000
53.0800 712.0000 1.0000
53.1200 721.0000 1.0000
53.1600 744.0000 1.0000
53.2000 709.0000 1.0000
53.2400 753.0000 1.0000
53.2800 685.0000 1.0000
53.3200 670.0000 1.0000
53.3600 693.0000 1.0000
53.4000 766.0000 1.0000
53.4400 668.0000 1.0000
53.4800 717.0000 1.0000
53.5200 700.0000 1.0000
53.5600 701.0000 1.0000
53.6000 734.0000 1.0000
53.6400 697.0000 1.0000
53.6800 693.0000 1.0000
53.7200 702.0000 1.0000
53.7600 722.0000 1.0000
53.8000 702.0000 1.0000
53.8400 682.0000 1.0000
53.8800 698.0000 1.0000
53.9200 714.0000 1.0000
53.9600 685.0000 1.0000
54.0000 706.0000 1.0000
54.0400 686.0000 1.0000
54.0800 678.0000 1.0000
54.1200 685.0000 1.0000
54.1600 716.0000 1.0000
54.2000 672.0000 1.0000
54.2400 698.0000 1.0000
54.2800 688.0000 1.0000
54.3200 681.0000 1.0000
54.3600 614.0000 1.0000
54.4000 706.0000 1.0000
54.4400 694.0000 1.0000
54.4800 713.0000 1.0000
54.5200 701.0000 1.0000
54.5600 667.0000 1.0000
54.6000 663.0000 1.0000
54.6400 730.0000 1.0000
54.6800 709.0000 1.0000
54.7200 735.0000 1.0000
54.7600 735.0000 1.0000
54.8000 753.0000 1.0000
54.8400 725.0000 1.0000
54.8800 788.0000 1.0000
54.9200 741.0000 1.0000
54.9600 734.0000 1.0000
55.0000 745.0000 1.0000
55.0400 774.0000 1.0000
55.0800 800.0000 1.0000
55.1200 789.0000 1.0000
55.1600 868.0000 1.0000
55.2000 935.0000 1.0000
55.2400 971.0000 1.0000
55.2800 1060.0000 1.0000
55.3200 1056.0000 1.0000
55.3600 1040.0000 1.0000
55.4000 971.0000 1.0000
55.4400 948.0000 1.0000
55.4800 904.0000 1.0000
55.5200 888.0000 1.0000
55.5600 815.0000 1.0000
55.6000 826.0000 1.0000
55.6400 813.0000 1.0000
55.6800 765.0000 1.0000
55.7200 731.0000 1.0000
55.7600 716.0000 1.0000
55.8000 691.0000 1.0000
55.8400 694.0000 1.0000
55.8800 686.0000 1.0000
55.9200 727.0000 1.0000
55.9600 691.0000 1.0000
56.0000 660.0000 1.0000
56.0400 671.0000 1.0000
56.0800 717.0000 1.0000
56.1200 683.0000 1.0000
56.1600 699.0000 1.0000
56.2000 690.0000 1.0000
56.2400 616.0000 1.0000
56.2800 654.0000 1.0000
56.3200 678.0000 1.0000
56.3600 663.0000 1.0000
56.4000 725.0000 1.0000
56.4400 719.0000 1.0000
56.4800 660.0000 1.0000
56.5200 692.0000 1.0000
56.5600 607.0000 1.0000
56.6000 689.0000 1.0000
56.6400 675.0000 1.0000
56.6800 709.0000 1.0000
56.7200 687.0000 1.0000
56.7600 630.0000 1.0000
56.8000 684.0000 1.0000
56.8400 684.0000 1.0000
56.8800 684.0000 1.0000
56.9200 667.0000 1.0000
56.9600 648.0000 1.0000
57.0000 652.0000 1.0000
57.0400 668.0000 1.0000
57.0800 661.0000 1.0000
57.1200 685.0000 1.0000
57.1600 643.0000 1.0000
57.2000 598.0000 1.0000
57.2400 722.0000 1.0000
57.2800 640.0000 1.0000
57.3200 639.0000 1.0000
57.3600 669.0000 1.0000
57.4000 643.0000 1.0000
57.4400 679.0000 1.0000
57.4800 637.0000 1.0000
57.5200 631.0000 1.0000
57.5600 634.0000 1.0000
57.6000 618.0000 1.0000
57.6400 661.0000 1.0000
57.6800 649.0000 1.0000
57.7200 626.0000 1.0000
57.7600 632.0000 1.0000
57.8000 635.0000 1.0000
57.8400 664.0000 1.0000
57.8800 658.0000 1.0000
57.9200 694.0000 1.0000
57.9600 653.0000 1.0000
58.0000 659.0000 1.0000
58.0400 617.0000 1.0000
58.0800 676.0000 1.0000
58.1200 697.0000 1.0000
58.1600 680.0000 1.0000
58.2000 686.0000 1.0000
58.2400 669.0000 1.0000
58.2800 711.0000 1.0000
58.3200 702.0000 1.0000
58.3600 681.0000 1.0000
58.4000 681.0000 1.0000
58.4400 648.0000 1.0000
58.4800 668.0000 1.0000
58.5200 655.0000 1.0000
58.5600 705.0000 1.0000
58.6000 658.0000 1.0000
58.6400 669.0000 1.0000
58.6800 654.0000 1.0000
58.7200 628.0000 1.0000
58.7600 670.0000 1.0000
58.8000 633.0000 1.0000
58.8400 670.0000 1.0000
58.8800 665.0000 1.0000
58.9200 634.0000 1.0000
58.9600 671.0000 1.0000
59.0000 616.0000 1.0000
59.0400 654.0000 1.0000
59.0800 679.0000 1.0000
59.1200 641.0000 1.0000
59.1600 648.0000 1.0000
59.2000 649.0000 1.0000
59.2400 642.0000 1.0000
59.2800 667.0000 1.0000
59.3200 714.0000 1.0000
59.3600 630.0000 1.0000
59.4000 670.0000 1.0000
59.4400 612.0000 1.0000
59.4800 658.0000 1.0000
59.5200 667.0000 1.0000
59.5600 675.0000 1.0000
59.6000 622.0000 1.0000
59.6400 691.0000 1.0000
59.6800 703.0000 1.0000
59.7200 631.0000 1.0000
59.7600 654.0000 1.0000
59.8000 647.0000 1.0000
59.8400 646.0000 1.0000
59.8800 675.0000 1.0000
59.9200 638.0000 1.0000
59.9600 661.0000 1.0000
60.0000 644.0000 1.0000
60.0400 626.0000 1.0000
60.0800 643.0000 1.0000
60.1200 635.0000 1.0000
60.1600 658.0000 1.0000
60.2000 641.0000 1.0000
60.2400 652.0000 1.0000
60.2800 653.0000 1.0000
60.3200 654.0000 1.0000
60.3600 639.0000 1.0000
60.4000 657.0000 1.0000
60.4400 657.0000 1.0000
60.4800 640.0000 1.0000
60.5200 634.0000 1.0000
60.5600 698.0000 1.0000
60.6000 643.0000 1.0000
60.6400 671.0000 1.0000
60.6800 672.0000 1.0000
60.7200 689.0000 1.0000
60.7600 636.0000 1.0000
60.8000 625.0000 1.0000
60.8400 670.0000 1.0000
60.8800 645.0000 1.0000
60.9200 640.0000 1.0000
60.9600 687.0000 1.0000
61.0000 651.0000 1.0000
61.0400 633.0000 1.0000
61.0800 642.0000 1.0000
61.1200 632.0000 1.0000
61.1600 629.0000 1.0000
61.2000 676.0000 1.0000
61.2400 666.0000 1.0000
61.2800 673.0000 1.0000
61.3200 641.0000 1.0000
61.3600 633.0000 1.0000
61.4000 705.0000 1.0000
61.4400 655.0000 1.0000
61.4800 658.0000 1.0000
61.5200 671.0000 1.0000
61.5600 688.0000 1.0000
61.6000 685.0000 1.0000
61.6400 673.0000 1.0000
61.6800 655.0000 1.0000
61.7200 712.0000 1.0000
61.7600 667.0000 1.0000
61.8000 695.0000 1.0000
61.8400 693.0000 1.0000
61.8800 727.0000 1.0000
61.9200 736.0000 1.0000
61.9600 764.0000 1.0000
62.0000 804.0000 1.0000
62.0400 878.0000 1.0000
62.0800 888.0000 1.0000
62.1200 975.0000 1.0000
62.1600 1117.0000 1.0000
62.2000 1229.0000 1.0000
62.2400 1353.0000 1.0000
62.2800 1538.0000 1.0000
62.3200 1559.0000 1.0000
62.3600 1514.0000 1.0000
62.4000 1590.0000 1.0000
62.4400 1510.0000 1.0000
62.4800 1428.0000 1.0000
62.5200 1294.0000 1.0000
62.5600 1225.0000 1.0000
62.6000 1098.0000 1.0000
62.6400 1077.0000 1.0000
62.6800 982.0000 1.0000
62.7200 908.0000 1.0000
62.7600 871.0000 1.0000
62.8000 818.0000 1.0000
62.8400 789.0000 1.0000
62.8800 759.0000 1.0000
62.9200 708.0000 1.0000
62.9600 764.0000 1.0000
63.0000 731.0000 1.0000
63.0400 697.0000 1.0000
63.0800 727.0000 1.0000
63.1200 747.0000 1.0000
63.1600 723.0000 1.0000
63.2000 708.0000 1.0000
63.2400 707.0000 1.0000
63.2800 699.0000 1.0000
63.3200 709.0000 1.0000
63.3600 708.0000 1.0000
63.4000 675.0000 1.0000
63.4400 676.0000 1.0000
63.4800 665.0000 1.0000
63.5200 663.0000 1.0000
63.5600 660.0000 1.0000
63.6000 624.0000 1.0000
63.6400 649.0000 1.0000
63.6800 619.0000 1.0000
63.7200 660.0000 1.0000
63.7600 646.0000 1.0000
63.8000 681.0000 1.0000
63.8400 646.0000 1.0000
63.8800 643.0000 1.0000
63.9200 660.0000 1.0000
63.9600 657.0000 1.0000
64.0000 665.0000 1.0000
64.0400 643.0000 1.0000
64.0800 615.0000 1.0000
64.1200 659.0000 1.0000
64.1600 707.0000 1.0000
64.2000 709.0000 1.0000
64.2400 667.0000 1.0000
64.2800 676.0000 1.0000
64.3200 652.0000 1.0000
64.3600 652.0000 1.0000
64.4000 700.0000 1.0000
64.4400 661.0000 1.0000
64.4800 733.0000 1.0000
64.5200 677.0000 1.0000
64.5600 708.0000 1.0000
64.6000 737.0000 1.0000
64.6400 778.0000 1.0000
64.6800 902.0000 1.0000
64.7200 896.0000 1.0000
64.7600 812.0000 1.0000
64.8000 808.0000 1.0000
64.8400 814.0000 1.0000
64.8800 812.0000 1.0000
64.9200 841.0000 1.0000
64.9600 780.0000 1.0000
65.0000 737.0000 1.0000
65.0400 697.0000 1.0000
65.0800 705.0000 1.0000
65.1200 701.0000 1.0000
65.1600 686.0000 1.0000
65.2000 648.0000 1.0000
65.2400 707.0000 1.0000
65.2800 669.0000 1.0000
65.3200 693.0000 1.0000
65.3600 706.0000 1.0000
65.4000 677.0000 1.0000
65.4400 678.0000 1.0000
65.4800 672.0000 1.0000
65.5200 670.0000 1.0000
65.5600 657.0000 1.0000
65.6000 748.0000 1.0000
65.6400 698.0000 1.0000
65.6800 729.0000 1.0000
65.7200 702.0000 1.0000
65.7600 696.0000 1.0000
65.8000 729.0000 1.0000
65.8400 768.0000 1.0000
65.8800 782.0000 1.0000
65.9200 821.0000 1.0000
65.9600 859.0000 1.0000
66.0000 887.0000 1.0000
66.0400 1033.0000 1.0000
66.0800 1146.0000 1.0000
66.1200 1361.0000 1.0000
66.1600 1593.0000 1.0000
66.2000 1939.0000 1.0000
66.2400 2427.0000 1.0000
66.2800 2656.0000 1.0000
66.3200 2591.0000 1.0000
66.3600 2412.0000 1.0000
66.4000 2343.0000 1.0000
66.4400 2143.0000 1.0000
66.4800 2062.0000 1.0000
66.5200 1749.0000 1.0000
66.5600 1535.0000 1.0000
66.6000 1276.0000 1.0000
66.6400 1180.0000 1.0000
66.6800 1021.0000 1.0000
66.7200 919.0000 1.0000
66.7600 865.0000 1.0000
66.8000 794.0000 1.0000
66.8400 781.0000 1.0000
66.8800 779.0000 1.0000
66.9200 722.0000 1.0000
66.9600 676.0000 1.0000
67.0000 662.0000 1.0000
67.0400 691.0000 1.0000
67.0800 675.0000 1.0000
67.1200 687.0000 1.0000
67.1600 673.0000 1.0000
67.2000 628.0000 1.0000
67.2400 641.0000 1.0000
67.2800 603.0000 1.0000
67.3200 598.0000 1.0000
67.3600 610.0000 1.0000
67.4000 595.0000 1.0000
67.4400 607.0000 1.0000
67.4800 641.0000 1.0000
67.5200 615.0000 1.0000
67.5600 608.0000 1.0000
67.6000 604.0000 1.0000
67.6400 610.0000 1.0000
67.6800 601.0000 1.0000
67.7200 606.0000 1.0000
67.7600 604.0000 1.0000
67.8000 589.0000 1.0000
67.8400 625.0000 1.0000
67.8800 609.0000 1.0000
67.9200 596.0000 1.0000
67.9600 641.0000 1.0000
68.0000 593.0000 1.0000
68.0400 596.0000 1.0000
68.0800 584.0000 1.0000
68.1200 582.0000 1.0000
68.1600 608.0000 1.0000
68.2000 586.0000 1.0000
68.2400 590.0000 1.0000
68.2800 560.0000 1.0000
68.3200 555.0000 1.0000
68.3600 590.0000 1.0000
68.4000 590.0000 1.0000
68.4400 633.0000 1.0000
68.4800 570.0000 1.0000
68.5200 550.0000 1.0000
68.5600 629.0000 1.0000
68.6000 582.0000 1.0000
68.6400 591.0000 1.0000
68.6800 571.0000 1.0000
68.7200 560.0000 1.0000
68.7600 558.0000 1.0000
68.8000 585.0000 1.0000
68.8400 585.0000 1.0000
68.8800 570.0000 1.0000
68.9200 570.0000 1.0000
68.9600 612.0000 1.0000
69.0000 552.0000 1.0000
69.0400 577.0000 1.0000
69.0800 585.0000 1.0000
69.1200 586.0000 1.0000
69.1600 566.0000 1.0000
69.2000 570.0000 1.0000
69.2400 561.0000 1.0000
69.2800 527.0000 1.0000
69.3200 549.0000 1.0000
69.3600 593.0000 1.0000
69.4000 597.0000 1.0000
69.4400 564.0000 1.0000
69.4800 573.0000 1.0000
69.5200 579.0000 1.0000
69.5600 575.0000 1.0000
69.6000 583.0000 1.0000
69.6400 601.0000 1.0000
69.6800 551.0000 1.0000
69.7200 554.0000 1.0000
69.7600 576.0000 1.0000
69.8000 612.0000 1.0000
69.8400 597.0000 1.0000
69.8800 571.0000 1.0000
69.9200 561.0000 1.0000
69.9600 540.0000 1.0000
70.0000 550.0000 1.0000
*RAS_INT_END
*RAS_TEMPERATURE_START
*RAS_TEMPERATURE_END
*RAS_DATA_END