File: Data/Dataset1_Only_water/5_XRD/No_022_VS2_1.ras
*RAS_DATA_START
*RAS_HEADER_START
*DISP_FMT_X "%.2f"
*DISP_FMT_Y "%.0f"
*DISP_FULLSCALE "15196.0000000000"
*DISP_LINE_COLOR "255.0000000000"
*DISP_LINE_STYLE "0.0000000000"
*DISP_LINE_WIDTH "0.2500000000"
*DISP_NOTE "測定データ-1"
*DISP_OFFSET_Y "0.0000000000"
*DISP_PEAKSEARCH_UNIT_Y "cps"
*DISP_RANGE_BOTTOM "0.0000000000"
*DISP_RANGE_LEFT "20.0000000000"
*DISP_RANGE_LOGCUTOFF "0.0100000000"
*DISP_RANGE_RIGHT "70.0000000000"
*DISP_RANGE_TOP "15196.0000000000"
*DISP_SCALE_MODE_Y "0.0000000000"
*DISP_TAB_NAME "2θ/θ"
*DISP_TITLE_Y "強度"
*DISP_UNIT_Y "cps"
*DISP_WINDOW_NAME "MSG_MACROENGINE"
*FILE_COMMENT " "
*FILE_MD5 ""
*FILE_MEMO " "
*FILE_OPERATOR "Administrator"
*FILE_SAMPLE " "
*FILE_TYPE "RAS_RAW"
*FILE_USERGROUP "システムマネージャ"
*FILE_VERSION "1.0000000000"
*HW_ATTACHMENT_ID "ATT0025"
*HW_ATTACHMENT_NAME "標準|Standard"
*HW_COUNTER_ID-0 "CUT0025"
*HW_COUNTER_ID-1 "CUT0020"
*HW_COUNTER_ID-2 "CUT0020"
*HW_COUNTER_ID-3 "CSL0021"
*HW_COUNTER_ID-4 "CMC0021"
*HW_COUNTER_NAME-0 "D/teX Ultra|D/teX Ultra"
*HW_COUNTER_NAME-1 "None|None"
*HW_COUNTER_NAME-2 "None|None"
*HW_COUNTER_NAME-3 "BBM|BBM"
*HW_COUNTER_NAME-4 "検出器モノクロメータ|Detector monochromator"
*HW_COUNTER_SELECT_NAME "D/teX Ultra|D/teX Ultra"
*HW_GONIOMETER_ID "GON0023"
*HW_GONIOMETER_NAME "SmartLab|SmartLab"
*HW_GONIOMETER_RADIUS-0 "90.0"
*HW_GONIOMETER_RADIUS-1 "114.0"
*HW_GONIOMETER_RADIUS-2 "190.0"
*HW_GONIOMETER_RADIUS-3 "300.0"
*HW_GONIOMETER_RADIUS-4 "187.0"
*HW_GONIOMETER_RADIUS-5 "300.0"
*HW_GONIOMETER_RADIUS-6 "113.0"
*HW_GONIOMETER_RADIUS-7 "331.0"
*HW_I_OPT_ID-0 "CBO0021"
*HW_I_OPT_ID-1 "ICR0023"
*HW_I_OPT_ID-2 "ISL0021"
*HW_I_OPT_ID-3 "ISO0021"
*HW_I_OPT_ID-4 "IAD0021"
*HW_I_OPT_ID-5 "IPR0001"
*HW_I_OPT_NAME-0 "CBOユニット|CBO unit"
*HW_I_OPT_NAME-1 "標準入射光学ユニット|Standard incident optical unit"
*HW_I_OPT_NAME-2 "標準入射スリットボックス|Standard incident slit box"
*HW_I_OPT_NAME-3 "入射平行スリット|Incident parallel slit"
*HW_I_OPT_NAME-4 "長手制限スリット|Length limiting slit"
*HW_I_OPT_NAME-5 "None|None"
*HW_R_ATTENUATER_AUTOMODE "0"
*HW_R_OPT_ID-0 "RSS0021"
*HW_R_OPT_ID-1 "RCR0023"
*HW_R_OPT_ID-2 "RSO0021"
*HW_R_OPT_ID-3 "RRS0021"
*HW_R_OPT_ID-4 "ATN0021"
*HW_R_OPT_ID-5 "RFL0021"
*HW_R_OPT_ID-6 "RAD0021"
*HW_R_OPT_NAME-0 "標準受光スリットボックス1|Standard receiving slit box # 1"
*HW_R_OPT_NAME-1 "標準受光光学ユニット1|Standard receiving unit # 1"
*HW_R_OPT_NAME-2 "標準受光光学ユニット2|Standard receiving optical unit # 2"
*HW_R_OPT_NAME-3 "標準受光スリットボックス2|Standard receiving slit box # 2"
*HW_R_OPT_NAME-4 "標準アッテネータ|Standard Attenuator"
*HW_R_OPT_NAME-5 "Cu Kβ|Cu K-beta"
*HW_R_OPT_NAME-6 "調整用受光スリット|Alignment receiving slit"
*HW_SAMPLE_HOLDER_ID "SMP0023"
*HW_SAMPLE_HOLDER_NAME "標準Zステージ|Standard Z stage"
*HW_XG_CURRENT_MAX "50"
*HW_XG_CURRENT_MIN "2"
*HW_XG_CURRENT_RESOLUTION "1"
*HW_XG_CURRENT_UNIT "mA"
*HW_XG_FOCUS "1mm x 10mm"
*HW_XG_FOCUS_TYPE "Normal"
*HW_XG_ID ""
*HW_XG_NAME "3kW 封入管(ID:1200)|3kW Sealed tube(ID:1200)"
*HW_XG_TARGET_ATOMIC_NUMBER "29.0000000000"
*HW_XG_TARGET_NAME "Cu"
*HW_XG_TYPE "Hermetic"
*HW_XG_VOLTAGE_MAX "60"
*HW_XG_VOLTAGE_MIN "20"
*HW_XG_VOLTAGE_RESOLUTION "1"
*HW_XG_VOLTAGE_UNIT "kV"
*HW_XG_WATT_MAX "1.500"
*HW_XG_WATT_UNIT "kW"
*HW_XG_WAVE_LENGTH_ALPHA1 "1.540593"
*HW_XG_WAVE_LENGTH_ALPHA2 "1.544414"
*HW_XG_WAVE_LENGTH_BETA "1.392250"
*MEAS_COND_AXIS_NAME-0 "2θ/θ"
*MEAS_COND_AXIS_NAME-1 "2θ"
*MEAS_COND_AXIS_NAME-2 "ω"
*MEAS_COND_AXIS_NAME-3 "Z"
*MEAS_COND_AXIS_NAME-4 "2θ/ω"
*MEAS_COND_AXIS_NAME-5 "θs"
*MEAS_COND_AXIS_NAME-6 "θd"
*MEAS_COND_AXIS_NAME-7 "Ts"
*MEAS_COND_AXIS_NAME-8 "CBO選択スリット"
*MEAS_COND_AXIS_NAME-9 "M"
*MEAS_COND_AXIS_NAME-10 "入射平行スリット"
*MEAS_COND_AXIS_NAME-11 "入射スリット"
*MEAS_COND_AXIS_NAME-12 ""
*MEAS_COND_AXIS_NAME-13 "Zs"
*MEAS_COND_AXIS_NAME-14 "入射光学素子"
*MEAS_COND_AXIS_NAME-15 "長手制限スリット"
*MEAS_COND_AXIS_NAME-16 "センタースリット"
*MEAS_COND_AXIS_NAME-17 "フィルター"
*MEAS_COND_AXIS_NAME-18 "受光スリット1"
*MEAS_COND_AXIS_NAME-19 "受光スリット2"
*MEAS_COND_AXIS_NAME-20 "受光光学素子"
*MEAS_COND_AXIS_NAME-21 "受光平行スリット"
*MEAS_COND_AXIS_NAME-22 "調整用受光スリット"
*MEAS_COND_AXIS_NAME-23 ""
*MEAS_COND_AXIS_NAME-24 ""
*MEAS_COND_AXIS_NAME-25 "Zd"
*MEAS_COND_AXIS_NAME-26 "アッテネータ"
*MEAS_COND_AXIS_NAME-27 "検出器モノクロメータ"
*MEAS_COND_AXIS_NAME-28 "モノクロメータスリット"
*MEAS_COND_AXIS_NAME-29 "プライマリビーム"
*MEAS_COND_AXIS_NAME-30 "PHA"
*MEAS_COND_AXIS_NAME_INTERNAL-0 "TwoThetaTheta"
*MEAS_COND_AXIS_NAME_INTERNAL-1 "TwoTheta"
*MEAS_COND_AXIS_NAME_INTERNAL-2 "Omega"
*MEAS_COND_AXIS_NAME_INTERNAL-3 "Z"
*MEAS_COND_AXIS_NAME_INTERNAL-4 "TwoThetaOmega"
*MEAS_COND_AXIS_NAME_INTERNAL-5 "ThetaS"
*MEAS_COND_AXIS_NAME_INTERNAL-6 "ThetaD"
*MEAS_COND_AXIS_NAME_INTERNAL-7 "Ts"
*MEAS_COND_AXIS_NAME_INTERNAL-8 "CBO"
*MEAS_COND_AXIS_NAME_INTERNAL-9 "CBO-M"
*MEAS_COND_AXIS_NAME_INTERNAL-10 "IncidentSollerSlit"
*MEAS_COND_AXIS_NAME_INTERNAL-11 "IncidentSlitBox"
*MEAS_COND_AXIS_NAME_INTERNAL-12 "IncidentSlitBox-_Axis"
*MEAS_COND_AXIS_NAME_INTERNAL-13 "Zs"
*MEAS_COND_AXIS_NAME_INTERNAL-14 "IncidentMonochromator"
*MEAS_COND_AXIS_NAME_INTERNAL-15 "IncidentAxdSlit"
*MEAS_COND_AXIS_NAME_INTERNAL-16 "CenterSlit"
*MEAS_COND_AXIS_NAME_INTERNAL-17 "Filter"
*MEAS_COND_AXIS_NAME_INTERNAL-18 "ReceivingSlitBox1"
*MEAS_COND_AXIS_NAME_INTERNAL-19 "ReceivingSlitBox2"
*MEAS_COND_AXIS_NAME_INTERNAL-20 "ReceivingOptics"
*MEAS_COND_AXIS_NAME_INTERNAL-21 "ReceivingSollerSlit"
*MEAS_COND_AXIS_NAME_INTERNAL-22 "ReceivingAxdSlit"
*MEAS_COND_AXIS_NAME_INTERNAL-23 "ReceivingSlitBox1-_Axis"
*MEAS_COND_AXIS_NAME_INTERNAL-24 "ReceivingSlitBox2-_Axis"
*MEAS_COND_AXIS_NAME_INTERNAL-25 "ReceivingSlitBox2-Zd"
*MEAS_COND_AXIS_NAME_INTERNAL-26 "Attenuator"
*MEAS_COND_AXIS_NAME_INTERNAL-27 "CounterMonochromator"
*MEAS_COND_AXIS_NAME_INTERNAL-28 "CounterSlit"
*MEAS_COND_AXIS_NAME_INTERNAL-29 "IncidentPrimary"
*MEAS_COND_AXIS_NAME_INTERNAL-30 "PHA"
*MEAS_COND_AXIS_NAME_MAGICNO-0 "83951616.0000000000"
*MEAS_COND_AXIS_NAME_MAGICNO-1 "268632064.0000000000"
*MEAS_COND_AXIS_NAME_MAGICNO-2 "268500992.0000000000"
*MEAS_COND_AXIS_NAME_MAGICNO-3 "285278208.0000000000"
*MEAS_COND_AXIS_NAME_MAGICNO-4 "83951616.0000000000"
*MEAS_COND_AXIS_NAME_MAGICNO-5 "131072.0000000000"
*MEAS_COND_AXIS_NAME_MAGICNO-6 "131072.0000000000"
*MEAS_COND_AXIS_NAME_MAGICNO-7 "318898176.0000000000"
*MEAS_COND_AXIS_NAME_MAGICNO-8 "20971521.0000000000"
*MEAS_COND_AXIS_NAME_MAGICNO-9 "285343744.0000000000"
*MEAS_COND_AXIS_NAME_MAGICNO-10 "20971521.0000000000"
*MEAS_COND_AXIS_NAME_MAGICNO-11 "22020097.0000000000"
*MEAS_COND_AXIS_NAME_MAGICNO-12 "25165824.0000000000"
*MEAS_COND_AXIS_NAME_MAGICNO-13 "318898176.0000000000"
*MEAS_COND_AXIS_NAME_MAGICNO-14 "1.0000000000"
*MEAS_COND_AXIS_NAME_MAGICNO-15 "20971521.0000000000"
*MEAS_COND_AXIS_NAME_MAGICNO-16 "20971521.0000000000"
*MEAS_COND_AXIS_NAME_MAGICNO-17 "20971521.0000000000"
*MEAS_COND_AXIS_NAME_MAGICNO-18 "23068673.0000000000"
*MEAS_COND_AXIS_NAME_MAGICNO-19 "23068673.0000000000"
*MEAS_COND_AXIS_NAME_MAGICNO-20 "20971521.0000000000"
*MEAS_COND_AXIS_NAME_MAGICNO-21 "20971521.0000000000"
*MEAS_COND_AXIS_NAME_MAGICNO-22 "20971521.0000000000"
*MEAS_COND_AXIS_NAME_MAGICNO-23 "25165824.0000000000"
*MEAS_COND_AXIS_NAME_MAGICNO-24 "25165824.0000000000"
*MEAS_COND_AXIS_NAME_MAGICNO-25 "285343744.0000000000"
*MEAS_COND_AXIS_NAME_MAGICNO-26 "17301505.0000000000"
*MEAS_COND_AXIS_NAME_MAGICNO-27 "20971521.0000000000"
*MEAS_COND_AXIS_NAME_MAGICNO-28 "20971521.0000000000"
*MEAS_COND_AXIS_NAME_MAGICNO-29 "20971521.0000000000"
*MEAS_COND_AXIS_NAME_MAGICNO-30 "0.0000000000"
*MEAS_COND_AXIS_OFFSET-0 "-"
*MEAS_COND_AXIS_OFFSET-1 "-0.1081000000"
*MEAS_COND_AXIS_OFFSET-2 "0.3758000000"
*MEAS_COND_AXIS_OFFSET-3 "-"
*MEAS_COND_AXIS_OFFSET-4 "-"
*MEAS_COND_AXIS_OFFSET-5 "0.3758000000"
*MEAS_COND_AXIS_OFFSET-6 "-0.4839000000"
*MEAS_COND_AXIS_OFFSET-7 "-"
*MEAS_COND_AXIS_OFFSET-8 "-"
*MEAS_COND_AXIS_OFFSET-9 "-"
*MEAS_COND_AXIS_OFFSET-10 "-"
*MEAS_COND_AXIS_OFFSET-11 "-"
*MEAS_COND_AXIS_OFFSET-12 "-"
*MEAS_COND_AXIS_OFFSET-13 "-"
*MEAS_COND_AXIS_OFFSET-14 "-"
*MEAS_COND_AXIS_OFFSET-15 "-"
*MEAS_COND_AXIS_OFFSET-16 "-"
*MEAS_COND_AXIS_OFFSET-17 "-"
*MEAS_COND_AXIS_OFFSET-18 "-"
*MEAS_COND_AXIS_OFFSET-19 "-"
*MEAS_COND_AXIS_OFFSET-20 "-"
*MEAS_COND_AXIS_OFFSET-21 "-"
*MEAS_COND_AXIS_OFFSET-22 "-"
*MEAS_COND_AXIS_OFFSET-23 "-"
*MEAS_COND_AXIS_OFFSET-24 "-"
*MEAS_COND_AXIS_OFFSET-25 "-"
*MEAS_COND_AXIS_OFFSET-26 "-"
*MEAS_COND_AXIS_OFFSET-27 "-"
*MEAS_COND_AXIS_OFFSET-28 "-"
*MEAS_COND_AXIS_OFFSET-29 "-"
*MEAS_COND_AXIS_OFFSET-30 "-"
*MEAS_COND_AXIS_POSITION-0 "0.0000000000"
*MEAS_COND_AXIS_POSITION-1 "0.0000000000"
*MEAS_COND_AXIS_POSITION-2 "0.0000000000"
*MEAS_COND_AXIS_POSITION-3 "-0.5500000000"
*MEAS_COND_AXIS_POSITION-4 "0.0000000000"
*MEAS_COND_AXIS_POSITION-5 "0.0000000000"
*MEAS_COND_AXIS_POSITION-6 "0.0000000000"
*MEAS_COND_AXIS_POSITION-7 "-0.4278800000"
*MEAS_COND_AXIS_POSITION-8 "BB"
*MEAS_COND_AXIS_POSITION-9 "0.0000000000"
*MEAS_COND_AXIS_POSITION-10 "Soller_slit_5.0deg"
*MEAS_COND_AXIS_POSITION-11 "2/3deg"
*MEAS_COND_AXIS_POSITION-12 "2.2088000000"
*MEAS_COND_AXIS_POSITION-13 "-0.4140600000"
*MEAS_COND_AXIS_POSITION-14 "0.0000000000"
*MEAS_COND_AXIS_POSITION-15 "10.0mm"
*MEAS_COND_AXIS_POSITION-16 "None"
*MEAS_COND_AXIS_POSITION-17 "Cu_K-beta"
*MEAS_COND_AXIS_POSITION-18 "13.000mm"
*MEAS_COND_AXIS_POSITION-19 "13.000mm"
*MEAS_COND_AXIS_POSITION-20 "No_unit"
*MEAS_COND_AXIS_POSITION-21 "Soller_slit_5.0deg"
*MEAS_COND_AXIS_POSITION-22 "None"
*MEAS_COND_AXIS_POSITION-23 "13.0000000000"
*MEAS_COND_AXIS_POSITION-24 "13.0000000000"
*MEAS_COND_AXIS_POSITION-25 "0.0109400000"
*MEAS_COND_AXIS_POSITION-26 "Open"
*MEAS_COND_AXIS_POSITION-27 "None"
*MEAS_COND_AXIS_POSITION-28 "None"
*MEAS_COND_AXIS_POSITION-29 "None"
*MEAS_COND_AXIS_POSITION-30 "38.0000000000"
*MEAS_COND_AXIS_UNIT-0 "deg"
*MEAS_COND_AXIS_UNIT-1 "deg"
*MEAS_COND_AXIS_UNIT-2 "deg"
*MEAS_COND_AXIS_UNIT-3 "mm"
*MEAS_COND_AXIS_UNIT-4 "deg"
*MEAS_COND_AXIS_UNIT-5 "deg"
*MEAS_COND_AXIS_UNIT-6 "deg"
*MEAS_COND_AXIS_UNIT-7 "mm"
*MEAS_COND_AXIS_UNIT-8 ""
*MEAS_COND_AXIS_UNIT-9 "pulse"
*MEAS_COND_AXIS_UNIT-10 ""
*MEAS_COND_AXIS_UNIT-11 ""
*MEAS_COND_AXIS_UNIT-12 "mm"
*MEAS_COND_AXIS_UNIT-13 "mm"
*MEAS_COND_AXIS_UNIT-14 ""
*MEAS_COND_AXIS_UNIT-15 ""
*MEAS_COND_AXIS_UNIT-16 ""
*MEAS_COND_AXIS_UNIT-17 ""
*MEAS_COND_AXIS_UNIT-18 ""
*MEAS_COND_AXIS_UNIT-19 ""
*MEAS_COND_AXIS_UNIT-20 ""
*MEAS_COND_AXIS_UNIT-21 ""
*MEAS_COND_AXIS_UNIT-22 ""
*MEAS_COND_AXIS_UNIT-23 "mm"
*MEAS_COND_AXIS_UNIT-24 "mm"
*MEAS_COND_AXIS_UNIT-25 "mm"
*MEAS_COND_AXIS_UNIT-26 ""
*MEAS_COND_AXIS_UNIT-27 ""
*MEAS_COND_AXIS_UNIT-28 ""
*MEAS_COND_AXIS_UNIT-29 ""
*MEAS_COND_AXIS_UNIT-30 "div"
*MEAS_COND_COUNTER_CNTLOSS_CORR "0.0000000000"
*MEAS_COND_COUNTER_PHABASE "38.0000000000"
*MEAS_COND_COUNTER_PHAWINDOW "16.0000000000"
*MEAS_COND_COUNTER_PHA_UNIT "div"
*MEAS_COND_COUNTER_TAUDIFF "30.0000000000"
*MEAS_COND_COUNTER_TAUINT "0.0000000000"
*MEAS_COND_IRRADIATION_MODE "OFF"
*MEAS_COND_IRRADIATION_WIDTH ""
*MEAS_COND_OPT_ATTR "集中法"
*MEAS_COND_OPT_NAME "@集中法"
*MEAS_COND_UNSYMMETRIC_MODE "OFF"
*MEAS_COND_XG_CURRENT "30.0000000000"
*MEAS_COND_XG_VOLTAGE "40.0000000000"
*MEAS_COND_XG_WAVE_TYPE "Ka"
*MEAS_DATA_COUNT "5001.0000000000"
*MEAS_SCAN_AXIS_X "2θ/θ"
*MEAS_SCAN_AXIS_X_INTERNAL "TwoThetaTheta"
*MEAS_SCAN_END_TIME "07/20/21 11:19:35"
*MEAS_SCAN_MODE "CONTINUOUS"
*MEAS_SCAN_MONITOR "0"
*MEAS_SCAN_RESOLUTION_X "0.0002"
*MEAS_SCAN_SPEED "1.0"
*MEAS_SCAN_SPEED_UNIT "deg/min"
*MEAS_SCAN_START "20.0000000000"
*MEAS_SCAN_START_TIME "07/20/21 10:26:44"
*MEAS_SCAN_STEP "0.0100000000"
*MEAS_SCAN_STOP "70.0000000000"
*MEAS_SCAN_UNIT_X "deg"
*MEAS_SCAN_UNIT_Y "counts"
*RAS_HEADER_END
*RAS_INT_START
20.0000 1609.0000 1.0000
20.0400 1661.0000 1.0000
20.0800 1674.0000 1.0000
20.1200 1675.0000 1.0000
20.1600 1639.0000 1.0000
20.2000 1638.0000 1.0000
20.2400 1645.0000 1.0000
20.2800 1661.0000 1.0000
20.3200 1716.0000 1.0000
20.3600 1621.0000 1.0000
20.4000 1630.0000 1.0000
20.4400 1643.0000 1.0000
20.4800 1602.0000 1.0000
20.5200 1658.0000 1.0000
20.5600 1616.0000 1.0000
20.6000 1624.0000 1.0000
20.6400 1651.0000 1.0000
20.6800 1599.0000 1.0000
20.7200 1631.0000 1.0000
20.7600 1605.0000 1.0000
20.8000 1612.0000 1.0000
20.8400 1629.0000 1.0000
20.8800 1630.0000 1.0000
20.9200 1696.0000 1.0000
20.9600 1635.0000 1.0000
21.0000 1648.0000 1.0000
21.0400 1613.0000 1.0000
21.0800 1647.0000 1.0000
21.1200 1665.0000 1.0000
21.1600 1618.0000 1.0000
21.2000 1691.0000 1.0000
21.2400 1640.0000 1.0000
21.2800 1615.0000 1.0000
21.3200 1633.0000 1.0000
21.3600 1757.0000 1.0000
21.4000 1624.0000 1.0000
21.4400 1653.0000 1.0000
21.4800 1622.0000 1.0000
21.5200 1619.0000 1.0000
21.5600 1663.0000 1.0000
21.6000 1673.0000 1.0000
21.6400 1634.0000 1.0000
21.6800 1709.0000 1.0000
21.7200 1597.0000 1.0000
21.7600 1641.0000 1.0000
21.8000 1622.0000 1.0000
21.8400 1659.0000 1.0000
21.8800 1687.0000 1.0000
21.9200 1653.0000 1.0000
21.9600 1695.0000 1.0000
22.0000 1648.0000 1.0000
22.0400 1654.0000 1.0000
22.0800 1661.0000 1.0000
22.1200 1668.0000 1.0000
22.1600 1684.0000 1.0000
22.2000 1628.0000 1.0000
22.2400 1680.0000 1.0000
22.2800 1679.0000 1.0000
22.3200 1708.0000 1.0000
22.3600 1679.0000 1.0000
22.4000 1662.0000 1.0000
22.4400 1684.0000 1.0000
22.4800 1660.0000 1.0000
22.5200 1733.0000 1.0000
22.5600 1698.0000 1.0000
22.6000 1665.0000 1.0000
22.6400 1709.0000 1.0000
22.6800 1685.0000 1.0000
22.7200 1687.0000 1.0000
22.7600 1704.0000 1.0000
22.8000 1610.0000 1.0000
22.8400 1677.0000 1.0000
22.8800 1661.0000 1.0000
22.9200 1680.0000 1.0000
22.9600 1638.0000 1.0000
23.0000 1672.0000 1.0000
23.0400 1701.0000 1.0000
23.0800 1748.0000 1.0000
23.1200 1667.0000 1.0000
23.1600 1767.0000 1.0000
23.2000 1714.0000 1.0000
23.2400 1626.0000 1.0000
23.2800 1726.0000 1.0000
23.3200 1709.0000 1.0000
23.3600 1660.0000 1.0000
23.4000 1706.0000 1.0000
23.4400 1699.0000 1.0000
23.4800 1740.0000 1.0000
23.5200 1705.0000 1.0000
23.5600 1703.0000 1.0000
23.6000 1738.0000 1.0000
23.6400 1684.0000 1.0000
23.6800 1692.0000 1.0000
23.7200 1584.0000 1.0000
23.7600 1792.0000 1.0000
23.8000 1672.0000 1.0000
23.8400 1689.0000 1.0000
23.8800 1674.0000 1.0000
23.9200 1762.0000 1.0000
23.9600 1706.0000 1.0000
24.0000 1722.0000 1.0000
24.0400 1699.0000 1.0000
24.0800 1705.0000 1.0000
24.1200 1732.0000 1.0000
24.1600 1721.0000 1.0000
24.2000 1777.0000 1.0000
24.2400 1697.0000 1.0000
24.2800 1691.0000 1.0000
24.3200 1737.0000 1.0000
24.3600 1678.0000 1.0000
24.4000 1663.0000 1.0000
24.4400 1657.0000 1.0000
24.4800 1713.0000 1.0000
24.5200 1726.0000 1.0000
24.5600 1818.0000 1.0000
24.6000 1757.0000 1.0000
24.6400 1834.0000 1.0000
24.6800 1790.0000 1.0000
24.7200 1808.0000 1.0000
24.7600 1738.0000 1.0000
24.8000 1793.0000 1.0000
24.8400 1748.0000 1.0000
24.8800 1805.0000 1.0000
24.9200 1744.0000 1.0000
24.9600 1754.0000 1.0000
25.0000 1744.0000 1.0000
25.0400 1742.0000 1.0000
25.0800 1775.0000 1.0000
25.1200 1813.0000 1.0000
25.1600 1782.0000 1.0000
25.2000 1773.0000 1.0000
25.2400 1779.0000 1.0000
25.2800 1835.0000 1.0000
25.3200 1736.0000 1.0000
25.3600 1776.0000 1.0000
25.4000 1777.0000 1.0000
25.4400 1760.0000 1.0000
25.4800 1792.0000 1.0000
25.5200 1753.0000 1.0000
25.5600 1785.0000 1.0000
25.6000 1773.0000 1.0000
25.6400 1758.0000 1.0000
25.6800 1801.0000 1.0000
25.7200 1774.0000 1.0000
25.7600 1826.0000 1.0000
25.8000 1739.0000 1.0000
25.8400 1773.0000 1.0000
25.8800 1783.0000 1.0000
25.9200 1641.0000 1.0000
25.9600 1724.0000 1.0000
26.0000 1787.0000 1.0000
26.0400 1758.0000 1.0000
26.0800 1785.0000 1.0000
26.1200 1808.0000 1.0000
26.1600 1794.0000 1.0000
26.2000 1736.0000 1.0000
26.2400 1629.0000 1.0000
26.2800 1742.0000 1.0000
26.3200 1800.0000 1.0000
26.3600 1824.0000 1.0000
26.4000 1803.0000 1.0000
26.4400 1839.0000 1.0000
26.4800 1794.0000 1.0000
26.5200 1807.0000 1.0000
26.5600 1825.0000 1.0000
26.6000 1934.0000 1.0000
26.6400 1848.0000 1.0000
26.6800 1854.0000 1.0000
26.7200 1837.0000 1.0000
26.7600 1903.0000 1.0000
26.8000 1990.0000 1.0000
26.8400 1934.0000 1.0000
26.8800 2021.0000 1.0000
26.9200 2087.0000 1.0000
26.9600 2292.0000 1.0000
27.0000 2461.0000 1.0000
27.0400 2682.0000 1.0000
27.0800 3069.0000 1.0000
27.1200 3551.0000 1.0000
27.1600 4285.0000 1.0000
27.2000 5438.0000 1.0000
27.2400 6517.0000 1.0000
27.2800 7062.0000 1.0000
27.3200 6614.0000 1.0000
27.3600 5405.0000 1.0000
27.4000 4337.0000 1.0000
27.4400 3649.0000 1.0000
27.4800 3083.0000 1.0000
27.5200 2621.0000 1.0000
27.5600 2489.0000 1.0000
27.6000 2200.0000 1.0000
27.6400 2140.0000 1.0000
27.6800 2018.0000 1.0000
27.7200 1943.0000 1.0000
27.7600 1922.0000 1.0000
27.8000 1859.0000 1.0000
27.8400 1725.0000 1.0000
27.8800 1805.0000 1.0000
27.9200 1706.0000 1.0000
27.9600 1709.0000 1.0000
28.0000 1689.0000 1.0000
28.0400 1689.0000 1.0000
28.0800 1668.0000 1.0000
28.1200 1687.0000 1.0000
28.1600 1664.0000 1.0000
28.2000 1666.0000 1.0000
28.2400 1733.0000 1.0000
28.2800 1638.0000 1.0000
28.3200 1619.0000 1.0000
28.3600 1645.0000 1.0000
28.4000 1604.0000 1.0000
28.4400 1655.0000 1.0000
28.4800 1594.0000 1.0000
28.5200 1586.0000 1.0000
28.5600 1609.0000 1.0000
28.6000 1589.0000 1.0000
28.6400 1629.0000 1.0000
28.6800 1507.0000 1.0000
28.7200 1565.0000 1.0000
28.7600 1589.0000 1.0000
28.8000 1587.0000 1.0000
28.8400 1545.0000 1.0000
28.8800 1510.0000 1.0000
28.9200 1541.0000 1.0000
28.9600 1568.0000 1.0000
29.0000 1510.0000 1.0000
29.0400 1516.0000 1.0000
29.0800 1541.0000 1.0000
29.1200 1546.0000 1.0000
29.1600 1504.0000 1.0000
29.2000 1507.0000 1.0000
29.2400 1543.0000 1.0000
29.2800 1529.0000 1.0000
29.3200 1557.0000 1.0000
29.3600 1441.0000 1.0000
29.4000 1464.0000 1.0000
29.4400 1505.0000 1.0000
29.4800 1528.0000 1.0000
29.5200 1475.0000 1.0000
29.5600 1532.0000 1.0000
29.6000 1542.0000 1.0000
29.6400 1445.0000 1.0000
29.6800 1513.0000 1.0000
29.7200 1473.0000 1.0000
29.7600 1483.0000 1.0000
29.8000 1482.0000 1.0000
29.8400 1458.0000 1.0000
29.8800 1547.0000 1.0000
29.9200 1480.0000 1.0000
29.9600 1501.0000 1.0000
30.0000 1494.0000 1.0000
30.0400 1483.0000 1.0000
30.0800 1400.0000 1.0000
30.1200 1465.0000 1.0000
30.1600 1468.0000 1.0000
30.2000 1453.0000 1.0000
30.2400 1488.0000 1.0000
30.2800 1476.0000 1.0000
30.3200 1438.0000 1.0000
30.3600 1436.0000 1.0000
30.4000 1459.0000 1.0000
30.4400 1443.0000 1.0000
30.4800 1432.0000 1.0000
30.5200 1367.0000 1.0000
30.5600 1374.0000 1.0000
30.6000 1427.0000 1.0000
30.6400 1418.0000 1.0000
30.6800 1434.0000 1.0000
30.7200 1395.0000 1.0000
30.7600 1412.0000 1.0000
30.8000 1438.0000 1.0000
30.8400 1363.0000 1.0000
30.8800 1376.0000 1.0000
30.9200 1348.0000 1.0000
30.9600 1388.0000 1.0000
31.0000 1398.0000 1.0000
31.0400 1379.0000 1.0000
31.0800 1390.0000 1.0000
31.1200 1351.0000 1.0000
31.1600 1429.0000 1.0000
31.2000 1394.0000 1.0000
31.2400 1371.0000 1.0000
31.2800 1389.0000 1.0000
31.3200 1420.0000 1.0000
31.3600 1358.0000 1.0000
31.4000 1368.0000 1.0000
31.4400 1362.0000 1.0000
31.4800 1390.0000 1.0000
31.5200 1333.0000 1.0000
31.5600 1378.0000 1.0000
31.6000 1264.0000 1.0000
31.6400 1339.0000 1.0000
31.6800 1388.0000 1.0000
31.7200 1352.0000 1.0000
31.7600 1338.0000 1.0000
31.8000 1363.0000 1.0000
31.8400 1373.0000 1.0000
31.8800 1395.0000 1.0000
31.9200 1426.0000 1.0000
31.9600 1378.0000 1.0000
32.0000 1451.0000 1.0000
32.0400 1382.0000 1.0000
32.0800 1437.0000 1.0000
32.1200 1358.0000 1.0000
32.1600 1362.0000 1.0000
32.2000 1398.0000 1.0000
32.2400 1345.0000 1.0000
32.2800 1336.0000 1.0000
32.3200 1309.0000 1.0000
32.3600 1290.0000 1.0000
32.4000 1289.0000 1.0000
32.4400 1325.0000 1.0000
32.4800 1336.0000 1.0000
32.5200 1265.0000 1.0000
32.5600 1293.0000 1.0000
32.6000 1363.0000 1.0000
32.6400 1257.0000 1.0000
32.6800 1313.0000 1.0000
32.7200 1360.0000 1.0000
32.7600 1337.0000 1.0000
32.8000 1274.0000 1.0000
32.8400 1319.0000 1.0000
32.8800 1237.0000 1.0000
32.9200 1303.0000 1.0000
32.9600 1261.0000 1.0000
33.0000 1304.0000 1.0000
33.0400 1247.0000 1.0000
33.0800 1261.0000 1.0000
33.1200 1257.0000 1.0000
33.1600 1255.0000 1.0000
33.2000 1249.0000 1.0000
33.2400 1239.0000 1.0000
33.2800 1300.0000 1.0000
33.3200 1226.0000 1.0000
33.3600 1246.0000 1.0000
33.4000 1233.0000 1.0000
33.4400 1231.0000 1.0000
33.4800 1261.0000 1.0000
33.5200 1280.0000 1.0000
33.5600 1287.0000 1.0000
33.6000 1288.0000 1.0000
33.6400 1312.0000 1.0000
33.6800 1243.0000 1.0000
33.7200 1297.0000 1.0000
33.7600 1259.0000 1.0000
33.8000 1370.0000 1.0000
33.8400 1337.0000 1.0000
33.8800 1365.0000 1.0000
33.9200 1396.0000 1.0000
33.9600 1407.0000 1.0000
34.0000 1387.0000 1.0000
34.0400 1464.0000 1.0000
34.0800 1375.0000 1.0000
34.1200 1472.0000 1.0000
34.1600 1485.0000 1.0000
34.2000 1488.0000 1.0000
34.2400 1571.0000 1.0000
34.2800 1761.0000 1.0000
34.3200 1899.0000 1.0000
34.3600 2134.0000 1.0000
34.4000 2519.0000 1.0000
34.4400 2772.0000 1.0000
34.4800 2921.0000 1.0000
34.5200 2823.0000 1.0000
34.5600 2471.0000 1.0000
34.6000 2160.0000 1.0000
34.6400 1921.0000 1.0000
34.6800 1736.0000 1.0000
34.7200 1573.0000 1.0000
34.7600 1475.0000 1.0000
34.8000 1463.0000 1.0000
34.8400 1369.0000 1.0000
34.8800 1311.0000 1.0000
34.9200 1293.0000 1.0000
34.9600 1263.0000 1.0000
35.0000 1199.0000 1.0000
35.0400 1211.0000 1.0000
35.0800 1198.0000 1.0000
35.1200 1173.0000 1.0000
35.1600 1160.0000 1.0000
35.2000 1179.0000 1.0000
35.2400 1121.0000 1.0000
35.2800 1148.0000 1.0000
35.3200 1179.0000 1.0000
35.3600 1162.0000 1.0000
35.4000 1126.0000 1.0000
35.4400 1124.0000 1.0000
35.4800 1119.0000 1.0000
35.5200 1103.0000 1.0000
35.5600 1113.0000 1.0000
35.6000 1098.0000 1.0000
35.6400 1113.0000 1.0000
35.6800 1083.0000 1.0000
35.7200 1093.0000 1.0000
35.7600 1122.0000 1.0000
35.8000 1099.0000 1.0000
35.8400 1092.0000 1.0000
35.8800 1071.0000 1.0000
35.9200 1027.0000 1.0000
35.9600 1162.0000 1.0000
36.0000 1061.0000 1.0000
36.0400 1178.0000 1.0000
36.0800 1154.0000 1.0000
36.1200 1141.0000 1.0000
36.1600 1188.0000 1.0000
36.2000 1263.0000 1.0000
36.2400 1335.0000 1.0000
36.2800 1415.0000 1.0000
36.3200 1461.0000 1.0000
36.3600 1508.0000 1.0000
36.4000 1543.0000 1.0000
36.4400 1554.0000 1.0000
36.4800 1483.0000 1.0000
36.5200 1347.0000 1.0000
36.5600 1220.0000 1.0000
36.6000 1220.0000 1.0000
36.6400 1096.0000 1.0000
36.6800 1089.0000 1.0000
36.7200 1123.0000 1.0000
36.7600 1082.0000 1.0000
36.8000 1045.0000 1.0000
36.8400 1090.0000 1.0000
36.8800 1035.0000 1.0000
36.9200 1000.0000 1.0000
36.9600 997.0000 1.0000
37.0000 1002.0000 1.0000
37.0400 1040.0000 1.0000
37.0800 1044.0000 1.0000
37.1200 1032.0000 1.0000
37.1600 1036.0000 1.0000
37.2000 1041.0000 1.0000
37.2400 1031.0000 1.0000
37.2800 1004.0000 1.0000
37.3200 1051.0000 1.0000
37.3600 996.0000 1.0000
37.4000 1036.0000 1.0000
37.4400 959.0000 1.0000
37.4800 1022.0000 1.0000
37.5200 982.0000 1.0000
37.5600 991.0000 1.0000
37.6000 1062.0000 1.0000
37.6400 1003.0000 1.0000
37.6800 999.0000 1.0000
37.7200 1007.0000 1.0000
37.7600 1046.0000 1.0000
37.8000 1030.0000 1.0000
37.8400 1027.0000 1.0000
37.8800 1057.0000 1.0000
37.9200 1073.0000 1.0000
37.9600 1035.0000 1.0000
38.0000 1127.0000 1.0000
38.0400 1120.0000 1.0000
38.0800 1193.0000 1.0000
38.1200 1277.0000 1.0000
38.1600 1408.0000 1.0000
38.2000 1588.0000 1.0000
38.2400 1731.0000 1.0000
38.2800 2091.0000 1.0000
38.3200 2576.0000 1.0000
38.3600 3345.0000 1.0000
38.4000 4421.0000 1.0000
38.4400 5955.0000 1.0000
38.4800 7275.0000 1.0000
38.5200 7598.0000 1.0000
38.5600 7130.0000 1.0000
38.6000 6119.0000 1.0000
38.6400 4767.0000 1.0000
38.6800 3729.0000 1.0000
38.7200 2827.0000 1.0000
38.7600 2173.0000 1.0000
38.8000 1829.0000 1.0000
38.8400 1465.0000 1.0000
38.8800 1393.0000 1.0000
38.9200 1189.0000 1.0000
38.9600 1143.0000 1.0000
39.0000 1120.0000 1.0000
39.0400 1073.0000 1.0000
39.0800 1031.0000 1.0000
39.1200 917.0000 1.0000
39.1600 1001.0000 1.0000
39.2000 941.0000 1.0000
39.2400 927.0000 1.0000
39.2800 970.0000 1.0000
39.3200 944.0000 1.0000
39.3600 957.0000 1.0000
39.4000 930.0000 1.0000
39.4400 939.0000 1.0000
39.4800 914.0000 1.0000
39.5200 923.0000 1.0000
39.5600 940.0000 1.0000
39.6000 970.0000 1.0000
39.6400 962.0000 1.0000
39.6800 934.0000 1.0000
39.7200 902.0000 1.0000
39.7600 833.0000 1.0000
39.8000 860.0000 1.0000
39.8400 880.0000 1.0000
39.8800 866.0000 1.0000
39.9200 896.0000 1.0000
39.9600 881.0000 1.0000
40.0000 823.0000 1.0000
40.0400 821.0000 1.0000
40.0800 867.0000 1.0000
40.1200 844.0000 1.0000
40.1600 845.0000 1.0000
40.2000 792.0000 1.0000
40.2400 819.0000 1.0000
40.2800 803.0000 1.0000
40.3200 842.0000 1.0000
40.3600 830.0000 1.0000
40.4000 882.0000 1.0000
40.4400 854.0000 1.0000
40.4800 866.0000 1.0000
40.5200 827.0000 1.0000
40.5600 874.0000 1.0000
40.6000 822.0000 1.0000
40.6400 833.0000 1.0000
40.6800 837.0000 1.0000
40.7200 830.0000 1.0000
40.7600 828.0000 1.0000
40.8000 825.0000 1.0000
40.8400 792.0000 1.0000
40.8800 832.0000 1.0000
40.9200 799.0000 1.0000
40.9600 800.0000 1.0000
41.0000 795.0000 1.0000
41.0400 780.0000 1.0000
41.0800 840.0000 1.0000
41.1200 795.0000 1.0000
41.1600 811.0000 1.0000
41.2000 819.0000 1.0000
41.2400 834.0000 1.0000
41.2800 819.0000 1.0000
41.3200 782.0000 1.0000
41.3600 828.0000 1.0000
41.4000 905.0000 1.0000
41.4400 839.0000 1.0000
41.4800 789.0000 1.0000
41.5200 780.0000 1.0000
41.5600 804.0000 1.0000
41.6000 793.0000 1.0000
41.6400 810.0000 1.0000
41.6800 800.0000 1.0000
41.7200 783.0000 1.0000
41.7600 793.0000 1.0000
41.8000 840.0000 1.0000
41.8400 826.0000 1.0000
41.8800 810.0000 1.0000
41.9200 827.0000 1.0000
41.9600 774.0000 1.0000
42.0000 828.0000 1.0000
42.0400 801.0000 1.0000
42.0800 763.0000 1.0000
42.1200 817.0000 1.0000
42.1600 777.0000 1.0000
42.2000 775.0000 1.0000
42.2400 723.0000 1.0000
42.2800 819.0000 1.0000
42.3200 752.0000 1.0000
42.3600 794.0000 1.0000
42.4000 790.0000 1.0000
42.4400 838.0000 1.0000
42.4800 778.0000 1.0000
42.5200 755.0000 1.0000
42.5600 801.0000 1.0000
42.6000 827.0000 1.0000
42.6400 799.0000 1.0000
42.6800 831.0000 1.0000
42.7200 810.0000 1.0000
42.7600 850.0000 1.0000
42.8000 781.0000 1.0000
42.8400 811.0000 1.0000
42.8800 804.0000 1.0000
42.9200 786.0000 1.0000
42.9600 821.0000 1.0000
43.0000 827.0000 1.0000
43.0400 817.0000 1.0000
43.0800 865.0000 1.0000
43.1200 846.0000 1.0000
43.1600 863.0000 1.0000
43.2000 868.0000 1.0000
43.2400 880.0000 1.0000
43.2800 871.0000 1.0000
43.3200 800.0000 1.0000
43.3600 801.0000 1.0000
43.4000 803.0000 1.0000
43.4400 820.0000 1.0000
43.4800 843.0000 1.0000
43.5200 843.0000 1.0000
43.5600 797.0000 1.0000
43.6000 801.0000 1.0000
43.6400 827.0000 1.0000
43.6800 766.0000 1.0000
43.7200 782.0000 1.0000
43.7600 766.0000 1.0000
43.8000 830.0000 1.0000
43.8400 801.0000 1.0000
43.8800 774.0000 1.0000
43.9200 772.0000 1.0000
43.9600 800.0000 1.0000
44.0000 757.0000 1.0000
44.0400 763.0000 1.0000
44.0800 790.0000 1.0000
44.1200 813.0000 1.0000
44.1600 761.0000 1.0000
44.2000 808.0000 1.0000
44.2400 740.0000 1.0000
44.2800 762.0000 1.0000
44.3200 799.0000 1.0000
44.3600 761.0000 1.0000
44.4000 757.0000 1.0000
44.4400 793.0000 1.0000
44.4800 777.0000 1.0000
44.5200 767.0000 1.0000
44.5600 790.0000 1.0000
44.6000 772.0000 1.0000
44.6400 743.0000 1.0000
44.6800 765.0000 1.0000
44.7200 728.0000 1.0000
44.7600 754.0000 1.0000
44.8000 792.0000 1.0000
44.8400 742.0000 1.0000
44.8800 751.0000 1.0000
44.9200 759.0000 1.0000
44.9600 747.0000 1.0000
45.0000 760.0000 1.0000
45.0400 748.0000 1.0000
45.0800 741.0000 1.0000
45.1200 701.0000 1.0000
45.1600 744.0000 1.0000
45.2000 726.0000 1.0000
45.2400 733.0000 1.0000
45.2800 756.0000 1.0000
45.3200 751.0000 1.0000
45.3600 739.0000 1.0000
45.4000 728.0000 1.0000
45.4400 759.0000 1.0000
45.4800 777.0000 1.0000
45.5200 700.0000 1.0000
45.5600 716.0000 1.0000
45.6000 739.0000 1.0000
45.6400 768.0000 1.0000
45.6800 754.0000 1.0000
45.7200 716.0000 1.0000
45.7600 721.0000 1.0000
45.8000 763.0000 1.0000
45.8400 727.0000 1.0000
45.8800 681.0000 1.0000
45.9200 751.0000 1.0000
45.9600 689.0000 1.0000
46.0000 719.0000 1.0000
46.0400 751.0000 1.0000
46.0800 778.0000 1.0000
46.1200 713.0000 1.0000
46.1600 699.0000 1.0000
46.2000 749.0000 1.0000
46.2400 695.0000 1.0000
46.2800 716.0000 1.0000
46.3200 754.0000 1.0000
46.3600 671.0000 1.0000
46.4000 702.0000 1.0000
46.4400 688.0000 1.0000
46.4800 701.0000 1.0000
46.5200 713.0000 1.0000
46.5600 703.0000 1.0000
46.6000 714.0000 1.0000
46.6400 741.0000 1.0000
46.6800 676.0000 1.0000
46.7200 711.0000 1.0000
46.7600 716.0000 1.0000
46.8000 727.0000 1.0000
46.8400 688.0000 1.0000
46.8800 721.0000 1.0000
46.9200 702.0000 1.0000
46.9600 775.0000 1.0000
47.0000 705.0000 1.0000
47.0400 708.0000 1.0000
47.0800 739.0000 1.0000
47.1200 707.0000 1.0000
47.1600 701.0000 1.0000
47.2000 712.0000 1.0000
47.2400 714.0000 1.0000
47.2800 712.0000 1.0000
47.3200 695.0000 1.0000
47.3600 728.0000 1.0000
47.4000 702.0000 1.0000
47.4400 720.0000 1.0000
47.4800 714.0000 1.0000
47.5200 725.0000 1.0000
47.5600 678.0000 1.0000
47.6000 710.0000 1.0000
47.6400 699.0000 1.0000
47.6800 682.0000 1.0000
47.7200 706.0000 1.0000
47.7600 696.0000 1.0000
47.8000 690.0000 1.0000
47.8400 699.0000 1.0000
47.8800 714.0000 1.0000
47.9200 662.0000 1.0000
47.9600 676.0000 1.0000
48.0000 697.0000 1.0000
48.0400 667.0000 1.0000
48.0800 703.0000 1.0000
48.1200 696.0000 1.0000
48.1600 690.0000 1.0000
48.2000 703.0000 1.0000
48.2400 683.0000 1.0000
48.2800 672.0000 1.0000
48.3200 663.0000 1.0000
48.3600 687.0000 1.0000
48.4000 665.0000 1.0000
48.4400 729.0000 1.0000
48.4800 677.0000 1.0000
48.5200 666.0000 1.0000
48.5600 705.0000 1.0000
48.6000 671.0000 1.0000
48.6400 704.0000 1.0000
48.6800 678.0000 1.0000
48.7200 737.0000 1.0000
48.7600 676.0000 1.0000
48.8000 691.0000 1.0000
48.8400 661.0000 1.0000
48.8800 660.0000 1.0000
48.9200 711.0000 1.0000
48.9600 712.0000 1.0000
49.0000 672.0000 1.0000
49.0400 704.0000 1.0000
49.0800 699.0000 1.0000
49.1200 672.0000 1.0000
49.1600 685.0000 1.0000
49.2000 663.0000 1.0000
49.2400 670.0000 1.0000
49.2800 687.0000 1.0000
49.3200 670.0000 1.0000
49.3600 706.0000 1.0000
49.4000 708.0000 1.0000
49.4400 698.0000 1.0000
49.4800 627.0000 1.0000
49.5200 681.0000 1.0000
49.5600 662.0000 1.0000
49.6000 663.0000 1.0000
49.6400 655.0000 1.0000
49.6800 650.0000 1.0000
49.7200 713.0000 1.0000
49.7600 686.0000 1.0000
49.8000 665.0000 1.0000
49.8400 687.0000 1.0000
49.8800 723.0000 1.0000
49.9200 680.0000 1.0000
49.9600 697.0000 1.0000
50.0000 734.0000 1.0000
50.0400 669.0000 1.0000
50.0800 685.0000 1.0000
50.1200 684.0000 1.0000
50.1600 704.0000 1.0000
50.2000 624.0000 1.0000
50.2400 709.0000 1.0000
50.2800 662.0000 1.0000
50.3200 730.0000 1.0000
50.3600 721.0000 1.0000
50.4000 665.0000 1.0000
50.4400 694.0000 1.0000
50.4800 684.0000 1.0000
50.5200 678.0000 1.0000
50.5600 699.0000 1.0000
50.6000 719.0000 1.0000
50.6400 735.0000 1.0000
50.6800 701.0000 1.0000
50.7200 710.0000 1.0000
50.7600 707.0000 1.0000
50.8000 661.0000 1.0000
50.8400 661.0000 1.0000
50.8800 640.0000 1.0000
50.9200 674.0000 1.0000
50.9600 642.0000 1.0000
51.0000 683.0000 1.0000
51.0400 665.0000 1.0000
51.0800 708.0000 1.0000
51.1200 670.0000 1.0000
51.1600 690.0000 1.0000
51.2000 686.0000 1.0000
51.2400 667.0000 1.0000
51.2800 691.0000 1.0000
51.3200 664.0000 1.0000
51.3600 685.0000 1.0000
51.4000 670.0000 1.0000
51.4400 719.0000 1.0000
51.4800 738.0000 1.0000
51.5200 671.0000 1.0000
51.5600 700.0000 1.0000
51.6000 777.0000 1.0000
51.6400 716.0000 1.0000
51.6800 705.0000 1.0000
51.7200 717.0000 1.0000
51.7600 784.0000 1.0000
51.8000 787.0000 1.0000
51.8400 824.0000 1.0000
51.8800 860.0000 1.0000
51.9200 1010.0000 1.0000
51.9600 1038.0000 1.0000
52.0000 1199.0000 1.0000
52.0400 1421.0000 1.0000
52.0800 1743.0000 1.0000
52.1200 2451.0000 1.0000
52.1600 3346.0000 1.0000
52.2000 4538.0000 1.0000
52.2400 4946.0000 1.0000
52.2800 4472.0000 1.0000
52.3200 4012.0000 1.0000
52.3600 3670.0000 1.0000
52.4000 3164.0000 1.0000
52.4400 2439.0000 1.0000
52.4800 1735.0000 1.0000
52.5200 1402.0000 1.0000
52.5600 1257.0000 1.0000
52.6000 1004.0000 1.0000
52.6400 998.0000 1.0000
52.6800 913.0000 1.0000
52.7200 911.0000 1.0000
52.7600 831.0000 1.0000
52.8000 803.0000 1.0000
52.8400 810.0000 1.0000
52.8800 753.0000 1.0000
52.9200 762.0000 1.0000
52.9600 762.0000 1.0000
53.0000 714.0000 1.0000
53.0400 754.0000 1.0000
53.0800 740.0000 1.0000
53.1200 681.0000 1.0000
53.1600 672.0000 1.0000
53.2000 738.0000 1.0000
53.2400 687.0000 1.0000
53.2800 694.0000 1.0000
53.3200 662.0000 1.0000
53.3600 659.0000 1.0000
53.4000 668.0000 1.0000
53.4400 658.0000 1.0000
53.4800 650.0000 1.0000
53.5200 653.0000 1.0000
53.5600 667.0000 1.0000
53.6000 680.0000 1.0000
53.6400 693.0000 1.0000
53.6800 664.0000 1.0000
53.7200 651.0000 1.0000
53.7600 689.0000 1.0000
53.8000 713.0000 1.0000
53.8400 653.0000 1.0000
53.8800 651.0000 1.0000
53.9200 676.0000 1.0000
53.9600 689.0000 1.0000
54.0000 664.0000 1.0000
54.0400 655.0000 1.0000
54.0800 659.0000 1.0000
54.1200 695.0000 1.0000
54.1600 662.0000 1.0000
54.2000 658.0000 1.0000
54.2400 687.0000 1.0000
54.2800 707.0000 1.0000
54.3200 627.0000 1.0000
54.3600 628.0000 1.0000
54.4000 677.0000 1.0000
54.4400 678.0000 1.0000
54.4800 647.0000 1.0000
54.5200 740.0000 1.0000
54.5600 674.0000 1.0000
54.6000 674.0000 1.0000
54.6400 692.0000 1.0000
54.6800 679.0000 1.0000
54.7200 666.0000 1.0000
54.7600 726.0000 1.0000
54.8000 724.0000 1.0000
54.8400 737.0000 1.0000
54.8800 734.0000 1.0000
54.9200 718.0000 1.0000
54.9600 717.0000 1.0000
55.0000 769.0000 1.0000
55.0400 807.0000 1.0000
55.0800 845.0000 1.0000
55.1200 896.0000 1.0000
55.1600 929.0000 1.0000
55.2000 974.0000 1.0000
55.2400 1059.0000 1.0000
55.2800 1033.0000 1.0000
55.3200 1005.0000 1.0000
55.3600 977.0000 1.0000
55.4000 989.0000 1.0000
55.4400 889.0000 1.0000
55.4800 838.0000 1.0000
55.5200 786.0000 1.0000
55.5600 787.0000 1.0000
55.6000 709.0000 1.0000
55.6400 726.0000 1.0000
55.6800 704.0000 1.0000
55.7200 675.0000 1.0000
55.7600 700.0000 1.0000
55.8000 687.0000 1.0000
55.8400 724.0000 1.0000
55.8800 691.0000 1.0000
55.9200 659.0000 1.0000
55.9600 650.0000 1.0000
56.0000 649.0000 1.0000
56.0400 649.0000 1.0000
56.0800 692.0000 1.0000
56.1200 644.0000 1.0000
56.1600 600.0000 1.0000
56.2000 672.0000 1.0000
56.2400 672.0000 1.0000
56.2800 650.0000 1.0000
56.3200 648.0000 1.0000
56.3600 645.0000 1.0000
56.4000 628.0000 1.0000
56.4400 634.0000 1.0000
56.4800 633.0000 1.0000
56.5200 648.0000 1.0000
56.5600 603.0000 1.0000
56.6000 682.0000 1.0000
56.6400 652.0000 1.0000
56.6800 602.0000 1.0000
56.7200 677.0000 1.0000
56.7600 671.0000 1.0000
56.8000 669.0000 1.0000
56.8400 637.0000 1.0000
56.8800 643.0000 1.0000
56.9200 668.0000 1.0000
56.9600 608.0000 1.0000
57.0000 655.0000 1.0000
57.0400 665.0000 1.0000
57.0800 596.0000 1.0000
57.1200 640.0000 1.0000
57.1600 618.0000 1.0000
57.2000 639.0000 1.0000
57.2400 654.0000 1.0000
57.2800 638.0000 1.0000
57.3200 635.0000 1.0000
57.3600 652.0000 1.0000
57.4000 652.0000 1.0000
57.4400 635.0000 1.0000
57.4800 606.0000 1.0000
57.5200 656.0000 1.0000
57.5600 624.0000 1.0000
57.6000 589.0000 1.0000
57.6400 640.0000 1.0000
57.6800 629.0000 1.0000
57.7200 661.0000 1.0000
57.7600 672.0000 1.0000
57.8000 638.0000 1.0000
57.8400 666.0000 1.0000
57.8800 665.0000 1.0000
57.9200 696.0000 1.0000
57.9600 656.0000 1.0000
58.0000 704.0000 1.0000
58.0400 615.0000 1.0000
58.0800 634.0000 1.0000
58.1200 657.0000 1.0000
58.1600 653.0000 1.0000
58.2000 678.0000 1.0000
58.2400 645.0000 1.0000
58.2800 681.0000 1.0000
58.3200 658.0000 1.0000
58.3600 647.0000 1.0000
58.4000 659.0000 1.0000
58.4400 667.0000 1.0000
58.4800 711.0000 1.0000
58.5200 610.0000 1.0000
58.5600 627.0000 1.0000
58.6000 635.0000 1.0000
58.6400 633.0000 1.0000
58.6800 658.0000 1.0000
58.7200 655.0000 1.0000
58.7600 629.0000 1.0000
58.8000 609.0000 1.0000
58.8400 675.0000 1.0000
58.8800 621.0000 1.0000
58.9200 654.0000 1.0000
58.9600 605.0000 1.0000
59.0000 615.0000 1.0000
59.0400 635.0000 1.0000
59.0800 618.0000 1.0000
59.1200 620.0000 1.0000
59.1600 662.0000 1.0000
59.2000 658.0000 1.0000
59.2400 653.0000 1.0000
59.2800 679.0000 1.0000
59.3200 664.0000 1.0000
59.3600 648.0000 1.0000
59.4000 705.0000 1.0000
59.4400 644.0000 1.0000
59.4800 649.0000 1.0000
59.5200 663.0000 1.0000
59.5600 649.0000 1.0000
59.6000 644.0000 1.0000
59.6400 614.0000 1.0000
59.6800 620.0000 1.0000
59.7200 611.0000 1.0000
59.7600 659.0000 1.0000
59.8000 630.0000 1.0000
59.8400 631.0000 1.0000
59.8800 634.0000 1.0000
59.9200 648.0000 1.0000
59.9600 653.0000 1.0000
60.0000 598.0000 1.0000
60.0400 649.0000 1.0000
60.0800 661.0000 1.0000
60.1200 641.0000 1.0000
60.1600 660.0000 1.0000
60.2000 639.0000 1.0000
60.2400 633.0000 1.0000
60.2800 641.0000 1.0000
60.3200 655.0000 1.0000
60.3600 683.0000 1.0000
60.4000 644.0000 1.0000
60.4400 632.0000 1.0000
60.4800 651.0000 1.0000
60.5200 620.0000 1.0000
60.5600 681.0000 1.0000
60.6000 658.0000 1.0000
60.6400 666.0000 1.0000
60.6800 607.0000 1.0000
60.7200 612.0000 1.0000
60.7600 634.0000 1.0000
60.8000 595.0000 1.0000
60.8400 606.0000 1.0000
60.8800 651.0000 1.0000
60.9200 614.0000 1.0000
60.9600 633.0000 1.0000
61.0000 651.0000 1.0000
61.0400 680.0000 1.0000
61.0800 674.0000 1.0000
61.1200 622.0000 1.0000
61.1600 633.0000 1.0000
61.2000 663.0000 1.0000
61.2400 640.0000 1.0000
61.2800 658.0000 1.0000
61.3200 668.0000 1.0000
61.3600 673.0000 1.0000
61.4000 680.0000 1.0000
61.4400 660.0000 1.0000
61.4800 657.0000 1.0000
61.5200 669.0000 1.0000
61.5600 704.0000 1.0000
61.6000 640.0000 1.0000
61.6400 676.0000 1.0000
61.6800 703.0000 1.0000
61.7200 693.0000 1.0000
61.7600 728.0000 1.0000
61.8000 750.0000 1.0000
61.8400 752.0000 1.0000
61.8800 783.0000 1.0000
61.9200 772.0000 1.0000
61.9600 864.0000 1.0000
62.0000 935.0000 1.0000
62.0400 993.0000 1.0000
62.0800 1099.0000 1.0000
62.1200 1213.0000 1.0000
62.1600 1364.0000 1.0000
62.2000 1503.0000 1.0000
62.2400 1563.0000 1.0000
62.2800 1677.0000 1.0000
62.3200 1599.0000 1.0000
62.3600 1501.0000 1.0000
62.4000 1463.0000 1.0000
62.4400 1384.0000 1.0000
62.4800 1279.0000 1.0000
62.5200 1113.0000 1.0000
62.5600 1025.0000 1.0000
62.6000 959.0000 1.0000
62.6400 936.0000 1.0000
62.6800 823.0000 1.0000
62.7200 855.0000 1.0000
62.7600 766.0000 1.0000
62.8000 751.0000 1.0000
62.8400 717.0000 1.0000
62.8800 743.0000 1.0000
62.9200 737.0000 1.0000
62.9600 712.0000 1.0000
63.0000 777.0000 1.0000
63.0400 696.0000 1.0000
63.0800 690.0000 1.0000
63.1200 710.0000 1.0000
63.1600 679.0000 1.0000
63.2000 670.0000 1.0000
63.2400 726.0000 1.0000
63.2800 686.0000 1.0000
63.3200 663.0000 1.0000
63.3600 698.0000 1.0000
63.4000 677.0000 1.0000
63.4400 650.0000 1.0000
63.4800 656.0000 1.0000
63.5200 685.0000 1.0000
63.5600 664.0000 1.0000
63.6000 668.0000 1.0000
63.6400 728.0000 1.0000
63.6800 636.0000 1.0000
63.7200 651.0000 1.0000
63.7600 672.0000 1.0000
63.8000 680.0000 1.0000
63.8400 726.0000 1.0000
63.8800 697.0000 1.0000
63.9200 631.0000 1.0000
63.9600 616.0000 1.0000
64.0000 660.0000 1.0000
64.0400 647.0000 1.0000
64.0800 614.0000 1.0000
64.1200 620.0000 1.0000
64.1600 624.0000 1.0000
64.2000 695.0000 1.0000
64.2400 685.0000 1.0000
64.2800 667.0000 1.0000
64.3200 682.0000 1.0000
64.3600 681.0000 1.0000
64.4000 631.0000 1.0000
64.4400 699.0000 1.0000
64.4800 689.0000 1.0000
64.5200 678.0000 1.0000
64.5600 720.0000 1.0000
64.6000 745.0000 1.0000
64.6400 784.0000 1.0000
64.6800 745.0000 1.0000
64.7200 761.0000 1.0000
64.7600 731.0000 1.0000
64.8000 743.0000 1.0000
64.8400 744.0000 1.0000
64.8800 703.0000 1.0000
64.9200 720.0000 1.0000
64.9600 747.0000 1.0000
65.0000 721.0000 1.0000
65.0400 736.0000 1.0000
65.0800 709.0000 1.0000
65.1200 685.0000 1.0000
65.1600 708.0000 1.0000
65.2000 693.0000 1.0000
65.2400 709.0000 1.0000
65.2800 703.0000 1.0000
65.3200 659.0000 1.0000
65.3600 732.0000 1.0000
65.4000 679.0000 1.0000
65.4400 743.0000 1.0000
65.4800 695.0000 1.0000
65.5200 724.0000 1.0000
65.5600 632.0000 1.0000
65.6000 675.0000 1.0000
65.6400 682.0000 1.0000
65.6800 728.0000 1.0000
65.7200 736.0000 1.0000
65.7600 791.0000 1.0000
65.8000 784.0000 1.0000
65.8400 807.0000 1.0000
65.8800 850.0000 1.0000
65.9200 972.0000 1.0000
65.9600 997.0000 1.0000
66.0000 1136.0000 1.0000
66.0400 1373.0000 1.0000
66.0800 1542.0000 1.0000
66.1200 1960.0000 1.0000
66.1600 2321.0000 1.0000
66.2000 2623.0000 1.0000
66.2400 2644.0000 1.0000
66.2800 2454.0000 1.0000
66.3200 2319.0000 1.0000
66.3600 2255.0000 1.0000
66.4000 2057.0000 1.0000
66.4400 1851.0000 1.0000
66.4800 1598.0000 1.0000
66.5200 1327.0000 1.0000
66.5600 1155.0000 1.0000
66.6000 1017.0000 1.0000
66.6400 929.0000 1.0000
66.6800 870.0000 1.0000
66.7200 877.0000 1.0000
66.7600 784.0000 1.0000
66.8000 716.0000 1.0000
66.8400 747.0000 1.0000
66.8800 668.0000 1.0000
66.9200 674.0000 1.0000
66.9600 649.0000 1.0000
67.0000 671.0000 1.0000
67.0400 635.0000 1.0000
67.0800 677.0000 1.0000
67.1200 651.0000 1.0000
67.1600 595.0000 1.0000
67.2000 648.0000 1.0000
67.2400 647.0000 1.0000
67.2800 632.0000 1.0000
67.3200 634.0000 1.0000
67.3600 626.0000 1.0000
67.4000 617.0000 1.0000
67.4400 611.0000 1.0000
67.4800 563.0000 1.0000
67.5200 596.0000 1.0000
67.5600 605.0000 1.0000
67.6000 585.0000 1.0000
67.6400 595.0000 1.0000
67.6800 609.0000 1.0000
67.7200 647.0000 1.0000
67.7600 615.0000 1.0000
67.8000 615.0000 1.0000
67.8400 575.0000 1.0000
67.8800 588.0000 1.0000
67.9200 577.0000 1.0000
67.9600 608.0000 1.0000
68.0000 577.0000 1.0000
68.0400 586.0000 1.0000
68.0800 597.0000 1.0000
68.1200 585.0000 1.0000
68.1600 630.0000 1.0000
68.2000 595.0000 1.0000
68.2400 587.0000 1.0000
68.2800 624.0000 1.0000
68.3200 585.0000 1.0000
68.3600 562.0000 1.0000
68.4000 611.0000 1.0000
68.4400 582.0000 1.0000
68.4800 594.0000 1.0000
68.5200 564.0000 1.0000
68.5600 575.0000 1.0000
68.6000 594.0000 1.0000
68.6400 577.0000 1.0000
68.6800 604.0000 1.0000
68.7200 566.0000 1.0000
68.7600 568.0000 1.0000
68.8000 580.0000 1.0000
68.8400 597.0000 1.0000
68.8800 556.0000 1.0000
68.9200 537.0000 1.0000
68.9600 550.0000 1.0000
69.0000 581.0000 1.0000
69.0400 551.0000 1.0000
69.0800 558.0000 1.0000
69.1200 560.0000 1.0000
69.1600 570.0000 1.0000
69.2000 614.0000 1.0000
69.2400 586.0000 1.0000
69.2800 528.0000 1.0000
69.3200 558.0000 1.0000
69.3600 520.0000 1.0000
69.4000 583.0000 1.0000
69.4400 568.0000 1.0000
69.4800 604.0000 1.0000
69.5200 584.0000 1.0000
69.5600 590.0000 1.0000
69.6000 576.0000 1.0000
69.6400 538.0000 1.0000
69.6800 564.0000 1.0000
69.7200 561.0000 1.0000
69.7600 571.0000 1.0000
69.8000 581.0000 1.0000
69.8400 593.0000 1.0000
69.8800 578.0000 1.0000
69.9200 572.0000 1.0000
69.9600 585.0000 1.0000
70.0000 554.0000 1.0000
*RAS_INT_END
*RAS_TEMPERATURE_START
*RAS_TEMPERATURE_END
*RAS_DATA_END