File: Data/Dataset1_Only_water/5_XRD/No_013_FS4_1.ras
*RAS_DATA_START
*RAS_HEADER_START
*DISP_FMT_X "%.2f"
*DISP_FMT_Y "%.0f"
*DISP_FULLSCALE "15830.0000000000"
*DISP_LINE_COLOR "255.0000000000"
*DISP_LINE_STYLE "0.0000000000"
*DISP_LINE_WIDTH "0.2500000000"
*DISP_NOTE "測定データ-4"
*DISP_OFFSET_Y "0.0000000000"
*DISP_PEAKSEARCH_UNIT_Y "cps"
*DISP_RANGE_BOTTOM "0.0000000000"
*DISP_RANGE_LEFT "20.0000000000"
*DISP_RANGE_LOGCUTOFF "0.0100000000"
*DISP_RANGE_RIGHT "70.0000000000"
*DISP_RANGE_TOP "15830.0000000000"
*DISP_SCALE_MODE_Y "0.0000000000"
*DISP_TAB_NAME "2θ/θ"
*DISP_TITLE_Y "強度"
*DISP_UNIT_Y "cps"
*DISP_WINDOW_NAME "MSG_MACROENGINE"
*FILE_COMMENT " "
*FILE_MD5 ""
*FILE_MEMO " "
*FILE_OPERATOR "Administrator"
*FILE_SAMPLE " "
*FILE_TYPE "RAS_RAW"
*FILE_USERGROUP "システムマネージャ"
*FILE_VERSION "1.0000000000"
*HW_ATTACHMENT_ID "ATT0025"
*HW_ATTACHMENT_NAME "標準|Standard"
*HW_COUNTER_ID-0 "CUT0025"
*HW_COUNTER_ID-1 "CUT0020"
*HW_COUNTER_ID-2 "CUT0020"
*HW_COUNTER_ID-3 "CSL0021"
*HW_COUNTER_ID-4 "CMC0021"
*HW_COUNTER_NAME-0 "D/teX Ultra|D/teX Ultra"
*HW_COUNTER_NAME-1 "None|None"
*HW_COUNTER_NAME-2 "None|None"
*HW_COUNTER_NAME-3 "BBM|BBM"
*HW_COUNTER_NAME-4 "検出器モノクロメータ|Detector monochromator"
*HW_COUNTER_SELECT_NAME "D/teX Ultra|D/teX Ultra"
*HW_GONIOMETER_ID "GON0023"
*HW_GONIOMETER_NAME "SmartLab|SmartLab"
*HW_GONIOMETER_RADIUS-0 "90.0"
*HW_GONIOMETER_RADIUS-1 "114.0"
*HW_GONIOMETER_RADIUS-2 "190.0"
*HW_GONIOMETER_RADIUS-3 "300.0"
*HW_GONIOMETER_RADIUS-4 "187.0"
*HW_GONIOMETER_RADIUS-5 "300.0"
*HW_GONIOMETER_RADIUS-6 "113.0"
*HW_GONIOMETER_RADIUS-7 "331.0"
*HW_I_OPT_ID-0 "CBO0021"
*HW_I_OPT_ID-1 "ICR0023"
*HW_I_OPT_ID-2 "ISL0021"
*HW_I_OPT_ID-3 "ISO0021"
*HW_I_OPT_ID-4 "IAD0021"
*HW_I_OPT_ID-5 "IPR0001"
*HW_I_OPT_NAME-0 "CBOユニット|CBO unit"
*HW_I_OPT_NAME-1 "標準入射光学ユニット|Standard incident optical unit"
*HW_I_OPT_NAME-2 "標準入射スリットボックス|Standard incident slit box"
*HW_I_OPT_NAME-3 "入射平行スリット|Incident parallel slit"
*HW_I_OPT_NAME-4 "長手制限スリット|Length limiting slit"
*HW_I_OPT_NAME-5 "None|None"
*HW_R_ATTENUATER_AUTOMODE "0"
*HW_R_OPT_ID-0 "RSS0021"
*HW_R_OPT_ID-1 "RCR0023"
*HW_R_OPT_ID-2 "RSO0021"
*HW_R_OPT_ID-3 "RRS0021"
*HW_R_OPT_ID-4 "ATN0021"
*HW_R_OPT_ID-5 "RFL0021"
*HW_R_OPT_ID-6 "RAD0021"
*HW_R_OPT_NAME-0 "標準受光スリットボックス1|Standard receiving slit box # 1"
*HW_R_OPT_NAME-1 "標準受光光学ユニット1|Standard receiving unit # 1"
*HW_R_OPT_NAME-2 "標準受光光学ユニット2|Standard receiving optical unit # 2"
*HW_R_OPT_NAME-3 "標準受光スリットボックス2|Standard receiving slit box # 2"
*HW_R_OPT_NAME-4 "標準アッテネータ|Standard Attenuator"
*HW_R_OPT_NAME-5 "Cu Kβ|Cu K-beta"
*HW_R_OPT_NAME-6 "調整用受光スリット|Alignment receiving slit"
*HW_SAMPLE_HOLDER_ID "SMP0023"
*HW_SAMPLE_HOLDER_NAME "標準Zステージ|Standard Z stage"
*HW_XG_CURRENT_MAX "50"
*HW_XG_CURRENT_MIN "2"
*HW_XG_CURRENT_RESOLUTION "1"
*HW_XG_CURRENT_UNIT "mA"
*HW_XG_FOCUS "1mm x 10mm"
*HW_XG_FOCUS_TYPE "Normal"
*HW_XG_ID ""
*HW_XG_NAME "3kW 封入管(ID:1200)|3kW Sealed tube(ID:1200)"
*HW_XG_TARGET_ATOMIC_NUMBER "29.0000000000"
*HW_XG_TARGET_NAME "Cu"
*HW_XG_TYPE "Hermetic"
*HW_XG_VOLTAGE_MAX "60"
*HW_XG_VOLTAGE_MIN "20"
*HW_XG_VOLTAGE_RESOLUTION "1"
*HW_XG_VOLTAGE_UNIT "kV"
*HW_XG_WATT_MAX "1.500"
*HW_XG_WATT_UNIT "kW"
*HW_XG_WAVE_LENGTH_ALPHA1 "1.540593"
*HW_XG_WAVE_LENGTH_ALPHA2 "1.544414"
*HW_XG_WAVE_LENGTH_BETA "1.392250"
*MEAS_COND_AXIS_NAME-0 "2θ/θ"
*MEAS_COND_AXIS_NAME-1 "2θ"
*MEAS_COND_AXIS_NAME-2 "ω"
*MEAS_COND_AXIS_NAME-3 "Z"
*MEAS_COND_AXIS_NAME-4 "2θ/ω"
*MEAS_COND_AXIS_NAME-5 "θs"
*MEAS_COND_AXIS_NAME-6 "θd"
*MEAS_COND_AXIS_NAME-7 "Ts"
*MEAS_COND_AXIS_NAME-8 "CBO選択スリット"
*MEAS_COND_AXIS_NAME-9 "M"
*MEAS_COND_AXIS_NAME-10 "入射平行スリット"
*MEAS_COND_AXIS_NAME-11 "入射スリット"
*MEAS_COND_AXIS_NAME-12 ""
*MEAS_COND_AXIS_NAME-13 "Zs"
*MEAS_COND_AXIS_NAME-14 "入射光学素子"
*MEAS_COND_AXIS_NAME-15 "長手制限スリット"
*MEAS_COND_AXIS_NAME-16 "センタースリット"
*MEAS_COND_AXIS_NAME-17 "フィルター"
*MEAS_COND_AXIS_NAME-18 "受光スリット1"
*MEAS_COND_AXIS_NAME-19 "受光スリット2"
*MEAS_COND_AXIS_NAME-20 "受光光学素子"
*MEAS_COND_AXIS_NAME-21 "受光平行スリット"
*MEAS_COND_AXIS_NAME-22 "調整用受光スリット"
*MEAS_COND_AXIS_NAME-23 ""
*MEAS_COND_AXIS_NAME-24 ""
*MEAS_COND_AXIS_NAME-25 "Zd"
*MEAS_COND_AXIS_NAME-26 "アッテネータ"
*MEAS_COND_AXIS_NAME-27 "検出器モノクロメータ"
*MEAS_COND_AXIS_NAME-28 "モノクロメータスリット"
*MEAS_COND_AXIS_NAME-29 "プライマリビーム"
*MEAS_COND_AXIS_NAME-30 "PHA"
*MEAS_COND_AXIS_NAME_INTERNAL-0 "TwoThetaTheta"
*MEAS_COND_AXIS_NAME_INTERNAL-1 "TwoTheta"
*MEAS_COND_AXIS_NAME_INTERNAL-2 "Omega"
*MEAS_COND_AXIS_NAME_INTERNAL-3 "Z"
*MEAS_COND_AXIS_NAME_INTERNAL-4 "TwoThetaOmega"
*MEAS_COND_AXIS_NAME_INTERNAL-5 "ThetaS"
*MEAS_COND_AXIS_NAME_INTERNAL-6 "ThetaD"
*MEAS_COND_AXIS_NAME_INTERNAL-7 "Ts"
*MEAS_COND_AXIS_NAME_INTERNAL-8 "CBO"
*MEAS_COND_AXIS_NAME_INTERNAL-9 "CBO-M"
*MEAS_COND_AXIS_NAME_INTERNAL-10 "IncidentSollerSlit"
*MEAS_COND_AXIS_NAME_INTERNAL-11 "IncidentSlitBox"
*MEAS_COND_AXIS_NAME_INTERNAL-12 "IncidentSlitBox-_Axis"
*MEAS_COND_AXIS_NAME_INTERNAL-13 "Zs"
*MEAS_COND_AXIS_NAME_INTERNAL-14 "IncidentMonochromator"
*MEAS_COND_AXIS_NAME_INTERNAL-15 "IncidentAxdSlit"
*MEAS_COND_AXIS_NAME_INTERNAL-16 "CenterSlit"
*MEAS_COND_AXIS_NAME_INTERNAL-17 "Filter"
*MEAS_COND_AXIS_NAME_INTERNAL-18 "ReceivingSlitBox1"
*MEAS_COND_AXIS_NAME_INTERNAL-19 "ReceivingSlitBox2"
*MEAS_COND_AXIS_NAME_INTERNAL-20 "ReceivingOptics"
*MEAS_COND_AXIS_NAME_INTERNAL-21 "ReceivingSollerSlit"
*MEAS_COND_AXIS_NAME_INTERNAL-22 "ReceivingAxdSlit"
*MEAS_COND_AXIS_NAME_INTERNAL-23 "ReceivingSlitBox1-_Axis"
*MEAS_COND_AXIS_NAME_INTERNAL-24 "ReceivingSlitBox2-_Axis"
*MEAS_COND_AXIS_NAME_INTERNAL-25 "ReceivingSlitBox2-Zd"
*MEAS_COND_AXIS_NAME_INTERNAL-26 "Attenuator"
*MEAS_COND_AXIS_NAME_INTERNAL-27 "CounterMonochromator"
*MEAS_COND_AXIS_NAME_INTERNAL-28 "CounterSlit"
*MEAS_COND_AXIS_NAME_INTERNAL-29 "IncidentPrimary"
*MEAS_COND_AXIS_NAME_INTERNAL-30 "PHA"
*MEAS_COND_AXIS_NAME_MAGICNO-0 "83951616.0000000000"
*MEAS_COND_AXIS_NAME_MAGICNO-1 "268632064.0000000000"
*MEAS_COND_AXIS_NAME_MAGICNO-2 "268500992.0000000000"
*MEAS_COND_AXIS_NAME_MAGICNO-3 "285278208.0000000000"
*MEAS_COND_AXIS_NAME_MAGICNO-4 "83951616.0000000000"
*MEAS_COND_AXIS_NAME_MAGICNO-5 "131072.0000000000"
*MEAS_COND_AXIS_NAME_MAGICNO-6 "131072.0000000000"
*MEAS_COND_AXIS_NAME_MAGICNO-7 "318898176.0000000000"
*MEAS_COND_AXIS_NAME_MAGICNO-8 "20971521.0000000000"
*MEAS_COND_AXIS_NAME_MAGICNO-9 "285343744.0000000000"
*MEAS_COND_AXIS_NAME_MAGICNO-10 "20971521.0000000000"
*MEAS_COND_AXIS_NAME_MAGICNO-11 "22020097.0000000000"
*MEAS_COND_AXIS_NAME_MAGICNO-12 "25165824.0000000000"
*MEAS_COND_AXIS_NAME_MAGICNO-13 "318898176.0000000000"
*MEAS_COND_AXIS_NAME_MAGICNO-14 "1.0000000000"
*MEAS_COND_AXIS_NAME_MAGICNO-15 "20971521.0000000000"
*MEAS_COND_AXIS_NAME_MAGICNO-16 "20971521.0000000000"
*MEAS_COND_AXIS_NAME_MAGICNO-17 "20971521.0000000000"
*MEAS_COND_AXIS_NAME_MAGICNO-18 "23068673.0000000000"
*MEAS_COND_AXIS_NAME_MAGICNO-19 "23068673.0000000000"
*MEAS_COND_AXIS_NAME_MAGICNO-20 "20971521.0000000000"
*MEAS_COND_AXIS_NAME_MAGICNO-21 "20971521.0000000000"
*MEAS_COND_AXIS_NAME_MAGICNO-22 "20971521.0000000000"
*MEAS_COND_AXIS_NAME_MAGICNO-23 "25165824.0000000000"
*MEAS_COND_AXIS_NAME_MAGICNO-24 "25165824.0000000000"
*MEAS_COND_AXIS_NAME_MAGICNO-25 "285343744.0000000000"
*MEAS_COND_AXIS_NAME_MAGICNO-26 "17301505.0000000000"
*MEAS_COND_AXIS_NAME_MAGICNO-27 "20971521.0000000000"
*MEAS_COND_AXIS_NAME_MAGICNO-28 "20971521.0000000000"
*MEAS_COND_AXIS_NAME_MAGICNO-29 "20971521.0000000000"
*MEAS_COND_AXIS_NAME_MAGICNO-30 "0.0000000000"
*MEAS_COND_AXIS_OFFSET-0 "-"
*MEAS_COND_AXIS_OFFSET-1 "-0.1081000000"
*MEAS_COND_AXIS_OFFSET-2 "0.3758000000"
*MEAS_COND_AXIS_OFFSET-3 "-"
*MEAS_COND_AXIS_OFFSET-4 "-"
*MEAS_COND_AXIS_OFFSET-5 "0.3758000000"
*MEAS_COND_AXIS_OFFSET-6 "-0.4839000000"
*MEAS_COND_AXIS_OFFSET-7 "-"
*MEAS_COND_AXIS_OFFSET-8 "-"
*MEAS_COND_AXIS_OFFSET-9 "-"
*MEAS_COND_AXIS_OFFSET-10 "-"
*MEAS_COND_AXIS_OFFSET-11 "-"
*MEAS_COND_AXIS_OFFSET-12 "-"
*MEAS_COND_AXIS_OFFSET-13 "-"
*MEAS_COND_AXIS_OFFSET-14 "-"
*MEAS_COND_AXIS_OFFSET-15 "-"
*MEAS_COND_AXIS_OFFSET-16 "-"
*MEAS_COND_AXIS_OFFSET-17 "-"
*MEAS_COND_AXIS_OFFSET-18 "-"
*MEAS_COND_AXIS_OFFSET-19 "-"
*MEAS_COND_AXIS_OFFSET-20 "-"
*MEAS_COND_AXIS_OFFSET-21 "-"
*MEAS_COND_AXIS_OFFSET-22 "-"
*MEAS_COND_AXIS_OFFSET-23 "-"
*MEAS_COND_AXIS_OFFSET-24 "-"
*MEAS_COND_AXIS_OFFSET-25 "-"
*MEAS_COND_AXIS_OFFSET-26 "-"
*MEAS_COND_AXIS_OFFSET-27 "-"
*MEAS_COND_AXIS_OFFSET-28 "-"
*MEAS_COND_AXIS_OFFSET-29 "-"
*MEAS_COND_AXIS_OFFSET-30 "-"
*MEAS_COND_AXIS_POSITION-0 "0.0000000000"
*MEAS_COND_AXIS_POSITION-1 "0.0000000000"
*MEAS_COND_AXIS_POSITION-2 "0.0000000000"
*MEAS_COND_AXIS_POSITION-3 "-0.5500000000"
*MEAS_COND_AXIS_POSITION-4 "0.0000000000"
*MEAS_COND_AXIS_POSITION-5 "0.0000000000"
*MEAS_COND_AXIS_POSITION-6 "0.0000000000"
*MEAS_COND_AXIS_POSITION-7 "-0.4278800000"
*MEAS_COND_AXIS_POSITION-8 "BB"
*MEAS_COND_AXIS_POSITION-9 "0.0000000000"
*MEAS_COND_AXIS_POSITION-10 "Soller_slit_5.0deg"
*MEAS_COND_AXIS_POSITION-11 "2/3deg"
*MEAS_COND_AXIS_POSITION-12 "2.2088000000"
*MEAS_COND_AXIS_POSITION-13 "-0.4140600000"
*MEAS_COND_AXIS_POSITION-14 "0.0000000000"
*MEAS_COND_AXIS_POSITION-15 "10.0mm"
*MEAS_COND_AXIS_POSITION-16 "None"
*MEAS_COND_AXIS_POSITION-17 "Cu_K-beta"
*MEAS_COND_AXIS_POSITION-18 "13.000mm"
*MEAS_COND_AXIS_POSITION-19 "13.000mm"
*MEAS_COND_AXIS_POSITION-20 "No_unit"
*MEAS_COND_AXIS_POSITION-21 "Soller_slit_5.0deg"
*MEAS_COND_AXIS_POSITION-22 "None"
*MEAS_COND_AXIS_POSITION-23 "13.0000000000"
*MEAS_COND_AXIS_POSITION-24 "13.0000000000"
*MEAS_COND_AXIS_POSITION-25 "0.0109400000"
*MEAS_COND_AXIS_POSITION-26 "Open"
*MEAS_COND_AXIS_POSITION-27 "None"
*MEAS_COND_AXIS_POSITION-28 "None"
*MEAS_COND_AXIS_POSITION-29 "None"
*MEAS_COND_AXIS_POSITION-30 "38.0000000000"
*MEAS_COND_AXIS_UNIT-0 "deg"
*MEAS_COND_AXIS_UNIT-1 "deg"
*MEAS_COND_AXIS_UNIT-2 "deg"
*MEAS_COND_AXIS_UNIT-3 "mm"
*MEAS_COND_AXIS_UNIT-4 "deg"
*MEAS_COND_AXIS_UNIT-5 "deg"
*MEAS_COND_AXIS_UNIT-6 "deg"
*MEAS_COND_AXIS_UNIT-7 "mm"
*MEAS_COND_AXIS_UNIT-8 ""
*MEAS_COND_AXIS_UNIT-9 "pulse"
*MEAS_COND_AXIS_UNIT-10 ""
*MEAS_COND_AXIS_UNIT-11 ""
*MEAS_COND_AXIS_UNIT-12 "mm"
*MEAS_COND_AXIS_UNIT-13 "mm"
*MEAS_COND_AXIS_UNIT-14 ""
*MEAS_COND_AXIS_UNIT-15 ""
*MEAS_COND_AXIS_UNIT-16 ""
*MEAS_COND_AXIS_UNIT-17 ""
*MEAS_COND_AXIS_UNIT-18 ""
*MEAS_COND_AXIS_UNIT-19 ""
*MEAS_COND_AXIS_UNIT-20 ""
*MEAS_COND_AXIS_UNIT-21 ""
*MEAS_COND_AXIS_UNIT-22 ""
*MEAS_COND_AXIS_UNIT-23 "mm"
*MEAS_COND_AXIS_UNIT-24 "mm"
*MEAS_COND_AXIS_UNIT-25 "mm"
*MEAS_COND_AXIS_UNIT-26 ""
*MEAS_COND_AXIS_UNIT-27 ""
*MEAS_COND_AXIS_UNIT-28 ""
*MEAS_COND_AXIS_UNIT-29 ""
*MEAS_COND_AXIS_UNIT-30 "div"
*MEAS_COND_COUNTER_CNTLOSS_CORR "0.0000000000"
*MEAS_COND_COUNTER_PHABASE "38.0000000000"
*MEAS_COND_COUNTER_PHAWINDOW "16.0000000000"
*MEAS_COND_COUNTER_PHA_UNIT "div"
*MEAS_COND_COUNTER_TAUDIFF "30.0000000000"
*MEAS_COND_COUNTER_TAUINT "0.0000000000"
*MEAS_COND_IRRADIATION_MODE "OFF"
*MEAS_COND_IRRADIATION_WIDTH ""
*MEAS_COND_OPT_ATTR "集中法"
*MEAS_COND_OPT_NAME "@集中法"
*MEAS_COND_UNSYMMETRIC_MODE "OFF"
*MEAS_COND_XG_CURRENT "30.0000000000"
*MEAS_COND_XG_VOLTAGE "40.0000000000"
*MEAS_COND_XG_WAVE_TYPE "Ka"
*MEAS_DATA_COUNT "5001.0000000000"
*MEAS_SCAN_AXIS_X "2θ/θ"
*MEAS_SCAN_AXIS_X_INTERNAL "TwoThetaTheta"
*MEAS_SCAN_END_TIME "07/06/21 16:19:16"
*MEAS_SCAN_MODE "CONTINUOUS"
*MEAS_SCAN_MONITOR "0"
*MEAS_SCAN_RESOLUTION_X "0.0002"
*MEAS_SCAN_SPEED "1.0"
*MEAS_SCAN_SPEED_UNIT "deg/min"
*MEAS_SCAN_START "20.0000000000"
*MEAS_SCAN_START_TIME "07/06/21 15:26:24"
*MEAS_SCAN_STEP "0.0100000000"
*MEAS_SCAN_STOP "70.0000000000"
*MEAS_SCAN_UNIT_X "deg"
*MEAS_SCAN_UNIT_Y "counts"
*RAS_HEADER_END
*RAS_INT_START
20.0000 1709.0000 1.0000
20.0400 1654.0000 1.0000
20.0800 1679.0000 1.0000
20.1200 1602.0000 1.0000
20.1600 1663.0000 1.0000
20.2000 1625.0000 1.0000
20.2400 1652.0000 1.0000
20.2800 1680.0000 1.0000
20.3200 1727.0000 1.0000
20.3600 1686.0000 1.0000
20.4000 1651.0000 1.0000
20.4400 1653.0000 1.0000
20.4800 1634.0000 1.0000
20.5200 1689.0000 1.0000
20.5600 1698.0000 1.0000
20.6000 1673.0000 1.0000
20.6400 1685.0000 1.0000
20.6800 1692.0000 1.0000
20.7200 1685.0000 1.0000
20.7600 1663.0000 1.0000
20.8000 1730.0000 1.0000
20.8400 1646.0000 1.0000
20.8800 1653.0000 1.0000
20.9200 1637.0000 1.0000
20.9600 1660.0000 1.0000
21.0000 1617.0000 1.0000
21.0400 1627.0000 1.0000
21.0800 1708.0000 1.0000
21.1200 1599.0000 1.0000
21.1600 1688.0000 1.0000
21.2000 1717.0000 1.0000
21.2400 1773.0000 1.0000
21.2800 1694.0000 1.0000
21.3200 1669.0000 1.0000
21.3600 1675.0000 1.0000
21.4000 1651.0000 1.0000
21.4400 1661.0000 1.0000
21.4800 1694.0000 1.0000
21.5200 1639.0000 1.0000
21.5600 1681.0000 1.0000
21.6000 1704.0000 1.0000
21.6400 1619.0000 1.0000
21.6800 1658.0000 1.0000
21.7200 1733.0000 1.0000
21.7600 1677.0000 1.0000
21.8000 1667.0000 1.0000
21.8400 1660.0000 1.0000
21.8800 1664.0000 1.0000
21.9200 1679.0000 1.0000
21.9600 1730.0000 1.0000
22.0000 1764.0000 1.0000
22.0400 1699.0000 1.0000
22.0800 1585.0000 1.0000
22.1200 1694.0000 1.0000
22.1600 1678.0000 1.0000
22.2000 1651.0000 1.0000
22.2400 1712.0000 1.0000
22.2800 1686.0000 1.0000
22.3200 1706.0000 1.0000
22.3600 1720.0000 1.0000
22.4000 1658.0000 1.0000
22.4400 1675.0000 1.0000
22.4800 1728.0000 1.0000
22.5200 1671.0000 1.0000
22.5600 1647.0000 1.0000
22.6000 1757.0000 1.0000
22.6400 1663.0000 1.0000
22.6800 1748.0000 1.0000
22.7200 1736.0000 1.0000
22.7600 1682.0000 1.0000
22.8000 1746.0000 1.0000
22.8400 1773.0000 1.0000
22.8800 1705.0000 1.0000
22.9200 1704.0000 1.0000
22.9600 1754.0000 1.0000
23.0000 1713.0000 1.0000
23.0400 1730.0000 1.0000
23.0800 1718.0000 1.0000
23.1200 1730.0000 1.0000
23.1600 1704.0000 1.0000
23.2000 1688.0000 1.0000
23.2400 1730.0000 1.0000
23.2800 1745.0000 1.0000
23.3200 1752.0000 1.0000
23.3600 1730.0000 1.0000
23.4000 1716.0000 1.0000
23.4400 1778.0000 1.0000
23.4800 1695.0000 1.0000
23.5200 1750.0000 1.0000
23.5600 1680.0000 1.0000
23.6000 1681.0000 1.0000
23.6400 1713.0000 1.0000
23.6800 1706.0000 1.0000
23.7200 1815.0000 1.0000
23.7600 1693.0000 1.0000
23.8000 1711.0000 1.0000
23.8400 1662.0000 1.0000
23.8800 1749.0000 1.0000
23.9200 1769.0000 1.0000
23.9600 1709.0000 1.0000
24.0000 1701.0000 1.0000
24.0400 1732.0000 1.0000
24.0800 1747.0000 1.0000
24.1200 1763.0000 1.0000
24.1600 1793.0000 1.0000
24.2000 1782.0000 1.0000
24.2400 1674.0000 1.0000
24.2800 1715.0000 1.0000
24.3200 1675.0000 1.0000
24.3600 1692.0000 1.0000
24.4000 1770.0000 1.0000
24.4400 1695.0000 1.0000
24.4800 1757.0000 1.0000
24.5200 1780.0000 1.0000
24.5600 1737.0000 1.0000
24.6000 1826.0000 1.0000
24.6400 1788.0000 1.0000
24.6800 1790.0000 1.0000
24.7200 1811.0000 1.0000
24.7600 1842.0000 1.0000
24.8000 1762.0000 1.0000
24.8400 1860.0000 1.0000
24.8800 1785.0000 1.0000
24.9200 1916.0000 1.0000
24.9600 1828.0000 1.0000
25.0000 1856.0000 1.0000
25.0400 1779.0000 1.0000
25.0800 1739.0000 1.0000
25.1200 1786.0000 1.0000
25.1600 1841.0000 1.0000
25.2000 1853.0000 1.0000
25.2400 1769.0000 1.0000
25.2800 1814.0000 1.0000
25.3200 1754.0000 1.0000
25.3600 1719.0000 1.0000
25.4000 1837.0000 1.0000
25.4400 1797.0000 1.0000
25.4800 1759.0000 1.0000
25.5200 1747.0000 1.0000
25.5600 1777.0000 1.0000
25.6000 1760.0000 1.0000
25.6400 1721.0000 1.0000
25.6800 1739.0000 1.0000
25.7200 1804.0000 1.0000
25.7600 1852.0000 1.0000
25.8000 1845.0000 1.0000
25.8400 1778.0000 1.0000
25.8800 1788.0000 1.0000
25.9200 1745.0000 1.0000
25.9600 1810.0000 1.0000
26.0000 1781.0000 1.0000
26.0400 1804.0000 1.0000
26.0800 1746.0000 1.0000
26.1200 1773.0000 1.0000
26.1600 1722.0000 1.0000
26.2000 1745.0000 1.0000
26.2400 1771.0000 1.0000
26.2800 1823.0000 1.0000
26.3200 1878.0000 1.0000
26.3600 1826.0000 1.0000
26.4000 1879.0000 1.0000
26.4400 1871.0000 1.0000
26.4800 1819.0000 1.0000
26.5200 1887.0000 1.0000
26.5600 1926.0000 1.0000
26.6000 1858.0000 1.0000
26.6400 1802.0000 1.0000
26.6800 1942.0000 1.0000
26.7200 1906.0000 1.0000
26.7600 1997.0000 1.0000
26.8000 2021.0000 1.0000
26.8400 2130.0000 1.0000
26.8800 2141.0000 1.0000
26.9200 2204.0000 1.0000
26.9600 2351.0000 1.0000
27.0000 2456.0000 1.0000
27.0400 2708.0000 1.0000
27.0800 2954.0000 1.0000
27.1200 3364.0000 1.0000
27.1600 4002.0000 1.0000
27.2000 4827.0000 1.0000
27.2400 5864.0000 1.0000
27.2800 6707.0000 1.0000
27.3200 6644.0000 1.0000
27.3600 5953.0000 1.0000
27.4000 4750.0000 1.0000
27.4400 3921.0000 1.0000
27.4800 3320.0000 1.0000
27.5200 2968.0000 1.0000
27.5600 2695.0000 1.0000
27.6000 2440.0000 1.0000
27.6400 2341.0000 1.0000
27.6800 2054.0000 1.0000
27.7200 2030.0000 1.0000
27.7600 2094.0000 1.0000
27.8000 1955.0000 1.0000
27.8400 1941.0000 1.0000
27.8800 1908.0000 1.0000
27.9200 1853.0000 1.0000
27.9600 1904.0000 1.0000
28.0000 1872.0000 1.0000
28.0400 1815.0000 1.0000
28.0800 1802.0000 1.0000
28.1200 1834.0000 1.0000
28.1600 1828.0000 1.0000
28.2000 1648.0000 1.0000
28.2400 1791.0000 1.0000
28.2800 1773.0000 1.0000
28.3200 1815.0000 1.0000
28.3600 1736.0000 1.0000
28.4000 1659.0000 1.0000
28.4400 1778.0000 1.0000
28.4800 1830.0000 1.0000
28.5200 1700.0000 1.0000
28.5600 1732.0000 1.0000
28.6000 1703.0000 1.0000
28.6400 1710.0000 1.0000
28.6800 1720.0000 1.0000
28.7200 1709.0000 1.0000
28.7600 1662.0000 1.0000
28.8000 1706.0000 1.0000
28.8400 1718.0000 1.0000
28.8800 1644.0000 1.0000
28.9200 1645.0000 1.0000
28.9600 1650.0000 1.0000
29.0000 1707.0000 1.0000
29.0400 1647.0000 1.0000
29.0800 1655.0000 1.0000
29.1200 1784.0000 1.0000
29.1600 1672.0000 1.0000
29.2000 1627.0000 1.0000
29.2400 1679.0000 1.0000
29.2800 1629.0000 1.0000
29.3200 1610.0000 1.0000
29.3600 1682.0000 1.0000
29.4000 1614.0000 1.0000
29.4400 1661.0000 1.0000
29.4800 1619.0000 1.0000
29.5200 1649.0000 1.0000
29.5600 1681.0000 1.0000
29.6000 1626.0000 1.0000
29.6400 1629.0000 1.0000
29.6800 1551.0000 1.0000
29.7200 1598.0000 1.0000
29.7600 1626.0000 1.0000
29.8000 1607.0000 1.0000
29.8400 1609.0000 1.0000
29.8800 1591.0000 1.0000
29.9200 1578.0000 1.0000
29.9600 1641.0000 1.0000
30.0000 1607.0000 1.0000
30.0400 1640.0000 1.0000
30.0800 1619.0000 1.0000
30.1200 1596.0000 1.0000
30.1600 1593.0000 1.0000
30.2000 1611.0000 1.0000
30.2400 1575.0000 1.0000
30.2800 1561.0000 1.0000
30.3200 1589.0000 1.0000
30.3600 1653.0000 1.0000
30.4000 1546.0000 1.0000
30.4400 1581.0000 1.0000
30.4800 1532.0000 1.0000
30.5200 1576.0000 1.0000
30.5600 1518.0000 1.0000
30.6000 1497.0000 1.0000
30.6400 1603.0000 1.0000
30.6800 1585.0000 1.0000
30.7200 1533.0000 1.0000
30.7600 1532.0000 1.0000
30.8000 1615.0000 1.0000
30.8400 1584.0000 1.0000
30.8800 1494.0000 1.0000
30.9200 1551.0000 1.0000
30.9600 1579.0000 1.0000
31.0000 1532.0000 1.0000
31.0400 1461.0000 1.0000
31.0800 1575.0000 1.0000
31.1200 1549.0000 1.0000
31.1600 1538.0000 1.0000
31.2000 1531.0000 1.0000
31.2400 1532.0000 1.0000
31.2800 1496.0000 1.0000
31.3200 1494.0000 1.0000
31.3600 1505.0000 1.0000
31.4000 1514.0000 1.0000
31.4400 1473.0000 1.0000
31.4800 1512.0000 1.0000
31.5200 1494.0000 1.0000
31.5600 1478.0000 1.0000
31.6000 1521.0000 1.0000
31.6400 1509.0000 1.0000
31.6800 1499.0000 1.0000
31.7200 1501.0000 1.0000
31.7600 1517.0000 1.0000
31.8000 1479.0000 1.0000
31.8400 1515.0000 1.0000
31.8800 1523.0000 1.0000
31.9200 1597.0000 1.0000
31.9600 1570.0000 1.0000
32.0000 1502.0000 1.0000
32.0400 1481.0000 1.0000
32.0800 1540.0000 1.0000
32.1200 1522.0000 1.0000
32.1600 1481.0000 1.0000
32.2000 1515.0000 1.0000
32.2400 1496.0000 1.0000
32.2800 1469.0000 1.0000
32.3200 1486.0000 1.0000
32.3600 1521.0000 1.0000
32.4000 1425.0000 1.0000
32.4400 1520.0000 1.0000
32.4800 1444.0000 1.0000
32.5200 1422.0000 1.0000
32.5600 1495.0000 1.0000
32.6000 1431.0000 1.0000
32.6400 1428.0000 1.0000
32.6800 1421.0000 1.0000
32.7200 1447.0000 1.0000
32.7600 1392.0000 1.0000
32.8000 1408.0000 1.0000
32.8400 1419.0000 1.0000
32.8800 1407.0000 1.0000
32.9200 1461.0000 1.0000
32.9600 1455.0000 1.0000
33.0000 1441.0000 1.0000
33.0400 1435.0000 1.0000
33.0800 1433.0000 1.0000
33.1200 1368.0000 1.0000
33.1600 1384.0000 1.0000
33.2000 1464.0000 1.0000
33.2400 1412.0000 1.0000
33.2800 1469.0000 1.0000
33.3200 1439.0000 1.0000
33.3600 1380.0000 1.0000
33.4000 1448.0000 1.0000
33.4400 1432.0000 1.0000
33.4800 1377.0000 1.0000
33.5200 1412.0000 1.0000
33.5600 1421.0000 1.0000
33.6000 1425.0000 1.0000
33.6400 1412.0000 1.0000
33.6800 1395.0000 1.0000
33.7200 1384.0000 1.0000
33.7600 1450.0000 1.0000
33.8000 1475.0000 1.0000
33.8400 1528.0000 1.0000
33.8800 1597.0000 1.0000
33.9200 1699.0000 1.0000
33.9600 1633.0000 1.0000
34.0000 1621.0000 1.0000
34.0400 1568.0000 1.0000
34.0800 1552.0000 1.0000
34.1200 1549.0000 1.0000
34.1600 1545.0000 1.0000
34.2000 1639.0000 1.0000
34.2400 1688.0000 1.0000
34.2800 1789.0000 1.0000
34.3200 1929.0000 1.0000
34.3600 2210.0000 1.0000
34.4000 2500.0000 1.0000
34.4400 2875.0000 1.0000
34.4800 3201.0000 1.0000
34.5200 3162.0000 1.0000
34.5600 2827.0000 1.0000
34.6000 2524.0000 1.0000
34.6400 2235.0000 1.0000
34.6800 2002.0000 1.0000
34.7200 1829.0000 1.0000
34.7600 1788.0000 1.0000
34.8000 1643.0000 1.0000
34.8400 1566.0000 1.0000
34.8800 1510.0000 1.0000
34.9200 1450.0000 1.0000
34.9600 1450.0000 1.0000
35.0000 1390.0000 1.0000
35.0400 1396.0000 1.0000
35.0800 1384.0000 1.0000
35.1200 1396.0000 1.0000
35.1600 1308.0000 1.0000
35.2000 1291.0000 1.0000
35.2400 1329.0000 1.0000
35.2800 1234.0000 1.0000
35.3200 1213.0000 1.0000
35.3600 1261.0000 1.0000
35.4000 1269.0000 1.0000
35.4400 1241.0000 1.0000
35.4800 1253.0000 1.0000
35.5200 1291.0000 1.0000
35.5600 1260.0000 1.0000
35.6000 1294.0000 1.0000
35.6400 1247.0000 1.0000
35.6800 1252.0000 1.0000
35.7200 1268.0000 1.0000
35.7600 1233.0000 1.0000
35.8000 1212.0000 1.0000
35.8400 1207.0000 1.0000
35.8800 1198.0000 1.0000
35.9200 1190.0000 1.0000
35.9600 1249.0000 1.0000
36.0000 1124.0000 1.0000
36.0400 1168.0000 1.0000
36.0800 1208.0000 1.0000
36.1200 1225.0000 1.0000
36.1600 1307.0000 1.0000
36.2000 1386.0000 1.0000
36.2400 1459.0000 1.0000
36.2800 1595.0000 1.0000
36.3200 1934.0000 1.0000
36.3600 2351.0000 1.0000
36.4000 2572.0000 1.0000
36.4400 2424.0000 1.0000
36.4800 2175.0000 1.0000
36.5200 1840.0000 1.0000
36.5600 1498.0000 1.0000
36.6000 1351.0000 1.0000
36.6400 1240.0000 1.0000
36.6800 1209.0000 1.0000
36.7200 1147.0000 1.0000
36.7600 1135.0000 1.0000
36.8000 1190.0000 1.0000
36.8400 1155.0000 1.0000
36.8800 1128.0000 1.0000
36.9200 1102.0000 1.0000
36.9600 1111.0000 1.0000
37.0000 1151.0000 1.0000
37.0400 1103.0000 1.0000
37.0800 1157.0000 1.0000
37.1200 1105.0000 1.0000
37.1600 1125.0000 1.0000
37.2000 1146.0000 1.0000
37.2400 1137.0000 1.0000
37.2800 1112.0000 1.0000
37.3200 1132.0000 1.0000
37.3600 1108.0000 1.0000
37.4000 1140.0000 1.0000
37.4400 1105.0000 1.0000
37.4800 1170.0000 1.0000
37.5200 1143.0000 1.0000
37.5600 1099.0000 1.0000
37.6000 1142.0000 1.0000
37.6400 1154.0000 1.0000
37.6800 1116.0000 1.0000
37.7200 1168.0000 1.0000
37.7600 1132.0000 1.0000
37.8000 1195.0000 1.0000
37.8400 1149.0000 1.0000
37.8800 1215.0000 1.0000
37.9200 1139.0000 1.0000
37.9600 1190.0000 1.0000
38.0000 1167.0000 1.0000
38.0400 1270.0000 1.0000
38.0800 1270.0000 1.0000
38.1200 1281.0000 1.0000
38.1600 1392.0000 1.0000
38.2000 1525.0000 1.0000
38.2400 1739.0000 1.0000
38.2800 1996.0000 1.0000
38.3200 2349.0000 1.0000
38.3600 2950.0000 1.0000
38.4000 3733.0000 1.0000
38.4400 5032.0000 1.0000
38.4800 6452.0000 1.0000
38.5200 7525.0000 1.0000
38.5600 7915.0000 1.0000
38.6000 7250.0000 1.0000
38.6400 6139.0000 1.0000
38.6800 4760.0000 1.0000
38.7200 3655.0000 1.0000
38.7600 2833.0000 1.0000
38.8000 2184.0000 1.0000
38.8400 1811.0000 1.0000
38.8800 1557.0000 1.0000
38.9200 1351.0000 1.0000
38.9600 1336.0000 1.0000
39.0000 1244.0000 1.0000
39.0400 1155.0000 1.0000
39.0800 1161.0000 1.0000
39.1200 1135.0000 1.0000
39.1600 1073.0000 1.0000
39.2000 1058.0000 1.0000
39.2400 1006.0000 1.0000
39.2800 1051.0000 1.0000
39.3200 1078.0000 1.0000
39.3600 1042.0000 1.0000
39.4000 1033.0000 1.0000
39.4400 997.0000 1.0000
39.4800 1077.0000 1.0000
39.5200 1093.0000 1.0000
39.5600 1038.0000 1.0000
39.6000 1045.0000 1.0000
39.6400 1088.0000 1.0000
39.6800 1039.0000 1.0000
39.7200 1002.0000 1.0000
39.7600 1001.0000 1.0000
39.8000 1027.0000 1.0000
39.8400 985.0000 1.0000
39.8800 1007.0000 1.0000
39.9200 987.0000 1.0000
39.9600 954.0000 1.0000
40.0000 921.0000 1.0000
40.0400 920.0000 1.0000
40.0800 948.0000 1.0000
40.1200 908.0000 1.0000
40.1600 984.0000 1.0000
40.2000 976.0000 1.0000
40.2400 953.0000 1.0000
40.2800 976.0000 1.0000
40.3200 940.0000 1.0000
40.3600 935.0000 1.0000
40.4000 930.0000 1.0000
40.4400 914.0000 1.0000
40.4800 914.0000 1.0000
40.5200 969.0000 1.0000
40.5600 932.0000 1.0000
40.6000 953.0000 1.0000
40.6400 948.0000 1.0000
40.6800 965.0000 1.0000
40.7200 919.0000 1.0000
40.7600 918.0000 1.0000
40.8000 926.0000 1.0000
40.8400 897.0000 1.0000
40.8800 909.0000 1.0000
40.9200 904.0000 1.0000
40.9600 917.0000 1.0000
41.0000 943.0000 1.0000
41.0400 929.0000 1.0000
41.0800 885.0000 1.0000
41.1200 892.0000 1.0000
41.1600 910.0000 1.0000
41.2000 894.0000 1.0000
41.2400 924.0000 1.0000
41.2800 953.0000 1.0000
41.3200 909.0000 1.0000
41.3600 900.0000 1.0000
41.4000 853.0000 1.0000
41.4400 900.0000 1.0000
41.4800 934.0000 1.0000
41.5200 910.0000 1.0000
41.5600 883.0000 1.0000
41.6000 912.0000 1.0000
41.6400 959.0000 1.0000
41.6800 1009.0000 1.0000
41.7200 936.0000 1.0000
41.7600 905.0000 1.0000
41.8000 874.0000 1.0000
41.8400 879.0000 1.0000
41.8800 911.0000 1.0000
41.9200 890.0000 1.0000
41.9600 893.0000 1.0000
42.0000 947.0000 1.0000
42.0400 947.0000 1.0000
42.0800 912.0000 1.0000
42.1200 898.0000 1.0000
42.1600 967.0000 1.0000
42.2000 888.0000 1.0000
42.2400 883.0000 1.0000
42.2800 875.0000 1.0000
42.3200 855.0000 1.0000
42.3600 899.0000 1.0000
42.4000 901.0000 1.0000
42.4400 896.0000 1.0000
42.4800 909.0000 1.0000
42.5200 870.0000 1.0000
42.5600 831.0000 1.0000
42.6000 871.0000 1.0000
42.6400 923.0000 1.0000
42.6800 916.0000 1.0000
42.7200 924.0000 1.0000
42.7600 947.0000 1.0000
42.8000 904.0000 1.0000
42.8400 887.0000 1.0000
42.8800 899.0000 1.0000
42.9200 942.0000 1.0000
42.9600 838.0000 1.0000
43.0000 910.0000 1.0000
43.0400 911.0000 1.0000
43.0800 905.0000 1.0000
43.1200 905.0000 1.0000
43.1600 985.0000 1.0000
43.2000 934.0000 1.0000
43.2400 1016.0000 1.0000
43.2800 989.0000 1.0000
43.3200 974.0000 1.0000
43.3600 931.0000 1.0000
43.4000 934.0000 1.0000
43.4400 923.0000 1.0000
43.4800 954.0000 1.0000
43.5200 936.0000 1.0000
43.5600 881.0000 1.0000
43.6000 901.0000 1.0000
43.6400 871.0000 1.0000
43.6800 903.0000 1.0000
43.7200 864.0000 1.0000
43.7600 876.0000 1.0000
43.8000 916.0000 1.0000
43.8400 858.0000 1.0000
43.8800 871.0000 1.0000
43.9200 869.0000 1.0000
43.9600 816.0000 1.0000
44.0000 869.0000 1.0000
44.0400 899.0000 1.0000
44.0800 878.0000 1.0000
44.1200 861.0000 1.0000
44.1600 849.0000 1.0000
44.2000 832.0000 1.0000
44.2400 885.0000 1.0000
44.2800 902.0000 1.0000
44.3200 881.0000 1.0000
44.3600 869.0000 1.0000
44.4000 903.0000 1.0000
44.4400 825.0000 1.0000
44.4800 847.0000 1.0000
44.5200 842.0000 1.0000
44.5600 895.0000 1.0000
44.6000 848.0000 1.0000
44.6400 834.0000 1.0000
44.6800 880.0000 1.0000
44.7200 845.0000 1.0000
44.7600 879.0000 1.0000
44.8000 903.0000 1.0000
44.8400 820.0000 1.0000
44.8800 900.0000 1.0000
44.9200 841.0000 1.0000
44.9600 834.0000 1.0000
45.0000 906.0000 1.0000
45.0400 868.0000 1.0000
45.0800 820.0000 1.0000
45.1200 852.0000 1.0000
45.1600 806.0000 1.0000
45.2000 832.0000 1.0000
45.2400 841.0000 1.0000
45.2800 909.0000 1.0000
45.3200 893.0000 1.0000
45.3600 835.0000 1.0000
45.4000 832.0000 1.0000
45.4400 833.0000 1.0000
45.4800 824.0000 1.0000
45.5200 853.0000 1.0000
45.5600 882.0000 1.0000
45.6000 834.0000 1.0000
45.6400 862.0000 1.0000
45.6800 831.0000 1.0000
45.7200 918.0000 1.0000
45.7600 855.0000 1.0000
45.8000 812.0000 1.0000
45.8400 811.0000 1.0000
45.8800 819.0000 1.0000
45.9200 789.0000 1.0000
45.9600 807.0000 1.0000
46.0000 863.0000 1.0000
46.0400 790.0000 1.0000
46.0800 804.0000 1.0000
46.1200 857.0000 1.0000
46.1600 833.0000 1.0000
46.2000 833.0000 1.0000
46.2400 865.0000 1.0000
46.2800 806.0000 1.0000
46.3200 898.0000 1.0000
46.3600 809.0000 1.0000
46.4000 782.0000 1.0000
46.4400 793.0000 1.0000
46.4800 836.0000 1.0000
46.5200 790.0000 1.0000
46.5600 845.0000 1.0000
46.6000 804.0000 1.0000
46.6400 791.0000 1.0000
46.6800 828.0000 1.0000
46.7200 786.0000 1.0000
46.7600 869.0000 1.0000
46.8000 806.0000 1.0000
46.8400 816.0000 1.0000
46.8800 815.0000 1.0000
46.9200 843.0000 1.0000
46.9600 876.0000 1.0000
47.0000 894.0000 1.0000
47.0400 829.0000 1.0000
47.0800 842.0000 1.0000
47.1200 849.0000 1.0000
47.1600 806.0000 1.0000
47.2000 762.0000 1.0000
47.2400 788.0000 1.0000
47.2800 809.0000 1.0000
47.3200 767.0000 1.0000
47.3600 795.0000 1.0000
47.4000 842.0000 1.0000
47.4400 811.0000 1.0000
47.4800 792.0000 1.0000
47.5200 789.0000 1.0000
47.5600 808.0000 1.0000
47.6000 799.0000 1.0000
47.6400 801.0000 1.0000
47.6800 809.0000 1.0000
47.7200 769.0000 1.0000
47.7600 800.0000 1.0000
47.8000 833.0000 1.0000
47.8400 783.0000 1.0000
47.8800 804.0000 1.0000
47.9200 783.0000 1.0000
47.9600 825.0000 1.0000
48.0000 778.0000 1.0000
48.0400 778.0000 1.0000
48.0800 796.0000 1.0000
48.1200 801.0000 1.0000
48.1600 741.0000 1.0000
48.2000 759.0000 1.0000
48.2400 794.0000 1.0000
48.2800 790.0000 1.0000
48.3200 827.0000 1.0000
48.3600 797.0000 1.0000
48.4000 786.0000 1.0000
48.4400 821.0000 1.0000
48.4800 779.0000 1.0000
48.5200 753.0000 1.0000
48.5600 765.0000 1.0000
48.6000 769.0000 1.0000
48.6400 773.0000 1.0000
48.6800 751.0000 1.0000
48.7200 776.0000 1.0000
48.7600 788.0000 1.0000
48.8000 816.0000 1.0000
48.8400 767.0000 1.0000
48.8800 796.0000 1.0000
48.9200 754.0000 1.0000
48.9600 745.0000 1.0000
49.0000 746.0000 1.0000
49.0400 761.0000 1.0000
49.0800 735.0000 1.0000
49.1200 736.0000 1.0000
49.1600 778.0000 1.0000
49.2000 751.0000 1.0000
49.2400 782.0000 1.0000
49.2800 737.0000 1.0000
49.3200 757.0000 1.0000
49.3600 774.0000 1.0000
49.4000 729.0000 1.0000
49.4400 775.0000 1.0000
49.4800 799.0000 1.0000
49.5200 757.0000 1.0000
49.5600 726.0000 1.0000
49.6000 748.0000 1.0000
49.6400 730.0000 1.0000
49.6800 768.0000 1.0000
49.7200 735.0000 1.0000
49.7600 718.0000 1.0000
49.8000 757.0000 1.0000
49.8400 742.0000 1.0000
49.8800 784.0000 1.0000
49.9200 752.0000 1.0000
49.9600 747.0000 1.0000
50.0000 768.0000 1.0000
50.0400 768.0000 1.0000
50.0800 812.0000 1.0000
50.1200 773.0000 1.0000
50.1600 777.0000 1.0000
50.2000 816.0000 1.0000
50.2400 747.0000 1.0000
50.2800 785.0000 1.0000
50.3200 772.0000 1.0000
50.3600 795.0000 1.0000
50.4000 782.0000 1.0000
50.4400 785.0000 1.0000
50.4800 793.0000 1.0000
50.5200 759.0000 1.0000
50.5600 766.0000 1.0000
50.6000 790.0000 1.0000
50.6400 777.0000 1.0000
50.6800 765.0000 1.0000
50.7200 829.0000 1.0000
50.7600 800.0000 1.0000
50.8000 797.0000 1.0000
50.8400 735.0000 1.0000
50.8800 781.0000 1.0000
50.9200 753.0000 1.0000
50.9600 804.0000 1.0000
51.0000 748.0000 1.0000
51.0400 752.0000 1.0000
51.0800 720.0000 1.0000
51.1200 781.0000 1.0000
51.1600 793.0000 1.0000
51.2000 784.0000 1.0000
51.2400 785.0000 1.0000
51.2800 785.0000 1.0000
51.3200 772.0000 1.0000
51.3600 761.0000 1.0000
51.4000 787.0000 1.0000
51.4400 787.0000 1.0000
51.4800 799.0000 1.0000
51.5200 822.0000 1.0000
51.5600 759.0000 1.0000
51.6000 830.0000 1.0000
51.6400 795.0000 1.0000
51.6800 799.0000 1.0000
51.7200 771.0000 1.0000
51.7600 829.0000 1.0000
51.8000 843.0000 1.0000
51.8400 857.0000 1.0000
51.8800 918.0000 1.0000
51.9200 972.0000 1.0000
51.9600 1139.0000 1.0000
52.0000 1213.0000 1.0000
52.0400 1396.0000 1.0000
52.0800 1616.0000 1.0000
52.1200 2112.0000 1.0000
52.1600 2741.0000 1.0000
52.2000 3673.0000 1.0000
52.2400 4813.0000 1.0000
52.2800 5161.0000 1.0000
52.3200 4636.0000 1.0000
52.3600 4106.0000 1.0000
52.4000 3792.0000 1.0000
52.4400 3144.0000 1.0000
52.4800 2474.0000 1.0000
52.5200 1912.0000 1.0000
52.5600 1563.0000 1.0000
52.6000 1338.0000 1.0000
52.6400 1143.0000 1.0000
52.6800 1049.0000 1.0000
52.7200 1003.0000 1.0000
52.7600 962.0000 1.0000
52.8000 859.0000 1.0000
52.8400 855.0000 1.0000
52.8800 872.0000 1.0000
52.9200 840.0000 1.0000
52.9600 816.0000 1.0000
53.0000 841.0000 1.0000
53.0400 783.0000 1.0000
53.0800 778.0000 1.0000
53.1200 805.0000 1.0000
53.1600 790.0000 1.0000
53.2000 811.0000 1.0000
53.2400 780.0000 1.0000
53.2800 801.0000 1.0000
53.3200 747.0000 1.0000
53.3600 787.0000 1.0000
53.4000 770.0000 1.0000
53.4400 733.0000 1.0000
53.4800 771.0000 1.0000
53.5200 783.0000 1.0000
53.5600 759.0000 1.0000
53.6000 732.0000 1.0000
53.6400 774.0000 1.0000
53.6800 769.0000 1.0000
53.7200 754.0000 1.0000
53.7600 685.0000 1.0000
53.8000 773.0000 1.0000
53.8400 776.0000 1.0000
53.8800 736.0000 1.0000
53.9200 739.0000 1.0000
53.9600 756.0000 1.0000
54.0000 722.0000 1.0000
54.0400 695.0000 1.0000
54.0800 728.0000 1.0000
54.1200 714.0000 1.0000
54.1600 742.0000 1.0000
54.2000 730.0000 1.0000
54.2400 780.0000 1.0000
54.2800 756.0000 1.0000
54.3200 792.0000 1.0000
54.3600 720.0000 1.0000
54.4000 748.0000 1.0000
54.4400 734.0000 1.0000
54.4800 755.0000 1.0000
54.5200 770.0000 1.0000
54.5600 742.0000 1.0000
54.6000 755.0000 1.0000
54.6400 790.0000 1.0000
54.6800 765.0000 1.0000
54.7200 782.0000 1.0000
54.7600 769.0000 1.0000
54.8000 822.0000 1.0000
54.8400 818.0000 1.0000
54.8800 793.0000 1.0000
54.9200 825.0000 1.0000
54.9600 818.0000 1.0000
55.0000 805.0000 1.0000
55.0400 802.0000 1.0000
55.0800 847.0000 1.0000
55.1200 860.0000 1.0000
55.1600 976.0000 1.0000
55.2000 968.0000 1.0000
55.2400 1086.0000 1.0000
55.2800 1131.0000 1.0000
55.3200 1121.0000 1.0000
55.3600 1104.0000 1.0000
55.4000 1067.0000 1.0000
55.4400 981.0000 1.0000
55.4800 999.0000 1.0000
55.5200 864.0000 1.0000
55.5600 847.0000 1.0000
55.6000 843.0000 1.0000
55.6400 767.0000 1.0000
55.6800 819.0000 1.0000
55.7200 771.0000 1.0000
55.7600 748.0000 1.0000
55.8000 776.0000 1.0000
55.8400 777.0000 1.0000
55.8800 746.0000 1.0000
55.9200 752.0000 1.0000
55.9600 690.0000 1.0000
56.0000 761.0000 1.0000
56.0400 758.0000 1.0000
56.0800 752.0000 1.0000
56.1200 738.0000 1.0000
56.1600 711.0000 1.0000
56.2000 719.0000 1.0000
56.2400 736.0000 1.0000
56.2800 734.0000 1.0000
56.3200 754.0000 1.0000
56.3600 699.0000 1.0000
56.4000 710.0000 1.0000
56.4400 705.0000 1.0000
56.4800 713.0000 1.0000
56.5200 692.0000 1.0000
56.5600 710.0000 1.0000
56.6000 746.0000 1.0000
56.6400 748.0000 1.0000
56.6800 710.0000 1.0000
56.7200 729.0000 1.0000
56.7600 719.0000 1.0000
56.8000 734.0000 1.0000
56.8400 757.0000 1.0000
56.8800 683.0000 1.0000
56.9200 737.0000 1.0000
56.9600 735.0000 1.0000
57.0000 710.0000 1.0000
57.0400 749.0000 1.0000
57.0800 672.0000 1.0000
57.1200 714.0000 1.0000
57.1600 761.0000 1.0000
57.2000 722.0000 1.0000
57.2400 726.0000 1.0000
57.2800 697.0000 1.0000
57.3200 748.0000 1.0000
57.3600 742.0000 1.0000
57.4000 714.0000 1.0000
57.4400 746.0000 1.0000
57.4800 687.0000 1.0000
57.5200 661.0000 1.0000
57.5600 705.0000 1.0000
57.6000 717.0000 1.0000
57.6400 730.0000 1.0000
57.6800 714.0000 1.0000
57.7200 708.0000 1.0000
57.7600 791.0000 1.0000
57.8000 706.0000 1.0000
57.8400 726.0000 1.0000
57.8800 707.0000 1.0000
57.9200 721.0000 1.0000
57.9600 700.0000 1.0000
58.0000 734.0000 1.0000
58.0400 739.0000 1.0000
58.0800 711.0000 1.0000
58.1200 786.0000 1.0000
58.1600 756.0000 1.0000
58.2000 713.0000 1.0000
58.2400 734.0000 1.0000
58.2800 758.0000 1.0000
58.3200 736.0000 1.0000
58.3600 714.0000 1.0000
58.4000 736.0000 1.0000
58.4400 761.0000 1.0000
58.4800 703.0000 1.0000
58.5200 745.0000 1.0000
58.5600 677.0000 1.0000
58.6000 711.0000 1.0000
58.6400 697.0000 1.0000
58.6800 689.0000 1.0000
58.7200 740.0000 1.0000
58.7600 732.0000 1.0000
58.8000 702.0000 1.0000
58.8400 681.0000 1.0000
58.8800 717.0000 1.0000
58.9200 714.0000 1.0000
58.9600 706.0000 1.0000
59.0000 712.0000 1.0000
59.0400 669.0000 1.0000
59.0800 714.0000 1.0000
59.1200 709.0000 1.0000
59.1600 712.0000 1.0000
59.2000 685.0000 1.0000
59.2400 732.0000 1.0000
59.2800 754.0000 1.0000
59.3200 755.0000 1.0000
59.3600 695.0000 1.0000
59.4000 683.0000 1.0000
59.4400 690.0000 1.0000
59.4800 732.0000 1.0000
59.5200 688.0000 1.0000
59.5600 714.0000 1.0000
59.6000 698.0000 1.0000
59.6400 685.0000 1.0000
59.6800 735.0000 1.0000
59.7200 715.0000 1.0000
59.7600 740.0000 1.0000
59.8000 730.0000 1.0000
59.8400 715.0000 1.0000
59.8800 698.0000 1.0000
59.9200 707.0000 1.0000
59.9600 690.0000 1.0000
60.0000 718.0000 1.0000
60.0400 720.0000 1.0000
60.0800 713.0000 1.0000
60.1200 673.0000 1.0000
60.1600 715.0000 1.0000
60.2000 719.0000 1.0000
60.2400 747.0000 1.0000
60.2800 707.0000 1.0000
60.3200 692.0000 1.0000
60.3600 721.0000 1.0000
60.4000 722.0000 1.0000
60.4400 724.0000 1.0000
60.4800 686.0000 1.0000
60.5200 711.0000 1.0000
60.5600 745.0000 1.0000
60.6000 706.0000 1.0000
60.6400 684.0000 1.0000
60.6800 696.0000 1.0000
60.7200 708.0000 1.0000
60.7600 713.0000 1.0000
60.8000 666.0000 1.0000
60.8400 685.0000 1.0000
60.8800 731.0000 1.0000
60.9200 707.0000 1.0000
60.9600 711.0000 1.0000
61.0000 701.0000 1.0000
61.0400 747.0000 1.0000
61.0800 723.0000 1.0000
61.1200 712.0000 1.0000
61.1600 719.0000 1.0000
61.2000 681.0000 1.0000
61.2400 696.0000 1.0000
61.2800 742.0000 1.0000
61.3200 724.0000 1.0000
61.3600 671.0000 1.0000
61.4000 727.0000 1.0000
61.4400 660.0000 1.0000
61.4800 702.0000 1.0000
61.5200 711.0000 1.0000
61.5600 731.0000 1.0000
61.6000 707.0000 1.0000
61.6400 732.0000 1.0000
61.6800 767.0000 1.0000
61.7200 788.0000 1.0000
61.7600 768.0000 1.0000
61.8000 800.0000 1.0000
61.8400 776.0000 1.0000
61.8800 824.0000 1.0000
61.9200 870.0000 1.0000
61.9600 871.0000 1.0000
62.0000 932.0000 1.0000
62.0400 980.0000 1.0000
62.0800 1093.0000 1.0000
62.1200 1207.0000 1.0000
62.1600 1359.0000 1.0000
62.2000 1434.0000 1.0000
62.2400 1561.0000 1.0000
62.2800 1699.0000 1.0000
62.3200 1731.0000 1.0000
62.3600 1728.0000 1.0000
62.4000 1650.0000 1.0000
62.4400 1571.0000 1.0000
62.4800 1476.0000 1.0000
62.5200 1334.0000 1.0000
62.5600 1262.0000 1.0000
62.6000 1109.0000 1.0000
62.6400 1066.0000 1.0000
62.6800 1006.0000 1.0000
62.7200 915.0000 1.0000
62.7600 888.0000 1.0000
62.8000 811.0000 1.0000
62.8400 790.0000 1.0000
62.8800 823.0000 1.0000
62.9200 833.0000 1.0000
62.9600 800.0000 1.0000
63.0000 817.0000 1.0000
63.0400 789.0000 1.0000
63.0800 773.0000 1.0000
63.1200 801.0000 1.0000
63.1600 805.0000 1.0000
63.2000 775.0000 1.0000
63.2400 757.0000 1.0000
63.2800 761.0000 1.0000
63.3200 756.0000 1.0000
63.3600 737.0000 1.0000
63.4000 715.0000 1.0000
63.4400 725.0000 1.0000
63.4800 662.0000 1.0000
63.5200 686.0000 1.0000
63.5600 721.0000 1.0000
63.6000 691.0000 1.0000
63.6400 738.0000 1.0000
63.6800 754.0000 1.0000
63.7200 702.0000 1.0000
63.7600 735.0000 1.0000
63.8000 707.0000 1.0000
63.8400 712.0000 1.0000
63.8800 715.0000 1.0000
63.9200 695.0000 1.0000
63.9600 711.0000 1.0000
64.0000 687.0000 1.0000
64.0400 726.0000 1.0000
64.0800 721.0000 1.0000
64.1200 731.0000 1.0000
64.1600 717.0000 1.0000
64.2000 745.0000 1.0000
64.2400 721.0000 1.0000
64.2800 760.0000 1.0000
64.3200 720.0000 1.0000
64.3600 753.0000 1.0000
64.4000 736.0000 1.0000
64.4400 759.0000 1.0000
64.4800 746.0000 1.0000
64.5200 802.0000 1.0000
64.5600 791.0000 1.0000
64.6000 877.0000 1.0000
64.6400 954.0000 1.0000
64.6800 972.0000 1.0000
64.7200 903.0000 1.0000
64.7600 907.0000 1.0000
64.8000 922.0000 1.0000
64.8400 952.0000 1.0000
64.8800 902.0000 1.0000
64.9200 810.0000 1.0000
64.9600 769.0000 1.0000
65.0000 759.0000 1.0000
65.0400 757.0000 1.0000
65.0800 782.0000 1.0000
65.1200 707.0000 1.0000
65.1600 725.0000 1.0000
65.2000 770.0000 1.0000
65.2400 679.0000 1.0000
65.2800 747.0000 1.0000
65.3200 793.0000 1.0000
65.3600 752.0000 1.0000
65.4000 706.0000 1.0000
65.4400 700.0000 1.0000
65.4800 729.0000 1.0000
65.5200 719.0000 1.0000
65.5600 738.0000 1.0000
65.6000 707.0000 1.0000
65.6400 758.0000 1.0000
65.6800 780.0000 1.0000
65.7200 772.0000 1.0000
65.7600 817.0000 1.0000
65.8000 829.0000 1.0000
65.8400 860.0000 1.0000
65.8800 889.0000 1.0000
65.9200 929.0000 1.0000
65.9600 954.0000 1.0000
66.0000 1040.0000 1.0000
66.0400 1207.0000 1.0000
66.0800 1394.0000 1.0000
66.1200 1586.0000 1.0000
66.1600 2004.0000 1.0000
66.2000 2384.0000 1.0000
66.2400 2748.0000 1.0000
66.2800 2864.0000 1.0000
66.3200 2711.0000 1.0000
66.3600 2518.0000 1.0000
66.4000 2302.0000 1.0000
66.4400 2264.0000 1.0000
66.4800 1975.0000 1.0000
66.5200 1689.0000 1.0000
66.5600 1452.0000 1.0000
66.6000 1279.0000 1.0000
66.6400 1096.0000 1.0000
66.6800 1040.0000 1.0000
66.7200 959.0000 1.0000
66.7600 902.0000 1.0000
66.8000 847.0000 1.0000
66.8400 813.0000 1.0000
66.8800 806.0000 1.0000
66.9200 740.0000 1.0000
66.9600 726.0000 1.0000
67.0000 750.0000 1.0000
67.0400 706.0000 1.0000
67.0800 736.0000 1.0000
67.1200 709.0000 1.0000
67.1600 698.0000 1.0000
67.2000 732.0000 1.0000
67.2400 681.0000 1.0000
67.2800 677.0000 1.0000
67.3200 704.0000 1.0000
67.3600 695.0000 1.0000
67.4000 704.0000 1.0000
67.4400 680.0000 1.0000
67.4800 692.0000 1.0000
67.5200 665.0000 1.0000
67.5600 684.0000 1.0000
67.6000 657.0000 1.0000
67.6400 665.0000 1.0000
67.6800 636.0000 1.0000
67.7200 703.0000 1.0000
67.7600 639.0000 1.0000
67.8000 651.0000 1.0000
67.8400 677.0000 1.0000
67.8800 663.0000 1.0000
67.9200 657.0000 1.0000
67.9600 688.0000 1.0000
68.0000 692.0000 1.0000
68.0400 671.0000 1.0000
68.0800 633.0000 1.0000
68.1200 635.0000 1.0000
68.1600 648.0000 1.0000
68.2000 683.0000 1.0000
68.2400 611.0000 1.0000
68.2800 636.0000 1.0000
68.3200 677.0000 1.0000
68.3600 623.0000 1.0000
68.4000 616.0000 1.0000
68.4400 644.0000 1.0000
68.4800 632.0000 1.0000
68.5200 620.0000 1.0000
68.5600 623.0000 1.0000
68.6000 641.0000 1.0000
68.6400 615.0000 1.0000
68.6800 662.0000 1.0000
68.7200 595.0000 1.0000
68.7600 632.0000 1.0000
68.8000 664.0000 1.0000
68.8400 632.0000 1.0000
68.8800 619.0000 1.0000
68.9200 634.0000 1.0000
68.9600 645.0000 1.0000
69.0000 626.0000 1.0000
69.0400 656.0000 1.0000
69.0800 628.0000 1.0000
69.1200 628.0000 1.0000
69.1600 659.0000 1.0000
69.2000 615.0000 1.0000
69.2400 613.0000 1.0000
69.2800 641.0000 1.0000
69.3200 632.0000 1.0000
69.3600 595.0000 1.0000
69.4000 626.0000 1.0000
69.4400 659.0000 1.0000
69.4800 588.0000 1.0000
69.5200 626.0000 1.0000
69.5600 615.0000 1.0000
69.6000 633.0000 1.0000
69.6400 612.0000 1.0000
69.6800 615.0000 1.0000
69.7200 619.0000 1.0000
69.7600 632.0000 1.0000
69.8000 632.0000 1.0000
69.8400 608.0000 1.0000
69.8800 620.0000 1.0000
69.9200 651.0000 1.0000
69.9600 608.0000 1.0000
70.0000 626.0000 1.0000
*RAS_INT_END
*RAS_TEMPERATURE_START
*RAS_TEMPERATURE_END
*RAS_DATA_END