File: Data/Dataset1_Only_water/5_XRD/No_007_FS2_3.ras
*RAS_DATA_START
*RAS_HEADER_START
*DISP_FMT_X "%.2f"
*DISP_FMT_Y "%.0f"
*DISP_FULLSCALE "14536.0000000000"
*DISP_LINE_COLOR "255.0000000000"
*DISP_LINE_STYLE "0.0000000000"
*DISP_LINE_WIDTH "0.2500000000"
*DISP_NOTE "測定データ-4"
*DISP_OFFSET_Y "0.0000000000"
*DISP_PEAKSEARCH_UNIT_Y "cps"
*DISP_RANGE_BOTTOM "0.0000000000"
*DISP_RANGE_LEFT "20.0000000000"
*DISP_RANGE_LOGCUTOFF "0.0100000000"
*DISP_RANGE_RIGHT "70.0000000000"
*DISP_RANGE_TOP "14536.0000000000"
*DISP_SCALE_MODE_Y "0.0000000000"
*DISP_TAB_NAME "2θ/θ"
*DISP_TITLE_Y "強度"
*DISP_UNIT_Y "cps"
*DISP_WINDOW_NAME "MSG_MACROENGINE"
*FILE_COMMENT " "
*FILE_MD5 ""
*FILE_MEMO " "
*FILE_OPERATOR "Administrator"
*FILE_SAMPLE " "
*FILE_TYPE "RAS_RAW"
*FILE_USERGROUP "システムマネージャ"
*FILE_VERSION "1.0000000000"
*HW_ATTACHMENT_ID "ATT0025"
*HW_ATTACHMENT_NAME "標準|Standard"
*HW_COUNTER_ID-0 "CUT0025"
*HW_COUNTER_ID-1 "CUT0020"
*HW_COUNTER_ID-2 "CUT0020"
*HW_COUNTER_ID-3 "CSL0021"
*HW_COUNTER_ID-4 "CMC0021"
*HW_COUNTER_NAME-0 "D/teX Ultra|D/teX Ultra"
*HW_COUNTER_NAME-1 "None|None"
*HW_COUNTER_NAME-2 "None|None"
*HW_COUNTER_NAME-3 "BBM|BBM"
*HW_COUNTER_NAME-4 "検出器モノクロメータ|Detector monochromator"
*HW_COUNTER_SELECT_NAME "D/teX Ultra|D/teX Ultra"
*HW_GONIOMETER_ID "GON0023"
*HW_GONIOMETER_NAME "SmartLab|SmartLab"
*HW_GONIOMETER_RADIUS-0 "90.0"
*HW_GONIOMETER_RADIUS-1 "114.0"
*HW_GONIOMETER_RADIUS-2 "190.0"
*HW_GONIOMETER_RADIUS-3 "300.0"
*HW_GONIOMETER_RADIUS-4 "187.0"
*HW_GONIOMETER_RADIUS-5 "300.0"
*HW_GONIOMETER_RADIUS-6 "113.0"
*HW_GONIOMETER_RADIUS-7 "331.0"
*HW_I_OPT_ID-0 "CBO0021"
*HW_I_OPT_ID-1 "ICR0023"
*HW_I_OPT_ID-2 "ISL0021"
*HW_I_OPT_ID-3 "ISO0021"
*HW_I_OPT_ID-4 "IAD0021"
*HW_I_OPT_ID-5 "IPR0001"
*HW_I_OPT_NAME-0 "CBOユニット|CBO unit"
*HW_I_OPT_NAME-1 "標準入射光学ユニット|Standard incident optical unit"
*HW_I_OPT_NAME-2 "標準入射スリットボックス|Standard incident slit box"
*HW_I_OPT_NAME-3 "入射平行スリット|Incident parallel slit"
*HW_I_OPT_NAME-4 "長手制限スリット|Length limiting slit"
*HW_I_OPT_NAME-5 "None|None"
*HW_R_ATTENUATER_AUTOMODE "0"
*HW_R_OPT_ID-0 "RSS0021"
*HW_R_OPT_ID-1 "RCR0023"
*HW_R_OPT_ID-2 "RSO0021"
*HW_R_OPT_ID-3 "RRS0021"
*HW_R_OPT_ID-4 "ATN0021"
*HW_R_OPT_ID-5 "RFL0021"
*HW_R_OPT_ID-6 "RAD0021"
*HW_R_OPT_NAME-0 "標準受光スリットボックス1|Standard receiving slit box # 1"
*HW_R_OPT_NAME-1 "標準受光光学ユニット1|Standard receiving unit # 1"
*HW_R_OPT_NAME-2 "標準受光光学ユニット2|Standard receiving optical unit # 2"
*HW_R_OPT_NAME-3 "標準受光スリットボックス2|Standard receiving slit box # 2"
*HW_R_OPT_NAME-4 "標準アッテネータ|Standard Attenuator"
*HW_R_OPT_NAME-5 "Cu Kβ|Cu K-beta"
*HW_R_OPT_NAME-6 "調整用受光スリット|Alignment receiving slit"
*HW_SAMPLE_HOLDER_ID "SMP0023"
*HW_SAMPLE_HOLDER_NAME "標準Zステージ|Standard Z stage"
*HW_XG_CURRENT_MAX "50"
*HW_XG_CURRENT_MIN "2"
*HW_XG_CURRENT_RESOLUTION "1"
*HW_XG_CURRENT_UNIT "mA"
*HW_XG_FOCUS "1mm x 10mm"
*HW_XG_FOCUS_TYPE "Normal"
*HW_XG_ID ""
*HW_XG_NAME "3kW 封入管(ID:1200)|3kW Sealed tube(ID:1200)"
*HW_XG_TARGET_ATOMIC_NUMBER "29.0000000000"
*HW_XG_TARGET_NAME "Cu"
*HW_XG_TYPE "Hermetic"
*HW_XG_VOLTAGE_MAX "60"
*HW_XG_VOLTAGE_MIN "20"
*HW_XG_VOLTAGE_RESOLUTION "1"
*HW_XG_VOLTAGE_UNIT "kV"
*HW_XG_WATT_MAX "1.500"
*HW_XG_WATT_UNIT "kW"
*HW_XG_WAVE_LENGTH_ALPHA1 "1.540593"
*HW_XG_WAVE_LENGTH_ALPHA2 "1.544414"
*HW_XG_WAVE_LENGTH_BETA "1.392250"
*MEAS_COND_AXIS_NAME-0 "2θ/θ"
*MEAS_COND_AXIS_NAME-1 "2θ"
*MEAS_COND_AXIS_NAME-2 "ω"
*MEAS_COND_AXIS_NAME-3 "Z"
*MEAS_COND_AXIS_NAME-4 "2θ/ω"
*MEAS_COND_AXIS_NAME-5 "θs"
*MEAS_COND_AXIS_NAME-6 "θd"
*MEAS_COND_AXIS_NAME-7 "Ts"
*MEAS_COND_AXIS_NAME-8 "CBO選択スリット"
*MEAS_COND_AXIS_NAME-9 "M"
*MEAS_COND_AXIS_NAME-10 "入射平行スリット"
*MEAS_COND_AXIS_NAME-11 "入射スリット"
*MEAS_COND_AXIS_NAME-12 ""
*MEAS_COND_AXIS_NAME-13 "Zs"
*MEAS_COND_AXIS_NAME-14 "入射光学素子"
*MEAS_COND_AXIS_NAME-15 "長手制限スリット"
*MEAS_COND_AXIS_NAME-16 "センタースリット"
*MEAS_COND_AXIS_NAME-17 "フィルター"
*MEAS_COND_AXIS_NAME-18 "受光スリット1"
*MEAS_COND_AXIS_NAME-19 "受光スリット2"
*MEAS_COND_AXIS_NAME-20 "受光光学素子"
*MEAS_COND_AXIS_NAME-21 "受光平行スリット"
*MEAS_COND_AXIS_NAME-22 "調整用受光スリット"
*MEAS_COND_AXIS_NAME-23 ""
*MEAS_COND_AXIS_NAME-24 ""
*MEAS_COND_AXIS_NAME-25 "Zd"
*MEAS_COND_AXIS_NAME-26 "アッテネータ"
*MEAS_COND_AXIS_NAME-27 "検出器モノクロメータ"
*MEAS_COND_AXIS_NAME-28 "モノクロメータスリット"
*MEAS_COND_AXIS_NAME-29 "プライマリビーム"
*MEAS_COND_AXIS_NAME-30 "PHA"
*MEAS_COND_AXIS_NAME_INTERNAL-0 "TwoThetaTheta"
*MEAS_COND_AXIS_NAME_INTERNAL-1 "TwoTheta"
*MEAS_COND_AXIS_NAME_INTERNAL-2 "Omega"
*MEAS_COND_AXIS_NAME_INTERNAL-3 "Z"
*MEAS_COND_AXIS_NAME_INTERNAL-4 "TwoThetaOmega"
*MEAS_COND_AXIS_NAME_INTERNAL-5 "ThetaS"
*MEAS_COND_AXIS_NAME_INTERNAL-6 "ThetaD"
*MEAS_COND_AXIS_NAME_INTERNAL-7 "Ts"
*MEAS_COND_AXIS_NAME_INTERNAL-8 "CBO"
*MEAS_COND_AXIS_NAME_INTERNAL-9 "CBO-M"
*MEAS_COND_AXIS_NAME_INTERNAL-10 "IncidentSollerSlit"
*MEAS_COND_AXIS_NAME_INTERNAL-11 "IncidentSlitBox"
*MEAS_COND_AXIS_NAME_INTERNAL-12 "IncidentSlitBox-_Axis"
*MEAS_COND_AXIS_NAME_INTERNAL-13 "Zs"
*MEAS_COND_AXIS_NAME_INTERNAL-14 "IncidentMonochromator"
*MEAS_COND_AXIS_NAME_INTERNAL-15 "IncidentAxdSlit"
*MEAS_COND_AXIS_NAME_INTERNAL-16 "CenterSlit"
*MEAS_COND_AXIS_NAME_INTERNAL-17 "Filter"
*MEAS_COND_AXIS_NAME_INTERNAL-18 "ReceivingSlitBox1"
*MEAS_COND_AXIS_NAME_INTERNAL-19 "ReceivingSlitBox2"
*MEAS_COND_AXIS_NAME_INTERNAL-20 "ReceivingOptics"
*MEAS_COND_AXIS_NAME_INTERNAL-21 "ReceivingSollerSlit"
*MEAS_COND_AXIS_NAME_INTERNAL-22 "ReceivingAxdSlit"
*MEAS_COND_AXIS_NAME_INTERNAL-23 "ReceivingSlitBox1-_Axis"
*MEAS_COND_AXIS_NAME_INTERNAL-24 "ReceivingSlitBox2-_Axis"
*MEAS_COND_AXIS_NAME_INTERNAL-25 "ReceivingSlitBox2-Zd"
*MEAS_COND_AXIS_NAME_INTERNAL-26 "Attenuator"
*MEAS_COND_AXIS_NAME_INTERNAL-27 "CounterMonochromator"
*MEAS_COND_AXIS_NAME_INTERNAL-28 "CounterSlit"
*MEAS_COND_AXIS_NAME_INTERNAL-29 "IncidentPrimary"
*MEAS_COND_AXIS_NAME_INTERNAL-30 "PHA"
*MEAS_COND_AXIS_NAME_MAGICNO-0 "83951616.0000000000"
*MEAS_COND_AXIS_NAME_MAGICNO-1 "268632064.0000000000"
*MEAS_COND_AXIS_NAME_MAGICNO-2 "268500992.0000000000"
*MEAS_COND_AXIS_NAME_MAGICNO-3 "285278208.0000000000"
*MEAS_COND_AXIS_NAME_MAGICNO-4 "83951616.0000000000"
*MEAS_COND_AXIS_NAME_MAGICNO-5 "131072.0000000000"
*MEAS_COND_AXIS_NAME_MAGICNO-6 "131072.0000000000"
*MEAS_COND_AXIS_NAME_MAGICNO-7 "318898176.0000000000"
*MEAS_COND_AXIS_NAME_MAGICNO-8 "20971521.0000000000"
*MEAS_COND_AXIS_NAME_MAGICNO-9 "285343744.0000000000"
*MEAS_COND_AXIS_NAME_MAGICNO-10 "20971521.0000000000"
*MEAS_COND_AXIS_NAME_MAGICNO-11 "22020097.0000000000"
*MEAS_COND_AXIS_NAME_MAGICNO-12 "25165824.0000000000"
*MEAS_COND_AXIS_NAME_MAGICNO-13 "318898176.0000000000"
*MEAS_COND_AXIS_NAME_MAGICNO-14 "1.0000000000"
*MEAS_COND_AXIS_NAME_MAGICNO-15 "20971521.0000000000"
*MEAS_COND_AXIS_NAME_MAGICNO-16 "20971521.0000000000"
*MEAS_COND_AXIS_NAME_MAGICNO-17 "20971521.0000000000"
*MEAS_COND_AXIS_NAME_MAGICNO-18 "23068673.0000000000"
*MEAS_COND_AXIS_NAME_MAGICNO-19 "23068673.0000000000"
*MEAS_COND_AXIS_NAME_MAGICNO-20 "20971521.0000000000"
*MEAS_COND_AXIS_NAME_MAGICNO-21 "20971521.0000000000"
*MEAS_COND_AXIS_NAME_MAGICNO-22 "20971521.0000000000"
*MEAS_COND_AXIS_NAME_MAGICNO-23 "25165824.0000000000"
*MEAS_COND_AXIS_NAME_MAGICNO-24 "25165824.0000000000"
*MEAS_COND_AXIS_NAME_MAGICNO-25 "285343744.0000000000"
*MEAS_COND_AXIS_NAME_MAGICNO-26 "17301505.0000000000"
*MEAS_COND_AXIS_NAME_MAGICNO-27 "20971521.0000000000"
*MEAS_COND_AXIS_NAME_MAGICNO-28 "20971521.0000000000"
*MEAS_COND_AXIS_NAME_MAGICNO-29 "20971521.0000000000"
*MEAS_COND_AXIS_NAME_MAGICNO-30 "0.0000000000"
*MEAS_COND_AXIS_OFFSET-0 "-"
*MEAS_COND_AXIS_OFFSET-1 "-0.1081000000"
*MEAS_COND_AXIS_OFFSET-2 "0.3758000000"
*MEAS_COND_AXIS_OFFSET-3 "-"
*MEAS_COND_AXIS_OFFSET-4 "-"
*MEAS_COND_AXIS_OFFSET-5 "0.3758000000"
*MEAS_COND_AXIS_OFFSET-6 "-0.4839000000"
*MEAS_COND_AXIS_OFFSET-7 "-"
*MEAS_COND_AXIS_OFFSET-8 "-"
*MEAS_COND_AXIS_OFFSET-9 "-"
*MEAS_COND_AXIS_OFFSET-10 "-"
*MEAS_COND_AXIS_OFFSET-11 "-"
*MEAS_COND_AXIS_OFFSET-12 "-"
*MEAS_COND_AXIS_OFFSET-13 "-"
*MEAS_COND_AXIS_OFFSET-14 "-"
*MEAS_COND_AXIS_OFFSET-15 "-"
*MEAS_COND_AXIS_OFFSET-16 "-"
*MEAS_COND_AXIS_OFFSET-17 "-"
*MEAS_COND_AXIS_OFFSET-18 "-"
*MEAS_COND_AXIS_OFFSET-19 "-"
*MEAS_COND_AXIS_OFFSET-20 "-"
*MEAS_COND_AXIS_OFFSET-21 "-"
*MEAS_COND_AXIS_OFFSET-22 "-"
*MEAS_COND_AXIS_OFFSET-23 "-"
*MEAS_COND_AXIS_OFFSET-24 "-"
*MEAS_COND_AXIS_OFFSET-25 "-"
*MEAS_COND_AXIS_OFFSET-26 "-"
*MEAS_COND_AXIS_OFFSET-27 "-"
*MEAS_COND_AXIS_OFFSET-28 "-"
*MEAS_COND_AXIS_OFFSET-29 "-"
*MEAS_COND_AXIS_OFFSET-30 "-"
*MEAS_COND_AXIS_POSITION-0 "0.0000000000"
*MEAS_COND_AXIS_POSITION-1 "0.0000000000"
*MEAS_COND_AXIS_POSITION-2 "0.0000000000"
*MEAS_COND_AXIS_POSITION-3 "-0.5500000000"
*MEAS_COND_AXIS_POSITION-4 "0.0000000000"
*MEAS_COND_AXIS_POSITION-5 "0.0000000000"
*MEAS_COND_AXIS_POSITION-6 "0.0000000000"
*MEAS_COND_AXIS_POSITION-7 "-0.4278800000"
*MEAS_COND_AXIS_POSITION-8 "BB"
*MEAS_COND_AXIS_POSITION-9 "0.0000000000"
*MEAS_COND_AXIS_POSITION-10 "Soller_slit_5.0deg"
*MEAS_COND_AXIS_POSITION-11 "2/3deg"
*MEAS_COND_AXIS_POSITION-12 "2.2088000000"
*MEAS_COND_AXIS_POSITION-13 "-0.4140600000"
*MEAS_COND_AXIS_POSITION-14 "0.0000000000"
*MEAS_COND_AXIS_POSITION-15 "10.0mm"
*MEAS_COND_AXIS_POSITION-16 "None"
*MEAS_COND_AXIS_POSITION-17 "Cu_K-beta"
*MEAS_COND_AXIS_POSITION-18 "13.000mm"
*MEAS_COND_AXIS_POSITION-19 "13.000mm"
*MEAS_COND_AXIS_POSITION-20 "No_unit"
*MEAS_COND_AXIS_POSITION-21 "Soller_slit_5.0deg"
*MEAS_COND_AXIS_POSITION-22 "None"
*MEAS_COND_AXIS_POSITION-23 "13.0000000000"
*MEAS_COND_AXIS_POSITION-24 "13.0000000000"
*MEAS_COND_AXIS_POSITION-25 "0.0109400000"
*MEAS_COND_AXIS_POSITION-26 "Open"
*MEAS_COND_AXIS_POSITION-27 "None"
*MEAS_COND_AXIS_POSITION-28 "None"
*MEAS_COND_AXIS_POSITION-29 "None"
*MEAS_COND_AXIS_POSITION-30 "38.0000000000"
*MEAS_COND_AXIS_UNIT-0 "deg"
*MEAS_COND_AXIS_UNIT-1 "deg"
*MEAS_COND_AXIS_UNIT-2 "deg"
*MEAS_COND_AXIS_UNIT-3 "mm"
*MEAS_COND_AXIS_UNIT-4 "deg"
*MEAS_COND_AXIS_UNIT-5 "deg"
*MEAS_COND_AXIS_UNIT-6 "deg"
*MEAS_COND_AXIS_UNIT-7 "mm"
*MEAS_COND_AXIS_UNIT-8 ""
*MEAS_COND_AXIS_UNIT-9 "pulse"
*MEAS_COND_AXIS_UNIT-10 ""
*MEAS_COND_AXIS_UNIT-11 ""
*MEAS_COND_AXIS_UNIT-12 "mm"
*MEAS_COND_AXIS_UNIT-13 "mm"
*MEAS_COND_AXIS_UNIT-14 ""
*MEAS_COND_AXIS_UNIT-15 ""
*MEAS_COND_AXIS_UNIT-16 ""
*MEAS_COND_AXIS_UNIT-17 ""
*MEAS_COND_AXIS_UNIT-18 ""
*MEAS_COND_AXIS_UNIT-19 ""
*MEAS_COND_AXIS_UNIT-20 ""
*MEAS_COND_AXIS_UNIT-21 ""
*MEAS_COND_AXIS_UNIT-22 ""
*MEAS_COND_AXIS_UNIT-23 "mm"
*MEAS_COND_AXIS_UNIT-24 "mm"
*MEAS_COND_AXIS_UNIT-25 "mm"
*MEAS_COND_AXIS_UNIT-26 ""
*MEAS_COND_AXIS_UNIT-27 ""
*MEAS_COND_AXIS_UNIT-28 ""
*MEAS_COND_AXIS_UNIT-29 ""
*MEAS_COND_AXIS_UNIT-30 "div"
*MEAS_COND_COUNTER_CNTLOSS_CORR "0.0000000000"
*MEAS_COND_COUNTER_PHABASE "38.0000000000"
*MEAS_COND_COUNTER_PHAWINDOW "16.0000000000"
*MEAS_COND_COUNTER_PHA_UNIT "div"
*MEAS_COND_COUNTER_TAUDIFF "30.0000000000"
*MEAS_COND_COUNTER_TAUINT "0.0000000000"
*MEAS_COND_IRRADIATION_MODE "OFF"
*MEAS_COND_IRRADIATION_WIDTH ""
*MEAS_COND_OPT_ATTR "集中法"
*MEAS_COND_OPT_NAME "@集中法"
*MEAS_COND_UNSYMMETRIC_MODE "OFF"
*MEAS_COND_XG_CURRENT "30.0000000000"
*MEAS_COND_XG_VOLTAGE "40.0000000000"
*MEAS_COND_XG_WAVE_TYPE "Ka"
*MEAS_DATA_COUNT "5001.0000000000"
*MEAS_SCAN_AXIS_X "2θ/θ"
*MEAS_SCAN_AXIS_X_INTERNAL "TwoThetaTheta"
*MEAS_SCAN_END_TIME "06/30/21 15:17:49"
*MEAS_SCAN_MODE "CONTINUOUS"
*MEAS_SCAN_MONITOR "0"
*MEAS_SCAN_RESOLUTION_X "0.0002"
*MEAS_SCAN_SPEED "1.0"
*MEAS_SCAN_SPEED_UNIT "deg/min"
*MEAS_SCAN_START "20.0000000000"
*MEAS_SCAN_START_TIME "06/30/21 14:24:56"
*MEAS_SCAN_STEP "0.0100000000"
*MEAS_SCAN_STOP "70.0000000000"
*MEAS_SCAN_UNIT_X "deg"
*MEAS_SCAN_UNIT_Y "counts"
*RAS_HEADER_END
*RAS_INT_START
20.0000 1612.0000 1.0000
20.0400 1582.0000 1.0000
20.0800 1633.0000 1.0000
20.1200 1566.0000 1.0000
20.1600 1588.0000 1.0000
20.2000 1541.0000 1.0000
20.2400 1577.0000 1.0000
20.2800 1548.0000 1.0000
20.3200 1587.0000 1.0000
20.3600 1615.0000 1.0000
20.4000 1544.0000 1.0000
20.4400 1601.0000 1.0000
20.4800 1575.0000 1.0000
20.5200 1575.0000 1.0000
20.5600 1578.0000 1.0000
20.6000 1580.0000 1.0000
20.6400 1592.0000 1.0000
20.6800 1572.0000 1.0000
20.7200 1597.0000 1.0000
20.7600 1588.0000 1.0000
20.8000 1637.0000 1.0000
20.8400 1620.0000 1.0000
20.8800 1609.0000 1.0000
20.9200 1598.0000 1.0000
20.9600 1516.0000 1.0000
21.0000 1543.0000 1.0000
21.0400 1608.0000 1.0000
21.0800 1597.0000 1.0000
21.1200 1587.0000 1.0000
21.1600 1595.0000 1.0000
21.2000 1611.0000 1.0000
21.2400 1585.0000 1.0000
21.2800 1624.0000 1.0000
21.3200 1606.0000 1.0000
21.3600 1524.0000 1.0000
21.4000 1588.0000 1.0000
21.4400 1650.0000 1.0000
21.4800 1634.0000 1.0000
21.5200 1548.0000 1.0000
21.5600 1561.0000 1.0000
21.6000 1540.0000 1.0000
21.6400 1532.0000 1.0000
21.6800 1637.0000 1.0000
21.7200 1597.0000 1.0000
21.7600 1579.0000 1.0000
21.8000 1575.0000 1.0000
21.8400 1604.0000 1.0000
21.8800 1625.0000 1.0000
21.9200 1599.0000 1.0000
21.9600 1620.0000 1.0000
22.0000 1635.0000 1.0000
22.0400 1633.0000 1.0000
22.0800 1579.0000 1.0000
22.1200 1605.0000 1.0000
22.1600 1659.0000 1.0000
22.2000 1628.0000 1.0000
22.2400 1614.0000 1.0000
22.2800 1612.0000 1.0000
22.3200 1561.0000 1.0000
22.3600 1659.0000 1.0000
22.4000 1641.0000 1.0000
22.4400 1592.0000 1.0000
22.4800 1650.0000 1.0000
22.5200 1631.0000 1.0000
22.5600 1612.0000 1.0000
22.6000 1617.0000 1.0000
22.6400 1607.0000 1.0000
22.6800 1589.0000 1.0000
22.7200 1621.0000 1.0000
22.7600 1629.0000 1.0000
22.8000 1648.0000 1.0000
22.8400 1591.0000 1.0000
22.8800 1664.0000 1.0000
22.9200 1606.0000 1.0000
22.9600 1673.0000 1.0000
23.0000 1654.0000 1.0000
23.0400 1603.0000 1.0000
23.0800 1643.0000 1.0000
23.1200 1684.0000 1.0000
23.1600 1633.0000 1.0000
23.2000 1635.0000 1.0000
23.2400 1578.0000 1.0000
23.2800 1659.0000 1.0000
23.3200 1624.0000 1.0000
23.3600 1659.0000 1.0000
23.4000 1584.0000 1.0000
23.4400 1638.0000 1.0000
23.4800 1605.0000 1.0000
23.5200 1659.0000 1.0000
23.5600 1675.0000 1.0000
23.6000 1682.0000 1.0000
23.6400 1697.0000 1.0000
23.6800 1640.0000 1.0000
23.7200 1640.0000 1.0000
23.7600 1637.0000 1.0000
23.8000 1639.0000 1.0000
23.8400 1651.0000 1.0000
23.8800 1641.0000 1.0000
23.9200 1677.0000 1.0000
23.9600 1668.0000 1.0000
24.0000 1636.0000 1.0000
24.0400 1640.0000 1.0000
24.0800 1622.0000 1.0000
24.1200 1646.0000 1.0000
24.1600 1660.0000 1.0000
24.2000 1657.0000 1.0000
24.2400 1685.0000 1.0000
24.2800 1700.0000 1.0000
24.3200 1673.0000 1.0000
24.3600 1653.0000 1.0000
24.4000 1654.0000 1.0000
24.4400 1651.0000 1.0000
24.4800 1722.0000 1.0000
24.5200 1696.0000 1.0000
24.5600 1657.0000 1.0000
24.6000 1689.0000 1.0000
24.6400 1693.0000 1.0000
24.6800 1681.0000 1.0000
24.7200 1631.0000 1.0000
24.7600 1731.0000 1.0000
24.8000 1673.0000 1.0000
24.8400 1664.0000 1.0000
24.8800 1674.0000 1.0000
24.9200 1689.0000 1.0000
24.9600 1734.0000 1.0000
25.0000 1745.0000 1.0000
25.0400 1766.0000 1.0000
25.0800 1742.0000 1.0000
25.1200 1734.0000 1.0000
25.1600 1812.0000 1.0000
25.2000 1771.0000 1.0000
25.2400 1693.0000 1.0000
25.2800 1696.0000 1.0000
25.3200 1764.0000 1.0000
25.3600 1735.0000 1.0000
25.4000 1748.0000 1.0000
25.4400 1711.0000 1.0000
25.4800 1684.0000 1.0000
25.5200 1647.0000 1.0000
25.5600 1699.0000 1.0000
25.6000 1736.0000 1.0000
25.6400 1704.0000 1.0000
25.6800 1664.0000 1.0000
25.7200 1672.0000 1.0000
25.7600 1647.0000 1.0000
25.8000 1670.0000 1.0000
25.8400 1691.0000 1.0000
25.8800 1708.0000 1.0000
25.9200 1669.0000 1.0000
25.9600 1633.0000 1.0000
26.0000 1783.0000 1.0000
26.0400 1726.0000 1.0000
26.0800 1723.0000 1.0000
26.1200 1733.0000 1.0000
26.1600 1684.0000 1.0000
26.2000 1718.0000 1.0000
26.2400 1682.0000 1.0000
26.2800 1763.0000 1.0000
26.3200 1709.0000 1.0000
26.3600 1783.0000 1.0000
26.4000 1787.0000 1.0000
26.4400 1804.0000 1.0000
26.4800 1751.0000 1.0000
26.5200 1763.0000 1.0000
26.5600 1775.0000 1.0000
26.6000 1876.0000 1.0000
26.6400 1804.0000 1.0000
26.6800 1797.0000 1.0000
26.7200 1890.0000 1.0000
26.7600 1844.0000 1.0000
26.8000 1795.0000 1.0000
26.8400 1900.0000 1.0000
26.8800 1906.0000 1.0000
26.9200 1985.0000 1.0000
26.9600 2056.0000 1.0000
27.0000 2266.0000 1.0000
27.0400 2411.0000 1.0000
27.0800 2556.0000 1.0000
27.1200 2769.0000 1.0000
27.1600 3099.0000 1.0000
27.2000 3769.0000 1.0000
27.2400 4506.0000 1.0000
27.2800 5364.0000 1.0000
27.3200 6052.0000 1.0000
27.3600 6443.0000 1.0000
27.4000 6003.0000 1.0000
27.4400 5078.0000 1.0000
27.4800 4151.0000 1.0000
27.5200 3344.0000 1.0000
27.5600 2924.0000 1.0000
27.6000 2701.0000 1.0000
27.6400 2437.0000 1.0000
27.6800 2259.0000 1.0000
27.7200 2055.0000 1.0000
27.7600 2041.0000 1.0000
27.8000 2018.0000 1.0000
27.8400 1894.0000 1.0000
27.8800 1877.0000 1.0000
27.9200 1869.0000 1.0000
27.9600 1907.0000 1.0000
28.0000 1748.0000 1.0000
28.0400 1761.0000 1.0000
28.0800 1809.0000 1.0000
28.1200 1733.0000 1.0000
28.1600 1790.0000 1.0000
28.2000 1724.0000 1.0000
28.2400 1713.0000 1.0000
28.2800 1734.0000 1.0000
28.3200 1736.0000 1.0000
28.3600 1645.0000 1.0000
28.4000 1704.0000 1.0000
28.4400 1612.0000 1.0000
28.4800 1687.0000 1.0000
28.5200 1678.0000 1.0000
28.5600 1702.0000 1.0000
28.6000 1719.0000 1.0000
28.6400 1707.0000 1.0000
28.6800 1690.0000 1.0000
28.7200 1613.0000 1.0000
28.7600 1655.0000 1.0000
28.8000 1685.0000 1.0000
28.8400 1621.0000 1.0000
28.8800 1663.0000 1.0000
28.9200 1636.0000 1.0000
28.9600 1654.0000 1.0000
29.0000 1644.0000 1.0000
29.0400 1644.0000 1.0000
29.0800 1554.0000 1.0000
29.1200 1676.0000 1.0000
29.1600 1633.0000 1.0000
29.2000 1656.0000 1.0000
29.2400 1662.0000 1.0000
29.2800 1536.0000 1.0000
29.3200 1577.0000 1.0000
29.3600 1633.0000 1.0000
29.4000 1663.0000 1.0000
29.4400 1558.0000 1.0000
29.4800 1549.0000 1.0000
29.5200 1596.0000 1.0000
29.5600 1610.0000 1.0000
29.6000 1621.0000 1.0000
29.6400 1622.0000 1.0000
29.6800 1629.0000 1.0000
29.7200 1601.0000 1.0000
29.7600 1540.0000 1.0000
29.8000 1586.0000 1.0000
29.8400 1505.0000 1.0000
29.8800 1555.0000 1.0000
29.9200 1557.0000 1.0000
29.9600 1533.0000 1.0000
30.0000 1532.0000 1.0000
30.0400 1551.0000 1.0000
30.0800 1559.0000 1.0000
30.1200 1580.0000 1.0000
30.1600 1579.0000 1.0000
30.2000 1580.0000 1.0000
30.2400 1550.0000 1.0000
30.2800 1539.0000 1.0000
30.3200 1522.0000 1.0000
30.3600 1472.0000 1.0000
30.4000 1598.0000 1.0000
30.4400 1491.0000 1.0000
30.4800 1549.0000 1.0000
30.5200 1580.0000 1.0000
30.5600 1562.0000 1.0000
30.6000 1541.0000 1.0000
30.6400 1473.0000 1.0000
30.6800 1509.0000 1.0000
30.7200 1592.0000 1.0000
30.7600 1550.0000 1.0000
30.8000 1545.0000 1.0000
30.8400 1479.0000 1.0000
30.8800 1487.0000 1.0000
30.9200 1465.0000 1.0000
30.9600 1503.0000 1.0000
31.0000 1461.0000 1.0000
31.0400 1501.0000 1.0000
31.0800 1451.0000 1.0000
31.1200 1516.0000 1.0000
31.1600 1567.0000 1.0000
31.2000 1519.0000 1.0000
31.2400 1449.0000 1.0000
31.2800 1518.0000 1.0000
31.3200 1466.0000 1.0000
31.3600 1456.0000 1.0000
31.4000 1458.0000 1.0000
31.4400 1504.0000 1.0000
31.4800 1450.0000 1.0000
31.5200 1468.0000 1.0000
31.5600 1490.0000 1.0000
31.6000 1442.0000 1.0000
31.6400 1414.0000 1.0000
31.6800 1476.0000 1.0000
31.7200 1434.0000 1.0000
31.7600 1464.0000 1.0000
31.8000 1439.0000 1.0000
31.8400 1448.0000 1.0000
31.8800 1447.0000 1.0000
31.9200 1460.0000 1.0000
31.9600 1454.0000 1.0000
32.0000 1512.0000 1.0000
32.0400 1473.0000 1.0000
32.0800 1526.0000 1.0000
32.1200 1482.0000 1.0000
32.1600 1459.0000 1.0000
32.2000 1474.0000 1.0000
32.2400 1456.0000 1.0000
32.2800 1448.0000 1.0000
32.3200 1449.0000 1.0000
32.3600 1485.0000 1.0000
32.4000 1416.0000 1.0000
32.4400 1443.0000 1.0000
32.4800 1405.0000 1.0000
32.5200 1387.0000 1.0000
32.5600 1377.0000 1.0000
32.6000 1345.0000 1.0000
32.6400 1415.0000 1.0000
32.6800 1409.0000 1.0000
32.7200 1469.0000 1.0000
32.7600 1407.0000 1.0000
32.8000 1401.0000 1.0000
32.8400 1440.0000 1.0000
32.8800 1400.0000 1.0000
32.9200 1412.0000 1.0000
32.9600 1380.0000 1.0000
33.0000 1385.0000 1.0000
33.0400 1441.0000 1.0000
33.0800 1354.0000 1.0000
33.1200 1424.0000 1.0000
33.1600 1333.0000 1.0000
33.2000 1322.0000 1.0000
33.2400 1348.0000 1.0000
33.2800 1334.0000 1.0000
33.3200 1353.0000 1.0000
33.3600 1381.0000 1.0000
33.4000 1382.0000 1.0000
33.4400 1376.0000 1.0000
33.4800 1323.0000 1.0000
33.5200 1333.0000 1.0000
33.5600 1386.0000 1.0000
33.6000 1400.0000 1.0000
33.6400 1336.0000 1.0000
33.6800 1379.0000 1.0000
33.7200 1368.0000 1.0000
33.7600 1419.0000 1.0000
33.8000 1453.0000 1.0000
33.8400 1528.0000 1.0000
33.8800 1430.0000 1.0000
33.9200 1569.0000 1.0000
33.9600 1618.0000 1.0000
34.0000 1639.0000 1.0000
34.0400 1587.0000 1.0000
34.0800 1538.0000 1.0000
34.1200 1510.0000 1.0000
34.1600 1566.0000 1.0000
34.2000 1532.0000 1.0000
34.2400 1580.0000 1.0000
34.2800 1592.0000 1.0000
34.3200 1728.0000 1.0000
34.3600 1864.0000 1.0000
34.4000 2192.0000 1.0000
34.4400 2358.0000 1.0000
34.4800 2840.0000 1.0000
34.5200 3194.0000 1.0000
34.5600 3271.0000 1.0000
34.6000 3037.0000 1.0000
34.6400 2731.0000 1.0000
34.6800 2389.0000 1.0000
34.7200 2074.0000 1.0000
34.7600 1844.0000 1.0000
34.8000 1749.0000 1.0000
34.8400 1636.0000 1.0000
34.8800 1596.0000 1.0000
34.9200 1478.0000 1.0000
34.9600 1418.0000 1.0000
35.0000 1430.0000 1.0000
35.0400 1355.0000 1.0000
35.0800 1298.0000 1.0000
35.1200 1296.0000 1.0000
35.1600 1355.0000 1.0000
35.2000 1281.0000 1.0000
35.2400 1252.0000 1.0000
35.2800 1224.0000 1.0000
35.3200 1266.0000 1.0000
35.3600 1294.0000 1.0000
35.4000 1258.0000 1.0000
35.4400 1239.0000 1.0000
35.4800 1251.0000 1.0000
35.5200 1152.0000 1.0000
35.5600 1219.0000 1.0000
35.6000 1197.0000 1.0000
35.6400 1196.0000 1.0000
35.6800 1233.0000 1.0000
35.7200 1200.0000 1.0000
35.7600 1183.0000 1.0000
35.8000 1195.0000 1.0000
35.8400 1200.0000 1.0000
35.8800 1143.0000 1.0000
35.9200 1144.0000 1.0000
35.9600 1199.0000 1.0000
36.0000 1105.0000 1.0000
36.0400 1177.0000 1.0000
36.0800 1173.0000 1.0000
36.1200 1141.0000 1.0000
36.1600 1212.0000 1.0000
36.2000 1210.0000 1.0000
36.2400 1276.0000 1.0000
36.2800 1381.0000 1.0000
36.3200 1482.0000 1.0000
36.3600 1593.0000 1.0000
36.4000 1871.0000 1.0000
36.4400 2150.0000 1.0000
36.4800 2148.0000 1.0000
36.5200 1888.0000 1.0000
36.5600 1737.0000 1.0000
36.6000 1555.0000 1.0000
36.6400 1361.0000 1.0000
36.6800 1253.0000 1.0000
36.7200 1157.0000 1.0000
36.7600 1126.0000 1.0000
36.8000 1118.0000 1.0000
36.8400 1124.0000 1.0000
36.8800 1136.0000 1.0000
36.9200 1137.0000 1.0000
36.9600 1120.0000 1.0000
37.0000 1135.0000 1.0000
37.0400 1077.0000 1.0000
37.0800 1093.0000 1.0000
37.1200 1073.0000 1.0000
37.1600 1103.0000 1.0000
37.2000 1049.0000 1.0000
37.2400 1092.0000 1.0000
37.2800 1107.0000 1.0000
37.3200 1100.0000 1.0000
37.3600 1148.0000 1.0000
37.4000 1091.0000 1.0000
37.4400 1098.0000 1.0000
37.4800 1060.0000 1.0000
37.5200 1050.0000 1.0000
37.5600 1050.0000 1.0000
37.6000 1090.0000 1.0000
37.6400 1053.0000 1.0000
37.6800 1065.0000 1.0000
37.7200 1128.0000 1.0000
37.7600 1095.0000 1.0000
37.8000 1073.0000 1.0000
37.8400 1136.0000 1.0000
37.8800 1114.0000 1.0000
37.9200 1116.0000 1.0000
37.9600 1144.0000 1.0000
38.0000 1136.0000 1.0000
38.0400 1134.0000 1.0000
38.0800 1155.0000 1.0000
38.1200 1240.0000 1.0000
38.1600 1222.0000 1.0000
38.2000 1328.0000 1.0000
38.2400 1400.0000 1.0000
38.2800 1653.0000 1.0000
38.3200 1888.0000 1.0000
38.3600 2253.0000 1.0000
38.4000 2531.0000 1.0000
38.4400 3264.0000 1.0000
38.4800 4273.0000 1.0000
38.5200 5681.0000 1.0000
38.5600 6819.0000 1.0000
38.6000 7158.0000 1.0000
38.6400 6933.0000 1.0000
38.6800 5919.0000 1.0000
38.7200 4706.0000 1.0000
38.7600 3669.0000 1.0000
38.8000 2744.0000 1.0000
38.8400 2201.0000 1.0000
38.8800 1868.0000 1.0000
38.9200 1585.0000 1.0000
38.9600 1457.0000 1.0000
39.0000 1255.0000 1.0000
39.0400 1206.0000 1.0000
39.0800 1101.0000 1.0000
39.1200 1087.0000 1.0000
39.1600 1079.0000 1.0000
39.2000 1078.0000 1.0000
39.2400 990.0000 1.0000
39.2800 1005.0000 1.0000
39.3200 1045.0000 1.0000
39.3600 1044.0000 1.0000
39.4000 968.0000 1.0000
39.4400 1031.0000 1.0000
39.4800 920.0000 1.0000
39.5200 1008.0000 1.0000
39.5600 982.0000 1.0000
39.6000 988.0000 1.0000
39.6400 994.0000 1.0000
39.6800 1008.0000 1.0000
39.7200 1047.0000 1.0000
39.7600 994.0000 1.0000
39.8000 1022.0000 1.0000
39.8400 958.0000 1.0000
39.8800 1009.0000 1.0000
39.9200 944.0000 1.0000
39.9600 940.0000 1.0000
40.0000 906.0000 1.0000
40.0400 960.0000 1.0000
40.0800 937.0000 1.0000
40.1200 913.0000 1.0000
40.1600 982.0000 1.0000
40.2000 955.0000 1.0000
40.2400 957.0000 1.0000
40.2800 894.0000 1.0000
40.3200 900.0000 1.0000
40.3600 909.0000 1.0000
40.4000 961.0000 1.0000
40.4400 930.0000 1.0000
40.4800 933.0000 1.0000
40.5200 919.0000 1.0000
40.5600 888.0000 1.0000
40.6000 919.0000 1.0000
40.6400 876.0000 1.0000
40.6800 880.0000 1.0000
40.7200 916.0000 1.0000
40.7600 890.0000 1.0000
40.8000 916.0000 1.0000
40.8400 897.0000 1.0000
40.8800 887.0000 1.0000
40.9200 913.0000 1.0000
40.9600 866.0000 1.0000
41.0000 879.0000 1.0000
41.0400 860.0000 1.0000
41.0800 876.0000 1.0000
41.1200 883.0000 1.0000
41.1600 966.0000 1.0000
41.2000 907.0000 1.0000
41.2400 899.0000 1.0000
41.2800 886.0000 1.0000
41.3200 881.0000 1.0000
41.3600 937.0000 1.0000
41.4000 849.0000 1.0000
41.4400 849.0000 1.0000
41.4800 908.0000 1.0000
41.5200 874.0000 1.0000
41.5600 857.0000 1.0000
41.6000 884.0000 1.0000
41.6400 917.0000 1.0000
41.6800 942.0000 1.0000
41.7200 845.0000 1.0000
41.7600 918.0000 1.0000
41.8000 901.0000 1.0000
41.8400 871.0000 1.0000
41.8800 886.0000 1.0000
41.9200 858.0000 1.0000
41.9600 924.0000 1.0000
42.0000 835.0000 1.0000
42.0400 909.0000 1.0000
42.0800 829.0000 1.0000
42.1200 879.0000 1.0000
42.1600 887.0000 1.0000
42.2000 872.0000 1.0000
42.2400 853.0000 1.0000
42.2800 901.0000 1.0000
42.3200 875.0000 1.0000
42.3600 873.0000 1.0000
42.4000 867.0000 1.0000
42.4400 853.0000 1.0000
42.4800 837.0000 1.0000
42.5200 857.0000 1.0000
42.5600 869.0000 1.0000
42.6000 890.0000 1.0000
42.6400 841.0000 1.0000
42.6800 896.0000 1.0000
42.7200 867.0000 1.0000
42.7600 889.0000 1.0000
42.8000 898.0000 1.0000
42.8400 876.0000 1.0000
42.8800 870.0000 1.0000
42.9200 867.0000 1.0000
42.9600 937.0000 1.0000
43.0000 872.0000 1.0000
43.0400 902.0000 1.0000
43.0800 914.0000 1.0000
43.1200 879.0000 1.0000
43.1600 918.0000 1.0000
43.2000 943.0000 1.0000
43.2400 926.0000 1.0000
43.2800 929.0000 1.0000
43.3200 961.0000 1.0000
43.3600 956.0000 1.0000
43.4000 889.0000 1.0000
43.4400 938.0000 1.0000
43.4800 897.0000 1.0000
43.5200 830.0000 1.0000
43.5600 884.0000 1.0000
43.6000 884.0000 1.0000
43.6400 881.0000 1.0000
43.6800 845.0000 1.0000
43.7200 848.0000 1.0000
43.7600 818.0000 1.0000
43.8000 895.0000 1.0000
43.8400 833.0000 1.0000
43.8800 883.0000 1.0000
43.9200 867.0000 1.0000
43.9600 807.0000 1.0000
44.0000 837.0000 1.0000
44.0400 854.0000 1.0000
44.0800 841.0000 1.0000
44.1200 807.0000 1.0000
44.1600 846.0000 1.0000
44.2000 842.0000 1.0000
44.2400 841.0000 1.0000
44.2800 887.0000 1.0000
44.3200 851.0000 1.0000
44.3600 855.0000 1.0000
44.4000 864.0000 1.0000
44.4400 844.0000 1.0000
44.4800 829.0000 1.0000
44.5200 845.0000 1.0000
44.5600 822.0000 1.0000
44.6000 857.0000 1.0000
44.6400 834.0000 1.0000
44.6800 846.0000 1.0000
44.7200 851.0000 1.0000
44.7600 811.0000 1.0000
44.8000 852.0000 1.0000
44.8400 812.0000 1.0000
44.8800 823.0000 1.0000
44.9200 768.0000 1.0000
44.9600 795.0000 1.0000
45.0000 816.0000 1.0000
45.0400 844.0000 1.0000
45.0800 800.0000 1.0000
45.1200 821.0000 1.0000
45.1600 817.0000 1.0000
45.2000 811.0000 1.0000
45.2400 769.0000 1.0000
45.2800 803.0000 1.0000
45.3200 802.0000 1.0000
45.3600 829.0000 1.0000
45.4000 800.0000 1.0000
45.4400 811.0000 1.0000
45.4800 792.0000 1.0000
45.5200 806.0000 1.0000
45.5600 883.0000 1.0000
45.6000 795.0000 1.0000
45.6400 768.0000 1.0000
45.6800 854.0000 1.0000
45.7200 821.0000 1.0000
45.7600 843.0000 1.0000
45.8000 781.0000 1.0000
45.8400 818.0000 1.0000
45.8800 763.0000 1.0000
45.9200 837.0000 1.0000
45.9600 818.0000 1.0000
46.0000 816.0000 1.0000
46.0400 826.0000 1.0000
46.0800 791.0000 1.0000
46.1200 795.0000 1.0000
46.1600 810.0000 1.0000
46.2000 768.0000 1.0000
46.2400 771.0000 1.0000
46.2800 802.0000 1.0000
46.3200 760.0000 1.0000
46.3600 802.0000 1.0000
46.4000 784.0000 1.0000
46.4400 778.0000 1.0000
46.4800 807.0000 1.0000
46.5200 744.0000 1.0000
46.5600 772.0000 1.0000
46.6000 788.0000 1.0000
46.6400 815.0000 1.0000
46.6800 785.0000 1.0000
46.7200 780.0000 1.0000
46.7600 794.0000 1.0000
46.8000 760.0000 1.0000
46.8400 829.0000 1.0000
46.8800 788.0000 1.0000
46.9200 805.0000 1.0000
46.9600 795.0000 1.0000
47.0000 822.0000 1.0000
47.0400 816.0000 1.0000
47.0800 831.0000 1.0000
47.1200 828.0000 1.0000
47.1600 836.0000 1.0000
47.2000 753.0000 1.0000
47.2400 797.0000 1.0000
47.2800 800.0000 1.0000
47.3200 773.0000 1.0000
47.3600 763.0000 1.0000
47.4000 783.0000 1.0000
47.4400 766.0000 1.0000
47.4800 765.0000 1.0000
47.5200 734.0000 1.0000
47.5600 762.0000 1.0000
47.6000 732.0000 1.0000
47.6400 761.0000 1.0000
47.6800 793.0000 1.0000
47.7200 757.0000 1.0000
47.7600 787.0000 1.0000
47.8000 810.0000 1.0000
47.8400 769.0000 1.0000
47.8800 750.0000 1.0000
47.9200 811.0000 1.0000
47.9600 797.0000 1.0000
48.0000 791.0000 1.0000
48.0400 755.0000 1.0000
48.0800 801.0000 1.0000
48.1200 752.0000 1.0000
48.1600 742.0000 1.0000
48.2000 801.0000 1.0000
48.2400 754.0000 1.0000
48.2800 710.0000 1.0000
48.3200 756.0000 1.0000
48.3600 755.0000 1.0000
48.4000 796.0000 1.0000
48.4400 753.0000 1.0000
48.4800 764.0000 1.0000
48.5200 771.0000 1.0000
48.5600 733.0000 1.0000
48.6000 758.0000 1.0000
48.6400 737.0000 1.0000
48.6800 731.0000 1.0000
48.7200 790.0000 1.0000
48.7600 781.0000 1.0000
48.8000 696.0000 1.0000
48.8400 709.0000 1.0000
48.8800 759.0000 1.0000
48.9200 730.0000 1.0000
48.9600 745.0000 1.0000
49.0000 793.0000 1.0000
49.0400 775.0000 1.0000
49.0800 803.0000 1.0000
49.1200 724.0000 1.0000
49.1600 720.0000 1.0000
49.2000 748.0000 1.0000
49.2400 766.0000 1.0000
49.2800 759.0000 1.0000
49.3200 773.0000 1.0000
49.3600 758.0000 1.0000
49.4000 744.0000 1.0000
49.4400 773.0000 1.0000
49.4800 781.0000 1.0000
49.5200 762.0000 1.0000
49.5600 746.0000 1.0000
49.6000 753.0000 1.0000
49.6400 774.0000 1.0000
49.6800 730.0000 1.0000
49.7200 746.0000 1.0000
49.7600 742.0000 1.0000
49.8000 773.0000 1.0000
49.8400 749.0000 1.0000
49.8800 735.0000 1.0000
49.9200 736.0000 1.0000
49.9600 779.0000 1.0000
50.0000 772.0000 1.0000
50.0400 777.0000 1.0000
50.0800 750.0000 1.0000
50.1200 763.0000 1.0000
50.1600 747.0000 1.0000
50.2000 795.0000 1.0000
50.2400 818.0000 1.0000
50.2800 707.0000 1.0000
50.3200 726.0000 1.0000
50.3600 766.0000 1.0000
50.4000 773.0000 1.0000
50.4400 776.0000 1.0000
50.4800 729.0000 1.0000
50.5200 736.0000 1.0000
50.5600 761.0000 1.0000
50.6000 806.0000 1.0000
50.6400 739.0000 1.0000
50.6800 789.0000 1.0000
50.7200 773.0000 1.0000
50.7600 758.0000 1.0000
50.8000 715.0000 1.0000
50.8400 715.0000 1.0000
50.8800 769.0000 1.0000
50.9200 787.0000 1.0000
50.9600 781.0000 1.0000
51.0000 715.0000 1.0000
51.0400 755.0000 1.0000
51.0800 730.0000 1.0000
51.1200 733.0000 1.0000
51.1600 775.0000 1.0000
51.2000 726.0000 1.0000
51.2400 767.0000 1.0000
51.2800 777.0000 1.0000
51.3200 783.0000 1.0000
51.3600 751.0000 1.0000
51.4000 788.0000 1.0000
51.4400 744.0000 1.0000
51.4800 783.0000 1.0000
51.5200 792.0000 1.0000
51.5600 803.0000 1.0000
51.6000 776.0000 1.0000
51.6400 801.0000 1.0000
51.6800 767.0000 1.0000
51.7200 822.0000 1.0000
51.7600 824.0000 1.0000
51.8000 807.0000 1.0000
51.8400 861.0000 1.0000
51.8800 886.0000 1.0000
51.9200 884.0000 1.0000
51.9600 957.0000 1.0000
52.0000 1050.0000 1.0000
52.0400 1189.0000 1.0000
52.0800 1368.0000 1.0000
52.1200 1519.0000 1.0000
52.1600 1908.0000 1.0000
52.2000 2603.0000 1.0000
52.2400 3479.0000 1.0000
52.2800 4482.0000 1.0000
52.3200 5272.0000 1.0000
52.3600 5067.0000 1.0000
52.4000 4361.0000 1.0000
52.4400 3984.0000 1.0000
52.4800 3492.0000 1.0000
52.5200 2737.0000 1.0000
52.5600 2056.0000 1.0000
52.6000 1614.0000 1.0000
52.6400 1374.0000 1.0000
52.6800 1222.0000 1.0000
52.7200 1086.0000 1.0000
52.7600 1005.0000 1.0000
52.8000 961.0000 1.0000
52.8400 939.0000 1.0000
52.8800 851.0000 1.0000
52.9200 800.0000 1.0000
52.9600 866.0000 1.0000
53.0000 800.0000 1.0000
53.0400 835.0000 1.0000
53.0800 797.0000 1.0000
53.1200 742.0000 1.0000
53.1600 795.0000 1.0000
53.2000 793.0000 1.0000
53.2400 765.0000 1.0000
53.2800 759.0000 1.0000
53.3200 768.0000 1.0000
53.3600 787.0000 1.0000
53.4000 695.0000 1.0000
53.4400 755.0000 1.0000
53.4800 753.0000 1.0000
53.5200 720.0000 1.0000
53.5600 770.0000 1.0000
53.6000 674.0000 1.0000
53.6400 745.0000 1.0000
53.6800 733.0000 1.0000
53.7200 713.0000 1.0000
53.7600 721.0000 1.0000
53.8000 771.0000 1.0000
53.8400 738.0000 1.0000
53.8800 756.0000 1.0000
53.9200 739.0000 1.0000
53.9600 726.0000 1.0000
54.0000 762.0000 1.0000
54.0400 710.0000 1.0000
54.0800 734.0000 1.0000
54.1200 729.0000 1.0000
54.1600 758.0000 1.0000
54.2000 700.0000 1.0000
54.2400 715.0000 1.0000
54.2800 739.0000 1.0000
54.3200 746.0000 1.0000
54.3600 720.0000 1.0000
54.4000 701.0000 1.0000
54.4400 713.0000 1.0000
54.4800 711.0000 1.0000
54.5200 717.0000 1.0000
54.5600 759.0000 1.0000
54.6000 721.0000 1.0000
54.6400 741.0000 1.0000
54.6800 780.0000 1.0000
54.7200 754.0000 1.0000
54.7600 775.0000 1.0000
54.8000 764.0000 1.0000
54.8400 796.0000 1.0000
54.8800 803.0000 1.0000
54.9200 785.0000 1.0000
54.9600 791.0000 1.0000
55.0000 765.0000 1.0000
55.0400 827.0000 1.0000
55.0800 787.0000 1.0000
55.1200 873.0000 1.0000
55.1600 844.0000 1.0000
55.2000 924.0000 1.0000
55.2400 998.0000 1.0000
55.2800 1083.0000 1.0000
55.3200 1099.0000 1.0000
55.3600 1118.0000 1.0000
55.4000 1130.0000 1.0000
55.4400 1040.0000 1.0000
55.4800 1039.0000 1.0000
55.5200 911.0000 1.0000
55.5600 913.0000 1.0000
55.6000 814.0000 1.0000
55.6400 818.0000 1.0000
55.6800 800.0000 1.0000
55.7200 789.0000 1.0000
55.7600 801.0000 1.0000
55.8000 764.0000 1.0000
55.8400 773.0000 1.0000
55.8800 766.0000 1.0000
55.9200 741.0000 1.0000
55.9600 753.0000 1.0000
56.0000 765.0000 1.0000
56.0400 738.0000 1.0000
56.0800 734.0000 1.0000
56.1200 694.0000 1.0000
56.1600 720.0000 1.0000
56.2000 739.0000 1.0000
56.2400 688.0000 1.0000
56.2800 692.0000 1.0000
56.3200 715.0000 1.0000
56.3600 690.0000 1.0000
56.4000 684.0000 1.0000
56.4400 719.0000 1.0000
56.4800 723.0000 1.0000
56.5200 696.0000 1.0000
56.5600 717.0000 1.0000
56.6000 723.0000 1.0000
56.6400 724.0000 1.0000
56.6800 716.0000 1.0000
56.7200 721.0000 1.0000
56.7600 660.0000 1.0000
56.8000 666.0000 1.0000
56.8400 700.0000 1.0000
56.8800 732.0000 1.0000
56.9200 710.0000 1.0000
56.9600 714.0000 1.0000
57.0000 716.0000 1.0000
57.0400 721.0000 1.0000
57.0800 709.0000 1.0000
57.1200 766.0000 1.0000
57.1600 667.0000 1.0000
57.2000 681.0000 1.0000
57.2400 714.0000 1.0000
57.2800 716.0000 1.0000
57.3200 748.0000 1.0000
57.3600 703.0000 1.0000
57.4000 716.0000 1.0000
57.4400 729.0000 1.0000
57.4800 730.0000 1.0000
57.5200 670.0000 1.0000
57.5600 716.0000 1.0000
57.6000 719.0000 1.0000
57.6400 704.0000 1.0000
57.6800 735.0000 1.0000
57.7200 676.0000 1.0000
57.7600 712.0000 1.0000
57.8000 718.0000 1.0000
57.8400 719.0000 1.0000
57.8800 706.0000 1.0000
57.9200 713.0000 1.0000
57.9600 730.0000 1.0000
58.0000 689.0000 1.0000
58.0400 727.0000 1.0000
58.0800 726.0000 1.0000
58.1200 729.0000 1.0000
58.1600 716.0000 1.0000
58.2000 724.0000 1.0000
58.2400 727.0000 1.0000
58.2800 734.0000 1.0000
58.3200 752.0000 1.0000
58.3600 714.0000 1.0000
58.4000 704.0000 1.0000
58.4400 697.0000 1.0000
58.4800 704.0000 1.0000
58.5200 746.0000 1.0000
58.5600 709.0000 1.0000
58.6000 685.0000 1.0000
58.6400 718.0000 1.0000
58.6800 683.0000 1.0000
58.7200 703.0000 1.0000
58.7600 742.0000 1.0000
58.8000 665.0000 1.0000
58.8400 667.0000 1.0000
58.8800 704.0000 1.0000
58.9200 645.0000 1.0000
58.9600 728.0000 1.0000
59.0000 742.0000 1.0000
59.0400 754.0000 1.0000
59.0800 698.0000 1.0000
59.1200 674.0000 1.0000
59.1600 715.0000 1.0000
59.2000 730.0000 1.0000
59.2400 690.0000 1.0000
59.2800 703.0000 1.0000
59.3200 736.0000 1.0000
59.3600 762.0000 1.0000
59.4000 692.0000 1.0000
59.4400 719.0000 1.0000
59.4800 707.0000 1.0000
59.5200 734.0000 1.0000
59.5600 697.0000 1.0000
59.6000 702.0000 1.0000
59.6400 676.0000 1.0000
59.6800 704.0000 1.0000
59.7200 684.0000 1.0000
59.7600 661.0000 1.0000
59.8000 642.0000 1.0000
59.8400 663.0000 1.0000
59.8800 653.0000 1.0000
59.9200 716.0000 1.0000
59.9600 666.0000 1.0000
60.0000 743.0000 1.0000
60.0400 657.0000 1.0000
60.0800 702.0000 1.0000
60.1200 696.0000 1.0000
60.1600 687.0000 1.0000
60.2000 694.0000 1.0000
60.2400 655.0000 1.0000
60.2800 667.0000 1.0000
60.3200 734.0000 1.0000
60.3600 717.0000 1.0000
60.4000 691.0000 1.0000
60.4400 705.0000 1.0000
60.4800 719.0000 1.0000
60.5200 705.0000 1.0000
60.5600 729.0000 1.0000
60.6000 706.0000 1.0000
60.6400 734.0000 1.0000
60.6800 744.0000 1.0000
60.7200 681.0000 1.0000
60.7600 692.0000 1.0000
60.8000 704.0000 1.0000
60.8400 668.0000 1.0000
60.8800 702.0000 1.0000
60.9200 724.0000 1.0000
60.9600 725.0000 1.0000
61.0000 707.0000 1.0000
61.0400 695.0000 1.0000
61.0800 693.0000 1.0000
61.1200 708.0000 1.0000
61.1600 688.0000 1.0000
61.2000 687.0000 1.0000
61.2400 723.0000 1.0000
61.2800 689.0000 1.0000
61.3200 697.0000 1.0000
61.3600 685.0000 1.0000
61.4000 722.0000 1.0000
61.4400 689.0000 1.0000
61.4800 734.0000 1.0000
61.5200 720.0000 1.0000
61.5600 719.0000 1.0000
61.6000 724.0000 1.0000
61.6400 733.0000 1.0000
61.6800 743.0000 1.0000
61.7200 698.0000 1.0000
61.7600 764.0000 1.0000
61.8000 732.0000 1.0000
61.8400 752.0000 1.0000
61.8800 749.0000 1.0000
61.9200 806.0000 1.0000
61.9600 820.0000 1.0000
62.0000 842.0000 1.0000
62.0400 873.0000 1.0000
62.0800 950.0000 1.0000
62.1200 1093.0000 1.0000
62.1600 1126.0000 1.0000
62.2000 1288.0000 1.0000
62.2400 1430.0000 1.0000
62.2800 1561.0000 1.0000
62.3200 1616.0000 1.0000
62.3600 1625.0000 1.0000
62.4000 1635.0000 1.0000
62.4400 1604.0000 1.0000
62.4800 1539.0000 1.0000
62.5200 1414.0000 1.0000
62.5600 1333.0000 1.0000
62.6000 1171.0000 1.0000
62.6400 1099.0000 1.0000
62.6800 1029.0000 1.0000
62.7200 948.0000 1.0000
62.7600 900.0000 1.0000
62.8000 885.0000 1.0000
62.8400 878.0000 1.0000
62.8800 825.0000 1.0000
62.9200 801.0000 1.0000
62.9600 808.0000 1.0000
63.0000 737.0000 1.0000
63.0400 777.0000 1.0000
63.0800 725.0000 1.0000
63.1200 744.0000 1.0000
63.1600 770.0000 1.0000
63.2000 737.0000 1.0000
63.2400 790.0000 1.0000
63.2800 749.0000 1.0000
63.3200 735.0000 1.0000
63.3600 702.0000 1.0000
63.4000 721.0000 1.0000
63.4400 728.0000 1.0000
63.4800 729.0000 1.0000
63.5200 669.0000 1.0000
63.5600 710.0000 1.0000
63.6000 716.0000 1.0000
63.6400 699.0000 1.0000
63.6800 702.0000 1.0000
63.7200 722.0000 1.0000
63.7600 692.0000 1.0000
63.8000 681.0000 1.0000
63.8400 704.0000 1.0000
63.8800 750.0000 1.0000
63.9200 730.0000 1.0000
63.9600 725.0000 1.0000
64.0000 674.0000 1.0000
64.0400 664.0000 1.0000
64.0800 700.0000 1.0000
64.1200 699.0000 1.0000
64.1600 732.0000 1.0000
64.2000 712.0000 1.0000
64.2400 683.0000 1.0000
64.2800 690.0000 1.0000
64.3200 694.0000 1.0000
64.3600 725.0000 1.0000
64.4000 683.0000 1.0000
64.4400 741.0000 1.0000
64.4800 746.0000 1.0000
64.5200 732.0000 1.0000
64.5600 792.0000 1.0000
64.6000 763.0000 1.0000
64.6400 843.0000 1.0000
64.6800 831.0000 1.0000
64.7200 853.0000 1.0000
64.7600 911.0000 1.0000
64.8000 891.0000 1.0000
64.8400 844.0000 1.0000
64.8800 860.0000 1.0000
64.9200 847.0000 1.0000
64.9600 817.0000 1.0000
65.0000 798.0000 1.0000
65.0400 711.0000 1.0000
65.0800 760.0000 1.0000
65.1200 780.0000 1.0000
65.1600 785.0000 1.0000
65.2000 740.0000 1.0000
65.2400 740.0000 1.0000
65.2800 751.0000 1.0000
65.3200 716.0000 1.0000
65.3600 735.0000 1.0000
65.4000 764.0000 1.0000
65.4400 714.0000 1.0000
65.4800 744.0000 1.0000
65.5200 728.0000 1.0000
65.5600 721.0000 1.0000
65.6000 752.0000 1.0000
65.6400 758.0000 1.0000
65.6800 763.0000 1.0000
65.7200 774.0000 1.0000
65.7600 758.0000 1.0000
65.8000 810.0000 1.0000
65.8400 793.0000 1.0000
65.8800 785.0000 1.0000
65.9200 876.0000 1.0000
65.9600 882.0000 1.0000
66.0000 930.0000 1.0000
66.0400 1023.0000 1.0000
66.0800 1194.0000 1.0000
66.1200 1331.0000 1.0000
66.1600 1587.0000 1.0000
66.2000 1860.0000 1.0000
66.2400 2329.0000 1.0000
66.2800 2784.0000 1.0000
66.3200 2806.0000 1.0000
66.3600 2660.0000 1.0000
66.4000 2577.0000 1.0000
66.4400 2354.0000 1.0000
66.4800 2261.0000 1.0000
66.5200 2113.0000 1.0000
66.5600 1756.0000 1.0000
66.6000 1491.0000 1.0000
66.6400 1291.0000 1.0000
66.6800 1194.0000 1.0000
66.7200 1041.0000 1.0000
66.7600 960.0000 1.0000
66.8000 894.0000 1.0000
66.8400 874.0000 1.0000
66.8800 832.0000 1.0000
66.9200 751.0000 1.0000
66.9600 761.0000 1.0000
67.0000 744.0000 1.0000
67.0400 735.0000 1.0000
67.0800 690.0000 1.0000
67.1200 679.0000 1.0000
67.1600 696.0000 1.0000
67.2000 695.0000 1.0000
67.2400 731.0000 1.0000
67.2800 680.0000 1.0000
67.3200 679.0000 1.0000
67.3600 708.0000 1.0000
67.4000 720.0000 1.0000
67.4400 682.0000 1.0000
67.4800 630.0000 1.0000
67.5200 681.0000 1.0000
67.5600 671.0000 1.0000
67.6000 644.0000 1.0000
67.6400 661.0000 1.0000
67.6800 673.0000 1.0000
67.7200 666.0000 1.0000
67.7600 601.0000 1.0000
67.8000 619.0000 1.0000
67.8400 671.0000 1.0000
67.8800 623.0000 1.0000
67.9200 657.0000 1.0000
67.9600 651.0000 1.0000
68.0000 636.0000 1.0000
68.0400 639.0000 1.0000
68.0800 653.0000 1.0000
68.1200 691.0000 1.0000
68.1600 632.0000 1.0000
68.2000 645.0000 1.0000
68.2400 634.0000 1.0000
68.2800 624.0000 1.0000
68.3200 640.0000 1.0000
68.3600 617.0000 1.0000
68.4000 654.0000 1.0000
68.4400 660.0000 1.0000
68.4800 603.0000 1.0000
68.5200 679.0000 1.0000
68.5600 649.0000 1.0000
68.6000 615.0000 1.0000
68.6400 632.0000 1.0000
68.6800 635.0000 1.0000
68.7200 644.0000 1.0000
68.7600 608.0000 1.0000
68.8000 622.0000 1.0000
68.8400 636.0000 1.0000
68.8800 642.0000 1.0000
68.9200 635.0000 1.0000
68.9600 619.0000 1.0000
69.0000 615.0000 1.0000
69.0400 631.0000 1.0000
69.0800 639.0000 1.0000
69.1200 592.0000 1.0000
69.1600 607.0000 1.0000
69.2000 598.0000 1.0000
69.2400 598.0000 1.0000
69.2800 634.0000 1.0000
69.3200 633.0000 1.0000
69.3600 611.0000 1.0000
69.4000 629.0000 1.0000
69.4400 619.0000 1.0000
69.4800 632.0000 1.0000
69.5200 620.0000 1.0000
69.5600 613.0000 1.0000
69.6000 636.0000 1.0000
69.6400 611.0000 1.0000
69.6800 612.0000 1.0000
69.7200 613.0000 1.0000
69.7600 636.0000 1.0000
69.8000 597.0000 1.0000
69.8400 571.0000 1.0000
69.8800 613.0000 1.0000
69.9200 623.0000 1.0000
69.9600 587.0000 1.0000
70.0000 611.0000 1.0000
*RAS_INT_END
*RAS_TEMPERATURE_START
*RAS_TEMPERATURE_END
*RAS_DATA_END