File: Data/Dataset1_Only_water/5_XRD/No_050_deposition_3h_Air_6.ras
*RAS_DATA_START
*RAS_HEADER_START
*DISP_FMT_X "%.2f"
*DISP_FMT_Y "%.0f"
*DISP_FULLSCALE "18450.0000000000"
*DISP_LINE_COLOR "255.0000000000"
*DISP_LINE_STYLE "0.0000000000"
*DISP_LINE_WIDTH "0.2500000000"
*DISP_NOTE "測定データ-7"
*DISP_OFFSET_Y "0.0000000000"
*DISP_PEAKSEARCH_UNIT_Y "cps"
*DISP_RANGE_BOTTOM "0.0000000000"
*DISP_RANGE_LEFT "20.0000000000"
*DISP_RANGE_LOGCUTOFF "0.0100000000"
*DISP_RANGE_RIGHT "70.0000000000"
*DISP_RANGE_TOP "18450.0000000000"
*DISP_SCALE_MODE_Y "0.0000000000"
*DISP_TAB_NAME "2θ/θ"
*DISP_TITLE_Y "強度"
*DISP_UNIT_Y "cps"
*DISP_WINDOW_NAME "MSG_MACROENGINE"
*FILE_COMMENT " "
*FILE_MD5 ""
*FILE_MEMO " "
*FILE_OPERATOR "Administrator"
*FILE_SAMPLE " "
*FILE_TYPE "RAS_RAW"
*FILE_USERGROUP "システムマネージャ"
*FILE_VERSION "1.0000000000"
*HW_ATTACHMENT_ID "ATT0025"
*HW_ATTACHMENT_NAME "標準|Standard"
*HW_COUNTER_ID-0 "CUT0025"
*HW_COUNTER_ID-1 "CUT0020"
*HW_COUNTER_ID-2 "CUT0020"
*HW_COUNTER_ID-3 "CSL0021"
*HW_COUNTER_ID-4 "CMC0021"
*HW_COUNTER_NAME-0 "D/teX Ultra|D/teX Ultra"
*HW_COUNTER_NAME-1 "None|None"
*HW_COUNTER_NAME-2 "None|None"
*HW_COUNTER_NAME-3 "BBM|BBM"
*HW_COUNTER_NAME-4 "検出器モノクロメータ|Detector monochromator"
*HW_COUNTER_SELECT_NAME "D/teX Ultra|D/teX Ultra"
*HW_GONIOMETER_ID "GON0023"
*HW_GONIOMETER_NAME "SmartLab|SmartLab"
*HW_GONIOMETER_RADIUS-0 "90.0"
*HW_GONIOMETER_RADIUS-1 "114.0"
*HW_GONIOMETER_RADIUS-2 "190.0"
*HW_GONIOMETER_RADIUS-3 "300.0"
*HW_GONIOMETER_RADIUS-4 "187.0"
*HW_GONIOMETER_RADIUS-5 "300.0"
*HW_GONIOMETER_RADIUS-6 "113.0"
*HW_GONIOMETER_RADIUS-7 "331.0"
*HW_I_OPT_ID-0 "CBO0021"
*HW_I_OPT_ID-1 "ICR0023"
*HW_I_OPT_ID-2 "ISL0021"
*HW_I_OPT_ID-3 "ISO0021"
*HW_I_OPT_ID-4 "IAD0021"
*HW_I_OPT_ID-5 "IPR0001"
*HW_I_OPT_NAME-0 "CBOユニット|CBO unit"
*HW_I_OPT_NAME-1 "標準入射光学ユニット|Standard incident optical unit"
*HW_I_OPT_NAME-2 "標準入射スリットボックス|Standard incident slit box"
*HW_I_OPT_NAME-3 "入射平行スリット|Incident parallel slit"
*HW_I_OPT_NAME-4 "長手制限スリット|Length limiting slit"
*HW_I_OPT_NAME-5 "None|None"
*HW_R_ATTENUATER_AUTOMODE "0"
*HW_R_OPT_ID-0 "RSS0021"
*HW_R_OPT_ID-1 "RCR0023"
*HW_R_OPT_ID-2 "RSO0021"
*HW_R_OPT_ID-3 "RRS0021"
*HW_R_OPT_ID-4 "ATN0021"
*HW_R_OPT_ID-5 "RFL0021"
*HW_R_OPT_ID-6 "RAD0021"
*HW_R_OPT_NAME-0 "標準受光スリットボックス1|Standard receiving slit box # 1"
*HW_R_OPT_NAME-1 "標準受光光学ユニット1|Standard receiving unit # 1"
*HW_R_OPT_NAME-2 "標準受光光学ユニット2|Standard receiving optical unit # 2"
*HW_R_OPT_NAME-3 "標準受光スリットボックス2|Standard receiving slit box # 2"
*HW_R_OPT_NAME-4 "標準アッテネータ|Standard Attenuator"
*HW_R_OPT_NAME-5 "Cu Kβ|Cu K-beta"
*HW_R_OPT_NAME-6 "調整用受光スリット|Alignment receiving slit"
*HW_SAMPLE_HOLDER_ID "SMP0023"
*HW_SAMPLE_HOLDER_NAME "標準Zステージ|Standard Z stage"
*HW_XG_CURRENT_MAX "50"
*HW_XG_CURRENT_MIN "2"
*HW_XG_CURRENT_RESOLUTION "1"
*HW_XG_CURRENT_UNIT "mA"
*HW_XG_FOCUS "1mm x 10mm"
*HW_XG_FOCUS_TYPE "Normal"
*HW_XG_ID ""
*HW_XG_NAME "3kW 封入管(ID:1200)|3kW Sealed tube(ID:1200)"
*HW_XG_TARGET_ATOMIC_NUMBER "29.0000000000"
*HW_XG_TARGET_NAME "Cu"
*HW_XG_TYPE "Hermetic"
*HW_XG_VOLTAGE_MAX "60"
*HW_XG_VOLTAGE_MIN "20"
*HW_XG_VOLTAGE_RESOLUTION "1"
*HW_XG_VOLTAGE_UNIT "kV"
*HW_XG_WATT_MAX "1.500"
*HW_XG_WATT_UNIT "kW"
*HW_XG_WAVE_LENGTH_ALPHA1 "1.540593"
*HW_XG_WAVE_LENGTH_ALPHA2 "1.544414"
*HW_XG_WAVE_LENGTH_BETA "1.392250"
*MEAS_COND_AXIS_NAME-0 "2θ/θ"
*MEAS_COND_AXIS_NAME-1 "2θ"
*MEAS_COND_AXIS_NAME-2 "ω"
*MEAS_COND_AXIS_NAME-3 "Z"
*MEAS_COND_AXIS_NAME-4 "2θ/ω"
*MEAS_COND_AXIS_NAME-5 "θs"
*MEAS_COND_AXIS_NAME-6 "θd"
*MEAS_COND_AXIS_NAME-7 "Ts"
*MEAS_COND_AXIS_NAME-8 "CBO選択スリット"
*MEAS_COND_AXIS_NAME-9 "M"
*MEAS_COND_AXIS_NAME-10 "入射平行スリット"
*MEAS_COND_AXIS_NAME-11 "入射スリット"
*MEAS_COND_AXIS_NAME-12 ""
*MEAS_COND_AXIS_NAME-13 "Zs"
*MEAS_COND_AXIS_NAME-14 "入射光学素子"
*MEAS_COND_AXIS_NAME-15 "長手制限スリット"
*MEAS_COND_AXIS_NAME-16 "センタースリット"
*MEAS_COND_AXIS_NAME-17 "フィルター"
*MEAS_COND_AXIS_NAME-18 "受光スリット1"
*MEAS_COND_AXIS_NAME-19 "受光スリット2"
*MEAS_COND_AXIS_NAME-20 "受光光学素子"
*MEAS_COND_AXIS_NAME-21 "受光平行スリット"
*MEAS_COND_AXIS_NAME-22 "調整用受光スリット"
*MEAS_COND_AXIS_NAME-23 ""
*MEAS_COND_AXIS_NAME-24 ""
*MEAS_COND_AXIS_NAME-25 "Zd"
*MEAS_COND_AXIS_NAME-26 "アッテネータ"
*MEAS_COND_AXIS_NAME-27 "検出器モノクロメータ"
*MEAS_COND_AXIS_NAME-28 "モノクロメータスリット"
*MEAS_COND_AXIS_NAME-29 "プライマリビーム"
*MEAS_COND_AXIS_NAME-30 "PHA"
*MEAS_COND_AXIS_NAME_INTERNAL-0 "TwoThetaTheta"
*MEAS_COND_AXIS_NAME_INTERNAL-1 "TwoTheta"
*MEAS_COND_AXIS_NAME_INTERNAL-2 "Omega"
*MEAS_COND_AXIS_NAME_INTERNAL-3 "Z"
*MEAS_COND_AXIS_NAME_INTERNAL-4 "TwoThetaOmega"
*MEAS_COND_AXIS_NAME_INTERNAL-5 "ThetaS"
*MEAS_COND_AXIS_NAME_INTERNAL-6 "ThetaD"
*MEAS_COND_AXIS_NAME_INTERNAL-7 "Ts"
*MEAS_COND_AXIS_NAME_INTERNAL-8 "CBO"
*MEAS_COND_AXIS_NAME_INTERNAL-9 "CBO-M"
*MEAS_COND_AXIS_NAME_INTERNAL-10 "IncidentSollerSlit"
*MEAS_COND_AXIS_NAME_INTERNAL-11 "IncidentSlitBox"
*MEAS_COND_AXIS_NAME_INTERNAL-12 "IncidentSlitBox-_Axis"
*MEAS_COND_AXIS_NAME_INTERNAL-13 "Zs"
*MEAS_COND_AXIS_NAME_INTERNAL-14 "IncidentMonochromator"
*MEAS_COND_AXIS_NAME_INTERNAL-15 "IncidentAxdSlit"
*MEAS_COND_AXIS_NAME_INTERNAL-16 "CenterSlit"
*MEAS_COND_AXIS_NAME_INTERNAL-17 "Filter"
*MEAS_COND_AXIS_NAME_INTERNAL-18 "ReceivingSlitBox1"
*MEAS_COND_AXIS_NAME_INTERNAL-19 "ReceivingSlitBox2"
*MEAS_COND_AXIS_NAME_INTERNAL-20 "ReceivingOptics"
*MEAS_COND_AXIS_NAME_INTERNAL-21 "ReceivingSollerSlit"
*MEAS_COND_AXIS_NAME_INTERNAL-22 "ReceivingAxdSlit"
*MEAS_COND_AXIS_NAME_INTERNAL-23 "ReceivingSlitBox1-_Axis"
*MEAS_COND_AXIS_NAME_INTERNAL-24 "ReceivingSlitBox2-_Axis"
*MEAS_COND_AXIS_NAME_INTERNAL-25 "ReceivingSlitBox2-Zd"
*MEAS_COND_AXIS_NAME_INTERNAL-26 "Attenuator"
*MEAS_COND_AXIS_NAME_INTERNAL-27 "CounterMonochromator"
*MEAS_COND_AXIS_NAME_INTERNAL-28 "CounterSlit"
*MEAS_COND_AXIS_NAME_INTERNAL-29 "IncidentPrimary"
*MEAS_COND_AXIS_NAME_INTERNAL-30 "PHA"
*MEAS_COND_AXIS_NAME_MAGICNO-0 "83951616.0000000000"
*MEAS_COND_AXIS_NAME_MAGICNO-1 "268632064.0000000000"
*MEAS_COND_AXIS_NAME_MAGICNO-2 "268500992.0000000000"
*MEAS_COND_AXIS_NAME_MAGICNO-3 "285278208.0000000000"
*MEAS_COND_AXIS_NAME_MAGICNO-4 "83951616.0000000000"
*MEAS_COND_AXIS_NAME_MAGICNO-5 "131072.0000000000"
*MEAS_COND_AXIS_NAME_MAGICNO-6 "131072.0000000000"
*MEAS_COND_AXIS_NAME_MAGICNO-7 "318898176.0000000000"
*MEAS_COND_AXIS_NAME_MAGICNO-8 "20971521.0000000000"
*MEAS_COND_AXIS_NAME_MAGICNO-9 "285343744.0000000000"
*MEAS_COND_AXIS_NAME_MAGICNO-10 "20971521.0000000000"
*MEAS_COND_AXIS_NAME_MAGICNO-11 "22020097.0000000000"
*MEAS_COND_AXIS_NAME_MAGICNO-12 "25165824.0000000000"
*MEAS_COND_AXIS_NAME_MAGICNO-13 "318898176.0000000000"
*MEAS_COND_AXIS_NAME_MAGICNO-14 "1.0000000000"
*MEAS_COND_AXIS_NAME_MAGICNO-15 "20971521.0000000000"
*MEAS_COND_AXIS_NAME_MAGICNO-16 "20971521.0000000000"
*MEAS_COND_AXIS_NAME_MAGICNO-17 "20971521.0000000000"
*MEAS_COND_AXIS_NAME_MAGICNO-18 "23068673.0000000000"
*MEAS_COND_AXIS_NAME_MAGICNO-19 "23068673.0000000000"
*MEAS_COND_AXIS_NAME_MAGICNO-20 "20971521.0000000000"
*MEAS_COND_AXIS_NAME_MAGICNO-21 "20971521.0000000000"
*MEAS_COND_AXIS_NAME_MAGICNO-22 "20971521.0000000000"
*MEAS_COND_AXIS_NAME_MAGICNO-23 "25165824.0000000000"
*MEAS_COND_AXIS_NAME_MAGICNO-24 "25165824.0000000000"
*MEAS_COND_AXIS_NAME_MAGICNO-25 "285343744.0000000000"
*MEAS_COND_AXIS_NAME_MAGICNO-26 "17301505.0000000000"
*MEAS_COND_AXIS_NAME_MAGICNO-27 "20971521.0000000000"
*MEAS_COND_AXIS_NAME_MAGICNO-28 "20971521.0000000000"
*MEAS_COND_AXIS_NAME_MAGICNO-29 "20971521.0000000000"
*MEAS_COND_AXIS_NAME_MAGICNO-30 "0.0000000000"
*MEAS_COND_AXIS_OFFSET-0 "-"
*MEAS_COND_AXIS_OFFSET-1 "-0.0801000000"
*MEAS_COND_AXIS_OFFSET-2 "0.1646000000"
*MEAS_COND_AXIS_OFFSET-3 "-"
*MEAS_COND_AXIS_OFFSET-4 "-"
*MEAS_COND_AXIS_OFFSET-5 "0.1646000000"
*MEAS_COND_AXIS_OFFSET-6 "-0.2447000000"
*MEAS_COND_AXIS_OFFSET-7 "-"
*MEAS_COND_AXIS_OFFSET-8 "-"
*MEAS_COND_AXIS_OFFSET-9 "-"
*MEAS_COND_AXIS_OFFSET-10 "-"
*MEAS_COND_AXIS_OFFSET-11 "-"
*MEAS_COND_AXIS_OFFSET-12 "-"
*MEAS_COND_AXIS_OFFSET-13 "-"
*MEAS_COND_AXIS_OFFSET-14 "-"
*MEAS_COND_AXIS_OFFSET-15 "-"
*MEAS_COND_AXIS_OFFSET-16 "-"
*MEAS_COND_AXIS_OFFSET-17 "-"
*MEAS_COND_AXIS_OFFSET-18 "-"
*MEAS_COND_AXIS_OFFSET-19 "-"
*MEAS_COND_AXIS_OFFSET-20 "-"
*MEAS_COND_AXIS_OFFSET-21 "-"
*MEAS_COND_AXIS_OFFSET-22 "-"
*MEAS_COND_AXIS_OFFSET-23 "-"
*MEAS_COND_AXIS_OFFSET-24 "-"
*MEAS_COND_AXIS_OFFSET-25 "-"
*MEAS_COND_AXIS_OFFSET-26 "-"
*MEAS_COND_AXIS_OFFSET-27 "-"
*MEAS_COND_AXIS_OFFSET-28 "-"
*MEAS_COND_AXIS_OFFSET-29 "-"
*MEAS_COND_AXIS_OFFSET-30 "-"
*MEAS_COND_AXIS_POSITION-0 "0.0000000000"
*MEAS_COND_AXIS_POSITION-1 "0.0000000000"
*MEAS_COND_AXIS_POSITION-2 "0.0000000000"
*MEAS_COND_AXIS_POSITION-3 "-2.9256400000"
*MEAS_COND_AXIS_POSITION-4 "0.0000000000"
*MEAS_COND_AXIS_POSITION-5 "0.0000000000"
*MEAS_COND_AXIS_POSITION-6 "0.0000000000"
*MEAS_COND_AXIS_POSITION-7 "-0.4278800000"
*MEAS_COND_AXIS_POSITION-8 "BB"
*MEAS_COND_AXIS_POSITION-9 "0.0000000000"
*MEAS_COND_AXIS_POSITION-10 "Soller_slit_5.0deg"
*MEAS_COND_AXIS_POSITION-11 "2/3deg"
*MEAS_COND_AXIS_POSITION-12 "2.2088000000"
*MEAS_COND_AXIS_POSITION-13 "-1.0609400000"
*MEAS_COND_AXIS_POSITION-14 "0.0000000000"
*MEAS_COND_AXIS_POSITION-15 "10.0mm"
*MEAS_COND_AXIS_POSITION-16 "None"
*MEAS_COND_AXIS_POSITION-17 "Cu_K-beta"
*MEAS_COND_AXIS_POSITION-18 "13.000mm"
*MEAS_COND_AXIS_POSITION-19 "13.000mm"
*MEAS_COND_AXIS_POSITION-20 "No_unit"
*MEAS_COND_AXIS_POSITION-21 "Soller_slit_5.0deg"
*MEAS_COND_AXIS_POSITION-22 "None"
*MEAS_COND_AXIS_POSITION-23 "13.0000000000"
*MEAS_COND_AXIS_POSITION-24 "13.0000000000"
*MEAS_COND_AXIS_POSITION-25 "0.0081300000"
*MEAS_COND_AXIS_POSITION-26 "Open"
*MEAS_COND_AXIS_POSITION-27 "None"
*MEAS_COND_AXIS_POSITION-28 "None"
*MEAS_COND_AXIS_POSITION-29 "None"
*MEAS_COND_AXIS_POSITION-30 "38.0000000000"
*MEAS_COND_AXIS_UNIT-0 "deg"
*MEAS_COND_AXIS_UNIT-1 "deg"
*MEAS_COND_AXIS_UNIT-2 "deg"
*MEAS_COND_AXIS_UNIT-3 "mm"
*MEAS_COND_AXIS_UNIT-4 "deg"
*MEAS_COND_AXIS_UNIT-5 "deg"
*MEAS_COND_AXIS_UNIT-6 "deg"
*MEAS_COND_AXIS_UNIT-7 "mm"
*MEAS_COND_AXIS_UNIT-8 ""
*MEAS_COND_AXIS_UNIT-9 "pulse"
*MEAS_COND_AXIS_UNIT-10 ""
*MEAS_COND_AXIS_UNIT-11 ""
*MEAS_COND_AXIS_UNIT-12 "mm"
*MEAS_COND_AXIS_UNIT-13 "mm"
*MEAS_COND_AXIS_UNIT-14 ""
*MEAS_COND_AXIS_UNIT-15 ""
*MEAS_COND_AXIS_UNIT-16 ""
*MEAS_COND_AXIS_UNIT-17 ""
*MEAS_COND_AXIS_UNIT-18 ""
*MEAS_COND_AXIS_UNIT-19 ""
*MEAS_COND_AXIS_UNIT-20 ""
*MEAS_COND_AXIS_UNIT-21 ""
*MEAS_COND_AXIS_UNIT-22 ""
*MEAS_COND_AXIS_UNIT-23 "mm"
*MEAS_COND_AXIS_UNIT-24 "mm"
*MEAS_COND_AXIS_UNIT-25 "mm"
*MEAS_COND_AXIS_UNIT-26 ""
*MEAS_COND_AXIS_UNIT-27 ""
*MEAS_COND_AXIS_UNIT-28 ""
*MEAS_COND_AXIS_UNIT-29 ""
*MEAS_COND_AXIS_UNIT-30 "div"
*MEAS_COND_COUNTER_CNTLOSS_CORR "0.0000000000"
*MEAS_COND_COUNTER_PHABASE "38.0000000000"
*MEAS_COND_COUNTER_PHAWINDOW "16.0000000000"
*MEAS_COND_COUNTER_PHA_UNIT "div"
*MEAS_COND_COUNTER_TAUDIFF "30.0000000000"
*MEAS_COND_COUNTER_TAUINT "0.0000000000"
*MEAS_COND_IRRADIATION_MODE "OFF"
*MEAS_COND_IRRADIATION_WIDTH ""
*MEAS_COND_OPT_ATTR "集中法"
*MEAS_COND_OPT_NAME "@集中法"
*MEAS_COND_UNSYMMETRIC_MODE "OFF"
*MEAS_COND_XG_CURRENT "30.0000000000"
*MEAS_COND_XG_VOLTAGE "40.0000000000"
*MEAS_COND_XG_WAVE_TYPE "Ka"
*MEAS_DATA_COUNT "5001.0000000000"
*MEAS_SCAN_AXIS_X "2θ/θ"
*MEAS_SCAN_AXIS_X_INTERNAL "TwoThetaTheta"
*MEAS_SCAN_END_TIME "07/09/22 15:24:58"
*MEAS_SCAN_MODE "CONTINUOUS"
*MEAS_SCAN_MONITOR "0"
*MEAS_SCAN_RESOLUTION_X "0.0002"
*MEAS_SCAN_SPEED "2.5"
*MEAS_SCAN_SPEED_UNIT "deg/min"
*MEAS_SCAN_START "20.0000000000"
*MEAS_SCAN_START_TIME "07/09/22 15:03:36"
*MEAS_SCAN_STEP "0.0100000000"
*MEAS_SCAN_STOP "70.0000000000"
*MEAS_SCAN_UNIT_X "deg"
*MEAS_SCAN_UNIT_Y "counts"
*RAS_HEADER_END
*RAS_INT_START
20.0000 1023.0000 1.0000
20.0400 996.0000 1.0000
20.0800 1033.0000 1.0000
20.1200 1006.0000 1.0000
20.1600 1048.0000 1.0000
20.2000 1023.0000 1.0000
20.2400 1015.0000 1.0000
20.2800 1062.0000 1.0000
20.3200 1069.0000 1.0000
20.3600 1053.0000 1.0000
20.4000 1045.0000 1.0000
20.4400 1061.0000 1.0000
20.4800 1056.0000 1.0000
20.5200 1083.0000 1.0000
20.5600 1014.0000 1.0000
20.6000 958.0000 1.0000
20.6400 984.0000 1.0000
20.6800 1090.0000 1.0000
20.7200 969.0000 1.0000
20.7600 1087.0000 1.0000
20.8000 1029.0000 1.0000
20.8400 1072.0000 1.0000
20.8800 954.0000 1.0000
20.9200 1018.0000 1.0000
20.9600 1027.0000 1.0000
21.0000 993.0000 1.0000
21.0400 1007.0000 1.0000
21.0800 1060.0000 1.0000
21.1200 1032.0000 1.0000
21.1600 1069.0000 1.0000
21.2000 1044.0000 1.0000
21.2400 1001.0000 1.0000
21.2800 980.0000 1.0000
21.3200 1020.0000 1.0000
21.3600 1078.0000 1.0000
21.4000 1009.0000 1.0000
21.4400 1062.0000 1.0000
21.4800 1047.0000 1.0000
21.5200 1038.0000 1.0000
21.5600 1002.0000 1.0000
21.6000 1043.0000 1.0000
21.6400 1065.0000 1.0000
21.6800 1010.0000 1.0000
21.7200 1076.0000 1.0000
21.7600 1071.0000 1.0000
21.8000 1002.0000 1.0000
21.8400 976.0000 1.0000
21.8800 994.0000 1.0000
21.9200 971.0000 1.0000
21.9600 983.0000 1.0000
22.0000 999.0000 1.0000
22.0400 1034.0000 1.0000
22.0800 1017.0000 1.0000
22.1200 1058.0000 1.0000
22.1600 1015.0000 1.0000
22.2000 1052.0000 1.0000
22.2400 1029.0000 1.0000
22.2800 1050.0000 1.0000
22.3200 1016.0000 1.0000
22.3600 1031.0000 1.0000
22.4000 1012.0000 1.0000
22.4400 1040.0000 1.0000
22.4800 1006.0000 1.0000
22.5200 975.0000 1.0000
22.5600 1006.0000 1.0000
22.6000 1058.0000 1.0000
22.6400 995.0000 1.0000
22.6800 1016.0000 1.0000
22.7200 984.0000 1.0000
22.7600 1026.0000 1.0000
22.8000 1052.0000 1.0000
22.8400 1052.0000 1.0000
22.8800 1030.0000 1.0000
22.9200 1059.0000 1.0000
22.9600 1013.0000 1.0000
23.0000 1042.0000 1.0000
23.0400 1028.0000 1.0000
23.0800 1060.0000 1.0000
23.1200 1048.0000 1.0000
23.1600 1015.0000 1.0000
23.2000 968.0000 1.0000
23.2400 1014.0000 1.0000
23.2800 1014.0000 1.0000
23.3200 993.0000 1.0000
23.3600 997.0000 1.0000
23.4000 1020.0000 1.0000
23.4400 1058.0000 1.0000
23.4800 1007.0000 1.0000
23.5200 1040.0000 1.0000
23.5600 1002.0000 1.0000
23.6000 967.0000 1.0000
23.6400 1023.0000 1.0000
23.6800 1017.0000 1.0000
23.7200 1043.0000 1.0000
23.7600 1047.0000 1.0000
23.8000 1056.0000 1.0000
23.8400 1076.0000 1.0000
23.8800 1049.0000 1.0000
23.9200 1063.0000 1.0000
23.9600 1004.0000 1.0000
24.0000 1088.0000 1.0000
24.0400 1059.0000 1.0000
24.0800 1124.0000 1.0000
24.1200 1061.0000 1.0000
24.1600 1055.0000 1.0000
24.2000 1076.0000 1.0000
24.2400 1032.0000 1.0000
24.2800 1042.0000 1.0000
24.3200 1061.0000 1.0000
24.3600 993.0000 1.0000
24.4000 968.0000 1.0000
24.4400 986.0000 1.0000
24.4800 1021.0000 1.0000
24.5200 986.0000 1.0000
24.5600 1045.0000 1.0000
24.6000 978.0000 1.0000
24.6400 1024.0000 1.0000
24.6800 1062.0000 1.0000
24.7200 1027.0000 1.0000
24.7600 1003.0000 1.0000
24.8000 986.0000 1.0000
24.8400 1015.0000 1.0000
24.8800 1020.0000 1.0000
24.9200 1001.0000 1.0000
24.9600 1026.0000 1.0000
25.0000 991.0000 1.0000
25.0400 983.0000 1.0000
25.0800 1013.0000 1.0000
25.1200 1030.0000 1.0000
25.1600 969.0000 1.0000
25.2000 980.0000 1.0000
25.2400 950.0000 1.0000
25.2800 1023.0000 1.0000
25.3200 1014.0000 1.0000
25.3600 1006.0000 1.0000
25.4000 1039.0000 1.0000
25.4400 1021.0000 1.0000
25.4800 980.0000 1.0000
25.5200 1027.0000 1.0000
25.5600 976.0000 1.0000
25.6000 976.0000 1.0000
25.6400 1008.0000 1.0000
25.6800 1056.0000 1.0000
25.7200 992.0000 1.0000
25.7600 992.0000 1.0000
25.8000 1019.0000 1.0000
25.8400 1061.0000 1.0000
25.8800 1059.0000 1.0000
25.9200 1068.0000 1.0000
25.9600 1136.0000 1.0000
26.0000 1196.0000 1.0000
26.0400 1148.0000 1.0000
26.0800 1202.0000 1.0000
26.1200 1280.0000 1.0000
26.1600 1358.0000 1.0000
26.2000 1456.0000 1.0000
26.2400 1680.0000 1.0000
26.2800 1916.0000 1.0000
26.3200 2314.0000 1.0000
26.3600 2863.0000 1.0000
26.4000 3482.0000 1.0000
26.4400 3683.0000 1.0000
26.4800 3339.0000 1.0000
26.5200 2696.0000 1.0000
26.5600 2134.0000 1.0000
26.6000 1800.0000 1.0000
26.6400 1559.0000 1.0000
26.6800 1436.0000 1.0000
26.7200 1249.0000 1.0000
26.7600 1220.0000 1.0000
26.8000 1171.0000 1.0000
26.8400 1079.0000 1.0000
26.8800 1124.0000 1.0000
26.9200 1073.0000 1.0000
26.9600 1006.0000 1.0000
27.0000 994.0000 1.0000
27.0400 993.0000 1.0000
27.0800 927.0000 1.0000
27.1200 1044.0000 1.0000
27.1600 1009.0000 1.0000
27.2000 962.0000 1.0000
27.2400 946.0000 1.0000
27.2800 948.0000 1.0000
27.3200 977.0000 1.0000
27.3600 947.0000 1.0000
27.4000 960.0000 1.0000
27.4400 930.0000 1.0000
27.4800 911.0000 1.0000
27.5200 930.0000 1.0000
27.5600 904.0000 1.0000
27.6000 895.0000 1.0000
27.6400 937.0000 1.0000
27.6800 959.0000 1.0000
27.7200 930.0000 1.0000
27.7600 896.0000 1.0000
27.8000 878.0000 1.0000
27.8400 911.0000 1.0000
27.8800 941.0000 1.0000
27.9200 896.0000 1.0000
27.9600 874.0000 1.0000
28.0000 982.0000 1.0000
28.0400 909.0000 1.0000
28.0800 900.0000 1.0000
28.1200 878.0000 1.0000
28.1600 936.0000 1.0000
28.2000 901.0000 1.0000
28.2400 855.0000 1.0000
28.2800 901.0000 1.0000
28.3200 902.0000 1.0000
28.3600 872.0000 1.0000
28.4000 876.0000 1.0000
28.4400 902.0000 1.0000
28.4800 858.0000 1.0000
28.5200 881.0000 1.0000
28.5600 866.0000 1.0000
28.6000 892.0000 1.0000
28.6400 839.0000 1.0000
28.6800 895.0000 1.0000
28.7200 826.0000 1.0000
28.7600 843.0000 1.0000
28.8000 889.0000 1.0000
28.8400 834.0000 1.0000
28.8800 807.0000 1.0000
28.9200 878.0000 1.0000
28.9600 852.0000 1.0000
29.0000 862.0000 1.0000
29.0400 816.0000 1.0000
29.0800 860.0000 1.0000
29.1200 865.0000 1.0000
29.1600 794.0000 1.0000
29.2000 861.0000 1.0000
29.2400 816.0000 1.0000
29.2800 807.0000 1.0000
29.3200 867.0000 1.0000
29.3600 845.0000 1.0000
29.4000 908.0000 1.0000
29.4400 838.0000 1.0000
29.4800 843.0000 1.0000
29.5200 848.0000 1.0000
29.5600 798.0000 1.0000
29.6000 818.0000 1.0000
29.6400 819.0000 1.0000
29.6800 816.0000 1.0000
29.7200 796.0000 1.0000
29.7600 865.0000 1.0000
29.8000 841.0000 1.0000
29.8400 825.0000 1.0000
29.8800 780.0000 1.0000
29.9200 825.0000 1.0000
29.9600 799.0000 1.0000
30.0000 792.0000 1.0000
30.0400 779.0000 1.0000
30.0800 825.0000 1.0000
30.1200 792.0000 1.0000
30.1600 794.0000 1.0000
30.2000 824.0000 1.0000
30.2400 843.0000 1.0000
30.2800 802.0000 1.0000
30.3200 849.0000 1.0000
30.3600 779.0000 1.0000
30.4000 862.0000 1.0000
30.4400 792.0000 1.0000
30.4800 837.0000 1.0000
30.5200 790.0000 1.0000
30.5600 743.0000 1.0000
30.6000 767.0000 1.0000
30.6400 850.0000 1.0000
30.6800 760.0000 1.0000
30.7200 772.0000 1.0000
30.7600 832.0000 1.0000
30.8000 774.0000 1.0000
30.8400 740.0000 1.0000
30.8800 837.0000 1.0000
30.9200 781.0000 1.0000
30.9600 783.0000 1.0000
31.0000 766.0000 1.0000
31.0400 782.0000 1.0000
31.0800 770.0000 1.0000
31.1200 818.0000 1.0000
31.1600 814.0000 1.0000
31.2000 832.0000 1.0000
31.2400 813.0000 1.0000
31.2800 756.0000 1.0000
31.3200 759.0000 1.0000
31.3600 771.0000 1.0000
31.4000 791.0000 1.0000
31.4400 766.0000 1.0000
31.4800 778.0000 1.0000
31.5200 750.0000 1.0000
31.5600 757.0000 1.0000
31.6000 766.0000 1.0000
31.6400 750.0000 1.0000
31.6800 726.0000 1.0000
31.7200 735.0000 1.0000
31.7600 764.0000 1.0000
31.8000 787.0000 1.0000
31.8400 754.0000 1.0000
31.8800 766.0000 1.0000
31.9200 765.0000 1.0000
31.9600 780.0000 1.0000
32.0000 760.0000 1.0000
32.0400 731.0000 1.0000
32.0800 779.0000 1.0000
32.1200 759.0000 1.0000
32.1600 769.0000 1.0000
32.2000 771.0000 1.0000
32.2400 751.0000 1.0000
32.2800 761.0000 1.0000
32.3200 717.0000 1.0000
32.3600 720.0000 1.0000
32.4000 772.0000 1.0000
32.4400 681.0000 1.0000
32.4800 768.0000 1.0000
32.5200 756.0000 1.0000
32.5600 719.0000 1.0000
32.6000 726.0000 1.0000
32.6400 741.0000 1.0000
32.6800 730.0000 1.0000
32.7200 777.0000 1.0000
32.7600 762.0000 1.0000
32.8000 744.0000 1.0000
32.8400 781.0000 1.0000
32.8800 753.0000 1.0000
32.9200 816.0000 1.0000
32.9600 838.0000 1.0000
33.0000 845.0000 1.0000
33.0400 891.0000 1.0000
33.0800 936.0000 1.0000
33.1200 917.0000 1.0000
33.1600 907.0000 1.0000
33.2000 839.0000 1.0000
33.2400 835.0000 1.0000
33.2800 811.0000 1.0000
33.3200 872.0000 1.0000
33.3600 885.0000 1.0000
33.4000 908.0000 1.0000
33.4400 954.0000 1.0000
33.4800 1049.0000 1.0000
33.5200 1272.0000 1.0000
33.5600 1491.0000 1.0000
33.6000 1768.0000 1.0000
33.6400 1887.0000 1.0000
33.6800 1806.0000 1.0000
33.7200 1543.0000 1.0000
33.7600 1356.0000 1.0000
33.8000 1192.0000 1.0000
33.8400 1029.0000 1.0000
33.8800 891.0000 1.0000
33.9200 922.0000 1.0000
33.9600 853.0000 1.0000
34.0000 780.0000 1.0000
34.0400 804.0000 1.0000
34.0800 744.0000 1.0000
34.1200 733.0000 1.0000
34.1600 682.0000 1.0000
34.2000 717.0000 1.0000
34.2400 689.0000 1.0000
34.2800 716.0000 1.0000
34.3200 664.0000 1.0000
34.3600 663.0000 1.0000
34.4000 699.0000 1.0000
34.4400 657.0000 1.0000
34.4800 685.0000 1.0000
34.5200 653.0000 1.0000
34.5600 643.0000 1.0000
34.6000 668.0000 1.0000
34.6400 693.0000 1.0000
34.6800 667.0000 1.0000
34.7200 677.0000 1.0000
34.7600 670.0000 1.0000
34.8000 642.0000 1.0000
34.8400 642.0000 1.0000
34.8800 648.0000 1.0000
34.9200 690.0000 1.0000
34.9600 623.0000 1.0000
35.0000 647.0000 1.0000
35.0400 627.0000 1.0000
35.0800 599.0000 1.0000
35.1200 659.0000 1.0000
35.1600 633.0000 1.0000
35.2000 591.0000 1.0000
35.2400 665.0000 1.0000
35.2800 652.0000 1.0000
35.3200 661.0000 1.0000
35.3600 710.0000 1.0000
35.4000 735.0000 1.0000
35.4400 822.0000 1.0000
35.4800 997.0000 1.0000
35.5200 1179.0000 1.0000
35.5600 1268.0000 1.0000
35.6000 1101.0000 1.0000
35.6400 1047.0000 1.0000
35.6800 947.0000 1.0000
35.7200 796.0000 1.0000
35.7600 715.0000 1.0000
35.8000 630.0000 1.0000
35.8400 611.0000 1.0000
35.8800 635.0000 1.0000
35.9200 613.0000 1.0000
35.9600 616.0000 1.0000
36.0000 641.0000 1.0000
36.0400 589.0000 1.0000
36.0800 636.0000 1.0000
36.1200 608.0000 1.0000
36.1600 613.0000 1.0000
36.2000 579.0000 1.0000
36.2400 597.0000 1.0000
36.2800 602.0000 1.0000
36.3200 591.0000 1.0000
36.3600 593.0000 1.0000
36.4000 572.0000 1.0000
36.4400 566.0000 1.0000
36.4800 635.0000 1.0000
36.5200 596.0000 1.0000
36.5600 598.0000 1.0000
36.6000 572.0000 1.0000
36.6400 583.0000 1.0000
36.6800 572.0000 1.0000
36.7200 596.0000 1.0000
36.7600 594.0000 1.0000
36.8000 581.0000 1.0000
36.8400 596.0000 1.0000
36.8800 582.0000 1.0000
36.9200 584.0000 1.0000
36.9600 584.0000 1.0000
37.0000 570.0000 1.0000
37.0400 611.0000 1.0000
37.0800 593.0000 1.0000
37.1200 587.0000 1.0000
37.1600 590.0000 1.0000
37.2000 637.0000 1.0000
37.2400 670.0000 1.0000
37.2800 665.0000 1.0000
37.3200 690.0000 1.0000
37.3600 743.0000 1.0000
37.4000 787.0000 1.0000
37.4400 925.0000 1.0000
37.4800 1068.0000 1.0000
37.5200 1232.0000 1.0000
37.5600 1577.0000 1.0000
37.6000 2084.0000 1.0000
37.6400 2509.0000 1.0000
37.6800 2828.0000 1.0000
37.7200 2795.0000 1.0000
37.7600 2488.0000 1.0000
37.8000 2114.0000 1.0000
37.8400 1683.0000 1.0000
37.8800 1360.0000 1.0000
37.9200 1090.0000 1.0000
37.9600 944.0000 1.0000
38.0000 777.0000 1.0000
38.0400 721.0000 1.0000
38.0800 661.0000 1.0000
38.1200 649.0000 1.0000
38.1600 579.0000 1.0000
38.2000 567.0000 1.0000
38.2400 553.0000 1.0000
38.2800 531.0000 1.0000
38.3200 568.0000 1.0000
38.3600 540.0000 1.0000
38.4000 555.0000 1.0000
38.4400 558.0000 1.0000
38.4800 570.0000 1.0000
38.5200 531.0000 1.0000
38.5600 548.0000 1.0000
38.6000 542.0000 1.0000
38.6400 577.0000 1.0000
38.6800 552.0000 1.0000
38.7200 586.0000 1.0000
38.7600 563.0000 1.0000
38.8000 560.0000 1.0000
38.8400 548.0000 1.0000
38.8800 544.0000 1.0000
38.9200 526.0000 1.0000
38.9600 540.0000 1.0000
39.0000 529.0000 1.0000
39.0400 521.0000 1.0000
39.0800 531.0000 1.0000
39.1200 518.0000 1.0000
39.1600 522.0000 1.0000
39.2000 524.0000 1.0000
39.2400 534.0000 1.0000
39.2800 505.0000 1.0000
39.3200 516.0000 1.0000
39.3600 503.0000 1.0000
39.4000 501.0000 1.0000
39.4400 495.0000 1.0000
39.4800 488.0000 1.0000
39.5200 531.0000 1.0000
39.5600 476.0000 1.0000
39.6000 493.0000 1.0000
39.6400 479.0000 1.0000
39.6800 483.0000 1.0000
39.7200 510.0000 1.0000
39.7600 472.0000 1.0000
39.8000 527.0000 1.0000
39.8400 494.0000 1.0000
39.8800 469.0000 1.0000
39.9200 513.0000 1.0000
39.9600 492.0000 1.0000
40.0000 500.0000 1.0000
40.0400 471.0000 1.0000
40.0800 484.0000 1.0000
40.1200 524.0000 1.0000
40.1600 488.0000 1.0000
40.2000 441.0000 1.0000
40.2400 451.0000 1.0000
40.2800 518.0000 1.0000
40.3200 469.0000 1.0000
40.3600 529.0000 1.0000
40.4000 484.0000 1.0000
40.4400 518.0000 1.0000
40.4800 491.0000 1.0000
40.5200 449.0000 1.0000
40.5600 514.0000 1.0000
40.6000 491.0000 1.0000
40.6400 477.0000 1.0000
40.6800 498.0000 1.0000
40.7200 537.0000 1.0000
40.7600 514.0000 1.0000
40.8000 481.0000 1.0000
40.8400 486.0000 1.0000
40.8800 506.0000 1.0000
40.9200 482.0000 1.0000
40.9600 525.0000 1.0000
41.0000 482.0000 1.0000
41.0400 462.0000 1.0000
41.0800 490.0000 1.0000
41.1200 479.0000 1.0000
41.1600 471.0000 1.0000
41.2000 502.0000 1.0000
41.2400 481.0000 1.0000
41.2800 458.0000 1.0000
41.3200 524.0000 1.0000
41.3600 435.0000 1.0000
41.4000 523.0000 1.0000
41.4400 492.0000 1.0000
41.4800 449.0000 1.0000
41.5200 448.0000 1.0000
41.5600 485.0000 1.0000
41.6000 471.0000 1.0000
41.6400 453.0000 1.0000
41.6800 507.0000 1.0000
41.7200 445.0000 1.0000
41.7600 489.0000 1.0000
41.8000 479.0000 1.0000
41.8400 489.0000 1.0000
41.8800 464.0000 1.0000
41.9200 457.0000 1.0000
41.9600 462.0000 1.0000
42.0000 484.0000 1.0000
42.0400 496.0000 1.0000
42.0800 463.0000 1.0000
42.1200 513.0000 1.0000
42.1600 464.0000 1.0000
42.2000 505.0000 1.0000
42.2400 494.0000 1.0000
42.2800 508.0000 1.0000
42.3200 488.0000 1.0000
42.3600 522.0000 1.0000
42.4000 546.0000 1.0000
42.4400 500.0000 1.0000
42.4800 566.0000 1.0000
42.5200 507.0000 1.0000
42.5600 465.0000 1.0000
42.6000 481.0000 1.0000
42.6400 501.0000 1.0000
42.6800 444.0000 1.0000
42.7200 474.0000 1.0000
42.7600 456.0000 1.0000
42.8000 517.0000 1.0000
42.8400 472.0000 1.0000
42.8800 459.0000 1.0000
42.9200 494.0000 1.0000
42.9600 484.0000 1.0000
43.0000 456.0000 1.0000
43.0400 443.0000 1.0000
43.0800 494.0000 1.0000
43.1200 459.0000 1.0000
43.1600 460.0000 1.0000
43.2000 469.0000 1.0000
43.2400 457.0000 1.0000
43.2800 450.0000 1.0000
43.3200 439.0000 1.0000
43.3600 439.0000 1.0000
43.4000 483.0000 1.0000
43.4400 470.0000 1.0000
43.4800 441.0000 1.0000
43.5200 472.0000 1.0000
43.5600 460.0000 1.0000
43.6000 459.0000 1.0000
43.6400 479.0000 1.0000
43.6800 438.0000 1.0000
43.7200 439.0000 1.0000
43.7600 422.0000 1.0000
43.8000 452.0000 1.0000
43.8400 458.0000 1.0000
43.8800 446.0000 1.0000
43.9200 460.0000 1.0000
43.9600 415.0000 1.0000
44.0000 487.0000 1.0000
44.0400 441.0000 1.0000
44.0800 444.0000 1.0000
44.1200 451.0000 1.0000
44.1600 413.0000 1.0000
44.2000 450.0000 1.0000
44.2400 457.0000 1.0000
44.2800 445.0000 1.0000
44.3200 450.0000 1.0000
44.3600 419.0000 1.0000
44.4000 486.0000 1.0000
44.4400 448.0000 1.0000
44.4800 472.0000 1.0000
44.5200 427.0000 1.0000
44.5600 448.0000 1.0000
44.6000 451.0000 1.0000
44.6400 457.0000 1.0000
44.6800 470.0000 1.0000
44.7200 455.0000 1.0000
44.7600 406.0000 1.0000
44.8000 441.0000 1.0000
44.8400 446.0000 1.0000
44.8800 458.0000 1.0000
44.9200 414.0000 1.0000
44.9600 425.0000 1.0000
45.0000 423.0000 1.0000
45.0400 445.0000 1.0000
45.0800 476.0000 1.0000
45.1200 469.0000 1.0000
45.1600 483.0000 1.0000
45.2000 423.0000 1.0000
45.2400 435.0000 1.0000
45.2800 427.0000 1.0000
45.3200 424.0000 1.0000
45.3600 414.0000 1.0000
45.4000 420.0000 1.0000
45.4400 445.0000 1.0000
45.4800 449.0000 1.0000
45.5200 448.0000 1.0000
45.5600 437.0000 1.0000
45.6000 402.0000 1.0000
45.6400 432.0000 1.0000
45.6800 440.0000 1.0000
45.7200 413.0000 1.0000
45.7600 409.0000 1.0000
45.8000 447.0000 1.0000
45.8400 418.0000 1.0000
45.8800 435.0000 1.0000
45.9200 438.0000 1.0000
45.9600 410.0000 1.0000
46.0000 391.0000 1.0000
46.0400 456.0000 1.0000
46.0800 411.0000 1.0000
46.1200 425.0000 1.0000
46.1600 447.0000 1.0000
46.2000 427.0000 1.0000
46.2400 458.0000 1.0000
46.2800 468.0000 1.0000
46.3200 452.0000 1.0000
46.3600 428.0000 1.0000
46.4000 418.0000 1.0000
46.4400 426.0000 1.0000
46.4800 407.0000 1.0000
46.5200 406.0000 1.0000
46.5600 428.0000 1.0000
46.6000 401.0000 1.0000
46.6400 425.0000 1.0000
46.6800 424.0000 1.0000
46.7200 414.0000 1.0000
46.7600 402.0000 1.0000
46.8000 443.0000 1.0000
46.8400 434.0000 1.0000
46.8800 435.0000 1.0000
46.9200 408.0000 1.0000
46.9600 428.0000 1.0000
47.0000 424.0000 1.0000
47.0400 414.0000 1.0000
47.0800 417.0000 1.0000
47.1200 412.0000 1.0000
47.1600 460.0000 1.0000
47.2000 374.0000 1.0000
47.2400 434.0000 1.0000
47.2800 397.0000 1.0000
47.3200 430.0000 1.0000
47.3600 395.0000 1.0000
47.4000 436.0000 1.0000
47.4400 423.0000 1.0000
47.4800 403.0000 1.0000
47.5200 410.0000 1.0000
47.5600 392.0000 1.0000
47.6000 414.0000 1.0000
47.6400 398.0000 1.0000
47.6800 408.0000 1.0000
47.7200 435.0000 1.0000
47.7600 399.0000 1.0000
47.8000 397.0000 1.0000
47.8400 423.0000 1.0000
47.8800 446.0000 1.0000
47.9200 403.0000 1.0000
47.9600 403.0000 1.0000
48.0000 398.0000 1.0000
48.0400 415.0000 1.0000
48.0800 381.0000 1.0000
48.1200 384.0000 1.0000
48.1600 410.0000 1.0000
48.2000 417.0000 1.0000
48.2400 387.0000 1.0000
48.2800 386.0000 1.0000
48.3200 429.0000 1.0000
48.3600 394.0000 1.0000
48.4000 387.0000 1.0000
48.4400 404.0000 1.0000
48.4800 398.0000 1.0000
48.5200 409.0000 1.0000
48.5600 407.0000 1.0000
48.6000 433.0000 1.0000
48.6400 411.0000 1.0000
48.6800 411.0000 1.0000
48.7200 393.0000 1.0000
48.7600 413.0000 1.0000
48.8000 414.0000 1.0000
48.8400 406.0000 1.0000
48.8800 398.0000 1.0000
48.9200 405.0000 1.0000
48.9600 423.0000 1.0000
49.0000 397.0000 1.0000
49.0400 422.0000 1.0000
49.0800 403.0000 1.0000
49.1200 435.0000 1.0000
49.1600 410.0000 1.0000
49.2000 413.0000 1.0000
49.2400 427.0000 1.0000
49.2800 427.0000 1.0000
49.3200 440.0000 1.0000
49.3600 411.0000 1.0000
49.4000 430.0000 1.0000
49.4400 463.0000 1.0000
49.4800 502.0000 1.0000
49.5200 493.0000 1.0000
49.5600 449.0000 1.0000
49.6000 409.0000 1.0000
49.6400 425.0000 1.0000
49.6800 413.0000 1.0000
49.7200 409.0000 1.0000
49.7600 416.0000 1.0000
49.8000 446.0000 1.0000
49.8400 436.0000 1.0000
49.8800 398.0000 1.0000
49.9200 399.0000 1.0000
49.9600 390.0000 1.0000
50.0000 417.0000 1.0000
50.0400 403.0000 1.0000
50.0800 384.0000 1.0000
50.1200 419.0000 1.0000
50.1600 415.0000 1.0000
50.2000 411.0000 1.0000
50.2400 393.0000 1.0000
50.2800 409.0000 1.0000
50.3200 404.0000 1.0000
50.3600 400.0000 1.0000
50.4000 417.0000 1.0000
50.4400 381.0000 1.0000
50.4800 413.0000 1.0000
50.5200 392.0000 1.0000
50.5600 396.0000 1.0000
50.6000 409.0000 1.0000
50.6400 393.0000 1.0000
50.6800 434.0000 1.0000
50.7200 433.0000 1.0000
50.7600 426.0000 1.0000
50.8000 423.0000 1.0000
50.8400 399.0000 1.0000
50.8800 434.0000 1.0000
50.9200 456.0000 1.0000
50.9600 480.0000 1.0000
51.0000 448.0000 1.0000
51.0400 449.0000 1.0000
51.0800 476.0000 1.0000
51.1200 545.0000 1.0000
51.1600 594.0000 1.0000
51.2000 702.0000 1.0000
51.2400 708.0000 1.0000
51.2800 938.0000 1.0000
51.3200 1182.0000 1.0000
51.3600 1530.0000 1.0000
51.4000 2045.0000 1.0000
51.4400 2588.0000 1.0000
51.4800 2741.0000 1.0000
51.5200 2642.0000 1.0000
51.5600 2302.0000 1.0000
51.6000 2075.0000 1.0000
51.6400 1757.0000 1.0000
51.6800 1315.0000 1.0000
51.7200 984.0000 1.0000
51.7600 808.0000 1.0000
51.8000 680.0000 1.0000
51.8400 656.0000 1.0000
51.8800 545.0000 1.0000
51.9200 492.0000 1.0000
51.9600 493.0000 1.0000
52.0000 469.0000 1.0000
52.0400 483.0000 1.0000
52.0800 457.0000 1.0000
52.1200 429.0000 1.0000
52.1600 445.0000 1.0000
52.2000 436.0000 1.0000
52.2400 436.0000 1.0000
52.2800 421.0000 1.0000
52.3200 411.0000 1.0000
52.3600 436.0000 1.0000
52.4000 401.0000 1.0000
52.4400 440.0000 1.0000
52.4800 437.0000 1.0000
52.5200 415.0000 1.0000
52.5600 377.0000 1.0000
52.6000 434.0000 1.0000
52.6400 355.0000 1.0000
52.6800 396.0000 1.0000
52.7200 400.0000 1.0000
52.7600 398.0000 1.0000
52.8000 387.0000 1.0000
52.8400 380.0000 1.0000
52.8800 409.0000 1.0000
52.9200 399.0000 1.0000
52.9600 408.0000 1.0000
53.0000 413.0000 1.0000
53.0400 381.0000 1.0000
53.0800 403.0000 1.0000
53.1200 387.0000 1.0000
53.1600 391.0000 1.0000
53.2000 385.0000 1.0000
53.2400 367.0000 1.0000
53.2800 378.0000 1.0000
53.3200 402.0000 1.0000
53.3600 398.0000 1.0000
53.4000 354.0000 1.0000
53.4400 423.0000 1.0000
53.4800 381.0000 1.0000
53.5200 387.0000 1.0000
53.5600 410.0000 1.0000
53.6000 387.0000 1.0000
53.6400 416.0000 1.0000
53.6800 411.0000 1.0000
53.7200 440.0000 1.0000
53.7600 407.0000 1.0000
53.8000 421.0000 1.0000
53.8400 369.0000 1.0000
53.8800 380.0000 1.0000
53.9200 372.0000 1.0000
53.9600 426.0000 1.0000
54.0000 392.0000 1.0000
54.0400 436.0000 1.0000
54.0800 456.0000 1.0000
54.1200 420.0000 1.0000
54.1600 412.0000 1.0000
54.2000 451.0000 1.0000
54.2400 458.0000 1.0000
54.2800 441.0000 1.0000
54.3200 467.0000 1.0000
54.3600 489.0000 1.0000
54.4000 510.0000 1.0000
54.4400 569.0000 1.0000
54.4800 595.0000 1.0000
54.5200 612.0000 1.0000
54.5600 586.0000 1.0000
54.6000 564.0000 1.0000
54.6400 496.0000 1.0000
54.6800 498.0000 1.0000
54.7200 472.0000 1.0000
54.7600 468.0000 1.0000
54.8000 409.0000 1.0000
54.8400 400.0000 1.0000
54.8800 396.0000 1.0000
54.9200 380.0000 1.0000
54.9600 383.0000 1.0000
55.0000 409.0000 1.0000
55.0400 401.0000 1.0000
55.0800 388.0000 1.0000
55.1200 393.0000 1.0000
55.1600 401.0000 1.0000
55.2000 412.0000 1.0000
55.2400 372.0000 1.0000
55.2800 382.0000 1.0000
55.3200 435.0000 1.0000
55.3600 385.0000 1.0000
55.4000 406.0000 1.0000
55.4400 391.0000 1.0000
55.4800 362.0000 1.0000
55.5200 367.0000 1.0000
55.5600 417.0000 1.0000
55.6000 374.0000 1.0000
55.6400 375.0000 1.0000
55.6800 380.0000 1.0000
55.7200 340.0000 1.0000
55.7600 380.0000 1.0000
55.8000 367.0000 1.0000
55.8400 372.0000 1.0000
55.8800 374.0000 1.0000
55.9200 382.0000 1.0000
55.9600 360.0000 1.0000
56.0000 393.0000 1.0000
56.0400 368.0000 1.0000
56.0800 404.0000 1.0000
56.1200 364.0000 1.0000
56.1600 370.0000 1.0000
56.2000 374.0000 1.0000
56.2400 365.0000 1.0000
56.2800 362.0000 1.0000
56.3200 377.0000 1.0000
56.3600 356.0000 1.0000
56.4000 370.0000 1.0000
56.4400 388.0000 1.0000
56.4800 357.0000 1.0000
56.5200 349.0000 1.0000
56.5600 386.0000 1.0000
56.6000 389.0000 1.0000
56.6400 369.0000 1.0000
56.6800 346.0000 1.0000
56.7200 381.0000 1.0000
56.7600 366.0000 1.0000
56.8000 369.0000 1.0000
56.8400 374.0000 1.0000
56.8800 369.0000 1.0000
56.9200 383.0000 1.0000
56.9600 392.0000 1.0000
57.0000 374.0000 1.0000
57.0400 379.0000 1.0000
57.0800 395.0000 1.0000
57.1200 374.0000 1.0000
57.1600 374.0000 1.0000
57.2000 363.0000 1.0000
57.2400 373.0000 1.0000
57.2800 368.0000 1.0000
57.3200 371.0000 1.0000
57.3600 380.0000 1.0000
57.4000 370.0000 1.0000
57.4400 402.0000 1.0000
57.4800 377.0000 1.0000
57.5200 400.0000 1.0000
57.5600 394.0000 1.0000
57.6000 370.0000 1.0000
57.6400 376.0000 1.0000
57.6800 354.0000 1.0000
57.7200 407.0000 1.0000
57.7600 356.0000 1.0000
57.8000 361.0000 1.0000
57.8400 368.0000 1.0000
57.8800 347.0000 1.0000
57.9200 391.0000 1.0000
57.9600 396.0000 1.0000
58.0000 388.0000 1.0000
58.0400 373.0000 1.0000
58.0800 332.0000 1.0000
58.1200 370.0000 1.0000
58.1600 403.0000 1.0000
58.2000 358.0000 1.0000
58.2400 358.0000 1.0000
58.2800 379.0000 1.0000
58.3200 369.0000 1.0000
58.3600 361.0000 1.0000
58.4000 374.0000 1.0000
58.4400 361.0000 1.0000
58.4800 392.0000 1.0000
58.5200 367.0000 1.0000
58.5600 366.0000 1.0000
58.6000 382.0000 1.0000
58.6400 371.0000 1.0000
58.6800 380.0000 1.0000
58.7200 372.0000 1.0000
58.7600 352.0000 1.0000
58.8000 380.0000 1.0000
58.8400 377.0000 1.0000
58.8800 364.0000 1.0000
58.9200 376.0000 1.0000
58.9600 356.0000 1.0000
59.0000 380.0000 1.0000
59.0400 378.0000 1.0000
59.0800 349.0000 1.0000
59.1200 365.0000 1.0000
59.1600 356.0000 1.0000
59.2000 387.0000 1.0000
59.2400 393.0000 1.0000
59.2800 339.0000 1.0000
59.3200 402.0000 1.0000
59.3600 364.0000 1.0000
59.4000 389.0000 1.0000
59.4400 398.0000 1.0000
59.4800 348.0000 1.0000
59.5200 377.0000 1.0000
59.5600 359.0000 1.0000
59.6000 381.0000 1.0000
59.6400 366.0000 1.0000
59.6800 335.0000 1.0000
59.7200 398.0000 1.0000
59.7600 346.0000 1.0000
59.8000 389.0000 1.0000
59.8400 371.0000 1.0000
59.8800 331.0000 1.0000
59.9200 376.0000 1.0000
59.9600 354.0000 1.0000
60.0000 392.0000 1.0000
60.0400 346.0000 1.0000
60.0800 359.0000 1.0000
60.1200 383.0000 1.0000
60.1600 364.0000 1.0000
60.2000 349.0000 1.0000
60.2400 372.0000 1.0000
60.2800 371.0000 1.0000
60.3200 371.0000 1.0000
60.3600 366.0000 1.0000
60.4000 364.0000 1.0000
60.4400 371.0000 1.0000
60.4800 365.0000 1.0000
60.5200 360.0000 1.0000
60.5600 345.0000 1.0000
60.6000 361.0000 1.0000
60.6400 363.0000 1.0000
60.6800 400.0000 1.0000
60.7200 369.0000 1.0000
60.7600 373.0000 1.0000
60.8000 367.0000 1.0000
60.8400 350.0000 1.0000
60.8800 345.0000 1.0000
60.9200 355.0000 1.0000
60.9600 371.0000 1.0000
61.0000 384.0000 1.0000
61.0400 414.0000 1.0000
61.0800 403.0000 1.0000
61.1200 416.0000 1.0000
61.1600 427.0000 1.0000
61.2000 437.0000 1.0000
61.2400 496.0000 1.0000
61.2800 474.0000 1.0000
61.3200 520.0000 1.0000
61.3600 552.0000 1.0000
61.4000 631.0000 1.0000
61.4400 697.0000 1.0000
61.4800 730.0000 1.0000
61.5200 722.0000 1.0000
61.5600 757.0000 1.0000
61.6000 723.0000 1.0000
61.6400 721.0000 1.0000
61.6800 717.0000 1.0000
61.7200 621.0000 1.0000
61.7600 578.0000 1.0000
61.8000 561.0000 1.0000
61.8400 515.0000 1.0000
61.8800 470.0000 1.0000
61.9200 492.0000 1.0000
61.9600 412.0000 1.0000
62.0000 422.0000 1.0000
62.0400 422.0000 1.0000
62.0800 415.0000 1.0000
62.1200 402.0000 1.0000
62.1600 429.0000 1.0000
62.2000 416.0000 1.0000
62.2400 442.0000 1.0000
62.2800 422.0000 1.0000
62.3200 404.0000 1.0000
62.3600 440.0000 1.0000
62.4000 405.0000 1.0000
62.4400 412.0000 1.0000
62.4800 452.0000 1.0000
62.5200 391.0000 1.0000
62.5600 365.0000 1.0000
62.6000 390.0000 1.0000
62.6400 371.0000 1.0000
62.6800 385.0000 1.0000
62.7200 352.0000 1.0000
62.7600 362.0000 1.0000
62.8000 397.0000 1.0000
62.8400 363.0000 1.0000
62.8800 352.0000 1.0000
62.9200 331.0000 1.0000
62.9600 366.0000 1.0000
63.0000 363.0000 1.0000
63.0400 398.0000 1.0000
63.0800 360.0000 1.0000
63.1200 359.0000 1.0000
63.1600 391.0000 1.0000
63.2000 390.0000 1.0000
63.2400 391.0000 1.0000
63.2800 352.0000 1.0000
63.3200 364.0000 1.0000
63.3600 368.0000 1.0000
63.4000 341.0000 1.0000
63.4400 384.0000 1.0000
63.4800 350.0000 1.0000
63.5200 381.0000 1.0000
63.5600 373.0000 1.0000
63.6000 384.0000 1.0000
63.6400 409.0000 1.0000
63.6800 391.0000 1.0000
63.7200 410.0000 1.0000
63.7600 416.0000 1.0000
63.8000 428.0000 1.0000
63.8400 454.0000 1.0000
63.8800 559.0000 1.0000
63.9200 601.0000 1.0000
63.9600 599.0000 1.0000
64.0000 541.0000 1.0000
64.0400 501.0000 1.0000
64.0800 534.0000 1.0000
64.1200 480.0000 1.0000
64.1600 482.0000 1.0000
64.2000 439.0000 1.0000
64.2400 405.0000 1.0000
64.2800 435.0000 1.0000
64.3200 370.0000 1.0000
64.3600 431.0000 1.0000
64.4000 400.0000 1.0000
64.4400 376.0000 1.0000
64.4800 401.0000 1.0000
64.5200 385.0000 1.0000
64.5600 379.0000 1.0000
64.6000 381.0000 1.0000
64.6400 396.0000 1.0000
64.6800 371.0000 1.0000
64.7200 388.0000 1.0000
64.7600 368.0000 1.0000
64.8000 389.0000 1.0000
64.8400 383.0000 1.0000
64.8800 417.0000 1.0000
64.9200 374.0000 1.0000
64.9600 411.0000 1.0000
65.0000 372.0000 1.0000
65.0400 390.0000 1.0000
65.0800 415.0000 1.0000
65.1200 507.0000 1.0000
65.1600 433.0000 1.0000
65.2000 523.0000 1.0000
65.2400 513.0000 1.0000
65.2800 581.0000 1.0000
65.3200 664.0000 1.0000
65.3600 730.0000 1.0000
65.4000 906.0000 1.0000
65.4400 1082.0000 1.0000
65.4800 1249.0000 1.0000
65.5200 1363.0000 1.0000
65.5600 1317.0000 1.0000
65.6000 1298.0000 1.0000
65.6400 1214.0000 1.0000
65.6800 1133.0000 1.0000
65.7200 1043.0000 1.0000
65.7600 927.0000 1.0000
65.8000 756.0000 1.0000
65.8400 685.0000 1.0000
65.8800 594.0000 1.0000
65.9200 581.0000 1.0000
65.9600 448.0000 1.0000
66.0000 429.0000 1.0000
66.0400 430.0000 1.0000
66.0800 419.0000 1.0000
66.1200 421.0000 1.0000
66.1600 407.0000 1.0000
66.2000 380.0000 1.0000
66.2400 361.0000 1.0000
66.2800 394.0000 1.0000
66.3200 351.0000 1.0000
66.3600 368.0000 1.0000
66.4000 354.0000 1.0000
66.4400 342.0000 1.0000
66.4800 365.0000 1.0000
66.5200 342.0000 1.0000
66.5600 348.0000 1.0000
66.6000 320.0000 1.0000
66.6400 348.0000 1.0000
66.6800 353.0000 1.0000
66.7200 352.0000 1.0000
66.7600 345.0000 1.0000
66.8000 337.0000 1.0000
66.8400 363.0000 1.0000
66.8800 328.0000 1.0000
66.9200 345.0000 1.0000
66.9600 355.0000 1.0000
67.0000 347.0000 1.0000
67.0400 333.0000 1.0000
67.0800 338.0000 1.0000
67.1200 333.0000 1.0000
67.1600 349.0000 1.0000
67.2000 332.0000 1.0000
67.2400 315.0000 1.0000
67.2800 357.0000 1.0000
67.3200 351.0000 1.0000
67.3600 335.0000 1.0000
67.4000 320.0000 1.0000
67.4400 321.0000 1.0000
67.4800 322.0000 1.0000
67.5200 345.0000 1.0000
67.5600 356.0000 1.0000
67.6000 325.0000 1.0000
67.6400 353.0000 1.0000
67.6800 335.0000 1.0000
67.7200 369.0000 1.0000
67.7600 335.0000 1.0000
67.8000 348.0000 1.0000
67.8400 330.0000 1.0000
67.8800 354.0000 1.0000
67.9200 319.0000 1.0000
67.9600 285.0000 1.0000
68.0000 311.0000 1.0000
68.0400 304.0000 1.0000
68.0800 329.0000 1.0000
68.1200 356.0000 1.0000
68.1600 351.0000 1.0000
68.2000 318.0000 1.0000
68.2400 328.0000 1.0000
68.2800 335.0000 1.0000
68.3200 338.0000 1.0000
68.3600 327.0000 1.0000
68.4000 323.0000 1.0000
68.4400 311.0000 1.0000
68.4800 315.0000 1.0000
68.5200 307.0000 1.0000
68.5600 336.0000 1.0000
68.6000 334.0000 1.0000
68.6400 341.0000 1.0000
68.6800 327.0000 1.0000
68.7200 335.0000 1.0000
68.7600 335.0000 1.0000
68.8000 303.0000 1.0000
68.8400 336.0000 1.0000
68.8800 313.0000 1.0000
68.9200 372.0000 1.0000
68.9600 298.0000 1.0000
69.0000 316.0000 1.0000
69.0400 303.0000 1.0000
69.0800 310.0000 1.0000
69.1200 321.0000 1.0000
69.1600 330.0000 1.0000
69.2000 288.0000 1.0000
69.2400 300.0000 1.0000
69.2800 335.0000 1.0000
69.3200 303.0000 1.0000
69.3600 327.0000 1.0000
69.4000 315.0000 1.0000
69.4400 337.0000 1.0000
69.4800 344.0000 1.0000
69.5200 335.0000 1.0000
69.5600 343.0000 1.0000
69.6000 317.0000 1.0000
69.6400 331.0000 1.0000
69.6800 324.0000 1.0000
69.7200 299.0000 1.0000
69.7600 324.0000 1.0000
69.8000 341.0000 1.0000
69.8400 332.0000 1.0000
69.8800 315.0000 1.0000
69.9200 291.0000 1.0000
69.9600 324.0000 1.0000
70.0000 317.0000 1.0000
*RAS_INT_END
*RAS_TEMPERATURE_START
*RAS_TEMPERATURE_END
*RAS_DATA_END