File: Data/Dataset1_Only_water/5_XRD/No_039_100℃S3_3.ras
*RAS_DATA_START
*RAS_HEADER_START
*DISP_FMT_X "%.2f"
*DISP_FMT_Y "%.0f"
*DISP_FULLSCALE "12285.0000000000"
*DISP_LINE_COLOR "255.0000000000"
*DISP_LINE_STYLE "0.0000000000"
*DISP_LINE_WIDTH "0.2500000000"
*DISP_NOTE "測定データ-2"
*DISP_OFFSET_Y "0.0000000000"
*DISP_PEAKSEARCH_UNIT_Y "cps"
*DISP_RANGE_BOTTOM "0.0000000000"
*DISP_RANGE_LEFT "20.0000000000"
*DISP_RANGE_LOGCUTOFF "0.0100000000"
*DISP_RANGE_RIGHT "70.0000000000"
*DISP_RANGE_TOP "12285.0000000000"
*DISP_SCALE_MODE_Y "0.0000000000"
*DISP_TAB_NAME "2θ/θ"
*DISP_TITLE_Y "強度"
*DISP_UNIT_Y "cps"
*DISP_WINDOW_NAME "MSG_MACROENGINE"
*FILE_COMMENT " "
*FILE_MD5 ""
*FILE_MEMO " "
*FILE_OPERATOR "Administrator"
*FILE_SAMPLE " "
*FILE_TYPE "RAS_RAW"
*FILE_USERGROUP "システムマネージャ"
*FILE_VERSION "1.0000000000"
*HW_ATTACHMENT_ID "ATT0025"
*HW_ATTACHMENT_NAME "標準|Standard"
*HW_COUNTER_ID-0 "CUT0025"
*HW_COUNTER_ID-1 "CUT0020"
*HW_COUNTER_ID-2 "CUT0020"
*HW_COUNTER_ID-3 "CSL0021"
*HW_COUNTER_ID-4 "CMC0021"
*HW_COUNTER_NAME-0 "D/teX Ultra|D/teX Ultra"
*HW_COUNTER_NAME-1 "None|None"
*HW_COUNTER_NAME-2 "None|None"
*HW_COUNTER_NAME-3 "BBM|BBM"
*HW_COUNTER_NAME-4 "検出器モノクロメータ|Detector monochromator"
*HW_COUNTER_SELECT_NAME "D/teX Ultra|D/teX Ultra"
*HW_GONIOMETER_ID "GON0023"
*HW_GONIOMETER_NAME "SmartLab|SmartLab"
*HW_GONIOMETER_RADIUS-0 "90.0"
*HW_GONIOMETER_RADIUS-1 "114.0"
*HW_GONIOMETER_RADIUS-2 "190.0"
*HW_GONIOMETER_RADIUS-3 "300.0"
*HW_GONIOMETER_RADIUS-4 "187.0"
*HW_GONIOMETER_RADIUS-5 "300.0"
*HW_GONIOMETER_RADIUS-6 "113.0"
*HW_GONIOMETER_RADIUS-7 "331.0"
*HW_I_OPT_ID-0 "CBO0021"
*HW_I_OPT_ID-1 "ICR0023"
*HW_I_OPT_ID-2 "ISL0021"
*HW_I_OPT_ID-3 "ISO0021"
*HW_I_OPT_ID-4 "IAD0021"
*HW_I_OPT_ID-5 "IPR0001"
*HW_I_OPT_NAME-0 "CBOユニット|CBO unit"
*HW_I_OPT_NAME-1 "標準入射光学ユニット|Standard incident optical unit"
*HW_I_OPT_NAME-2 "標準入射スリットボックス|Standard incident slit box"
*HW_I_OPT_NAME-3 "入射平行スリット|Incident parallel slit"
*HW_I_OPT_NAME-4 "長手制限スリット|Length limiting slit"
*HW_I_OPT_NAME-5 "None|None"
*HW_R_ATTENUATER_AUTOMODE "0"
*HW_R_OPT_ID-0 "RSS0021"
*HW_R_OPT_ID-1 "RCR0023"
*HW_R_OPT_ID-2 "RSO0021"
*HW_R_OPT_ID-3 "RRS0021"
*HW_R_OPT_ID-4 "ATN0021"
*HW_R_OPT_ID-5 "RFL0021"
*HW_R_OPT_ID-6 "RAD0021"
*HW_R_OPT_NAME-0 "標準受光スリットボックス1|Standard receiving slit box # 1"
*HW_R_OPT_NAME-1 "標準受光光学ユニット1|Standard receiving unit # 1"
*HW_R_OPT_NAME-2 "標準受光光学ユニット2|Standard receiving optical unit # 2"
*HW_R_OPT_NAME-3 "標準受光スリットボックス2|Standard receiving slit box # 2"
*HW_R_OPT_NAME-4 "標準アッテネータ|Standard Attenuator"
*HW_R_OPT_NAME-5 "Cu Kβ|Cu K-beta"
*HW_R_OPT_NAME-6 "調整用受光スリット|Alignment receiving slit"
*HW_SAMPLE_HOLDER_ID "SMP0023"
*HW_SAMPLE_HOLDER_NAME "標準Zステージ|Standard Z stage"
*HW_XG_CURRENT_MAX "50"
*HW_XG_CURRENT_MIN "2"
*HW_XG_CURRENT_RESOLUTION "1"
*HW_XG_CURRENT_UNIT "mA"
*HW_XG_FOCUS "1mm x 10mm"
*HW_XG_FOCUS_TYPE "Normal"
*HW_XG_ID ""
*HW_XG_NAME "3kW 封入管(ID:1200)|3kW Sealed tube(ID:1200)"
*HW_XG_TARGET_ATOMIC_NUMBER "29.0000000000"
*HW_XG_TARGET_NAME "Cu"
*HW_XG_TYPE "Hermetic"
*HW_XG_VOLTAGE_MAX "60"
*HW_XG_VOLTAGE_MIN "20"
*HW_XG_VOLTAGE_RESOLUTION "1"
*HW_XG_VOLTAGE_UNIT "kV"
*HW_XG_WATT_MAX "1.500"
*HW_XG_WATT_UNIT "kW"
*HW_XG_WAVE_LENGTH_ALPHA1 "1.540593"
*HW_XG_WAVE_LENGTH_ALPHA2 "1.544414"
*HW_XG_WAVE_LENGTH_BETA "1.392250"
*MEAS_COND_AXIS_NAME-0 "2θ/θ"
*MEAS_COND_AXIS_NAME-1 "2θ"
*MEAS_COND_AXIS_NAME-2 "ω"
*MEAS_COND_AXIS_NAME-3 "Z"
*MEAS_COND_AXIS_NAME-4 "2θ/ω"
*MEAS_COND_AXIS_NAME-5 "θs"
*MEAS_COND_AXIS_NAME-6 "θd"
*MEAS_COND_AXIS_NAME-7 "Ts"
*MEAS_COND_AXIS_NAME-8 "CBO選択スリット"
*MEAS_COND_AXIS_NAME-9 "M"
*MEAS_COND_AXIS_NAME-10 "入射平行スリット"
*MEAS_COND_AXIS_NAME-11 "入射スリット"
*MEAS_COND_AXIS_NAME-12 ""
*MEAS_COND_AXIS_NAME-13 "Zs"
*MEAS_COND_AXIS_NAME-14 "入射光学素子"
*MEAS_COND_AXIS_NAME-15 "長手制限スリット"
*MEAS_COND_AXIS_NAME-16 "センタースリット"
*MEAS_COND_AXIS_NAME-17 "フィルター"
*MEAS_COND_AXIS_NAME-18 "受光スリット1"
*MEAS_COND_AXIS_NAME-19 "受光スリット2"
*MEAS_COND_AXIS_NAME-20 "受光光学素子"
*MEAS_COND_AXIS_NAME-21 "受光平行スリット"
*MEAS_COND_AXIS_NAME-22 "調整用受光スリット"
*MEAS_COND_AXIS_NAME-23 ""
*MEAS_COND_AXIS_NAME-24 ""
*MEAS_COND_AXIS_NAME-25 "Zd"
*MEAS_COND_AXIS_NAME-26 "アッテネータ"
*MEAS_COND_AXIS_NAME-27 "検出器モノクロメータ"
*MEAS_COND_AXIS_NAME-28 "モノクロメータスリット"
*MEAS_COND_AXIS_NAME-29 "プライマリビーム"
*MEAS_COND_AXIS_NAME-30 "PHA"
*MEAS_COND_AXIS_NAME_INTERNAL-0 "TwoThetaTheta"
*MEAS_COND_AXIS_NAME_INTERNAL-1 "TwoTheta"
*MEAS_COND_AXIS_NAME_INTERNAL-2 "Omega"
*MEAS_COND_AXIS_NAME_INTERNAL-3 "Z"
*MEAS_COND_AXIS_NAME_INTERNAL-4 "TwoThetaOmega"
*MEAS_COND_AXIS_NAME_INTERNAL-5 "ThetaS"
*MEAS_COND_AXIS_NAME_INTERNAL-6 "ThetaD"
*MEAS_COND_AXIS_NAME_INTERNAL-7 "Ts"
*MEAS_COND_AXIS_NAME_INTERNAL-8 "CBO"
*MEAS_COND_AXIS_NAME_INTERNAL-9 "CBO-M"
*MEAS_COND_AXIS_NAME_INTERNAL-10 "IncidentSollerSlit"
*MEAS_COND_AXIS_NAME_INTERNAL-11 "IncidentSlitBox"
*MEAS_COND_AXIS_NAME_INTERNAL-12 "IncidentSlitBox-_Axis"
*MEAS_COND_AXIS_NAME_INTERNAL-13 "Zs"
*MEAS_COND_AXIS_NAME_INTERNAL-14 "IncidentMonochromator"
*MEAS_COND_AXIS_NAME_INTERNAL-15 "IncidentAxdSlit"
*MEAS_COND_AXIS_NAME_INTERNAL-16 "CenterSlit"
*MEAS_COND_AXIS_NAME_INTERNAL-17 "Filter"
*MEAS_COND_AXIS_NAME_INTERNAL-18 "ReceivingSlitBox1"
*MEAS_COND_AXIS_NAME_INTERNAL-19 "ReceivingSlitBox2"
*MEAS_COND_AXIS_NAME_INTERNAL-20 "ReceivingOptics"
*MEAS_COND_AXIS_NAME_INTERNAL-21 "ReceivingSollerSlit"
*MEAS_COND_AXIS_NAME_INTERNAL-22 "ReceivingAxdSlit"
*MEAS_COND_AXIS_NAME_INTERNAL-23 "ReceivingSlitBox1-_Axis"
*MEAS_COND_AXIS_NAME_INTERNAL-24 "ReceivingSlitBox2-_Axis"
*MEAS_COND_AXIS_NAME_INTERNAL-25 "ReceivingSlitBox2-Zd"
*MEAS_COND_AXIS_NAME_INTERNAL-26 "Attenuator"
*MEAS_COND_AXIS_NAME_INTERNAL-27 "CounterMonochromator"
*MEAS_COND_AXIS_NAME_INTERNAL-28 "CounterSlit"
*MEAS_COND_AXIS_NAME_INTERNAL-29 "IncidentPrimary"
*MEAS_COND_AXIS_NAME_INTERNAL-30 "PHA"
*MEAS_COND_AXIS_NAME_MAGICNO-0 "83951616.0000000000"
*MEAS_COND_AXIS_NAME_MAGICNO-1 "268632064.0000000000"
*MEAS_COND_AXIS_NAME_MAGICNO-2 "268500992.0000000000"
*MEAS_COND_AXIS_NAME_MAGICNO-3 "285278208.0000000000"
*MEAS_COND_AXIS_NAME_MAGICNO-4 "83951616.0000000000"
*MEAS_COND_AXIS_NAME_MAGICNO-5 "131072.0000000000"
*MEAS_COND_AXIS_NAME_MAGICNO-6 "131072.0000000000"
*MEAS_COND_AXIS_NAME_MAGICNO-7 "318898176.0000000000"
*MEAS_COND_AXIS_NAME_MAGICNO-8 "20971521.0000000000"
*MEAS_COND_AXIS_NAME_MAGICNO-9 "285343744.0000000000"
*MEAS_COND_AXIS_NAME_MAGICNO-10 "20971521.0000000000"
*MEAS_COND_AXIS_NAME_MAGICNO-11 "22020097.0000000000"
*MEAS_COND_AXIS_NAME_MAGICNO-12 "25165824.0000000000"
*MEAS_COND_AXIS_NAME_MAGICNO-13 "318898176.0000000000"
*MEAS_COND_AXIS_NAME_MAGICNO-14 "1.0000000000"
*MEAS_COND_AXIS_NAME_MAGICNO-15 "20971521.0000000000"
*MEAS_COND_AXIS_NAME_MAGICNO-16 "20971521.0000000000"
*MEAS_COND_AXIS_NAME_MAGICNO-17 "20971521.0000000000"
*MEAS_COND_AXIS_NAME_MAGICNO-18 "23068673.0000000000"
*MEAS_COND_AXIS_NAME_MAGICNO-19 "23068673.0000000000"
*MEAS_COND_AXIS_NAME_MAGICNO-20 "20971521.0000000000"
*MEAS_COND_AXIS_NAME_MAGICNO-21 "20971521.0000000000"
*MEAS_COND_AXIS_NAME_MAGICNO-22 "20971521.0000000000"
*MEAS_COND_AXIS_NAME_MAGICNO-23 "25165824.0000000000"
*MEAS_COND_AXIS_NAME_MAGICNO-24 "25165824.0000000000"
*MEAS_COND_AXIS_NAME_MAGICNO-25 "285343744.0000000000"
*MEAS_COND_AXIS_NAME_MAGICNO-26 "17301505.0000000000"
*MEAS_COND_AXIS_NAME_MAGICNO-27 "20971521.0000000000"
*MEAS_COND_AXIS_NAME_MAGICNO-28 "20971521.0000000000"
*MEAS_COND_AXIS_NAME_MAGICNO-29 "20971521.0000000000"
*MEAS_COND_AXIS_NAME_MAGICNO-30 "0.0000000000"
*MEAS_COND_AXIS_OFFSET-0 "-"
*MEAS_COND_AXIS_OFFSET-1 "-0.1081000000"
*MEAS_COND_AXIS_OFFSET-2 "0.3758000000"
*MEAS_COND_AXIS_OFFSET-3 "-"
*MEAS_COND_AXIS_OFFSET-4 "-"
*MEAS_COND_AXIS_OFFSET-5 "0.3758000000"
*MEAS_COND_AXIS_OFFSET-6 "-0.4839000000"
*MEAS_COND_AXIS_OFFSET-7 "-"
*MEAS_COND_AXIS_OFFSET-8 "-"
*MEAS_COND_AXIS_OFFSET-9 "-"
*MEAS_COND_AXIS_OFFSET-10 "-"
*MEAS_COND_AXIS_OFFSET-11 "-"
*MEAS_COND_AXIS_OFFSET-12 "-"
*MEAS_COND_AXIS_OFFSET-13 "-"
*MEAS_COND_AXIS_OFFSET-14 "-"
*MEAS_COND_AXIS_OFFSET-15 "-"
*MEAS_COND_AXIS_OFFSET-16 "-"
*MEAS_COND_AXIS_OFFSET-17 "-"
*MEAS_COND_AXIS_OFFSET-18 "-"
*MEAS_COND_AXIS_OFFSET-19 "-"
*MEAS_COND_AXIS_OFFSET-20 "-"
*MEAS_COND_AXIS_OFFSET-21 "-"
*MEAS_COND_AXIS_OFFSET-22 "-"
*MEAS_COND_AXIS_OFFSET-23 "-"
*MEAS_COND_AXIS_OFFSET-24 "-"
*MEAS_COND_AXIS_OFFSET-25 "-"
*MEAS_COND_AXIS_OFFSET-26 "-"
*MEAS_COND_AXIS_OFFSET-27 "-"
*MEAS_COND_AXIS_OFFSET-28 "-"
*MEAS_COND_AXIS_OFFSET-29 "-"
*MEAS_COND_AXIS_OFFSET-30 "-"
*MEAS_COND_AXIS_POSITION-0 "0.0000000000"
*MEAS_COND_AXIS_POSITION-1 "0.0000000000"
*MEAS_COND_AXIS_POSITION-2 "0.0000000000"
*MEAS_COND_AXIS_POSITION-3 "-0.5500000000"
*MEAS_COND_AXIS_POSITION-4 "0.0000000000"
*MEAS_COND_AXIS_POSITION-5 "0.0000000000"
*MEAS_COND_AXIS_POSITION-6 "0.0000000000"
*MEAS_COND_AXIS_POSITION-7 "-0.4278800000"
*MEAS_COND_AXIS_POSITION-8 "BB"
*MEAS_COND_AXIS_POSITION-9 "0.0000000000"
*MEAS_COND_AXIS_POSITION-10 "Soller_slit_5.0deg"
*MEAS_COND_AXIS_POSITION-11 "2/3deg"
*MEAS_COND_AXIS_POSITION-12 "2.2088000000"
*MEAS_COND_AXIS_POSITION-13 "-0.4140600000"
*MEAS_COND_AXIS_POSITION-14 "0.0000000000"
*MEAS_COND_AXIS_POSITION-15 "10.0mm"
*MEAS_COND_AXIS_POSITION-16 "None"
*MEAS_COND_AXIS_POSITION-17 "Cu_K-beta"
*MEAS_COND_AXIS_POSITION-18 "13.000mm"
*MEAS_COND_AXIS_POSITION-19 "13.000mm"
*MEAS_COND_AXIS_POSITION-20 "No_unit"
*MEAS_COND_AXIS_POSITION-21 "Soller_slit_5.0deg"
*MEAS_COND_AXIS_POSITION-22 "None"
*MEAS_COND_AXIS_POSITION-23 "13.0000000000"
*MEAS_COND_AXIS_POSITION-24 "13.0000000000"
*MEAS_COND_AXIS_POSITION-25 "0.0109400000"
*MEAS_COND_AXIS_POSITION-26 "Open"
*MEAS_COND_AXIS_POSITION-27 "None"
*MEAS_COND_AXIS_POSITION-28 "None"
*MEAS_COND_AXIS_POSITION-29 "None"
*MEAS_COND_AXIS_POSITION-30 "38.0000000000"
*MEAS_COND_AXIS_UNIT-0 "deg"
*MEAS_COND_AXIS_UNIT-1 "deg"
*MEAS_COND_AXIS_UNIT-2 "deg"
*MEAS_COND_AXIS_UNIT-3 "mm"
*MEAS_COND_AXIS_UNIT-4 "deg"
*MEAS_COND_AXIS_UNIT-5 "deg"
*MEAS_COND_AXIS_UNIT-6 "deg"
*MEAS_COND_AXIS_UNIT-7 "mm"
*MEAS_COND_AXIS_UNIT-8 ""
*MEAS_COND_AXIS_UNIT-9 "pulse"
*MEAS_COND_AXIS_UNIT-10 ""
*MEAS_COND_AXIS_UNIT-11 ""
*MEAS_COND_AXIS_UNIT-12 "mm"
*MEAS_COND_AXIS_UNIT-13 "mm"
*MEAS_COND_AXIS_UNIT-14 ""
*MEAS_COND_AXIS_UNIT-15 ""
*MEAS_COND_AXIS_UNIT-16 ""
*MEAS_COND_AXIS_UNIT-17 ""
*MEAS_COND_AXIS_UNIT-18 ""
*MEAS_COND_AXIS_UNIT-19 ""
*MEAS_COND_AXIS_UNIT-20 ""
*MEAS_COND_AXIS_UNIT-21 ""
*MEAS_COND_AXIS_UNIT-22 ""
*MEAS_COND_AXIS_UNIT-23 "mm"
*MEAS_COND_AXIS_UNIT-24 "mm"
*MEAS_COND_AXIS_UNIT-25 "mm"
*MEAS_COND_AXIS_UNIT-26 ""
*MEAS_COND_AXIS_UNIT-27 ""
*MEAS_COND_AXIS_UNIT-28 ""
*MEAS_COND_AXIS_UNIT-29 ""
*MEAS_COND_AXIS_UNIT-30 "div"
*MEAS_COND_COUNTER_CNTLOSS_CORR "0.0000000000"
*MEAS_COND_COUNTER_PHABASE "38.0000000000"
*MEAS_COND_COUNTER_PHAWINDOW "16.0000000000"
*MEAS_COND_COUNTER_PHA_UNIT "div"
*MEAS_COND_COUNTER_TAUDIFF "30.0000000000"
*MEAS_COND_COUNTER_TAUINT "0.0000000000"
*MEAS_COND_IRRADIATION_MODE "OFF"
*MEAS_COND_IRRADIATION_WIDTH ""
*MEAS_COND_OPT_ATTR "集中法"
*MEAS_COND_OPT_NAME "@集中法"
*MEAS_COND_UNSYMMETRIC_MODE "OFF"
*MEAS_COND_XG_CURRENT "30.0000000000"
*MEAS_COND_XG_VOLTAGE "40.0000000000"
*MEAS_COND_XG_WAVE_TYPE "Ka"
*MEAS_DATA_COUNT "5001.0000000000"
*MEAS_SCAN_AXIS_X "2θ/θ"
*MEAS_SCAN_AXIS_X_INTERNAL "TwoThetaTheta"
*MEAS_SCAN_END_TIME "08/03/21 11:58:08"
*MEAS_SCAN_MODE "CONTINUOUS"
*MEAS_SCAN_MONITOR "0"
*MEAS_SCAN_RESOLUTION_X "0.0002"
*MEAS_SCAN_SPEED "2.5"
*MEAS_SCAN_SPEED_UNIT "deg/min"
*MEAS_SCAN_START "20.0000000000"
*MEAS_SCAN_START_TIME "08/03/21 11:36:45"
*MEAS_SCAN_STEP "0.0100000000"
*MEAS_SCAN_STOP "70.0000000000"
*MEAS_SCAN_UNIT_X "deg"
*MEAS_SCAN_UNIT_Y "counts"
*RAS_HEADER_END
*RAS_INT_START
20.0000 654.0000 1.0000
20.0400 613.0000 1.0000
20.0800 592.0000 1.0000
20.1200 641.0000 1.0000
20.1600 607.0000 1.0000
20.2000 608.0000 1.0000
20.2400 605.0000 1.0000
20.2800 605.0000 1.0000
20.3200 576.0000 1.0000
20.3600 583.0000 1.0000
20.4000 622.0000 1.0000
20.4400 591.0000 1.0000
20.4800 557.0000 1.0000
20.5200 621.0000 1.0000
20.5600 588.0000 1.0000
20.6000 616.0000 1.0000
20.6400 586.0000 1.0000
20.6800 567.0000 1.0000
20.7200 564.0000 1.0000
20.7600 631.0000 1.0000
20.8000 585.0000 1.0000
20.8400 613.0000 1.0000
20.8800 584.0000 1.0000
20.9200 618.0000 1.0000
20.9600 568.0000 1.0000
21.0000 579.0000 1.0000
21.0400 573.0000 1.0000
21.0800 617.0000 1.0000
21.1200 613.0000 1.0000
21.1600 603.0000 1.0000
21.2000 592.0000 1.0000
21.2400 551.0000 1.0000
21.2800 577.0000 1.0000
21.3200 619.0000 1.0000
21.3600 562.0000 1.0000
21.4000 583.0000 1.0000
21.4400 622.0000 1.0000
21.4800 591.0000 1.0000
21.5200 615.0000 1.0000
21.5600 583.0000 1.0000
21.6000 604.0000 1.0000
21.6400 615.0000 1.0000
21.6800 599.0000 1.0000
21.7200 591.0000 1.0000
21.7600 556.0000 1.0000
21.8000 592.0000 1.0000
21.8400 629.0000 1.0000
21.8800 589.0000 1.0000
21.9200 610.0000 1.0000
21.9600 560.0000 1.0000
22.0000 620.0000 1.0000
22.0400 604.0000 1.0000
22.0800 619.0000 1.0000
22.1200 606.0000 1.0000
22.1600 576.0000 1.0000
22.2000 621.0000 1.0000
22.2400 571.0000 1.0000
22.2800 587.0000 1.0000
22.3200 577.0000 1.0000
22.3600 570.0000 1.0000
22.4000 607.0000 1.0000
22.4400 590.0000 1.0000
22.4800 582.0000 1.0000
22.5200 579.0000 1.0000
22.5600 607.0000 1.0000
22.6000 584.0000 1.0000
22.6400 588.0000 1.0000
22.6800 588.0000 1.0000
22.7200 585.0000 1.0000
22.7600 604.0000 1.0000
22.8000 604.0000 1.0000
22.8400 602.0000 1.0000
22.8800 651.0000 1.0000
22.9200 598.0000 1.0000
22.9600 594.0000 1.0000
23.0000 634.0000 1.0000
23.0400 614.0000 1.0000
23.0800 581.0000 1.0000
23.1200 599.0000 1.0000
23.1600 589.0000 1.0000
23.2000 549.0000 1.0000
23.2400 591.0000 1.0000
23.2800 621.0000 1.0000
23.3200 592.0000 1.0000
23.3600 614.0000 1.0000
23.4000 608.0000 1.0000
23.4400 610.0000 1.0000
23.4800 514.0000 1.0000
23.5200 565.0000 1.0000
23.5600 621.0000 1.0000
23.6000 601.0000 1.0000
23.6400 602.0000 1.0000
23.6800 592.0000 1.0000
23.7200 623.0000 1.0000
23.7600 625.0000 1.0000
23.8000 628.0000 1.0000
23.8400 585.0000 1.0000
23.8800 622.0000 1.0000
23.9200 563.0000 1.0000
23.9600 634.0000 1.0000
24.0000 590.0000 1.0000
24.0400 567.0000 1.0000
24.0800 597.0000 1.0000
24.1200 604.0000 1.0000
24.1600 614.0000 1.0000
24.2000 585.0000 1.0000
24.2400 590.0000 1.0000
24.2800 632.0000 1.0000
24.3200 623.0000 1.0000
24.3600 612.0000 1.0000
24.4000 612.0000 1.0000
24.4400 605.0000 1.0000
24.4800 658.0000 1.0000
24.5200 627.0000 1.0000
24.5600 672.0000 1.0000
24.6000 624.0000 1.0000
24.6400 647.0000 1.0000
24.6800 622.0000 1.0000
24.7200 632.0000 1.0000
24.7600 617.0000 1.0000
24.8000 604.0000 1.0000
24.8400 613.0000 1.0000
24.8800 624.0000 1.0000
24.9200 631.0000 1.0000
24.9600 622.0000 1.0000
25.0000 615.0000 1.0000
25.0400 643.0000 1.0000
25.0800 665.0000 1.0000
25.1200 599.0000 1.0000
25.1600 619.0000 1.0000
25.2000 603.0000 1.0000
25.2400 609.0000 1.0000
25.2800 619.0000 1.0000
25.3200 624.0000 1.0000
25.3600 620.0000 1.0000
25.4000 615.0000 1.0000
25.4400 642.0000 1.0000
25.4800 626.0000 1.0000
25.5200 614.0000 1.0000
25.5600 577.0000 1.0000
25.6000 637.0000 1.0000
25.6400 597.0000 1.0000
25.6800 608.0000 1.0000
25.7200 621.0000 1.0000
25.7600 617.0000 1.0000
25.8000 631.0000 1.0000
25.8400 607.0000 1.0000
25.8800 630.0000 1.0000
25.9200 607.0000 1.0000
25.9600 605.0000 1.0000
26.0000 644.0000 1.0000
26.0400 589.0000 1.0000
26.0800 614.0000 1.0000
26.1200 633.0000 1.0000
26.1600 610.0000 1.0000
26.2000 623.0000 1.0000
26.2400 607.0000 1.0000
26.2800 608.0000 1.0000
26.3200 598.0000 1.0000
26.3600 655.0000 1.0000
26.4000 656.0000 1.0000
26.4400 690.0000 1.0000
26.4800 652.0000 1.0000
26.5200 695.0000 1.0000
26.5600 642.0000 1.0000
26.6000 642.0000 1.0000
26.6400 643.0000 1.0000
26.6800 677.0000 1.0000
26.7200 686.0000 1.0000
26.7600 643.0000 1.0000
26.8000 712.0000 1.0000
26.8400 674.0000 1.0000
26.8800 657.0000 1.0000
26.9200 703.0000 1.0000
26.9600 746.0000 1.0000
27.0000 767.0000 1.0000
27.0400 906.0000 1.0000
27.0800 899.0000 1.0000
27.1200 1021.0000 1.0000
27.1600 1198.0000 1.0000
27.2000 1473.0000 1.0000
27.2400 1805.0000 1.0000
27.2800 2122.0000 1.0000
27.3200 2315.0000 1.0000
27.3600 2164.0000 1.0000
27.4000 1808.0000 1.0000
27.4400 1517.0000 1.0000
27.4800 1267.0000 1.0000
27.5200 1064.0000 1.0000
27.5600 982.0000 1.0000
27.6000 890.0000 1.0000
27.6400 763.0000 1.0000
27.6800 730.0000 1.0000
27.7200 726.0000 1.0000
27.7600 701.0000 1.0000
27.8000 735.0000 1.0000
27.8400 677.0000 1.0000
27.8800 636.0000 1.0000
27.9200 653.0000 1.0000
27.9600 641.0000 1.0000
28.0000 662.0000 1.0000
28.0400 628.0000 1.0000
28.0800 617.0000 1.0000
28.1200 649.0000 1.0000
28.1600 634.0000 1.0000
28.2000 633.0000 1.0000
28.2400 635.0000 1.0000
28.2800 642.0000 1.0000
28.3200 648.0000 1.0000
28.3600 645.0000 1.0000
28.4000 642.0000 1.0000
28.4400 593.0000 1.0000
28.4800 666.0000 1.0000
28.5200 607.0000 1.0000
28.5600 626.0000 1.0000
28.6000 613.0000 1.0000
28.6400 620.0000 1.0000
28.6800 628.0000 1.0000
28.7200 632.0000 1.0000
28.7600 636.0000 1.0000
28.8000 587.0000 1.0000
28.8400 613.0000 1.0000
28.8800 617.0000 1.0000
28.9200 591.0000 1.0000
28.9600 612.0000 1.0000
29.0000 629.0000 1.0000
29.0400 574.0000 1.0000
29.0800 603.0000 1.0000
29.1200 617.0000 1.0000
29.1600 640.0000 1.0000
29.2000 592.0000 1.0000
29.2400 599.0000 1.0000
29.2800 599.0000 1.0000
29.3200 612.0000 1.0000
29.3600 645.0000 1.0000
29.4000 584.0000 1.0000
29.4400 604.0000 1.0000
29.4800 620.0000 1.0000
29.5200 578.0000 1.0000
29.5600 633.0000 1.0000
29.6000 593.0000 1.0000
29.6400 589.0000 1.0000
29.6800 601.0000 1.0000
29.7200 586.0000 1.0000
29.7600 567.0000 1.0000
29.8000 585.0000 1.0000
29.8400 561.0000 1.0000
29.8800 576.0000 1.0000
29.9200 568.0000 1.0000
29.9600 580.0000 1.0000
30.0000 573.0000 1.0000
30.0400 556.0000 1.0000
30.0800 580.0000 1.0000
30.1200 572.0000 1.0000
30.1600 512.0000 1.0000
30.2000 561.0000 1.0000
30.2400 600.0000 1.0000
30.2800 576.0000 1.0000
30.3200 560.0000 1.0000
30.3600 582.0000 1.0000
30.4000 558.0000 1.0000
30.4400 586.0000 1.0000
30.4800 541.0000 1.0000
30.5200 579.0000 1.0000
30.5600 551.0000 1.0000
30.6000 548.0000 1.0000
30.6400 591.0000 1.0000
30.6800 547.0000 1.0000
30.7200 582.0000 1.0000
30.7600 565.0000 1.0000
30.8000 573.0000 1.0000
30.8400 562.0000 1.0000
30.8800 592.0000 1.0000
30.9200 572.0000 1.0000
30.9600 577.0000 1.0000
31.0000 559.0000 1.0000
31.0400 554.0000 1.0000
31.0800 563.0000 1.0000
31.1200 540.0000 1.0000
31.1600 554.0000 1.0000
31.2000 600.0000 1.0000
31.2400 585.0000 1.0000
31.2800 547.0000 1.0000
31.3200 548.0000 1.0000
31.3600 574.0000 1.0000
31.4000 568.0000 1.0000
31.4400 579.0000 1.0000
31.4800 577.0000 1.0000
31.5200 552.0000 1.0000
31.5600 549.0000 1.0000
31.6000 574.0000 1.0000
31.6400 510.0000 1.0000
31.6800 551.0000 1.0000
31.7200 576.0000 1.0000
31.7600 585.0000 1.0000
31.8000 550.0000 1.0000
31.8400 532.0000 1.0000
31.8800 554.0000 1.0000
31.9200 566.0000 1.0000
31.9600 557.0000 1.0000
32.0000 556.0000 1.0000
32.0400 582.0000 1.0000
32.0800 561.0000 1.0000
32.1200 584.0000 1.0000
32.1600 559.0000 1.0000
32.2000 534.0000 1.0000
32.2400 552.0000 1.0000
32.2800 540.0000 1.0000
32.3200 540.0000 1.0000
32.3600 525.0000 1.0000
32.4000 560.0000 1.0000
32.4400 542.0000 1.0000
32.4800 559.0000 1.0000
32.5200 526.0000 1.0000
32.5600 571.0000 1.0000
32.6000 565.0000 1.0000
32.6400 551.0000 1.0000
32.6800 541.0000 1.0000
32.7200 515.0000 1.0000
32.7600 555.0000 1.0000
32.8000 528.0000 1.0000
32.8400 526.0000 1.0000
32.8800 510.0000 1.0000
32.9200 553.0000 1.0000
32.9600 501.0000 1.0000
33.0000 535.0000 1.0000
33.0400 543.0000 1.0000
33.0800 555.0000 1.0000
33.1200 512.0000 1.0000
33.1600 519.0000 1.0000
33.2000 521.0000 1.0000
33.2400 540.0000 1.0000
33.2800 512.0000 1.0000
33.3200 494.0000 1.0000
33.3600 508.0000 1.0000
33.4000 524.0000 1.0000
33.4400 479.0000 1.0000
33.4800 523.0000 1.0000
33.5200 525.0000 1.0000
33.5600 475.0000 1.0000
33.6000 573.0000 1.0000
33.6400 514.0000 1.0000
33.6800 579.0000 1.0000
33.7200 528.0000 1.0000
33.7600 550.0000 1.0000
33.8000 591.0000 1.0000
33.8400 538.0000 1.0000
33.8800 564.0000 1.0000
33.9200 587.0000 1.0000
33.9600 592.0000 1.0000
34.0000 575.0000 1.0000
34.0400 607.0000 1.0000
34.0800 602.0000 1.0000
34.1200 620.0000 1.0000
34.1600 595.0000 1.0000
34.2000 580.0000 1.0000
34.2400 641.0000 1.0000
34.2800 683.0000 1.0000
34.3200 744.0000 1.0000
34.3600 843.0000 1.0000
34.4000 951.0000 1.0000
34.4400 1086.0000 1.0000
34.4800 1348.0000 1.0000
34.5200 1248.0000 1.0000
34.5600 1245.0000 1.0000
34.6000 1132.0000 1.0000
34.6400 962.0000 1.0000
34.6800 829.0000 1.0000
34.7200 723.0000 1.0000
34.7600 630.0000 1.0000
34.8000 645.0000 1.0000
34.8400 607.0000 1.0000
34.8800 563.0000 1.0000
34.9200 545.0000 1.0000
34.9600 525.0000 1.0000
35.0000 522.0000 1.0000
35.0400 486.0000 1.0000
35.0800 503.0000 1.0000
35.1200 507.0000 1.0000
35.1600 497.0000 1.0000
35.2000 509.0000 1.0000
35.2400 468.0000 1.0000
35.2800 477.0000 1.0000
35.3200 459.0000 1.0000
35.3600 493.0000 1.0000
35.4000 480.0000 1.0000
35.4400 471.0000 1.0000
35.4800 487.0000 1.0000
35.5200 437.0000 1.0000
35.5600 480.0000 1.0000
35.6000 426.0000 1.0000
35.6400 454.0000 1.0000
35.6800 417.0000 1.0000
35.7200 472.0000 1.0000
35.7600 439.0000 1.0000
35.8000 467.0000 1.0000
35.8400 465.0000 1.0000
35.8800 463.0000 1.0000
35.9200 447.0000 1.0000
35.9600 422.0000 1.0000
36.0000 455.0000 1.0000
36.0400 444.0000 1.0000
36.0800 486.0000 1.0000
36.1200 452.0000 1.0000
36.1600 511.0000 1.0000
36.2000 499.0000 1.0000
36.2400 484.0000 1.0000
36.2800 554.0000 1.0000
36.3200 595.0000 1.0000
36.3600 650.0000 1.0000
36.4000 761.0000 1.0000
36.4400 740.0000 1.0000
36.4800 679.0000 1.0000
36.5200 698.0000 1.0000
36.5600 601.0000 1.0000
36.6000 525.0000 1.0000
36.6400 482.0000 1.0000
36.6800 503.0000 1.0000
36.7200 486.0000 1.0000
36.7600 462.0000 1.0000
36.8000 476.0000 1.0000
36.8400 448.0000 1.0000
36.8800 420.0000 1.0000
36.9200 409.0000 1.0000
36.9600 416.0000 1.0000
37.0000 410.0000 1.0000
37.0400 402.0000 1.0000
37.0800 411.0000 1.0000
37.1200 384.0000 1.0000
37.1600 448.0000 1.0000
37.2000 414.0000 1.0000
37.2400 426.0000 1.0000
37.2800 405.0000 1.0000
37.3200 430.0000 1.0000
37.3600 396.0000 1.0000
37.4000 412.0000 1.0000
37.4400 421.0000 1.0000
37.4800 422.0000 1.0000
37.5200 410.0000 1.0000
37.5600 393.0000 1.0000
37.6000 457.0000 1.0000
37.6400 400.0000 1.0000
37.6800 397.0000 1.0000
37.7200 437.0000 1.0000
37.7600 441.0000 1.0000
37.8000 429.0000 1.0000
37.8400 377.0000 1.0000
37.8800 396.0000 1.0000
37.9200 450.0000 1.0000
37.9600 410.0000 1.0000
38.0000 455.0000 1.0000
38.0400 441.0000 1.0000
38.0800 466.0000 1.0000
38.1200 462.0000 1.0000
38.1600 486.0000 1.0000
38.2000 511.0000 1.0000
38.2400 542.0000 1.0000
38.2800 601.0000 1.0000
38.3200 780.0000 1.0000
38.3600 916.0000 1.0000
38.4000 1106.0000 1.0000
38.4400 1408.0000 1.0000
38.4800 1880.0000 1.0000
38.5200 2272.0000 1.0000
38.5600 2386.0000 1.0000
38.6000 2186.0000 1.0000
38.6400 1930.0000 1.0000
38.6800 1568.0000 1.0000
38.7200 1246.0000 1.0000
38.7600 948.0000 1.0000
38.8000 733.0000 1.0000
38.8400 653.0000 1.0000
38.8800 599.0000 1.0000
38.9200 532.0000 1.0000
38.9600 491.0000 1.0000
39.0000 446.0000 1.0000
39.0400 427.0000 1.0000
39.0800 414.0000 1.0000
39.1200 413.0000 1.0000
39.1600 413.0000 1.0000
39.2000 374.0000 1.0000
39.2400 365.0000 1.0000
39.2800 385.0000 1.0000
39.3200 370.0000 1.0000
39.3600 409.0000 1.0000
39.4000 398.0000 1.0000
39.4400 376.0000 1.0000
39.4800 391.0000 1.0000
39.5200 374.0000 1.0000
39.5600 395.0000 1.0000
39.6000 392.0000 1.0000
39.6400 408.0000 1.0000
39.6800 401.0000 1.0000
39.7200 395.0000 1.0000
39.7600 345.0000 1.0000
39.8000 368.0000 1.0000
39.8400 352.0000 1.0000
39.8800 374.0000 1.0000
39.9200 363.0000 1.0000
39.9600 345.0000 1.0000
40.0000 348.0000 1.0000
40.0400 376.0000 1.0000
40.0800 369.0000 1.0000
40.1200 377.0000 1.0000
40.1600 347.0000 1.0000
40.2000 372.0000 1.0000
40.2400 368.0000 1.0000
40.2800 338.0000 1.0000
40.3200 353.0000 1.0000
40.3600 340.0000 1.0000
40.4000 384.0000 1.0000
40.4400 332.0000 1.0000
40.4800 318.0000 1.0000
40.5200 339.0000 1.0000
40.5600 368.0000 1.0000
40.6000 362.0000 1.0000
40.6400 354.0000 1.0000
40.6800 337.0000 1.0000
40.7200 362.0000 1.0000
40.7600 352.0000 1.0000
40.8000 351.0000 1.0000
40.8400 338.0000 1.0000
40.8800 358.0000 1.0000
40.9200 349.0000 1.0000
40.9600 348.0000 1.0000
41.0000 376.0000 1.0000
41.0400 334.0000 1.0000
41.0800 317.0000 1.0000
41.1200 323.0000 1.0000
41.1600 339.0000 1.0000
41.2000 351.0000 1.0000
41.2400 334.0000 1.0000
41.2800 328.0000 1.0000
41.3200 319.0000 1.0000
41.3600 341.0000 1.0000
41.4000 331.0000 1.0000
41.4400 342.0000 1.0000
41.4800 336.0000 1.0000
41.5200 350.0000 1.0000
41.5600 360.0000 1.0000
41.6000 330.0000 1.0000
41.6400 330.0000 1.0000
41.6800 367.0000 1.0000
41.7200 380.0000 1.0000
41.7600 369.0000 1.0000
41.8000 366.0000 1.0000
41.8400 312.0000 1.0000
41.8800 315.0000 1.0000
41.9200 324.0000 1.0000
41.9600 348.0000 1.0000
42.0000 345.0000 1.0000
42.0400 343.0000 1.0000
42.0800 334.0000 1.0000
42.1200 330.0000 1.0000
42.1600 329.0000 1.0000
42.2000 328.0000 1.0000
42.2400 380.0000 1.0000
42.2800 373.0000 1.0000
42.3200 337.0000 1.0000
42.3600 353.0000 1.0000
42.4000 335.0000 1.0000
42.4400 316.0000 1.0000
42.4800 332.0000 1.0000
42.5200 350.0000 1.0000
42.5600 342.0000 1.0000
42.6000 324.0000 1.0000
42.6400 319.0000 1.0000
42.6800 328.0000 1.0000
42.7200 324.0000 1.0000
42.7600 353.0000 1.0000
42.8000 350.0000 1.0000
42.8400 330.0000 1.0000
42.8800 329.0000 1.0000
42.9200 362.0000 1.0000
42.9600 355.0000 1.0000
43.0000 333.0000 1.0000
43.0400 340.0000 1.0000
43.0800 357.0000 1.0000
43.1200 334.0000 1.0000
43.1600 353.0000 1.0000
43.2000 351.0000 1.0000
43.2400 356.0000 1.0000
43.2800 356.0000 1.0000
43.3200 378.0000 1.0000
43.3600 373.0000 1.0000
43.4000 338.0000 1.0000
43.4400 355.0000 1.0000
43.4800 314.0000 1.0000
43.5200 298.0000 1.0000
43.5600 347.0000 1.0000
43.6000 297.0000 1.0000
43.6400 370.0000 1.0000
43.6800 319.0000 1.0000
43.7200 339.0000 1.0000
43.7600 347.0000 1.0000
43.8000 297.0000 1.0000
43.8400 365.0000 1.0000
43.8800 324.0000 1.0000
43.9200 351.0000 1.0000
43.9600 296.0000 1.0000
44.0000 322.0000 1.0000
44.0400 299.0000 1.0000
44.0800 328.0000 1.0000
44.1200 333.0000 1.0000
44.1600 350.0000 1.0000
44.2000 309.0000 1.0000
44.2400 332.0000 1.0000
44.2800 336.0000 1.0000
44.3200 354.0000 1.0000
44.3600 307.0000 1.0000
44.4000 331.0000 1.0000
44.4400 303.0000 1.0000
44.4800 337.0000 1.0000
44.5200 320.0000 1.0000
44.5600 330.0000 1.0000
44.6000 325.0000 1.0000
44.6400 329.0000 1.0000
44.6800 306.0000 1.0000
44.7200 329.0000 1.0000
44.7600 333.0000 1.0000
44.8000 308.0000 1.0000
44.8400 346.0000 1.0000
44.8800 335.0000 1.0000
44.9200 318.0000 1.0000
44.9600 317.0000 1.0000
45.0000 302.0000 1.0000
45.0400 349.0000 1.0000
45.0800 314.0000 1.0000
45.1200 338.0000 1.0000
45.1600 304.0000 1.0000
45.2000 284.0000 1.0000
45.2400 330.0000 1.0000
45.2800 307.0000 1.0000
45.3200 279.0000 1.0000
45.3600 309.0000 1.0000
45.4000 334.0000 1.0000
45.4400 320.0000 1.0000
45.4800 337.0000 1.0000
45.5200 335.0000 1.0000
45.5600 303.0000 1.0000
45.6000 294.0000 1.0000
45.6400 309.0000 1.0000
45.6800 325.0000 1.0000
45.7200 295.0000 1.0000
45.7600 294.0000 1.0000
45.8000 293.0000 1.0000
45.8400 309.0000 1.0000
45.8800 322.0000 1.0000
45.9200 331.0000 1.0000
45.9600 313.0000 1.0000
46.0000 330.0000 1.0000
46.0400 301.0000 1.0000
46.0800 303.0000 1.0000
46.1200 307.0000 1.0000
46.1600 327.0000 1.0000
46.2000 330.0000 1.0000
46.2400 305.0000 1.0000
46.2800 341.0000 1.0000
46.3200 313.0000 1.0000
46.3600 315.0000 1.0000
46.4000 316.0000 1.0000
46.4400 288.0000 1.0000
46.4800 279.0000 1.0000
46.5200 297.0000 1.0000
46.5600 300.0000 1.0000
46.6000 295.0000 1.0000
46.6400 317.0000 1.0000
46.6800 332.0000 1.0000
46.7200 305.0000 1.0000
46.7600 323.0000 1.0000
46.8000 292.0000 1.0000
46.8400 338.0000 1.0000
46.8800 282.0000 1.0000
46.9200 299.0000 1.0000
46.9600 311.0000 1.0000
47.0000 319.0000 1.0000
47.0400 323.0000 1.0000
47.0800 326.0000 1.0000
47.1200 306.0000 1.0000
47.1600 323.0000 1.0000
47.2000 328.0000 1.0000
47.2400 316.0000 1.0000
47.2800 332.0000 1.0000
47.3200 315.0000 1.0000
47.3600 276.0000 1.0000
47.4000 304.0000 1.0000
47.4400 299.0000 1.0000
47.4800 287.0000 1.0000
47.5200 330.0000 1.0000
47.5600 306.0000 1.0000
47.6000 313.0000 1.0000
47.6400 300.0000 1.0000
47.6800 277.0000 1.0000
47.7200 317.0000 1.0000
47.7600 291.0000 1.0000
47.8000 276.0000 1.0000
47.8400 344.0000 1.0000
47.8800 302.0000 1.0000
47.9200 264.0000 1.0000
47.9600 314.0000 1.0000
48.0000 299.0000 1.0000
48.0400 276.0000 1.0000
48.0800 320.0000 1.0000
48.1200 303.0000 1.0000
48.1600 272.0000 1.0000
48.2000 285.0000 1.0000
48.2400 273.0000 1.0000
48.2800 286.0000 1.0000
48.3200 292.0000 1.0000
48.3600 281.0000 1.0000
48.4000 299.0000 1.0000
48.4400 289.0000 1.0000
48.4800 313.0000 1.0000
48.5200 299.0000 1.0000
48.5600 282.0000 1.0000
48.6000 312.0000 1.0000
48.6400 267.0000 1.0000
48.6800 300.0000 1.0000
48.7200 290.0000 1.0000
48.7600 296.0000 1.0000
48.8000 308.0000 1.0000
48.8400 308.0000 1.0000
48.8800 298.0000 1.0000
48.9200 267.0000 1.0000
48.9600 259.0000 1.0000
49.0000 300.0000 1.0000
49.0400 284.0000 1.0000
49.0800 294.0000 1.0000
49.1200 285.0000 1.0000
49.1600 297.0000 1.0000
49.2000 309.0000 1.0000
49.2400 309.0000 1.0000
49.2800 302.0000 1.0000
49.3200 279.0000 1.0000
49.3600 257.0000 1.0000
49.4000 297.0000 1.0000
49.4400 316.0000 1.0000
49.4800 286.0000 1.0000
49.5200 270.0000 1.0000
49.5600 291.0000 1.0000
49.6000 263.0000 1.0000
49.6400 289.0000 1.0000
49.6800 285.0000 1.0000
49.7200 282.0000 1.0000
49.7600 296.0000 1.0000
49.8000 287.0000 1.0000
49.8400 302.0000 1.0000
49.8800 267.0000 1.0000
49.9200 281.0000 1.0000
49.9600 306.0000 1.0000
50.0000 282.0000 1.0000
50.0400 300.0000 1.0000
50.0800 293.0000 1.0000
50.1200 296.0000 1.0000
50.1600 300.0000 1.0000
50.2000 314.0000 1.0000
50.2400 300.0000 1.0000
50.2800 289.0000 1.0000
50.3200 328.0000 1.0000
50.3600 292.0000 1.0000
50.4000 302.0000 1.0000
50.4400 292.0000 1.0000
50.4800 297.0000 1.0000
50.5200 313.0000 1.0000
50.5600 281.0000 1.0000
50.6000 311.0000 1.0000
50.6400 277.0000 1.0000
50.6800 289.0000 1.0000
50.7200 304.0000 1.0000
50.7600 276.0000 1.0000
50.8000 280.0000 1.0000
50.8400 278.0000 1.0000
50.8800 290.0000 1.0000
50.9200 310.0000 1.0000
50.9600 308.0000 1.0000
51.0000 285.0000 1.0000
51.0400 274.0000 1.0000
51.0800 281.0000 1.0000
51.1200 312.0000 1.0000
51.1600 285.0000 1.0000
51.2000 303.0000 1.0000
51.2400 277.0000 1.0000
51.2800 290.0000 1.0000
51.3200 303.0000 1.0000
51.3600 264.0000 1.0000
51.4000 280.0000 1.0000
51.4400 303.0000 1.0000
51.4800 285.0000 1.0000
51.5200 275.0000 1.0000
51.5600 305.0000 1.0000
51.6000 309.0000 1.0000
51.6400 299.0000 1.0000
51.6800 302.0000 1.0000
51.7200 307.0000 1.0000
51.7600 301.0000 1.0000
51.8000 317.0000 1.0000
51.8400 354.0000 1.0000
51.8800 372.0000 1.0000
51.9200 326.0000 1.0000
51.9600 407.0000 1.0000
52.0000 482.0000 1.0000
52.0400 488.0000 1.0000
52.0800 606.0000 1.0000
52.1200 706.0000 1.0000
52.1600 1002.0000 1.0000
52.2000 1376.0000 1.0000
52.2400 1908.0000 1.0000
52.2800 2144.0000 1.0000
52.3200 2170.0000 1.0000
52.3600 1842.0000 1.0000
52.4000 1676.0000 1.0000
52.4400 1471.0000 1.0000
52.4800 1113.0000 1.0000
52.5200 783.0000 1.0000
52.5600 656.0000 1.0000
52.6000 571.0000 1.0000
52.6400 461.0000 1.0000
52.6800 399.0000 1.0000
52.7200 353.0000 1.0000
52.7600 343.0000 1.0000
52.8000 342.0000 1.0000
52.8400 334.0000 1.0000
52.8800 331.0000 1.0000
52.9200 344.0000 1.0000
52.9600 328.0000 1.0000
53.0000 285.0000 1.0000
53.0400 321.0000 1.0000
53.0800 316.0000 1.0000
53.1200 300.0000 1.0000
53.1600 312.0000 1.0000
53.2000 306.0000 1.0000
53.2400 274.0000 1.0000
53.2800 272.0000 1.0000
53.3200 275.0000 1.0000
53.3600 300.0000 1.0000
53.4000 308.0000 1.0000
53.4400 293.0000 1.0000
53.4800 317.0000 1.0000
53.5200 309.0000 1.0000
53.5600 274.0000 1.0000
53.6000 269.0000 1.0000
53.6400 296.0000 1.0000
53.6800 267.0000 1.0000
53.7200 309.0000 1.0000
53.7600 300.0000 1.0000
53.8000 307.0000 1.0000
53.8400 294.0000 1.0000
53.8800 273.0000 1.0000
53.9200 272.0000 1.0000
53.9600 267.0000 1.0000
54.0000 263.0000 1.0000
54.0400 275.0000 1.0000
54.0800 309.0000 1.0000
54.1200 278.0000 1.0000
54.1600 269.0000 1.0000
54.2000 268.0000 1.0000
54.2400 290.0000 1.0000
54.2800 286.0000 1.0000
54.3200 302.0000 1.0000
54.3600 290.0000 1.0000
54.4000 291.0000 1.0000
54.4400 273.0000 1.0000
54.4800 291.0000 1.0000
54.5200 272.0000 1.0000
54.5600 269.0000 1.0000
54.6000 305.0000 1.0000
54.6400 283.0000 1.0000
54.6800 298.0000 1.0000
54.7200 281.0000 1.0000
54.7600 300.0000 1.0000
54.8000 279.0000 1.0000
54.8400 342.0000 1.0000
54.8800 284.0000 1.0000
54.9200 302.0000 1.0000
54.9600 285.0000 1.0000
55.0000 312.0000 1.0000
55.0400 324.0000 1.0000
55.0800 266.0000 1.0000
55.1200 336.0000 1.0000
55.1600 371.0000 1.0000
55.2000 366.0000 1.0000
55.2400 417.0000 1.0000
55.2800 428.0000 1.0000
55.3200 391.0000 1.0000
55.3600 393.0000 1.0000
55.4000 424.0000 1.0000
55.4400 351.0000 1.0000
55.4800 386.0000 1.0000
55.5200 366.0000 1.0000
55.5600 326.0000 1.0000
55.6000 348.0000 1.0000
55.6400 310.0000 1.0000
55.6800 318.0000 1.0000
55.7200 319.0000 1.0000
55.7600 309.0000 1.0000
55.8000 289.0000 1.0000
55.8400 281.0000 1.0000
55.8800 279.0000 1.0000
55.9200 258.0000 1.0000
55.9600 276.0000 1.0000
56.0000 279.0000 1.0000
56.0400 269.0000 1.0000
56.0800 274.0000 1.0000
56.1200 279.0000 1.0000
56.1600 261.0000 1.0000
56.2000 270.0000 1.0000
56.2400 288.0000 1.0000
56.2800 280.0000 1.0000
56.3200 279.0000 1.0000
56.3600 299.0000 1.0000
56.4000 263.0000 1.0000
56.4400 256.0000 1.0000
56.4800 288.0000 1.0000
56.5200 276.0000 1.0000
56.5600 253.0000 1.0000
56.6000 276.0000 1.0000
56.6400 247.0000 1.0000
56.6800 297.0000 1.0000
56.7200 266.0000 1.0000
56.7600 268.0000 1.0000
56.8000 275.0000 1.0000
56.8400 289.0000 1.0000
56.8800 278.0000 1.0000
56.9200 287.0000 1.0000
56.9600 272.0000 1.0000
57.0000 284.0000 1.0000
57.0400 281.0000 1.0000
57.0800 291.0000 1.0000
57.1200 264.0000 1.0000
57.1600 268.0000 1.0000
57.2000 286.0000 1.0000
57.2400 288.0000 1.0000
57.2800 272.0000 1.0000
57.3200 259.0000 1.0000
57.3600 293.0000 1.0000
57.4000 279.0000 1.0000
57.4400 279.0000 1.0000
57.4800 275.0000 1.0000
57.5200 266.0000 1.0000
57.5600 259.0000 1.0000
57.6000 265.0000 1.0000
57.6400 261.0000 1.0000
57.6800 282.0000 1.0000
57.7200 280.0000 1.0000
57.7600 295.0000 1.0000
57.8000 268.0000 1.0000
57.8400 292.0000 1.0000
57.8800 262.0000 1.0000
57.9200 249.0000 1.0000
57.9600 239.0000 1.0000
58.0000 260.0000 1.0000
58.0400 280.0000 1.0000
58.0800 239.0000 1.0000
58.1200 245.0000 1.0000
58.1600 276.0000 1.0000
58.2000 274.0000 1.0000
58.2400 272.0000 1.0000
58.2800 247.0000 1.0000
58.3200 260.0000 1.0000
58.3600 239.0000 1.0000
58.4000 277.0000 1.0000
58.4400 277.0000 1.0000
58.4800 291.0000 1.0000
58.5200 273.0000 1.0000
58.5600 288.0000 1.0000
58.6000 279.0000 1.0000
58.6400 286.0000 1.0000
58.6800 272.0000 1.0000
58.7200 280.0000 1.0000
58.7600 261.0000 1.0000
58.8000 275.0000 1.0000
58.8400 283.0000 1.0000
58.8800 256.0000 1.0000
58.9200 268.0000 1.0000
58.9600 278.0000 1.0000
59.0000 299.0000 1.0000
59.0400 265.0000 1.0000
59.0800 282.0000 1.0000
59.1200 263.0000 1.0000
59.1600 267.0000 1.0000
59.2000 270.0000 1.0000
59.2400 261.0000 1.0000
59.2800 270.0000 1.0000
59.3200 263.0000 1.0000
59.3600 276.0000 1.0000
59.4000 270.0000 1.0000
59.4400 276.0000 1.0000
59.4800 285.0000 1.0000
59.5200 246.0000 1.0000
59.5600 280.0000 1.0000
59.6000 261.0000 1.0000
59.6400 251.0000 1.0000
59.6800 256.0000 1.0000
59.7200 258.0000 1.0000
59.7600 282.0000 1.0000
59.8000 265.0000 1.0000
59.8400 246.0000 1.0000
59.8800 252.0000 1.0000
59.9200 295.0000 1.0000
59.9600 267.0000 1.0000
60.0000 277.0000 1.0000
60.0400 265.0000 1.0000
60.0800 271.0000 1.0000
60.1200 288.0000 1.0000
60.1600 279.0000 1.0000
60.2000 263.0000 1.0000
60.2400 229.0000 1.0000
60.2800 257.0000 1.0000
60.3200 256.0000 1.0000
60.3600 255.0000 1.0000
60.4000 264.0000 1.0000
60.4400 265.0000 1.0000
60.4800 252.0000 1.0000
60.5200 254.0000 1.0000
60.5600 277.0000 1.0000
60.6000 285.0000 1.0000
60.6400 258.0000 1.0000
60.6800 262.0000 1.0000
60.7200 267.0000 1.0000
60.7600 259.0000 1.0000
60.8000 257.0000 1.0000
60.8400 253.0000 1.0000
60.8800 282.0000 1.0000
60.9200 252.0000 1.0000
60.9600 272.0000 1.0000
61.0000 277.0000 1.0000
61.0400 254.0000 1.0000
61.0800 286.0000 1.0000
61.1200 265.0000 1.0000
61.1600 262.0000 1.0000
61.2000 251.0000 1.0000
61.2400 244.0000 1.0000
61.2800 265.0000 1.0000
61.3200 270.0000 1.0000
61.3600 293.0000 1.0000
61.4000 284.0000 1.0000
61.4400 264.0000 1.0000
61.4800 257.0000 1.0000
61.5200 274.0000 1.0000
61.5600 271.0000 1.0000
61.6000 256.0000 1.0000
61.6400 308.0000 1.0000
61.6800 283.0000 1.0000
61.7200 280.0000 1.0000
61.7600 307.0000 1.0000
61.8000 287.0000 1.0000
61.8400 289.0000 1.0000
61.8800 275.0000 1.0000
61.9200 304.0000 1.0000
61.9600 288.0000 1.0000
62.0000 326.0000 1.0000
62.0400 389.0000 1.0000
62.0800 380.0000 1.0000
62.1200 391.0000 1.0000
62.1600 463.0000 1.0000
62.2000 493.0000 1.0000
62.2400 546.0000 1.0000
62.2800 559.0000 1.0000
62.3200 599.0000 1.0000
62.3600 560.0000 1.0000
62.4000 522.0000 1.0000
62.4400 544.0000 1.0000
62.4800 509.0000 1.0000
62.5200 470.0000 1.0000
62.5600 426.0000 1.0000
62.6000 383.0000 1.0000
62.6400 378.0000 1.0000
62.6800 361.0000 1.0000
62.7200 336.0000 1.0000
62.7600 309.0000 1.0000
62.8000 297.0000 1.0000
62.8400 296.0000 1.0000
62.8800 316.0000 1.0000
62.9200 285.0000 1.0000
62.9600 297.0000 1.0000
63.0000 274.0000 1.0000
63.0400 278.0000 1.0000
63.0800 302.0000 1.0000
63.1200 295.0000 1.0000
63.1600 314.0000 1.0000
63.2000 264.0000 1.0000
63.2400 267.0000 1.0000
63.2800 272.0000 1.0000
63.3200 307.0000 1.0000
63.3600 282.0000 1.0000
63.4000 274.0000 1.0000
63.4400 259.0000 1.0000
63.4800 273.0000 1.0000
63.5200 282.0000 1.0000
63.5600 249.0000 1.0000
63.6000 282.0000 1.0000
63.6400 281.0000 1.0000
63.6800 270.0000 1.0000
63.7200 263.0000 1.0000
63.7600 268.0000 1.0000
63.8000 253.0000 1.0000
63.8400 271.0000 1.0000
63.8800 279.0000 1.0000
63.9200 250.0000 1.0000
63.9600 259.0000 1.0000
64.0000 236.0000 1.0000
64.0400 277.0000 1.0000
64.0800 270.0000 1.0000
64.1200 267.0000 1.0000
64.1600 289.0000 1.0000
64.2000 260.0000 1.0000
64.2400 262.0000 1.0000
64.2800 275.0000 1.0000
64.3200 264.0000 1.0000
64.3600 285.0000 1.0000
64.4000 285.0000 1.0000
64.4400 284.0000 1.0000
64.4800 297.0000 1.0000
64.5200 305.0000 1.0000
64.5600 326.0000 1.0000
64.6000 289.0000 1.0000
64.6400 316.0000 1.0000
64.6800 332.0000 1.0000
64.7200 339.0000 1.0000
64.7600 349.0000 1.0000
64.8000 340.0000 1.0000
64.8400 326.0000 1.0000
64.8800 317.0000 1.0000
64.9200 294.0000 1.0000
64.9600 324.0000 1.0000
65.0000 314.0000 1.0000
65.0400 298.0000 1.0000
65.0800 302.0000 1.0000
65.1200 317.0000 1.0000
65.1600 285.0000 1.0000
65.2000 311.0000 1.0000
65.2400 274.0000 1.0000
65.2800 284.0000 1.0000
65.3200 306.0000 1.0000
65.3600 258.0000 1.0000
65.4000 270.0000 1.0000
65.4400 295.0000 1.0000
65.4800 286.0000 1.0000
65.5200 290.0000 1.0000
65.5600 302.0000 1.0000
65.6000 311.0000 1.0000
65.6400 287.0000 1.0000
65.6800 269.0000 1.0000
65.7200 306.0000 1.0000
65.7600 304.0000 1.0000
65.8000 307.0000 1.0000
65.8400 292.0000 1.0000
65.8800 338.0000 1.0000
65.9200 375.0000 1.0000
65.9600 355.0000 1.0000
66.0000 371.0000 1.0000
66.0400 441.0000 1.0000
66.0800 483.0000 1.0000
66.1200 599.0000 1.0000
66.1600 736.0000 1.0000
66.2000 953.0000 1.0000
66.2400 1055.0000 1.0000
66.2800 1134.0000 1.0000
66.3200 1091.0000 1.0000
66.3600 948.0000 1.0000
66.4000 955.0000 1.0000
66.4400 898.0000 1.0000
66.4800 811.0000 1.0000
66.5200 740.0000 1.0000
66.5600 603.0000 1.0000
66.6000 502.0000 1.0000
66.6400 432.0000 1.0000
66.6800 399.0000 1.0000
66.7200 356.0000 1.0000
66.7600 332.0000 1.0000
66.8000 318.0000 1.0000
66.8400 296.0000 1.0000
66.8800 312.0000 1.0000
66.9200 278.0000 1.0000
66.9600 275.0000 1.0000
67.0000 291.0000 1.0000
67.0400 289.0000 1.0000
67.0800 272.0000 1.0000
67.1200 281.0000 1.0000
67.1600 264.0000 1.0000
67.2000 269.0000 1.0000
67.2400 286.0000 1.0000
67.2800 242.0000 1.0000
67.3200 250.0000 1.0000
67.3600 283.0000 1.0000
67.4000 246.0000 1.0000
67.4400 257.0000 1.0000
67.4800 254.0000 1.0000
67.5200 269.0000 1.0000
67.5600 255.0000 1.0000
67.6000 239.0000 1.0000
67.6400 254.0000 1.0000
67.6800 267.0000 1.0000
67.7200 260.0000 1.0000
67.7600 261.0000 1.0000
67.8000 263.0000 1.0000
67.8400 245.0000 1.0000
67.8800 247.0000 1.0000
67.9200 258.0000 1.0000
67.9600 261.0000 1.0000
68.0000 260.0000 1.0000
68.0400 253.0000 1.0000
68.0800 271.0000 1.0000
68.1200 228.0000 1.0000
68.1600 285.0000 1.0000
68.2000 243.0000 1.0000
68.2400 237.0000 1.0000
68.2800 257.0000 1.0000
68.3200 229.0000 1.0000
68.3600 247.0000 1.0000
68.4000 221.0000 1.0000
68.4400 236.0000 1.0000
68.4800 233.0000 1.0000
68.5200 255.0000 1.0000
68.5600 241.0000 1.0000
68.6000 262.0000 1.0000
68.6400 219.0000 1.0000
68.6800 233.0000 1.0000
68.7200 277.0000 1.0000
68.7600 233.0000 1.0000
68.8000 250.0000 1.0000
68.8400 235.0000 1.0000
68.8800 247.0000 1.0000
68.9200 230.0000 1.0000
68.9600 244.0000 1.0000
69.0000 228.0000 1.0000
69.0400 259.0000 1.0000
69.0800 217.0000 1.0000
69.1200 265.0000 1.0000
69.1600 236.0000 1.0000
69.2000 237.0000 1.0000
69.2400 249.0000 1.0000
69.2800 245.0000 1.0000
69.3200 223.0000 1.0000
69.3600 241.0000 1.0000
69.4000 244.0000 1.0000
69.4400 251.0000 1.0000
69.4800 261.0000 1.0000
69.5200 261.0000 1.0000
69.5600 224.0000 1.0000
69.6000 237.0000 1.0000
69.6400 227.0000 1.0000
69.6800 225.0000 1.0000
69.7200 228.0000 1.0000
69.7600 227.0000 1.0000
69.8000 247.0000 1.0000
69.8400 248.0000 1.0000
69.8800 265.0000 1.0000
69.9200 252.0000 1.0000
69.9600 229.0000 1.0000
70.0000 234.0000 1.0000
*RAS_INT_END
*RAS_TEMPERATURE_START
*RAS_TEMPERATURE_END
*RAS_DATA_END