File: Data/Dataset1_Only_water/5_XRD/No_012_FS3_4.ras
*RAS_DATA_START
*RAS_HEADER_START
*DISP_FMT_X "%.2f"
*DISP_FMT_Y "%.0f"
*DISP_FULLSCALE "16316.0000000000"
*DISP_LINE_COLOR "255.0000000000"
*DISP_LINE_STYLE "0.0000000000"
*DISP_LINE_WIDTH "0.2500000000"
*DISP_NOTE "測定データ-3"
*DISP_OFFSET_Y "0.0000000000"
*DISP_PEAKSEARCH_UNIT_Y "cps"
*DISP_RANGE_BOTTOM "0.0000000000"
*DISP_RANGE_LEFT "20.0000000000"
*DISP_RANGE_LOGCUTOFF "0.0100000000"
*DISP_RANGE_RIGHT "70.0000000000"
*DISP_RANGE_TOP "16316.0000000000"
*DISP_SCALE_MODE_Y "0.0000000000"
*DISP_TAB_NAME "2θ/θ"
*DISP_TITLE_Y "強度"
*DISP_UNIT_Y "cps"
*DISP_WINDOW_NAME "MSG_MACROENGINE"
*FILE_COMMENT " "
*FILE_MD5 ""
*FILE_MEMO " "
*FILE_OPERATOR "Administrator"
*FILE_SAMPLE " "
*FILE_TYPE "RAS_RAW"
*FILE_USERGROUP "システムマネージャ"
*FILE_VERSION "1.0000000000"
*HW_ATTACHMENT_ID "ATT0025"
*HW_ATTACHMENT_NAME "標準|Standard"
*HW_COUNTER_ID-0 "CUT0025"
*HW_COUNTER_ID-1 "CUT0020"
*HW_COUNTER_ID-2 "CUT0020"
*HW_COUNTER_ID-3 "CSL0021"
*HW_COUNTER_ID-4 "CMC0021"
*HW_COUNTER_NAME-0 "D/teX Ultra|D/teX Ultra"
*HW_COUNTER_NAME-1 "None|None"
*HW_COUNTER_NAME-2 "None|None"
*HW_COUNTER_NAME-3 "BBM|BBM"
*HW_COUNTER_NAME-4 "検出器モノクロメータ|Detector monochromator"
*HW_COUNTER_SELECT_NAME "D/teX Ultra|D/teX Ultra"
*HW_GONIOMETER_ID "GON0023"
*HW_GONIOMETER_NAME "SmartLab|SmartLab"
*HW_GONIOMETER_RADIUS-0 "90.0"
*HW_GONIOMETER_RADIUS-1 "114.0"
*HW_GONIOMETER_RADIUS-2 "190.0"
*HW_GONIOMETER_RADIUS-3 "300.0"
*HW_GONIOMETER_RADIUS-4 "187.0"
*HW_GONIOMETER_RADIUS-5 "300.0"
*HW_GONIOMETER_RADIUS-6 "113.0"
*HW_GONIOMETER_RADIUS-7 "331.0"
*HW_I_OPT_ID-0 "CBO0021"
*HW_I_OPT_ID-1 "ICR0023"
*HW_I_OPT_ID-2 "ISL0021"
*HW_I_OPT_ID-3 "ISO0021"
*HW_I_OPT_ID-4 "IAD0021"
*HW_I_OPT_ID-5 "IPR0001"
*HW_I_OPT_NAME-0 "CBOユニット|CBO unit"
*HW_I_OPT_NAME-1 "標準入射光学ユニット|Standard incident optical unit"
*HW_I_OPT_NAME-2 "標準入射スリットボックス|Standard incident slit box"
*HW_I_OPT_NAME-3 "入射平行スリット|Incident parallel slit"
*HW_I_OPT_NAME-4 "長手制限スリット|Length limiting slit"
*HW_I_OPT_NAME-5 "None|None"
*HW_R_ATTENUATER_AUTOMODE "0"
*HW_R_OPT_ID-0 "RSS0021"
*HW_R_OPT_ID-1 "RCR0023"
*HW_R_OPT_ID-2 "RSO0021"
*HW_R_OPT_ID-3 "RRS0021"
*HW_R_OPT_ID-4 "ATN0021"
*HW_R_OPT_ID-5 "RFL0021"
*HW_R_OPT_ID-6 "RAD0021"
*HW_R_OPT_NAME-0 "標準受光スリットボックス1|Standard receiving slit box # 1"
*HW_R_OPT_NAME-1 "標準受光光学ユニット1|Standard receiving unit # 1"
*HW_R_OPT_NAME-2 "標準受光光学ユニット2|Standard receiving optical unit # 2"
*HW_R_OPT_NAME-3 "標準受光スリットボックス2|Standard receiving slit box # 2"
*HW_R_OPT_NAME-4 "標準アッテネータ|Standard Attenuator"
*HW_R_OPT_NAME-5 "Cu Kβ|Cu K-beta"
*HW_R_OPT_NAME-6 "調整用受光スリット|Alignment receiving slit"
*HW_SAMPLE_HOLDER_ID "SMP0023"
*HW_SAMPLE_HOLDER_NAME "標準Zステージ|Standard Z stage"
*HW_XG_CURRENT_MAX "50"
*HW_XG_CURRENT_MIN "2"
*HW_XG_CURRENT_RESOLUTION "1"
*HW_XG_CURRENT_UNIT "mA"
*HW_XG_FOCUS "1mm x 10mm"
*HW_XG_FOCUS_TYPE "Normal"
*HW_XG_ID ""
*HW_XG_NAME "3kW 封入管(ID:1200)|3kW Sealed tube(ID:1200)"
*HW_XG_TARGET_ATOMIC_NUMBER "29.0000000000"
*HW_XG_TARGET_NAME "Cu"
*HW_XG_TYPE "Hermetic"
*HW_XG_VOLTAGE_MAX "60"
*HW_XG_VOLTAGE_MIN "20"
*HW_XG_VOLTAGE_RESOLUTION "1"
*HW_XG_VOLTAGE_UNIT "kV"
*HW_XG_WATT_MAX "1.500"
*HW_XG_WATT_UNIT "kW"
*HW_XG_WAVE_LENGTH_ALPHA1 "1.540593"
*HW_XG_WAVE_LENGTH_ALPHA2 "1.544414"
*HW_XG_WAVE_LENGTH_BETA "1.392250"
*MEAS_COND_AXIS_NAME-0 "2θ/θ"
*MEAS_COND_AXIS_NAME-1 "2θ"
*MEAS_COND_AXIS_NAME-2 "ω"
*MEAS_COND_AXIS_NAME-3 "Z"
*MEAS_COND_AXIS_NAME-4 "2θ/ω"
*MEAS_COND_AXIS_NAME-5 "θs"
*MEAS_COND_AXIS_NAME-6 "θd"
*MEAS_COND_AXIS_NAME-7 "Ts"
*MEAS_COND_AXIS_NAME-8 "CBO選択スリット"
*MEAS_COND_AXIS_NAME-9 "M"
*MEAS_COND_AXIS_NAME-10 "入射平行スリット"
*MEAS_COND_AXIS_NAME-11 "入射スリット"
*MEAS_COND_AXIS_NAME-12 ""
*MEAS_COND_AXIS_NAME-13 "Zs"
*MEAS_COND_AXIS_NAME-14 "入射光学素子"
*MEAS_COND_AXIS_NAME-15 "長手制限スリット"
*MEAS_COND_AXIS_NAME-16 "センタースリット"
*MEAS_COND_AXIS_NAME-17 "フィルター"
*MEAS_COND_AXIS_NAME-18 "受光スリット1"
*MEAS_COND_AXIS_NAME-19 "受光スリット2"
*MEAS_COND_AXIS_NAME-20 "受光光学素子"
*MEAS_COND_AXIS_NAME-21 "受光平行スリット"
*MEAS_COND_AXIS_NAME-22 "調整用受光スリット"
*MEAS_COND_AXIS_NAME-23 ""
*MEAS_COND_AXIS_NAME-24 ""
*MEAS_COND_AXIS_NAME-25 "Zd"
*MEAS_COND_AXIS_NAME-26 "アッテネータ"
*MEAS_COND_AXIS_NAME-27 "検出器モノクロメータ"
*MEAS_COND_AXIS_NAME-28 "モノクロメータスリット"
*MEAS_COND_AXIS_NAME-29 "プライマリビーム"
*MEAS_COND_AXIS_NAME-30 "PHA"
*MEAS_COND_AXIS_NAME_INTERNAL-0 "TwoThetaTheta"
*MEAS_COND_AXIS_NAME_INTERNAL-1 "TwoTheta"
*MEAS_COND_AXIS_NAME_INTERNAL-2 "Omega"
*MEAS_COND_AXIS_NAME_INTERNAL-3 "Z"
*MEAS_COND_AXIS_NAME_INTERNAL-4 "TwoThetaOmega"
*MEAS_COND_AXIS_NAME_INTERNAL-5 "ThetaS"
*MEAS_COND_AXIS_NAME_INTERNAL-6 "ThetaD"
*MEAS_COND_AXIS_NAME_INTERNAL-7 "Ts"
*MEAS_COND_AXIS_NAME_INTERNAL-8 "CBO"
*MEAS_COND_AXIS_NAME_INTERNAL-9 "CBO-M"
*MEAS_COND_AXIS_NAME_INTERNAL-10 "IncidentSollerSlit"
*MEAS_COND_AXIS_NAME_INTERNAL-11 "IncidentSlitBox"
*MEAS_COND_AXIS_NAME_INTERNAL-12 "IncidentSlitBox-_Axis"
*MEAS_COND_AXIS_NAME_INTERNAL-13 "Zs"
*MEAS_COND_AXIS_NAME_INTERNAL-14 "IncidentMonochromator"
*MEAS_COND_AXIS_NAME_INTERNAL-15 "IncidentAxdSlit"
*MEAS_COND_AXIS_NAME_INTERNAL-16 "CenterSlit"
*MEAS_COND_AXIS_NAME_INTERNAL-17 "Filter"
*MEAS_COND_AXIS_NAME_INTERNAL-18 "ReceivingSlitBox1"
*MEAS_COND_AXIS_NAME_INTERNAL-19 "ReceivingSlitBox2"
*MEAS_COND_AXIS_NAME_INTERNAL-20 "ReceivingOptics"
*MEAS_COND_AXIS_NAME_INTERNAL-21 "ReceivingSollerSlit"
*MEAS_COND_AXIS_NAME_INTERNAL-22 "ReceivingAxdSlit"
*MEAS_COND_AXIS_NAME_INTERNAL-23 "ReceivingSlitBox1-_Axis"
*MEAS_COND_AXIS_NAME_INTERNAL-24 "ReceivingSlitBox2-_Axis"
*MEAS_COND_AXIS_NAME_INTERNAL-25 "ReceivingSlitBox2-Zd"
*MEAS_COND_AXIS_NAME_INTERNAL-26 "Attenuator"
*MEAS_COND_AXIS_NAME_INTERNAL-27 "CounterMonochromator"
*MEAS_COND_AXIS_NAME_INTERNAL-28 "CounterSlit"
*MEAS_COND_AXIS_NAME_INTERNAL-29 "IncidentPrimary"
*MEAS_COND_AXIS_NAME_INTERNAL-30 "PHA"
*MEAS_COND_AXIS_NAME_MAGICNO-0 "83951616.0000000000"
*MEAS_COND_AXIS_NAME_MAGICNO-1 "268632064.0000000000"
*MEAS_COND_AXIS_NAME_MAGICNO-2 "268500992.0000000000"
*MEAS_COND_AXIS_NAME_MAGICNO-3 "285278208.0000000000"
*MEAS_COND_AXIS_NAME_MAGICNO-4 "83951616.0000000000"
*MEAS_COND_AXIS_NAME_MAGICNO-5 "131072.0000000000"
*MEAS_COND_AXIS_NAME_MAGICNO-6 "131072.0000000000"
*MEAS_COND_AXIS_NAME_MAGICNO-7 "318898176.0000000000"
*MEAS_COND_AXIS_NAME_MAGICNO-8 "20971521.0000000000"
*MEAS_COND_AXIS_NAME_MAGICNO-9 "285343744.0000000000"
*MEAS_COND_AXIS_NAME_MAGICNO-10 "20971521.0000000000"
*MEAS_COND_AXIS_NAME_MAGICNO-11 "22020097.0000000000"
*MEAS_COND_AXIS_NAME_MAGICNO-12 "25165824.0000000000"
*MEAS_COND_AXIS_NAME_MAGICNO-13 "318898176.0000000000"
*MEAS_COND_AXIS_NAME_MAGICNO-14 "1.0000000000"
*MEAS_COND_AXIS_NAME_MAGICNO-15 "20971521.0000000000"
*MEAS_COND_AXIS_NAME_MAGICNO-16 "20971521.0000000000"
*MEAS_COND_AXIS_NAME_MAGICNO-17 "20971521.0000000000"
*MEAS_COND_AXIS_NAME_MAGICNO-18 "23068673.0000000000"
*MEAS_COND_AXIS_NAME_MAGICNO-19 "23068673.0000000000"
*MEAS_COND_AXIS_NAME_MAGICNO-20 "20971521.0000000000"
*MEAS_COND_AXIS_NAME_MAGICNO-21 "20971521.0000000000"
*MEAS_COND_AXIS_NAME_MAGICNO-22 "20971521.0000000000"
*MEAS_COND_AXIS_NAME_MAGICNO-23 "25165824.0000000000"
*MEAS_COND_AXIS_NAME_MAGICNO-24 "25165824.0000000000"
*MEAS_COND_AXIS_NAME_MAGICNO-25 "285343744.0000000000"
*MEAS_COND_AXIS_NAME_MAGICNO-26 "17301505.0000000000"
*MEAS_COND_AXIS_NAME_MAGICNO-27 "20971521.0000000000"
*MEAS_COND_AXIS_NAME_MAGICNO-28 "20971521.0000000000"
*MEAS_COND_AXIS_NAME_MAGICNO-29 "20971521.0000000000"
*MEAS_COND_AXIS_NAME_MAGICNO-30 "0.0000000000"
*MEAS_COND_AXIS_OFFSET-0 "-"
*MEAS_COND_AXIS_OFFSET-1 "-0.1081000000"
*MEAS_COND_AXIS_OFFSET-2 "0.3758000000"
*MEAS_COND_AXIS_OFFSET-3 "-"
*MEAS_COND_AXIS_OFFSET-4 "-"
*MEAS_COND_AXIS_OFFSET-5 "0.3758000000"
*MEAS_COND_AXIS_OFFSET-6 "-0.4839000000"
*MEAS_COND_AXIS_OFFSET-7 "-"
*MEAS_COND_AXIS_OFFSET-8 "-"
*MEAS_COND_AXIS_OFFSET-9 "-"
*MEAS_COND_AXIS_OFFSET-10 "-"
*MEAS_COND_AXIS_OFFSET-11 "-"
*MEAS_COND_AXIS_OFFSET-12 "-"
*MEAS_COND_AXIS_OFFSET-13 "-"
*MEAS_COND_AXIS_OFFSET-14 "-"
*MEAS_COND_AXIS_OFFSET-15 "-"
*MEAS_COND_AXIS_OFFSET-16 "-"
*MEAS_COND_AXIS_OFFSET-17 "-"
*MEAS_COND_AXIS_OFFSET-18 "-"
*MEAS_COND_AXIS_OFFSET-19 "-"
*MEAS_COND_AXIS_OFFSET-20 "-"
*MEAS_COND_AXIS_OFFSET-21 "-"
*MEAS_COND_AXIS_OFFSET-22 "-"
*MEAS_COND_AXIS_OFFSET-23 "-"
*MEAS_COND_AXIS_OFFSET-24 "-"
*MEAS_COND_AXIS_OFFSET-25 "-"
*MEAS_COND_AXIS_OFFSET-26 "-"
*MEAS_COND_AXIS_OFFSET-27 "-"
*MEAS_COND_AXIS_OFFSET-28 "-"
*MEAS_COND_AXIS_OFFSET-29 "-"
*MEAS_COND_AXIS_OFFSET-30 "-"
*MEAS_COND_AXIS_POSITION-0 "0.0000000000"
*MEAS_COND_AXIS_POSITION-1 "0.0000000000"
*MEAS_COND_AXIS_POSITION-2 "0.0000000000"
*MEAS_COND_AXIS_POSITION-3 "-0.5500000000"
*MEAS_COND_AXIS_POSITION-4 "0.0000000000"
*MEAS_COND_AXIS_POSITION-5 "0.0000000000"
*MEAS_COND_AXIS_POSITION-6 "0.0000000000"
*MEAS_COND_AXIS_POSITION-7 "-0.4278800000"
*MEAS_COND_AXIS_POSITION-8 "BB"
*MEAS_COND_AXIS_POSITION-9 "0.0000000000"
*MEAS_COND_AXIS_POSITION-10 "Soller_slit_5.0deg"
*MEAS_COND_AXIS_POSITION-11 "2/3deg"
*MEAS_COND_AXIS_POSITION-12 "2.2088000000"
*MEAS_COND_AXIS_POSITION-13 "-0.4140600000"
*MEAS_COND_AXIS_POSITION-14 "0.0000000000"
*MEAS_COND_AXIS_POSITION-15 "10.0mm"
*MEAS_COND_AXIS_POSITION-16 "None"
*MEAS_COND_AXIS_POSITION-17 "Cu_K-beta"
*MEAS_COND_AXIS_POSITION-18 "13.000mm"
*MEAS_COND_AXIS_POSITION-19 "13.000mm"
*MEAS_COND_AXIS_POSITION-20 "No_unit"
*MEAS_COND_AXIS_POSITION-21 "Soller_slit_5.0deg"
*MEAS_COND_AXIS_POSITION-22 "None"
*MEAS_COND_AXIS_POSITION-23 "13.0000000000"
*MEAS_COND_AXIS_POSITION-24 "13.0000000000"
*MEAS_COND_AXIS_POSITION-25 "0.0109400000"
*MEAS_COND_AXIS_POSITION-26 "Open"
*MEAS_COND_AXIS_POSITION-27 "None"
*MEAS_COND_AXIS_POSITION-28 "None"
*MEAS_COND_AXIS_POSITION-29 "None"
*MEAS_COND_AXIS_POSITION-30 "38.0000000000"
*MEAS_COND_AXIS_UNIT-0 "deg"
*MEAS_COND_AXIS_UNIT-1 "deg"
*MEAS_COND_AXIS_UNIT-2 "deg"
*MEAS_COND_AXIS_UNIT-3 "mm"
*MEAS_COND_AXIS_UNIT-4 "deg"
*MEAS_COND_AXIS_UNIT-5 "deg"
*MEAS_COND_AXIS_UNIT-6 "deg"
*MEAS_COND_AXIS_UNIT-7 "mm"
*MEAS_COND_AXIS_UNIT-8 ""
*MEAS_COND_AXIS_UNIT-9 "pulse"
*MEAS_COND_AXIS_UNIT-10 ""
*MEAS_COND_AXIS_UNIT-11 ""
*MEAS_COND_AXIS_UNIT-12 "mm"
*MEAS_COND_AXIS_UNIT-13 "mm"
*MEAS_COND_AXIS_UNIT-14 ""
*MEAS_COND_AXIS_UNIT-15 ""
*MEAS_COND_AXIS_UNIT-16 ""
*MEAS_COND_AXIS_UNIT-17 ""
*MEAS_COND_AXIS_UNIT-18 ""
*MEAS_COND_AXIS_UNIT-19 ""
*MEAS_COND_AXIS_UNIT-20 ""
*MEAS_COND_AXIS_UNIT-21 ""
*MEAS_COND_AXIS_UNIT-22 ""
*MEAS_COND_AXIS_UNIT-23 "mm"
*MEAS_COND_AXIS_UNIT-24 "mm"
*MEAS_COND_AXIS_UNIT-25 "mm"
*MEAS_COND_AXIS_UNIT-26 ""
*MEAS_COND_AXIS_UNIT-27 ""
*MEAS_COND_AXIS_UNIT-28 ""
*MEAS_COND_AXIS_UNIT-29 ""
*MEAS_COND_AXIS_UNIT-30 "div"
*MEAS_COND_COUNTER_CNTLOSS_CORR "0.0000000000"
*MEAS_COND_COUNTER_PHABASE "38.0000000000"
*MEAS_COND_COUNTER_PHAWINDOW "16.0000000000"
*MEAS_COND_COUNTER_PHA_UNIT "div"
*MEAS_COND_COUNTER_TAUDIFF "30.0000000000"
*MEAS_COND_COUNTER_TAUINT "0.0000000000"
*MEAS_COND_IRRADIATION_MODE "OFF"
*MEAS_COND_IRRADIATION_WIDTH ""
*MEAS_COND_OPT_ATTR "集中法"
*MEAS_COND_OPT_NAME "@集中法"
*MEAS_COND_UNSYMMETRIC_MODE "OFF"
*MEAS_COND_XG_CURRENT "30.0000000000"
*MEAS_COND_XG_VOLTAGE "40.0000000000"
*MEAS_COND_XG_WAVE_TYPE "Ka"
*MEAS_DATA_COUNT "5001.0000000000"
*MEAS_SCAN_AXIS_X "2θ/θ"
*MEAS_SCAN_AXIS_X_INTERNAL "TwoThetaTheta"
*MEAS_SCAN_END_TIME "07/06/21 15:24:12"
*MEAS_SCAN_MODE "CONTINUOUS"
*MEAS_SCAN_MONITOR "0"
*MEAS_SCAN_RESOLUTION_X "0.0002"
*MEAS_SCAN_SPEED "1.0"
*MEAS_SCAN_SPEED_UNIT "deg/min"
*MEAS_SCAN_START "20.0000000000"
*MEAS_SCAN_START_TIME "07/06/21 14:31:18"
*MEAS_SCAN_STEP "0.0100000000"
*MEAS_SCAN_STOP "70.0000000000"
*MEAS_SCAN_UNIT_X "deg"
*MEAS_SCAN_UNIT_Y "counts"
*RAS_HEADER_END
*RAS_INT_START
20.0000 1659.0000 1.0000
20.0400 1702.0000 1.0000
20.0800 1679.0000 1.0000
20.1200 1710.0000 1.0000
20.1600 1634.0000 1.0000
20.2000 1654.0000 1.0000
20.2400 1676.0000 1.0000
20.2800 1687.0000 1.0000
20.3200 1660.0000 1.0000
20.3600 1612.0000 1.0000
20.4000 1673.0000 1.0000
20.4400 1640.0000 1.0000
20.4800 1680.0000 1.0000
20.5200 1742.0000 1.0000
20.5600 1589.0000 1.0000
20.6000 1700.0000 1.0000
20.6400 1631.0000 1.0000
20.6800 1667.0000 1.0000
20.7200 1656.0000 1.0000
20.7600 1647.0000 1.0000
20.8000 1708.0000 1.0000
20.8400 1686.0000 1.0000
20.8800 1679.0000 1.0000
20.9200 1735.0000 1.0000
20.9600 1701.0000 1.0000
21.0000 1657.0000 1.0000
21.0400 1670.0000 1.0000
21.0800 1651.0000 1.0000
21.1200 1700.0000 1.0000
21.1600 1657.0000 1.0000
21.2000 1719.0000 1.0000
21.2400 1610.0000 1.0000
21.2800 1674.0000 1.0000
21.3200 1673.0000 1.0000
21.3600 1734.0000 1.0000
21.4000 1658.0000 1.0000
21.4400 1670.0000 1.0000
21.4800 1680.0000 1.0000
21.5200 1701.0000 1.0000
21.5600 1630.0000 1.0000
21.6000 1654.0000 1.0000
21.6400 1767.0000 1.0000
21.6800 1744.0000 1.0000
21.7200 1715.0000 1.0000
21.7600 1680.0000 1.0000
21.8000 1718.0000 1.0000
21.8400 1718.0000 1.0000
21.8800 1681.0000 1.0000
21.9200 1742.0000 1.0000
21.9600 1675.0000 1.0000
22.0000 1721.0000 1.0000
22.0400 1743.0000 1.0000
22.0800 1710.0000 1.0000
22.1200 1695.0000 1.0000
22.1600 1660.0000 1.0000
22.2000 1716.0000 1.0000
22.2400 1710.0000 1.0000
22.2800 1726.0000 1.0000
22.3200 1704.0000 1.0000
22.3600 1673.0000 1.0000
22.4000 1710.0000 1.0000
22.4400 1727.0000 1.0000
22.4800 1774.0000 1.0000
22.5200 1775.0000 1.0000
22.5600 1646.0000 1.0000
22.6000 1679.0000 1.0000
22.6400 1710.0000 1.0000
22.6800 1698.0000 1.0000
22.7200 1781.0000 1.0000
22.7600 1686.0000 1.0000
22.8000 1708.0000 1.0000
22.8400 1732.0000 1.0000
22.8800 1689.0000 1.0000
22.9200 1772.0000 1.0000
22.9600 1749.0000 1.0000
23.0000 1724.0000 1.0000
23.0400 1758.0000 1.0000
23.0800 1729.0000 1.0000
23.1200 1773.0000 1.0000
23.1600 1743.0000 1.0000
23.2000 1729.0000 1.0000
23.2400 1752.0000 1.0000
23.2800 1739.0000 1.0000
23.3200 1745.0000 1.0000
23.3600 1697.0000 1.0000
23.4000 1764.0000 1.0000
23.4400 1783.0000 1.0000
23.4800 1782.0000 1.0000
23.5200 1747.0000 1.0000
23.5600 1792.0000 1.0000
23.6000 1737.0000 1.0000
23.6400 1689.0000 1.0000
23.6800 1765.0000 1.0000
23.7200 1740.0000 1.0000
23.7600 1746.0000 1.0000
23.8000 1689.0000 1.0000
23.8400 1771.0000 1.0000
23.8800 1724.0000 1.0000
23.9200 1772.0000 1.0000
23.9600 1778.0000 1.0000
24.0000 1767.0000 1.0000
24.0400 1750.0000 1.0000
24.0800 1772.0000 1.0000
24.1200 1762.0000 1.0000
24.1600 1784.0000 1.0000
24.2000 1746.0000 1.0000
24.2400 1788.0000 1.0000
24.2800 1756.0000 1.0000
24.3200 1769.0000 1.0000
24.3600 1806.0000 1.0000
24.4000 1745.0000 1.0000
24.4400 1764.0000 1.0000
24.4800 1792.0000 1.0000
24.5200 1751.0000 1.0000
24.5600 1821.0000 1.0000
24.6000 1847.0000 1.0000
24.6400 1791.0000 1.0000
24.6800 1839.0000 1.0000
24.7200 1839.0000 1.0000
24.7600 1802.0000 1.0000
24.8000 1762.0000 1.0000
24.8400 1879.0000 1.0000
24.8800 1853.0000 1.0000
24.9200 1849.0000 1.0000
24.9600 1869.0000 1.0000
25.0000 1852.0000 1.0000
25.0400 1820.0000 1.0000
25.0800 1822.0000 1.0000
25.1200 1784.0000 1.0000
25.1600 1770.0000 1.0000
25.2000 1864.0000 1.0000
25.2400 1871.0000 1.0000
25.2800 1815.0000 1.0000
25.3200 1791.0000 1.0000
25.3600 1873.0000 1.0000
25.4000 1837.0000 1.0000
25.4400 1813.0000 1.0000
25.4800 1851.0000 1.0000
25.5200 1831.0000 1.0000
25.5600 1795.0000 1.0000
25.6000 1801.0000 1.0000
25.6400 1793.0000 1.0000
25.6800 1806.0000 1.0000
25.7200 1780.0000 1.0000
25.7600 1860.0000 1.0000
25.8000 1804.0000 1.0000
25.8400 1822.0000 1.0000
25.8800 1828.0000 1.0000
25.9200 1798.0000 1.0000
25.9600 1816.0000 1.0000
26.0000 1782.0000 1.0000
26.0400 1799.0000 1.0000
26.0800 1827.0000 1.0000
26.1200 1798.0000 1.0000
26.1600 1869.0000 1.0000
26.2000 1864.0000 1.0000
26.2400 1816.0000 1.0000
26.2800 1808.0000 1.0000
26.3200 1838.0000 1.0000
26.3600 1827.0000 1.0000
26.4000 1884.0000 1.0000
26.4400 1799.0000 1.0000
26.4800 1878.0000 1.0000
26.5200 1928.0000 1.0000
26.5600 1863.0000 1.0000
26.6000 1962.0000 1.0000
26.6400 1975.0000 1.0000
26.6800 1972.0000 1.0000
26.7200 1915.0000 1.0000
26.7600 2008.0000 1.0000
26.8000 2017.0000 1.0000
26.8400 2065.0000 1.0000
26.8800 2116.0000 1.0000
26.9200 2145.0000 1.0000
26.9600 2327.0000 1.0000
27.0000 2475.0000 1.0000
27.0400 2662.0000 1.0000
27.0800 2957.0000 1.0000
27.1200 3373.0000 1.0000
27.1600 3893.0000 1.0000
27.2000 4747.0000 1.0000
27.2400 5866.0000 1.0000
27.2800 6809.0000 1.0000
27.3200 6767.0000 1.0000
27.3600 5936.0000 1.0000
27.4000 4936.0000 1.0000
27.4400 4105.0000 1.0000
27.4800 3363.0000 1.0000
27.5200 2903.0000 1.0000
27.5600 2607.0000 1.0000
27.6000 2416.0000 1.0000
27.6400 2197.0000 1.0000
27.6800 2218.0000 1.0000
27.7200 2060.0000 1.0000
27.7600 1991.0000 1.0000
27.8000 1982.0000 1.0000
27.8400 1955.0000 1.0000
27.8800 1924.0000 1.0000
27.9200 1910.0000 1.0000
27.9600 1932.0000 1.0000
28.0000 1886.0000 1.0000
28.0400 1843.0000 1.0000
28.0800 1796.0000 1.0000
28.1200 1843.0000 1.0000
28.1600 1760.0000 1.0000
28.2000 1772.0000 1.0000
28.2400 1871.0000 1.0000
28.2800 1760.0000 1.0000
28.3200 1795.0000 1.0000
28.3600 1690.0000 1.0000
28.4000 1703.0000 1.0000
28.4400 1797.0000 1.0000
28.4800 1718.0000 1.0000
28.5200 1677.0000 1.0000
28.5600 1711.0000 1.0000
28.6000 1757.0000 1.0000
28.6400 1760.0000 1.0000
28.6800 1700.0000 1.0000
28.7200 1728.0000 1.0000
28.7600 1723.0000 1.0000
28.8000 1657.0000 1.0000
28.8400 1715.0000 1.0000
28.8800 1628.0000 1.0000
28.9200 1682.0000 1.0000
28.9600 1639.0000 1.0000
29.0000 1744.0000 1.0000
29.0400 1672.0000 1.0000
29.0800 1682.0000 1.0000
29.1200 1606.0000 1.0000
29.1600 1663.0000 1.0000
29.2000 1692.0000 1.0000
29.2400 1664.0000 1.0000
29.2800 1593.0000 1.0000
29.3200 1686.0000 1.0000
29.3600 1603.0000 1.0000
29.4000 1718.0000 1.0000
29.4400 1630.0000 1.0000
29.4800 1685.0000 1.0000
29.5200 1608.0000 1.0000
29.5600 1681.0000 1.0000
29.6000 1601.0000 1.0000
29.6400 1648.0000 1.0000
29.6800 1619.0000 1.0000
29.7200 1621.0000 1.0000
29.7600 1611.0000 1.0000
29.8000 1539.0000 1.0000
29.8400 1621.0000 1.0000
29.8800 1634.0000 1.0000
29.9200 1571.0000 1.0000
29.9600 1622.0000 1.0000
30.0000 1595.0000 1.0000
30.0400 1588.0000 1.0000
30.0800 1607.0000 1.0000
30.1200 1571.0000 1.0000
30.1600 1581.0000 1.0000
30.2000 1548.0000 1.0000
30.2400 1556.0000 1.0000
30.2800 1603.0000 1.0000
30.3200 1576.0000 1.0000
30.3600 1574.0000 1.0000
30.4000 1545.0000 1.0000
30.4400 1596.0000 1.0000
30.4800 1591.0000 1.0000
30.5200 1596.0000 1.0000
30.5600 1526.0000 1.0000
30.6000 1571.0000 1.0000
30.6400 1629.0000 1.0000
30.6800 1599.0000 1.0000
30.7200 1489.0000 1.0000
30.7600 1602.0000 1.0000
30.8000 1482.0000 1.0000
30.8400 1575.0000 1.0000
30.8800 1542.0000 1.0000
30.9200 1648.0000 1.0000
30.9600 1585.0000 1.0000
31.0000 1467.0000 1.0000
31.0400 1524.0000 1.0000
31.0800 1551.0000 1.0000
31.1200 1611.0000 1.0000
31.1600 1473.0000 1.0000
31.2000 1466.0000 1.0000
31.2400 1523.0000 1.0000
31.2800 1505.0000 1.0000
31.3200 1476.0000 1.0000
31.3600 1518.0000 1.0000
31.4000 1516.0000 1.0000
31.4400 1573.0000 1.0000
31.4800 1439.0000 1.0000
31.5200 1526.0000 1.0000
31.5600 1451.0000 1.0000
31.6000 1498.0000 1.0000
31.6400 1541.0000 1.0000
31.6800 1471.0000 1.0000
31.7200 1464.0000 1.0000
31.7600 1507.0000 1.0000
31.8000 1540.0000 1.0000
31.8400 1499.0000 1.0000
31.8800 1610.0000 1.0000
31.9200 1499.0000 1.0000
31.9600 1566.0000 1.0000
32.0000 1568.0000 1.0000
32.0400 1568.0000 1.0000
32.0800 1509.0000 1.0000
32.1200 1523.0000 1.0000
32.1600 1474.0000 1.0000
32.2000 1492.0000 1.0000
32.2400 1504.0000 1.0000
32.2800 1473.0000 1.0000
32.3200 1465.0000 1.0000
32.3600 1483.0000 1.0000
32.4000 1472.0000 1.0000
32.4400 1487.0000 1.0000
32.4800 1382.0000 1.0000
32.5200 1507.0000 1.0000
32.5600 1436.0000 1.0000
32.6000 1458.0000 1.0000
32.6400 1476.0000 1.0000
32.6800 1400.0000 1.0000
32.7200 1473.0000 1.0000
32.7600 1477.0000 1.0000
32.8000 1434.0000 1.0000
32.8400 1469.0000 1.0000
32.8800 1455.0000 1.0000
32.9200 1459.0000 1.0000
32.9600 1451.0000 1.0000
33.0000 1476.0000 1.0000
33.0400 1409.0000 1.0000
33.0800 1416.0000 1.0000
33.1200 1376.0000 1.0000
33.1600 1466.0000 1.0000
33.2000 1396.0000 1.0000
33.2400 1445.0000 1.0000
33.2800 1391.0000 1.0000
33.3200 1493.0000 1.0000
33.3600 1431.0000 1.0000
33.4000 1430.0000 1.0000
33.4400 1410.0000 1.0000
33.4800 1400.0000 1.0000
33.5200 1438.0000 1.0000
33.5600 1443.0000 1.0000
33.6000 1407.0000 1.0000
33.6400 1356.0000 1.0000
33.6800 1383.0000 1.0000
33.7200 1421.0000 1.0000
33.7600 1400.0000 1.0000
33.8000 1440.0000 1.0000
33.8400 1495.0000 1.0000
33.8800 1561.0000 1.0000
33.9200 1627.0000 1.0000
33.9600 1665.0000 1.0000
34.0000 1659.0000 1.0000
34.0400 1585.0000 1.0000
34.0800 1545.0000 1.0000
34.1200 1640.0000 1.0000
34.1600 1553.0000 1.0000
34.2000 1677.0000 1.0000
34.2400 1688.0000 1.0000
34.2800 1855.0000 1.0000
34.3200 1950.0000 1.0000
34.3600 2166.0000 1.0000
34.4000 2534.0000 1.0000
34.4400 2900.0000 1.0000
34.4800 3129.0000 1.0000
34.5200 3083.0000 1.0000
34.5600 2834.0000 1.0000
34.6000 2520.0000 1.0000
34.6400 2296.0000 1.0000
34.6800 2017.0000 1.0000
34.7200 1862.0000 1.0000
34.7600 1787.0000 1.0000
34.8000 1626.0000 1.0000
34.8400 1557.0000 1.0000
34.8800 1488.0000 1.0000
34.9200 1449.0000 1.0000
34.9600 1421.0000 1.0000
35.0000 1417.0000 1.0000
35.0400 1319.0000 1.0000
35.0800 1393.0000 1.0000
35.1200 1330.0000 1.0000
35.1600 1343.0000 1.0000
35.2000 1326.0000 1.0000
35.2400 1295.0000 1.0000
35.2800 1263.0000 1.0000
35.3200 1234.0000 1.0000
35.3600 1252.0000 1.0000
35.4000 1240.0000 1.0000
35.4400 1174.0000 1.0000
35.4800 1258.0000 1.0000
35.5200 1275.0000 1.0000
35.5600 1310.0000 1.0000
35.6000 1289.0000 1.0000
35.6400 1185.0000 1.0000
35.6800 1212.0000 1.0000
35.7200 1261.0000 1.0000
35.7600 1193.0000 1.0000
35.8000 1203.0000 1.0000
35.8400 1213.0000 1.0000
35.8800 1171.0000 1.0000
35.9200 1160.0000 1.0000
35.9600 1207.0000 1.0000
36.0000 1276.0000 1.0000
36.0400 1239.0000 1.0000
36.0800 1250.0000 1.0000
36.1200 1249.0000 1.0000
36.1600 1303.0000 1.0000
36.2000 1316.0000 1.0000
36.2400 1445.0000 1.0000
36.2800 1602.0000 1.0000
36.3200 1770.0000 1.0000
36.3600 2155.0000 1.0000
36.4000 2478.0000 1.0000
36.4400 2338.0000 1.0000
36.4800 1940.0000 1.0000
36.5200 1775.0000 1.0000
36.5600 1491.0000 1.0000
36.6000 1282.0000 1.0000
36.6400 1233.0000 1.0000
36.6800 1222.0000 1.0000
36.7200 1187.0000 1.0000
36.7600 1114.0000 1.0000
36.8000 1143.0000 1.0000
36.8400 1172.0000 1.0000
36.8800 1085.0000 1.0000
36.9200 1128.0000 1.0000
36.9600 1198.0000 1.0000
37.0000 1083.0000 1.0000
37.0400 1096.0000 1.0000
37.0800 1116.0000 1.0000
37.1200 1127.0000 1.0000
37.1600 1100.0000 1.0000
37.2000 1146.0000 1.0000
37.2400 1084.0000 1.0000
37.2800 1103.0000 1.0000
37.3200 1149.0000 1.0000
37.3600 1144.0000 1.0000
37.4000 1156.0000 1.0000
37.4400 1119.0000 1.0000
37.4800 1132.0000 1.0000
37.5200 1090.0000 1.0000
37.5600 1077.0000 1.0000
37.6000 1131.0000 1.0000
37.6400 1125.0000 1.0000
37.6800 1196.0000 1.0000
37.7200 1092.0000 1.0000
37.7600 1141.0000 1.0000
37.8000 1093.0000 1.0000
37.8400 1161.0000 1.0000
37.8800 1168.0000 1.0000
37.9200 1167.0000 1.0000
37.9600 1208.0000 1.0000
38.0000 1195.0000 1.0000
38.0400 1212.0000 1.0000
38.0800 1311.0000 1.0000
38.1200 1353.0000 1.0000
38.1600 1408.0000 1.0000
38.2000 1534.0000 1.0000
38.2400 1784.0000 1.0000
38.2800 1980.0000 1.0000
38.3200 2373.0000 1.0000
38.3600 2920.0000 1.0000
38.4000 3838.0000 1.0000
38.4400 5063.0000 1.0000
38.4800 6625.0000 1.0000
38.5200 7753.0000 1.0000
38.5600 8158.0000 1.0000
38.6000 7535.0000 1.0000
38.6400 6263.0000 1.0000
38.6800 4990.0000 1.0000
38.7200 3750.0000 1.0000
38.7600 2801.0000 1.0000
38.8000 2296.0000 1.0000
38.8400 1863.0000 1.0000
38.8800 1667.0000 1.0000
38.9200 1447.0000 1.0000
38.9600 1344.0000 1.0000
39.0000 1290.0000 1.0000
39.0400 1211.0000 1.0000
39.0800 1182.0000 1.0000
39.1200 1145.0000 1.0000
39.1600 1091.0000 1.0000
39.2000 1057.0000 1.0000
39.2400 1034.0000 1.0000
39.2800 1019.0000 1.0000
39.3200 1048.0000 1.0000
39.3600 1063.0000 1.0000
39.4000 1071.0000 1.0000
39.4400 1083.0000 1.0000
39.4800 1047.0000 1.0000
39.5200 1047.0000 1.0000
39.5600 1028.0000 1.0000
39.6000 1037.0000 1.0000
39.6400 1066.0000 1.0000
39.6800 1057.0000 1.0000
39.7200 1025.0000 1.0000
39.7600 1028.0000 1.0000
39.8000 1021.0000 1.0000
39.8400 1001.0000 1.0000
39.8800 1015.0000 1.0000
39.9200 1008.0000 1.0000
39.9600 979.0000 1.0000
40.0000 987.0000 1.0000
40.0400 959.0000 1.0000
40.0800 987.0000 1.0000
40.1200 979.0000 1.0000
40.1600 985.0000 1.0000
40.2000 958.0000 1.0000
40.2400 924.0000 1.0000
40.2800 961.0000 1.0000
40.3200 920.0000 1.0000
40.3600 954.0000 1.0000
40.4000 966.0000 1.0000
40.4400 935.0000 1.0000
40.4800 940.0000 1.0000
40.5200 912.0000 1.0000
40.5600 983.0000 1.0000
40.6000 923.0000 1.0000
40.6400 913.0000 1.0000
40.6800 908.0000 1.0000
40.7200 993.0000 1.0000
40.7600 934.0000 1.0000
40.8000 891.0000 1.0000
40.8400 955.0000 1.0000
40.8800 924.0000 1.0000
40.9200 951.0000 1.0000
40.9600 909.0000 1.0000
41.0000 912.0000 1.0000
41.0400 926.0000 1.0000
41.0800 879.0000 1.0000
41.1200 928.0000 1.0000
41.1600 936.0000 1.0000
41.2000 928.0000 1.0000
41.2400 919.0000 1.0000
41.2800 911.0000 1.0000
41.3200 910.0000 1.0000
41.3600 865.0000 1.0000
41.4000 935.0000 1.0000
41.4400 876.0000 1.0000
41.4800 937.0000 1.0000
41.5200 922.0000 1.0000
41.5600 913.0000 1.0000
41.6000 938.0000 1.0000
41.6400 939.0000 1.0000
41.6800 943.0000 1.0000
41.7200 932.0000 1.0000
41.7600 888.0000 1.0000
41.8000 898.0000 1.0000
41.8400 948.0000 1.0000
41.8800 925.0000 1.0000
41.9200 927.0000 1.0000
41.9600 879.0000 1.0000
42.0000 904.0000 1.0000
42.0400 912.0000 1.0000
42.0800 875.0000 1.0000
42.1200 901.0000 1.0000
42.1600 949.0000 1.0000
42.2000 919.0000 1.0000
42.2400 898.0000 1.0000
42.2800 882.0000 1.0000
42.3200 927.0000 1.0000
42.3600 896.0000 1.0000
42.4000 890.0000 1.0000
42.4400 880.0000 1.0000
42.4800 901.0000 1.0000
42.5200 869.0000 1.0000
42.5600 906.0000 1.0000
42.6000 913.0000 1.0000
42.6400 939.0000 1.0000
42.6800 937.0000 1.0000
42.7200 910.0000 1.0000
42.7600 903.0000 1.0000
42.8000 910.0000 1.0000
42.8400 885.0000 1.0000
42.8800 947.0000 1.0000
42.9200 965.0000 1.0000
42.9600 916.0000 1.0000
43.0000 927.0000 1.0000
43.0400 906.0000 1.0000
43.0800 886.0000 1.0000
43.1200 958.0000 1.0000
43.1600 941.0000 1.0000
43.2000 991.0000 1.0000
43.2400 970.0000 1.0000
43.2800 977.0000 1.0000
43.3200 972.0000 1.0000
43.3600 940.0000 1.0000
43.4000 897.0000 1.0000
43.4400 953.0000 1.0000
43.4800 933.0000 1.0000
43.5200 903.0000 1.0000
43.5600 926.0000 1.0000
43.6000 917.0000 1.0000
43.6400 838.0000 1.0000
43.6800 920.0000 1.0000
43.7200 919.0000 1.0000
43.7600 862.0000 1.0000
43.8000 852.0000 1.0000
43.8400 860.0000 1.0000
43.8800 899.0000 1.0000
43.9200 832.0000 1.0000
43.9600 892.0000 1.0000
44.0000 879.0000 1.0000
44.0400 861.0000 1.0000
44.0800 902.0000 1.0000
44.1200 842.0000 1.0000
44.1600 878.0000 1.0000
44.2000 874.0000 1.0000
44.2400 917.0000 1.0000
44.2800 841.0000 1.0000
44.3200 878.0000 1.0000
44.3600 849.0000 1.0000
44.4000 820.0000 1.0000
44.4400 893.0000 1.0000
44.4800 851.0000 1.0000
44.5200 891.0000 1.0000
44.5600 843.0000 1.0000
44.6000 861.0000 1.0000
44.6400 867.0000 1.0000
44.6800 877.0000 1.0000
44.7200 858.0000 1.0000
44.7600 870.0000 1.0000
44.8000 813.0000 1.0000
44.8400 850.0000 1.0000
44.8800 844.0000 1.0000
44.9200 820.0000 1.0000
44.9600 893.0000 1.0000
45.0000 889.0000 1.0000
45.0400 864.0000 1.0000
45.0800 850.0000 1.0000
45.1200 823.0000 1.0000
45.1600 872.0000 1.0000
45.2000 844.0000 1.0000
45.2400 846.0000 1.0000
45.2800 858.0000 1.0000
45.3200 862.0000 1.0000
45.3600 846.0000 1.0000
45.4000 863.0000 1.0000
45.4400 817.0000 1.0000
45.4800 862.0000 1.0000
45.5200 831.0000 1.0000
45.5600 842.0000 1.0000
45.6000 846.0000 1.0000
45.6400 810.0000 1.0000
45.6800 814.0000 1.0000
45.7200 830.0000 1.0000
45.7600 785.0000 1.0000
45.8000 847.0000 1.0000
45.8400 805.0000 1.0000
45.8800 823.0000 1.0000
45.9200 837.0000 1.0000
45.9600 836.0000 1.0000
46.0000 793.0000 1.0000
46.0400 850.0000 1.0000
46.0800 830.0000 1.0000
46.1200 808.0000 1.0000
46.1600 861.0000 1.0000
46.2000 816.0000 1.0000
46.2400 822.0000 1.0000
46.2800 823.0000 1.0000
46.3200 824.0000 1.0000
46.3600 796.0000 1.0000
46.4000 758.0000 1.0000
46.4400 796.0000 1.0000
46.4800 820.0000 1.0000
46.5200 828.0000 1.0000
46.5600 821.0000 1.0000
46.6000 759.0000 1.0000
46.6400 799.0000 1.0000
46.6800 819.0000 1.0000
46.7200 835.0000 1.0000
46.7600 809.0000 1.0000
46.8000 805.0000 1.0000
46.8400 789.0000 1.0000
46.8800 845.0000 1.0000
46.9200 770.0000 1.0000
46.9600 832.0000 1.0000
47.0000 859.0000 1.0000
47.0400 834.0000 1.0000
47.0800 808.0000 1.0000
47.1200 787.0000 1.0000
47.1600 785.0000 1.0000
47.2000 818.0000 1.0000
47.2400 802.0000 1.0000
47.2800 770.0000 1.0000
47.3200 788.0000 1.0000
47.3600 795.0000 1.0000
47.4000 827.0000 1.0000
47.4400 838.0000 1.0000
47.4800 812.0000 1.0000
47.5200 794.0000 1.0000
47.5600 797.0000 1.0000
47.6000 797.0000 1.0000
47.6400 764.0000 1.0000
47.6800 756.0000 1.0000
47.7200 803.0000 1.0000
47.7600 770.0000 1.0000
47.8000 783.0000 1.0000
47.8400 827.0000 1.0000
47.8800 746.0000 1.0000
47.9200 799.0000 1.0000
47.9600 766.0000 1.0000
48.0000 752.0000 1.0000
48.0400 815.0000 1.0000
48.0800 814.0000 1.0000
48.1200 720.0000 1.0000
48.1600 799.0000 1.0000
48.2000 803.0000 1.0000
48.2400 791.0000 1.0000
48.2800 813.0000 1.0000
48.3200 750.0000 1.0000
48.3600 764.0000 1.0000
48.4000 746.0000 1.0000
48.4400 800.0000 1.0000
48.4800 801.0000 1.0000
48.5200 848.0000 1.0000
48.5600 727.0000 1.0000
48.6000 787.0000 1.0000
48.6400 747.0000 1.0000
48.6800 790.0000 1.0000
48.7200 765.0000 1.0000
48.7600 749.0000 1.0000
48.8000 790.0000 1.0000
48.8400 781.0000 1.0000
48.8800 784.0000 1.0000
48.9200 802.0000 1.0000
48.9600 757.0000 1.0000
49.0000 766.0000 1.0000
49.0400 800.0000 1.0000
49.0800 795.0000 1.0000
49.1200 764.0000 1.0000
49.1600 799.0000 1.0000
49.2000 717.0000 1.0000
49.2400 769.0000 1.0000
49.2800 796.0000 1.0000
49.3200 757.0000 1.0000
49.3600 714.0000 1.0000
49.4000 770.0000 1.0000
49.4400 756.0000 1.0000
49.4800 744.0000 1.0000
49.5200 743.0000 1.0000
49.5600 780.0000 1.0000
49.6000 781.0000 1.0000
49.6400 737.0000 1.0000
49.6800 746.0000 1.0000
49.7200 779.0000 1.0000
49.7600 761.0000 1.0000
49.8000 753.0000 1.0000
49.8400 745.0000 1.0000
49.8800 730.0000 1.0000
49.9200 747.0000 1.0000
49.9600 757.0000 1.0000
50.0000 796.0000 1.0000
50.0400 755.0000 1.0000
50.0800 783.0000 1.0000
50.1200 787.0000 1.0000
50.1600 789.0000 1.0000
50.2000 827.0000 1.0000
50.2400 777.0000 1.0000
50.2800 753.0000 1.0000
50.3200 813.0000 1.0000
50.3600 799.0000 1.0000
50.4000 764.0000 1.0000
50.4400 740.0000 1.0000
50.4800 754.0000 1.0000
50.5200 803.0000 1.0000
50.5600 815.0000 1.0000
50.6000 755.0000 1.0000
50.6400 740.0000 1.0000
50.6800 763.0000 1.0000
50.7200 748.0000 1.0000
50.7600 766.0000 1.0000
50.8000 763.0000 1.0000
50.8400 790.0000 1.0000
50.8800 750.0000 1.0000
50.9200 782.0000 1.0000
50.9600 805.0000 1.0000
51.0000 766.0000 1.0000
51.0400 764.0000 1.0000
51.0800 783.0000 1.0000
51.1200 800.0000 1.0000
51.1600 805.0000 1.0000
51.2000 770.0000 1.0000
51.2400 786.0000 1.0000
51.2800 760.0000 1.0000
51.3200 755.0000 1.0000
51.3600 758.0000 1.0000
51.4000 770.0000 1.0000
51.4400 835.0000 1.0000
51.4800 811.0000 1.0000
51.5200 758.0000 1.0000
51.5600 802.0000 1.0000
51.6000 829.0000 1.0000
51.6400 815.0000 1.0000
51.6800 772.0000 1.0000
51.7200 814.0000 1.0000
51.7600 880.0000 1.0000
51.8000 870.0000 1.0000
51.8400 907.0000 1.0000
51.8800 943.0000 1.0000
51.9200 967.0000 1.0000
51.9600 1093.0000 1.0000
52.0000 1232.0000 1.0000
52.0400 1377.0000 1.0000
52.0800 1618.0000 1.0000
52.1200 2021.0000 1.0000
52.1600 2810.0000 1.0000
52.2000 3881.0000 1.0000
52.2400 4911.0000 1.0000
52.2800 5340.0000 1.0000
52.3200 4692.0000 1.0000
52.3600 4222.0000 1.0000
52.4000 3858.0000 1.0000
52.4400 3160.0000 1.0000
52.4800 2452.0000 1.0000
52.5200 1881.0000 1.0000
52.5600 1497.0000 1.0000
52.6000 1307.0000 1.0000
52.6400 1262.0000 1.0000
52.6800 1037.0000 1.0000
52.7200 1025.0000 1.0000
52.7600 949.0000 1.0000
52.8000 911.0000 1.0000
52.8400 874.0000 1.0000
52.8800 887.0000 1.0000
52.9200 830.0000 1.0000
52.9600 828.0000 1.0000
53.0000 798.0000 1.0000
53.0400 874.0000 1.0000
53.0800 756.0000 1.0000
53.1200 852.0000 1.0000
53.1600 817.0000 1.0000
53.2000 784.0000 1.0000
53.2400 805.0000 1.0000
53.2800 753.0000 1.0000
53.3200 801.0000 1.0000
53.3600 754.0000 1.0000
53.4000 778.0000 1.0000
53.4400 760.0000 1.0000
53.4800 823.0000 1.0000
53.5200 770.0000 1.0000
53.5600 773.0000 1.0000
53.6000 744.0000 1.0000
53.6400 748.0000 1.0000
53.6800 745.0000 1.0000
53.7200 742.0000 1.0000
53.7600 740.0000 1.0000
53.8000 769.0000 1.0000
53.8400 751.0000 1.0000
53.8800 759.0000 1.0000
53.9200 746.0000 1.0000
53.9600 759.0000 1.0000
54.0000 758.0000 1.0000
54.0400 717.0000 1.0000
54.0800 730.0000 1.0000
54.1200 754.0000 1.0000
54.1600 772.0000 1.0000
54.2000 730.0000 1.0000
54.2400 737.0000 1.0000
54.2800 728.0000 1.0000
54.3200 742.0000 1.0000
54.3600 781.0000 1.0000
54.4000 751.0000 1.0000
54.4400 794.0000 1.0000
54.4800 730.0000 1.0000
54.5200 739.0000 1.0000
54.5600 753.0000 1.0000
54.6000 747.0000 1.0000
54.6400 731.0000 1.0000
54.6800 745.0000 1.0000
54.7200 786.0000 1.0000
54.7600 795.0000 1.0000
54.8000 822.0000 1.0000
54.8400 804.0000 1.0000
54.8800 816.0000 1.0000
54.9200 805.0000 1.0000
54.9600 807.0000 1.0000
55.0000 837.0000 1.0000
55.0400 868.0000 1.0000
55.0800 861.0000 1.0000
55.1200 905.0000 1.0000
55.1600 923.0000 1.0000
55.2000 1048.0000 1.0000
55.2400 1091.0000 1.0000
55.2800 1141.0000 1.0000
55.3200 1115.0000 1.0000
55.3600 1065.0000 1.0000
55.4000 1073.0000 1.0000
55.4400 1043.0000 1.0000
55.4800 925.0000 1.0000
55.5200 909.0000 1.0000
55.5600 867.0000 1.0000
55.6000 878.0000 1.0000
55.6400 813.0000 1.0000
55.6800 772.0000 1.0000
55.7200 727.0000 1.0000
55.7600 751.0000 1.0000
55.8000 735.0000 1.0000
55.8400 699.0000 1.0000
55.8800 715.0000 1.0000
55.9200 778.0000 1.0000
55.9600 742.0000 1.0000
56.0000 743.0000 1.0000
56.0400 706.0000 1.0000
56.0800 745.0000 1.0000
56.1200 751.0000 1.0000
56.1600 729.0000 1.0000
56.2000 721.0000 1.0000
56.2400 750.0000 1.0000
56.2800 713.0000 1.0000
56.3200 706.0000 1.0000
56.3600 718.0000 1.0000
56.4000 700.0000 1.0000
56.4400 703.0000 1.0000
56.4800 741.0000 1.0000
56.5200 689.0000 1.0000
56.5600 686.0000 1.0000
56.6000 730.0000 1.0000
56.6400 725.0000 1.0000
56.6800 708.0000 1.0000
56.7200 745.0000 1.0000
56.7600 742.0000 1.0000
56.8000 721.0000 1.0000
56.8400 703.0000 1.0000
56.8800 700.0000 1.0000
56.9200 756.0000 1.0000
56.9600 729.0000 1.0000
57.0000 668.0000 1.0000
57.0400 725.0000 1.0000
57.0800 723.0000 1.0000
57.1200 699.0000 1.0000
57.1600 726.0000 1.0000
57.2000 703.0000 1.0000
57.2400 737.0000 1.0000
57.2800 738.0000 1.0000
57.3200 754.0000 1.0000
57.3600 734.0000 1.0000
57.4000 688.0000 1.0000
57.4400 688.0000 1.0000
57.4800 721.0000 1.0000
57.5200 714.0000 1.0000
57.5600 713.0000 1.0000
57.6000 674.0000 1.0000
57.6400 750.0000 1.0000
57.6800 740.0000 1.0000
57.7200 696.0000 1.0000
57.7600 686.0000 1.0000
57.8000 707.0000 1.0000
57.8400 702.0000 1.0000
57.8800 713.0000 1.0000
57.9200 720.0000 1.0000
57.9600 694.0000 1.0000
58.0000 744.0000 1.0000
58.0400 738.0000 1.0000
58.0800 702.0000 1.0000
58.1200 780.0000 1.0000
58.1600 719.0000 1.0000
58.2000 732.0000 1.0000
58.2400 759.0000 1.0000
58.2800 706.0000 1.0000
58.3200 696.0000 1.0000
58.3600 743.0000 1.0000
58.4000 707.0000 1.0000
58.4400 734.0000 1.0000
58.4800 735.0000 1.0000
58.5200 703.0000 1.0000
58.5600 676.0000 1.0000
58.6000 741.0000 1.0000
58.6400 710.0000 1.0000
58.6800 677.0000 1.0000
58.7200 739.0000 1.0000
58.7600 705.0000 1.0000
58.8000 712.0000 1.0000
58.8400 675.0000 1.0000
58.8800 699.0000 1.0000
58.9200 696.0000 1.0000
58.9600 681.0000 1.0000
59.0000 739.0000 1.0000
59.0400 713.0000 1.0000
59.0800 731.0000 1.0000
59.1200 699.0000 1.0000
59.1600 713.0000 1.0000
59.2000 724.0000 1.0000
59.2400 743.0000 1.0000
59.2800 674.0000 1.0000
59.3200 709.0000 1.0000
59.3600 745.0000 1.0000
59.4000 727.0000 1.0000
59.4400 665.0000 1.0000
59.4800 758.0000 1.0000
59.5200 689.0000 1.0000
59.5600 743.0000 1.0000
59.6000 727.0000 1.0000
59.6400 718.0000 1.0000
59.6800 734.0000 1.0000
59.7200 699.0000 1.0000
59.7600 729.0000 1.0000
59.8000 740.0000 1.0000
59.8400 712.0000 1.0000
59.8800 730.0000 1.0000
59.9200 708.0000 1.0000
59.9600 686.0000 1.0000
60.0000 683.0000 1.0000
60.0400 719.0000 1.0000
60.0800 702.0000 1.0000
60.1200 708.0000 1.0000
60.1600 718.0000 1.0000
60.2000 708.0000 1.0000
60.2400 747.0000 1.0000
60.2800 710.0000 1.0000
60.3200 699.0000 1.0000
60.3600 705.0000 1.0000
60.4000 675.0000 1.0000
60.4400 681.0000 1.0000
60.4800 714.0000 1.0000
60.5200 705.0000 1.0000
60.5600 720.0000 1.0000
60.6000 691.0000 1.0000
60.6400 690.0000 1.0000
60.6800 693.0000 1.0000
60.7200 696.0000 1.0000
60.7600 715.0000 1.0000
60.8000 702.0000 1.0000
60.8400 730.0000 1.0000
60.8800 717.0000 1.0000
60.9200 700.0000 1.0000
60.9600 719.0000 1.0000
61.0000 726.0000 1.0000
61.0400 767.0000 1.0000
61.0800 715.0000 1.0000
61.1200 687.0000 1.0000
61.1600 726.0000 1.0000
61.2000 713.0000 1.0000
61.2400 729.0000 1.0000
61.2800 706.0000 1.0000
61.3200 689.0000 1.0000
61.3600 704.0000 1.0000
61.4000 673.0000 1.0000
61.4400 723.0000 1.0000
61.4800 749.0000 1.0000
61.5200 756.0000 1.0000
61.5600 754.0000 1.0000
61.6000 778.0000 1.0000
61.6400 746.0000 1.0000
61.6800 734.0000 1.0000
61.7200 816.0000 1.0000
61.7600 770.0000 1.0000
61.8000 779.0000 1.0000
61.8400 780.0000 1.0000
61.8800 808.0000 1.0000
61.9200 823.0000 1.0000
61.9600 849.0000 1.0000
62.0000 945.0000 1.0000
62.0400 971.0000 1.0000
62.0800 1112.0000 1.0000
62.1200 1229.0000 1.0000
62.1600 1256.0000 1.0000
62.2000 1463.0000 1.0000
62.2400 1640.0000 1.0000
62.2800 1731.0000 1.0000
62.3200 1771.0000 1.0000
62.3600 1747.0000 1.0000
62.4000 1656.0000 1.0000
62.4400 1569.0000 1.0000
62.4800 1477.0000 1.0000
62.5200 1368.0000 1.0000
62.5600 1298.0000 1.0000
62.6000 1117.0000 1.0000
62.6400 1056.0000 1.0000
62.6800 961.0000 1.0000
62.7200 952.0000 1.0000
62.7600 831.0000 1.0000
62.8000 888.0000 1.0000
62.8400 841.0000 1.0000
62.8800 781.0000 1.0000
62.9200 816.0000 1.0000
62.9600 810.0000 1.0000
63.0000 769.0000 1.0000
63.0400 784.0000 1.0000
63.0800 810.0000 1.0000
63.1200 775.0000 1.0000
63.1600 800.0000 1.0000
63.2000 764.0000 1.0000
63.2400 746.0000 1.0000
63.2800 779.0000 1.0000
63.3200 789.0000 1.0000
63.3600 748.0000 1.0000
63.4000 751.0000 1.0000
63.4400 773.0000 1.0000
63.4800 738.0000 1.0000
63.5200 726.0000 1.0000
63.5600 744.0000 1.0000
63.6000 771.0000 1.0000
63.6400 734.0000 1.0000
63.6800 733.0000 1.0000
63.7200 757.0000 1.0000
63.7600 703.0000 1.0000
63.8000 710.0000 1.0000
63.8400 717.0000 1.0000
63.8800 764.0000 1.0000
63.9200 693.0000 1.0000
63.9600 683.0000 1.0000
64.0000 730.0000 1.0000
64.0400 731.0000 1.0000
64.0800 709.0000 1.0000
64.1200 730.0000 1.0000
64.1600 725.0000 1.0000
64.2000 744.0000 1.0000
64.2400 739.0000 1.0000
64.2800 775.0000 1.0000
64.3200 733.0000 1.0000
64.3600 786.0000 1.0000
64.4000 715.0000 1.0000
64.4400 718.0000 1.0000
64.4800 728.0000 1.0000
64.5200 743.0000 1.0000
64.5600 822.0000 1.0000
64.6000 810.0000 1.0000
64.6400 911.0000 1.0000
64.6800 955.0000 1.0000
64.7200 946.0000 1.0000
64.7600 859.0000 1.0000
64.8000 909.0000 1.0000
64.8400 876.0000 1.0000
64.8800 799.0000 1.0000
64.9200 819.0000 1.0000
64.9600 794.0000 1.0000
65.0000 756.0000 1.0000
65.0400 773.0000 1.0000
65.0800 759.0000 1.0000
65.1200 721.0000 1.0000
65.1600 709.0000 1.0000
65.2000 753.0000 1.0000
65.2400 730.0000 1.0000
65.2800 788.0000 1.0000
65.3200 728.0000 1.0000
65.3600 772.0000 1.0000
65.4000 718.0000 1.0000
65.4400 789.0000 1.0000
65.4800 719.0000 1.0000
65.5200 701.0000 1.0000
65.5600 788.0000 1.0000
65.6000 772.0000 1.0000
65.6400 806.0000 1.0000
65.6800 730.0000 1.0000
65.7200 758.0000 1.0000
65.7600 788.0000 1.0000
65.8000 814.0000 1.0000
65.8400 872.0000 1.0000
65.8800 905.0000 1.0000
65.9200 939.0000 1.0000
65.9600 967.0000 1.0000
66.0000 1027.0000 1.0000
66.0400 1213.0000 1.0000
66.0800 1500.0000 1.0000
66.1200 1670.0000 1.0000
66.1600 2053.0000 1.0000
66.2000 2519.0000 1.0000
66.2400 2930.0000 1.0000
66.2800 2891.0000 1.0000
66.3200 2773.0000 1.0000
66.3600 2589.0000 1.0000
66.4000 2383.0000 1.0000
66.4400 2234.0000 1.0000
66.4800 2048.0000 1.0000
66.5200 1717.0000 1.0000
66.5600 1504.0000 1.0000
66.6000 1279.0000 1.0000
66.6400 1136.0000 1.0000
66.6800 1038.0000 1.0000
66.7200 952.0000 1.0000
66.7600 954.0000 1.0000
66.8000 853.0000 1.0000
66.8400 797.0000 1.0000
66.8800 721.0000 1.0000
66.9200 780.0000 1.0000
66.9600 756.0000 1.0000
67.0000 776.0000 1.0000
67.0400 709.0000 1.0000
67.0800 698.0000 1.0000
67.1200 713.0000 1.0000
67.1600 700.0000 1.0000
67.2000 676.0000 1.0000
67.2400 691.0000 1.0000
67.2800 728.0000 1.0000
67.3200 672.0000 1.0000
67.3600 650.0000 1.0000
67.4000 684.0000 1.0000
67.4400 628.0000 1.0000
67.4800 722.0000 1.0000
67.5200 664.0000 1.0000
67.5600 632.0000 1.0000
67.6000 678.0000 1.0000
67.6400 655.0000 1.0000
67.6800 732.0000 1.0000
67.7200 646.0000 1.0000
67.7600 680.0000 1.0000
67.8000 625.0000 1.0000
67.8400 613.0000 1.0000
67.8800 638.0000 1.0000
67.9200 636.0000 1.0000
67.9600 648.0000 1.0000
68.0000 623.0000 1.0000
68.0400 633.0000 1.0000
68.0800 653.0000 1.0000
68.1200 645.0000 1.0000
68.1600 714.0000 1.0000
68.2000 658.0000 1.0000
68.2400 627.0000 1.0000
68.2800 650.0000 1.0000
68.3200 619.0000 1.0000
68.3600 641.0000 1.0000
68.4000 658.0000 1.0000
68.4400 649.0000 1.0000
68.4800 648.0000 1.0000
68.5200 639.0000 1.0000
68.5600 666.0000 1.0000
68.6000 670.0000 1.0000
68.6400 633.0000 1.0000
68.6800 678.0000 1.0000
68.7200 643.0000 1.0000
68.7600 655.0000 1.0000
68.8000 671.0000 1.0000
68.8400 639.0000 1.0000
68.8800 660.0000 1.0000
68.9200 635.0000 1.0000
68.9600 625.0000 1.0000
69.0000 642.0000 1.0000
69.0400 660.0000 1.0000
69.0800 634.0000 1.0000
69.1200 626.0000 1.0000
69.1600 613.0000 1.0000
69.2000 617.0000 1.0000
69.2400 611.0000 1.0000
69.2800 638.0000 1.0000
69.3200 633.0000 1.0000
69.3600 583.0000 1.0000
69.4000 648.0000 1.0000
69.4400 634.0000 1.0000
69.4800 617.0000 1.0000
69.5200 624.0000 1.0000
69.5600 603.0000 1.0000
69.6000 643.0000 1.0000
69.6400 632.0000 1.0000
69.6800 668.0000 1.0000
69.7200 639.0000 1.0000
69.7600 639.0000 1.0000
69.8000 619.0000 1.0000
69.8400 613.0000 1.0000
69.8800 637.0000 1.0000
69.9200 616.0000 1.0000
69.9600 631.0000 1.0000
70.0000 637.0000 1.0000
*RAS_INT_END
*RAS_TEMPERATURE_START
*RAS_TEMPERATURE_END
*RAS_DATA_END