File: Data/Dataset1_Only_water/5_XRD/No_060_deposition_3h_TiO2_Air_7.ras
*RAS_DATA_START
*RAS_HEADER_START
*DISP_FMT_X "%.2f"
*DISP_FMT_Y "%.0f"
*DISP_FULLSCALE "20175.0000000000"
*DISP_LINE_COLOR "255.0000000000"
*DISP_LINE_STYLE "0.0000000000"
*DISP_LINE_WIDTH "0.2500000000"
*DISP_NOTE "測定データ-1"
*DISP_OFFSET_Y "0.0000000000"
*DISP_PEAKSEARCH_UNIT_Y "cps"
*DISP_RANGE_BOTTOM "0.0000000000"
*DISP_RANGE_LEFT "20.0000000000"
*DISP_RANGE_LOGCUTOFF "0.0100000000"
*DISP_RANGE_RIGHT "70.0000000000"
*DISP_RANGE_TOP "20175.0000000000"
*DISP_SCALE_MODE_Y "0.0000000000"
*DISP_TAB_NAME "2θ/θ"
*DISP_TITLE_Y "強度"
*DISP_UNIT_Y "cps"
*DISP_WINDOW_NAME "MSG_MACROENGINE"
*FILE_COMMENT " "
*FILE_MD5 ""
*FILE_MEMO " "
*FILE_OPERATOR "Administrator"
*FILE_SAMPLE " "
*FILE_TYPE "RAS_RAW"
*FILE_USERGROUP "システムマネージャ"
*FILE_VERSION "1.0000000000"
*HW_ATTACHMENT_ID "ATT0025"
*HW_ATTACHMENT_NAME "標準|Standard"
*HW_COUNTER_ID-0 "CUT0025"
*HW_COUNTER_ID-1 "CUT0020"
*HW_COUNTER_ID-2 "CUT0020"
*HW_COUNTER_ID-3 "CSL0021"
*HW_COUNTER_ID-4 "CMC0021"
*HW_COUNTER_NAME-0 "D/teX Ultra|D/teX Ultra"
*HW_COUNTER_NAME-1 "None|None"
*HW_COUNTER_NAME-2 "None|None"
*HW_COUNTER_NAME-3 "BBM|BBM"
*HW_COUNTER_NAME-4 "検出器モノクロメータ|Detector monochromator"
*HW_COUNTER_SELECT_NAME "D/teX Ultra|D/teX Ultra"
*HW_GONIOMETER_ID "GON0023"
*HW_GONIOMETER_NAME "SmartLab|SmartLab"
*HW_GONIOMETER_RADIUS-0 "90.0"
*HW_GONIOMETER_RADIUS-1 "114.0"
*HW_GONIOMETER_RADIUS-2 "190.0"
*HW_GONIOMETER_RADIUS-3 "300.0"
*HW_GONIOMETER_RADIUS-4 "187.0"
*HW_GONIOMETER_RADIUS-5 "300.0"
*HW_GONIOMETER_RADIUS-6 "113.0"
*HW_GONIOMETER_RADIUS-7 "331.0"
*HW_I_OPT_ID-0 "CBO0021"
*HW_I_OPT_ID-1 "ICR0023"
*HW_I_OPT_ID-2 "ISL0021"
*HW_I_OPT_ID-3 "ISO0021"
*HW_I_OPT_ID-4 "IAD0021"
*HW_I_OPT_ID-5 "IPR0001"
*HW_I_OPT_NAME-0 "CBOユニット|CBO unit"
*HW_I_OPT_NAME-1 "標準入射光学ユニット|Standard incident optical unit"
*HW_I_OPT_NAME-2 "標準入射スリットボックス|Standard incident slit box"
*HW_I_OPT_NAME-3 "入射平行スリット|Incident parallel slit"
*HW_I_OPT_NAME-4 "長手制限スリット|Length limiting slit"
*HW_I_OPT_NAME-5 "None|None"
*HW_R_ATTENUATER_AUTOMODE "0"
*HW_R_OPT_ID-0 "RSS0021"
*HW_R_OPT_ID-1 "RCR0023"
*HW_R_OPT_ID-2 "RSO0021"
*HW_R_OPT_ID-3 "RRS0021"
*HW_R_OPT_ID-4 "ATN0021"
*HW_R_OPT_ID-5 "RFL0021"
*HW_R_OPT_ID-6 "RAD0021"
*HW_R_OPT_NAME-0 "標準受光スリットボックス1|Standard receiving slit box # 1"
*HW_R_OPT_NAME-1 "標準受光光学ユニット1|Standard receiving unit # 1"
*HW_R_OPT_NAME-2 "標準受光光学ユニット2|Standard receiving optical unit # 2"
*HW_R_OPT_NAME-3 "標準受光スリットボックス2|Standard receiving slit box # 2"
*HW_R_OPT_NAME-4 "標準アッテネータ|Standard Attenuator"
*HW_R_OPT_NAME-5 "Cu Kβ|Cu K-beta"
*HW_R_OPT_NAME-6 "調整用受光スリット|Alignment receiving slit"
*HW_SAMPLE_HOLDER_ID "SMP0023"
*HW_SAMPLE_HOLDER_NAME "標準Zステージ|Standard Z stage"
*HW_XG_CURRENT_MAX "50"
*HW_XG_CURRENT_MIN "2"
*HW_XG_CURRENT_RESOLUTION "1"
*HW_XG_CURRENT_UNIT "mA"
*HW_XG_FOCUS "1mm x 10mm"
*HW_XG_FOCUS_TYPE "Normal"
*HW_XG_ID ""
*HW_XG_NAME "3kW 封入管(ID:1200)|3kW Sealed tube(ID:1200)"
*HW_XG_TARGET_ATOMIC_NUMBER "29.0000000000"
*HW_XG_TARGET_NAME "Cu"
*HW_XG_TYPE "Hermetic"
*HW_XG_VOLTAGE_MAX "60"
*HW_XG_VOLTAGE_MIN "20"
*HW_XG_VOLTAGE_RESOLUTION "1"
*HW_XG_VOLTAGE_UNIT "kV"
*HW_XG_WATT_MAX "1.500"
*HW_XG_WATT_UNIT "kW"
*HW_XG_WAVE_LENGTH_ALPHA1 "1.540593"
*HW_XG_WAVE_LENGTH_ALPHA2 "1.544414"
*HW_XG_WAVE_LENGTH_BETA "1.392250"
*MEAS_COND_AXIS_NAME-0 "2θ/θ"
*MEAS_COND_AXIS_NAME-1 "2θ"
*MEAS_COND_AXIS_NAME-2 "ω"
*MEAS_COND_AXIS_NAME-3 "Z"
*MEAS_COND_AXIS_NAME-4 "2θ/ω"
*MEAS_COND_AXIS_NAME-5 "θs"
*MEAS_COND_AXIS_NAME-6 "θd"
*MEAS_COND_AXIS_NAME-7 "Ts"
*MEAS_COND_AXIS_NAME-8 "CBO選択スリット"
*MEAS_COND_AXIS_NAME-9 "M"
*MEAS_COND_AXIS_NAME-10 "入射平行スリット"
*MEAS_COND_AXIS_NAME-11 "入射スリット"
*MEAS_COND_AXIS_NAME-12 ""
*MEAS_COND_AXIS_NAME-13 "Zs"
*MEAS_COND_AXIS_NAME-14 "入射光学素子"
*MEAS_COND_AXIS_NAME-15 "長手制限スリット"
*MEAS_COND_AXIS_NAME-16 "センタースリット"
*MEAS_COND_AXIS_NAME-17 "フィルター"
*MEAS_COND_AXIS_NAME-18 "受光スリット1"
*MEAS_COND_AXIS_NAME-19 "受光スリット2"
*MEAS_COND_AXIS_NAME-20 "受光光学素子"
*MEAS_COND_AXIS_NAME-21 "受光平行スリット"
*MEAS_COND_AXIS_NAME-22 "調整用受光スリット"
*MEAS_COND_AXIS_NAME-23 ""
*MEAS_COND_AXIS_NAME-24 ""
*MEAS_COND_AXIS_NAME-25 "Zd"
*MEAS_COND_AXIS_NAME-26 "アッテネータ"
*MEAS_COND_AXIS_NAME-27 "検出器モノクロメータ"
*MEAS_COND_AXIS_NAME-28 "モノクロメータスリット"
*MEAS_COND_AXIS_NAME-29 "プライマリビーム"
*MEAS_COND_AXIS_NAME-30 "PHA"
*MEAS_COND_AXIS_NAME_INTERNAL-0 "TwoThetaTheta"
*MEAS_COND_AXIS_NAME_INTERNAL-1 "TwoTheta"
*MEAS_COND_AXIS_NAME_INTERNAL-2 "Omega"
*MEAS_COND_AXIS_NAME_INTERNAL-3 "Z"
*MEAS_COND_AXIS_NAME_INTERNAL-4 "TwoThetaOmega"
*MEAS_COND_AXIS_NAME_INTERNAL-5 "ThetaS"
*MEAS_COND_AXIS_NAME_INTERNAL-6 "ThetaD"
*MEAS_COND_AXIS_NAME_INTERNAL-7 "Ts"
*MEAS_COND_AXIS_NAME_INTERNAL-8 "CBO"
*MEAS_COND_AXIS_NAME_INTERNAL-9 "CBO-M"
*MEAS_COND_AXIS_NAME_INTERNAL-10 "IncidentSollerSlit"
*MEAS_COND_AXIS_NAME_INTERNAL-11 "IncidentSlitBox"
*MEAS_COND_AXIS_NAME_INTERNAL-12 "IncidentSlitBox-_Axis"
*MEAS_COND_AXIS_NAME_INTERNAL-13 "Zs"
*MEAS_COND_AXIS_NAME_INTERNAL-14 "IncidentMonochromator"
*MEAS_COND_AXIS_NAME_INTERNAL-15 "IncidentAxdSlit"
*MEAS_COND_AXIS_NAME_INTERNAL-16 "CenterSlit"
*MEAS_COND_AXIS_NAME_INTERNAL-17 "Filter"
*MEAS_COND_AXIS_NAME_INTERNAL-18 "ReceivingSlitBox1"
*MEAS_COND_AXIS_NAME_INTERNAL-19 "ReceivingSlitBox2"
*MEAS_COND_AXIS_NAME_INTERNAL-20 "ReceivingOptics"
*MEAS_COND_AXIS_NAME_INTERNAL-21 "ReceivingSollerSlit"
*MEAS_COND_AXIS_NAME_INTERNAL-22 "ReceivingAxdSlit"
*MEAS_COND_AXIS_NAME_INTERNAL-23 "ReceivingSlitBox1-_Axis"
*MEAS_COND_AXIS_NAME_INTERNAL-24 "ReceivingSlitBox2-_Axis"
*MEAS_COND_AXIS_NAME_INTERNAL-25 "ReceivingSlitBox2-Zd"
*MEAS_COND_AXIS_NAME_INTERNAL-26 "Attenuator"
*MEAS_COND_AXIS_NAME_INTERNAL-27 "CounterMonochromator"
*MEAS_COND_AXIS_NAME_INTERNAL-28 "CounterSlit"
*MEAS_COND_AXIS_NAME_INTERNAL-29 "IncidentPrimary"
*MEAS_COND_AXIS_NAME_INTERNAL-30 "PHA"
*MEAS_COND_AXIS_NAME_MAGICNO-0 "83951616.0000000000"
*MEAS_COND_AXIS_NAME_MAGICNO-1 "268632064.0000000000"
*MEAS_COND_AXIS_NAME_MAGICNO-2 "268500992.0000000000"
*MEAS_COND_AXIS_NAME_MAGICNO-3 "285278208.0000000000"
*MEAS_COND_AXIS_NAME_MAGICNO-4 "83951616.0000000000"
*MEAS_COND_AXIS_NAME_MAGICNO-5 "131072.0000000000"
*MEAS_COND_AXIS_NAME_MAGICNO-6 "131072.0000000000"
*MEAS_COND_AXIS_NAME_MAGICNO-7 "318898176.0000000000"
*MEAS_COND_AXIS_NAME_MAGICNO-8 "20971521.0000000000"
*MEAS_COND_AXIS_NAME_MAGICNO-9 "285343744.0000000000"
*MEAS_COND_AXIS_NAME_MAGICNO-10 "20971521.0000000000"
*MEAS_COND_AXIS_NAME_MAGICNO-11 "22020097.0000000000"
*MEAS_COND_AXIS_NAME_MAGICNO-12 "25165824.0000000000"
*MEAS_COND_AXIS_NAME_MAGICNO-13 "318898176.0000000000"
*MEAS_COND_AXIS_NAME_MAGICNO-14 "1.0000000000"
*MEAS_COND_AXIS_NAME_MAGICNO-15 "20971521.0000000000"
*MEAS_COND_AXIS_NAME_MAGICNO-16 "20971521.0000000000"
*MEAS_COND_AXIS_NAME_MAGICNO-17 "20971521.0000000000"
*MEAS_COND_AXIS_NAME_MAGICNO-18 "23068673.0000000000"
*MEAS_COND_AXIS_NAME_MAGICNO-19 "23068673.0000000000"
*MEAS_COND_AXIS_NAME_MAGICNO-20 "20971521.0000000000"
*MEAS_COND_AXIS_NAME_MAGICNO-21 "20971521.0000000000"
*MEAS_COND_AXIS_NAME_MAGICNO-22 "20971521.0000000000"
*MEAS_COND_AXIS_NAME_MAGICNO-23 "25165824.0000000000"
*MEAS_COND_AXIS_NAME_MAGICNO-24 "25165824.0000000000"
*MEAS_COND_AXIS_NAME_MAGICNO-25 "285343744.0000000000"
*MEAS_COND_AXIS_NAME_MAGICNO-26 "17301505.0000000000"
*MEAS_COND_AXIS_NAME_MAGICNO-27 "20971521.0000000000"
*MEAS_COND_AXIS_NAME_MAGICNO-28 "20971521.0000000000"
*MEAS_COND_AXIS_NAME_MAGICNO-29 "20971521.0000000000"
*MEAS_COND_AXIS_NAME_MAGICNO-30 "0.0000000000"
*MEAS_COND_AXIS_OFFSET-0 "-"
*MEAS_COND_AXIS_OFFSET-1 "-0.0801000000"
*MEAS_COND_AXIS_OFFSET-2 "0.1283000000"
*MEAS_COND_AXIS_OFFSET-3 "-"
*MEAS_COND_AXIS_OFFSET-4 "-"
*MEAS_COND_AXIS_OFFSET-5 "0.1283000000"
*MEAS_COND_AXIS_OFFSET-6 "-0.2084000000"
*MEAS_COND_AXIS_OFFSET-7 "-"
*MEAS_COND_AXIS_OFFSET-8 "-"
*MEAS_COND_AXIS_OFFSET-9 "-"
*MEAS_COND_AXIS_OFFSET-10 "-"
*MEAS_COND_AXIS_OFFSET-11 "-"
*MEAS_COND_AXIS_OFFSET-12 "-"
*MEAS_COND_AXIS_OFFSET-13 "-"
*MEAS_COND_AXIS_OFFSET-14 "-"
*MEAS_COND_AXIS_OFFSET-15 "-"
*MEAS_COND_AXIS_OFFSET-16 "-"
*MEAS_COND_AXIS_OFFSET-17 "-"
*MEAS_COND_AXIS_OFFSET-18 "-"
*MEAS_COND_AXIS_OFFSET-19 "-"
*MEAS_COND_AXIS_OFFSET-20 "-"
*MEAS_COND_AXIS_OFFSET-21 "-"
*MEAS_COND_AXIS_OFFSET-22 "-"
*MEAS_COND_AXIS_OFFSET-23 "-"
*MEAS_COND_AXIS_OFFSET-24 "-"
*MEAS_COND_AXIS_OFFSET-25 "-"
*MEAS_COND_AXIS_OFFSET-26 "-"
*MEAS_COND_AXIS_OFFSET-27 "-"
*MEAS_COND_AXIS_OFFSET-28 "-"
*MEAS_COND_AXIS_OFFSET-29 "-"
*MEAS_COND_AXIS_OFFSET-30 "-"
*MEAS_COND_AXIS_POSITION-0 "0.0000000000"
*MEAS_COND_AXIS_POSITION-1 "0.0000000000"
*MEAS_COND_AXIS_POSITION-2 "0.0000000000"
*MEAS_COND_AXIS_POSITION-3 "-2.9935200000"
*MEAS_COND_AXIS_POSITION-4 "0.0000000000"
*MEAS_COND_AXIS_POSITION-5 "0.0000000000"
*MEAS_COND_AXIS_POSITION-6 "0.0000000000"
*MEAS_COND_AXIS_POSITION-7 "-0.4278800000"
*MEAS_COND_AXIS_POSITION-8 "BB"
*MEAS_COND_AXIS_POSITION-9 "0.0000000000"
*MEAS_COND_AXIS_POSITION-10 "Soller_slit_5.0deg"
*MEAS_COND_AXIS_POSITION-11 "2/3deg"
*MEAS_COND_AXIS_POSITION-12 "2.2088000000"
*MEAS_COND_AXIS_POSITION-13 "-1.0609400000"
*MEAS_COND_AXIS_POSITION-14 "0.0000000000"
*MEAS_COND_AXIS_POSITION-15 "10.0mm"
*MEAS_COND_AXIS_POSITION-16 "None"
*MEAS_COND_AXIS_POSITION-17 "Cu_K-beta"
*MEAS_COND_AXIS_POSITION-18 "13.000mm"
*MEAS_COND_AXIS_POSITION-19 "13.000mm"
*MEAS_COND_AXIS_POSITION-20 "No_unit"
*MEAS_COND_AXIS_POSITION-21 "Soller_slit_5.0deg"
*MEAS_COND_AXIS_POSITION-22 "None"
*MEAS_COND_AXIS_POSITION-23 "13.0000000000"
*MEAS_COND_AXIS_POSITION-24 "13.0000000000"
*MEAS_COND_AXIS_POSITION-25 "0.0081300000"
*MEAS_COND_AXIS_POSITION-26 "Open"
*MEAS_COND_AXIS_POSITION-27 "None"
*MEAS_COND_AXIS_POSITION-28 "None"
*MEAS_COND_AXIS_POSITION-29 "None"
*MEAS_COND_AXIS_POSITION-30 "38.0000000000"
*MEAS_COND_AXIS_UNIT-0 "deg"
*MEAS_COND_AXIS_UNIT-1 "deg"
*MEAS_COND_AXIS_UNIT-2 "deg"
*MEAS_COND_AXIS_UNIT-3 "mm"
*MEAS_COND_AXIS_UNIT-4 "deg"
*MEAS_COND_AXIS_UNIT-5 "deg"
*MEAS_COND_AXIS_UNIT-6 "deg"
*MEAS_COND_AXIS_UNIT-7 "mm"
*MEAS_COND_AXIS_UNIT-8 ""
*MEAS_COND_AXIS_UNIT-9 "pulse"
*MEAS_COND_AXIS_UNIT-10 ""
*MEAS_COND_AXIS_UNIT-11 ""
*MEAS_COND_AXIS_UNIT-12 "mm"
*MEAS_COND_AXIS_UNIT-13 "mm"
*MEAS_COND_AXIS_UNIT-14 ""
*MEAS_COND_AXIS_UNIT-15 ""
*MEAS_COND_AXIS_UNIT-16 ""
*MEAS_COND_AXIS_UNIT-17 ""
*MEAS_COND_AXIS_UNIT-18 ""
*MEAS_COND_AXIS_UNIT-19 ""
*MEAS_COND_AXIS_UNIT-20 ""
*MEAS_COND_AXIS_UNIT-21 ""
*MEAS_COND_AXIS_UNIT-22 ""
*MEAS_COND_AXIS_UNIT-23 "mm"
*MEAS_COND_AXIS_UNIT-24 "mm"
*MEAS_COND_AXIS_UNIT-25 "mm"
*MEAS_COND_AXIS_UNIT-26 ""
*MEAS_COND_AXIS_UNIT-27 ""
*MEAS_COND_AXIS_UNIT-28 ""
*MEAS_COND_AXIS_UNIT-29 ""
*MEAS_COND_AXIS_UNIT-30 "div"
*MEAS_COND_COUNTER_CNTLOSS_CORR "0.0000000000"
*MEAS_COND_COUNTER_PHABASE "38.0000000000"
*MEAS_COND_COUNTER_PHAWINDOW "16.0000000000"
*MEAS_COND_COUNTER_PHA_UNIT "div"
*MEAS_COND_COUNTER_TAUDIFF "30.0000000000"
*MEAS_COND_COUNTER_TAUINT "0.0000000000"
*MEAS_COND_IRRADIATION_MODE "OFF"
*MEAS_COND_IRRADIATION_WIDTH ""
*MEAS_COND_OPT_ATTR "集中法"
*MEAS_COND_OPT_NAME "@集中法"
*MEAS_COND_UNSYMMETRIC_MODE "OFF"
*MEAS_COND_XG_CURRENT "30.0000000000"
*MEAS_COND_XG_VOLTAGE "40.0000000000"
*MEAS_COND_XG_WAVE_TYPE "Ka"
*MEAS_DATA_COUNT "5001.0000000000"
*MEAS_SCAN_AXIS_X "2θ/θ"
*MEAS_SCAN_AXIS_X_INTERNAL "TwoThetaTheta"
*MEAS_SCAN_END_TIME "07/20/22 15:24:59"
*MEAS_SCAN_MODE "CONTINUOUS"
*MEAS_SCAN_MONITOR "0"
*MEAS_SCAN_RESOLUTION_X "0.0002"
*MEAS_SCAN_SPEED "2.5"
*MEAS_SCAN_SPEED_UNIT "deg/min"
*MEAS_SCAN_START "20.0000000000"
*MEAS_SCAN_START_TIME "07/20/22 15:03:36"
*MEAS_SCAN_STEP "0.0100000000"
*MEAS_SCAN_STOP "70.0000000000"
*MEAS_SCAN_UNIT_X "deg"
*MEAS_SCAN_UNIT_Y "counts"
*RAS_HEADER_END
*RAS_INT_START
20.0000 1013.0000 1.0000
20.0400 1019.0000 1.0000
20.0800 1007.0000 1.0000
20.1200 1066.0000 1.0000
20.1600 1070.0000 1.0000
20.2000 1091.0000 1.0000
20.2400 1111.0000 1.0000
20.2800 1061.0000 1.0000
20.3200 1077.0000 1.0000
20.3600 1113.0000 1.0000
20.4000 1056.0000 1.0000
20.4400 1042.0000 1.0000
20.4800 988.0000 1.0000
20.5200 1055.0000 1.0000
20.5600 1064.0000 1.0000
20.6000 1047.0000 1.0000
20.6400 1069.0000 1.0000
20.6800 1076.0000 1.0000
20.7200 1076.0000 1.0000
20.7600 1032.0000 1.0000
20.8000 1030.0000 1.0000
20.8400 1038.0000 1.0000
20.8800 1116.0000 1.0000
20.9200 1068.0000 1.0000
20.9600 1063.0000 1.0000
21.0000 1087.0000 1.0000
21.0400 1042.0000 1.0000
21.0800 1062.0000 1.0000
21.1200 1024.0000 1.0000
21.1600 1058.0000 1.0000
21.2000 1055.0000 1.0000
21.2400 1090.0000 1.0000
21.2800 1032.0000 1.0000
21.3200 1084.0000 1.0000
21.3600 1045.0000 1.0000
21.4000 1056.0000 1.0000
21.4400 1046.0000 1.0000
21.4800 1015.0000 1.0000
21.5200 1025.0000 1.0000
21.5600 1045.0000 1.0000
21.6000 1045.0000 1.0000
21.6400 1052.0000 1.0000
21.6800 1045.0000 1.0000
21.7200 1003.0000 1.0000
21.7600 1103.0000 1.0000
21.8000 986.0000 1.0000
21.8400 1028.0000 1.0000
21.8800 1094.0000 1.0000
21.9200 1056.0000 1.0000
21.9600 1026.0000 1.0000
22.0000 1046.0000 1.0000
22.0400 1059.0000 1.0000
22.0800 1031.0000 1.0000
22.1200 1010.0000 1.0000
22.1600 1017.0000 1.0000
22.2000 1052.0000 1.0000
22.2400 1083.0000 1.0000
22.2800 1050.0000 1.0000
22.3200 994.0000 1.0000
22.3600 989.0000 1.0000
22.4000 1061.0000 1.0000
22.4400 1042.0000 1.0000
22.4800 1033.0000 1.0000
22.5200 1023.0000 1.0000
22.5600 1087.0000 1.0000
22.6000 1028.0000 1.0000
22.6400 1057.0000 1.0000
22.6800 1039.0000 1.0000
22.7200 1047.0000 1.0000
22.7600 1029.0000 1.0000
22.8000 1028.0000 1.0000
22.8400 980.0000 1.0000
22.8800 1019.0000 1.0000
22.9200 1033.0000 1.0000
22.9600 1034.0000 1.0000
23.0000 1046.0000 1.0000
23.0400 975.0000 1.0000
23.0800 990.0000 1.0000
23.1200 1038.0000 1.0000
23.1600 969.0000 1.0000
23.2000 1041.0000 1.0000
23.2400 1008.0000 1.0000
23.2800 1013.0000 1.0000
23.3200 1020.0000 1.0000
23.3600 1007.0000 1.0000
23.4000 1042.0000 1.0000
23.4400 1028.0000 1.0000
23.4800 1005.0000 1.0000
23.5200 1011.0000 1.0000
23.5600 1035.0000 1.0000
23.6000 998.0000 1.0000
23.6400 1039.0000 1.0000
23.6800 1012.0000 1.0000
23.7200 1052.0000 1.0000
23.7600 1019.0000 1.0000
23.8000 1009.0000 1.0000
23.8400 1043.0000 1.0000
23.8800 1074.0000 1.0000
23.9200 1057.0000 1.0000
23.9600 1080.0000 1.0000
24.0000 1115.0000 1.0000
24.0400 1108.0000 1.0000
24.0800 1134.0000 1.0000
24.1200 1192.0000 1.0000
24.1600 1093.0000 1.0000
24.2000 1047.0000 1.0000
24.2400 1022.0000 1.0000
24.2800 1054.0000 1.0000
24.3200 998.0000 1.0000
24.3600 1026.0000 1.0000
24.4000 1073.0000 1.0000
24.4400 986.0000 1.0000
24.4800 1030.0000 1.0000
24.5200 1021.0000 1.0000
24.5600 941.0000 1.0000
24.6000 1001.0000 1.0000
24.6400 1051.0000 1.0000
24.6800 998.0000 1.0000
24.7200 994.0000 1.0000
24.7600 1004.0000 1.0000
24.8000 1002.0000 1.0000
24.8400 990.0000 1.0000
24.8800 1010.0000 1.0000
24.9200 1036.0000 1.0000
24.9600 967.0000 1.0000
25.0000 1007.0000 1.0000
25.0400 1009.0000 1.0000
25.0800 1006.0000 1.0000
25.1200 1016.0000 1.0000
25.1600 1012.0000 1.0000
25.2000 991.0000 1.0000
25.2400 1010.0000 1.0000
25.2800 1003.0000 1.0000
25.3200 964.0000 1.0000
25.3600 995.0000 1.0000
25.4000 1002.0000 1.0000
25.4400 1075.0000 1.0000
25.4800 1063.0000 1.0000
25.5200 1005.0000 1.0000
25.5600 978.0000 1.0000
25.6000 1010.0000 1.0000
25.6400 1017.0000 1.0000
25.6800 1025.0000 1.0000
25.7200 1036.0000 1.0000
25.7600 1052.0000 1.0000
25.8000 1040.0000 1.0000
25.8400 1048.0000 1.0000
25.8800 1073.0000 1.0000
25.9200 1071.0000 1.0000
25.9600 1083.0000 1.0000
26.0000 1170.0000 1.0000
26.0400 1198.0000 1.0000
26.0800 1208.0000 1.0000
26.1200 1286.0000 1.0000
26.1600 1411.0000 1.0000
26.2000 1519.0000 1.0000
26.2400 1753.0000 1.0000
26.2800 2080.0000 1.0000
26.3200 2505.0000 1.0000
26.3600 3152.0000 1.0000
26.4000 3834.0000 1.0000
26.4400 4035.0000 1.0000
26.4800 3724.0000 1.0000
26.5200 3015.0000 1.0000
26.5600 2482.0000 1.0000
26.6000 2039.0000 1.0000
26.6400 1721.0000 1.0000
26.6800 1503.0000 1.0000
26.7200 1351.0000 1.0000
26.7600 1282.0000 1.0000
26.8000 1190.0000 1.0000
26.8400 1152.0000 1.0000
26.8800 1028.0000 1.0000
26.9200 1109.0000 1.0000
26.9600 1105.0000 1.0000
27.0000 1099.0000 1.0000
27.0400 1029.0000 1.0000
27.0800 1071.0000 1.0000
27.1200 1031.0000 1.0000
27.1600 984.0000 1.0000
27.2000 1020.0000 1.0000
27.2400 1042.0000 1.0000
27.2800 986.0000 1.0000
27.3200 1007.0000 1.0000
27.3600 967.0000 1.0000
27.4000 1012.0000 1.0000
27.4400 962.0000 1.0000
27.4800 946.0000 1.0000
27.5200 943.0000 1.0000
27.5600 899.0000 1.0000
27.6000 937.0000 1.0000
27.6400 931.0000 1.0000
27.6800 1004.0000 1.0000
27.7200 967.0000 1.0000
27.7600 939.0000 1.0000
27.8000 999.0000 1.0000
27.8400 952.0000 1.0000
27.8800 869.0000 1.0000
27.9200 937.0000 1.0000
27.9600 913.0000 1.0000
28.0000 915.0000 1.0000
28.0400 912.0000 1.0000
28.0800 920.0000 1.0000
28.1200 968.0000 1.0000
28.1600 887.0000 1.0000
28.2000 925.0000 1.0000
28.2400 906.0000 1.0000
28.2800 937.0000 1.0000
28.3200 890.0000 1.0000
28.3600 915.0000 1.0000
28.4000 901.0000 1.0000
28.4400 876.0000 1.0000
28.4800 926.0000 1.0000
28.5200 966.0000 1.0000
28.5600 908.0000 1.0000
28.6000 877.0000 1.0000
28.6400 875.0000 1.0000
28.6800 838.0000 1.0000
28.7200 890.0000 1.0000
28.7600 888.0000 1.0000
28.8000 871.0000 1.0000
28.8400 861.0000 1.0000
28.8800 899.0000 1.0000
28.9200 899.0000 1.0000
28.9600 886.0000 1.0000
29.0000 944.0000 1.0000
29.0400 861.0000 1.0000
29.0800 842.0000 1.0000
29.1200 863.0000 1.0000
29.1600 874.0000 1.0000
29.2000 912.0000 1.0000
29.2400 861.0000 1.0000
29.2800 917.0000 1.0000
29.3200 900.0000 1.0000
29.3600 873.0000 1.0000
29.4000 846.0000 1.0000
29.4400 876.0000 1.0000
29.4800 857.0000 1.0000
29.5200 895.0000 1.0000
29.5600 829.0000 1.0000
29.6000 897.0000 1.0000
29.6400 868.0000 1.0000
29.6800 877.0000 1.0000
29.7200 837.0000 1.0000
29.7600 875.0000 1.0000
29.8000 843.0000 1.0000
29.8400 834.0000 1.0000
29.8800 839.0000 1.0000
29.9200 818.0000 1.0000
29.9600 821.0000 1.0000
30.0000 894.0000 1.0000
30.0400 836.0000 1.0000
30.0800 831.0000 1.0000
30.1200 825.0000 1.0000
30.1600 864.0000 1.0000
30.2000 895.0000 1.0000
30.2400 846.0000 1.0000
30.2800 860.0000 1.0000
30.3200 826.0000 1.0000
30.3600 785.0000 1.0000
30.4000 835.0000 1.0000
30.4400 847.0000 1.0000
30.4800 862.0000 1.0000
30.5200 849.0000 1.0000
30.5600 818.0000 1.0000
30.6000 806.0000 1.0000
30.6400 827.0000 1.0000
30.6800 785.0000 1.0000
30.7200 806.0000 1.0000
30.7600 858.0000 1.0000
30.8000 807.0000 1.0000
30.8400 845.0000 1.0000
30.8800 817.0000 1.0000
30.9200 835.0000 1.0000
30.9600 836.0000 1.0000
31.0000 765.0000 1.0000
31.0400 846.0000 1.0000
31.0800 838.0000 1.0000
31.1200 840.0000 1.0000
31.1600 829.0000 1.0000
31.2000 834.0000 1.0000
31.2400 819.0000 1.0000
31.2800 792.0000 1.0000
31.3200 770.0000 1.0000
31.3600 792.0000 1.0000
31.4000 826.0000 1.0000
31.4400 777.0000 1.0000
31.4800 802.0000 1.0000
31.5200 835.0000 1.0000
31.5600 816.0000 1.0000
31.6000 776.0000 1.0000
31.6400 827.0000 1.0000
31.6800 776.0000 1.0000
31.7200 788.0000 1.0000
31.7600 769.0000 1.0000
31.8000 780.0000 1.0000
31.8400 714.0000 1.0000
31.8800 818.0000 1.0000
31.9200 789.0000 1.0000
31.9600 773.0000 1.0000
32.0000 768.0000 1.0000
32.0400 765.0000 1.0000
32.0800 787.0000 1.0000
32.1200 773.0000 1.0000
32.1600 789.0000 1.0000
32.2000 782.0000 1.0000
32.2400 777.0000 1.0000
32.2800 788.0000 1.0000
32.3200 766.0000 1.0000
32.3600 780.0000 1.0000
32.4000 816.0000 1.0000
32.4400 751.0000 1.0000
32.4800 712.0000 1.0000
32.5200 729.0000 1.0000
32.5600 750.0000 1.0000
32.6000 762.0000 1.0000
32.6400 745.0000 1.0000
32.6800 786.0000 1.0000
32.7200 719.0000 1.0000
32.7600 768.0000 1.0000
32.8000 808.0000 1.0000
32.8400 800.0000 1.0000
32.8800 816.0000 1.0000
32.9200 847.0000 1.0000
32.9600 893.0000 1.0000
33.0000 955.0000 1.0000
33.0400 1051.0000 1.0000
33.0800 1119.0000 1.0000
33.1200 1148.0000 1.0000
33.1600 1017.0000 1.0000
33.2000 958.0000 1.0000
33.2400 859.0000 1.0000
33.2800 890.0000 1.0000
33.3200 878.0000 1.0000
33.3600 916.0000 1.0000
33.4000 926.0000 1.0000
33.4400 1055.0000 1.0000
33.4800 1132.0000 1.0000
33.5200 1269.0000 1.0000
33.5600 1610.0000 1.0000
33.6000 1827.0000 1.0000
33.6400 1957.0000 1.0000
33.6800 1893.0000 1.0000
33.7200 1703.0000 1.0000
33.7600 1476.0000 1.0000
33.8000 1214.0000 1.0000
33.8400 1081.0000 1.0000
33.8800 1012.0000 1.0000
33.9200 921.0000 1.0000
33.9600 874.0000 1.0000
34.0000 841.0000 1.0000
34.0400 836.0000 1.0000
34.0800 774.0000 1.0000
34.1200 784.0000 1.0000
34.1600 746.0000 1.0000
34.2000 747.0000 1.0000
34.2400 732.0000 1.0000
34.2800 699.0000 1.0000
34.3200 699.0000 1.0000
34.3600 719.0000 1.0000
34.4000 694.0000 1.0000
34.4400 697.0000 1.0000
34.4800 694.0000 1.0000
34.5200 714.0000 1.0000
34.5600 684.0000 1.0000
34.6000 663.0000 1.0000
34.6400 653.0000 1.0000
34.6800 708.0000 1.0000
34.7200 690.0000 1.0000
34.7600 684.0000 1.0000
34.8000 641.0000 1.0000
34.8400 673.0000 1.0000
34.8800 662.0000 1.0000
34.9200 660.0000 1.0000
34.9600 703.0000 1.0000
35.0000 678.0000 1.0000
35.0400 678.0000 1.0000
35.0800 692.0000 1.0000
35.1200 675.0000 1.0000
35.1600 659.0000 1.0000
35.2000 673.0000 1.0000
35.2400 684.0000 1.0000
35.2800 705.0000 1.0000
35.3200 706.0000 1.0000
35.3600 701.0000 1.0000
35.4000 688.0000 1.0000
35.4400 842.0000 1.0000
35.4800 901.0000 1.0000
35.5200 1046.0000 1.0000
35.5600 1052.0000 1.0000
35.6000 1122.0000 1.0000
35.6400 969.0000 1.0000
35.6800 839.0000 1.0000
35.7200 762.0000 1.0000
35.7600 643.0000 1.0000
35.8000 689.0000 1.0000
35.8400 665.0000 1.0000
35.8800 647.0000 1.0000
35.9200 633.0000 1.0000
35.9600 664.0000 1.0000
36.0000 626.0000 1.0000
36.0400 571.0000 1.0000
36.0800 587.0000 1.0000
36.1200 632.0000 1.0000
36.1600 592.0000 1.0000
36.2000 606.0000 1.0000
36.2400 615.0000 1.0000
36.2800 582.0000 1.0000
36.3200 590.0000 1.0000
36.3600 610.0000 1.0000
36.4000 598.0000 1.0000
36.4400 628.0000 1.0000
36.4800 583.0000 1.0000
36.5200 579.0000 1.0000
36.5600 602.0000 1.0000
36.6000 637.0000 1.0000
36.6400 615.0000 1.0000
36.6800 616.0000 1.0000
36.7200 658.0000 1.0000
36.7600 594.0000 1.0000
36.8000 572.0000 1.0000
36.8400 614.0000 1.0000
36.8800 600.0000 1.0000
36.9200 606.0000 1.0000
36.9600 606.0000 1.0000
37.0000 623.0000 1.0000
37.0400 609.0000 1.0000
37.0800 634.0000 1.0000
37.1200 613.0000 1.0000
37.1600 607.0000 1.0000
37.2000 625.0000 1.0000
37.2400 614.0000 1.0000
37.2800 645.0000 1.0000
37.3200 738.0000 1.0000
37.3600 808.0000 1.0000
37.4000 827.0000 1.0000
37.4400 1028.0000 1.0000
37.4800 1179.0000 1.0000
37.5200 1475.0000 1.0000
37.5600 1813.0000 1.0000
37.6000 2275.0000 1.0000
37.6400 2924.0000 1.0000
37.6800 3242.0000 1.0000
37.7200 3196.0000 1.0000
37.7600 2921.0000 1.0000
37.8000 2364.0000 1.0000
37.8400 1966.0000 1.0000
37.8800 1477.0000 1.0000
37.9200 1212.0000 1.0000
37.9600 960.0000 1.0000
38.0000 844.0000 1.0000
38.0400 750.0000 1.0000
38.0800 695.0000 1.0000
38.1200 649.0000 1.0000
38.1600 616.0000 1.0000
38.2000 610.0000 1.0000
38.2400 647.0000 1.0000
38.2800 612.0000 1.0000
38.3200 586.0000 1.0000
38.3600 576.0000 1.0000
38.4000 586.0000 1.0000
38.4400 580.0000 1.0000
38.4800 580.0000 1.0000
38.5200 540.0000 1.0000
38.5600 543.0000 1.0000
38.6000 557.0000 1.0000
38.6400 582.0000 1.0000
38.6800 566.0000 1.0000
38.7200 596.0000 1.0000
38.7600 560.0000 1.0000
38.8000 606.0000 1.0000
38.8400 547.0000 1.0000
38.8800 570.0000 1.0000
38.9200 532.0000 1.0000
38.9600 516.0000 1.0000
39.0000 508.0000 1.0000
39.0400 498.0000 1.0000
39.0800 520.0000 1.0000
39.1200 520.0000 1.0000
39.1600 584.0000 1.0000
39.2000 553.0000 1.0000
39.2400 556.0000 1.0000
39.2800 509.0000 1.0000
39.3200 512.0000 1.0000
39.3600 525.0000 1.0000
39.4000 511.0000 1.0000
39.4400 504.0000 1.0000
39.4800 515.0000 1.0000
39.5200 528.0000 1.0000
39.5600 467.0000 1.0000
39.6000 437.0000 1.0000
39.6400 530.0000 1.0000
39.6800 520.0000 1.0000
39.7200 502.0000 1.0000
39.7600 504.0000 1.0000
39.8000 534.0000 1.0000
39.8400 513.0000 1.0000
39.8800 490.0000 1.0000
39.9200 482.0000 1.0000
39.9600 495.0000 1.0000
40.0000 509.0000 1.0000
40.0400 484.0000 1.0000
40.0800 500.0000 1.0000
40.1200 520.0000 1.0000
40.1600 493.0000 1.0000
40.2000 469.0000 1.0000
40.2400 507.0000 1.0000
40.2800 476.0000 1.0000
40.3200 493.0000 1.0000
40.3600 491.0000 1.0000
40.4000 487.0000 1.0000
40.4400 500.0000 1.0000
40.4800 473.0000 1.0000
40.5200 490.0000 1.0000
40.5600 484.0000 1.0000
40.6000 507.0000 1.0000
40.6400 498.0000 1.0000
40.6800 502.0000 1.0000
40.7200 519.0000 1.0000
40.7600 585.0000 1.0000
40.8000 543.0000 1.0000
40.8400 533.0000 1.0000
40.8800 543.0000 1.0000
40.9200 530.0000 1.0000
40.9600 490.0000 1.0000
41.0000 493.0000 1.0000
41.0400 478.0000 1.0000
41.0800 475.0000 1.0000
41.1200 500.0000 1.0000
41.1600 487.0000 1.0000
41.2000 479.0000 1.0000
41.2400 499.0000 1.0000
41.2800 479.0000 1.0000
41.3200 516.0000 1.0000
41.3600 458.0000 1.0000
41.4000 518.0000 1.0000
41.4400 495.0000 1.0000
41.4800 453.0000 1.0000
41.5200 503.0000 1.0000
41.5600 477.0000 1.0000
41.6000 487.0000 1.0000
41.6400 469.0000 1.0000
41.6800 476.0000 1.0000
41.7200 489.0000 1.0000
41.7600 509.0000 1.0000
41.8000 514.0000 1.0000
41.8400 472.0000 1.0000
41.8800 464.0000 1.0000
41.9200 480.0000 1.0000
41.9600 516.0000 1.0000
42.0000 471.0000 1.0000
42.0400 491.0000 1.0000
42.0800 485.0000 1.0000
42.1200 450.0000 1.0000
42.1600 482.0000 1.0000
42.2000 477.0000 1.0000
42.2400 501.0000 1.0000
42.2800 537.0000 1.0000
42.3200 548.0000 1.0000
42.3600 565.0000 1.0000
42.4000 542.0000 1.0000
42.4400 516.0000 1.0000
42.4800 523.0000 1.0000
42.5200 525.0000 1.0000
42.5600 498.0000 1.0000
42.6000 492.0000 1.0000
42.6400 480.0000 1.0000
42.6800 463.0000 1.0000
42.7200 430.0000 1.0000
42.7600 466.0000 1.0000
42.8000 468.0000 1.0000
42.8400 440.0000 1.0000
42.8800 484.0000 1.0000
42.9200 481.0000 1.0000
42.9600 463.0000 1.0000
43.0000 467.0000 1.0000
43.0400 471.0000 1.0000
43.0800 472.0000 1.0000
43.1200 498.0000 1.0000
43.1600 476.0000 1.0000
43.2000 452.0000 1.0000
43.2400 453.0000 1.0000
43.2800 461.0000 1.0000
43.3200 442.0000 1.0000
43.3600 458.0000 1.0000
43.4000 462.0000 1.0000
43.4400 482.0000 1.0000
43.4800 489.0000 1.0000
43.5200 444.0000 1.0000
43.5600 486.0000 1.0000
43.6000 436.0000 1.0000
43.6400 462.0000 1.0000
43.6800 441.0000 1.0000
43.7200 473.0000 1.0000
43.7600 476.0000 1.0000
43.8000 463.0000 1.0000
43.8400 449.0000 1.0000
43.8800 486.0000 1.0000
43.9200 396.0000 1.0000
43.9600 467.0000 1.0000
44.0000 426.0000 1.0000
44.0400 434.0000 1.0000
44.0800 450.0000 1.0000
44.1200 440.0000 1.0000
44.1600 418.0000 1.0000
44.2000 465.0000 1.0000
44.2400 456.0000 1.0000
44.2800 458.0000 1.0000
44.3200 466.0000 1.0000
44.3600 449.0000 1.0000
44.4000 421.0000 1.0000
44.4400 453.0000 1.0000
44.4800 470.0000 1.0000
44.5200 458.0000 1.0000
44.5600 428.0000 1.0000
44.6000 450.0000 1.0000
44.6400 436.0000 1.0000
44.6800 441.0000 1.0000
44.7200 423.0000 1.0000
44.7600 459.0000 1.0000
44.8000 418.0000 1.0000
44.8400 434.0000 1.0000
44.8800 465.0000 1.0000
44.9200 453.0000 1.0000
44.9600 448.0000 1.0000
45.0000 415.0000 1.0000
45.0400 433.0000 1.0000
45.0800 466.0000 1.0000
45.1200 416.0000 1.0000
45.1600 486.0000 1.0000
45.2000 415.0000 1.0000
45.2400 461.0000 1.0000
45.2800 459.0000 1.0000
45.3200 461.0000 1.0000
45.3600 435.0000 1.0000
45.4000 496.0000 1.0000
45.4400 454.0000 1.0000
45.4800 455.0000 1.0000
45.5200 407.0000 1.0000
45.5600 436.0000 1.0000
45.6000 436.0000 1.0000
45.6400 443.0000 1.0000
45.6800 428.0000 1.0000
45.7200 424.0000 1.0000
45.7600 441.0000 1.0000
45.8000 431.0000 1.0000
45.8400 436.0000 1.0000
45.8800 481.0000 1.0000
45.9200 442.0000 1.0000
45.9600 449.0000 1.0000
46.0000 416.0000 1.0000
46.0400 400.0000 1.0000
46.0800 431.0000 1.0000
46.1200 449.0000 1.0000
46.1600 442.0000 1.0000
46.2000 454.0000 1.0000
46.2400 438.0000 1.0000
46.2800 460.0000 1.0000
46.3200 435.0000 1.0000
46.3600 462.0000 1.0000
46.4000 460.0000 1.0000
46.4400 439.0000 1.0000
46.4800 413.0000 1.0000
46.5200 417.0000 1.0000
46.5600 418.0000 1.0000
46.6000 428.0000 1.0000
46.6400 451.0000 1.0000
46.6800 445.0000 1.0000
46.7200 463.0000 1.0000
46.7600 442.0000 1.0000
46.8000 439.0000 1.0000
46.8400 456.0000 1.0000
46.8800 396.0000 1.0000
46.9200 410.0000 1.0000
46.9600 434.0000 1.0000
47.0000 441.0000 1.0000
47.0400 471.0000 1.0000
47.0800 436.0000 1.0000
47.1200 454.0000 1.0000
47.1600 424.0000 1.0000
47.2000 460.0000 1.0000
47.2400 434.0000 1.0000
47.2800 433.0000 1.0000
47.3200 438.0000 1.0000
47.3600 441.0000 1.0000
47.4000 453.0000 1.0000
47.4400 483.0000 1.0000
47.4800 468.0000 1.0000
47.5200 403.0000 1.0000
47.5600 443.0000 1.0000
47.6000 433.0000 1.0000
47.6400 454.0000 1.0000
47.6800 441.0000 1.0000
47.7200 437.0000 1.0000
47.7600 412.0000 1.0000
47.8000 463.0000 1.0000
47.8400 397.0000 1.0000
47.8800 398.0000 1.0000
47.9200 417.0000 1.0000
47.9600 424.0000 1.0000
48.0000 409.0000 1.0000
48.0400 398.0000 1.0000
48.0800 429.0000 1.0000
48.1200 424.0000 1.0000
48.1600 414.0000 1.0000
48.2000 444.0000 1.0000
48.2400 449.0000 1.0000
48.2800 436.0000 1.0000
48.3200 392.0000 1.0000
48.3600 439.0000 1.0000
48.4000 456.0000 1.0000
48.4400 424.0000 1.0000
48.4800 386.0000 1.0000
48.5200 419.0000 1.0000
48.5600 443.0000 1.0000
48.6000 419.0000 1.0000
48.6400 424.0000 1.0000
48.6800 425.0000 1.0000
48.7200 407.0000 1.0000
48.7600 402.0000 1.0000
48.8000 431.0000 1.0000
48.8400 407.0000 1.0000
48.8800 387.0000 1.0000
48.9200 436.0000 1.0000
48.9600 422.0000 1.0000
49.0000 405.0000 1.0000
49.0400 418.0000 1.0000
49.0800 399.0000 1.0000
49.1200 399.0000 1.0000
49.1600 415.0000 1.0000
49.2000 423.0000 1.0000
49.2400 449.0000 1.0000
49.2800 460.0000 1.0000
49.3200 453.0000 1.0000
49.3600 494.0000 1.0000
49.4000 491.0000 1.0000
49.4400 504.0000 1.0000
49.4800 480.0000 1.0000
49.5200 476.0000 1.0000
49.5600 401.0000 1.0000
49.6000 450.0000 1.0000
49.6400 447.0000 1.0000
49.6800 412.0000 1.0000
49.7200 431.0000 1.0000
49.7600 453.0000 1.0000
49.8000 452.0000 1.0000
49.8400 432.0000 1.0000
49.8800 423.0000 1.0000
49.9200 409.0000 1.0000
49.9600 441.0000 1.0000
50.0000 479.0000 1.0000
50.0400 402.0000 1.0000
50.0800 432.0000 1.0000
50.1200 419.0000 1.0000
50.1600 440.0000 1.0000
50.2000 422.0000 1.0000
50.2400 398.0000 1.0000
50.2800 397.0000 1.0000
50.3200 433.0000 1.0000
50.3600 432.0000 1.0000
50.4000 419.0000 1.0000
50.4400 434.0000 1.0000
50.4800 428.0000 1.0000
50.5200 401.0000 1.0000
50.5600 415.0000 1.0000
50.6000 414.0000 1.0000
50.6400 392.0000 1.0000
50.6800 438.0000 1.0000
50.7200 410.0000 1.0000
50.7600 454.0000 1.0000
50.8000 407.0000 1.0000
50.8400 448.0000 1.0000
50.8800 458.0000 1.0000
50.9200 501.0000 1.0000
50.9600 461.0000 1.0000
51.0000 437.0000 1.0000
51.0400 459.0000 1.0000
51.0800 495.0000 1.0000
51.1200 580.0000 1.0000
51.1600 582.0000 1.0000
51.2000 664.0000 1.0000
51.2400 756.0000 1.0000
51.2800 965.0000 1.0000
51.3200 1246.0000 1.0000
51.3600 1587.0000 1.0000
51.4000 2150.0000 1.0000
51.4400 2764.0000 1.0000
51.4800 2951.0000 1.0000
51.5200 2758.0000 1.0000
51.5600 2439.0000 1.0000
51.6000 2140.0000 1.0000
51.6400 1820.0000 1.0000
51.6800 1377.0000 1.0000
51.7200 1033.0000 1.0000
51.7600 846.0000 1.0000
51.8000 737.0000 1.0000
51.8400 641.0000 1.0000
51.8800 606.0000 1.0000
51.9200 515.0000 1.0000
51.9600 514.0000 1.0000
52.0000 502.0000 1.0000
52.0400 477.0000 1.0000
52.0800 484.0000 1.0000
52.1200 482.0000 1.0000
52.1600 426.0000 1.0000
52.2000 433.0000 1.0000
52.2400 425.0000 1.0000
52.2800 424.0000 1.0000
52.3200 380.0000 1.0000
52.3600 424.0000 1.0000
52.4000 408.0000 1.0000
52.4400 423.0000 1.0000
52.4800 393.0000 1.0000
52.5200 441.0000 1.0000
52.5600 424.0000 1.0000
52.6000 452.0000 1.0000
52.6400 404.0000 1.0000
52.6800 428.0000 1.0000
52.7200 422.0000 1.0000
52.7600 380.0000 1.0000
52.8000 396.0000 1.0000
52.8400 363.0000 1.0000
52.8800 406.0000 1.0000
52.9200 387.0000 1.0000
52.9600 402.0000 1.0000
53.0000 418.0000 1.0000
53.0400 446.0000 1.0000
53.0800 374.0000 1.0000
53.1200 392.0000 1.0000
53.1600 385.0000 1.0000
53.2000 439.0000 1.0000
53.2400 407.0000 1.0000
53.2800 408.0000 1.0000
53.3200 378.0000 1.0000
53.3600 390.0000 1.0000
53.4000 399.0000 1.0000
53.4400 388.0000 1.0000
53.4800 384.0000 1.0000
53.5200 395.0000 1.0000
53.5600 424.0000 1.0000
53.6000 405.0000 1.0000
53.6400 373.0000 1.0000
53.6800 405.0000 1.0000
53.7200 418.0000 1.0000
53.7600 375.0000 1.0000
53.8000 422.0000 1.0000
53.8400 422.0000 1.0000
53.8800 410.0000 1.0000
53.9200 462.0000 1.0000
53.9600 500.0000 1.0000
54.0000 505.0000 1.0000
54.0400 482.0000 1.0000
54.0800 449.0000 1.0000
54.1200 489.0000 1.0000
54.1600 465.0000 1.0000
54.2000 475.0000 1.0000
54.2400 444.0000 1.0000
54.2800 470.0000 1.0000
54.3200 471.0000 1.0000
54.3600 501.0000 1.0000
54.4000 588.0000 1.0000
54.4400 577.0000 1.0000
54.4800 647.0000 1.0000
54.5200 655.0000 1.0000
54.5600 607.0000 1.0000
54.6000 585.0000 1.0000
54.6400 570.0000 1.0000
54.6800 538.0000 1.0000
54.7200 512.0000 1.0000
54.7600 454.0000 1.0000
54.8000 417.0000 1.0000
54.8400 454.0000 1.0000
54.8800 412.0000 1.0000
54.9200 407.0000 1.0000
54.9600 397.0000 1.0000
55.0000 385.0000 1.0000
55.0400 409.0000 1.0000
55.0800 407.0000 1.0000
55.1200 394.0000 1.0000
55.1600 378.0000 1.0000
55.2000 395.0000 1.0000
55.2400 386.0000 1.0000
55.2800 394.0000 1.0000
55.3200 406.0000 1.0000
55.3600 383.0000 1.0000
55.4000 410.0000 1.0000
55.4400 415.0000 1.0000
55.4800 367.0000 1.0000
55.5200 390.0000 1.0000
55.5600 396.0000 1.0000
55.6000 377.0000 1.0000
55.6400 387.0000 1.0000
55.6800 387.0000 1.0000
55.7200 394.0000 1.0000
55.7600 367.0000 1.0000
55.8000 358.0000 1.0000
55.8400 365.0000 1.0000
55.8800 390.0000 1.0000
55.9200 404.0000 1.0000
55.9600 363.0000 1.0000
56.0000 379.0000 1.0000
56.0400 343.0000 1.0000
56.0800 374.0000 1.0000
56.1200 365.0000 1.0000
56.1600 382.0000 1.0000
56.2000 366.0000 1.0000
56.2400 360.0000 1.0000
56.2800 369.0000 1.0000
56.3200 395.0000 1.0000
56.3600 351.0000 1.0000
56.4000 392.0000 1.0000
56.4400 370.0000 1.0000
56.4800 368.0000 1.0000
56.5200 361.0000 1.0000
56.5600 365.0000 1.0000
56.6000 385.0000 1.0000
56.6400 348.0000 1.0000
56.6800 374.0000 1.0000
56.7200 396.0000 1.0000
56.7600 358.0000 1.0000
56.8000 355.0000 1.0000
56.8400 374.0000 1.0000
56.8800 349.0000 1.0000
56.9200 357.0000 1.0000
56.9600 359.0000 1.0000
57.0000 380.0000 1.0000
57.0400 354.0000 1.0000
57.0800 382.0000 1.0000
57.1200 364.0000 1.0000
57.1600 373.0000 1.0000
57.2000 384.0000 1.0000
57.2400 388.0000 1.0000
57.2800 367.0000 1.0000
57.3200 390.0000 1.0000
57.3600 355.0000 1.0000
57.4000 375.0000 1.0000
57.4400 377.0000 1.0000
57.4800 394.0000 1.0000
57.5200 375.0000 1.0000
57.5600 392.0000 1.0000
57.6000 390.0000 1.0000
57.6400 378.0000 1.0000
57.6800 374.0000 1.0000
57.7200 380.0000 1.0000
57.7600 379.0000 1.0000
57.8000 370.0000 1.0000
57.8400 371.0000 1.0000
57.8800 374.0000 1.0000
57.9200 351.0000 1.0000
57.9600 353.0000 1.0000
58.0000 367.0000 1.0000
58.0400 361.0000 1.0000
58.0800 364.0000 1.0000
58.1200 400.0000 1.0000
58.1600 381.0000 1.0000
58.2000 357.0000 1.0000
58.2400 379.0000 1.0000
58.2800 384.0000 1.0000
58.3200 352.0000 1.0000
58.3600 362.0000 1.0000
58.4000 369.0000 1.0000
58.4400 349.0000 1.0000
58.4800 357.0000 1.0000
58.5200 401.0000 1.0000
58.5600 393.0000 1.0000
58.6000 374.0000 1.0000
58.6400 349.0000 1.0000
58.6800 346.0000 1.0000
58.7200 359.0000 1.0000
58.7600 401.0000 1.0000
58.8000 401.0000 1.0000
58.8400 358.0000 1.0000
58.8800 392.0000 1.0000
58.9200 392.0000 1.0000
58.9600 354.0000 1.0000
59.0000 385.0000 1.0000
59.0400 386.0000 1.0000
59.0800 367.0000 1.0000
59.1200 379.0000 1.0000
59.1600 366.0000 1.0000
59.2000 361.0000 1.0000
59.2400 380.0000 1.0000
59.2800 390.0000 1.0000
59.3200 376.0000 1.0000
59.3600 381.0000 1.0000
59.4000 407.0000 1.0000
59.4400 374.0000 1.0000
59.4800 357.0000 1.0000
59.5200 361.0000 1.0000
59.5600 386.0000 1.0000
59.6000 350.0000 1.0000
59.6400 398.0000 1.0000
59.6800 360.0000 1.0000
59.7200 366.0000 1.0000
59.7600 375.0000 1.0000
59.8000 358.0000 1.0000
59.8400 364.0000 1.0000
59.8800 365.0000 1.0000
59.9200 360.0000 1.0000
59.9600 369.0000 1.0000
60.0000 385.0000 1.0000
60.0400 358.0000 1.0000
60.0800 341.0000 1.0000
60.1200 353.0000 1.0000
60.1600 364.0000 1.0000
60.2000 358.0000 1.0000
60.2400 368.0000 1.0000
60.2800 352.0000 1.0000
60.3200 356.0000 1.0000
60.3600 374.0000 1.0000
60.4000 367.0000 1.0000
60.4400 378.0000 1.0000
60.4800 357.0000 1.0000
60.5200 366.0000 1.0000
60.5600 342.0000 1.0000
60.6000 374.0000 1.0000
60.6400 363.0000 1.0000
60.6800 360.0000 1.0000
60.7200 364.0000 1.0000
60.7600 383.0000 1.0000
60.8000 375.0000 1.0000
60.8400 394.0000 1.0000
60.8800 343.0000 1.0000
60.9200 390.0000 1.0000
60.9600 388.0000 1.0000
61.0000 383.0000 1.0000
61.0400 376.0000 1.0000
61.0800 413.0000 1.0000
61.1200 421.0000 1.0000
61.1600 391.0000 1.0000
61.2000 409.0000 1.0000
61.2400 452.0000 1.0000
61.2800 467.0000 1.0000
61.3200 538.0000 1.0000
61.3600 572.0000 1.0000
61.4000 627.0000 1.0000
61.4400 746.0000 1.0000
61.4800 708.0000 1.0000
61.5200 778.0000 1.0000
61.5600 810.0000 1.0000
61.6000 806.0000 1.0000
61.6400 745.0000 1.0000
61.6800 731.0000 1.0000
61.7200 635.0000 1.0000
61.7600 613.0000 1.0000
61.8000 525.0000 1.0000
61.8400 567.0000 1.0000
61.8800 472.0000 1.0000
61.9200 462.0000 1.0000
61.9600 468.0000 1.0000
62.0000 470.0000 1.0000
62.0400 441.0000 1.0000
62.0800 442.0000 1.0000
62.1200 392.0000 1.0000
62.1600 432.0000 1.0000
62.2000 388.0000 1.0000
62.2400 361.0000 1.0000
62.2800 407.0000 1.0000
62.3200 419.0000 1.0000
62.3600 432.0000 1.0000
62.4000 441.0000 1.0000
62.4400 428.0000 1.0000
62.4800 425.0000 1.0000
62.5200 412.0000 1.0000
62.5600 400.0000 1.0000
62.6000 411.0000 1.0000
62.6400 393.0000 1.0000
62.6800 371.0000 1.0000
62.7200 368.0000 1.0000
62.7600 364.0000 1.0000
62.8000 343.0000 1.0000
62.8400 367.0000 1.0000
62.8800 375.0000 1.0000
62.9200 359.0000 1.0000
62.9600 362.0000 1.0000
63.0000 339.0000 1.0000
63.0400 360.0000 1.0000
63.0800 367.0000 1.0000
63.1200 360.0000 1.0000
63.1600 381.0000 1.0000
63.2000 354.0000 1.0000
63.2400 361.0000 1.0000
63.2800 370.0000 1.0000
63.3200 355.0000 1.0000
63.3600 350.0000 1.0000
63.4000 372.0000 1.0000
63.4400 328.0000 1.0000
63.4800 360.0000 1.0000
63.5200 350.0000 1.0000
63.5600 362.0000 1.0000
63.6000 387.0000 1.0000
63.6400 371.0000 1.0000
63.6800 378.0000 1.0000
63.7200 380.0000 1.0000
63.7600 382.0000 1.0000
63.8000 378.0000 1.0000
63.8400 401.0000 1.0000
63.8800 444.0000 1.0000
63.9200 483.0000 1.0000
63.9600 454.0000 1.0000
64.0000 444.0000 1.0000
64.0400 402.0000 1.0000
64.0800 404.0000 1.0000
64.1200 471.0000 1.0000
64.1600 402.0000 1.0000
64.2000 422.0000 1.0000
64.2400 388.0000 1.0000
64.2800 413.0000 1.0000
64.3200 369.0000 1.0000
64.3600 373.0000 1.0000
64.4000 400.0000 1.0000
64.4400 382.0000 1.0000
64.4800 398.0000 1.0000
64.5200 380.0000 1.0000
64.5600 428.0000 1.0000
64.6000 366.0000 1.0000
64.6400 370.0000 1.0000
64.6800 393.0000 1.0000
64.7200 388.0000 1.0000
64.7600 389.0000 1.0000
64.8000 393.0000 1.0000
64.8400 390.0000 1.0000
64.8800 370.0000 1.0000
64.9200 393.0000 1.0000
64.9600 401.0000 1.0000
65.0000 404.0000 1.0000
65.0400 382.0000 1.0000
65.0800 404.0000 1.0000
65.1200 477.0000 1.0000
65.1600 512.0000 1.0000
65.2000 481.0000 1.0000
65.2400 553.0000 1.0000
65.2800 576.0000 1.0000
65.3200 701.0000 1.0000
65.3600 804.0000 1.0000
65.4000 940.0000 1.0000
65.4400 1170.0000 1.0000
65.4800 1287.0000 1.0000
65.5200 1349.0000 1.0000
65.5600 1333.0000 1.0000
65.6000 1234.0000 1.0000
65.6400 1196.0000 1.0000
65.6800 1119.0000 1.0000
65.7200 1036.0000 1.0000
65.7600 865.0000 1.0000
65.8000 751.0000 1.0000
65.8400 645.0000 1.0000
65.8800 534.0000 1.0000
65.9200 528.0000 1.0000
65.9600 493.0000 1.0000
66.0000 463.0000 1.0000
66.0400 412.0000 1.0000
66.0800 418.0000 1.0000
66.1200 413.0000 1.0000
66.1600 372.0000 1.0000
66.2000 386.0000 1.0000
66.2400 414.0000 1.0000
66.2800 353.0000 1.0000
66.3200 359.0000 1.0000
66.3600 367.0000 1.0000
66.4000 352.0000 1.0000
66.4400 376.0000 1.0000
66.4800 349.0000 1.0000
66.5200 334.0000 1.0000
66.5600 371.0000 1.0000
66.6000 357.0000 1.0000
66.6400 361.0000 1.0000
66.6800 379.0000 1.0000
66.7200 359.0000 1.0000
66.7600 347.0000 1.0000
66.8000 360.0000 1.0000
66.8400 326.0000 1.0000
66.8800 335.0000 1.0000
66.9200 336.0000 1.0000
66.9600 359.0000 1.0000
67.0000 337.0000 1.0000
67.0400 319.0000 1.0000
67.0800 333.0000 1.0000
67.1200 299.0000 1.0000
67.1600 350.0000 1.0000
67.2000 343.0000 1.0000
67.2400 341.0000 1.0000
67.2800 318.0000 1.0000
67.3200 339.0000 1.0000
67.3600 333.0000 1.0000
67.4000 334.0000 1.0000
67.4400 346.0000 1.0000
67.4800 304.0000 1.0000
67.5200 323.0000 1.0000
67.5600 323.0000 1.0000
67.6000 331.0000 1.0000
67.6400 313.0000 1.0000
67.6800 313.0000 1.0000
67.7200 327.0000 1.0000
67.7600 322.0000 1.0000
67.8000 302.0000 1.0000
67.8400 334.0000 1.0000
67.8800 328.0000 1.0000
67.9200 312.0000 1.0000
67.9600 330.0000 1.0000
68.0000 303.0000 1.0000
68.0400 318.0000 1.0000
68.0800 322.0000 1.0000
68.1200 346.0000 1.0000
68.1600 321.0000 1.0000
68.2000 333.0000 1.0000
68.2400 298.0000 1.0000
68.2800 331.0000 1.0000
68.3200 327.0000 1.0000
68.3600 342.0000 1.0000
68.4000 295.0000 1.0000
68.4400 307.0000 1.0000
68.4800 331.0000 1.0000
68.5200 329.0000 1.0000
68.5600 309.0000 1.0000
68.6000 329.0000 1.0000
68.6400 328.0000 1.0000
68.6800 339.0000 1.0000
68.7200 345.0000 1.0000
68.7600 325.0000 1.0000
68.8000 338.0000 1.0000
68.8400 327.0000 1.0000
68.8800 319.0000 1.0000
68.9200 339.0000 1.0000
68.9600 330.0000 1.0000
69.0000 311.0000 1.0000
69.0400 343.0000 1.0000
69.0800 338.0000 1.0000
69.1200 341.0000 1.0000
69.1600 339.0000 1.0000
69.2000 328.0000 1.0000
69.2400 320.0000 1.0000
69.2800 325.0000 1.0000
69.3200 311.0000 1.0000
69.3600 368.0000 1.0000
69.4000 325.0000 1.0000
69.4400 310.0000 1.0000
69.4800 346.0000 1.0000
69.5200 328.0000 1.0000
69.5600 323.0000 1.0000
69.6000 324.0000 1.0000
69.6400 334.0000 1.0000
69.6800 338.0000 1.0000
69.7200 329.0000 1.0000
69.7600 310.0000 1.0000
69.8000 300.0000 1.0000
69.8400 304.0000 1.0000
69.8800 346.0000 1.0000
69.9200 327.0000 1.0000
69.9600 307.0000 1.0000
70.0000 305.0000 1.0000
*RAS_INT_END
*RAS_TEMPERATURE_START
*RAS_TEMPERATURE_END
*RAS_DATA_END