File: Data/Dataset1_Only_water/5_XRD/No_008_FS2_4.ras
*RAS_DATA_START
*RAS_HEADER_START
*DISP_FMT_X "%.2f"
*DISP_FMT_Y "%.0f"
*DISP_FULLSCALE "14292.0000000000"
*DISP_LINE_COLOR "255.0000000000"
*DISP_LINE_STYLE "0.0000000000"
*DISP_LINE_WIDTH "0.2500000000"
*DISP_NOTE "測定データ-5"
*DISP_OFFSET_Y "0.0000000000"
*DISP_PEAKSEARCH_UNIT_Y "cps"
*DISP_RANGE_BOTTOM "0.0000000000"
*DISP_RANGE_LEFT "20.0000000000"
*DISP_RANGE_LOGCUTOFF "0.0100000000"
*DISP_RANGE_RIGHT "70.0000000000"
*DISP_RANGE_TOP "14292.0000000000"
*DISP_SCALE_MODE_Y "0.0000000000"
*DISP_TAB_NAME "2θ/θ"
*DISP_TITLE_Y "強度"
*DISP_UNIT_Y "cps"
*DISP_WINDOW_NAME "MSG_MACROENGINE"
*FILE_COMMENT " "
*FILE_MD5 ""
*FILE_MEMO " "
*FILE_OPERATOR "Administrator"
*FILE_SAMPLE " "
*FILE_TYPE "RAS_RAW"
*FILE_USERGROUP "システムマネージャ"
*FILE_VERSION "1.0000000000"
*HW_ATTACHMENT_ID "ATT0025"
*HW_ATTACHMENT_NAME "標準|Standard"
*HW_COUNTER_ID-0 "CUT0025"
*HW_COUNTER_ID-1 "CUT0020"
*HW_COUNTER_ID-2 "CUT0020"
*HW_COUNTER_ID-3 "CSL0021"
*HW_COUNTER_ID-4 "CMC0021"
*HW_COUNTER_NAME-0 "D/teX Ultra|D/teX Ultra"
*HW_COUNTER_NAME-1 "None|None"
*HW_COUNTER_NAME-2 "None|None"
*HW_COUNTER_NAME-3 "BBM|BBM"
*HW_COUNTER_NAME-4 "検出器モノクロメータ|Detector monochromator"
*HW_COUNTER_SELECT_NAME "D/teX Ultra|D/teX Ultra"
*HW_GONIOMETER_ID "GON0023"
*HW_GONIOMETER_NAME "SmartLab|SmartLab"
*HW_GONIOMETER_RADIUS-0 "90.0"
*HW_GONIOMETER_RADIUS-1 "114.0"
*HW_GONIOMETER_RADIUS-2 "190.0"
*HW_GONIOMETER_RADIUS-3 "300.0"
*HW_GONIOMETER_RADIUS-4 "187.0"
*HW_GONIOMETER_RADIUS-5 "300.0"
*HW_GONIOMETER_RADIUS-6 "113.0"
*HW_GONIOMETER_RADIUS-7 "331.0"
*HW_I_OPT_ID-0 "CBO0021"
*HW_I_OPT_ID-1 "ICR0023"
*HW_I_OPT_ID-2 "ISL0021"
*HW_I_OPT_ID-3 "ISO0021"
*HW_I_OPT_ID-4 "IAD0021"
*HW_I_OPT_ID-5 "IPR0001"
*HW_I_OPT_NAME-0 "CBOユニット|CBO unit"
*HW_I_OPT_NAME-1 "標準入射光学ユニット|Standard incident optical unit"
*HW_I_OPT_NAME-2 "標準入射スリットボックス|Standard incident slit box"
*HW_I_OPT_NAME-3 "入射平行スリット|Incident parallel slit"
*HW_I_OPT_NAME-4 "長手制限スリット|Length limiting slit"
*HW_I_OPT_NAME-5 "None|None"
*HW_R_ATTENUATER_AUTOMODE "0"
*HW_R_OPT_ID-0 "RSS0021"
*HW_R_OPT_ID-1 "RCR0023"
*HW_R_OPT_ID-2 "RSO0021"
*HW_R_OPT_ID-3 "RRS0021"
*HW_R_OPT_ID-4 "ATN0021"
*HW_R_OPT_ID-5 "RFL0021"
*HW_R_OPT_ID-6 "RAD0021"
*HW_R_OPT_NAME-0 "標準受光スリットボックス1|Standard receiving slit box # 1"
*HW_R_OPT_NAME-1 "標準受光光学ユニット1|Standard receiving unit # 1"
*HW_R_OPT_NAME-2 "標準受光光学ユニット2|Standard receiving optical unit # 2"
*HW_R_OPT_NAME-3 "標準受光スリットボックス2|Standard receiving slit box # 2"
*HW_R_OPT_NAME-4 "標準アッテネータ|Standard Attenuator"
*HW_R_OPT_NAME-5 "Cu Kβ|Cu K-beta"
*HW_R_OPT_NAME-6 "調整用受光スリット|Alignment receiving slit"
*HW_SAMPLE_HOLDER_ID "SMP0023"
*HW_SAMPLE_HOLDER_NAME "標準Zステージ|Standard Z stage"
*HW_XG_CURRENT_MAX "50"
*HW_XG_CURRENT_MIN "2"
*HW_XG_CURRENT_RESOLUTION "1"
*HW_XG_CURRENT_UNIT "mA"
*HW_XG_FOCUS "1mm x 10mm"
*HW_XG_FOCUS_TYPE "Normal"
*HW_XG_ID ""
*HW_XG_NAME "3kW 封入管(ID:1200)|3kW Sealed tube(ID:1200)"
*HW_XG_TARGET_ATOMIC_NUMBER "29.0000000000"
*HW_XG_TARGET_NAME "Cu"
*HW_XG_TYPE "Hermetic"
*HW_XG_VOLTAGE_MAX "60"
*HW_XG_VOLTAGE_MIN "20"
*HW_XG_VOLTAGE_RESOLUTION "1"
*HW_XG_VOLTAGE_UNIT "kV"
*HW_XG_WATT_MAX "1.500"
*HW_XG_WATT_UNIT "kW"
*HW_XG_WAVE_LENGTH_ALPHA1 "1.540593"
*HW_XG_WAVE_LENGTH_ALPHA2 "1.544414"
*HW_XG_WAVE_LENGTH_BETA "1.392250"
*MEAS_COND_AXIS_NAME-0 "2θ/θ"
*MEAS_COND_AXIS_NAME-1 "2θ"
*MEAS_COND_AXIS_NAME-2 "ω"
*MEAS_COND_AXIS_NAME-3 "Z"
*MEAS_COND_AXIS_NAME-4 "2θ/ω"
*MEAS_COND_AXIS_NAME-5 "θs"
*MEAS_COND_AXIS_NAME-6 "θd"
*MEAS_COND_AXIS_NAME-7 "Ts"
*MEAS_COND_AXIS_NAME-8 "CBO選択スリット"
*MEAS_COND_AXIS_NAME-9 "M"
*MEAS_COND_AXIS_NAME-10 "入射平行スリット"
*MEAS_COND_AXIS_NAME-11 "入射スリット"
*MEAS_COND_AXIS_NAME-12 ""
*MEAS_COND_AXIS_NAME-13 "Zs"
*MEAS_COND_AXIS_NAME-14 "入射光学素子"
*MEAS_COND_AXIS_NAME-15 "長手制限スリット"
*MEAS_COND_AXIS_NAME-16 "センタースリット"
*MEAS_COND_AXIS_NAME-17 "フィルター"
*MEAS_COND_AXIS_NAME-18 "受光スリット1"
*MEAS_COND_AXIS_NAME-19 "受光スリット2"
*MEAS_COND_AXIS_NAME-20 "受光光学素子"
*MEAS_COND_AXIS_NAME-21 "受光平行スリット"
*MEAS_COND_AXIS_NAME-22 "調整用受光スリット"
*MEAS_COND_AXIS_NAME-23 ""
*MEAS_COND_AXIS_NAME-24 ""
*MEAS_COND_AXIS_NAME-25 "Zd"
*MEAS_COND_AXIS_NAME-26 "アッテネータ"
*MEAS_COND_AXIS_NAME-27 "検出器モノクロメータ"
*MEAS_COND_AXIS_NAME-28 "モノクロメータスリット"
*MEAS_COND_AXIS_NAME-29 "プライマリビーム"
*MEAS_COND_AXIS_NAME-30 "PHA"
*MEAS_COND_AXIS_NAME_INTERNAL-0 "TwoThetaTheta"
*MEAS_COND_AXIS_NAME_INTERNAL-1 "TwoTheta"
*MEAS_COND_AXIS_NAME_INTERNAL-2 "Omega"
*MEAS_COND_AXIS_NAME_INTERNAL-3 "Z"
*MEAS_COND_AXIS_NAME_INTERNAL-4 "TwoThetaOmega"
*MEAS_COND_AXIS_NAME_INTERNAL-5 "ThetaS"
*MEAS_COND_AXIS_NAME_INTERNAL-6 "ThetaD"
*MEAS_COND_AXIS_NAME_INTERNAL-7 "Ts"
*MEAS_COND_AXIS_NAME_INTERNAL-8 "CBO"
*MEAS_COND_AXIS_NAME_INTERNAL-9 "CBO-M"
*MEAS_COND_AXIS_NAME_INTERNAL-10 "IncidentSollerSlit"
*MEAS_COND_AXIS_NAME_INTERNAL-11 "IncidentSlitBox"
*MEAS_COND_AXIS_NAME_INTERNAL-12 "IncidentSlitBox-_Axis"
*MEAS_COND_AXIS_NAME_INTERNAL-13 "Zs"
*MEAS_COND_AXIS_NAME_INTERNAL-14 "IncidentMonochromator"
*MEAS_COND_AXIS_NAME_INTERNAL-15 "IncidentAxdSlit"
*MEAS_COND_AXIS_NAME_INTERNAL-16 "CenterSlit"
*MEAS_COND_AXIS_NAME_INTERNAL-17 "Filter"
*MEAS_COND_AXIS_NAME_INTERNAL-18 "ReceivingSlitBox1"
*MEAS_COND_AXIS_NAME_INTERNAL-19 "ReceivingSlitBox2"
*MEAS_COND_AXIS_NAME_INTERNAL-20 "ReceivingOptics"
*MEAS_COND_AXIS_NAME_INTERNAL-21 "ReceivingSollerSlit"
*MEAS_COND_AXIS_NAME_INTERNAL-22 "ReceivingAxdSlit"
*MEAS_COND_AXIS_NAME_INTERNAL-23 "ReceivingSlitBox1-_Axis"
*MEAS_COND_AXIS_NAME_INTERNAL-24 "ReceivingSlitBox2-_Axis"
*MEAS_COND_AXIS_NAME_INTERNAL-25 "ReceivingSlitBox2-Zd"
*MEAS_COND_AXIS_NAME_INTERNAL-26 "Attenuator"
*MEAS_COND_AXIS_NAME_INTERNAL-27 "CounterMonochromator"
*MEAS_COND_AXIS_NAME_INTERNAL-28 "CounterSlit"
*MEAS_COND_AXIS_NAME_INTERNAL-29 "IncidentPrimary"
*MEAS_COND_AXIS_NAME_INTERNAL-30 "PHA"
*MEAS_COND_AXIS_NAME_MAGICNO-0 "83951616.0000000000"
*MEAS_COND_AXIS_NAME_MAGICNO-1 "268632064.0000000000"
*MEAS_COND_AXIS_NAME_MAGICNO-2 "268500992.0000000000"
*MEAS_COND_AXIS_NAME_MAGICNO-3 "285278208.0000000000"
*MEAS_COND_AXIS_NAME_MAGICNO-4 "83951616.0000000000"
*MEAS_COND_AXIS_NAME_MAGICNO-5 "131072.0000000000"
*MEAS_COND_AXIS_NAME_MAGICNO-6 "131072.0000000000"
*MEAS_COND_AXIS_NAME_MAGICNO-7 "318898176.0000000000"
*MEAS_COND_AXIS_NAME_MAGICNO-8 "20971521.0000000000"
*MEAS_COND_AXIS_NAME_MAGICNO-9 "285343744.0000000000"
*MEAS_COND_AXIS_NAME_MAGICNO-10 "20971521.0000000000"
*MEAS_COND_AXIS_NAME_MAGICNO-11 "22020097.0000000000"
*MEAS_COND_AXIS_NAME_MAGICNO-12 "25165824.0000000000"
*MEAS_COND_AXIS_NAME_MAGICNO-13 "318898176.0000000000"
*MEAS_COND_AXIS_NAME_MAGICNO-14 "1.0000000000"
*MEAS_COND_AXIS_NAME_MAGICNO-15 "20971521.0000000000"
*MEAS_COND_AXIS_NAME_MAGICNO-16 "20971521.0000000000"
*MEAS_COND_AXIS_NAME_MAGICNO-17 "20971521.0000000000"
*MEAS_COND_AXIS_NAME_MAGICNO-18 "23068673.0000000000"
*MEAS_COND_AXIS_NAME_MAGICNO-19 "23068673.0000000000"
*MEAS_COND_AXIS_NAME_MAGICNO-20 "20971521.0000000000"
*MEAS_COND_AXIS_NAME_MAGICNO-21 "20971521.0000000000"
*MEAS_COND_AXIS_NAME_MAGICNO-22 "20971521.0000000000"
*MEAS_COND_AXIS_NAME_MAGICNO-23 "25165824.0000000000"
*MEAS_COND_AXIS_NAME_MAGICNO-24 "25165824.0000000000"
*MEAS_COND_AXIS_NAME_MAGICNO-25 "285343744.0000000000"
*MEAS_COND_AXIS_NAME_MAGICNO-26 "17301505.0000000000"
*MEAS_COND_AXIS_NAME_MAGICNO-27 "20971521.0000000000"
*MEAS_COND_AXIS_NAME_MAGICNO-28 "20971521.0000000000"
*MEAS_COND_AXIS_NAME_MAGICNO-29 "20971521.0000000000"
*MEAS_COND_AXIS_NAME_MAGICNO-30 "0.0000000000"
*MEAS_COND_AXIS_OFFSET-0 "-"
*MEAS_COND_AXIS_OFFSET-1 "-0.1081000000"
*MEAS_COND_AXIS_OFFSET-2 "0.3758000000"
*MEAS_COND_AXIS_OFFSET-3 "-"
*MEAS_COND_AXIS_OFFSET-4 "-"
*MEAS_COND_AXIS_OFFSET-5 "0.3758000000"
*MEAS_COND_AXIS_OFFSET-6 "-0.4839000000"
*MEAS_COND_AXIS_OFFSET-7 "-"
*MEAS_COND_AXIS_OFFSET-8 "-"
*MEAS_COND_AXIS_OFFSET-9 "-"
*MEAS_COND_AXIS_OFFSET-10 "-"
*MEAS_COND_AXIS_OFFSET-11 "-"
*MEAS_COND_AXIS_OFFSET-12 "-"
*MEAS_COND_AXIS_OFFSET-13 "-"
*MEAS_COND_AXIS_OFFSET-14 "-"
*MEAS_COND_AXIS_OFFSET-15 "-"
*MEAS_COND_AXIS_OFFSET-16 "-"
*MEAS_COND_AXIS_OFFSET-17 "-"
*MEAS_COND_AXIS_OFFSET-18 "-"
*MEAS_COND_AXIS_OFFSET-19 "-"
*MEAS_COND_AXIS_OFFSET-20 "-"
*MEAS_COND_AXIS_OFFSET-21 "-"
*MEAS_COND_AXIS_OFFSET-22 "-"
*MEAS_COND_AXIS_OFFSET-23 "-"
*MEAS_COND_AXIS_OFFSET-24 "-"
*MEAS_COND_AXIS_OFFSET-25 "-"
*MEAS_COND_AXIS_OFFSET-26 "-"
*MEAS_COND_AXIS_OFFSET-27 "-"
*MEAS_COND_AXIS_OFFSET-28 "-"
*MEAS_COND_AXIS_OFFSET-29 "-"
*MEAS_COND_AXIS_OFFSET-30 "-"
*MEAS_COND_AXIS_POSITION-0 "0.0000000000"
*MEAS_COND_AXIS_POSITION-1 "0.0000000000"
*MEAS_COND_AXIS_POSITION-2 "0.0000000000"
*MEAS_COND_AXIS_POSITION-3 "-0.5500000000"
*MEAS_COND_AXIS_POSITION-4 "0.0000000000"
*MEAS_COND_AXIS_POSITION-5 "0.0000000000"
*MEAS_COND_AXIS_POSITION-6 "0.0000000000"
*MEAS_COND_AXIS_POSITION-7 "-0.4278800000"
*MEAS_COND_AXIS_POSITION-8 "BB"
*MEAS_COND_AXIS_POSITION-9 "0.0000000000"
*MEAS_COND_AXIS_POSITION-10 "Soller_slit_5.0deg"
*MEAS_COND_AXIS_POSITION-11 "2/3deg"
*MEAS_COND_AXIS_POSITION-12 "2.2088000000"
*MEAS_COND_AXIS_POSITION-13 "-0.4140600000"
*MEAS_COND_AXIS_POSITION-14 "0.0000000000"
*MEAS_COND_AXIS_POSITION-15 "10.0mm"
*MEAS_COND_AXIS_POSITION-16 "None"
*MEAS_COND_AXIS_POSITION-17 "Cu_K-beta"
*MEAS_COND_AXIS_POSITION-18 "13.000mm"
*MEAS_COND_AXIS_POSITION-19 "13.000mm"
*MEAS_COND_AXIS_POSITION-20 "No_unit"
*MEAS_COND_AXIS_POSITION-21 "Soller_slit_5.0deg"
*MEAS_COND_AXIS_POSITION-22 "None"
*MEAS_COND_AXIS_POSITION-23 "13.0000000000"
*MEAS_COND_AXIS_POSITION-24 "13.0000000000"
*MEAS_COND_AXIS_POSITION-25 "0.0109400000"
*MEAS_COND_AXIS_POSITION-26 "Open"
*MEAS_COND_AXIS_POSITION-27 "None"
*MEAS_COND_AXIS_POSITION-28 "None"
*MEAS_COND_AXIS_POSITION-29 "None"
*MEAS_COND_AXIS_POSITION-30 "38.0000000000"
*MEAS_COND_AXIS_UNIT-0 "deg"
*MEAS_COND_AXIS_UNIT-1 "deg"
*MEAS_COND_AXIS_UNIT-2 "deg"
*MEAS_COND_AXIS_UNIT-3 "mm"
*MEAS_COND_AXIS_UNIT-4 "deg"
*MEAS_COND_AXIS_UNIT-5 "deg"
*MEAS_COND_AXIS_UNIT-6 "deg"
*MEAS_COND_AXIS_UNIT-7 "mm"
*MEAS_COND_AXIS_UNIT-8 ""
*MEAS_COND_AXIS_UNIT-9 "pulse"
*MEAS_COND_AXIS_UNIT-10 ""
*MEAS_COND_AXIS_UNIT-11 ""
*MEAS_COND_AXIS_UNIT-12 "mm"
*MEAS_COND_AXIS_UNIT-13 "mm"
*MEAS_COND_AXIS_UNIT-14 ""
*MEAS_COND_AXIS_UNIT-15 ""
*MEAS_COND_AXIS_UNIT-16 ""
*MEAS_COND_AXIS_UNIT-17 ""
*MEAS_COND_AXIS_UNIT-18 ""
*MEAS_COND_AXIS_UNIT-19 ""
*MEAS_COND_AXIS_UNIT-20 ""
*MEAS_COND_AXIS_UNIT-21 ""
*MEAS_COND_AXIS_UNIT-22 ""
*MEAS_COND_AXIS_UNIT-23 "mm"
*MEAS_COND_AXIS_UNIT-24 "mm"
*MEAS_COND_AXIS_UNIT-25 "mm"
*MEAS_COND_AXIS_UNIT-26 ""
*MEAS_COND_AXIS_UNIT-27 ""
*MEAS_COND_AXIS_UNIT-28 ""
*MEAS_COND_AXIS_UNIT-29 ""
*MEAS_COND_AXIS_UNIT-30 "div"
*MEAS_COND_COUNTER_CNTLOSS_CORR "0.0000000000"
*MEAS_COND_COUNTER_PHABASE "38.0000000000"
*MEAS_COND_COUNTER_PHAWINDOW "16.0000000000"
*MEAS_COND_COUNTER_PHA_UNIT "div"
*MEAS_COND_COUNTER_TAUDIFF "30.0000000000"
*MEAS_COND_COUNTER_TAUINT "0.0000000000"
*MEAS_COND_IRRADIATION_MODE "OFF"
*MEAS_COND_IRRADIATION_WIDTH ""
*MEAS_COND_OPT_ATTR "集中法"
*MEAS_COND_OPT_NAME "@集中法"
*MEAS_COND_UNSYMMETRIC_MODE "OFF"
*MEAS_COND_XG_CURRENT "30.0000000000"
*MEAS_COND_XG_VOLTAGE "40.0000000000"
*MEAS_COND_XG_WAVE_TYPE "Ka"
*MEAS_DATA_COUNT "5001.0000000000"
*MEAS_SCAN_AXIS_X "2θ/θ"
*MEAS_SCAN_AXIS_X_INTERNAL "TwoThetaTheta"
*MEAS_SCAN_END_TIME "06/30/21 16:13:01"
*MEAS_SCAN_MODE "CONTINUOUS"
*MEAS_SCAN_MONITOR "0"
*MEAS_SCAN_RESOLUTION_X "0.0002"
*MEAS_SCAN_SPEED "1.0"
*MEAS_SCAN_SPEED_UNIT "deg/min"
*MEAS_SCAN_START "20.0000000000"
*MEAS_SCAN_START_TIME "06/30/21 15:20:07"
*MEAS_SCAN_STEP "0.0100000000"
*MEAS_SCAN_STOP "70.0000000000"
*MEAS_SCAN_UNIT_X "deg"
*MEAS_SCAN_UNIT_Y "counts"
*RAS_HEADER_END
*RAS_INT_START
20.0000 1580.0000 1.0000
20.0400 1571.0000 1.0000
20.0800 1587.0000 1.0000
20.1200 1517.0000 1.0000
20.1600 1584.0000 1.0000
20.2000 1574.0000 1.0000
20.2400 1525.0000 1.0000
20.2800 1582.0000 1.0000
20.3200 1545.0000 1.0000
20.3600 1511.0000 1.0000
20.4000 1492.0000 1.0000
20.4400 1526.0000 1.0000
20.4800 1482.0000 1.0000
20.5200 1532.0000 1.0000
20.5600 1519.0000 1.0000
20.6000 1552.0000 1.0000
20.6400 1505.0000 1.0000
20.6800 1540.0000 1.0000
20.7200 1542.0000 1.0000
20.7600 1518.0000 1.0000
20.8000 1546.0000 1.0000
20.8400 1502.0000 1.0000
20.8800 1497.0000 1.0000
20.9200 1568.0000 1.0000
20.9600 1525.0000 1.0000
21.0000 1538.0000 1.0000
21.0400 1498.0000 1.0000
21.0800 1593.0000 1.0000
21.1200 1615.0000 1.0000
21.1600 1528.0000 1.0000
21.2000 1488.0000 1.0000
21.2400 1536.0000 1.0000
21.2800 1519.0000 1.0000
21.3200 1505.0000 1.0000
21.3600 1512.0000 1.0000
21.4000 1559.0000 1.0000
21.4400 1642.0000 1.0000
21.4800 1582.0000 1.0000
21.5200 1555.0000 1.0000
21.5600 1557.0000 1.0000
21.6000 1533.0000 1.0000
21.6400 1591.0000 1.0000
21.6800 1480.0000 1.0000
21.7200 1551.0000 1.0000
21.7600 1497.0000 1.0000
21.8000 1552.0000 1.0000
21.8400 1557.0000 1.0000
21.8800 1570.0000 1.0000
21.9200 1519.0000 1.0000
21.9600 1507.0000 1.0000
22.0000 1602.0000 1.0000
22.0400 1556.0000 1.0000
22.0800 1554.0000 1.0000
22.1200 1547.0000 1.0000
22.1600 1500.0000 1.0000
22.2000 1617.0000 1.0000
22.2400 1592.0000 1.0000
22.2800 1513.0000 1.0000
22.3200 1590.0000 1.0000
22.3600 1629.0000 1.0000
22.4000 1565.0000 1.0000
22.4400 1591.0000 1.0000
22.4800 1521.0000 1.0000
22.5200 1576.0000 1.0000
22.5600 1528.0000 1.0000
22.6000 1510.0000 1.0000
22.6400 1574.0000 1.0000
22.6800 1612.0000 1.0000
22.7200 1579.0000 1.0000
22.7600 1666.0000 1.0000
22.8000 1569.0000 1.0000
22.8400 1569.0000 1.0000
22.8800 1596.0000 1.0000
22.9200 1612.0000 1.0000
22.9600 1489.0000 1.0000
23.0000 1595.0000 1.0000
23.0400 1543.0000 1.0000
23.0800 1556.0000 1.0000
23.1200 1549.0000 1.0000
23.1600 1607.0000 1.0000
23.2000 1548.0000 1.0000
23.2400 1543.0000 1.0000
23.2800 1522.0000 1.0000
23.3200 1578.0000 1.0000
23.3600 1574.0000 1.0000
23.4000 1624.0000 1.0000
23.4400 1524.0000 1.0000
23.4800 1529.0000 1.0000
23.5200 1575.0000 1.0000
23.5600 1618.0000 1.0000
23.6000 1599.0000 1.0000
23.6400 1558.0000 1.0000
23.6800 1710.0000 1.0000
23.7200 1582.0000 1.0000
23.7600 1695.0000 1.0000
23.8000 1630.0000 1.0000
23.8400 1480.0000 1.0000
23.8800 1587.0000 1.0000
23.9200 1641.0000 1.0000
23.9600 1567.0000 1.0000
24.0000 1561.0000 1.0000
24.0400 1610.0000 1.0000
24.0800 1581.0000 1.0000
24.1200 1608.0000 1.0000
24.1600 1632.0000 1.0000
24.2000 1576.0000 1.0000
24.2400 1647.0000 1.0000
24.2800 1674.0000 1.0000
24.3200 1625.0000 1.0000
24.3600 1638.0000 1.0000
24.4000 1605.0000 1.0000
24.4400 1536.0000 1.0000
24.4800 1543.0000 1.0000
24.5200 1588.0000 1.0000
24.5600 1603.0000 1.0000
24.6000 1633.0000 1.0000
24.6400 1646.0000 1.0000
24.6800 1619.0000 1.0000
24.7200 1695.0000 1.0000
24.7600 1622.0000 1.0000
24.8000 1601.0000 1.0000
24.8400 1654.0000 1.0000
24.8800 1673.0000 1.0000
24.9200 1713.0000 1.0000
24.9600 1679.0000 1.0000
25.0000 1667.0000 1.0000
25.0400 1740.0000 1.0000
25.0800 1674.0000 1.0000
25.1200 1805.0000 1.0000
25.1600 1707.0000 1.0000
25.2000 1700.0000 1.0000
25.2400 1748.0000 1.0000
25.2800 1682.0000 1.0000
25.3200 1665.0000 1.0000
25.3600 1647.0000 1.0000
25.4000 1715.0000 1.0000
25.4400 1670.0000 1.0000
25.4800 1706.0000 1.0000
25.5200 1685.0000 1.0000
25.5600 1632.0000 1.0000
25.6000 1639.0000 1.0000
25.6400 1662.0000 1.0000
25.6800 1707.0000 1.0000
25.7200 1622.0000 1.0000
25.7600 1633.0000 1.0000
25.8000 1716.0000 1.0000
25.8400 1628.0000 1.0000
25.8800 1639.0000 1.0000
25.9200 1644.0000 1.0000
25.9600 1641.0000 1.0000
26.0000 1575.0000 1.0000
26.0400 1739.0000 1.0000
26.0800 1622.0000 1.0000
26.1200 1681.0000 1.0000
26.1600 1636.0000 1.0000
26.2000 1654.0000 1.0000
26.2400 1700.0000 1.0000
26.2800 1680.0000 1.0000
26.3200 1631.0000 1.0000
26.3600 1743.0000 1.0000
26.4000 1683.0000 1.0000
26.4400 1754.0000 1.0000
26.4800 1717.0000 1.0000
26.5200 1781.0000 1.0000
26.5600 1690.0000 1.0000
26.6000 1719.0000 1.0000
26.6400 1792.0000 1.0000
26.6800 1758.0000 1.0000
26.7200 1809.0000 1.0000
26.7600 1807.0000 1.0000
26.8000 1759.0000 1.0000
26.8400 1938.0000 1.0000
26.8800 1844.0000 1.0000
26.9200 1907.0000 1.0000
26.9600 1949.0000 1.0000
27.0000 2106.0000 1.0000
27.0400 2132.0000 1.0000
27.0800 2370.0000 1.0000
27.1200 2649.0000 1.0000
27.1600 2982.0000 1.0000
27.2000 3550.0000 1.0000
27.2400 4192.0000 1.0000
27.2800 5044.0000 1.0000
27.3200 6041.0000 1.0000
27.3600 6572.0000 1.0000
27.4000 5956.0000 1.0000
27.4400 5091.0000 1.0000
27.4800 4216.0000 1.0000
27.5200 3508.0000 1.0000
27.5600 2970.0000 1.0000
27.6000 2611.0000 1.0000
27.6400 2271.0000 1.0000
27.6800 2245.0000 1.0000
27.7200 2103.0000 1.0000
27.7600 2025.0000 1.0000
27.8000 1942.0000 1.0000
27.8400 1993.0000 1.0000
27.8800 1882.0000 1.0000
27.9200 1818.0000 1.0000
27.9600 1819.0000 1.0000
28.0000 1732.0000 1.0000
28.0400 1765.0000 1.0000
28.0800 1705.0000 1.0000
28.1200 1695.0000 1.0000
28.1600 1665.0000 1.0000
28.2000 1727.0000 1.0000
28.2400 1725.0000 1.0000
28.2800 1698.0000 1.0000
28.3200 1723.0000 1.0000
28.3600 1641.0000 1.0000
28.4000 1653.0000 1.0000
28.4400 1653.0000 1.0000
28.4800 1623.0000 1.0000
28.5200 1670.0000 1.0000
28.5600 1667.0000 1.0000
28.6000 1614.0000 1.0000
28.6400 1634.0000 1.0000
28.6800 1603.0000 1.0000
28.7200 1550.0000 1.0000
28.7600 1540.0000 1.0000
28.8000 1621.0000 1.0000
28.8400 1545.0000 1.0000
28.8800 1573.0000 1.0000
28.9200 1596.0000 1.0000
28.9600 1650.0000 1.0000
29.0000 1570.0000 1.0000
29.0400 1633.0000 1.0000
29.0800 1624.0000 1.0000
29.1200 1604.0000 1.0000
29.1600 1627.0000 1.0000
29.2000 1553.0000 1.0000
29.2400 1663.0000 1.0000
29.2800 1563.0000 1.0000
29.3200 1597.0000 1.0000
29.3600 1624.0000 1.0000
29.4000 1557.0000 1.0000
29.4400 1587.0000 1.0000
29.4800 1600.0000 1.0000
29.5200 1513.0000 1.0000
29.5600 1536.0000 1.0000
29.6000 1542.0000 1.0000
29.6400 1511.0000 1.0000
29.6800 1543.0000 1.0000
29.7200 1549.0000 1.0000
29.7600 1511.0000 1.0000
29.8000 1570.0000 1.0000
29.8400 1532.0000 1.0000
29.8800 1546.0000 1.0000
29.9200 1515.0000 1.0000
29.9600 1530.0000 1.0000
30.0000 1552.0000 1.0000
30.0400 1503.0000 1.0000
30.0800 1538.0000 1.0000
30.1200 1529.0000 1.0000
30.1600 1498.0000 1.0000
30.2000 1525.0000 1.0000
30.2400 1508.0000 1.0000
30.2800 1584.0000 1.0000
30.3200 1572.0000 1.0000
30.3600 1491.0000 1.0000
30.4000 1513.0000 1.0000
30.4400 1489.0000 1.0000
30.4800 1510.0000 1.0000
30.5200 1482.0000 1.0000
30.5600 1483.0000 1.0000
30.6000 1536.0000 1.0000
30.6400 1535.0000 1.0000
30.6800 1511.0000 1.0000
30.7200 1518.0000 1.0000
30.7600 1490.0000 1.0000
30.8000 1531.0000 1.0000
30.8400 1497.0000 1.0000
30.8800 1454.0000 1.0000
30.9200 1466.0000 1.0000
30.9600 1508.0000 1.0000
31.0000 1472.0000 1.0000
31.0400 1411.0000 1.0000
31.0800 1523.0000 1.0000
31.1200 1527.0000 1.0000
31.1600 1501.0000 1.0000
31.2000 1487.0000 1.0000
31.2400 1520.0000 1.0000
31.2800 1474.0000 1.0000
31.3200 1518.0000 1.0000
31.3600 1511.0000 1.0000
31.4000 1412.0000 1.0000
31.4400 1469.0000 1.0000
31.4800 1453.0000 1.0000
31.5200 1462.0000 1.0000
31.5600 1461.0000 1.0000
31.6000 1487.0000 1.0000
31.6400 1511.0000 1.0000
31.6800 1482.0000 1.0000
31.7200 1451.0000 1.0000
31.7600 1450.0000 1.0000
31.8000 1501.0000 1.0000
31.8400 1428.0000 1.0000
31.8800 1455.0000 1.0000
31.9200 1415.0000 1.0000
31.9600 1523.0000 1.0000
32.0000 1480.0000 1.0000
32.0400 1500.0000 1.0000
32.0800 1482.0000 1.0000
32.1200 1456.0000 1.0000
32.1600 1449.0000 1.0000
32.2000 1462.0000 1.0000
32.2400 1443.0000 1.0000
32.2800 1381.0000 1.0000
32.3200 1437.0000 1.0000
32.3600 1418.0000 1.0000
32.4000 1398.0000 1.0000
32.4400 1368.0000 1.0000
32.4800 1405.0000 1.0000
32.5200 1377.0000 1.0000
32.5600 1351.0000 1.0000
32.6000 1350.0000 1.0000
32.6400 1419.0000 1.0000
32.6800 1376.0000 1.0000
32.7200 1402.0000 1.0000
32.7600 1408.0000 1.0000
32.8000 1384.0000 1.0000
32.8400 1336.0000 1.0000
32.8800 1331.0000 1.0000
32.9200 1343.0000 1.0000
32.9600 1333.0000 1.0000
33.0000 1396.0000 1.0000
33.0400 1374.0000 1.0000
33.0800 1389.0000 1.0000
33.1200 1344.0000 1.0000
33.1600 1375.0000 1.0000
33.2000 1365.0000 1.0000
33.2400 1315.0000 1.0000
33.2800 1389.0000 1.0000
33.3200 1353.0000 1.0000
33.3600 1333.0000 1.0000
33.4000 1293.0000 1.0000
33.4400 1382.0000 1.0000
33.4800 1422.0000 1.0000
33.5200 1389.0000 1.0000
33.5600 1387.0000 1.0000
33.6000 1338.0000 1.0000
33.6400 1361.0000 1.0000
33.6800 1361.0000 1.0000
33.7200 1352.0000 1.0000
33.7600 1368.0000 1.0000
33.8000 1402.0000 1.0000
33.8400 1432.0000 1.0000
33.8800 1493.0000 1.0000
33.9200 1560.0000 1.0000
33.9600 1518.0000 1.0000
34.0000 1710.0000 1.0000
34.0400 1595.0000 1.0000
34.0800 1537.0000 1.0000
34.1200 1501.0000 1.0000
34.1600 1537.0000 1.0000
34.2000 1536.0000 1.0000
34.2400 1577.0000 1.0000
34.2800 1628.0000 1.0000
34.3200 1790.0000 1.0000
34.3600 1809.0000 1.0000
34.4000 2074.0000 1.0000
34.4400 2407.0000 1.0000
34.4800 2847.0000 1.0000
34.5200 3112.0000 1.0000
34.5600 3234.0000 1.0000
34.6000 3047.0000 1.0000
34.6400 2763.0000 1.0000
34.6800 2371.0000 1.0000
34.7200 2165.0000 1.0000
34.7600 1834.0000 1.0000
34.8000 1741.0000 1.0000
34.8400 1664.0000 1.0000
34.8800 1570.0000 1.0000
34.9200 1494.0000 1.0000
34.9600 1424.0000 1.0000
35.0000 1401.0000 1.0000
35.0400 1357.0000 1.0000
35.0800 1230.0000 1.0000
35.1200 1309.0000 1.0000
35.1600 1302.0000 1.0000
35.2000 1300.0000 1.0000
35.2400 1322.0000 1.0000
35.2800 1291.0000 1.0000
35.3200 1246.0000 1.0000
35.3600 1233.0000 1.0000
35.4000 1220.0000 1.0000
35.4400 1214.0000 1.0000
35.4800 1196.0000 1.0000
35.5200 1196.0000 1.0000
35.5600 1232.0000 1.0000
35.6000 1194.0000 1.0000
35.6400 1193.0000 1.0000
35.6800 1177.0000 1.0000
35.7200 1203.0000 1.0000
35.7600 1153.0000 1.0000
35.8000 1154.0000 1.0000
35.8400 1187.0000 1.0000
35.8800 1182.0000 1.0000
35.9200 1195.0000 1.0000
35.9600 1139.0000 1.0000
36.0000 1141.0000 1.0000
36.0400 1162.0000 1.0000
36.0800 1198.0000 1.0000
36.1200 1201.0000 1.0000
36.1600 1179.0000 1.0000
36.2000 1288.0000 1.0000
36.2400 1252.0000 1.0000
36.2800 1321.0000 1.0000
36.3200 1413.0000 1.0000
36.3600 1589.0000 1.0000
36.4000 1857.0000 1.0000
36.4400 2188.0000 1.0000
36.4800 2108.0000 1.0000
36.5200 1962.0000 1.0000
36.5600 1733.0000 1.0000
36.6000 1452.0000 1.0000
36.6400 1339.0000 1.0000
36.6800 1192.0000 1.0000
36.7200 1157.0000 1.0000
36.7600 1130.0000 1.0000
36.8000 1099.0000 1.0000
36.8400 1116.0000 1.0000
36.8800 1121.0000 1.0000
36.9200 1097.0000 1.0000
36.9600 1072.0000 1.0000
37.0000 1065.0000 1.0000
37.0400 1079.0000 1.0000
37.0800 1104.0000 1.0000
37.1200 1100.0000 1.0000
37.1600 1121.0000 1.0000
37.2000 1039.0000 1.0000
37.2400 1083.0000 1.0000
37.2800 1095.0000 1.0000
37.3200 1127.0000 1.0000
37.3600 1061.0000 1.0000
37.4000 1099.0000 1.0000
37.4400 1077.0000 1.0000
37.4800 1085.0000 1.0000
37.5200 1038.0000 1.0000
37.5600 1081.0000 1.0000
37.6000 1087.0000 1.0000
37.6400 1025.0000 1.0000
37.6800 1106.0000 1.0000
37.7200 1130.0000 1.0000
37.7600 1066.0000 1.0000
37.8000 1064.0000 1.0000
37.8400 1097.0000 1.0000
37.8800 1122.0000 1.0000
37.9200 1066.0000 1.0000
37.9600 1071.0000 1.0000
38.0000 1144.0000 1.0000
38.0400 1151.0000 1.0000
38.0800 1143.0000 1.0000
38.1200 1206.0000 1.0000
38.1600 1249.0000 1.0000
38.2000 1299.0000 1.0000
38.2400 1531.0000 1.0000
38.2800 1586.0000 1.0000
38.3200 1810.0000 1.0000
38.3600 2062.0000 1.0000
38.4000 2591.0000 1.0000
38.4400 3195.0000 1.0000
38.4800 4174.0000 1.0000
38.5200 5395.0000 1.0000
38.5600 6599.0000 1.0000
38.6000 7036.0000 1.0000
38.6400 6860.0000 1.0000
38.6800 5940.0000 1.0000
38.7200 4762.0000 1.0000
38.7600 3541.0000 1.0000
38.8000 2832.0000 1.0000
38.8400 2140.0000 1.0000
38.8800 1773.0000 1.0000
38.9200 1583.0000 1.0000
38.9600 1356.0000 1.0000
39.0000 1239.0000 1.0000
39.0400 1147.0000 1.0000
39.0800 1111.0000 1.0000
39.1200 1061.0000 1.0000
39.1600 1037.0000 1.0000
39.2000 1041.0000 1.0000
39.2400 1054.0000 1.0000
39.2800 1030.0000 1.0000
39.3200 980.0000 1.0000
39.3600 1017.0000 1.0000
39.4000 1043.0000 1.0000
39.4400 1018.0000 1.0000
39.4800 1000.0000 1.0000
39.5200 989.0000 1.0000
39.5600 999.0000 1.0000
39.6000 1053.0000 1.0000
39.6400 1012.0000 1.0000
39.6800 1036.0000 1.0000
39.7200 995.0000 1.0000
39.7600 1018.0000 1.0000
39.8000 957.0000 1.0000
39.8400 960.0000 1.0000
39.8800 936.0000 1.0000
39.9200 966.0000 1.0000
39.9600 929.0000 1.0000
40.0000 928.0000 1.0000
40.0400 896.0000 1.0000
40.0800 987.0000 1.0000
40.1200 973.0000 1.0000
40.1600 957.0000 1.0000
40.2000 931.0000 1.0000
40.2400 912.0000 1.0000
40.2800 927.0000 1.0000
40.3200 926.0000 1.0000
40.3600 873.0000 1.0000
40.4000 883.0000 1.0000
40.4400 959.0000 1.0000
40.4800 901.0000 1.0000
40.5200 892.0000 1.0000
40.5600 898.0000 1.0000
40.6000 886.0000 1.0000
40.6400 892.0000 1.0000
40.6800 864.0000 1.0000
40.7200 884.0000 1.0000
40.7600 911.0000 1.0000
40.8000 850.0000 1.0000
40.8400 895.0000 1.0000
40.8800 892.0000 1.0000
40.9200 885.0000 1.0000
40.9600 889.0000 1.0000
41.0000 911.0000 1.0000
41.0400 847.0000 1.0000
41.0800 868.0000 1.0000
41.1200 904.0000 1.0000
41.1600 908.0000 1.0000
41.2000 839.0000 1.0000
41.2400 902.0000 1.0000
41.2800 879.0000 1.0000
41.3200 903.0000 1.0000
41.3600 839.0000 1.0000
41.4000 879.0000 1.0000
41.4400 835.0000 1.0000
41.4800 893.0000 1.0000
41.5200 840.0000 1.0000
41.5600 888.0000 1.0000
41.6000 908.0000 1.0000
41.6400 919.0000 1.0000
41.6800 939.0000 1.0000
41.7200 889.0000 1.0000
41.7600 894.0000 1.0000
41.8000 885.0000 1.0000
41.8400 944.0000 1.0000
41.8800 860.0000 1.0000
41.9200 876.0000 1.0000
41.9600 876.0000 1.0000
42.0000 894.0000 1.0000
42.0400 844.0000 1.0000
42.0800 862.0000 1.0000
42.1200 888.0000 1.0000
42.1600 918.0000 1.0000
42.2000 851.0000 1.0000
42.2400 852.0000 1.0000
42.2800 885.0000 1.0000
42.3200 859.0000 1.0000
42.3600 893.0000 1.0000
42.4000 864.0000 1.0000
42.4400 897.0000 1.0000
42.4800 837.0000 1.0000
42.5200 865.0000 1.0000
42.5600 858.0000 1.0000
42.6000 866.0000 1.0000
42.6400 890.0000 1.0000
42.6800 897.0000 1.0000
42.7200 893.0000 1.0000
42.7600 893.0000 1.0000
42.8000 876.0000 1.0000
42.8400 894.0000 1.0000
42.8800 876.0000 1.0000
42.9200 873.0000 1.0000
42.9600 886.0000 1.0000
43.0000 859.0000 1.0000
43.0400 892.0000 1.0000
43.0800 873.0000 1.0000
43.1200 911.0000 1.0000
43.1600 906.0000 1.0000
43.2000 913.0000 1.0000
43.2400 930.0000 1.0000
43.2800 912.0000 1.0000
43.3200 995.0000 1.0000
43.3600 929.0000 1.0000
43.4000 885.0000 1.0000
43.4400 931.0000 1.0000
43.4800 891.0000 1.0000
43.5200 886.0000 1.0000
43.5600 860.0000 1.0000
43.6000 873.0000 1.0000
43.6400 858.0000 1.0000
43.6800 852.0000 1.0000
43.7200 868.0000 1.0000
43.7600 892.0000 1.0000
43.8000 923.0000 1.0000
43.8400 832.0000 1.0000
43.8800 854.0000 1.0000
43.9200 852.0000 1.0000
43.9600 859.0000 1.0000
44.0000 808.0000 1.0000
44.0400 818.0000 1.0000
44.0800 848.0000 1.0000
44.1200 839.0000 1.0000
44.1600 828.0000 1.0000
44.2000 799.0000 1.0000
44.2400 816.0000 1.0000
44.2800 842.0000 1.0000
44.3200 863.0000 1.0000
44.3600 888.0000 1.0000
44.4000 842.0000 1.0000
44.4400 856.0000 1.0000
44.4800 837.0000 1.0000
44.5200 832.0000 1.0000
44.5600 807.0000 1.0000
44.6000 814.0000 1.0000
44.6400 804.0000 1.0000
44.6800 825.0000 1.0000
44.7200 822.0000 1.0000
44.7600 841.0000 1.0000
44.8000 819.0000 1.0000
44.8400 828.0000 1.0000
44.8800 779.0000 1.0000
44.9200 829.0000 1.0000
44.9600 860.0000 1.0000
45.0000 842.0000 1.0000
45.0400 789.0000 1.0000
45.0800 808.0000 1.0000
45.1200 839.0000 1.0000
45.1600 805.0000 1.0000
45.2000 830.0000 1.0000
45.2400 827.0000 1.0000
45.2800 815.0000 1.0000
45.3200 848.0000 1.0000
45.3600 820.0000 1.0000
45.4000 802.0000 1.0000
45.4400 764.0000 1.0000
45.4800 811.0000 1.0000
45.5200 820.0000 1.0000
45.5600 768.0000 1.0000
45.6000 785.0000 1.0000
45.6400 804.0000 1.0000
45.6800 777.0000 1.0000
45.7200 778.0000 1.0000
45.7600 797.0000 1.0000
45.8000 793.0000 1.0000
45.8400 773.0000 1.0000
45.8800 819.0000 1.0000
45.9200 760.0000 1.0000
45.9600 823.0000 1.0000
46.0000 746.0000 1.0000
46.0400 790.0000 1.0000
46.0800 755.0000 1.0000
46.1200 780.0000 1.0000
46.1600 739.0000 1.0000
46.2000 845.0000 1.0000
46.2400 812.0000 1.0000
46.2800 787.0000 1.0000
46.3200 811.0000 1.0000
46.3600 776.0000 1.0000
46.4000 798.0000 1.0000
46.4400 762.0000 1.0000
46.4800 803.0000 1.0000
46.5200 805.0000 1.0000
46.5600 804.0000 1.0000
46.6000 786.0000 1.0000
46.6400 807.0000 1.0000
46.6800 750.0000 1.0000
46.7200 744.0000 1.0000
46.7600 783.0000 1.0000
46.8000 735.0000 1.0000
46.8400 783.0000 1.0000
46.8800 836.0000 1.0000
46.9200 739.0000 1.0000
46.9600 762.0000 1.0000
47.0000 812.0000 1.0000
47.0400 844.0000 1.0000
47.0800 795.0000 1.0000
47.1200 798.0000 1.0000
47.1600 753.0000 1.0000
47.2000 784.0000 1.0000
47.2400 770.0000 1.0000
47.2800 793.0000 1.0000
47.3200 769.0000 1.0000
47.3600 770.0000 1.0000
47.4000 785.0000 1.0000
47.4400 765.0000 1.0000
47.4800 756.0000 1.0000
47.5200 748.0000 1.0000
47.5600 775.0000 1.0000
47.6000 804.0000 1.0000
47.6400 728.0000 1.0000
47.6800 734.0000 1.0000
47.7200 743.0000 1.0000
47.7600 721.0000 1.0000
47.8000 761.0000 1.0000
47.8400 766.0000 1.0000
47.8800 684.0000 1.0000
47.9200 751.0000 1.0000
47.9600 699.0000 1.0000
48.0000 738.0000 1.0000
48.0400 765.0000 1.0000
48.0800 737.0000 1.0000
48.1200 671.0000 1.0000
48.1600 729.0000 1.0000
48.2000 739.0000 1.0000
48.2400 746.0000 1.0000
48.2800 677.0000 1.0000
48.3200 735.0000 1.0000
48.3600 758.0000 1.0000
48.4000 751.0000 1.0000
48.4400 782.0000 1.0000
48.4800 763.0000 1.0000
48.5200 734.0000 1.0000
48.5600 746.0000 1.0000
48.6000 773.0000 1.0000
48.6400 773.0000 1.0000
48.6800 733.0000 1.0000
48.7200 766.0000 1.0000
48.7600 746.0000 1.0000
48.8000 725.0000 1.0000
48.8400 776.0000 1.0000
48.8800 793.0000 1.0000
48.9200 736.0000 1.0000
48.9600 703.0000 1.0000
49.0000 736.0000 1.0000
49.0400 760.0000 1.0000
49.0800 753.0000 1.0000
49.1200 752.0000 1.0000
49.1600 717.0000 1.0000
49.2000 732.0000 1.0000
49.2400 738.0000 1.0000
49.2800 746.0000 1.0000
49.3200 764.0000 1.0000
49.3600 729.0000 1.0000
49.4000 754.0000 1.0000
49.4400 697.0000 1.0000
49.4800 726.0000 1.0000
49.5200 711.0000 1.0000
49.5600 689.0000 1.0000
49.6000 740.0000 1.0000
49.6400 758.0000 1.0000
49.6800 735.0000 1.0000
49.7200 749.0000 1.0000
49.7600 715.0000 1.0000
49.8000 714.0000 1.0000
49.8400 687.0000 1.0000
49.8800 706.0000 1.0000
49.9200 724.0000 1.0000
49.9600 752.0000 1.0000
50.0000 717.0000 1.0000
50.0400 736.0000 1.0000
50.0800 705.0000 1.0000
50.1200 768.0000 1.0000
50.1600 700.0000 1.0000
50.2000 817.0000 1.0000
50.2400 742.0000 1.0000
50.2800 794.0000 1.0000
50.3200 744.0000 1.0000
50.3600 750.0000 1.0000
50.4000 783.0000 1.0000
50.4400 760.0000 1.0000
50.4800 765.0000 1.0000
50.5200 783.0000 1.0000
50.5600 743.0000 1.0000
50.6000 728.0000 1.0000
50.6400 733.0000 1.0000
50.6800 698.0000 1.0000
50.7200 781.0000 1.0000
50.7600 742.0000 1.0000
50.8000 774.0000 1.0000
50.8400 737.0000 1.0000
50.8800 742.0000 1.0000
50.9200 678.0000 1.0000
50.9600 738.0000 1.0000
51.0000 739.0000 1.0000
51.0400 731.0000 1.0000
51.0800 733.0000 1.0000
51.1200 705.0000 1.0000
51.1600 732.0000 1.0000
51.2000 712.0000 1.0000
51.2400 739.0000 1.0000
51.2800 733.0000 1.0000
51.3200 758.0000 1.0000
51.3600 665.0000 1.0000
51.4000 758.0000 1.0000
51.4400 772.0000 1.0000
51.4800 764.0000 1.0000
51.5200 741.0000 1.0000
51.5600 739.0000 1.0000
51.6000 729.0000 1.0000
51.6400 783.0000 1.0000
51.6800 786.0000 1.0000
51.7200 816.0000 1.0000
51.7600 811.0000 1.0000
51.8000 846.0000 1.0000
51.8400 814.0000 1.0000
51.8800 827.0000 1.0000
51.9200 911.0000 1.0000
51.9600 973.0000 1.0000
52.0000 1056.0000 1.0000
52.0400 1140.0000 1.0000
52.0800 1351.0000 1.0000
52.1200 1547.0000 1.0000
52.1600 1849.0000 1.0000
52.2000 2498.0000 1.0000
52.2400 3426.0000 1.0000
52.2800 4668.0000 1.0000
52.3200 5020.0000 1.0000
52.3600 4962.0000 1.0000
52.4000 4317.0000 1.0000
52.4400 4017.0000 1.0000
52.4800 3443.0000 1.0000
52.5200 2644.0000 1.0000
52.5600 2043.0000 1.0000
52.6000 1559.0000 1.0000
52.6400 1287.0000 1.0000
52.6800 1164.0000 1.0000
52.7200 1024.0000 1.0000
52.7600 957.0000 1.0000
52.8000 921.0000 1.0000
52.8400 869.0000 1.0000
52.8800 872.0000 1.0000
52.9200 878.0000 1.0000
52.9600 802.0000 1.0000
53.0000 815.0000 1.0000
53.0400 772.0000 1.0000
53.0800 774.0000 1.0000
53.1200 731.0000 1.0000
53.1600 811.0000 1.0000
53.2000 722.0000 1.0000
53.2400 785.0000 1.0000
53.2800 732.0000 1.0000
53.3200 763.0000 1.0000
53.3600 752.0000 1.0000
53.4000 731.0000 1.0000
53.4400 721.0000 1.0000
53.4800 776.0000 1.0000
53.5200 744.0000 1.0000
53.5600 731.0000 1.0000
53.6000 724.0000 1.0000
53.6400 723.0000 1.0000
53.6800 713.0000 1.0000
53.7200 682.0000 1.0000
53.7600 768.0000 1.0000
53.8000 733.0000 1.0000
53.8400 716.0000 1.0000
53.8800 726.0000 1.0000
53.9200 746.0000 1.0000
53.9600 708.0000 1.0000
54.0000 747.0000 1.0000
54.0400 720.0000 1.0000
54.0800 693.0000 1.0000
54.1200 715.0000 1.0000
54.1600 699.0000 1.0000
54.2000 700.0000 1.0000
54.2400 712.0000 1.0000
54.2800 729.0000 1.0000
54.3200 751.0000 1.0000
54.3600 708.0000 1.0000
54.4000 707.0000 1.0000
54.4400 749.0000 1.0000
54.4800 750.0000 1.0000
54.5200 767.0000 1.0000
54.5600 704.0000 1.0000
54.6000 720.0000 1.0000
54.6400 698.0000 1.0000
54.6800 721.0000 1.0000
54.7200 747.0000 1.0000
54.7600 794.0000 1.0000
54.8000 783.0000 1.0000
54.8400 816.0000 1.0000
54.8800 759.0000 1.0000
54.9200 755.0000 1.0000
54.9600 791.0000 1.0000
55.0000 802.0000 1.0000
55.0400 790.0000 1.0000
55.0800 838.0000 1.0000
55.1200 816.0000 1.0000
55.1600 875.0000 1.0000
55.2000 876.0000 1.0000
55.2400 1006.0000 1.0000
55.2800 1069.0000 1.0000
55.3200 1057.0000 1.0000
55.3600 1085.0000 1.0000
55.4000 1083.0000 1.0000
55.4400 1044.0000 1.0000
55.4800 1009.0000 1.0000
55.5200 967.0000 1.0000
55.5600 889.0000 1.0000
55.6000 875.0000 1.0000
55.6400 802.0000 1.0000
55.6800 762.0000 1.0000
55.7200 734.0000 1.0000
55.7600 755.0000 1.0000
55.8000 723.0000 1.0000
55.8400 737.0000 1.0000
55.8800 712.0000 1.0000
55.9200 730.0000 1.0000
55.9600 713.0000 1.0000
56.0000 734.0000 1.0000
56.0400 704.0000 1.0000
56.0800 686.0000 1.0000
56.1200 708.0000 1.0000
56.1600 687.0000 1.0000
56.2000 694.0000 1.0000
56.2400 687.0000 1.0000
56.2800 677.0000 1.0000
56.3200 748.0000 1.0000
56.3600 643.0000 1.0000
56.4000 675.0000 1.0000
56.4400 692.0000 1.0000
56.4800 706.0000 1.0000
56.5200 699.0000 1.0000
56.5600 706.0000 1.0000
56.6000 738.0000 1.0000
56.6400 629.0000 1.0000
56.6800 697.0000 1.0000
56.7200 698.0000 1.0000
56.7600 700.0000 1.0000
56.8000 686.0000 1.0000
56.8400 665.0000 1.0000
56.8800 657.0000 1.0000
56.9200 680.0000 1.0000
56.9600 656.0000 1.0000
57.0000 698.0000 1.0000
57.0400 678.0000 1.0000
57.0800 693.0000 1.0000
57.1200 675.0000 1.0000
57.1600 713.0000 1.0000
57.2000 680.0000 1.0000
57.2400 670.0000 1.0000
57.2800 676.0000 1.0000
57.3200 693.0000 1.0000
57.3600 680.0000 1.0000
57.4000 690.0000 1.0000
57.4400 716.0000 1.0000
57.4800 699.0000 1.0000
57.5200 745.0000 1.0000
57.5600 663.0000 1.0000
57.6000 643.0000 1.0000
57.6400 661.0000 1.0000
57.6800 663.0000 1.0000
57.7200 686.0000 1.0000
57.7600 676.0000 1.0000
57.8000 707.0000 1.0000
57.8400 662.0000 1.0000
57.8800 666.0000 1.0000
57.9200 692.0000 1.0000
57.9600 666.0000 1.0000
58.0000 681.0000 1.0000
58.0400 666.0000 1.0000
58.0800 667.0000 1.0000
58.1200 671.0000 1.0000
58.1600 685.0000 1.0000
58.2000 690.0000 1.0000
58.2400 705.0000 1.0000
58.2800 698.0000 1.0000
58.3200 667.0000 1.0000
58.3600 733.0000 1.0000
58.4000 681.0000 1.0000
58.4400 691.0000 1.0000
58.4800 715.0000 1.0000
58.5200 678.0000 1.0000
58.5600 670.0000 1.0000
58.6000 691.0000 1.0000
58.6400 720.0000 1.0000
58.6800 712.0000 1.0000
58.7200 677.0000 1.0000
58.7600 701.0000 1.0000
58.8000 670.0000 1.0000
58.8400 715.0000 1.0000
58.8800 659.0000 1.0000
58.9200 680.0000 1.0000
58.9600 711.0000 1.0000
59.0000 688.0000 1.0000
59.0400 665.0000 1.0000
59.0800 738.0000 1.0000
59.1200 680.0000 1.0000
59.1600 714.0000 1.0000
59.2000 679.0000 1.0000
59.2400 699.0000 1.0000
59.2800 694.0000 1.0000
59.3200 692.0000 1.0000
59.3600 701.0000 1.0000
59.4000 714.0000 1.0000
59.4400 657.0000 1.0000
59.4800 687.0000 1.0000
59.5200 689.0000 1.0000
59.5600 678.0000 1.0000
59.6000 694.0000 1.0000
59.6400 682.0000 1.0000
59.6800 677.0000 1.0000
59.7200 684.0000 1.0000
59.7600 663.0000 1.0000
59.8000 666.0000 1.0000
59.8400 682.0000 1.0000
59.8800 674.0000 1.0000
59.9200 669.0000 1.0000
59.9600 689.0000 1.0000
60.0000 686.0000 1.0000
60.0400 705.0000 1.0000
60.0800 707.0000 1.0000
60.1200 678.0000 1.0000
60.1600 667.0000 1.0000
60.2000 682.0000 1.0000
60.2400 667.0000 1.0000
60.2800 685.0000 1.0000
60.3200 684.0000 1.0000
60.3600 644.0000 1.0000
60.4000 695.0000 1.0000
60.4400 649.0000 1.0000
60.4800 699.0000 1.0000
60.5200 687.0000 1.0000
60.5600 681.0000 1.0000
60.6000 694.0000 1.0000
60.6400 695.0000 1.0000
60.6800 697.0000 1.0000
60.7200 694.0000 1.0000
60.7600 687.0000 1.0000
60.8000 700.0000 1.0000
60.8400 663.0000 1.0000
60.8800 665.0000 1.0000
60.9200 678.0000 1.0000
60.9600 702.0000 1.0000
61.0000 674.0000 1.0000
61.0400 683.0000 1.0000
61.0800 661.0000 1.0000
61.1200 684.0000 1.0000
61.1600 681.0000 1.0000
61.2000 701.0000 1.0000
61.2400 705.0000 1.0000
61.2800 709.0000 1.0000
61.3200 678.0000 1.0000
61.3600 714.0000 1.0000
61.4000 692.0000 1.0000
61.4400 655.0000 1.0000
61.4800 714.0000 1.0000
61.5200 721.0000 1.0000
61.5600 685.0000 1.0000
61.6000 701.0000 1.0000
61.6400 696.0000 1.0000
61.6800 684.0000 1.0000
61.7200 715.0000 1.0000
61.7600 723.0000 1.0000
61.8000 727.0000 1.0000
61.8400 754.0000 1.0000
61.8800 745.0000 1.0000
61.9200 782.0000 1.0000
61.9600 791.0000 1.0000
62.0000 829.0000 1.0000
62.0400 836.0000 1.0000
62.0800 877.0000 1.0000
62.1200 1007.0000 1.0000
62.1600 1096.0000 1.0000
62.2000 1227.0000 1.0000
62.2400 1296.0000 1.0000
62.2800 1457.0000 1.0000
62.3200 1571.0000 1.0000
62.3600 1613.0000 1.0000
62.4000 1624.0000 1.0000
62.4400 1580.0000 1.0000
62.4800 1484.0000 1.0000
62.5200 1382.0000 1.0000
62.5600 1321.0000 1.0000
62.6000 1227.0000 1.0000
62.6400 1083.0000 1.0000
62.6800 1023.0000 1.0000
62.7200 879.0000 1.0000
62.7600 860.0000 1.0000
62.8000 889.0000 1.0000
62.8400 828.0000 1.0000
62.8800 795.0000 1.0000
62.9200 793.0000 1.0000
62.9600 785.0000 1.0000
63.0000 771.0000 1.0000
63.0400 770.0000 1.0000
63.0800 737.0000 1.0000
63.1200 764.0000 1.0000
63.1600 733.0000 1.0000
63.2000 797.0000 1.0000
63.2400 758.0000 1.0000
63.2800 701.0000 1.0000
63.3200 716.0000 1.0000
63.3600 763.0000 1.0000
63.4000 680.0000 1.0000
63.4400 684.0000 1.0000
63.4800 653.0000 1.0000
63.5200 696.0000 1.0000
63.5600 722.0000 1.0000
63.6000 684.0000 1.0000
63.6400 668.0000 1.0000
63.6800 685.0000 1.0000
63.7200 692.0000 1.0000
63.7600 674.0000 1.0000
63.8000 724.0000 1.0000
63.8400 691.0000 1.0000
63.8800 691.0000 1.0000
63.9200 653.0000 1.0000
63.9600 714.0000 1.0000
64.0000 696.0000 1.0000
64.0400 678.0000 1.0000
64.0800 714.0000 1.0000
64.1200 719.0000 1.0000
64.1600 664.0000 1.0000
64.2000 699.0000 1.0000
64.2400 755.0000 1.0000
64.2800 695.0000 1.0000
64.3200 676.0000 1.0000
64.3600 667.0000 1.0000
64.4000 699.0000 1.0000
64.4400 701.0000 1.0000
64.4800 697.0000 1.0000
64.5200 722.0000 1.0000
64.5600 734.0000 1.0000
64.6000 770.0000 1.0000
64.6400 756.0000 1.0000
64.6800 878.0000 1.0000
64.7200 908.0000 1.0000
64.7600 912.0000 1.0000
64.8000 855.0000 1.0000
64.8400 837.0000 1.0000
64.8800 808.0000 1.0000
64.9200 869.0000 1.0000
64.9600 764.0000 1.0000
65.0000 780.0000 1.0000
65.0400 743.0000 1.0000
65.0800 763.0000 1.0000
65.1200 751.0000 1.0000
65.1600 733.0000 1.0000
65.2000 667.0000 1.0000
65.2400 716.0000 1.0000
65.2800 716.0000 1.0000
65.3200 706.0000 1.0000
65.3600 678.0000 1.0000
65.4000 676.0000 1.0000
65.4400 665.0000 1.0000
65.4800 692.0000 1.0000
65.5200 756.0000 1.0000
65.5600 708.0000 1.0000
65.6000 717.0000 1.0000
65.6400 761.0000 1.0000
65.6800 694.0000 1.0000
65.7200 735.0000 1.0000
65.7600 769.0000 1.0000
65.8000 805.0000 1.0000
65.8400 814.0000 1.0000
65.8800 828.0000 1.0000
65.9200 866.0000 1.0000
65.9600 948.0000 1.0000
66.0000 938.0000 1.0000
66.0400 969.0000 1.0000
66.0800 1147.0000 1.0000
66.1200 1297.0000 1.0000
66.1600 1506.0000 1.0000
66.2000 1825.0000 1.0000
66.2400 2265.0000 1.0000
66.2800 2589.0000 1.0000
66.3200 2849.0000 1.0000
66.3600 2652.0000 1.0000
66.4000 2388.0000 1.0000
66.4400 2320.0000 1.0000
66.4800 2180.0000 1.0000
66.5200 2009.0000 1.0000
66.5600 1718.0000 1.0000
66.6000 1449.0000 1.0000
66.6400 1225.0000 1.0000
66.6800 1103.0000 1.0000
66.7200 1034.0000 1.0000
66.7600 887.0000 1.0000
66.8000 866.0000 1.0000
66.8400 838.0000 1.0000
66.8800 786.0000 1.0000
66.9200 768.0000 1.0000
66.9600 730.0000 1.0000
67.0000 699.0000 1.0000
67.0400 725.0000 1.0000
67.0800 693.0000 1.0000
67.1200 663.0000 1.0000
67.1600 684.0000 1.0000
67.2000 721.0000 1.0000
67.2400 654.0000 1.0000
67.2800 670.0000 1.0000
67.3200 667.0000 1.0000
67.3600 625.0000 1.0000
67.4000 647.0000 1.0000
67.4400 642.0000 1.0000
67.4800 652.0000 1.0000
67.5200 660.0000 1.0000
67.5600 652.0000 1.0000
67.6000 674.0000 1.0000
67.6400 668.0000 1.0000
67.6800 616.0000 1.0000
67.7200 635.0000 1.0000
67.7600 636.0000 1.0000
67.8000 599.0000 1.0000
67.8400 639.0000 1.0000
67.8800 644.0000 1.0000
67.9200 630.0000 1.0000
67.9600 623.0000 1.0000
68.0000 657.0000 1.0000
68.0400 617.0000 1.0000
68.0800 613.0000 1.0000
68.1200 644.0000 1.0000
68.1600 608.0000 1.0000
68.2000 652.0000 1.0000
68.2400 639.0000 1.0000
68.2800 604.0000 1.0000
68.3200 635.0000 1.0000
68.3600 622.0000 1.0000
68.4000 613.0000 1.0000
68.4400 600.0000 1.0000
68.4800 642.0000 1.0000
68.5200 602.0000 1.0000
68.5600 636.0000 1.0000
68.6000 617.0000 1.0000
68.6400 597.0000 1.0000
68.6800 626.0000 1.0000
68.7200 574.0000 1.0000
68.7600 581.0000 1.0000
68.8000 618.0000 1.0000
68.8400 547.0000 1.0000
68.8800 654.0000 1.0000
68.9200 622.0000 1.0000
68.9600 619.0000 1.0000
69.0000 588.0000 1.0000
69.0400 622.0000 1.0000
69.0800 650.0000 1.0000
69.1200 619.0000 1.0000
69.1600 620.0000 1.0000
69.2000 600.0000 1.0000
69.2400 591.0000 1.0000
69.2800 591.0000 1.0000
69.3200 607.0000 1.0000
69.3600 575.0000 1.0000
69.4000 589.0000 1.0000
69.4400 573.0000 1.0000
69.4800 560.0000 1.0000
69.5200 588.0000 1.0000
69.5600 601.0000 1.0000
69.6000 625.0000 1.0000
69.6400 575.0000 1.0000
69.6800 638.0000 1.0000
69.7200 647.0000 1.0000
69.7600 624.0000 1.0000
69.8000 611.0000 1.0000
69.8400 586.0000 1.0000
69.8800 644.0000 1.0000
69.9200 595.0000 1.0000
69.9600 560.0000 1.0000
70.0000 585.0000 1.0000
*RAS_INT_END
*RAS_TEMPERATURE_START
*RAS_TEMPERATURE_END
*RAS_DATA_END