File: Data/Dataset1_Only_water/5_XRD/No_010_FS3_2.ras
*RAS_DATA_START
*RAS_HEADER_START
*DISP_FMT_X "%.2f"
*DISP_FMT_Y "%.0f"
*DISP_FULLSCALE "16364.0000000000"
*DISP_LINE_COLOR "255.0000000000"
*DISP_LINE_STYLE "0.0000000000"
*DISP_LINE_WIDTH "0.2500000000"
*DISP_NOTE "測定データ-1"
*DISP_OFFSET_Y "0.0000000000"
*DISP_PEAKSEARCH_UNIT_Y "cps"
*DISP_RANGE_BOTTOM "0.0000000000"
*DISP_RANGE_LEFT "20.0000000000"
*DISP_RANGE_LOGCUTOFF "0.0100000000"
*DISP_RANGE_RIGHT "70.0000000000"
*DISP_RANGE_TOP "16364.0000000000"
*DISP_SCALE_MODE_Y "0.0000000000"
*DISP_TAB_NAME "2θ/θ"
*DISP_TITLE_Y "強度"
*DISP_UNIT_Y "cps"
*DISP_WINDOW_NAME "MSG_MACROENGINE"
*FILE_COMMENT " "
*FILE_MD5 ""
*FILE_MEMO " "
*FILE_OPERATOR "Administrator"
*FILE_SAMPLE " "
*FILE_TYPE "RAS_RAW"
*FILE_USERGROUP "システムマネージャ"
*FILE_VERSION "1.0000000000"
*HW_ATTACHMENT_ID "ATT0025"
*HW_ATTACHMENT_NAME "標準|Standard"
*HW_COUNTER_ID-0 "CUT0025"
*HW_COUNTER_ID-1 "CUT0020"
*HW_COUNTER_ID-2 "CUT0020"
*HW_COUNTER_ID-3 "CSL0021"
*HW_COUNTER_ID-4 "CMC0021"
*HW_COUNTER_NAME-0 "D/teX Ultra|D/teX Ultra"
*HW_COUNTER_NAME-1 "None|None"
*HW_COUNTER_NAME-2 "None|None"
*HW_COUNTER_NAME-3 "BBM|BBM"
*HW_COUNTER_NAME-4 "検出器モノクロメータ|Detector monochromator"
*HW_COUNTER_SELECT_NAME "D/teX Ultra|D/teX Ultra"
*HW_GONIOMETER_ID "GON0023"
*HW_GONIOMETER_NAME "SmartLab|SmartLab"
*HW_GONIOMETER_RADIUS-0 "90.0"
*HW_GONIOMETER_RADIUS-1 "114.0"
*HW_GONIOMETER_RADIUS-2 "190.0"
*HW_GONIOMETER_RADIUS-3 "300.0"
*HW_GONIOMETER_RADIUS-4 "187.0"
*HW_GONIOMETER_RADIUS-5 "300.0"
*HW_GONIOMETER_RADIUS-6 "113.0"
*HW_GONIOMETER_RADIUS-7 "331.0"
*HW_I_OPT_ID-0 "CBO0021"
*HW_I_OPT_ID-1 "ICR0023"
*HW_I_OPT_ID-2 "ISL0021"
*HW_I_OPT_ID-3 "ISO0021"
*HW_I_OPT_ID-4 "IAD0021"
*HW_I_OPT_ID-5 "IPR0001"
*HW_I_OPT_NAME-0 "CBOユニット|CBO unit"
*HW_I_OPT_NAME-1 "標準入射光学ユニット|Standard incident optical unit"
*HW_I_OPT_NAME-2 "標準入射スリットボックス|Standard incident slit box"
*HW_I_OPT_NAME-3 "入射平行スリット|Incident parallel slit"
*HW_I_OPT_NAME-4 "長手制限スリット|Length limiting slit"
*HW_I_OPT_NAME-5 "None|None"
*HW_R_ATTENUATER_AUTOMODE "0"
*HW_R_OPT_ID-0 "RSS0021"
*HW_R_OPT_ID-1 "RCR0023"
*HW_R_OPT_ID-2 "RSO0021"
*HW_R_OPT_ID-3 "RRS0021"
*HW_R_OPT_ID-4 "ATN0021"
*HW_R_OPT_ID-5 "RFL0021"
*HW_R_OPT_ID-6 "RAD0021"
*HW_R_OPT_NAME-0 "標準受光スリットボックス1|Standard receiving slit box # 1"
*HW_R_OPT_NAME-1 "標準受光光学ユニット1|Standard receiving unit # 1"
*HW_R_OPT_NAME-2 "標準受光光学ユニット2|Standard receiving optical unit # 2"
*HW_R_OPT_NAME-3 "標準受光スリットボックス2|Standard receiving slit box # 2"
*HW_R_OPT_NAME-4 "標準アッテネータ|Standard Attenuator"
*HW_R_OPT_NAME-5 "Cu Kβ|Cu K-beta"
*HW_R_OPT_NAME-6 "調整用受光スリット|Alignment receiving slit"
*HW_SAMPLE_HOLDER_ID "SMP0023"
*HW_SAMPLE_HOLDER_NAME "標準Zステージ|Standard Z stage"
*HW_XG_CURRENT_MAX "50"
*HW_XG_CURRENT_MIN "2"
*HW_XG_CURRENT_RESOLUTION "1"
*HW_XG_CURRENT_UNIT "mA"
*HW_XG_FOCUS "1mm x 10mm"
*HW_XG_FOCUS_TYPE "Normal"
*HW_XG_ID ""
*HW_XG_NAME "3kW 封入管(ID:1200)|3kW Sealed tube(ID:1200)"
*HW_XG_TARGET_ATOMIC_NUMBER "29.0000000000"
*HW_XG_TARGET_NAME "Cu"
*HW_XG_TYPE "Hermetic"
*HW_XG_VOLTAGE_MAX "60"
*HW_XG_VOLTAGE_MIN "20"
*HW_XG_VOLTAGE_RESOLUTION "1"
*HW_XG_VOLTAGE_UNIT "kV"
*HW_XG_WATT_MAX "1.500"
*HW_XG_WATT_UNIT "kW"
*HW_XG_WAVE_LENGTH_ALPHA1 "1.540593"
*HW_XG_WAVE_LENGTH_ALPHA2 "1.544414"
*HW_XG_WAVE_LENGTH_BETA "1.392250"
*MEAS_COND_AXIS_NAME-0 "2θ/θ"
*MEAS_COND_AXIS_NAME-1 "2θ"
*MEAS_COND_AXIS_NAME-2 "ω"
*MEAS_COND_AXIS_NAME-3 "Z"
*MEAS_COND_AXIS_NAME-4 "2θ/ω"
*MEAS_COND_AXIS_NAME-5 "θs"
*MEAS_COND_AXIS_NAME-6 "θd"
*MEAS_COND_AXIS_NAME-7 "Ts"
*MEAS_COND_AXIS_NAME-8 "CBO選択スリット"
*MEAS_COND_AXIS_NAME-9 "M"
*MEAS_COND_AXIS_NAME-10 "入射平行スリット"
*MEAS_COND_AXIS_NAME-11 "入射スリット"
*MEAS_COND_AXIS_NAME-12 ""
*MEAS_COND_AXIS_NAME-13 "Zs"
*MEAS_COND_AXIS_NAME-14 "入射光学素子"
*MEAS_COND_AXIS_NAME-15 "長手制限スリット"
*MEAS_COND_AXIS_NAME-16 "センタースリット"
*MEAS_COND_AXIS_NAME-17 "フィルター"
*MEAS_COND_AXIS_NAME-18 "受光スリット1"
*MEAS_COND_AXIS_NAME-19 "受光スリット2"
*MEAS_COND_AXIS_NAME-20 "受光光学素子"
*MEAS_COND_AXIS_NAME-21 "受光平行スリット"
*MEAS_COND_AXIS_NAME-22 "調整用受光スリット"
*MEAS_COND_AXIS_NAME-23 ""
*MEAS_COND_AXIS_NAME-24 ""
*MEAS_COND_AXIS_NAME-25 "Zd"
*MEAS_COND_AXIS_NAME-26 "アッテネータ"
*MEAS_COND_AXIS_NAME-27 "検出器モノクロメータ"
*MEAS_COND_AXIS_NAME-28 "モノクロメータスリット"
*MEAS_COND_AXIS_NAME-29 "プライマリビーム"
*MEAS_COND_AXIS_NAME-30 "PHA"
*MEAS_COND_AXIS_NAME_INTERNAL-0 "TwoThetaTheta"
*MEAS_COND_AXIS_NAME_INTERNAL-1 "TwoTheta"
*MEAS_COND_AXIS_NAME_INTERNAL-2 "Omega"
*MEAS_COND_AXIS_NAME_INTERNAL-3 "Z"
*MEAS_COND_AXIS_NAME_INTERNAL-4 "TwoThetaOmega"
*MEAS_COND_AXIS_NAME_INTERNAL-5 "ThetaS"
*MEAS_COND_AXIS_NAME_INTERNAL-6 "ThetaD"
*MEAS_COND_AXIS_NAME_INTERNAL-7 "Ts"
*MEAS_COND_AXIS_NAME_INTERNAL-8 "CBO"
*MEAS_COND_AXIS_NAME_INTERNAL-9 "CBO-M"
*MEAS_COND_AXIS_NAME_INTERNAL-10 "IncidentSollerSlit"
*MEAS_COND_AXIS_NAME_INTERNAL-11 "IncidentSlitBox"
*MEAS_COND_AXIS_NAME_INTERNAL-12 "IncidentSlitBox-_Axis"
*MEAS_COND_AXIS_NAME_INTERNAL-13 "Zs"
*MEAS_COND_AXIS_NAME_INTERNAL-14 "IncidentMonochromator"
*MEAS_COND_AXIS_NAME_INTERNAL-15 "IncidentAxdSlit"
*MEAS_COND_AXIS_NAME_INTERNAL-16 "CenterSlit"
*MEAS_COND_AXIS_NAME_INTERNAL-17 "Filter"
*MEAS_COND_AXIS_NAME_INTERNAL-18 "ReceivingSlitBox1"
*MEAS_COND_AXIS_NAME_INTERNAL-19 "ReceivingSlitBox2"
*MEAS_COND_AXIS_NAME_INTERNAL-20 "ReceivingOptics"
*MEAS_COND_AXIS_NAME_INTERNAL-21 "ReceivingSollerSlit"
*MEAS_COND_AXIS_NAME_INTERNAL-22 "ReceivingAxdSlit"
*MEAS_COND_AXIS_NAME_INTERNAL-23 "ReceivingSlitBox1-_Axis"
*MEAS_COND_AXIS_NAME_INTERNAL-24 "ReceivingSlitBox2-_Axis"
*MEAS_COND_AXIS_NAME_INTERNAL-25 "ReceivingSlitBox2-Zd"
*MEAS_COND_AXIS_NAME_INTERNAL-26 "Attenuator"
*MEAS_COND_AXIS_NAME_INTERNAL-27 "CounterMonochromator"
*MEAS_COND_AXIS_NAME_INTERNAL-28 "CounterSlit"
*MEAS_COND_AXIS_NAME_INTERNAL-29 "IncidentPrimary"
*MEAS_COND_AXIS_NAME_INTERNAL-30 "PHA"
*MEAS_COND_AXIS_NAME_MAGICNO-0 "83951616.0000000000"
*MEAS_COND_AXIS_NAME_MAGICNO-1 "268632064.0000000000"
*MEAS_COND_AXIS_NAME_MAGICNO-2 "268500992.0000000000"
*MEAS_COND_AXIS_NAME_MAGICNO-3 "285278208.0000000000"
*MEAS_COND_AXIS_NAME_MAGICNO-4 "83951616.0000000000"
*MEAS_COND_AXIS_NAME_MAGICNO-5 "131072.0000000000"
*MEAS_COND_AXIS_NAME_MAGICNO-6 "131072.0000000000"
*MEAS_COND_AXIS_NAME_MAGICNO-7 "318898176.0000000000"
*MEAS_COND_AXIS_NAME_MAGICNO-8 "20971521.0000000000"
*MEAS_COND_AXIS_NAME_MAGICNO-9 "285343744.0000000000"
*MEAS_COND_AXIS_NAME_MAGICNO-10 "20971521.0000000000"
*MEAS_COND_AXIS_NAME_MAGICNO-11 "22020097.0000000000"
*MEAS_COND_AXIS_NAME_MAGICNO-12 "25165824.0000000000"
*MEAS_COND_AXIS_NAME_MAGICNO-13 "318898176.0000000000"
*MEAS_COND_AXIS_NAME_MAGICNO-14 "1.0000000000"
*MEAS_COND_AXIS_NAME_MAGICNO-15 "20971521.0000000000"
*MEAS_COND_AXIS_NAME_MAGICNO-16 "20971521.0000000000"
*MEAS_COND_AXIS_NAME_MAGICNO-17 "20971521.0000000000"
*MEAS_COND_AXIS_NAME_MAGICNO-18 "23068673.0000000000"
*MEAS_COND_AXIS_NAME_MAGICNO-19 "23068673.0000000000"
*MEAS_COND_AXIS_NAME_MAGICNO-20 "20971521.0000000000"
*MEAS_COND_AXIS_NAME_MAGICNO-21 "20971521.0000000000"
*MEAS_COND_AXIS_NAME_MAGICNO-22 "20971521.0000000000"
*MEAS_COND_AXIS_NAME_MAGICNO-23 "25165824.0000000000"
*MEAS_COND_AXIS_NAME_MAGICNO-24 "25165824.0000000000"
*MEAS_COND_AXIS_NAME_MAGICNO-25 "285343744.0000000000"
*MEAS_COND_AXIS_NAME_MAGICNO-26 "17301505.0000000000"
*MEAS_COND_AXIS_NAME_MAGICNO-27 "20971521.0000000000"
*MEAS_COND_AXIS_NAME_MAGICNO-28 "20971521.0000000000"
*MEAS_COND_AXIS_NAME_MAGICNO-29 "20971521.0000000000"
*MEAS_COND_AXIS_NAME_MAGICNO-30 "0.0000000000"
*MEAS_COND_AXIS_OFFSET-0 "-"
*MEAS_COND_AXIS_OFFSET-1 "-0.1081000000"
*MEAS_COND_AXIS_OFFSET-2 "0.3758000000"
*MEAS_COND_AXIS_OFFSET-3 "-"
*MEAS_COND_AXIS_OFFSET-4 "-"
*MEAS_COND_AXIS_OFFSET-5 "0.3758000000"
*MEAS_COND_AXIS_OFFSET-6 "-0.4839000000"
*MEAS_COND_AXIS_OFFSET-7 "-"
*MEAS_COND_AXIS_OFFSET-8 "-"
*MEAS_COND_AXIS_OFFSET-9 "-"
*MEAS_COND_AXIS_OFFSET-10 "-"
*MEAS_COND_AXIS_OFFSET-11 "-"
*MEAS_COND_AXIS_OFFSET-12 "-"
*MEAS_COND_AXIS_OFFSET-13 "-"
*MEAS_COND_AXIS_OFFSET-14 "-"
*MEAS_COND_AXIS_OFFSET-15 "-"
*MEAS_COND_AXIS_OFFSET-16 "-"
*MEAS_COND_AXIS_OFFSET-17 "-"
*MEAS_COND_AXIS_OFFSET-18 "-"
*MEAS_COND_AXIS_OFFSET-19 "-"
*MEAS_COND_AXIS_OFFSET-20 "-"
*MEAS_COND_AXIS_OFFSET-21 "-"
*MEAS_COND_AXIS_OFFSET-22 "-"
*MEAS_COND_AXIS_OFFSET-23 "-"
*MEAS_COND_AXIS_OFFSET-24 "-"
*MEAS_COND_AXIS_OFFSET-25 "-"
*MEAS_COND_AXIS_OFFSET-26 "-"
*MEAS_COND_AXIS_OFFSET-27 "-"
*MEAS_COND_AXIS_OFFSET-28 "-"
*MEAS_COND_AXIS_OFFSET-29 "-"
*MEAS_COND_AXIS_OFFSET-30 "-"
*MEAS_COND_AXIS_POSITION-0 "0.0000000000"
*MEAS_COND_AXIS_POSITION-1 "0.0000000000"
*MEAS_COND_AXIS_POSITION-2 "0.0000000000"
*MEAS_COND_AXIS_POSITION-3 "-0.5500000000"
*MEAS_COND_AXIS_POSITION-4 "0.0000000000"
*MEAS_COND_AXIS_POSITION-5 "0.0000000000"
*MEAS_COND_AXIS_POSITION-6 "0.0000000000"
*MEAS_COND_AXIS_POSITION-7 "-0.4278800000"
*MEAS_COND_AXIS_POSITION-8 "BB"
*MEAS_COND_AXIS_POSITION-9 "0.0000000000"
*MEAS_COND_AXIS_POSITION-10 "Soller_slit_5.0deg"
*MEAS_COND_AXIS_POSITION-11 "2/3deg"
*MEAS_COND_AXIS_POSITION-12 "2.2088000000"
*MEAS_COND_AXIS_POSITION-13 "-0.4140600000"
*MEAS_COND_AXIS_POSITION-14 "0.0000000000"
*MEAS_COND_AXIS_POSITION-15 "10.0mm"
*MEAS_COND_AXIS_POSITION-16 "None"
*MEAS_COND_AXIS_POSITION-17 "Cu_K-beta"
*MEAS_COND_AXIS_POSITION-18 "13.000mm"
*MEAS_COND_AXIS_POSITION-19 "13.000mm"
*MEAS_COND_AXIS_POSITION-20 "No_unit"
*MEAS_COND_AXIS_POSITION-21 "Soller_slit_5.0deg"
*MEAS_COND_AXIS_POSITION-22 "None"
*MEAS_COND_AXIS_POSITION-23 "13.0000000000"
*MEAS_COND_AXIS_POSITION-24 "13.0000000000"
*MEAS_COND_AXIS_POSITION-25 "0.0109400000"
*MEAS_COND_AXIS_POSITION-26 "Open"
*MEAS_COND_AXIS_POSITION-27 "None"
*MEAS_COND_AXIS_POSITION-28 "None"
*MEAS_COND_AXIS_POSITION-29 "None"
*MEAS_COND_AXIS_POSITION-30 "38.0000000000"
*MEAS_COND_AXIS_UNIT-0 "deg"
*MEAS_COND_AXIS_UNIT-1 "deg"
*MEAS_COND_AXIS_UNIT-2 "deg"
*MEAS_COND_AXIS_UNIT-3 "mm"
*MEAS_COND_AXIS_UNIT-4 "deg"
*MEAS_COND_AXIS_UNIT-5 "deg"
*MEAS_COND_AXIS_UNIT-6 "deg"
*MEAS_COND_AXIS_UNIT-7 "mm"
*MEAS_COND_AXIS_UNIT-8 ""
*MEAS_COND_AXIS_UNIT-9 "pulse"
*MEAS_COND_AXIS_UNIT-10 ""
*MEAS_COND_AXIS_UNIT-11 ""
*MEAS_COND_AXIS_UNIT-12 "mm"
*MEAS_COND_AXIS_UNIT-13 "mm"
*MEAS_COND_AXIS_UNIT-14 ""
*MEAS_COND_AXIS_UNIT-15 ""
*MEAS_COND_AXIS_UNIT-16 ""
*MEAS_COND_AXIS_UNIT-17 ""
*MEAS_COND_AXIS_UNIT-18 ""
*MEAS_COND_AXIS_UNIT-19 ""
*MEAS_COND_AXIS_UNIT-20 ""
*MEAS_COND_AXIS_UNIT-21 ""
*MEAS_COND_AXIS_UNIT-22 ""
*MEAS_COND_AXIS_UNIT-23 "mm"
*MEAS_COND_AXIS_UNIT-24 "mm"
*MEAS_COND_AXIS_UNIT-25 "mm"
*MEAS_COND_AXIS_UNIT-26 ""
*MEAS_COND_AXIS_UNIT-27 ""
*MEAS_COND_AXIS_UNIT-28 ""
*MEAS_COND_AXIS_UNIT-29 ""
*MEAS_COND_AXIS_UNIT-30 "div"
*MEAS_COND_COUNTER_CNTLOSS_CORR "0.0000000000"
*MEAS_COND_COUNTER_PHABASE "38.0000000000"
*MEAS_COND_COUNTER_PHAWINDOW "16.0000000000"
*MEAS_COND_COUNTER_PHA_UNIT "div"
*MEAS_COND_COUNTER_TAUDIFF "30.0000000000"
*MEAS_COND_COUNTER_TAUINT "0.0000000000"
*MEAS_COND_IRRADIATION_MODE "OFF"
*MEAS_COND_IRRADIATION_WIDTH ""
*MEAS_COND_OPT_ATTR "集中法"
*MEAS_COND_OPT_NAME "@集中法"
*MEAS_COND_UNSYMMETRIC_MODE "OFF"
*MEAS_COND_XG_CURRENT "30.0000000000"
*MEAS_COND_XG_VOLTAGE "40.0000000000"
*MEAS_COND_XG_WAVE_TYPE "Ka"
*MEAS_DATA_COUNT "5001.0000000000"
*MEAS_SCAN_AXIS_X "2θ/θ"
*MEAS_SCAN_AXIS_X_INTERNAL "TwoThetaTheta"
*MEAS_SCAN_END_TIME "07/06/21 12:18:31"
*MEAS_SCAN_MODE "CONTINUOUS"
*MEAS_SCAN_MONITOR "0"
*MEAS_SCAN_RESOLUTION_X "0.0002"
*MEAS_SCAN_SPEED "1.0"
*MEAS_SCAN_SPEED_UNIT "deg/min"
*MEAS_SCAN_START "20.0000000000"
*MEAS_SCAN_START_TIME "07/06/21 11:25:38"
*MEAS_SCAN_STEP "0.0100000000"
*MEAS_SCAN_STOP "70.0000000000"
*MEAS_SCAN_UNIT_X "deg"
*MEAS_SCAN_UNIT_Y "counts"
*RAS_HEADER_END
*RAS_INT_START
20.0000 1629.0000 1.0000
20.0400 1659.0000 1.0000
20.0800 1678.0000 1.0000
20.1200 1691.0000 1.0000
20.1600 1630.0000 1.0000
20.2000 1602.0000 1.0000
20.2400 1639.0000 1.0000
20.2800 1659.0000 1.0000
20.3200 1706.0000 1.0000
20.3600 1641.0000 1.0000
20.4000 1634.0000 1.0000
20.4400 1595.0000 1.0000
20.4800 1641.0000 1.0000
20.5200 1643.0000 1.0000
20.5600 1640.0000 1.0000
20.6000 1706.0000 1.0000
20.6400 1613.0000 1.0000
20.6800 1602.0000 1.0000
20.7200 1681.0000 1.0000
20.7600 1675.0000 1.0000
20.8000 1665.0000 1.0000
20.8400 1646.0000 1.0000
20.8800 1643.0000 1.0000
20.9200 1636.0000 1.0000
20.9600 1596.0000 1.0000
21.0000 1659.0000 1.0000
21.0400 1643.0000 1.0000
21.0800 1671.0000 1.0000
21.1200 1688.0000 1.0000
21.1600 1707.0000 1.0000
21.2000 1738.0000 1.0000
21.2400 1649.0000 1.0000
21.2800 1697.0000 1.0000
21.3200 1647.0000 1.0000
21.3600 1682.0000 1.0000
21.4000 1685.0000 1.0000
21.4400 1691.0000 1.0000
21.4800 1643.0000 1.0000
21.5200 1667.0000 1.0000
21.5600 1658.0000 1.0000
21.6000 1624.0000 1.0000
21.6400 1588.0000 1.0000
21.6800 1696.0000 1.0000
21.7200 1649.0000 1.0000
21.7600 1641.0000 1.0000
21.8000 1751.0000 1.0000
21.8400 1742.0000 1.0000
21.8800 1675.0000 1.0000
21.9200 1684.0000 1.0000
21.9600 1654.0000 1.0000
22.0000 1678.0000 1.0000
22.0400 1651.0000 1.0000
22.0800 1742.0000 1.0000
22.1200 1671.0000 1.0000
22.1600 1663.0000 1.0000
22.2000 1661.0000 1.0000
22.2400 1673.0000 1.0000
22.2800 1659.0000 1.0000
22.3200 1761.0000 1.0000
22.3600 1706.0000 1.0000
22.4000 1638.0000 1.0000
22.4400 1644.0000 1.0000
22.4800 1638.0000 1.0000
22.5200 1634.0000 1.0000
22.5600 1700.0000 1.0000
22.6000 1713.0000 1.0000
22.6400 1764.0000 1.0000
22.6800 1668.0000 1.0000
22.7200 1708.0000 1.0000
22.7600 1714.0000 1.0000
22.8000 1738.0000 1.0000
22.8400 1739.0000 1.0000
22.8800 1719.0000 1.0000
22.9200 1679.0000 1.0000
22.9600 1739.0000 1.0000
23.0000 1688.0000 1.0000
23.0400 1721.0000 1.0000
23.0800 1728.0000 1.0000
23.1200 1704.0000 1.0000
23.1600 1733.0000 1.0000
23.2000 1647.0000 1.0000
23.2400 1687.0000 1.0000
23.2800 1754.0000 1.0000
23.3200 1676.0000 1.0000
23.3600 1707.0000 1.0000
23.4000 1757.0000 1.0000
23.4400 1648.0000 1.0000
23.4800 1686.0000 1.0000
23.5200 1738.0000 1.0000
23.5600 1759.0000 1.0000
23.6000 1669.0000 1.0000
23.6400 1760.0000 1.0000
23.6800 1807.0000 1.0000
23.7200 1709.0000 1.0000
23.7600 1707.0000 1.0000
23.8000 1722.0000 1.0000
23.8400 1725.0000 1.0000
23.8800 1745.0000 1.0000
23.9200 1709.0000 1.0000
23.9600 1715.0000 1.0000
24.0000 1763.0000 1.0000
24.0400 1732.0000 1.0000
24.0800 1676.0000 1.0000
24.1200 1698.0000 1.0000
24.1600 1678.0000 1.0000
24.2000 1724.0000 1.0000
24.2400 1703.0000 1.0000
24.2800 1763.0000 1.0000
24.3200 1732.0000 1.0000
24.3600 1675.0000 1.0000
24.4000 1694.0000 1.0000
24.4400 1757.0000 1.0000
24.4800 1735.0000 1.0000
24.5200 1770.0000 1.0000
24.5600 1751.0000 1.0000
24.6000 1713.0000 1.0000
24.6400 1728.0000 1.0000
24.6800 1806.0000 1.0000
24.7200 1715.0000 1.0000
24.7600 1753.0000 1.0000
24.8000 1778.0000 1.0000
24.8400 1713.0000 1.0000
24.8800 1802.0000 1.0000
24.9200 1806.0000 1.0000
24.9600 1729.0000 1.0000
25.0000 1796.0000 1.0000
25.0400 1806.0000 1.0000
25.0800 1872.0000 1.0000
25.1200 1782.0000 1.0000
25.1600 1764.0000 1.0000
25.2000 1830.0000 1.0000
25.2400 1797.0000 1.0000
25.2800 1770.0000 1.0000
25.3200 1794.0000 1.0000
25.3600 1793.0000 1.0000
25.4000 1790.0000 1.0000
25.4400 1814.0000 1.0000
25.4800 1757.0000 1.0000
25.5200 1785.0000 1.0000
25.5600 1764.0000 1.0000
25.6000 1786.0000 1.0000
25.6400 1707.0000 1.0000
25.6800 1730.0000 1.0000
25.7200 1743.0000 1.0000
25.7600 1747.0000 1.0000
25.8000 1723.0000 1.0000
25.8400 1759.0000 1.0000
25.8800 1781.0000 1.0000
25.9200 1745.0000 1.0000
25.9600 1725.0000 1.0000
26.0000 1787.0000 1.0000
26.0400 1809.0000 1.0000
26.0800 1775.0000 1.0000
26.1200 1789.0000 1.0000
26.1600 1763.0000 1.0000
26.2000 1790.0000 1.0000
26.2400 1871.0000 1.0000
26.2800 1780.0000 1.0000
26.3200 1828.0000 1.0000
26.3600 1808.0000 1.0000
26.4000 1859.0000 1.0000
26.4400 1790.0000 1.0000
26.4800 1864.0000 1.0000
26.5200 1845.0000 1.0000
26.5600 1824.0000 1.0000
26.6000 1868.0000 1.0000
26.6400 1877.0000 1.0000
26.6800 1832.0000 1.0000
26.7200 1963.0000 1.0000
26.7600 1939.0000 1.0000
26.8000 1978.0000 1.0000
26.8400 1968.0000 1.0000
26.8800 2049.0000 1.0000
26.9200 2151.0000 1.0000
26.9600 2261.0000 1.0000
27.0000 2421.0000 1.0000
27.0400 2561.0000 1.0000
27.0800 2931.0000 1.0000
27.1200 3244.0000 1.0000
27.1600 3763.0000 1.0000
27.2000 4529.0000 1.0000
27.2400 5488.0000 1.0000
27.2800 6234.0000 1.0000
27.3200 6560.0000 1.0000
27.3600 5891.0000 1.0000
27.4000 4836.0000 1.0000
27.4400 3989.0000 1.0000
27.4800 3394.0000 1.0000
27.5200 2976.0000 1.0000
27.5600 2628.0000 1.0000
27.6000 2400.0000 1.0000
27.6400 2322.0000 1.0000
27.6800 2119.0000 1.0000
27.7200 2118.0000 1.0000
27.7600 2012.0000 1.0000
27.8000 2014.0000 1.0000
27.8400 1930.0000 1.0000
27.8800 1945.0000 1.0000
27.9200 1873.0000 1.0000
27.9600 1859.0000 1.0000
28.0000 1887.0000 1.0000
28.0400 1859.0000 1.0000
28.0800 1813.0000 1.0000
28.1200 1786.0000 1.0000
28.1600 1740.0000 1.0000
28.2000 1756.0000 1.0000
28.2400 1773.0000 1.0000
28.2800 1734.0000 1.0000
28.3200 1723.0000 1.0000
28.3600 1772.0000 1.0000
28.4000 1700.0000 1.0000
28.4400 1754.0000 1.0000
28.4800 1778.0000 1.0000
28.5200 1744.0000 1.0000
28.5600 1717.0000 1.0000
28.6000 1742.0000 1.0000
28.6400 1775.0000 1.0000
28.6800 1681.0000 1.0000
28.7200 1692.0000 1.0000
28.7600 1734.0000 1.0000
28.8000 1608.0000 1.0000
28.8400 1659.0000 1.0000
28.8800 1671.0000 1.0000
28.9200 1607.0000 1.0000
28.9600 1682.0000 1.0000
29.0000 1679.0000 1.0000
29.0400 1658.0000 1.0000
29.0800 1725.0000 1.0000
29.1200 1652.0000 1.0000
29.1600 1628.0000 1.0000
29.2000 1716.0000 1.0000
29.2400 1657.0000 1.0000
29.2800 1659.0000 1.0000
29.3200 1660.0000 1.0000
29.3600 1635.0000 1.0000
29.4000 1688.0000 1.0000
29.4400 1615.0000 1.0000
29.4800 1645.0000 1.0000
29.5200 1707.0000 1.0000
29.5600 1649.0000 1.0000
29.6000 1678.0000 1.0000
29.6400 1590.0000 1.0000
29.6800 1582.0000 1.0000
29.7200 1551.0000 1.0000
29.7600 1595.0000 1.0000
29.8000 1653.0000 1.0000
29.8400 1608.0000 1.0000
29.8800 1627.0000 1.0000
29.9200 1594.0000 1.0000
29.9600 1562.0000 1.0000
30.0000 1616.0000 1.0000
30.0400 1589.0000 1.0000
30.0800 1604.0000 1.0000
30.1200 1533.0000 1.0000
30.1600 1660.0000 1.0000
30.2000 1592.0000 1.0000
30.2400 1614.0000 1.0000
30.2800 1579.0000 1.0000
30.3200 1584.0000 1.0000
30.3600 1618.0000 1.0000
30.4000 1531.0000 1.0000
30.4400 1570.0000 1.0000
30.4800 1521.0000 1.0000
30.5200 1604.0000 1.0000
30.5600 1585.0000 1.0000
30.6000 1644.0000 1.0000
30.6400 1552.0000 1.0000
30.6800 1616.0000 1.0000
30.7200 1480.0000 1.0000
30.7600 1603.0000 1.0000
30.8000 1528.0000 1.0000
30.8400 1554.0000 1.0000
30.8800 1565.0000 1.0000
30.9200 1527.0000 1.0000
30.9600 1556.0000 1.0000
31.0000 1510.0000 1.0000
31.0400 1517.0000 1.0000
31.0800 1568.0000 1.0000
31.1200 1521.0000 1.0000
31.1600 1524.0000 1.0000
31.2000 1573.0000 1.0000
31.2400 1546.0000 1.0000
31.2800 1542.0000 1.0000
31.3200 1534.0000 1.0000
31.3600 1564.0000 1.0000
31.4000 1533.0000 1.0000
31.4400 1442.0000 1.0000
31.4800 1472.0000 1.0000
31.5200 1467.0000 1.0000
31.5600 1514.0000 1.0000
31.6000 1526.0000 1.0000
31.6400 1509.0000 1.0000
31.6800 1475.0000 1.0000
31.7200 1495.0000 1.0000
31.7600 1514.0000 1.0000
31.8000 1534.0000 1.0000
31.8400 1480.0000 1.0000
31.8800 1503.0000 1.0000
31.9200 1487.0000 1.0000
31.9600 1536.0000 1.0000
32.0000 1534.0000 1.0000
32.0400 1554.0000 1.0000
32.0800 1491.0000 1.0000
32.1200 1515.0000 1.0000
32.1600 1474.0000 1.0000
32.2000 1574.0000 1.0000
32.2400 1475.0000 1.0000
32.2800 1526.0000 1.0000
32.3200 1475.0000 1.0000
32.3600 1512.0000 1.0000
32.4000 1461.0000 1.0000
32.4400 1509.0000 1.0000
32.4800 1439.0000 1.0000
32.5200 1436.0000 1.0000
32.5600 1468.0000 1.0000
32.6000 1388.0000 1.0000
32.6400 1416.0000 1.0000
32.6800 1460.0000 1.0000
32.7200 1501.0000 1.0000
32.7600 1416.0000 1.0000
32.8000 1405.0000 1.0000
32.8400 1410.0000 1.0000
32.8800 1456.0000 1.0000
32.9200 1443.0000 1.0000
32.9600 1470.0000 1.0000
33.0000 1394.0000 1.0000
33.0400 1421.0000 1.0000
33.0800 1431.0000 1.0000
33.1200 1383.0000 1.0000
33.1600 1445.0000 1.0000
33.2000 1433.0000 1.0000
33.2400 1376.0000 1.0000
33.2800 1364.0000 1.0000
33.3200 1397.0000 1.0000
33.3600 1435.0000 1.0000
33.4000 1438.0000 1.0000
33.4400 1450.0000 1.0000
33.4800 1412.0000 1.0000
33.5200 1423.0000 1.0000
33.5600 1394.0000 1.0000
33.6000 1423.0000 1.0000
33.6400 1420.0000 1.0000
33.6800 1409.0000 1.0000
33.7200 1413.0000 1.0000
33.7600 1462.0000 1.0000
33.8000 1511.0000 1.0000
33.8400 1561.0000 1.0000
33.8800 1547.0000 1.0000
33.9200 1598.0000 1.0000
33.9600 1640.0000 1.0000
34.0000 1636.0000 1.0000
34.0400 1673.0000 1.0000
34.0800 1545.0000 1.0000
34.1200 1529.0000 1.0000
34.1600 1599.0000 1.0000
34.2000 1672.0000 1.0000
34.2400 1666.0000 1.0000
34.2800 1850.0000 1.0000
34.3200 1970.0000 1.0000
34.3600 2115.0000 1.0000
34.4000 2465.0000 1.0000
34.4400 2780.0000 1.0000
34.4800 3063.0000 1.0000
34.5200 3086.0000 1.0000
34.5600 2811.0000 1.0000
34.6000 2674.0000 1.0000
34.6400 2229.0000 1.0000
34.6800 2031.0000 1.0000
34.7200 1856.0000 1.0000
34.7600 1696.0000 1.0000
34.8000 1593.0000 1.0000
34.8400 1606.0000 1.0000
34.8800 1441.0000 1.0000
34.9200 1437.0000 1.0000
34.9600 1452.0000 1.0000
35.0000 1460.0000 1.0000
35.0400 1333.0000 1.0000
35.0800 1267.0000 1.0000
35.1200 1372.0000 1.0000
35.1600 1297.0000 1.0000
35.2000 1261.0000 1.0000
35.2400 1314.0000 1.0000
35.2800 1304.0000 1.0000
35.3200 1351.0000 1.0000
35.3600 1288.0000 1.0000
35.4000 1278.0000 1.0000
35.4400 1246.0000 1.0000
35.4800 1282.0000 1.0000
35.5200 1283.0000 1.0000
35.5600 1217.0000 1.0000
35.6000 1277.0000 1.0000
35.6400 1236.0000 1.0000
35.6800 1218.0000 1.0000
35.7200 1228.0000 1.0000
35.7600 1256.0000 1.0000
35.8000 1186.0000 1.0000
35.8400 1265.0000 1.0000
35.8800 1171.0000 1.0000
35.9200 1231.0000 1.0000
35.9600 1177.0000 1.0000
36.0000 1229.0000 1.0000
36.0400 1188.0000 1.0000
36.0800 1302.0000 1.0000
36.1200 1253.0000 1.0000
36.1600 1310.0000 1.0000
36.2000 1385.0000 1.0000
36.2400 1418.0000 1.0000
36.2800 1524.0000 1.0000
36.3200 1716.0000 1.0000
36.3600 1969.0000 1.0000
36.4000 2276.0000 1.0000
36.4400 2228.0000 1.0000
36.4800 2073.0000 1.0000
36.5200 1781.0000 1.0000
36.5600 1560.0000 1.0000
36.6000 1376.0000 1.0000
36.6400 1257.0000 1.0000
36.6800 1248.0000 1.0000
36.7200 1190.0000 1.0000
36.7600 1189.0000 1.0000
36.8000 1135.0000 1.0000
36.8400 1127.0000 1.0000
36.8800 1113.0000 1.0000
36.9200 1075.0000 1.0000
36.9600 1099.0000 1.0000
37.0000 1193.0000 1.0000
37.0400 1117.0000 1.0000
37.0800 1126.0000 1.0000
37.1200 1107.0000 1.0000
37.1600 1129.0000 1.0000
37.2000 1149.0000 1.0000
37.2400 1147.0000 1.0000
37.2800 1094.0000 1.0000
37.3200 1164.0000 1.0000
37.3600 1162.0000 1.0000
37.4000 1110.0000 1.0000
37.4400 1146.0000 1.0000
37.4800 1161.0000 1.0000
37.5200 1166.0000 1.0000
37.5600 1166.0000 1.0000
37.6000 1126.0000 1.0000
37.6400 1166.0000 1.0000
37.6800 1141.0000 1.0000
37.7200 1129.0000 1.0000
37.7600 1169.0000 1.0000
37.8000 1127.0000 1.0000
37.8400 1149.0000 1.0000
37.8800 1088.0000 1.0000
37.9200 1134.0000 1.0000
37.9600 1147.0000 1.0000
38.0000 1228.0000 1.0000
38.0400 1195.0000 1.0000
38.0800 1239.0000 1.0000
38.1200 1345.0000 1.0000
38.1600 1430.0000 1.0000
38.2000 1503.0000 1.0000
38.2400 1730.0000 1.0000
38.2800 1942.0000 1.0000
38.3200 2231.0000 1.0000
38.3600 2761.0000 1.0000
38.4000 3589.0000 1.0000
38.4400 4676.0000 1.0000
38.4800 6225.0000 1.0000
38.5200 7670.0000 1.0000
38.5600 8182.0000 1.0000
38.6000 7778.0000 1.0000
38.6400 6676.0000 1.0000
38.6800 5494.0000 1.0000
38.7200 4154.0000 1.0000
38.7600 3137.0000 1.0000
38.8000 2474.0000 1.0000
38.8400 1961.0000 1.0000
38.8800 1688.0000 1.0000
38.9200 1545.0000 1.0000
38.9600 1379.0000 1.0000
39.0000 1240.0000 1.0000
39.0400 1225.0000 1.0000
39.0800 1208.0000 1.0000
39.1200 1191.0000 1.0000
39.1600 1122.0000 1.0000
39.2000 1091.0000 1.0000
39.2400 1067.0000 1.0000
39.2800 1062.0000 1.0000
39.3200 1058.0000 1.0000
39.3600 1097.0000 1.0000
39.4000 1010.0000 1.0000
39.4400 1071.0000 1.0000
39.4800 1052.0000 1.0000
39.5200 1083.0000 1.0000
39.5600 1005.0000 1.0000
39.6000 1043.0000 1.0000
39.6400 1069.0000 1.0000
39.6800 1031.0000 1.0000
39.7200 1056.0000 1.0000
39.7600 1052.0000 1.0000
39.8000 1014.0000 1.0000
39.8400 972.0000 1.0000
39.8800 1026.0000 1.0000
39.9200 972.0000 1.0000
39.9600 976.0000 1.0000
40.0000 957.0000 1.0000
40.0400 984.0000 1.0000
40.0800 958.0000 1.0000
40.1200 1023.0000 1.0000
40.1600 959.0000 1.0000
40.2000 957.0000 1.0000
40.2400 971.0000 1.0000
40.2800 956.0000 1.0000
40.3200 951.0000 1.0000
40.3600 910.0000 1.0000
40.4000 981.0000 1.0000
40.4400 975.0000 1.0000
40.4800 934.0000 1.0000
40.5200 958.0000 1.0000
40.5600 922.0000 1.0000
40.6000 891.0000 1.0000
40.6400 946.0000 1.0000
40.6800 934.0000 1.0000
40.7200 954.0000 1.0000
40.7600 946.0000 1.0000
40.8000 964.0000 1.0000
40.8400 946.0000 1.0000
40.8800 936.0000 1.0000
40.9200 930.0000 1.0000
40.9600 976.0000 1.0000
41.0000 933.0000 1.0000
41.0400 916.0000 1.0000
41.0800 859.0000 1.0000
41.1200 950.0000 1.0000
41.1600 940.0000 1.0000
41.2000 871.0000 1.0000
41.2400 910.0000 1.0000
41.2800 929.0000 1.0000
41.3200 925.0000 1.0000
41.3600 965.0000 1.0000
41.4000 924.0000 1.0000
41.4400 940.0000 1.0000
41.4800 956.0000 1.0000
41.5200 952.0000 1.0000
41.5600 901.0000 1.0000
41.6000 915.0000 1.0000
41.6400 944.0000 1.0000
41.6800 979.0000 1.0000
41.7200 893.0000 1.0000
41.7600 965.0000 1.0000
41.8000 881.0000 1.0000
41.8400 901.0000 1.0000
41.8800 947.0000 1.0000
41.9200 949.0000 1.0000
41.9600 882.0000 1.0000
42.0000 903.0000 1.0000
42.0400 946.0000 1.0000
42.0800 893.0000 1.0000
42.1200 910.0000 1.0000
42.1600 917.0000 1.0000
42.2000 885.0000 1.0000
42.2400 912.0000 1.0000
42.2800 904.0000 1.0000
42.3200 920.0000 1.0000
42.3600 916.0000 1.0000
42.4000 924.0000 1.0000
42.4400 879.0000 1.0000
42.4800 903.0000 1.0000
42.5200 911.0000 1.0000
42.5600 938.0000 1.0000
42.6000 938.0000 1.0000
42.6400 924.0000 1.0000
42.6800 889.0000 1.0000
42.7200 905.0000 1.0000
42.7600 918.0000 1.0000
42.8000 865.0000 1.0000
42.8400 877.0000 1.0000
42.8800 941.0000 1.0000
42.9200 925.0000 1.0000
42.9600 928.0000 1.0000
43.0000 839.0000 1.0000
43.0400 934.0000 1.0000
43.0800 937.0000 1.0000
43.1200 978.0000 1.0000
43.1600 973.0000 1.0000
43.2000 984.0000 1.0000
43.2400 1010.0000 1.0000
43.2800 999.0000 1.0000
43.3200 1006.0000 1.0000
43.3600 995.0000 1.0000
43.4000 907.0000 1.0000
43.4400 937.0000 1.0000
43.4800 928.0000 1.0000
43.5200 908.0000 1.0000
43.5600 897.0000 1.0000
43.6000 877.0000 1.0000
43.6400 869.0000 1.0000
43.6800 923.0000 1.0000
43.7200 862.0000 1.0000
43.7600 861.0000 1.0000
43.8000 881.0000 1.0000
43.8400 876.0000 1.0000
43.8800 907.0000 1.0000
43.9200 858.0000 1.0000
43.9600 870.0000 1.0000
44.0000 836.0000 1.0000
44.0400 902.0000 1.0000
44.0800 895.0000 1.0000
44.1200 881.0000 1.0000
44.1600 840.0000 1.0000
44.2000 841.0000 1.0000
44.2400 868.0000 1.0000
44.2800 924.0000 1.0000
44.3200 880.0000 1.0000
44.3600 899.0000 1.0000
44.4000 926.0000 1.0000
44.4400 882.0000 1.0000
44.4800 891.0000 1.0000
44.5200 830.0000 1.0000
44.5600 879.0000 1.0000
44.6000 902.0000 1.0000
44.6400 858.0000 1.0000
44.6800 880.0000 1.0000
44.7200 880.0000 1.0000
44.7600 855.0000 1.0000
44.8000 812.0000 1.0000
44.8400 845.0000 1.0000
44.8800 880.0000 1.0000
44.9200 898.0000 1.0000
44.9600 849.0000 1.0000
45.0000 884.0000 1.0000
45.0400 849.0000 1.0000
45.0800 904.0000 1.0000
45.1200 862.0000 1.0000
45.1600 835.0000 1.0000
45.2000 827.0000 1.0000
45.2400 827.0000 1.0000
45.2800 826.0000 1.0000
45.3200 833.0000 1.0000
45.3600 823.0000 1.0000
45.4000 840.0000 1.0000
45.4400 824.0000 1.0000
45.4800 836.0000 1.0000
45.5200 824.0000 1.0000
45.5600 834.0000 1.0000
45.6000 834.0000 1.0000
45.6400 798.0000 1.0000
45.6800 879.0000 1.0000
45.7200 855.0000 1.0000
45.7600 873.0000 1.0000
45.8000 808.0000 1.0000
45.8400 805.0000 1.0000
45.8800 865.0000 1.0000
45.9200 809.0000 1.0000
45.9600 801.0000 1.0000
46.0000 806.0000 1.0000
46.0400 829.0000 1.0000
46.0800 835.0000 1.0000
46.1200 812.0000 1.0000
46.1600 836.0000 1.0000
46.2000 838.0000 1.0000
46.2400 853.0000 1.0000
46.2800 863.0000 1.0000
46.3200 813.0000 1.0000
46.3600 785.0000 1.0000
46.4000 801.0000 1.0000
46.4400 825.0000 1.0000
46.4800 866.0000 1.0000
46.5200 844.0000 1.0000
46.5600 825.0000 1.0000
46.6000 817.0000 1.0000
46.6400 801.0000 1.0000
46.6800 832.0000 1.0000
46.7200 785.0000 1.0000
46.7600 789.0000 1.0000
46.8000 869.0000 1.0000
46.8400 810.0000 1.0000
46.8800 839.0000 1.0000
46.9200 801.0000 1.0000
46.9600 798.0000 1.0000
47.0000 866.0000 1.0000
47.0400 816.0000 1.0000
47.0800 827.0000 1.0000
47.1200 859.0000 1.0000
47.1600 843.0000 1.0000
47.2000 832.0000 1.0000
47.2400 758.0000 1.0000
47.2800 766.0000 1.0000
47.3200 806.0000 1.0000
47.3600 864.0000 1.0000
47.4000 804.0000 1.0000
47.4400 848.0000 1.0000
47.4800 787.0000 1.0000
47.5200 830.0000 1.0000
47.5600 786.0000 1.0000
47.6000 794.0000 1.0000
47.6400 782.0000 1.0000
47.6800 795.0000 1.0000
47.7200 824.0000 1.0000
47.7600 761.0000 1.0000
47.8000 793.0000 1.0000
47.8400 808.0000 1.0000
47.8800 811.0000 1.0000
47.9200 820.0000 1.0000
47.9600 815.0000 1.0000
48.0000 796.0000 1.0000
48.0400 781.0000 1.0000
48.0800 771.0000 1.0000
48.1200 789.0000 1.0000
48.1600 808.0000 1.0000
48.2000 811.0000 1.0000
48.2400 729.0000 1.0000
48.2800 754.0000 1.0000
48.3200 747.0000 1.0000
48.3600 801.0000 1.0000
48.4000 799.0000 1.0000
48.4400 797.0000 1.0000
48.4800 793.0000 1.0000
48.5200 778.0000 1.0000
48.5600 784.0000 1.0000
48.6000 809.0000 1.0000
48.6400 714.0000 1.0000
48.6800 840.0000 1.0000
48.7200 802.0000 1.0000
48.7600 790.0000 1.0000
48.8000 783.0000 1.0000
48.8400 772.0000 1.0000
48.8800 744.0000 1.0000
48.9200 779.0000 1.0000
48.9600 805.0000 1.0000
49.0000 756.0000 1.0000
49.0400 790.0000 1.0000
49.0800 783.0000 1.0000
49.1200 786.0000 1.0000
49.1600 788.0000 1.0000
49.2000 770.0000 1.0000
49.2400 773.0000 1.0000
49.2800 764.0000 1.0000
49.3200 726.0000 1.0000
49.3600 791.0000 1.0000
49.4000 759.0000 1.0000
49.4400 778.0000 1.0000
49.4800 753.0000 1.0000
49.5200 727.0000 1.0000
49.5600 841.0000 1.0000
49.6000 730.0000 1.0000
49.6400 758.0000 1.0000
49.6800 776.0000 1.0000
49.7200 784.0000 1.0000
49.7600 771.0000 1.0000
49.8000 789.0000 1.0000
49.8400 779.0000 1.0000
49.8800 773.0000 1.0000
49.9200 786.0000 1.0000
49.9600 790.0000 1.0000
50.0000 810.0000 1.0000
50.0400 775.0000 1.0000
50.0800 785.0000 1.0000
50.1200 827.0000 1.0000
50.1600 837.0000 1.0000
50.2000 787.0000 1.0000
50.2400 840.0000 1.0000
50.2800 833.0000 1.0000
50.3200 810.0000 1.0000
50.3600 790.0000 1.0000
50.4000 728.0000 1.0000
50.4400 800.0000 1.0000
50.4800 814.0000 1.0000
50.5200 762.0000 1.0000
50.5600 779.0000 1.0000
50.6000 742.0000 1.0000
50.6400 797.0000 1.0000
50.6800 814.0000 1.0000
50.7200 767.0000 1.0000
50.7600 740.0000 1.0000
50.8000 811.0000 1.0000
50.8400 799.0000 1.0000
50.8800 777.0000 1.0000
50.9200 791.0000 1.0000
50.9600 813.0000 1.0000
51.0000 810.0000 1.0000
51.0400 770.0000 1.0000
51.0800 784.0000 1.0000
51.1200 782.0000 1.0000
51.1600 779.0000 1.0000
51.2000 740.0000 1.0000
51.2400 813.0000 1.0000
51.2800 774.0000 1.0000
51.3200 802.0000 1.0000
51.3600 761.0000 1.0000
51.4000 792.0000 1.0000
51.4400 728.0000 1.0000
51.4800 791.0000 1.0000
51.5200 815.0000 1.0000
51.5600 810.0000 1.0000
51.6000 773.0000 1.0000
51.6400 829.0000 1.0000
51.6800 786.0000 1.0000
51.7200 791.0000 1.0000
51.7600 876.0000 1.0000
51.8000 857.0000 1.0000
51.8400 905.0000 1.0000
51.8800 923.0000 1.0000
51.9200 1008.0000 1.0000
51.9600 1046.0000 1.0000
52.0000 1209.0000 1.0000
52.0400 1364.0000 1.0000
52.0800 1561.0000 1.0000
52.1200 1880.0000 1.0000
52.1600 2523.0000 1.0000
52.2000 3496.0000 1.0000
52.2400 4632.0000 1.0000
52.2800 5269.0000 1.0000
52.3200 4755.0000 1.0000
52.3600 4226.0000 1.0000
52.4000 3918.0000 1.0000
52.4400 3385.0000 1.0000
52.4800 2547.0000 1.0000
52.5200 1952.0000 1.0000
52.5600 1548.0000 1.0000
52.6000 1280.0000 1.0000
52.6400 1182.0000 1.0000
52.6800 1047.0000 1.0000
52.7200 1023.0000 1.0000
52.7600 974.0000 1.0000
52.8000 927.0000 1.0000
52.8400 835.0000 1.0000
52.8800 804.0000 1.0000
52.9200 830.0000 1.0000
52.9600 827.0000 1.0000
53.0000 833.0000 1.0000
53.0400 765.0000 1.0000
53.0800 758.0000 1.0000
53.1200 765.0000 1.0000
53.1600 787.0000 1.0000
53.2000 803.0000 1.0000
53.2400 772.0000 1.0000
53.2800 750.0000 1.0000
53.3200 767.0000 1.0000
53.3600 793.0000 1.0000
53.4000 798.0000 1.0000
53.4400 752.0000 1.0000
53.4800 753.0000 1.0000
53.5200 764.0000 1.0000
53.5600 739.0000 1.0000
53.6000 775.0000 1.0000
53.6400 774.0000 1.0000
53.6800 730.0000 1.0000
53.7200 746.0000 1.0000
53.7600 745.0000 1.0000
53.8000 716.0000 1.0000
53.8400 730.0000 1.0000
53.8800 739.0000 1.0000
53.9200 777.0000 1.0000
53.9600 751.0000 1.0000
54.0000 714.0000 1.0000
54.0400 744.0000 1.0000
54.0800 763.0000 1.0000
54.1200 756.0000 1.0000
54.1600 732.0000 1.0000
54.2000 756.0000 1.0000
54.2400 729.0000 1.0000
54.2800 763.0000 1.0000
54.3200 749.0000 1.0000
54.3600 752.0000 1.0000
54.4000 733.0000 1.0000
54.4400 716.0000 1.0000
54.4800 720.0000 1.0000
54.5200 799.0000 1.0000
54.5600 737.0000 1.0000
54.6000 739.0000 1.0000
54.6400 721.0000 1.0000
54.6800 795.0000 1.0000
54.7200 778.0000 1.0000
54.7600 776.0000 1.0000
54.8000 839.0000 1.0000
54.8400 795.0000 1.0000
54.8800 799.0000 1.0000
54.9200 814.0000 1.0000
54.9600 779.0000 1.0000
55.0000 838.0000 1.0000
55.0400 870.0000 1.0000
55.0800 925.0000 1.0000
55.1200 885.0000 1.0000
55.1600 942.0000 1.0000
55.2000 1032.0000 1.0000
55.2400 1039.0000 1.0000
55.2800 1106.0000 1.0000
55.3200 1024.0000 1.0000
55.3600 1054.0000 1.0000
55.4000 1053.0000 1.0000
55.4400 1017.0000 1.0000
55.4800 982.0000 1.0000
55.5200 888.0000 1.0000
55.5600 895.0000 1.0000
55.6000 829.0000 1.0000
55.6400 796.0000 1.0000
55.6800 835.0000 1.0000
55.7200 762.0000 1.0000
55.7600 693.0000 1.0000
55.8000 751.0000 1.0000
55.8400 751.0000 1.0000
55.8800 759.0000 1.0000
55.9200 703.0000 1.0000
55.9600 774.0000 1.0000
56.0000 753.0000 1.0000
56.0400 730.0000 1.0000
56.0800 730.0000 1.0000
56.1200 702.0000 1.0000
56.1600 724.0000 1.0000
56.2000 737.0000 1.0000
56.2400 689.0000 1.0000
56.2800 725.0000 1.0000
56.3200 744.0000 1.0000
56.3600 738.0000 1.0000
56.4000 731.0000 1.0000
56.4400 742.0000 1.0000
56.4800 708.0000 1.0000
56.5200 731.0000 1.0000
56.5600 699.0000 1.0000
56.6000 685.0000 1.0000
56.6400 692.0000 1.0000
56.6800 753.0000 1.0000
56.7200 737.0000 1.0000
56.7600 740.0000 1.0000
56.8000 736.0000 1.0000
56.8400 734.0000 1.0000
56.8800 697.0000 1.0000
56.9200 725.0000 1.0000
56.9600 702.0000 1.0000
57.0000 682.0000 1.0000
57.0400 708.0000 1.0000
57.0800 729.0000 1.0000
57.1200 706.0000 1.0000
57.1600 744.0000 1.0000
57.2000 714.0000 1.0000
57.2400 748.0000 1.0000
57.2800 728.0000 1.0000
57.3200 703.0000 1.0000
57.3600 680.0000 1.0000
57.4000 748.0000 1.0000
57.4400 710.0000 1.0000
57.4800 740.0000 1.0000
57.5200 717.0000 1.0000
57.5600 657.0000 1.0000
57.6000 718.0000 1.0000
57.6400 693.0000 1.0000
57.6800 715.0000 1.0000
57.7200 689.0000 1.0000
57.7600 698.0000 1.0000
57.8000 686.0000 1.0000
57.8400 699.0000 1.0000
57.8800 729.0000 1.0000
57.9200 737.0000 1.0000
57.9600 698.0000 1.0000
58.0000 717.0000 1.0000
58.0400 705.0000 1.0000
58.0800 703.0000 1.0000
58.1200 709.0000 1.0000
58.1600 741.0000 1.0000
58.2000 708.0000 1.0000
58.2400 712.0000 1.0000
58.2800 675.0000 1.0000
58.3200 740.0000 1.0000
58.3600 762.0000 1.0000
58.4000 719.0000 1.0000
58.4400 714.0000 1.0000
58.4800 692.0000 1.0000
58.5200 728.0000 1.0000
58.5600 667.0000 1.0000
58.6000 734.0000 1.0000
58.6400 764.0000 1.0000
58.6800 706.0000 1.0000
58.7200 714.0000 1.0000
58.7600 727.0000 1.0000
58.8000 711.0000 1.0000
58.8400 697.0000 1.0000
58.8800 707.0000 1.0000
58.9200 705.0000 1.0000
58.9600 711.0000 1.0000
59.0000 723.0000 1.0000
59.0400 705.0000 1.0000
59.0800 688.0000 1.0000
59.1200 683.0000 1.0000
59.1600 719.0000 1.0000
59.2000 704.0000 1.0000
59.2400 717.0000 1.0000
59.2800 737.0000 1.0000
59.3200 712.0000 1.0000
59.3600 730.0000 1.0000
59.4000 754.0000 1.0000
59.4400 687.0000 1.0000
59.4800 694.0000 1.0000
59.5200 763.0000 1.0000
59.5600 737.0000 1.0000
59.6000 699.0000 1.0000
59.6400 669.0000 1.0000
59.6800 726.0000 1.0000
59.7200 691.0000 1.0000
59.7600 703.0000 1.0000
59.8000 708.0000 1.0000
59.8400 712.0000 1.0000
59.8800 759.0000 1.0000
59.9200 709.0000 1.0000
59.9600 695.0000 1.0000
60.0000 718.0000 1.0000
60.0400 718.0000 1.0000
60.0800 694.0000 1.0000
60.1200 716.0000 1.0000
60.1600 702.0000 1.0000
60.2000 709.0000 1.0000
60.2400 705.0000 1.0000
60.2800 718.0000 1.0000
60.3200 725.0000 1.0000
60.3600 677.0000 1.0000
60.4000 722.0000 1.0000
60.4400 694.0000 1.0000
60.4800 703.0000 1.0000
60.5200 753.0000 1.0000
60.5600 692.0000 1.0000
60.6000 767.0000 1.0000
60.6400 724.0000 1.0000
60.6800 733.0000 1.0000
60.7200 712.0000 1.0000
60.7600 728.0000 1.0000
60.8000 714.0000 1.0000
60.8400 715.0000 1.0000
60.8800 712.0000 1.0000
60.9200 683.0000 1.0000
60.9600 716.0000 1.0000
61.0000 716.0000 1.0000
61.0400 723.0000 1.0000
61.0800 705.0000 1.0000
61.1200 705.0000 1.0000
61.1600 689.0000 1.0000
61.2000 689.0000 1.0000
61.2400 763.0000 1.0000
61.2800 708.0000 1.0000
61.3200 756.0000 1.0000
61.3600 763.0000 1.0000
61.4000 740.0000 1.0000
61.4400 736.0000 1.0000
61.4800 736.0000 1.0000
61.5200 764.0000 1.0000
61.5600 738.0000 1.0000
61.6000 745.0000 1.0000
61.6400 716.0000 1.0000
61.6800 749.0000 1.0000
61.7200 715.0000 1.0000
61.7600 771.0000 1.0000
61.8000 798.0000 1.0000
61.8400 753.0000 1.0000
61.8800 826.0000 1.0000
61.9200 827.0000 1.0000
61.9600 875.0000 1.0000
62.0000 966.0000 1.0000
62.0400 922.0000 1.0000
62.0800 1075.0000 1.0000
62.1200 1153.0000 1.0000
62.1600 1282.0000 1.0000
62.2000 1387.0000 1.0000
62.2400 1592.0000 1.0000
62.2800 1686.0000 1.0000
62.3200 1661.0000 1.0000
62.3600 1735.0000 1.0000
62.4000 1652.0000 1.0000
62.4400 1602.0000 1.0000
62.4800 1496.0000 1.0000
62.5200 1382.0000 1.0000
62.5600 1292.0000 1.0000
62.6000 1201.0000 1.0000
62.6400 1082.0000 1.0000
62.6800 975.0000 1.0000
62.7200 997.0000 1.0000
62.7600 868.0000 1.0000
62.8000 894.0000 1.0000
62.8400 820.0000 1.0000
62.8800 845.0000 1.0000
62.9200 837.0000 1.0000
62.9600 765.0000 1.0000
63.0000 800.0000 1.0000
63.0400 803.0000 1.0000
63.0800 776.0000 1.0000
63.1200 765.0000 1.0000
63.1600 825.0000 1.0000
63.2000 777.0000 1.0000
63.2400 779.0000 1.0000
63.2800 721.0000 1.0000
63.3200 787.0000 1.0000
63.3600 766.0000 1.0000
63.4000 766.0000 1.0000
63.4400 734.0000 1.0000
63.4800 741.0000 1.0000
63.5200 728.0000 1.0000
63.5600 718.0000 1.0000
63.6000 708.0000 1.0000
63.6400 765.0000 1.0000
63.6800 696.0000 1.0000
63.7200 706.0000 1.0000
63.7600 682.0000 1.0000
63.8000 681.0000 1.0000
63.8400 697.0000 1.0000
63.8800 738.0000 1.0000
63.9200 695.0000 1.0000
63.9600 744.0000 1.0000
64.0000 709.0000 1.0000
64.0400 772.0000 1.0000
64.0800 709.0000 1.0000
64.1200 713.0000 1.0000
64.1600 723.0000 1.0000
64.2000 716.0000 1.0000
64.2400 724.0000 1.0000
64.2800 736.0000 1.0000
64.3200 720.0000 1.0000
64.3600 719.0000 1.0000
64.4000 774.0000 1.0000
64.4400 726.0000 1.0000
64.4800 813.0000 1.0000
64.5200 747.0000 1.0000
64.5600 780.0000 1.0000
64.6000 851.0000 1.0000
64.6400 869.0000 1.0000
64.6800 972.0000 1.0000
64.7200 949.0000 1.0000
64.7600 912.0000 1.0000
64.8000 898.0000 1.0000
64.8400 877.0000 1.0000
64.8800 891.0000 1.0000
64.9200 847.0000 1.0000
64.9600 756.0000 1.0000
65.0000 780.0000 1.0000
65.0400 790.0000 1.0000
65.0800 803.0000 1.0000
65.1200 754.0000 1.0000
65.1600 722.0000 1.0000
65.2000 781.0000 1.0000
65.2400 722.0000 1.0000
65.2800 758.0000 1.0000
65.3200 724.0000 1.0000
65.3600 739.0000 1.0000
65.4000 752.0000 1.0000
65.4400 760.0000 1.0000
65.4800 749.0000 1.0000
65.5200 740.0000 1.0000
65.5600 739.0000 1.0000
65.6000 766.0000 1.0000
65.6400 782.0000 1.0000
65.6800 803.0000 1.0000
65.7200 846.0000 1.0000
65.7600 816.0000 1.0000
65.8000 822.0000 1.0000
65.8400 854.0000 1.0000
65.8800 820.0000 1.0000
65.9200 885.0000 1.0000
65.9600 957.0000 1.0000
66.0000 1112.0000 1.0000
66.0400 1204.0000 1.0000
66.0800 1388.0000 1.0000
66.1200 1556.0000 1.0000
66.1600 1874.0000 1.0000
66.2000 2348.0000 1.0000
66.2400 2764.0000 1.0000
66.2800 2912.0000 1.0000
66.3200 2832.0000 1.0000
66.3600 2544.0000 1.0000
66.4000 2397.0000 1.0000
66.4400 2277.0000 1.0000
66.4800 2073.0000 1.0000
66.5200 1808.0000 1.0000
66.5600 1574.0000 1.0000
66.6000 1277.0000 1.0000
66.6400 1090.0000 1.0000
66.6800 1039.0000 1.0000
66.7200 975.0000 1.0000
66.7600 904.0000 1.0000
66.8000 859.0000 1.0000
66.8400 835.0000 1.0000
66.8800 800.0000 1.0000
66.9200 780.0000 1.0000
66.9600 758.0000 1.0000
67.0000 720.0000 1.0000
67.0400 724.0000 1.0000
67.0800 764.0000 1.0000
67.1200 724.0000 1.0000
67.1600 678.0000 1.0000
67.2000 727.0000 1.0000
67.2400 721.0000 1.0000
67.2800 688.0000 1.0000
67.3200 730.0000 1.0000
67.3600 686.0000 1.0000
67.4000 743.0000 1.0000
67.4400 666.0000 1.0000
67.4800 667.0000 1.0000
67.5200 665.0000 1.0000
67.5600 634.0000 1.0000
67.6000 671.0000 1.0000
67.6400 666.0000 1.0000
67.6800 672.0000 1.0000
67.7200 694.0000 1.0000
67.7600 688.0000 1.0000
67.8000 670.0000 1.0000
67.8400 695.0000 1.0000
67.8800 705.0000 1.0000
67.9200 642.0000 1.0000
67.9600 609.0000 1.0000
68.0000 635.0000 1.0000
68.0400 658.0000 1.0000
68.0800 662.0000 1.0000
68.1200 624.0000 1.0000
68.1600 681.0000 1.0000
68.2000 673.0000 1.0000
68.2400 686.0000 1.0000
68.2800 611.0000 1.0000
68.3200 655.0000 1.0000
68.3600 675.0000 1.0000
68.4000 608.0000 1.0000
68.4400 659.0000 1.0000
68.4800 672.0000 1.0000
68.5200 595.0000 1.0000
68.5600 645.0000 1.0000
68.6000 627.0000 1.0000
68.6400 644.0000 1.0000
68.6800 617.0000 1.0000
68.7200 617.0000 1.0000
68.7600 658.0000 1.0000
68.8000 663.0000 1.0000
68.8400 631.0000 1.0000
68.8800 652.0000 1.0000
68.9200 628.0000 1.0000
68.9600 631.0000 1.0000
69.0000 677.0000 1.0000
69.0400 627.0000 1.0000
69.0800 665.0000 1.0000
69.1200 657.0000 1.0000
69.1600 624.0000 1.0000
69.2000 612.0000 1.0000
69.2400 665.0000 1.0000
69.2800 657.0000 1.0000
69.3200 639.0000 1.0000
69.3600 639.0000 1.0000
69.4000 646.0000 1.0000
69.4400 639.0000 1.0000
69.4800 641.0000 1.0000
69.5200 668.0000 1.0000
69.5600 650.0000 1.0000
69.6000 631.0000 1.0000
69.6400 590.0000 1.0000
69.6800 628.0000 1.0000
69.7200 672.0000 1.0000
69.7600 591.0000 1.0000
69.8000 672.0000 1.0000
69.8400 667.0000 1.0000
69.8800 629.0000 1.0000
69.9200 641.0000 1.0000
69.9600 593.0000 1.0000
70.0000 633.0000 1.0000
*RAS_INT_END
*RAS_TEMPERATURE_START
*RAS_TEMPERATURE_END
*RAS_DATA_END