File: Data/Dataset1_Only_water/5_XRD/No_059_deposition_3h_TiO2_Air_6.ras
*RAS_DATA_START
*RAS_HEADER_START
*DISP_FMT_X "%.2f"
*DISP_FMT_Y "%.0f"
*DISP_FULLSCALE "18960.0000000000"
*DISP_LINE_COLOR "255.0000000000"
*DISP_LINE_STYLE "0.0000000000"
*DISP_LINE_WIDTH "0.2500000000"
*DISP_NOTE "測定データ-12"
*DISP_OFFSET_Y "0.0000000000"
*DISP_PEAKSEARCH_UNIT_Y "cps"
*DISP_RANGE_BOTTOM "0.0000000000"
*DISP_RANGE_LEFT "20.0000000000"
*DISP_RANGE_LOGCUTOFF "0.0100000000"
*DISP_RANGE_RIGHT "70.0000000000"
*DISP_RANGE_TOP "18960.0000000000"
*DISP_SCALE_MODE_Y "0.0000000000"
*DISP_TAB_NAME "2θ/θ"
*DISP_TITLE_Y "強度"
*DISP_UNIT_Y "cps"
*DISP_WINDOW_NAME "MSG_MACROENGINE"
*FILE_COMMENT " "
*FILE_MD5 ""
*FILE_MEMO " "
*FILE_OPERATOR "Administrator"
*FILE_SAMPLE " "
*FILE_TYPE "RAS_RAW"
*FILE_USERGROUP "システムマネージャ"
*FILE_VERSION "1.0000000000"
*HW_ATTACHMENT_ID "ATT0025"
*HW_ATTACHMENT_NAME "標準|Standard"
*HW_COUNTER_ID-0 "CUT0025"
*HW_COUNTER_ID-1 "CUT0020"
*HW_COUNTER_ID-2 "CUT0020"
*HW_COUNTER_ID-3 "CSL0021"
*HW_COUNTER_ID-4 "CMC0021"
*HW_COUNTER_NAME-0 "D/teX Ultra|D/teX Ultra"
*HW_COUNTER_NAME-1 "None|None"
*HW_COUNTER_NAME-2 "None|None"
*HW_COUNTER_NAME-3 "BBM|BBM"
*HW_COUNTER_NAME-4 "検出器モノクロメータ|Detector monochromator"
*HW_COUNTER_SELECT_NAME "D/teX Ultra|D/teX Ultra"
*HW_GONIOMETER_ID "GON0023"
*HW_GONIOMETER_NAME "SmartLab|SmartLab"
*HW_GONIOMETER_RADIUS-0 "90.0"
*HW_GONIOMETER_RADIUS-1 "114.0"
*HW_GONIOMETER_RADIUS-2 "190.0"
*HW_GONIOMETER_RADIUS-3 "300.0"
*HW_GONIOMETER_RADIUS-4 "187.0"
*HW_GONIOMETER_RADIUS-5 "300.0"
*HW_GONIOMETER_RADIUS-6 "113.0"
*HW_GONIOMETER_RADIUS-7 "331.0"
*HW_I_OPT_ID-0 "CBO0021"
*HW_I_OPT_ID-1 "ICR0023"
*HW_I_OPT_ID-2 "ISL0021"
*HW_I_OPT_ID-3 "ISO0021"
*HW_I_OPT_ID-4 "IAD0021"
*HW_I_OPT_ID-5 "IPR0001"
*HW_I_OPT_NAME-0 "CBOユニット|CBO unit"
*HW_I_OPT_NAME-1 "標準入射光学ユニット|Standard incident optical unit"
*HW_I_OPT_NAME-2 "標準入射スリットボックス|Standard incident slit box"
*HW_I_OPT_NAME-3 "入射平行スリット|Incident parallel slit"
*HW_I_OPT_NAME-4 "長手制限スリット|Length limiting slit"
*HW_I_OPT_NAME-5 "None|None"
*HW_R_ATTENUATER_AUTOMODE "0"
*HW_R_OPT_ID-0 "RSS0021"
*HW_R_OPT_ID-1 "RCR0023"
*HW_R_OPT_ID-2 "RSO0021"
*HW_R_OPT_ID-3 "RRS0021"
*HW_R_OPT_ID-4 "ATN0021"
*HW_R_OPT_ID-5 "RFL0021"
*HW_R_OPT_ID-6 "RAD0021"
*HW_R_OPT_NAME-0 "標準受光スリットボックス1|Standard receiving slit box # 1"
*HW_R_OPT_NAME-1 "標準受光光学ユニット1|Standard receiving unit # 1"
*HW_R_OPT_NAME-2 "標準受光光学ユニット2|Standard receiving optical unit # 2"
*HW_R_OPT_NAME-3 "標準受光スリットボックス2|Standard receiving slit box # 2"
*HW_R_OPT_NAME-4 "標準アッテネータ|Standard Attenuator"
*HW_R_OPT_NAME-5 "Cu Kβ|Cu K-beta"
*HW_R_OPT_NAME-6 "調整用受光スリット|Alignment receiving slit"
*HW_SAMPLE_HOLDER_ID "SMP0023"
*HW_SAMPLE_HOLDER_NAME "標準Zステージ|Standard Z stage"
*HW_XG_CURRENT_MAX "50"
*HW_XG_CURRENT_MIN "2"
*HW_XG_CURRENT_RESOLUTION "1"
*HW_XG_CURRENT_UNIT "mA"
*HW_XG_FOCUS "1mm x 10mm"
*HW_XG_FOCUS_TYPE "Normal"
*HW_XG_ID ""
*HW_XG_NAME "3kW 封入管(ID:1200)|3kW Sealed tube(ID:1200)"
*HW_XG_TARGET_ATOMIC_NUMBER "29.0000000000"
*HW_XG_TARGET_NAME "Cu"
*HW_XG_TYPE "Hermetic"
*HW_XG_VOLTAGE_MAX "60"
*HW_XG_VOLTAGE_MIN "20"
*HW_XG_VOLTAGE_RESOLUTION "1"
*HW_XG_VOLTAGE_UNIT "kV"
*HW_XG_WATT_MAX "1.500"
*HW_XG_WATT_UNIT "kW"
*HW_XG_WAVE_LENGTH_ALPHA1 "1.540593"
*HW_XG_WAVE_LENGTH_ALPHA2 "1.544414"
*HW_XG_WAVE_LENGTH_BETA "1.392250"
*MEAS_COND_AXIS_NAME-0 "2θ/θ"
*MEAS_COND_AXIS_NAME-1 "2θ"
*MEAS_COND_AXIS_NAME-2 "ω"
*MEAS_COND_AXIS_NAME-3 "Z"
*MEAS_COND_AXIS_NAME-4 "2θ/ω"
*MEAS_COND_AXIS_NAME-5 "θs"
*MEAS_COND_AXIS_NAME-6 "θd"
*MEAS_COND_AXIS_NAME-7 "Ts"
*MEAS_COND_AXIS_NAME-8 "CBO選択スリット"
*MEAS_COND_AXIS_NAME-9 "M"
*MEAS_COND_AXIS_NAME-10 "入射平行スリット"
*MEAS_COND_AXIS_NAME-11 "入射スリット"
*MEAS_COND_AXIS_NAME-12 ""
*MEAS_COND_AXIS_NAME-13 "Zs"
*MEAS_COND_AXIS_NAME-14 "入射光学素子"
*MEAS_COND_AXIS_NAME-15 "長手制限スリット"
*MEAS_COND_AXIS_NAME-16 "センタースリット"
*MEAS_COND_AXIS_NAME-17 "フィルター"
*MEAS_COND_AXIS_NAME-18 "受光スリット1"
*MEAS_COND_AXIS_NAME-19 "受光スリット2"
*MEAS_COND_AXIS_NAME-20 "受光光学素子"
*MEAS_COND_AXIS_NAME-21 "受光平行スリット"
*MEAS_COND_AXIS_NAME-22 "調整用受光スリット"
*MEAS_COND_AXIS_NAME-23 ""
*MEAS_COND_AXIS_NAME-24 ""
*MEAS_COND_AXIS_NAME-25 "Zd"
*MEAS_COND_AXIS_NAME-26 "アッテネータ"
*MEAS_COND_AXIS_NAME-27 "検出器モノクロメータ"
*MEAS_COND_AXIS_NAME-28 "モノクロメータスリット"
*MEAS_COND_AXIS_NAME-29 "プライマリビーム"
*MEAS_COND_AXIS_NAME-30 "PHA"
*MEAS_COND_AXIS_NAME_INTERNAL-0 "TwoThetaTheta"
*MEAS_COND_AXIS_NAME_INTERNAL-1 "TwoTheta"
*MEAS_COND_AXIS_NAME_INTERNAL-2 "Omega"
*MEAS_COND_AXIS_NAME_INTERNAL-3 "Z"
*MEAS_COND_AXIS_NAME_INTERNAL-4 "TwoThetaOmega"
*MEAS_COND_AXIS_NAME_INTERNAL-5 "ThetaS"
*MEAS_COND_AXIS_NAME_INTERNAL-6 "ThetaD"
*MEAS_COND_AXIS_NAME_INTERNAL-7 "Ts"
*MEAS_COND_AXIS_NAME_INTERNAL-8 "CBO"
*MEAS_COND_AXIS_NAME_INTERNAL-9 "CBO-M"
*MEAS_COND_AXIS_NAME_INTERNAL-10 "IncidentSollerSlit"
*MEAS_COND_AXIS_NAME_INTERNAL-11 "IncidentSlitBox"
*MEAS_COND_AXIS_NAME_INTERNAL-12 "IncidentSlitBox-_Axis"
*MEAS_COND_AXIS_NAME_INTERNAL-13 "Zs"
*MEAS_COND_AXIS_NAME_INTERNAL-14 "IncidentMonochromator"
*MEAS_COND_AXIS_NAME_INTERNAL-15 "IncidentAxdSlit"
*MEAS_COND_AXIS_NAME_INTERNAL-16 "CenterSlit"
*MEAS_COND_AXIS_NAME_INTERNAL-17 "Filter"
*MEAS_COND_AXIS_NAME_INTERNAL-18 "ReceivingSlitBox1"
*MEAS_COND_AXIS_NAME_INTERNAL-19 "ReceivingSlitBox2"
*MEAS_COND_AXIS_NAME_INTERNAL-20 "ReceivingOptics"
*MEAS_COND_AXIS_NAME_INTERNAL-21 "ReceivingSollerSlit"
*MEAS_COND_AXIS_NAME_INTERNAL-22 "ReceivingAxdSlit"
*MEAS_COND_AXIS_NAME_INTERNAL-23 "ReceivingSlitBox1-_Axis"
*MEAS_COND_AXIS_NAME_INTERNAL-24 "ReceivingSlitBox2-_Axis"
*MEAS_COND_AXIS_NAME_INTERNAL-25 "ReceivingSlitBox2-Zd"
*MEAS_COND_AXIS_NAME_INTERNAL-26 "Attenuator"
*MEAS_COND_AXIS_NAME_INTERNAL-27 "CounterMonochromator"
*MEAS_COND_AXIS_NAME_INTERNAL-28 "CounterSlit"
*MEAS_COND_AXIS_NAME_INTERNAL-29 "IncidentPrimary"
*MEAS_COND_AXIS_NAME_INTERNAL-30 "PHA"
*MEAS_COND_AXIS_NAME_MAGICNO-0 "83951616.0000000000"
*MEAS_COND_AXIS_NAME_MAGICNO-1 "268632064.0000000000"
*MEAS_COND_AXIS_NAME_MAGICNO-2 "268500992.0000000000"
*MEAS_COND_AXIS_NAME_MAGICNO-3 "285278208.0000000000"
*MEAS_COND_AXIS_NAME_MAGICNO-4 "83951616.0000000000"
*MEAS_COND_AXIS_NAME_MAGICNO-5 "131072.0000000000"
*MEAS_COND_AXIS_NAME_MAGICNO-6 "131072.0000000000"
*MEAS_COND_AXIS_NAME_MAGICNO-7 "318898176.0000000000"
*MEAS_COND_AXIS_NAME_MAGICNO-8 "20971521.0000000000"
*MEAS_COND_AXIS_NAME_MAGICNO-9 "285343744.0000000000"
*MEAS_COND_AXIS_NAME_MAGICNO-10 "20971521.0000000000"
*MEAS_COND_AXIS_NAME_MAGICNO-11 "22020097.0000000000"
*MEAS_COND_AXIS_NAME_MAGICNO-12 "25165824.0000000000"
*MEAS_COND_AXIS_NAME_MAGICNO-13 "318898176.0000000000"
*MEAS_COND_AXIS_NAME_MAGICNO-14 "1.0000000000"
*MEAS_COND_AXIS_NAME_MAGICNO-15 "20971521.0000000000"
*MEAS_COND_AXIS_NAME_MAGICNO-16 "20971521.0000000000"
*MEAS_COND_AXIS_NAME_MAGICNO-17 "20971521.0000000000"
*MEAS_COND_AXIS_NAME_MAGICNO-18 "23068673.0000000000"
*MEAS_COND_AXIS_NAME_MAGICNO-19 "23068673.0000000000"
*MEAS_COND_AXIS_NAME_MAGICNO-20 "20971521.0000000000"
*MEAS_COND_AXIS_NAME_MAGICNO-21 "20971521.0000000000"
*MEAS_COND_AXIS_NAME_MAGICNO-22 "20971521.0000000000"
*MEAS_COND_AXIS_NAME_MAGICNO-23 "25165824.0000000000"
*MEAS_COND_AXIS_NAME_MAGICNO-24 "25165824.0000000000"
*MEAS_COND_AXIS_NAME_MAGICNO-25 "285343744.0000000000"
*MEAS_COND_AXIS_NAME_MAGICNO-26 "17301505.0000000000"
*MEAS_COND_AXIS_NAME_MAGICNO-27 "20971521.0000000000"
*MEAS_COND_AXIS_NAME_MAGICNO-28 "20971521.0000000000"
*MEAS_COND_AXIS_NAME_MAGICNO-29 "20971521.0000000000"
*MEAS_COND_AXIS_NAME_MAGICNO-30 "0.0000000000"
*MEAS_COND_AXIS_OFFSET-0 "-"
*MEAS_COND_AXIS_OFFSET-1 "-0.0801000000"
*MEAS_COND_AXIS_OFFSET-2 "0.1646000000"
*MEAS_COND_AXIS_OFFSET-3 "-"
*MEAS_COND_AXIS_OFFSET-4 "-"
*MEAS_COND_AXIS_OFFSET-5 "0.1646000000"
*MEAS_COND_AXIS_OFFSET-6 "-0.2447000000"
*MEAS_COND_AXIS_OFFSET-7 "-"
*MEAS_COND_AXIS_OFFSET-8 "-"
*MEAS_COND_AXIS_OFFSET-9 "-"
*MEAS_COND_AXIS_OFFSET-10 "-"
*MEAS_COND_AXIS_OFFSET-11 "-"
*MEAS_COND_AXIS_OFFSET-12 "-"
*MEAS_COND_AXIS_OFFSET-13 "-"
*MEAS_COND_AXIS_OFFSET-14 "-"
*MEAS_COND_AXIS_OFFSET-15 "-"
*MEAS_COND_AXIS_OFFSET-16 "-"
*MEAS_COND_AXIS_OFFSET-17 "-"
*MEAS_COND_AXIS_OFFSET-18 "-"
*MEAS_COND_AXIS_OFFSET-19 "-"
*MEAS_COND_AXIS_OFFSET-20 "-"
*MEAS_COND_AXIS_OFFSET-21 "-"
*MEAS_COND_AXIS_OFFSET-22 "-"
*MEAS_COND_AXIS_OFFSET-23 "-"
*MEAS_COND_AXIS_OFFSET-24 "-"
*MEAS_COND_AXIS_OFFSET-25 "-"
*MEAS_COND_AXIS_OFFSET-26 "-"
*MEAS_COND_AXIS_OFFSET-27 "-"
*MEAS_COND_AXIS_OFFSET-28 "-"
*MEAS_COND_AXIS_OFFSET-29 "-"
*MEAS_COND_AXIS_OFFSET-30 "-"
*MEAS_COND_AXIS_POSITION-0 "0.0000000000"
*MEAS_COND_AXIS_POSITION-1 "0.0000000000"
*MEAS_COND_AXIS_POSITION-2 "0.0000000000"
*MEAS_COND_AXIS_POSITION-3 "-2.9256400000"
*MEAS_COND_AXIS_POSITION-4 "0.0000000000"
*MEAS_COND_AXIS_POSITION-5 "0.0000000000"
*MEAS_COND_AXIS_POSITION-6 "0.0000000000"
*MEAS_COND_AXIS_POSITION-7 "-0.4278800000"
*MEAS_COND_AXIS_POSITION-8 "BB"
*MEAS_COND_AXIS_POSITION-9 "0.0000000000"
*MEAS_COND_AXIS_POSITION-10 "Soller_slit_5.0deg"
*MEAS_COND_AXIS_POSITION-11 "2/3deg"
*MEAS_COND_AXIS_POSITION-12 "2.2088000000"
*MEAS_COND_AXIS_POSITION-13 "-1.0609400000"
*MEAS_COND_AXIS_POSITION-14 "0.0000000000"
*MEAS_COND_AXIS_POSITION-15 "10.0mm"
*MEAS_COND_AXIS_POSITION-16 "None"
*MEAS_COND_AXIS_POSITION-17 "Cu_K-beta"
*MEAS_COND_AXIS_POSITION-18 "13.000mm"
*MEAS_COND_AXIS_POSITION-19 "13.000mm"
*MEAS_COND_AXIS_POSITION-20 "No_unit"
*MEAS_COND_AXIS_POSITION-21 "Soller_slit_5.0deg"
*MEAS_COND_AXIS_POSITION-22 "None"
*MEAS_COND_AXIS_POSITION-23 "13.0000000000"
*MEAS_COND_AXIS_POSITION-24 "13.0000000000"
*MEAS_COND_AXIS_POSITION-25 "0.0081300000"
*MEAS_COND_AXIS_POSITION-26 "Open"
*MEAS_COND_AXIS_POSITION-27 "None"
*MEAS_COND_AXIS_POSITION-28 "None"
*MEAS_COND_AXIS_POSITION-29 "None"
*MEAS_COND_AXIS_POSITION-30 "38.0000000000"
*MEAS_COND_AXIS_UNIT-0 "deg"
*MEAS_COND_AXIS_UNIT-1 "deg"
*MEAS_COND_AXIS_UNIT-2 "deg"
*MEAS_COND_AXIS_UNIT-3 "mm"
*MEAS_COND_AXIS_UNIT-4 "deg"
*MEAS_COND_AXIS_UNIT-5 "deg"
*MEAS_COND_AXIS_UNIT-6 "deg"
*MEAS_COND_AXIS_UNIT-7 "mm"
*MEAS_COND_AXIS_UNIT-8 ""
*MEAS_COND_AXIS_UNIT-9 "pulse"
*MEAS_COND_AXIS_UNIT-10 ""
*MEAS_COND_AXIS_UNIT-11 ""
*MEAS_COND_AXIS_UNIT-12 "mm"
*MEAS_COND_AXIS_UNIT-13 "mm"
*MEAS_COND_AXIS_UNIT-14 ""
*MEAS_COND_AXIS_UNIT-15 ""
*MEAS_COND_AXIS_UNIT-16 ""
*MEAS_COND_AXIS_UNIT-17 ""
*MEAS_COND_AXIS_UNIT-18 ""
*MEAS_COND_AXIS_UNIT-19 ""
*MEAS_COND_AXIS_UNIT-20 ""
*MEAS_COND_AXIS_UNIT-21 ""
*MEAS_COND_AXIS_UNIT-22 ""
*MEAS_COND_AXIS_UNIT-23 "mm"
*MEAS_COND_AXIS_UNIT-24 "mm"
*MEAS_COND_AXIS_UNIT-25 "mm"
*MEAS_COND_AXIS_UNIT-26 ""
*MEAS_COND_AXIS_UNIT-27 ""
*MEAS_COND_AXIS_UNIT-28 ""
*MEAS_COND_AXIS_UNIT-29 ""
*MEAS_COND_AXIS_UNIT-30 "div"
*MEAS_COND_COUNTER_CNTLOSS_CORR "0.0000000000"
*MEAS_COND_COUNTER_PHABASE "38.0000000000"
*MEAS_COND_COUNTER_PHAWINDOW "16.0000000000"
*MEAS_COND_COUNTER_PHA_UNIT "div"
*MEAS_COND_COUNTER_TAUDIFF "30.0000000000"
*MEAS_COND_COUNTER_TAUINT "0.0000000000"
*MEAS_COND_IRRADIATION_MODE "OFF"
*MEAS_COND_IRRADIATION_WIDTH ""
*MEAS_COND_OPT_ATTR "集中法"
*MEAS_COND_OPT_NAME "@集中法"
*MEAS_COND_UNSYMMETRIC_MODE "OFF"
*MEAS_COND_XG_CURRENT "30.0000000000"
*MEAS_COND_XG_VOLTAGE "40.0000000000"
*MEAS_COND_XG_WAVE_TYPE "Ka"
*MEAS_DATA_COUNT "5001.0000000000"
*MEAS_SCAN_AXIS_X "2θ/θ"
*MEAS_SCAN_AXIS_X_INTERNAL "TwoThetaTheta"
*MEAS_SCAN_END_TIME "07/09/22 17:24:59"
*MEAS_SCAN_MODE "CONTINUOUS"
*MEAS_SCAN_MONITOR "0"
*MEAS_SCAN_RESOLUTION_X "0.0002"
*MEAS_SCAN_SPEED "2.5"
*MEAS_SCAN_SPEED_UNIT "deg/min"
*MEAS_SCAN_START "20.0000000000"
*MEAS_SCAN_START_TIME "07/09/22 17:03:36"
*MEAS_SCAN_STEP "0.0100000000"
*MEAS_SCAN_STOP "70.0000000000"
*MEAS_SCAN_UNIT_X "deg"
*MEAS_SCAN_UNIT_Y "counts"
*RAS_HEADER_END
*RAS_INT_START
20.0000 1029.0000 1.0000
20.0400 960.0000 1.0000
20.0800 1031.0000 1.0000
20.1200 997.0000 1.0000
20.1600 1040.0000 1.0000
20.2000 1002.0000 1.0000
20.2400 1017.0000 1.0000
20.2800 997.0000 1.0000
20.3200 991.0000 1.0000
20.3600 1006.0000 1.0000
20.4000 980.0000 1.0000
20.4400 979.0000 1.0000
20.4800 1004.0000 1.0000
20.5200 1009.0000 1.0000
20.5600 1002.0000 1.0000
20.6000 969.0000 1.0000
20.6400 989.0000 1.0000
20.6800 938.0000 1.0000
20.7200 1054.0000 1.0000
20.7600 971.0000 1.0000
20.8000 961.0000 1.0000
20.8400 1010.0000 1.0000
20.8800 976.0000 1.0000
20.9200 968.0000 1.0000
20.9600 993.0000 1.0000
21.0000 975.0000 1.0000
21.0400 988.0000 1.0000
21.0800 939.0000 1.0000
21.1200 982.0000 1.0000
21.1600 982.0000 1.0000
21.2000 976.0000 1.0000
21.2400 962.0000 1.0000
21.2800 992.0000 1.0000
21.3200 1019.0000 1.0000
21.3600 973.0000 1.0000
21.4000 992.0000 1.0000
21.4400 994.0000 1.0000
21.4800 1031.0000 1.0000
21.5200 1068.0000 1.0000
21.5600 1005.0000 1.0000
21.6000 1000.0000 1.0000
21.6400 977.0000 1.0000
21.6800 985.0000 1.0000
21.7200 975.0000 1.0000
21.7600 967.0000 1.0000
21.8000 977.0000 1.0000
21.8400 1013.0000 1.0000
21.8800 1001.0000 1.0000
21.9200 1002.0000 1.0000
21.9600 1037.0000 1.0000
22.0000 972.0000 1.0000
22.0400 1003.0000 1.0000
22.0800 1030.0000 1.0000
22.1200 1005.0000 1.0000
22.1600 1010.0000 1.0000
22.2000 945.0000 1.0000
22.2400 1004.0000 1.0000
22.2800 997.0000 1.0000
22.3200 980.0000 1.0000
22.3600 961.0000 1.0000
22.4000 997.0000 1.0000
22.4400 970.0000 1.0000
22.4800 974.0000 1.0000
22.5200 1003.0000 1.0000
22.5600 1013.0000 1.0000
22.6000 983.0000 1.0000
22.6400 987.0000 1.0000
22.6800 956.0000 1.0000
22.7200 983.0000 1.0000
22.7600 1000.0000 1.0000
22.8000 995.0000 1.0000
22.8400 1000.0000 1.0000
22.8800 922.0000 1.0000
22.9200 954.0000 1.0000
22.9600 1006.0000 1.0000
23.0000 951.0000 1.0000
23.0400 1018.0000 1.0000
23.0800 956.0000 1.0000
23.1200 1000.0000 1.0000
23.1600 989.0000 1.0000
23.2000 982.0000 1.0000
23.2400 978.0000 1.0000
23.2800 963.0000 1.0000
23.3200 958.0000 1.0000
23.3600 960.0000 1.0000
23.4000 943.0000 1.0000
23.4400 972.0000 1.0000
23.4800 1001.0000 1.0000
23.5200 949.0000 1.0000
23.5600 1018.0000 1.0000
23.6000 1036.0000 1.0000
23.6400 992.0000 1.0000
23.6800 1001.0000 1.0000
23.7200 981.0000 1.0000
23.7600 1048.0000 1.0000
23.8000 967.0000 1.0000
23.8400 985.0000 1.0000
23.8800 1043.0000 1.0000
23.9200 1039.0000 1.0000
23.9600 1034.0000 1.0000
24.0000 1074.0000 1.0000
24.0400 1077.0000 1.0000
24.0800 1075.0000 1.0000
24.1200 1072.0000 1.0000
24.1600 1027.0000 1.0000
24.2000 1077.0000 1.0000
24.2400 1008.0000 1.0000
24.2800 1035.0000 1.0000
24.3200 1005.0000 1.0000
24.3600 1033.0000 1.0000
24.4000 985.0000 1.0000
24.4400 1003.0000 1.0000
24.4800 1012.0000 1.0000
24.5200 972.0000 1.0000
24.5600 988.0000 1.0000
24.6000 973.0000 1.0000
24.6400 983.0000 1.0000
24.6800 945.0000 1.0000
24.7200 915.0000 1.0000
24.7600 1009.0000 1.0000
24.8000 965.0000 1.0000
24.8400 991.0000 1.0000
24.8800 949.0000 1.0000
24.9200 992.0000 1.0000
24.9600 956.0000 1.0000
25.0000 957.0000 1.0000
25.0400 992.0000 1.0000
25.0800 973.0000 1.0000
25.1200 979.0000 1.0000
25.1600 947.0000 1.0000
25.2000 1015.0000 1.0000
25.2400 946.0000 1.0000
25.2800 936.0000 1.0000
25.3200 933.0000 1.0000
25.3600 1012.0000 1.0000
25.4000 964.0000 1.0000
25.4400 937.0000 1.0000
25.4800 941.0000 1.0000
25.5200 958.0000 1.0000
25.5600 998.0000 1.0000
25.6000 970.0000 1.0000
25.6400 954.0000 1.0000
25.6800 969.0000 1.0000
25.7200 977.0000 1.0000
25.7600 991.0000 1.0000
25.8000 963.0000 1.0000
25.8400 1031.0000 1.0000
25.8800 994.0000 1.0000
25.9200 1042.0000 1.0000
25.9600 1053.0000 1.0000
26.0000 1061.0000 1.0000
26.0400 1039.0000 1.0000
26.0800 1171.0000 1.0000
26.1200 1214.0000 1.0000
26.1600 1310.0000 1.0000
26.2000 1468.0000 1.0000
26.2400 1635.0000 1.0000
26.2800 1838.0000 1.0000
26.3200 2242.0000 1.0000
26.3600 2939.0000 1.0000
26.4000 3523.0000 1.0000
26.4400 3649.0000 1.0000
26.4800 3479.0000 1.0000
26.5200 2909.0000 1.0000
26.5600 2289.0000 1.0000
26.6000 1876.0000 1.0000
26.6400 1611.0000 1.0000
26.6800 1464.0000 1.0000
26.7200 1252.0000 1.0000
26.7600 1204.0000 1.0000
26.8000 1147.0000 1.0000
26.8400 1102.0000 1.0000
26.8800 1042.0000 1.0000
26.9200 1029.0000 1.0000
26.9600 1069.0000 1.0000
27.0000 1001.0000 1.0000
27.0400 940.0000 1.0000
27.0800 948.0000 1.0000
27.1200 948.0000 1.0000
27.1600 948.0000 1.0000
27.2000 932.0000 1.0000
27.2400 942.0000 1.0000
27.2800 937.0000 1.0000
27.3200 921.0000 1.0000
27.3600 892.0000 1.0000
27.4000 932.0000 1.0000
27.4400 959.0000 1.0000
27.4800 920.0000 1.0000
27.5200 889.0000 1.0000
27.5600 953.0000 1.0000
27.6000 881.0000 1.0000
27.6400 873.0000 1.0000
27.6800 873.0000 1.0000
27.7200 899.0000 1.0000
27.7600 887.0000 1.0000
27.8000 911.0000 1.0000
27.8400 889.0000 1.0000
27.8800 825.0000 1.0000
27.9200 850.0000 1.0000
27.9600 860.0000 1.0000
28.0000 851.0000 1.0000
28.0400 913.0000 1.0000
28.0800 831.0000 1.0000
28.1200 856.0000 1.0000
28.1600 913.0000 1.0000
28.2000 889.0000 1.0000
28.2400 824.0000 1.0000
28.2800 848.0000 1.0000
28.3200 889.0000 1.0000
28.3600 836.0000 1.0000
28.4000 863.0000 1.0000
28.4400 824.0000 1.0000
28.4800 821.0000 1.0000
28.5200 870.0000 1.0000
28.5600 870.0000 1.0000
28.6000 826.0000 1.0000
28.6400 794.0000 1.0000
28.6800 823.0000 1.0000
28.7200 838.0000 1.0000
28.7600 859.0000 1.0000
28.8000 803.0000 1.0000
28.8400 822.0000 1.0000
28.8800 800.0000 1.0000
28.9200 829.0000 1.0000
28.9600 856.0000 1.0000
29.0000 836.0000 1.0000
29.0400 819.0000 1.0000
29.0800 827.0000 1.0000
29.1200 788.0000 1.0000
29.1600 819.0000 1.0000
29.2000 787.0000 1.0000
29.2400 831.0000 1.0000
29.2800 807.0000 1.0000
29.3200 795.0000 1.0000
29.3600 820.0000 1.0000
29.4000 791.0000 1.0000
29.4400 846.0000 1.0000
29.4800 775.0000 1.0000
29.5200 833.0000 1.0000
29.5600 809.0000 1.0000
29.6000 802.0000 1.0000
29.6400 813.0000 1.0000
29.6800 792.0000 1.0000
29.7200 761.0000 1.0000
29.7600 776.0000 1.0000
29.8000 746.0000 1.0000
29.8400 747.0000 1.0000
29.8800 788.0000 1.0000
29.9200 770.0000 1.0000
29.9600 781.0000 1.0000
30.0000 819.0000 1.0000
30.0400 771.0000 1.0000
30.0800 790.0000 1.0000
30.1200 743.0000 1.0000
30.1600 745.0000 1.0000
30.2000 771.0000 1.0000
30.2400 758.0000 1.0000
30.2800 800.0000 1.0000
30.3200 744.0000 1.0000
30.3600 807.0000 1.0000
30.4000 776.0000 1.0000
30.4400 775.0000 1.0000
30.4800 782.0000 1.0000
30.5200 771.0000 1.0000
30.5600 744.0000 1.0000
30.6000 786.0000 1.0000
30.6400 746.0000 1.0000
30.6800 805.0000 1.0000
30.7200 722.0000 1.0000
30.7600 781.0000 1.0000
30.8000 741.0000 1.0000
30.8400 785.0000 1.0000
30.8800 772.0000 1.0000
30.9200 742.0000 1.0000
30.9600 770.0000 1.0000
31.0000 794.0000 1.0000
31.0400 802.0000 1.0000
31.0800 783.0000 1.0000
31.1200 760.0000 1.0000
31.1600 789.0000 1.0000
31.2000 727.0000 1.0000
31.2400 768.0000 1.0000
31.2800 726.0000 1.0000
31.3200 742.0000 1.0000
31.3600 762.0000 1.0000
31.4000 716.0000 1.0000
31.4400 753.0000 1.0000
31.4800 754.0000 1.0000
31.5200 738.0000 1.0000
31.5600 716.0000 1.0000
31.6000 747.0000 1.0000
31.6400 734.0000 1.0000
31.6800 719.0000 1.0000
31.7200 750.0000 1.0000
31.7600 774.0000 1.0000
31.8000 749.0000 1.0000
31.8400 738.0000 1.0000
31.8800 735.0000 1.0000
31.9200 717.0000 1.0000
31.9600 700.0000 1.0000
32.0000 727.0000 1.0000
32.0400 730.0000 1.0000
32.0800 745.0000 1.0000
32.1200 744.0000 1.0000
32.1600 682.0000 1.0000
32.2000 724.0000 1.0000
32.2400 705.0000 1.0000
32.2800 725.0000 1.0000
32.3200 725.0000 1.0000
32.3600 687.0000 1.0000
32.4000 715.0000 1.0000
32.4400 763.0000 1.0000
32.4800 731.0000 1.0000
32.5200 724.0000 1.0000
32.5600 728.0000 1.0000
32.6000 709.0000 1.0000
32.6400 729.0000 1.0000
32.6800 739.0000 1.0000
32.7200 741.0000 1.0000
32.7600 726.0000 1.0000
32.8000 734.0000 1.0000
32.8400 759.0000 1.0000
32.8800 733.0000 1.0000
32.9200 833.0000 1.0000
32.9600 809.0000 1.0000
33.0000 893.0000 1.0000
33.0400 941.0000 1.0000
33.0800 1019.0000 1.0000
33.1200 1006.0000 1.0000
33.1600 956.0000 1.0000
33.2000 911.0000 1.0000
33.2400 889.0000 1.0000
33.2800 902.0000 1.0000
33.3200 858.0000 1.0000
33.3600 863.0000 1.0000
33.4000 846.0000 1.0000
33.4400 930.0000 1.0000
33.4800 1067.0000 1.0000
33.5200 1135.0000 1.0000
33.5600 1431.0000 1.0000
33.6000 1733.0000 1.0000
33.6400 1759.0000 1.0000
33.6800 1738.0000 1.0000
33.7200 1670.0000 1.0000
33.7600 1423.0000 1.0000
33.8000 1160.0000 1.0000
33.8400 999.0000 1.0000
33.8800 888.0000 1.0000
33.9200 875.0000 1.0000
33.9600 820.0000 1.0000
34.0000 799.0000 1.0000
34.0400 741.0000 1.0000
34.0800 724.0000 1.0000
34.1200 723.0000 1.0000
34.1600 687.0000 1.0000
34.2000 663.0000 1.0000
34.2400 659.0000 1.0000
34.2800 652.0000 1.0000
34.3200 687.0000 1.0000
34.3600 643.0000 1.0000
34.4000 592.0000 1.0000
34.4400 672.0000 1.0000
34.4800 632.0000 1.0000
34.5200 629.0000 1.0000
34.5600 657.0000 1.0000
34.6000 601.0000 1.0000
34.6400 655.0000 1.0000
34.6800 626.0000 1.0000
34.7200 655.0000 1.0000
34.7600 624.0000 1.0000
34.8000 628.0000 1.0000
34.8400 627.0000 1.0000
34.8800 600.0000 1.0000
34.9200 624.0000 1.0000
34.9600 611.0000 1.0000
35.0000 601.0000 1.0000
35.0400 636.0000 1.0000
35.0800 629.0000 1.0000
35.1200 583.0000 1.0000
35.1600 618.0000 1.0000
35.2000 642.0000 1.0000
35.2400 620.0000 1.0000
35.2800 635.0000 1.0000
35.3200 672.0000 1.0000
35.3600 744.0000 1.0000
35.4000 734.0000 1.0000
35.4400 716.0000 1.0000
35.4800 829.0000 1.0000
35.5200 864.0000 1.0000
35.5600 864.0000 1.0000
35.6000 920.0000 1.0000
35.6400 838.0000 1.0000
35.6800 798.0000 1.0000
35.7200 715.0000 1.0000
35.7600 667.0000 1.0000
35.8000 606.0000 1.0000
35.8400 601.0000 1.0000
35.8800 552.0000 1.0000
35.9200 555.0000 1.0000
35.9600 604.0000 1.0000
36.0000 590.0000 1.0000
36.0400 556.0000 1.0000
36.0800 528.0000 1.0000
36.1200 545.0000 1.0000
36.1600 546.0000 1.0000
36.2000 549.0000 1.0000
36.2400 586.0000 1.0000
36.2800 564.0000 1.0000
36.3200 535.0000 1.0000
36.3600 551.0000 1.0000
36.4000 577.0000 1.0000
36.4400 574.0000 1.0000
36.4800 576.0000 1.0000
36.5200 583.0000 1.0000
36.5600 581.0000 1.0000
36.6000 540.0000 1.0000
36.6400 557.0000 1.0000
36.6800 556.0000 1.0000
36.7200 541.0000 1.0000
36.7600 562.0000 1.0000
36.8000 585.0000 1.0000
36.8400 524.0000 1.0000
36.8800 545.0000 1.0000
36.9200 578.0000 1.0000
36.9600 558.0000 1.0000
37.0000 574.0000 1.0000
37.0400 587.0000 1.0000
37.0800 573.0000 1.0000
37.1200 591.0000 1.0000
37.1600 610.0000 1.0000
37.2000 582.0000 1.0000
37.2400 624.0000 1.0000
37.2800 624.0000 1.0000
37.3200 629.0000 1.0000
37.3600 683.0000 1.0000
37.4000 710.0000 1.0000
37.4400 861.0000 1.0000
37.4800 978.0000 1.0000
37.5200 1241.0000 1.0000
37.5600 1526.0000 1.0000
37.6000 1887.0000 1.0000
37.6400 2422.0000 1.0000
37.6800 2811.0000 1.0000
37.7200 2914.0000 1.0000
37.7600 2738.0000 1.0000
37.8000 2306.0000 1.0000
37.8400 1950.0000 1.0000
37.8800 1460.0000 1.0000
37.9200 1135.0000 1.0000
37.9600 958.0000 1.0000
38.0000 835.0000 1.0000
38.0400 724.0000 1.0000
38.0800 633.0000 1.0000
38.1200 596.0000 1.0000
38.1600 613.0000 1.0000
38.2000 563.0000 1.0000
38.2400 569.0000 1.0000
38.2800 522.0000 1.0000
38.3200 520.0000 1.0000
38.3600 516.0000 1.0000
38.4000 554.0000 1.0000
38.4400 490.0000 1.0000
38.4800 517.0000 1.0000
38.5200 531.0000 1.0000
38.5600 542.0000 1.0000
38.6000 538.0000 1.0000
38.6400 496.0000 1.0000
38.6800 550.0000 1.0000
38.7200 508.0000 1.0000
38.7600 545.0000 1.0000
38.8000 519.0000 1.0000
38.8400 491.0000 1.0000
38.8800 514.0000 1.0000
38.9200 524.0000 1.0000
38.9600 483.0000 1.0000
39.0000 483.0000 1.0000
39.0400 498.0000 1.0000
39.0800 475.0000 1.0000
39.1200 509.0000 1.0000
39.1600 519.0000 1.0000
39.2000 488.0000 1.0000
39.2400 536.0000 1.0000
39.2800 480.0000 1.0000
39.3200 486.0000 1.0000
39.3600 467.0000 1.0000
39.4000 472.0000 1.0000
39.4400 500.0000 1.0000
39.4800 491.0000 1.0000
39.5200 512.0000 1.0000
39.5600 485.0000 1.0000
39.6000 472.0000 1.0000
39.6400 452.0000 1.0000
39.6800 486.0000 1.0000
39.7200 459.0000 1.0000
39.7600 484.0000 1.0000
39.8000 459.0000 1.0000
39.8400 445.0000 1.0000
39.8800 522.0000 1.0000
39.9200 467.0000 1.0000
39.9600 504.0000 1.0000
40.0000 458.0000 1.0000
40.0400 469.0000 1.0000
40.0800 430.0000 1.0000
40.1200 466.0000 1.0000
40.1600 433.0000 1.0000
40.2000 472.0000 1.0000
40.2400 486.0000 1.0000
40.2800 512.0000 1.0000
40.3200 458.0000 1.0000
40.3600 481.0000 1.0000
40.4000 437.0000 1.0000
40.4400 449.0000 1.0000
40.4800 445.0000 1.0000
40.5200 466.0000 1.0000
40.5600 485.0000 1.0000
40.6000 482.0000 1.0000
40.6400 474.0000 1.0000
40.6800 500.0000 1.0000
40.7200 513.0000 1.0000
40.7600 475.0000 1.0000
40.8000 594.0000 1.0000
40.8400 548.0000 1.0000
40.8800 516.0000 1.0000
40.9200 530.0000 1.0000
40.9600 485.0000 1.0000
41.0000 536.0000 1.0000
41.0400 462.0000 1.0000
41.0800 476.0000 1.0000
41.1200 490.0000 1.0000
41.1600 456.0000 1.0000
41.2000 445.0000 1.0000
41.2400 438.0000 1.0000
41.2800 465.0000 1.0000
41.3200 457.0000 1.0000
41.3600 428.0000 1.0000
41.4000 445.0000 1.0000
41.4400 446.0000 1.0000
41.4800 452.0000 1.0000
41.5200 420.0000 1.0000
41.5600 459.0000 1.0000
41.6000 453.0000 1.0000
41.6400 463.0000 1.0000
41.6800 413.0000 1.0000
41.7200 438.0000 1.0000
41.7600 465.0000 1.0000
41.8000 445.0000 1.0000
41.8400 433.0000 1.0000
41.8800 479.0000 1.0000
41.9200 438.0000 1.0000
41.9600 460.0000 1.0000
42.0000 440.0000 1.0000
42.0400 455.0000 1.0000
42.0800 456.0000 1.0000
42.1200 481.0000 1.0000
42.1600 484.0000 1.0000
42.2000 444.0000 1.0000
42.2400 461.0000 1.0000
42.2800 498.0000 1.0000
42.3200 482.0000 1.0000
42.3600 473.0000 1.0000
42.4000 515.0000 1.0000
42.4400 472.0000 1.0000
42.4800 489.0000 1.0000
42.5200 490.0000 1.0000
42.5600 451.0000 1.0000
42.6000 481.0000 1.0000
42.6400 448.0000 1.0000
42.6800 473.0000 1.0000
42.7200 469.0000 1.0000
42.7600 446.0000 1.0000
42.8000 442.0000 1.0000
42.8400 458.0000 1.0000
42.8800 427.0000 1.0000
42.9200 445.0000 1.0000
42.9600 448.0000 1.0000
43.0000 431.0000 1.0000
43.0400 449.0000 1.0000
43.0800 424.0000 1.0000
43.1200 431.0000 1.0000
43.1600 482.0000 1.0000
43.2000 420.0000 1.0000
43.2400 436.0000 1.0000
43.2800 424.0000 1.0000
43.3200 431.0000 1.0000
43.3600 404.0000 1.0000
43.4000 441.0000 1.0000
43.4400 446.0000 1.0000
43.4800 462.0000 1.0000
43.5200 434.0000 1.0000
43.5600 468.0000 1.0000
43.6000 414.0000 1.0000
43.6400 466.0000 1.0000
43.6800 425.0000 1.0000
43.7200 461.0000 1.0000
43.7600 416.0000 1.0000
43.8000 429.0000 1.0000
43.8400 430.0000 1.0000
43.8800 449.0000 1.0000
43.9200 413.0000 1.0000
43.9600 453.0000 1.0000
44.0000 469.0000 1.0000
44.0400 425.0000 1.0000
44.0800 427.0000 1.0000
44.1200 437.0000 1.0000
44.1600 433.0000 1.0000
44.2000 451.0000 1.0000
44.2400 465.0000 1.0000
44.2800 450.0000 1.0000
44.3200 431.0000 1.0000
44.3600 418.0000 1.0000
44.4000 410.0000 1.0000
44.4400 387.0000 1.0000
44.4800 419.0000 1.0000
44.5200 447.0000 1.0000
44.5600 423.0000 1.0000
44.6000 418.0000 1.0000
44.6400 428.0000 1.0000
44.6800 439.0000 1.0000
44.7200 399.0000 1.0000
44.7600 433.0000 1.0000
44.8000 408.0000 1.0000
44.8400 438.0000 1.0000
44.8800 396.0000 1.0000
44.9200 400.0000 1.0000
44.9600 406.0000 1.0000
45.0000 461.0000 1.0000
45.0400 441.0000 1.0000
45.0800 413.0000 1.0000
45.1200 428.0000 1.0000
45.1600 412.0000 1.0000
45.2000 422.0000 1.0000
45.2400 418.0000 1.0000
45.2800 391.0000 1.0000
45.3200 408.0000 1.0000
45.3600 435.0000 1.0000
45.4000 404.0000 1.0000
45.4400 404.0000 1.0000
45.4800 424.0000 1.0000
45.5200 428.0000 1.0000
45.5600 413.0000 1.0000
45.6000 421.0000 1.0000
45.6400 443.0000 1.0000
45.6800 382.0000 1.0000
45.7200 392.0000 1.0000
45.7600 410.0000 1.0000
45.8000 393.0000 1.0000
45.8400 411.0000 1.0000
45.8800 449.0000 1.0000
45.9200 409.0000 1.0000
45.9600 381.0000 1.0000
46.0000 418.0000 1.0000
46.0400 429.0000 1.0000
46.0800 406.0000 1.0000
46.1200 396.0000 1.0000
46.1600 421.0000 1.0000
46.2000 436.0000 1.0000
46.2400 423.0000 1.0000
46.2800 433.0000 1.0000
46.3200 372.0000 1.0000
46.3600 405.0000 1.0000
46.4000 411.0000 1.0000
46.4400 377.0000 1.0000
46.4800 388.0000 1.0000
46.5200 366.0000 1.0000
46.5600 393.0000 1.0000
46.6000 368.0000 1.0000
46.6400 400.0000 1.0000
46.6800 404.0000 1.0000
46.7200 362.0000 1.0000
46.7600 411.0000 1.0000
46.8000 392.0000 1.0000
46.8400 425.0000 1.0000
46.8800 381.0000 1.0000
46.9200 398.0000 1.0000
46.9600 380.0000 1.0000
47.0000 395.0000 1.0000
47.0400 372.0000 1.0000
47.0800 419.0000 1.0000
47.1200 410.0000 1.0000
47.1600 389.0000 1.0000
47.2000 388.0000 1.0000
47.2400 384.0000 1.0000
47.2800 377.0000 1.0000
47.3200 390.0000 1.0000
47.3600 387.0000 1.0000
47.4000 378.0000 1.0000
47.4400 372.0000 1.0000
47.4800 384.0000 1.0000
47.5200 411.0000 1.0000
47.5600 392.0000 1.0000
47.6000 357.0000 1.0000
47.6400 384.0000 1.0000
47.6800 369.0000 1.0000
47.7200 370.0000 1.0000
47.7600 429.0000 1.0000
47.8000 381.0000 1.0000
47.8400 389.0000 1.0000
47.8800 404.0000 1.0000
47.9200 407.0000 1.0000
47.9600 375.0000 1.0000
48.0000 371.0000 1.0000
48.0400 398.0000 1.0000
48.0800 377.0000 1.0000
48.1200 385.0000 1.0000
48.1600 362.0000 1.0000
48.2000 367.0000 1.0000
48.2400 385.0000 1.0000
48.2800 380.0000 1.0000
48.3200 403.0000 1.0000
48.3600 387.0000 1.0000
48.4000 366.0000 1.0000
48.4400 357.0000 1.0000
48.4800 390.0000 1.0000
48.5200 375.0000 1.0000
48.5600 372.0000 1.0000
48.6000 355.0000 1.0000
48.6400 408.0000 1.0000
48.6800 409.0000 1.0000
48.7200 397.0000 1.0000
48.7600 355.0000 1.0000
48.8000 390.0000 1.0000
48.8400 376.0000 1.0000
48.8800 347.0000 1.0000
48.9200 374.0000 1.0000
48.9600 394.0000 1.0000
49.0000 378.0000 1.0000
49.0400 399.0000 1.0000
49.0800 379.0000 1.0000
49.1200 402.0000 1.0000
49.1600 414.0000 1.0000
49.2000 445.0000 1.0000
49.2400 423.0000 1.0000
49.2800 412.0000 1.0000
49.3200 416.0000 1.0000
49.3600 448.0000 1.0000
49.4000 456.0000 1.0000
49.4400 478.0000 1.0000
49.4800 465.0000 1.0000
49.5200 432.0000 1.0000
49.5600 402.0000 1.0000
49.6000 445.0000 1.0000
49.6400 406.0000 1.0000
49.6800 411.0000 1.0000
49.7200 435.0000 1.0000
49.7600 371.0000 1.0000
49.8000 403.0000 1.0000
49.8400 377.0000 1.0000
49.8800 407.0000 1.0000
49.9200 349.0000 1.0000
49.9600 418.0000 1.0000
50.0000 362.0000 1.0000
50.0400 401.0000 1.0000
50.0800 397.0000 1.0000
50.1200 374.0000 1.0000
50.1600 370.0000 1.0000
50.2000 415.0000 1.0000
50.2400 398.0000 1.0000
50.2800 394.0000 1.0000
50.3200 376.0000 1.0000
50.3600 394.0000 1.0000
50.4000 362.0000 1.0000
50.4400 387.0000 1.0000
50.4800 371.0000 1.0000
50.5200 386.0000 1.0000
50.5600 398.0000 1.0000
50.6000 409.0000 1.0000
50.6400 401.0000 1.0000
50.6800 390.0000 1.0000
50.7200 386.0000 1.0000
50.7600 389.0000 1.0000
50.8000 373.0000 1.0000
50.8400 393.0000 1.0000
50.8800 377.0000 1.0000
50.9200 380.0000 1.0000
50.9600 407.0000 1.0000
51.0000 425.0000 1.0000
51.0400 470.0000 1.0000
51.0800 449.0000 1.0000
51.1200 509.0000 1.0000
51.1600 564.0000 1.0000
51.2000 558.0000 1.0000
51.2400 617.0000 1.0000
51.2800 821.0000 1.0000
51.3200 1034.0000 1.0000
51.3600 1394.0000 1.0000
51.4000 1803.0000 1.0000
51.4400 2259.0000 1.0000
51.4800 2603.0000 1.0000
51.5200 2498.0000 1.0000
51.5600 2227.0000 1.0000
51.6000 1926.0000 1.0000
51.6400 1651.0000 1.0000
51.6800 1344.0000 1.0000
51.7200 984.0000 1.0000
51.7600 819.0000 1.0000
51.8000 667.0000 1.0000
51.8400 580.0000 1.0000
51.8800 503.0000 1.0000
51.9200 480.0000 1.0000
51.9600 440.0000 1.0000
52.0000 449.0000 1.0000
52.0400 429.0000 1.0000
52.0800 408.0000 1.0000
52.1200 429.0000 1.0000
52.1600 403.0000 1.0000
52.2000 402.0000 1.0000
52.2400 419.0000 1.0000
52.2800 374.0000 1.0000
52.3200 391.0000 1.0000
52.3600 395.0000 1.0000
52.4000 372.0000 1.0000
52.4400 415.0000 1.0000
52.4800 408.0000 1.0000
52.5200 382.0000 1.0000
52.5600 398.0000 1.0000
52.6000 364.0000 1.0000
52.6400 369.0000 1.0000
52.6800 396.0000 1.0000
52.7200 351.0000 1.0000
52.7600 372.0000 1.0000
52.8000 361.0000 1.0000
52.8400 375.0000 1.0000
52.8800 387.0000 1.0000
52.9200 376.0000 1.0000
52.9600 383.0000 1.0000
53.0000 365.0000 1.0000
53.0400 396.0000 1.0000
53.0800 386.0000 1.0000
53.1200 367.0000 1.0000
53.1600 385.0000 1.0000
53.2000 385.0000 1.0000
53.2400 392.0000 1.0000
53.2800 336.0000 1.0000
53.3200 388.0000 1.0000
53.3600 346.0000 1.0000
53.4000 378.0000 1.0000
53.4400 356.0000 1.0000
53.4800 377.0000 1.0000
53.5200 358.0000 1.0000
53.5600 352.0000 1.0000
53.6000 383.0000 1.0000
53.6400 399.0000 1.0000
53.6800 389.0000 1.0000
53.7200 401.0000 1.0000
53.7600 378.0000 1.0000
53.8000 388.0000 1.0000
53.8400 398.0000 1.0000
53.8800 428.0000 1.0000
53.9200 450.0000 1.0000
53.9600 448.0000 1.0000
54.0000 465.0000 1.0000
54.0400 495.0000 1.0000
54.0800 437.0000 1.0000
54.1200 471.0000 1.0000
54.1600 432.0000 1.0000
54.2000 432.0000 1.0000
54.2400 431.0000 1.0000
54.2800 402.0000 1.0000
54.3200 421.0000 1.0000
54.3600 429.0000 1.0000
54.4000 499.0000 1.0000
54.4400 494.0000 1.0000
54.4800 586.0000 1.0000
54.5200 548.0000 1.0000
54.5600 504.0000 1.0000
54.6000 556.0000 1.0000
54.6400 531.0000 1.0000
54.6800 527.0000 1.0000
54.7200 471.0000 1.0000
54.7600 417.0000 1.0000
54.8000 449.0000 1.0000
54.8400 427.0000 1.0000
54.8800 390.0000 1.0000
54.9200 404.0000 1.0000
54.9600 365.0000 1.0000
55.0000 371.0000 1.0000
55.0400 417.0000 1.0000
55.0800 381.0000 1.0000
55.1200 361.0000 1.0000
55.1600 394.0000 1.0000
55.2000 358.0000 1.0000
55.2400 371.0000 1.0000
55.2800 381.0000 1.0000
55.3200 373.0000 1.0000
55.3600 364.0000 1.0000
55.4000 341.0000 1.0000
55.4400 348.0000 1.0000
55.4800 342.0000 1.0000
55.5200 347.0000 1.0000
55.5600 372.0000 1.0000
55.6000 359.0000 1.0000
55.6400 378.0000 1.0000
55.6800 372.0000 1.0000
55.7200 330.0000 1.0000
55.7600 346.0000 1.0000
55.8000 341.0000 1.0000
55.8400 349.0000 1.0000
55.8800 328.0000 1.0000
55.9200 321.0000 1.0000
55.9600 369.0000 1.0000
56.0000 346.0000 1.0000
56.0400 352.0000 1.0000
56.0800 333.0000 1.0000
56.1200 337.0000 1.0000
56.1600 332.0000 1.0000
56.2000 350.0000 1.0000
56.2400 340.0000 1.0000
56.2800 360.0000 1.0000
56.3200 364.0000 1.0000
56.3600 360.0000 1.0000
56.4000 371.0000 1.0000
56.4400 372.0000 1.0000
56.4800 366.0000 1.0000
56.5200 333.0000 1.0000
56.5600 353.0000 1.0000
56.6000 378.0000 1.0000
56.6400 361.0000 1.0000
56.6800 349.0000 1.0000
56.7200 372.0000 1.0000
56.7600 340.0000 1.0000
56.8000 345.0000 1.0000
56.8400 326.0000 1.0000
56.8800 348.0000 1.0000
56.9200 360.0000 1.0000
56.9600 353.0000 1.0000
57.0000 369.0000 1.0000
57.0400 359.0000 1.0000
57.0800 365.0000 1.0000
57.1200 343.0000 1.0000
57.1600 336.0000 1.0000
57.2000 343.0000 1.0000
57.2400 357.0000 1.0000
57.2800 339.0000 1.0000
57.3200 360.0000 1.0000
57.3600 393.0000 1.0000
57.4000 362.0000 1.0000
57.4400 336.0000 1.0000
57.4800 364.0000 1.0000
57.5200 366.0000 1.0000
57.5600 384.0000 1.0000
57.6000 390.0000 1.0000
57.6400 341.0000 1.0000
57.6800 353.0000 1.0000
57.7200 396.0000 1.0000
57.7600 363.0000 1.0000
57.8000 328.0000 1.0000
57.8400 338.0000 1.0000
57.8800 341.0000 1.0000
57.9200 353.0000 1.0000
57.9600 349.0000 1.0000
58.0000 339.0000 1.0000
58.0400 331.0000 1.0000
58.0800 344.0000 1.0000
58.1200 361.0000 1.0000
58.1600 356.0000 1.0000
58.2000 361.0000 1.0000
58.2400 382.0000 1.0000
58.2800 340.0000 1.0000
58.3200 329.0000 1.0000
58.3600 340.0000 1.0000
58.4000 331.0000 1.0000
58.4400 321.0000 1.0000
58.4800 340.0000 1.0000
58.5200 366.0000 1.0000
58.5600 363.0000 1.0000
58.6000 345.0000 1.0000
58.6400 362.0000 1.0000
58.6800 360.0000 1.0000
58.7200 361.0000 1.0000
58.7600 363.0000 1.0000
58.8000 364.0000 1.0000
58.8400 303.0000 1.0000
58.8800 372.0000 1.0000
58.9200 358.0000 1.0000
58.9600 321.0000 1.0000
59.0000 362.0000 1.0000
59.0400 335.0000 1.0000
59.0800 342.0000 1.0000
59.1200 356.0000 1.0000
59.1600 326.0000 1.0000
59.2000 333.0000 1.0000
59.2400 342.0000 1.0000
59.2800 347.0000 1.0000
59.3200 315.0000 1.0000
59.3600 322.0000 1.0000
59.4000 330.0000 1.0000
59.4400 359.0000 1.0000
59.4800 334.0000 1.0000
59.5200 368.0000 1.0000
59.5600 328.0000 1.0000
59.6000 347.0000 1.0000
59.6400 341.0000 1.0000
59.6800 356.0000 1.0000
59.7200 352.0000 1.0000
59.7600 354.0000 1.0000
59.8000 330.0000 1.0000
59.8400 360.0000 1.0000
59.8800 387.0000 1.0000
59.9200 339.0000 1.0000
59.9600 350.0000 1.0000
60.0000 330.0000 1.0000
60.0400 326.0000 1.0000
60.0800 338.0000 1.0000
60.1200 355.0000 1.0000
60.1600 383.0000 1.0000
60.2000 364.0000 1.0000
60.2400 342.0000 1.0000
60.2800 318.0000 1.0000
60.3200 350.0000 1.0000
60.3600 332.0000 1.0000
60.4000 338.0000 1.0000
60.4400 382.0000 1.0000
60.4800 345.0000 1.0000
60.5200 352.0000 1.0000
60.5600 350.0000 1.0000
60.6000 345.0000 1.0000
60.6400 360.0000 1.0000
60.6800 343.0000 1.0000
60.7200 361.0000 1.0000
60.7600 342.0000 1.0000
60.8000 332.0000 1.0000
60.8400 359.0000 1.0000
60.8800 374.0000 1.0000
60.9200 361.0000 1.0000
60.9600 355.0000 1.0000
61.0000 379.0000 1.0000
61.0400 403.0000 1.0000
61.0800 354.0000 1.0000
61.1200 396.0000 1.0000
61.1600 405.0000 1.0000
61.2000 412.0000 1.0000
61.2400 424.0000 1.0000
61.2800 461.0000 1.0000
61.3200 501.0000 1.0000
61.3600 566.0000 1.0000
61.4000 631.0000 1.0000
61.4400 670.0000 1.0000
61.4800 725.0000 1.0000
61.5200 734.0000 1.0000
61.5600 749.0000 1.0000
61.6000 783.0000 1.0000
61.6400 742.0000 1.0000
61.6800 695.0000 1.0000
61.7200 656.0000 1.0000
61.7600 567.0000 1.0000
61.8000 537.0000 1.0000
61.8400 483.0000 1.0000
61.8800 453.0000 1.0000
61.9200 468.0000 1.0000
61.9600 370.0000 1.0000
62.0000 391.0000 1.0000
62.0400 413.0000 1.0000
62.0800 410.0000 1.0000
62.1200 402.0000 1.0000
62.1600 373.0000 1.0000
62.2000 367.0000 1.0000
62.2400 374.0000 1.0000
62.2800 386.0000 1.0000
62.3200 396.0000 1.0000
62.3600 390.0000 1.0000
62.4000 419.0000 1.0000
62.4400 399.0000 1.0000
62.4800 399.0000 1.0000
62.5200 372.0000 1.0000
62.5600 343.0000 1.0000
62.6000 361.0000 1.0000
62.6400 352.0000 1.0000
62.6800 347.0000 1.0000
62.7200 344.0000 1.0000
62.7600 355.0000 1.0000
62.8000 375.0000 1.0000
62.8400 352.0000 1.0000
62.8800 319.0000 1.0000
62.9200 342.0000 1.0000
62.9600 330.0000 1.0000
63.0000 323.0000 1.0000
63.0400 370.0000 1.0000
63.0800 324.0000 1.0000
63.1200 349.0000 1.0000
63.1600 336.0000 1.0000
63.2000 341.0000 1.0000
63.2400 327.0000 1.0000
63.2800 339.0000 1.0000
63.3200 377.0000 1.0000
63.3600 353.0000 1.0000
63.4000 339.0000 1.0000
63.4400 337.0000 1.0000
63.4800 342.0000 1.0000
63.5200 366.0000 1.0000
63.5600 341.0000 1.0000
63.6000 337.0000 1.0000
63.6400 338.0000 1.0000
63.6800 348.0000 1.0000
63.7200 331.0000 1.0000
63.7600 379.0000 1.0000
63.8000 385.0000 1.0000
63.8400 357.0000 1.0000
63.8800 394.0000 1.0000
63.9200 402.0000 1.0000
63.9600 402.0000 1.0000
64.0000 382.0000 1.0000
64.0400 380.0000 1.0000
64.0800 388.0000 1.0000
64.1200 393.0000 1.0000
64.1600 386.0000 1.0000
64.2000 370.0000 1.0000
64.2400 380.0000 1.0000
64.2800 356.0000 1.0000
64.3200 328.0000 1.0000
64.3600 380.0000 1.0000
64.4000 343.0000 1.0000
64.4400 357.0000 1.0000
64.4800 356.0000 1.0000
64.5200 365.0000 1.0000
64.5600 340.0000 1.0000
64.6000 347.0000 1.0000
64.6400 371.0000 1.0000
64.6800 342.0000 1.0000
64.7200 355.0000 1.0000
64.7600 324.0000 1.0000
64.8000 376.0000 1.0000
64.8400 363.0000 1.0000
64.8800 352.0000 1.0000
64.9200 327.0000 1.0000
64.9600 342.0000 1.0000
65.0000 387.0000 1.0000
65.0400 419.0000 1.0000
65.0800 403.0000 1.0000
65.1200 397.0000 1.0000
65.1600 398.0000 1.0000
65.2000 462.0000 1.0000
65.2400 454.0000 1.0000
65.2800 543.0000 1.0000
65.3200 571.0000 1.0000
65.3600 686.0000 1.0000
65.4000 769.0000 1.0000
65.4400 971.0000 1.0000
65.4800 1096.0000 1.0000
65.5200 1217.0000 1.0000
65.5600 1239.0000 1.0000
65.6000 1185.0000 1.0000
65.6400 1140.0000 1.0000
65.6800 1019.0000 1.0000
65.7200 976.0000 1.0000
65.7600 879.0000 1.0000
65.8000 756.0000 1.0000
65.8400 644.0000 1.0000
65.8800 521.0000 1.0000
65.9200 525.0000 1.0000
65.9600 466.0000 1.0000
66.0000 436.0000 1.0000
66.0400 387.0000 1.0000
66.0800 398.0000 1.0000
66.1200 371.0000 1.0000
66.1600 354.0000 1.0000
66.2000 360.0000 1.0000
66.2400 341.0000 1.0000
66.2800 353.0000 1.0000
66.3200 358.0000 1.0000
66.3600 328.0000 1.0000
66.4000 340.0000 1.0000
66.4400 352.0000 1.0000
66.4800 367.0000 1.0000
66.5200 324.0000 1.0000
66.5600 321.0000 1.0000
66.6000 311.0000 1.0000
66.6400 312.0000 1.0000
66.6800 297.0000 1.0000
66.7200 350.0000 1.0000
66.7600 326.0000 1.0000
66.8000 292.0000 1.0000
66.8400 334.0000 1.0000
66.8800 330.0000 1.0000
66.9200 328.0000 1.0000
66.9600 320.0000 1.0000
67.0000 322.0000 1.0000
67.0400 348.0000 1.0000
67.0800 337.0000 1.0000
67.1200 315.0000 1.0000
67.1600 338.0000 1.0000
67.2000 313.0000 1.0000
67.2400 329.0000 1.0000
67.2800 295.0000 1.0000
67.3200 332.0000 1.0000
67.3600 308.0000 1.0000
67.4000 316.0000 1.0000
67.4400 329.0000 1.0000
67.4800 306.0000 1.0000
67.5200 320.0000 1.0000
67.5600 298.0000 1.0000
67.6000 306.0000 1.0000
67.6400 325.0000 1.0000
67.6800 267.0000 1.0000
67.7200 315.0000 1.0000
67.7600 320.0000 1.0000
67.8000 318.0000 1.0000
67.8400 285.0000 1.0000
67.8800 301.0000 1.0000
67.9200 320.0000 1.0000
67.9600 303.0000 1.0000
68.0000 325.0000 1.0000
68.0400 295.0000 1.0000
68.0800 313.0000 1.0000
68.1200 303.0000 1.0000
68.1600 293.0000 1.0000
68.2000 284.0000 1.0000
68.2400 287.0000 1.0000
68.2800 343.0000 1.0000
68.3200 309.0000 1.0000
68.3600 304.0000 1.0000
68.4000 306.0000 1.0000
68.4400 276.0000 1.0000
68.4800 362.0000 1.0000
68.5200 290.0000 1.0000
68.5600 310.0000 1.0000
68.6000 286.0000 1.0000
68.6400 308.0000 1.0000
68.6800 302.0000 1.0000
68.7200 313.0000 1.0000
68.7600 323.0000 1.0000
68.8000 319.0000 1.0000
68.8400 302.0000 1.0000
68.8800 339.0000 1.0000
68.9200 273.0000 1.0000
68.9600 319.0000 1.0000
69.0000 353.0000 1.0000
69.0400 294.0000 1.0000
69.0800 298.0000 1.0000
69.1200 315.0000 1.0000
69.1600 314.0000 1.0000
69.2000 298.0000 1.0000
69.2400 288.0000 1.0000
69.2800 319.0000 1.0000
69.3200 289.0000 1.0000
69.3600 292.0000 1.0000
69.4000 311.0000 1.0000
69.4400 299.0000 1.0000
69.4800 306.0000 1.0000
69.5200 327.0000 1.0000
69.5600 307.0000 1.0000
69.6000 326.0000 1.0000
69.6400 294.0000 1.0000
69.6800 322.0000 1.0000
69.7200 288.0000 1.0000
69.7600 302.0000 1.0000
69.8000 301.0000 1.0000
69.8400 316.0000 1.0000
69.8800 274.0000 1.0000
69.9200 284.0000 1.0000
69.9600 265.0000 1.0000
70.0000 300.0000 1.0000
*RAS_INT_END
*RAS_TEMPERATURE_START
*RAS_TEMPERATURE_END
*RAS_DATA_END