File: Data/Dataset1_Only_water/5_XRD/No_005_FS2_1.ras
*RAS_DATA_START
*RAS_HEADER_START
*DISP_FMT_X "%.2f"
*DISP_FMT_Y "%.0f"
*DISP_FULLSCALE "14372.0000000000"
*DISP_LINE_COLOR "255.0000000000"
*DISP_LINE_STYLE "0.0000000000"
*DISP_LINE_WIDTH "0.2500000000"
*DISP_NOTE "測定データ-2"
*DISP_OFFSET_Y "0.0000000000"
*DISP_PEAKSEARCH_UNIT_Y "cps"
*DISP_RANGE_BOTTOM "0.0000000000"
*DISP_RANGE_LEFT "20.0000000000"
*DISP_RANGE_LOGCUTOFF "0.0100000000"
*DISP_RANGE_RIGHT "70.0000000000"
*DISP_RANGE_TOP "14372.0000000000"
*DISP_SCALE_MODE_Y "0.0000000000"
*DISP_TAB_NAME "2θ/θ"
*DISP_TITLE_Y "強度"
*DISP_UNIT_Y "cps"
*DISP_WINDOW_NAME "MSG_MACROENGINE"
*FILE_COMMENT " "
*FILE_MD5 ""
*FILE_MEMO " "
*FILE_OPERATOR "Administrator"
*FILE_SAMPLE " "
*FILE_TYPE "RAS_RAW"
*FILE_USERGROUP "システムマネージャ"
*FILE_VERSION "1.0000000000"
*HW_ATTACHMENT_ID "ATT0025"
*HW_ATTACHMENT_NAME "標準|Standard"
*HW_COUNTER_ID-0 "CUT0025"
*HW_COUNTER_ID-1 "CUT0020"
*HW_COUNTER_ID-2 "CUT0020"
*HW_COUNTER_ID-3 "CSL0021"
*HW_COUNTER_ID-4 "CMC0021"
*HW_COUNTER_NAME-0 "D/teX Ultra|D/teX Ultra"
*HW_COUNTER_NAME-1 "None|None"
*HW_COUNTER_NAME-2 "None|None"
*HW_COUNTER_NAME-3 "BBM|BBM"
*HW_COUNTER_NAME-4 "検出器モノクロメータ|Detector monochromator"
*HW_COUNTER_SELECT_NAME "D/teX Ultra|D/teX Ultra"
*HW_GONIOMETER_ID "GON0023"
*HW_GONIOMETER_NAME "SmartLab|SmartLab"
*HW_GONIOMETER_RADIUS-0 "90.0"
*HW_GONIOMETER_RADIUS-1 "114.0"
*HW_GONIOMETER_RADIUS-2 "190.0"
*HW_GONIOMETER_RADIUS-3 "300.0"
*HW_GONIOMETER_RADIUS-4 "187.0"
*HW_GONIOMETER_RADIUS-5 "300.0"
*HW_GONIOMETER_RADIUS-6 "113.0"
*HW_GONIOMETER_RADIUS-7 "331.0"
*HW_I_OPT_ID-0 "CBO0021"
*HW_I_OPT_ID-1 "ICR0023"
*HW_I_OPT_ID-2 "ISL0021"
*HW_I_OPT_ID-3 "ISO0021"
*HW_I_OPT_ID-4 "IAD0021"
*HW_I_OPT_ID-5 "IPR0001"
*HW_I_OPT_NAME-0 "CBOユニット|CBO unit"
*HW_I_OPT_NAME-1 "標準入射光学ユニット|Standard incident optical unit"
*HW_I_OPT_NAME-2 "標準入射スリットボックス|Standard incident slit box"
*HW_I_OPT_NAME-3 "入射平行スリット|Incident parallel slit"
*HW_I_OPT_NAME-4 "長手制限スリット|Length limiting slit"
*HW_I_OPT_NAME-5 "None|None"
*HW_R_ATTENUATER_AUTOMODE "0"
*HW_R_OPT_ID-0 "RSS0021"
*HW_R_OPT_ID-1 "RCR0023"
*HW_R_OPT_ID-2 "RSO0021"
*HW_R_OPT_ID-3 "RRS0021"
*HW_R_OPT_ID-4 "ATN0021"
*HW_R_OPT_ID-5 "RFL0021"
*HW_R_OPT_ID-6 "RAD0021"
*HW_R_OPT_NAME-0 "標準受光スリットボックス1|Standard receiving slit box # 1"
*HW_R_OPT_NAME-1 "標準受光光学ユニット1|Standard receiving unit # 1"
*HW_R_OPT_NAME-2 "標準受光光学ユニット2|Standard receiving optical unit # 2"
*HW_R_OPT_NAME-3 "標準受光スリットボックス2|Standard receiving slit box # 2"
*HW_R_OPT_NAME-4 "標準アッテネータ|Standard Attenuator"
*HW_R_OPT_NAME-5 "Cu Kβ|Cu K-beta"
*HW_R_OPT_NAME-6 "調整用受光スリット|Alignment receiving slit"
*HW_SAMPLE_HOLDER_ID "SMP0023"
*HW_SAMPLE_HOLDER_NAME "標準Zステージ|Standard Z stage"
*HW_XG_CURRENT_MAX "50"
*HW_XG_CURRENT_MIN "2"
*HW_XG_CURRENT_RESOLUTION "1"
*HW_XG_CURRENT_UNIT "mA"
*HW_XG_FOCUS "1mm x 10mm"
*HW_XG_FOCUS_TYPE "Normal"
*HW_XG_ID ""
*HW_XG_NAME "3kW 封入管(ID:1200)|3kW Sealed tube(ID:1200)"
*HW_XG_TARGET_ATOMIC_NUMBER "29.0000000000"
*HW_XG_TARGET_NAME "Cu"
*HW_XG_TYPE "Hermetic"
*HW_XG_VOLTAGE_MAX "60"
*HW_XG_VOLTAGE_MIN "20"
*HW_XG_VOLTAGE_RESOLUTION "1"
*HW_XG_VOLTAGE_UNIT "kV"
*HW_XG_WATT_MAX "1.500"
*HW_XG_WATT_UNIT "kW"
*HW_XG_WAVE_LENGTH_ALPHA1 "1.540593"
*HW_XG_WAVE_LENGTH_ALPHA2 "1.544414"
*HW_XG_WAVE_LENGTH_BETA "1.392250"
*MEAS_COND_AXIS_NAME-0 "2θ/θ"
*MEAS_COND_AXIS_NAME-1 "2θ"
*MEAS_COND_AXIS_NAME-2 "ω"
*MEAS_COND_AXIS_NAME-3 "Z"
*MEAS_COND_AXIS_NAME-4 "2θ/ω"
*MEAS_COND_AXIS_NAME-5 "θs"
*MEAS_COND_AXIS_NAME-6 "θd"
*MEAS_COND_AXIS_NAME-7 "Ts"
*MEAS_COND_AXIS_NAME-8 "CBO選択スリット"
*MEAS_COND_AXIS_NAME-9 "M"
*MEAS_COND_AXIS_NAME-10 "入射平行スリット"
*MEAS_COND_AXIS_NAME-11 "入射スリット"
*MEAS_COND_AXIS_NAME-12 ""
*MEAS_COND_AXIS_NAME-13 "Zs"
*MEAS_COND_AXIS_NAME-14 "入射光学素子"
*MEAS_COND_AXIS_NAME-15 "長手制限スリット"
*MEAS_COND_AXIS_NAME-16 "センタースリット"
*MEAS_COND_AXIS_NAME-17 "フィルター"
*MEAS_COND_AXIS_NAME-18 "受光スリット1"
*MEAS_COND_AXIS_NAME-19 "受光スリット2"
*MEAS_COND_AXIS_NAME-20 "受光光学素子"
*MEAS_COND_AXIS_NAME-21 "受光平行スリット"
*MEAS_COND_AXIS_NAME-22 "調整用受光スリット"
*MEAS_COND_AXIS_NAME-23 ""
*MEAS_COND_AXIS_NAME-24 ""
*MEAS_COND_AXIS_NAME-25 "Zd"
*MEAS_COND_AXIS_NAME-26 "アッテネータ"
*MEAS_COND_AXIS_NAME-27 "検出器モノクロメータ"
*MEAS_COND_AXIS_NAME-28 "モノクロメータスリット"
*MEAS_COND_AXIS_NAME-29 "プライマリビーム"
*MEAS_COND_AXIS_NAME-30 "PHA"
*MEAS_COND_AXIS_NAME_INTERNAL-0 "TwoThetaTheta"
*MEAS_COND_AXIS_NAME_INTERNAL-1 "TwoTheta"
*MEAS_COND_AXIS_NAME_INTERNAL-2 "Omega"
*MEAS_COND_AXIS_NAME_INTERNAL-3 "Z"
*MEAS_COND_AXIS_NAME_INTERNAL-4 "TwoThetaOmega"
*MEAS_COND_AXIS_NAME_INTERNAL-5 "ThetaS"
*MEAS_COND_AXIS_NAME_INTERNAL-6 "ThetaD"
*MEAS_COND_AXIS_NAME_INTERNAL-7 "Ts"
*MEAS_COND_AXIS_NAME_INTERNAL-8 "CBO"
*MEAS_COND_AXIS_NAME_INTERNAL-9 "CBO-M"
*MEAS_COND_AXIS_NAME_INTERNAL-10 "IncidentSollerSlit"
*MEAS_COND_AXIS_NAME_INTERNAL-11 "IncidentSlitBox"
*MEAS_COND_AXIS_NAME_INTERNAL-12 "IncidentSlitBox-_Axis"
*MEAS_COND_AXIS_NAME_INTERNAL-13 "Zs"
*MEAS_COND_AXIS_NAME_INTERNAL-14 "IncidentMonochromator"
*MEAS_COND_AXIS_NAME_INTERNAL-15 "IncidentAxdSlit"
*MEAS_COND_AXIS_NAME_INTERNAL-16 "CenterSlit"
*MEAS_COND_AXIS_NAME_INTERNAL-17 "Filter"
*MEAS_COND_AXIS_NAME_INTERNAL-18 "ReceivingSlitBox1"
*MEAS_COND_AXIS_NAME_INTERNAL-19 "ReceivingSlitBox2"
*MEAS_COND_AXIS_NAME_INTERNAL-20 "ReceivingOptics"
*MEAS_COND_AXIS_NAME_INTERNAL-21 "ReceivingSollerSlit"
*MEAS_COND_AXIS_NAME_INTERNAL-22 "ReceivingAxdSlit"
*MEAS_COND_AXIS_NAME_INTERNAL-23 "ReceivingSlitBox1-_Axis"
*MEAS_COND_AXIS_NAME_INTERNAL-24 "ReceivingSlitBox2-_Axis"
*MEAS_COND_AXIS_NAME_INTERNAL-25 "ReceivingSlitBox2-Zd"
*MEAS_COND_AXIS_NAME_INTERNAL-26 "Attenuator"
*MEAS_COND_AXIS_NAME_INTERNAL-27 "CounterMonochromator"
*MEAS_COND_AXIS_NAME_INTERNAL-28 "CounterSlit"
*MEAS_COND_AXIS_NAME_INTERNAL-29 "IncidentPrimary"
*MEAS_COND_AXIS_NAME_INTERNAL-30 "PHA"
*MEAS_COND_AXIS_NAME_MAGICNO-0 "83951616.0000000000"
*MEAS_COND_AXIS_NAME_MAGICNO-1 "268632064.0000000000"
*MEAS_COND_AXIS_NAME_MAGICNO-2 "268500992.0000000000"
*MEAS_COND_AXIS_NAME_MAGICNO-3 "285278208.0000000000"
*MEAS_COND_AXIS_NAME_MAGICNO-4 "83951616.0000000000"
*MEAS_COND_AXIS_NAME_MAGICNO-5 "131072.0000000000"
*MEAS_COND_AXIS_NAME_MAGICNO-6 "131072.0000000000"
*MEAS_COND_AXIS_NAME_MAGICNO-7 "318898176.0000000000"
*MEAS_COND_AXIS_NAME_MAGICNO-8 "20971521.0000000000"
*MEAS_COND_AXIS_NAME_MAGICNO-9 "285343744.0000000000"
*MEAS_COND_AXIS_NAME_MAGICNO-10 "20971521.0000000000"
*MEAS_COND_AXIS_NAME_MAGICNO-11 "22020097.0000000000"
*MEAS_COND_AXIS_NAME_MAGICNO-12 "25165824.0000000000"
*MEAS_COND_AXIS_NAME_MAGICNO-13 "318898176.0000000000"
*MEAS_COND_AXIS_NAME_MAGICNO-14 "1.0000000000"
*MEAS_COND_AXIS_NAME_MAGICNO-15 "20971521.0000000000"
*MEAS_COND_AXIS_NAME_MAGICNO-16 "20971521.0000000000"
*MEAS_COND_AXIS_NAME_MAGICNO-17 "20971521.0000000000"
*MEAS_COND_AXIS_NAME_MAGICNO-18 "23068673.0000000000"
*MEAS_COND_AXIS_NAME_MAGICNO-19 "23068673.0000000000"
*MEAS_COND_AXIS_NAME_MAGICNO-20 "20971521.0000000000"
*MEAS_COND_AXIS_NAME_MAGICNO-21 "20971521.0000000000"
*MEAS_COND_AXIS_NAME_MAGICNO-22 "20971521.0000000000"
*MEAS_COND_AXIS_NAME_MAGICNO-23 "25165824.0000000000"
*MEAS_COND_AXIS_NAME_MAGICNO-24 "25165824.0000000000"
*MEAS_COND_AXIS_NAME_MAGICNO-25 "285343744.0000000000"
*MEAS_COND_AXIS_NAME_MAGICNO-26 "17301505.0000000000"
*MEAS_COND_AXIS_NAME_MAGICNO-27 "20971521.0000000000"
*MEAS_COND_AXIS_NAME_MAGICNO-28 "20971521.0000000000"
*MEAS_COND_AXIS_NAME_MAGICNO-29 "20971521.0000000000"
*MEAS_COND_AXIS_NAME_MAGICNO-30 "0.0000000000"
*MEAS_COND_AXIS_OFFSET-0 "-"
*MEAS_COND_AXIS_OFFSET-1 "-0.1081000000"
*MEAS_COND_AXIS_OFFSET-2 "0.3758000000"
*MEAS_COND_AXIS_OFFSET-3 "-"
*MEAS_COND_AXIS_OFFSET-4 "-"
*MEAS_COND_AXIS_OFFSET-5 "0.3758000000"
*MEAS_COND_AXIS_OFFSET-6 "-0.4839000000"
*MEAS_COND_AXIS_OFFSET-7 "-"
*MEAS_COND_AXIS_OFFSET-8 "-"
*MEAS_COND_AXIS_OFFSET-9 "-"
*MEAS_COND_AXIS_OFFSET-10 "-"
*MEAS_COND_AXIS_OFFSET-11 "-"
*MEAS_COND_AXIS_OFFSET-12 "-"
*MEAS_COND_AXIS_OFFSET-13 "-"
*MEAS_COND_AXIS_OFFSET-14 "-"
*MEAS_COND_AXIS_OFFSET-15 "-"
*MEAS_COND_AXIS_OFFSET-16 "-"
*MEAS_COND_AXIS_OFFSET-17 "-"
*MEAS_COND_AXIS_OFFSET-18 "-"
*MEAS_COND_AXIS_OFFSET-19 "-"
*MEAS_COND_AXIS_OFFSET-20 "-"
*MEAS_COND_AXIS_OFFSET-21 "-"
*MEAS_COND_AXIS_OFFSET-22 "-"
*MEAS_COND_AXIS_OFFSET-23 "-"
*MEAS_COND_AXIS_OFFSET-24 "-"
*MEAS_COND_AXIS_OFFSET-25 "-"
*MEAS_COND_AXIS_OFFSET-26 "-"
*MEAS_COND_AXIS_OFFSET-27 "-"
*MEAS_COND_AXIS_OFFSET-28 "-"
*MEAS_COND_AXIS_OFFSET-29 "-"
*MEAS_COND_AXIS_OFFSET-30 "-"
*MEAS_COND_AXIS_POSITION-0 "0.0000000000"
*MEAS_COND_AXIS_POSITION-1 "0.0000000000"
*MEAS_COND_AXIS_POSITION-2 "0.0000000000"
*MEAS_COND_AXIS_POSITION-3 "-0.5500000000"
*MEAS_COND_AXIS_POSITION-4 "0.0000000000"
*MEAS_COND_AXIS_POSITION-5 "0.0000000000"
*MEAS_COND_AXIS_POSITION-6 "0.0000000000"
*MEAS_COND_AXIS_POSITION-7 "-0.4278800000"
*MEAS_COND_AXIS_POSITION-8 "BB"
*MEAS_COND_AXIS_POSITION-9 "0.0000000000"
*MEAS_COND_AXIS_POSITION-10 "Soller_slit_5.0deg"
*MEAS_COND_AXIS_POSITION-11 "2/3deg"
*MEAS_COND_AXIS_POSITION-12 "2.2088000000"
*MEAS_COND_AXIS_POSITION-13 "-0.4140600000"
*MEAS_COND_AXIS_POSITION-14 "0.0000000000"
*MEAS_COND_AXIS_POSITION-15 "10.0mm"
*MEAS_COND_AXIS_POSITION-16 "None"
*MEAS_COND_AXIS_POSITION-17 "Cu_K-beta"
*MEAS_COND_AXIS_POSITION-18 "13.000mm"
*MEAS_COND_AXIS_POSITION-19 "13.000mm"
*MEAS_COND_AXIS_POSITION-20 "No_unit"
*MEAS_COND_AXIS_POSITION-21 "Soller_slit_5.0deg"
*MEAS_COND_AXIS_POSITION-22 "None"
*MEAS_COND_AXIS_POSITION-23 "13.0000000000"
*MEAS_COND_AXIS_POSITION-24 "13.0000000000"
*MEAS_COND_AXIS_POSITION-25 "0.0109400000"
*MEAS_COND_AXIS_POSITION-26 "Open"
*MEAS_COND_AXIS_POSITION-27 "None"
*MEAS_COND_AXIS_POSITION-28 "None"
*MEAS_COND_AXIS_POSITION-29 "None"
*MEAS_COND_AXIS_POSITION-30 "38.0000000000"
*MEAS_COND_AXIS_UNIT-0 "deg"
*MEAS_COND_AXIS_UNIT-1 "deg"
*MEAS_COND_AXIS_UNIT-2 "deg"
*MEAS_COND_AXIS_UNIT-3 "mm"
*MEAS_COND_AXIS_UNIT-4 "deg"
*MEAS_COND_AXIS_UNIT-5 "deg"
*MEAS_COND_AXIS_UNIT-6 "deg"
*MEAS_COND_AXIS_UNIT-7 "mm"
*MEAS_COND_AXIS_UNIT-8 ""
*MEAS_COND_AXIS_UNIT-9 "pulse"
*MEAS_COND_AXIS_UNIT-10 ""
*MEAS_COND_AXIS_UNIT-11 ""
*MEAS_COND_AXIS_UNIT-12 "mm"
*MEAS_COND_AXIS_UNIT-13 "mm"
*MEAS_COND_AXIS_UNIT-14 ""
*MEAS_COND_AXIS_UNIT-15 ""
*MEAS_COND_AXIS_UNIT-16 ""
*MEAS_COND_AXIS_UNIT-17 ""
*MEAS_COND_AXIS_UNIT-18 ""
*MEAS_COND_AXIS_UNIT-19 ""
*MEAS_COND_AXIS_UNIT-20 ""
*MEAS_COND_AXIS_UNIT-21 ""
*MEAS_COND_AXIS_UNIT-22 ""
*MEAS_COND_AXIS_UNIT-23 "mm"
*MEAS_COND_AXIS_UNIT-24 "mm"
*MEAS_COND_AXIS_UNIT-25 "mm"
*MEAS_COND_AXIS_UNIT-26 ""
*MEAS_COND_AXIS_UNIT-27 ""
*MEAS_COND_AXIS_UNIT-28 ""
*MEAS_COND_AXIS_UNIT-29 ""
*MEAS_COND_AXIS_UNIT-30 "div"
*MEAS_COND_COUNTER_CNTLOSS_CORR "0.0000000000"
*MEAS_COND_COUNTER_PHABASE "38.0000000000"
*MEAS_COND_COUNTER_PHAWINDOW "16.0000000000"
*MEAS_COND_COUNTER_PHA_UNIT "div"
*MEAS_COND_COUNTER_TAUDIFF "30.0000000000"
*MEAS_COND_COUNTER_TAUINT "0.0000000000"
*MEAS_COND_IRRADIATION_MODE "OFF"
*MEAS_COND_IRRADIATION_WIDTH ""
*MEAS_COND_OPT_ATTR "集中法"
*MEAS_COND_OPT_NAME "@集中法"
*MEAS_COND_UNSYMMETRIC_MODE "OFF"
*MEAS_COND_XG_CURRENT "30.0000000000"
*MEAS_COND_XG_VOLTAGE "40.0000000000"
*MEAS_COND_XG_WAVE_TYPE "Ka"
*MEAS_DATA_COUNT "5001.0000000000"
*MEAS_SCAN_AXIS_X "2θ/θ"
*MEAS_SCAN_AXIS_X_INTERNAL "TwoThetaTheta"
*MEAS_SCAN_END_TIME "06/30/21 13:24:50"
*MEAS_SCAN_MODE "CONTINUOUS"
*MEAS_SCAN_MONITOR "0"
*MEAS_SCAN_RESOLUTION_X "0.0002"
*MEAS_SCAN_SPEED "1.0"
*MEAS_SCAN_SPEED_UNIT "deg/min"
*MEAS_SCAN_START "20.0000000000"
*MEAS_SCAN_START_TIME "06/30/21 12:31:57"
*MEAS_SCAN_STEP "0.0100000000"
*MEAS_SCAN_STOP "70.0000000000"
*MEAS_SCAN_UNIT_X "deg"
*MEAS_SCAN_UNIT_Y "counts"
*RAS_HEADER_END
*RAS_INT_START
20.0000 1642.0000 1.0000
20.0400 1659.0000 1.0000
20.0800 1680.0000 1.0000
20.1200 1644.0000 1.0000
20.1600 1644.0000 1.0000
20.2000 1621.0000 1.0000
20.2400 1645.0000 1.0000
20.2800 1636.0000 1.0000
20.3200 1621.0000 1.0000
20.3600 1633.0000 1.0000
20.4000 1677.0000 1.0000
20.4400 1648.0000 1.0000
20.4800 1674.0000 1.0000
20.5200 1648.0000 1.0000
20.5600 1625.0000 1.0000
20.6000 1602.0000 1.0000
20.6400 1612.0000 1.0000
20.6800 1599.0000 1.0000
20.7200 1642.0000 1.0000
20.7600 1670.0000 1.0000
20.8000 1623.0000 1.0000
20.8400 1664.0000 1.0000
20.8800 1599.0000 1.0000
20.9200 1600.0000 1.0000
20.9600 1619.0000 1.0000
21.0000 1611.0000 1.0000
21.0400 1658.0000 1.0000
21.0800 1683.0000 1.0000
21.1200 1645.0000 1.0000
21.1600 1683.0000 1.0000
21.2000 1654.0000 1.0000
21.2400 1645.0000 1.0000
21.2800 1612.0000 1.0000
21.3200 1656.0000 1.0000
21.3600 1686.0000 1.0000
21.4000 1660.0000 1.0000
21.4400 1690.0000 1.0000
21.4800 1742.0000 1.0000
21.5200 1712.0000 1.0000
21.5600 1685.0000 1.0000
21.6000 1665.0000 1.0000
21.6400 1641.0000 1.0000
21.6800 1658.0000 1.0000
21.7200 1651.0000 1.0000
21.7600 1661.0000 1.0000
21.8000 1685.0000 1.0000
21.8400 1687.0000 1.0000
21.8800 1641.0000 1.0000
21.9200 1628.0000 1.0000
21.9600 1775.0000 1.0000
22.0000 1640.0000 1.0000
22.0400 1634.0000 1.0000
22.0800 1600.0000 1.0000
22.1200 1669.0000 1.0000
22.1600 1730.0000 1.0000
22.2000 1647.0000 1.0000
22.2400 1658.0000 1.0000
22.2800 1613.0000 1.0000
22.3200 1646.0000 1.0000
22.3600 1666.0000 1.0000
22.4000 1661.0000 1.0000
22.4400 1713.0000 1.0000
22.4800 1626.0000 1.0000
22.5200 1718.0000 1.0000
22.5600 1689.0000 1.0000
22.6000 1679.0000 1.0000
22.6400 1670.0000 1.0000
22.6800 1664.0000 1.0000
22.7200 1725.0000 1.0000
22.7600 1672.0000 1.0000
22.8000 1621.0000 1.0000
22.8400 1638.0000 1.0000
22.8800 1642.0000 1.0000
22.9200 1714.0000 1.0000
22.9600 1695.0000 1.0000
23.0000 1751.0000 1.0000
23.0400 1640.0000 1.0000
23.0800 1615.0000 1.0000
23.1200 1642.0000 1.0000
23.1600 1684.0000 1.0000
23.2000 1720.0000 1.0000
23.2400 1637.0000 1.0000
23.2800 1737.0000 1.0000
23.3200 1695.0000 1.0000
23.3600 1742.0000 1.0000
23.4000 1711.0000 1.0000
23.4400 1640.0000 1.0000
23.4800 1643.0000 1.0000
23.5200 1682.0000 1.0000
23.5600 1729.0000 1.0000
23.6000 1693.0000 1.0000
23.6400 1662.0000 1.0000
23.6800 1714.0000 1.0000
23.7200 1694.0000 1.0000
23.7600 1611.0000 1.0000
23.8000 1681.0000 1.0000
23.8400 1712.0000 1.0000
23.8800 1730.0000 1.0000
23.9200 1690.0000 1.0000
23.9600 1699.0000 1.0000
24.0000 1709.0000 1.0000
24.0400 1671.0000 1.0000
24.0800 1784.0000 1.0000
24.1200 1717.0000 1.0000
24.1600 1714.0000 1.0000
24.2000 1674.0000 1.0000
24.2400 1769.0000 1.0000
24.2800 1750.0000 1.0000
24.3200 1708.0000 1.0000
24.3600 1647.0000 1.0000
24.4000 1691.0000 1.0000
24.4400 1755.0000 1.0000
24.4800 1713.0000 1.0000
24.5200 1662.0000 1.0000
24.5600 1750.0000 1.0000
24.6000 1697.0000 1.0000
24.6400 1721.0000 1.0000
24.6800 1751.0000 1.0000
24.7200 1769.0000 1.0000
24.7600 1719.0000 1.0000
24.8000 1780.0000 1.0000
24.8400 1792.0000 1.0000
24.8800 1790.0000 1.0000
24.9200 1825.0000 1.0000
24.9600 1792.0000 1.0000
25.0000 1821.0000 1.0000
25.0400 1775.0000 1.0000
25.0800 1731.0000 1.0000
25.1200 1769.0000 1.0000
25.1600 1802.0000 1.0000
25.2000 1723.0000 1.0000
25.2400 1775.0000 1.0000
25.2800 1733.0000 1.0000
25.3200 1729.0000 1.0000
25.3600 1773.0000 1.0000
25.4000 1772.0000 1.0000
25.4400 1744.0000 1.0000
25.4800 1688.0000 1.0000
25.5200 1776.0000 1.0000
25.5600 1703.0000 1.0000
25.6000 1762.0000 1.0000
25.6400 1756.0000 1.0000
25.6800 1781.0000 1.0000
25.7200 1704.0000 1.0000
25.7600 1770.0000 1.0000
25.8000 1773.0000 1.0000
25.8400 1714.0000 1.0000
25.8800 1761.0000 1.0000
25.9200 1720.0000 1.0000
25.9600 1745.0000 1.0000
26.0000 1735.0000 1.0000
26.0400 1766.0000 1.0000
26.0800 1740.0000 1.0000
26.1200 1714.0000 1.0000
26.1600 1761.0000 1.0000
26.2000 1855.0000 1.0000
26.2400 1738.0000 1.0000
26.2800 1756.0000 1.0000
26.3200 1782.0000 1.0000
26.3600 1801.0000 1.0000
26.4000 1888.0000 1.0000
26.4400 1832.0000 1.0000
26.4800 1833.0000 1.0000
26.5200 1915.0000 1.0000
26.5600 1779.0000 1.0000
26.6000 1845.0000 1.0000
26.6400 1772.0000 1.0000
26.6800 1839.0000 1.0000
26.7200 1874.0000 1.0000
26.7600 1881.0000 1.0000
26.8000 1959.0000 1.0000
26.8400 1932.0000 1.0000
26.8800 2000.0000 1.0000
26.9200 2125.0000 1.0000
26.9600 2186.0000 1.0000
27.0000 2374.0000 1.0000
27.0400 2500.0000 1.0000
27.0800 2766.0000 1.0000
27.1200 3233.0000 1.0000
27.1600 3791.0000 1.0000
27.2000 4612.0000 1.0000
27.2400 5649.0000 1.0000
27.2800 6495.0000 1.0000
27.3200 6658.0000 1.0000
27.3600 5937.0000 1.0000
27.4000 5026.0000 1.0000
27.4400 4038.0000 1.0000
27.4800 3383.0000 1.0000
27.5200 2912.0000 1.0000
27.5600 2696.0000 1.0000
27.6000 2386.0000 1.0000
27.6400 2201.0000 1.0000
27.6800 2168.0000 1.0000
27.7200 2029.0000 1.0000
27.7600 1987.0000 1.0000
27.8000 1935.0000 1.0000
27.8400 1888.0000 1.0000
27.8800 1816.0000 1.0000
27.9200 1891.0000 1.0000
27.9600 1816.0000 1.0000
28.0000 1824.0000 1.0000
28.0400 1811.0000 1.0000
28.0800 1683.0000 1.0000
28.1200 1695.0000 1.0000
28.1600 1741.0000 1.0000
28.2000 1740.0000 1.0000
28.2400 1750.0000 1.0000
28.2800 1710.0000 1.0000
28.3200 1688.0000 1.0000
28.3600 1706.0000 1.0000
28.4000 1680.0000 1.0000
28.4400 1691.0000 1.0000
28.4800 1644.0000 1.0000
28.5200 1653.0000 1.0000
28.5600 1714.0000 1.0000
28.6000 1632.0000 1.0000
28.6400 1647.0000 1.0000
28.6800 1610.0000 1.0000
28.7200 1636.0000 1.0000
28.7600 1633.0000 1.0000
28.8000 1679.0000 1.0000
28.8400 1615.0000 1.0000
28.8800 1571.0000 1.0000
28.9200 1630.0000 1.0000
28.9600 1623.0000 1.0000
29.0000 1647.0000 1.0000
29.0400 1604.0000 1.0000
29.0800 1600.0000 1.0000
29.1200 1641.0000 1.0000
29.1600 1612.0000 1.0000
29.2000 1639.0000 1.0000
29.2400 1578.0000 1.0000
29.2800 1716.0000 1.0000
29.3200 1598.0000 1.0000
29.3600 1594.0000 1.0000
29.4000 1596.0000 1.0000
29.4400 1572.0000 1.0000
29.4800 1544.0000 1.0000
29.5200 1599.0000 1.0000
29.5600 1586.0000 1.0000
29.6000 1576.0000 1.0000
29.6400 1584.0000 1.0000
29.6800 1626.0000 1.0000
29.7200 1593.0000 1.0000
29.7600 1588.0000 1.0000
29.8000 1595.0000 1.0000
29.8400 1530.0000 1.0000
29.8800 1544.0000 1.0000
29.9200 1574.0000 1.0000
29.9600 1645.0000 1.0000
30.0000 1612.0000 1.0000
30.0400 1571.0000 1.0000
30.0800 1586.0000 1.0000
30.1200 1616.0000 1.0000
30.1600 1535.0000 1.0000
30.2000 1642.0000 1.0000
30.2400 1555.0000 1.0000
30.2800 1550.0000 1.0000
30.3200 1497.0000 1.0000
30.3600 1487.0000 1.0000
30.4000 1493.0000 1.0000
30.4400 1470.0000 1.0000
30.4800 1540.0000 1.0000
30.5200 1562.0000 1.0000
30.5600 1533.0000 1.0000
30.6000 1541.0000 1.0000
30.6400 1467.0000 1.0000
30.6800 1519.0000 1.0000
30.7200 1500.0000 1.0000
30.7600 1469.0000 1.0000
30.8000 1513.0000 1.0000
30.8400 1518.0000 1.0000
30.8800 1465.0000 1.0000
30.9200 1508.0000 1.0000
30.9600 1450.0000 1.0000
31.0000 1468.0000 1.0000
31.0400 1524.0000 1.0000
31.0800 1495.0000 1.0000
31.1200 1482.0000 1.0000
31.1600 1478.0000 1.0000
31.2000 1501.0000 1.0000
31.2400 1462.0000 1.0000
31.2800 1508.0000 1.0000
31.3200 1469.0000 1.0000
31.3600 1443.0000 1.0000
31.4000 1460.0000 1.0000
31.4400 1554.0000 1.0000
31.4800 1452.0000 1.0000
31.5200 1503.0000 1.0000
31.5600 1529.0000 1.0000
31.6000 1469.0000 1.0000
31.6400 1442.0000 1.0000
31.6800 1437.0000 1.0000
31.7200 1465.0000 1.0000
31.7600 1448.0000 1.0000
31.8000 1473.0000 1.0000
31.8400 1433.0000 1.0000
31.8800 1487.0000 1.0000
31.9200 1534.0000 1.0000
31.9600 1452.0000 1.0000
32.0000 1440.0000 1.0000
32.0400 1479.0000 1.0000
32.0800 1427.0000 1.0000
32.1200 1462.0000 1.0000
32.1600 1412.0000 1.0000
32.2000 1492.0000 1.0000
32.2400 1470.0000 1.0000
32.2800 1432.0000 1.0000
32.3200 1405.0000 1.0000
32.3600 1417.0000 1.0000
32.4000 1390.0000 1.0000
32.4400 1421.0000 1.0000
32.4800 1426.0000 1.0000
32.5200 1406.0000 1.0000
32.5600 1378.0000 1.0000
32.6000 1395.0000 1.0000
32.6400 1389.0000 1.0000
32.6800 1420.0000 1.0000
32.7200 1404.0000 1.0000
32.7600 1388.0000 1.0000
32.8000 1410.0000 1.0000
32.8400 1421.0000 1.0000
32.8800 1383.0000 1.0000
32.9200 1355.0000 1.0000
32.9600 1419.0000 1.0000
33.0000 1354.0000 1.0000
33.0400 1386.0000 1.0000
33.0800 1395.0000 1.0000
33.1200 1359.0000 1.0000
33.1600 1409.0000 1.0000
33.2000 1351.0000 1.0000
33.2400 1370.0000 1.0000
33.2800 1381.0000 1.0000
33.3200 1408.0000 1.0000
33.3600 1328.0000 1.0000
33.4000 1398.0000 1.0000
33.4400 1338.0000 1.0000
33.4800 1391.0000 1.0000
33.5200 1380.0000 1.0000
33.5600 1349.0000 1.0000
33.6000 1426.0000 1.0000
33.6400 1329.0000 1.0000
33.6800 1430.0000 1.0000
33.7200 1344.0000 1.0000
33.7600 1376.0000 1.0000
33.8000 1490.0000 1.0000
33.8400 1474.0000 1.0000
33.8800 1607.0000 1.0000
33.9200 1575.0000 1.0000
33.9600 1554.0000 1.0000
34.0000 1633.0000 1.0000
34.0400 1574.0000 1.0000
34.0800 1556.0000 1.0000
34.1200 1561.0000 1.0000
34.1600 1521.0000 1.0000
34.2000 1646.0000 1.0000
34.2400 1694.0000 1.0000
34.2800 1766.0000 1.0000
34.3200 1975.0000 1.0000
34.3600 2101.0000 1.0000
34.4000 2433.0000 1.0000
34.4400 2792.0000 1.0000
34.4800 3157.0000 1.0000
34.5200 3175.0000 1.0000
34.5600 3006.0000 1.0000
34.6000 2663.0000 1.0000
34.6400 2287.0000 1.0000
34.6800 2104.0000 1.0000
34.7200 1830.0000 1.0000
34.7600 1643.0000 1.0000
34.8000 1637.0000 1.0000
34.8400 1510.0000 1.0000
34.8800 1455.0000 1.0000
34.9200 1400.0000 1.0000
34.9600 1365.0000 1.0000
35.0000 1357.0000 1.0000
35.0400 1360.0000 1.0000
35.0800 1268.0000 1.0000
35.1200 1266.0000 1.0000
35.1600 1266.0000 1.0000
35.2000 1277.0000 1.0000
35.2400 1224.0000 1.0000
35.2800 1295.0000 1.0000
35.3200 1278.0000 1.0000
35.3600 1258.0000 1.0000
35.4000 1218.0000 1.0000
35.4400 1213.0000 1.0000
35.4800 1183.0000 1.0000
35.5200 1207.0000 1.0000
35.5600 1249.0000 1.0000
35.6000 1228.0000 1.0000
35.6400 1176.0000 1.0000
35.6800 1193.0000 1.0000
35.7200 1187.0000 1.0000
35.7600 1190.0000 1.0000
35.8000 1143.0000 1.0000
35.8400 1181.0000 1.0000
35.8800 1178.0000 1.0000
35.9200 1171.0000 1.0000
35.9600 1196.0000 1.0000
36.0000 1182.0000 1.0000
36.0400 1188.0000 1.0000
36.0800 1202.0000 1.0000
36.1200 1269.0000 1.0000
36.1600 1201.0000 1.0000
36.2000 1196.0000 1.0000
36.2400 1340.0000 1.0000
36.2800 1409.0000 1.0000
36.3200 1603.0000 1.0000
36.3600 1898.0000 1.0000
36.4000 2166.0000 1.0000
36.4400 2127.0000 1.0000
36.4800 1857.0000 1.0000
36.5200 1706.0000 1.0000
36.5600 1479.0000 1.0000
36.6000 1293.0000 1.0000
36.6400 1200.0000 1.0000
36.6800 1170.0000 1.0000
36.7200 1116.0000 1.0000
36.7600 1111.0000 1.0000
36.8000 1098.0000 1.0000
36.8400 1079.0000 1.0000
36.8800 1066.0000 1.0000
36.9200 1095.0000 1.0000
36.9600 1086.0000 1.0000
37.0000 1106.0000 1.0000
37.0400 1067.0000 1.0000
37.0800 1038.0000 1.0000
37.1200 1084.0000 1.0000
37.1600 1083.0000 1.0000
37.2000 1080.0000 1.0000
37.2400 1056.0000 1.0000
37.2800 1139.0000 1.0000
37.3200 1153.0000 1.0000
37.3600 1131.0000 1.0000
37.4000 1070.0000 1.0000
37.4400 1094.0000 1.0000
37.4800 1118.0000 1.0000
37.5200 1034.0000 1.0000
37.5600 1041.0000 1.0000
37.6000 1056.0000 1.0000
37.6400 1069.0000 1.0000
37.6800 1114.0000 1.0000
37.7200 1086.0000 1.0000
37.7600 1093.0000 1.0000
37.8000 1126.0000 1.0000
37.8400 1148.0000 1.0000
37.8800 1098.0000 1.0000
37.9200 1140.0000 1.0000
37.9600 1106.0000 1.0000
38.0000 1228.0000 1.0000
38.0400 1192.0000 1.0000
38.0800 1227.0000 1.0000
38.1200 1229.0000 1.0000
38.1600 1340.0000 1.0000
38.2000 1457.0000 1.0000
38.2400 1625.0000 1.0000
38.2800 1819.0000 1.0000
38.3200 2165.0000 1.0000
38.3600 2628.0000 1.0000
38.4000 3231.0000 1.0000
38.4400 4402.0000 1.0000
38.4800 5654.0000 1.0000
38.5200 6509.0000 1.0000
38.5600 7186.0000 1.0000
38.6000 6721.0000 1.0000
38.6400 5791.0000 1.0000
38.6800 4664.0000 1.0000
38.7200 3564.0000 1.0000
38.7600 2730.0000 1.0000
38.8000 2169.0000 1.0000
38.8400 1820.0000 1.0000
38.8800 1512.0000 1.0000
38.9200 1378.0000 1.0000
38.9600 1272.0000 1.0000
39.0000 1232.0000 1.0000
39.0400 1160.0000 1.0000
39.0800 1094.0000 1.0000
39.1200 1142.0000 1.0000
39.1600 1074.0000 1.0000
39.2000 1040.0000 1.0000
39.2400 1021.0000 1.0000
39.2800 1038.0000 1.0000
39.3200 995.0000 1.0000
39.3600 1017.0000 1.0000
39.4000 1031.0000 1.0000
39.4400 1057.0000 1.0000
39.4800 1023.0000 1.0000
39.5200 1015.0000 1.0000
39.5600 1024.0000 1.0000
39.6000 1080.0000 1.0000
39.6400 1025.0000 1.0000
39.6800 987.0000 1.0000
39.7200 1058.0000 1.0000
39.7600 948.0000 1.0000
39.8000 975.0000 1.0000
39.8400 993.0000 1.0000
39.8800 968.0000 1.0000
39.9200 895.0000 1.0000
39.9600 933.0000 1.0000
40.0000 908.0000 1.0000
40.0400 933.0000 1.0000
40.0800 921.0000 1.0000
40.1200 919.0000 1.0000
40.1600 942.0000 1.0000
40.2000 934.0000 1.0000
40.2400 926.0000 1.0000
40.2800 919.0000 1.0000
40.3200 937.0000 1.0000
40.3600 883.0000 1.0000
40.4000 887.0000 1.0000
40.4400 934.0000 1.0000
40.4800 864.0000 1.0000
40.5200 864.0000 1.0000
40.5600 926.0000 1.0000
40.6000 866.0000 1.0000
40.6400 899.0000 1.0000
40.6800 873.0000 1.0000
40.7200 891.0000 1.0000
40.7600 909.0000 1.0000
40.8000 914.0000 1.0000
40.8400 906.0000 1.0000
40.8800 839.0000 1.0000
40.9200 856.0000 1.0000
40.9600 881.0000 1.0000
41.0000 950.0000 1.0000
41.0400 909.0000 1.0000
41.0800 890.0000 1.0000
41.1200 868.0000 1.0000
41.1600 864.0000 1.0000
41.2000 887.0000 1.0000
41.2400 878.0000 1.0000
41.2800 858.0000 1.0000
41.3200 859.0000 1.0000
41.3600 893.0000 1.0000
41.4000 825.0000 1.0000
41.4400 840.0000 1.0000
41.4800 843.0000 1.0000
41.5200 881.0000 1.0000
41.5600 921.0000 1.0000
41.6000 905.0000 1.0000
41.6400 977.0000 1.0000
41.6800 891.0000 1.0000
41.7200 885.0000 1.0000
41.7600 890.0000 1.0000
41.8000 932.0000 1.0000
41.8400 937.0000 1.0000
41.8800 913.0000 1.0000
41.9200 922.0000 1.0000
41.9600 871.0000 1.0000
42.0000 847.0000 1.0000
42.0400 829.0000 1.0000
42.0800 875.0000 1.0000
42.1200 829.0000 1.0000
42.1600 845.0000 1.0000
42.2000 895.0000 1.0000
42.2400 863.0000 1.0000
42.2800 953.0000 1.0000
42.3200 852.0000 1.0000
42.3600 862.0000 1.0000
42.4000 890.0000 1.0000
42.4400 876.0000 1.0000
42.4800 827.0000 1.0000
42.5200 859.0000 1.0000
42.5600 870.0000 1.0000
42.6000 892.0000 1.0000
42.6400 803.0000 1.0000
42.6800 832.0000 1.0000
42.7200 889.0000 1.0000
42.7600 875.0000 1.0000
42.8000 868.0000 1.0000
42.8400 838.0000 1.0000
42.8800 858.0000 1.0000
42.9200 881.0000 1.0000
42.9600 889.0000 1.0000
43.0000 867.0000 1.0000
43.0400 866.0000 1.0000
43.0800 897.0000 1.0000
43.1200 823.0000 1.0000
43.1600 940.0000 1.0000
43.2000 919.0000 1.0000
43.2400 942.0000 1.0000
43.2800 965.0000 1.0000
43.3200 933.0000 1.0000
43.3600 965.0000 1.0000
43.4000 946.0000 1.0000
43.4400 873.0000 1.0000
43.4800 870.0000 1.0000
43.5200 887.0000 1.0000
43.5600 871.0000 1.0000
43.6000 878.0000 1.0000
43.6400 859.0000 1.0000
43.6800 882.0000 1.0000
43.7200 814.0000 1.0000
43.7600 878.0000 1.0000
43.8000 802.0000 1.0000
43.8400 853.0000 1.0000
43.8800 847.0000 1.0000
43.9200 868.0000 1.0000
43.9600 842.0000 1.0000
44.0000 817.0000 1.0000
44.0400 828.0000 1.0000
44.0800 821.0000 1.0000
44.1200 861.0000 1.0000
44.1600 811.0000 1.0000
44.2000 854.0000 1.0000
44.2400 876.0000 1.0000
44.2800 857.0000 1.0000
44.3200 839.0000 1.0000
44.3600 863.0000 1.0000
44.4000 819.0000 1.0000
44.4400 866.0000 1.0000
44.4800 850.0000 1.0000
44.5200 783.0000 1.0000
44.5600 821.0000 1.0000
44.6000 811.0000 1.0000
44.6400 826.0000 1.0000
44.6800 812.0000 1.0000
44.7200 825.0000 1.0000
44.7600 805.0000 1.0000
44.8000 805.0000 1.0000
44.8400 864.0000 1.0000
44.8800 873.0000 1.0000
44.9200 849.0000 1.0000
44.9600 802.0000 1.0000
45.0000 832.0000 1.0000
45.0400 859.0000 1.0000
45.0800 791.0000 1.0000
45.1200 816.0000 1.0000
45.1600 843.0000 1.0000
45.2000 808.0000 1.0000
45.2400 843.0000 1.0000
45.2800 811.0000 1.0000
45.3200 800.0000 1.0000
45.3600 776.0000 1.0000
45.4000 813.0000 1.0000
45.4400 766.0000 1.0000
45.4800 820.0000 1.0000
45.5200 779.0000 1.0000
45.5600 787.0000 1.0000
45.6000 829.0000 1.0000
45.6400 785.0000 1.0000
45.6800 822.0000 1.0000
45.7200 780.0000 1.0000
45.7600 816.0000 1.0000
45.8000 817.0000 1.0000
45.8400 841.0000 1.0000
45.8800 775.0000 1.0000
45.9200 840.0000 1.0000
45.9600 872.0000 1.0000
46.0000 815.0000 1.0000
46.0400 799.0000 1.0000
46.0800 756.0000 1.0000
46.1200 806.0000 1.0000
46.1600 754.0000 1.0000
46.2000 833.0000 1.0000
46.2400 774.0000 1.0000
46.2800 815.0000 1.0000
46.3200 804.0000 1.0000
46.3600 783.0000 1.0000
46.4000 792.0000 1.0000
46.4400 795.0000 1.0000
46.4800 785.0000 1.0000
46.5200 824.0000 1.0000
46.5600 796.0000 1.0000
46.6000 768.0000 1.0000
46.6400 779.0000 1.0000
46.6800 736.0000 1.0000
46.7200 774.0000 1.0000
46.7600 812.0000 1.0000
46.8000 832.0000 1.0000
46.8400 802.0000 1.0000
46.8800 802.0000 1.0000
46.9200 795.0000 1.0000
46.9600 805.0000 1.0000
47.0000 824.0000 1.0000
47.0400 809.0000 1.0000
47.0800 790.0000 1.0000
47.1200 783.0000 1.0000
47.1600 777.0000 1.0000
47.2000 751.0000 1.0000
47.2400 774.0000 1.0000
47.2800 792.0000 1.0000
47.3200 781.0000 1.0000
47.3600 779.0000 1.0000
47.4000 736.0000 1.0000
47.4400 789.0000 1.0000
47.4800 825.0000 1.0000
47.5200 787.0000 1.0000
47.5600 750.0000 1.0000
47.6000 796.0000 1.0000
47.6400 731.0000 1.0000
47.6800 754.0000 1.0000
47.7200 759.0000 1.0000
47.7600 769.0000 1.0000
47.8000 803.0000 1.0000
47.8400 808.0000 1.0000
47.8800 755.0000 1.0000
47.9200 790.0000 1.0000
47.9600 819.0000 1.0000
48.0000 734.0000 1.0000
48.0400 755.0000 1.0000
48.0800 781.0000 1.0000
48.1200 807.0000 1.0000
48.1600 734.0000 1.0000
48.2000 777.0000 1.0000
48.2400 752.0000 1.0000
48.2800 766.0000 1.0000
48.3200 790.0000 1.0000
48.3600 749.0000 1.0000
48.4000 764.0000 1.0000
48.4400 762.0000 1.0000
48.4800 726.0000 1.0000
48.5200 704.0000 1.0000
48.5600 766.0000 1.0000
48.6000 723.0000 1.0000
48.6400 729.0000 1.0000
48.6800 738.0000 1.0000
48.7200 743.0000 1.0000
48.7600 729.0000 1.0000
48.8000 724.0000 1.0000
48.8400 696.0000 1.0000
48.8800 741.0000 1.0000
48.9200 746.0000 1.0000
48.9600 725.0000 1.0000
49.0000 732.0000 1.0000
49.0400 704.0000 1.0000
49.0800 784.0000 1.0000
49.1200 721.0000 1.0000
49.1600 748.0000 1.0000
49.2000 750.0000 1.0000
49.2400 715.0000 1.0000
49.2800 755.0000 1.0000
49.3200 733.0000 1.0000
49.3600 723.0000 1.0000
49.4000 740.0000 1.0000
49.4400 731.0000 1.0000
49.4800 705.0000 1.0000
49.5200 706.0000 1.0000
49.5600 723.0000 1.0000
49.6000 746.0000 1.0000
49.6400 770.0000 1.0000
49.6800 803.0000 1.0000
49.7200 790.0000 1.0000
49.7600 774.0000 1.0000
49.8000 711.0000 1.0000
49.8400 783.0000 1.0000
49.8800 742.0000 1.0000
49.9200 743.0000 1.0000
49.9600 716.0000 1.0000
50.0000 737.0000 1.0000
50.0400 752.0000 1.0000
50.0800 750.0000 1.0000
50.1200 762.0000 1.0000
50.1600 755.0000 1.0000
50.2000 806.0000 1.0000
50.2400 762.0000 1.0000
50.2800 762.0000 1.0000
50.3200 773.0000 1.0000
50.3600 753.0000 1.0000
50.4000 750.0000 1.0000
50.4400 744.0000 1.0000
50.4800 780.0000 1.0000
50.5200 786.0000 1.0000
50.5600 718.0000 1.0000
50.6000 715.0000 1.0000
50.6400 771.0000 1.0000
50.6800 779.0000 1.0000
50.7200 762.0000 1.0000
50.7600 731.0000 1.0000
50.8000 698.0000 1.0000
50.8400 735.0000 1.0000
50.8800 742.0000 1.0000
50.9200 761.0000 1.0000
50.9600 749.0000 1.0000
51.0000 739.0000 1.0000
51.0400 704.0000 1.0000
51.0800 751.0000 1.0000
51.1200 712.0000 1.0000
51.1600 788.0000 1.0000
51.2000 762.0000 1.0000
51.2400 764.0000 1.0000
51.2800 797.0000 1.0000
51.3200 745.0000 1.0000
51.3600 794.0000 1.0000
51.4000 712.0000 1.0000
51.4400 729.0000 1.0000
51.4800 764.0000 1.0000
51.5200 802.0000 1.0000
51.5600 752.0000 1.0000
51.6000 784.0000 1.0000
51.6400 829.0000 1.0000
51.6800 765.0000 1.0000
51.7200 764.0000 1.0000
51.7600 784.0000 1.0000
51.8000 860.0000 1.0000
51.8400 861.0000 1.0000
51.8800 864.0000 1.0000
51.9200 885.0000 1.0000
51.9600 1037.0000 1.0000
52.0000 1117.0000 1.0000
52.0400 1336.0000 1.0000
52.0800 1531.0000 1.0000
52.1200 1884.0000 1.0000
52.1600 2406.0000 1.0000
52.2000 3355.0000 1.0000
52.2400 4480.0000 1.0000
52.2800 5197.0000 1.0000
52.3200 5019.0000 1.0000
52.3600 4341.0000 1.0000
52.4000 4038.0000 1.0000
52.4400 3415.0000 1.0000
52.4800 2662.0000 1.0000
52.5200 2087.0000 1.0000
52.5600 1559.0000 1.0000
52.6000 1384.0000 1.0000
52.6400 1177.0000 1.0000
52.6800 1021.0000 1.0000
52.7200 1006.0000 1.0000
52.7600 956.0000 1.0000
52.8000 915.0000 1.0000
52.8400 909.0000 1.0000
52.8800 847.0000 1.0000
52.9200 786.0000 1.0000
52.9600 800.0000 1.0000
53.0000 773.0000 1.0000
53.0400 783.0000 1.0000
53.0800 769.0000 1.0000
53.1200 766.0000 1.0000
53.1600 783.0000 1.0000
53.2000 758.0000 1.0000
53.2400 794.0000 1.0000
53.2800 775.0000 1.0000
53.3200 743.0000 1.0000
53.3600 777.0000 1.0000
53.4000 778.0000 1.0000
53.4400 731.0000 1.0000
53.4800 717.0000 1.0000
53.5200 711.0000 1.0000
53.5600 751.0000 1.0000
53.6000 725.0000 1.0000
53.6400 763.0000 1.0000
53.6800 719.0000 1.0000
53.7200 704.0000 1.0000
53.7600 732.0000 1.0000
53.8000 725.0000 1.0000
53.8400 730.0000 1.0000
53.8800 752.0000 1.0000
53.9200 726.0000 1.0000
53.9600 752.0000 1.0000
54.0000 708.0000 1.0000
54.0400 752.0000 1.0000
54.0800 721.0000 1.0000
54.1200 715.0000 1.0000
54.1600 686.0000 1.0000
54.2000 746.0000 1.0000
54.2400 701.0000 1.0000
54.2800 725.0000 1.0000
54.3200 776.0000 1.0000
54.3600 743.0000 1.0000
54.4000 710.0000 1.0000
54.4400 710.0000 1.0000
54.4800 750.0000 1.0000
54.5200 816.0000 1.0000
54.5600 781.0000 1.0000
54.6000 739.0000 1.0000
54.6400 756.0000 1.0000
54.6800 737.0000 1.0000
54.7200 789.0000 1.0000
54.7600 769.0000 1.0000
54.8000 784.0000 1.0000
54.8400 823.0000 1.0000
54.8800 797.0000 1.0000
54.9200 790.0000 1.0000
54.9600 800.0000 1.0000
55.0000 808.0000 1.0000
55.0400 806.0000 1.0000
55.0800 800.0000 1.0000
55.1200 885.0000 1.0000
55.1600 911.0000 1.0000
55.2000 969.0000 1.0000
55.2400 1050.0000 1.0000
55.2800 1078.0000 1.0000
55.3200 1102.0000 1.0000
55.3600 1064.0000 1.0000
55.4000 1054.0000 1.0000
55.4400 1025.0000 1.0000
55.4800 945.0000 1.0000
55.5200 882.0000 1.0000
55.5600 851.0000 1.0000
55.6000 825.0000 1.0000
55.6400 800.0000 1.0000
55.6800 738.0000 1.0000
55.7200 717.0000 1.0000
55.7600 758.0000 1.0000
55.8000 727.0000 1.0000
55.8400 778.0000 1.0000
55.8800 725.0000 1.0000
55.9200 766.0000 1.0000
55.9600 750.0000 1.0000
56.0000 758.0000 1.0000
56.0400 728.0000 1.0000
56.0800 696.0000 1.0000
56.1200 725.0000 1.0000
56.1600 727.0000 1.0000
56.2000 695.0000 1.0000
56.2400 695.0000 1.0000
56.2800 691.0000 1.0000
56.3200 697.0000 1.0000
56.3600 670.0000 1.0000
56.4000 704.0000 1.0000
56.4400 742.0000 1.0000
56.4800 692.0000 1.0000
56.5200 722.0000 1.0000
56.5600 723.0000 1.0000
56.6000 661.0000 1.0000
56.6400 655.0000 1.0000
56.6800 659.0000 1.0000
56.7200 690.0000 1.0000
56.7600 728.0000 1.0000
56.8000 723.0000 1.0000
56.8400 702.0000 1.0000
56.8800 705.0000 1.0000
56.9200 740.0000 1.0000
56.9600 703.0000 1.0000
57.0000 659.0000 1.0000
57.0400 711.0000 1.0000
57.0800 724.0000 1.0000
57.1200 686.0000 1.0000
57.1600 691.0000 1.0000
57.2000 666.0000 1.0000
57.2400 694.0000 1.0000
57.2800 662.0000 1.0000
57.3200 703.0000 1.0000
57.3600 669.0000 1.0000
57.4000 708.0000 1.0000
57.4400 664.0000 1.0000
57.4800 668.0000 1.0000
57.5200 701.0000 1.0000
57.5600 693.0000 1.0000
57.6000 748.0000 1.0000
57.6400 690.0000 1.0000
57.6800 700.0000 1.0000
57.7200 676.0000 1.0000
57.7600 711.0000 1.0000
57.8000 691.0000 1.0000
57.8400 685.0000 1.0000
57.8800 735.0000 1.0000
57.9200 690.0000 1.0000
57.9600 710.0000 1.0000
58.0000 719.0000 1.0000
58.0400 704.0000 1.0000
58.0800 718.0000 1.0000
58.1200 743.0000 1.0000
58.1600 725.0000 1.0000
58.2000 727.0000 1.0000
58.2400 720.0000 1.0000
58.2800 724.0000 1.0000
58.3200 734.0000 1.0000
58.3600 739.0000 1.0000
58.4000 711.0000 1.0000
58.4400 656.0000 1.0000
58.4800 712.0000 1.0000
58.5200 708.0000 1.0000
58.5600 676.0000 1.0000
58.6000 689.0000 1.0000
58.6400 705.0000 1.0000
58.6800 732.0000 1.0000
58.7200 664.0000 1.0000
58.7600 702.0000 1.0000
58.8000 692.0000 1.0000
58.8400 666.0000 1.0000
58.8800 703.0000 1.0000
58.9200 689.0000 1.0000
58.9600 712.0000 1.0000
59.0000 672.0000 1.0000
59.0400 709.0000 1.0000
59.0800 719.0000 1.0000
59.1200 679.0000 1.0000
59.1600 737.0000 1.0000
59.2000 678.0000 1.0000
59.2400 681.0000 1.0000
59.2800 676.0000 1.0000
59.3200 722.0000 1.0000
59.3600 700.0000 1.0000
59.4000 689.0000 1.0000
59.4400 687.0000 1.0000
59.4800 706.0000 1.0000
59.5200 715.0000 1.0000
59.5600 658.0000 1.0000
59.6000 725.0000 1.0000
59.6400 664.0000 1.0000
59.6800 721.0000 1.0000
59.7200 669.0000 1.0000
59.7600 654.0000 1.0000
59.8000 670.0000 1.0000
59.8400 676.0000 1.0000
59.8800 737.0000 1.0000
59.9200 712.0000 1.0000
59.9600 729.0000 1.0000
60.0000 694.0000 1.0000
60.0400 676.0000 1.0000
60.0800 704.0000 1.0000
60.1200 737.0000 1.0000
60.1600 713.0000 1.0000
60.2000 691.0000 1.0000
60.2400 697.0000 1.0000
60.2800 723.0000 1.0000
60.3200 688.0000 1.0000
60.3600 691.0000 1.0000
60.4000 659.0000 1.0000
60.4400 732.0000 1.0000
60.4800 696.0000 1.0000
60.5200 709.0000 1.0000
60.5600 682.0000 1.0000
60.6000 680.0000 1.0000
60.6400 641.0000 1.0000
60.6800 684.0000 1.0000
60.7200 695.0000 1.0000
60.7600 664.0000 1.0000
60.8000 710.0000 1.0000
60.8400 642.0000 1.0000
60.8800 691.0000 1.0000
60.9200 742.0000 1.0000
60.9600 732.0000 1.0000
61.0000 690.0000 1.0000
61.0400 675.0000 1.0000
61.0800 707.0000 1.0000
61.1200 710.0000 1.0000
61.1600 718.0000 1.0000
61.2000 703.0000 1.0000
61.2400 680.0000 1.0000
61.2800 703.0000 1.0000
61.3200 687.0000 1.0000
61.3600 729.0000 1.0000
61.4000 691.0000 1.0000
61.4400 704.0000 1.0000
61.4800 726.0000 1.0000
61.5200 710.0000 1.0000
61.5600 689.0000 1.0000
61.6000 689.0000 1.0000
61.6400 700.0000 1.0000
61.6800 710.0000 1.0000
61.7200 797.0000 1.0000
61.7600 719.0000 1.0000
61.8000 750.0000 1.0000
61.8400 746.0000 1.0000
61.8800 801.0000 1.0000
61.9200 841.0000 1.0000
61.9600 803.0000 1.0000
62.0000 856.0000 1.0000
62.0400 918.0000 1.0000
62.0800 959.0000 1.0000
62.1200 1134.0000 1.0000
62.1600 1291.0000 1.0000
62.2000 1329.0000 1.0000
62.2400 1520.0000 1.0000
62.2800 1608.0000 1.0000
62.3200 1667.0000 1.0000
62.3600 1636.0000 1.0000
62.4000 1581.0000 1.0000
62.4400 1495.0000 1.0000
62.4800 1415.0000 1.0000
62.5200 1304.0000 1.0000
62.5600 1190.0000 1.0000
62.6000 1065.0000 1.0000
62.6400 1063.0000 1.0000
62.6800 939.0000 1.0000
62.7200 916.0000 1.0000
62.7600 886.0000 1.0000
62.8000 825.0000 1.0000
62.8400 827.0000 1.0000
62.8800 786.0000 1.0000
62.9200 789.0000 1.0000
62.9600 746.0000 1.0000
63.0000 729.0000 1.0000
63.0400 781.0000 1.0000
63.0800 798.0000 1.0000
63.1200 754.0000 1.0000
63.1600 758.0000 1.0000
63.2000 746.0000 1.0000
63.2400 720.0000 1.0000
63.2800 700.0000 1.0000
63.3200 761.0000 1.0000
63.3600 722.0000 1.0000
63.4000 701.0000 1.0000
63.4400 673.0000 1.0000
63.4800 716.0000 1.0000
63.5200 693.0000 1.0000
63.5600 685.0000 1.0000
63.6000 703.0000 1.0000
63.6400 715.0000 1.0000
63.6800 701.0000 1.0000
63.7200 663.0000 1.0000
63.7600 699.0000 1.0000
63.8000 669.0000 1.0000
63.8400 688.0000 1.0000
63.8800 707.0000 1.0000
63.9200 740.0000 1.0000
63.9600 720.0000 1.0000
64.0000 702.0000 1.0000
64.0400 742.0000 1.0000
64.0800 729.0000 1.0000
64.1200 687.0000 1.0000
64.1600 690.0000 1.0000
64.2000 719.0000 1.0000
64.2400 693.0000 1.0000
64.2800 670.0000 1.0000
64.3200 729.0000 1.0000
64.3600 722.0000 1.0000
64.4000 696.0000 1.0000
64.4400 746.0000 1.0000
64.4800 675.0000 1.0000
64.5200 746.0000 1.0000
64.5600 787.0000 1.0000
64.6000 772.0000 1.0000
64.6400 846.0000 1.0000
64.6800 926.0000 1.0000
64.7200 956.0000 1.0000
64.7600 892.0000 1.0000
64.8000 837.0000 1.0000
64.8400 867.0000 1.0000
64.8800 801.0000 1.0000
64.9200 802.0000 1.0000
64.9600 809.0000 1.0000
65.0000 789.0000 1.0000
65.0400 718.0000 1.0000
65.0800 708.0000 1.0000
65.1200 731.0000 1.0000
65.1600 720.0000 1.0000
65.2000 740.0000 1.0000
65.2400 750.0000 1.0000
65.2800 691.0000 1.0000
65.3200 762.0000 1.0000
65.3600 680.0000 1.0000
65.4000 710.0000 1.0000
65.4400 719.0000 1.0000
65.4800 759.0000 1.0000
65.5200 736.0000 1.0000
65.5600 702.0000 1.0000
65.6000 760.0000 1.0000
65.6400 762.0000 1.0000
65.6800 786.0000 1.0000
65.7200 737.0000 1.0000
65.7600 748.0000 1.0000
65.8000 791.0000 1.0000
65.8400 777.0000 1.0000
65.8800 877.0000 1.0000
65.9200 879.0000 1.0000
65.9600 938.0000 1.0000
66.0000 1039.0000 1.0000
66.0400 1097.0000 1.0000
66.0800 1245.0000 1.0000
66.1200 1508.0000 1.0000
66.1600 1831.0000 1.0000
66.2000 2270.0000 1.0000
66.2400 2552.0000 1.0000
66.2800 2825.0000 1.0000
66.3200 2775.0000 1.0000
66.3600 2440.0000 1.0000
66.4000 2392.0000 1.0000
66.4400 2252.0000 1.0000
66.4800 2062.0000 1.0000
66.5200 1822.0000 1.0000
66.5600 1465.0000 1.0000
66.6000 1285.0000 1.0000
66.6400 1157.0000 1.0000
66.6800 1018.0000 1.0000
66.7200 950.0000 1.0000
66.7600 839.0000 1.0000
66.8000 801.0000 1.0000
66.8400 819.0000 1.0000
66.8800 769.0000 1.0000
66.9200 778.0000 1.0000
66.9600 746.0000 1.0000
67.0000 737.0000 1.0000
67.0400 704.0000 1.0000
67.0800 697.0000 1.0000
67.1200 719.0000 1.0000
67.1600 710.0000 1.0000
67.2000 661.0000 1.0000
67.2400 660.0000 1.0000
67.2800 688.0000 1.0000
67.3200 680.0000 1.0000
67.3600 660.0000 1.0000
67.4000 632.0000 1.0000
67.4400 646.0000 1.0000
67.4800 670.0000 1.0000
67.5200 659.0000 1.0000
67.5600 716.0000 1.0000
67.6000 657.0000 1.0000
67.6400 664.0000 1.0000
67.6800 663.0000 1.0000
67.7200 647.0000 1.0000
67.7600 660.0000 1.0000
67.8000 680.0000 1.0000
67.8400 628.0000 1.0000
67.8800 650.0000 1.0000
67.9200 657.0000 1.0000
67.9600 693.0000 1.0000
68.0000 660.0000 1.0000
68.0400 648.0000 1.0000
68.0800 643.0000 1.0000
68.1200 660.0000 1.0000
68.1600 648.0000 1.0000
68.2000 623.0000 1.0000
68.2400 629.0000 1.0000
68.2800 621.0000 1.0000
68.3200 658.0000 1.0000
68.3600 671.0000 1.0000
68.4000 625.0000 1.0000
68.4400 631.0000 1.0000
68.4800 640.0000 1.0000
68.5200 649.0000 1.0000
68.5600 682.0000 1.0000
68.6000 636.0000 1.0000
68.6400 628.0000 1.0000
68.6800 635.0000 1.0000
68.7200 621.0000 1.0000
68.7600 620.0000 1.0000
68.8000 605.0000 1.0000
68.8400 627.0000 1.0000
68.8800 657.0000 1.0000
68.9200 630.0000 1.0000
68.9600 585.0000 1.0000
69.0000 619.0000 1.0000
69.0400 579.0000 1.0000
69.0800 620.0000 1.0000
69.1200 599.0000 1.0000
69.1600 643.0000 1.0000
69.2000 627.0000 1.0000
69.2400 570.0000 1.0000
69.2800 614.0000 1.0000
69.3200 613.0000 1.0000
69.3600 646.0000 1.0000
69.4000 617.0000 1.0000
69.4400 631.0000 1.0000
69.4800 625.0000 1.0000
69.5200 644.0000 1.0000
69.5600 627.0000 1.0000
69.6000 658.0000 1.0000
69.6400 640.0000 1.0000
69.6800 644.0000 1.0000
69.7200 625.0000 1.0000
69.7600 601.0000 1.0000
69.8000 618.0000 1.0000
69.8400 609.0000 1.0000
69.8800 592.0000 1.0000
69.9200 619.0000 1.0000
69.9600 595.0000 1.0000
70.0000 617.0000 1.0000
*RAS_INT_END
*RAS_TEMPERATURE_START
*RAS_TEMPERATURE_END
*RAS_DATA_END