File: Data/Dataset1_Only_water/5_XRD/No_016_FS4_4.ras
*RAS_DATA_START
*RAS_HEADER_START
*DISP_FMT_X "%.2f"
*DISP_FMT_Y "%.0f"
*DISP_FULLSCALE "14984.0000000000"
*DISP_LINE_COLOR "255.0000000000"
*DISP_LINE_STYLE "0.0000000000"
*DISP_LINE_WIDTH "0.2500000000"
*DISP_NOTE "測定データ-7"
*DISP_OFFSET_Y "0.0000000000"
*DISP_PEAKSEARCH_UNIT_Y "cps"
*DISP_RANGE_BOTTOM "0.0000000000"
*DISP_RANGE_LEFT "20.0000000000"
*DISP_RANGE_LOGCUTOFF "0.0100000000"
*DISP_RANGE_RIGHT "70.0000000000"
*DISP_RANGE_TOP "14984.0000000000"
*DISP_SCALE_MODE_Y "0.0000000000"
*DISP_TAB_NAME "2θ/θ"
*DISP_TITLE_Y "強度"
*DISP_UNIT_Y "cps"
*DISP_WINDOW_NAME "MSG_MACROENGINE"
*FILE_COMMENT " "
*FILE_MD5 ""
*FILE_MEMO " "
*FILE_OPERATOR "Administrator"
*FILE_SAMPLE " "
*FILE_TYPE "RAS_RAW"
*FILE_USERGROUP "システムマネージャ"
*FILE_VERSION "1.0000000000"
*HW_ATTACHMENT_ID "ATT0025"
*HW_ATTACHMENT_NAME "標準|Standard"
*HW_COUNTER_ID-0 "CUT0025"
*HW_COUNTER_ID-1 "CUT0020"
*HW_COUNTER_ID-2 "CUT0020"
*HW_COUNTER_ID-3 "CSL0021"
*HW_COUNTER_ID-4 "CMC0021"
*HW_COUNTER_NAME-0 "D/teX Ultra|D/teX Ultra"
*HW_COUNTER_NAME-1 "None|None"
*HW_COUNTER_NAME-2 "None|None"
*HW_COUNTER_NAME-3 "BBM|BBM"
*HW_COUNTER_NAME-4 "検出器モノクロメータ|Detector monochromator"
*HW_COUNTER_SELECT_NAME "D/teX Ultra|D/teX Ultra"
*HW_GONIOMETER_ID "GON0023"
*HW_GONIOMETER_NAME "SmartLab|SmartLab"
*HW_GONIOMETER_RADIUS-0 "90.0"
*HW_GONIOMETER_RADIUS-1 "114.0"
*HW_GONIOMETER_RADIUS-2 "190.0"
*HW_GONIOMETER_RADIUS-3 "300.0"
*HW_GONIOMETER_RADIUS-4 "187.0"
*HW_GONIOMETER_RADIUS-5 "300.0"
*HW_GONIOMETER_RADIUS-6 "113.0"
*HW_GONIOMETER_RADIUS-7 "331.0"
*HW_I_OPT_ID-0 "CBO0021"
*HW_I_OPT_ID-1 "ICR0023"
*HW_I_OPT_ID-2 "ISL0021"
*HW_I_OPT_ID-3 "ISO0021"
*HW_I_OPT_ID-4 "IAD0021"
*HW_I_OPT_ID-5 "IPR0001"
*HW_I_OPT_NAME-0 "CBOユニット|CBO unit"
*HW_I_OPT_NAME-1 "標準入射光学ユニット|Standard incident optical unit"
*HW_I_OPT_NAME-2 "標準入射スリットボックス|Standard incident slit box"
*HW_I_OPT_NAME-3 "入射平行スリット|Incident parallel slit"
*HW_I_OPT_NAME-4 "長手制限スリット|Length limiting slit"
*HW_I_OPT_NAME-5 "None|None"
*HW_R_ATTENUATER_AUTOMODE "0"
*HW_R_OPT_ID-0 "RSS0021"
*HW_R_OPT_ID-1 "RCR0023"
*HW_R_OPT_ID-2 "RSO0021"
*HW_R_OPT_ID-3 "RRS0021"
*HW_R_OPT_ID-4 "ATN0021"
*HW_R_OPT_ID-5 "RFL0021"
*HW_R_OPT_ID-6 "RAD0021"
*HW_R_OPT_NAME-0 "標準受光スリットボックス1|Standard receiving slit box # 1"
*HW_R_OPT_NAME-1 "標準受光光学ユニット1|Standard receiving unit # 1"
*HW_R_OPT_NAME-2 "標準受光光学ユニット2|Standard receiving optical unit # 2"
*HW_R_OPT_NAME-3 "標準受光スリットボックス2|Standard receiving slit box # 2"
*HW_R_OPT_NAME-4 "標準アッテネータ|Standard Attenuator"
*HW_R_OPT_NAME-5 "Cu Kβ|Cu K-beta"
*HW_R_OPT_NAME-6 "調整用受光スリット|Alignment receiving slit"
*HW_SAMPLE_HOLDER_ID "SMP0023"
*HW_SAMPLE_HOLDER_NAME "標準Zステージ|Standard Z stage"
*HW_XG_CURRENT_MAX "50"
*HW_XG_CURRENT_MIN "2"
*HW_XG_CURRENT_RESOLUTION "1"
*HW_XG_CURRENT_UNIT "mA"
*HW_XG_FOCUS "1mm x 10mm"
*HW_XG_FOCUS_TYPE "Normal"
*HW_XG_ID ""
*HW_XG_NAME "3kW 封入管(ID:1200)|3kW Sealed tube(ID:1200)"
*HW_XG_TARGET_ATOMIC_NUMBER "29.0000000000"
*HW_XG_TARGET_NAME "Cu"
*HW_XG_TYPE "Hermetic"
*HW_XG_VOLTAGE_MAX "60"
*HW_XG_VOLTAGE_MIN "20"
*HW_XG_VOLTAGE_RESOLUTION "1"
*HW_XG_VOLTAGE_UNIT "kV"
*HW_XG_WATT_MAX "1.500"
*HW_XG_WATT_UNIT "kW"
*HW_XG_WAVE_LENGTH_ALPHA1 "1.540593"
*HW_XG_WAVE_LENGTH_ALPHA2 "1.544414"
*HW_XG_WAVE_LENGTH_BETA "1.392250"
*MEAS_COND_AXIS_NAME-0 "2θ/θ"
*MEAS_COND_AXIS_NAME-1 "2θ"
*MEAS_COND_AXIS_NAME-2 "ω"
*MEAS_COND_AXIS_NAME-3 "Z"
*MEAS_COND_AXIS_NAME-4 "2θ/ω"
*MEAS_COND_AXIS_NAME-5 "θs"
*MEAS_COND_AXIS_NAME-6 "θd"
*MEAS_COND_AXIS_NAME-7 "Ts"
*MEAS_COND_AXIS_NAME-8 "CBO選択スリット"
*MEAS_COND_AXIS_NAME-9 "M"
*MEAS_COND_AXIS_NAME-10 "入射平行スリット"
*MEAS_COND_AXIS_NAME-11 "入射スリット"
*MEAS_COND_AXIS_NAME-12 ""
*MEAS_COND_AXIS_NAME-13 "Zs"
*MEAS_COND_AXIS_NAME-14 "入射光学素子"
*MEAS_COND_AXIS_NAME-15 "長手制限スリット"
*MEAS_COND_AXIS_NAME-16 "センタースリット"
*MEAS_COND_AXIS_NAME-17 "フィルター"
*MEAS_COND_AXIS_NAME-18 "受光スリット1"
*MEAS_COND_AXIS_NAME-19 "受光スリット2"
*MEAS_COND_AXIS_NAME-20 "受光光学素子"
*MEAS_COND_AXIS_NAME-21 "受光平行スリット"
*MEAS_COND_AXIS_NAME-22 "調整用受光スリット"
*MEAS_COND_AXIS_NAME-23 ""
*MEAS_COND_AXIS_NAME-24 ""
*MEAS_COND_AXIS_NAME-25 "Zd"
*MEAS_COND_AXIS_NAME-26 "アッテネータ"
*MEAS_COND_AXIS_NAME-27 "検出器モノクロメータ"
*MEAS_COND_AXIS_NAME-28 "モノクロメータスリット"
*MEAS_COND_AXIS_NAME-29 "プライマリビーム"
*MEAS_COND_AXIS_NAME-30 "PHA"
*MEAS_COND_AXIS_NAME_INTERNAL-0 "TwoThetaTheta"
*MEAS_COND_AXIS_NAME_INTERNAL-1 "TwoTheta"
*MEAS_COND_AXIS_NAME_INTERNAL-2 "Omega"
*MEAS_COND_AXIS_NAME_INTERNAL-3 "Z"
*MEAS_COND_AXIS_NAME_INTERNAL-4 "TwoThetaOmega"
*MEAS_COND_AXIS_NAME_INTERNAL-5 "ThetaS"
*MEAS_COND_AXIS_NAME_INTERNAL-6 "ThetaD"
*MEAS_COND_AXIS_NAME_INTERNAL-7 "Ts"
*MEAS_COND_AXIS_NAME_INTERNAL-8 "CBO"
*MEAS_COND_AXIS_NAME_INTERNAL-9 "CBO-M"
*MEAS_COND_AXIS_NAME_INTERNAL-10 "IncidentSollerSlit"
*MEAS_COND_AXIS_NAME_INTERNAL-11 "IncidentSlitBox"
*MEAS_COND_AXIS_NAME_INTERNAL-12 "IncidentSlitBox-_Axis"
*MEAS_COND_AXIS_NAME_INTERNAL-13 "Zs"
*MEAS_COND_AXIS_NAME_INTERNAL-14 "IncidentMonochromator"
*MEAS_COND_AXIS_NAME_INTERNAL-15 "IncidentAxdSlit"
*MEAS_COND_AXIS_NAME_INTERNAL-16 "CenterSlit"
*MEAS_COND_AXIS_NAME_INTERNAL-17 "Filter"
*MEAS_COND_AXIS_NAME_INTERNAL-18 "ReceivingSlitBox1"
*MEAS_COND_AXIS_NAME_INTERNAL-19 "ReceivingSlitBox2"
*MEAS_COND_AXIS_NAME_INTERNAL-20 "ReceivingOptics"
*MEAS_COND_AXIS_NAME_INTERNAL-21 "ReceivingSollerSlit"
*MEAS_COND_AXIS_NAME_INTERNAL-22 "ReceivingAxdSlit"
*MEAS_COND_AXIS_NAME_INTERNAL-23 "ReceivingSlitBox1-_Axis"
*MEAS_COND_AXIS_NAME_INTERNAL-24 "ReceivingSlitBox2-_Axis"
*MEAS_COND_AXIS_NAME_INTERNAL-25 "ReceivingSlitBox2-Zd"
*MEAS_COND_AXIS_NAME_INTERNAL-26 "Attenuator"
*MEAS_COND_AXIS_NAME_INTERNAL-27 "CounterMonochromator"
*MEAS_COND_AXIS_NAME_INTERNAL-28 "CounterSlit"
*MEAS_COND_AXIS_NAME_INTERNAL-29 "IncidentPrimary"
*MEAS_COND_AXIS_NAME_INTERNAL-30 "PHA"
*MEAS_COND_AXIS_NAME_MAGICNO-0 "83951616.0000000000"
*MEAS_COND_AXIS_NAME_MAGICNO-1 "268632064.0000000000"
*MEAS_COND_AXIS_NAME_MAGICNO-2 "268500992.0000000000"
*MEAS_COND_AXIS_NAME_MAGICNO-3 "285278208.0000000000"
*MEAS_COND_AXIS_NAME_MAGICNO-4 "83951616.0000000000"
*MEAS_COND_AXIS_NAME_MAGICNO-5 "131072.0000000000"
*MEAS_COND_AXIS_NAME_MAGICNO-6 "131072.0000000000"
*MEAS_COND_AXIS_NAME_MAGICNO-7 "318898176.0000000000"
*MEAS_COND_AXIS_NAME_MAGICNO-8 "20971521.0000000000"
*MEAS_COND_AXIS_NAME_MAGICNO-9 "285343744.0000000000"
*MEAS_COND_AXIS_NAME_MAGICNO-10 "20971521.0000000000"
*MEAS_COND_AXIS_NAME_MAGICNO-11 "22020097.0000000000"
*MEAS_COND_AXIS_NAME_MAGICNO-12 "25165824.0000000000"
*MEAS_COND_AXIS_NAME_MAGICNO-13 "318898176.0000000000"
*MEAS_COND_AXIS_NAME_MAGICNO-14 "1.0000000000"
*MEAS_COND_AXIS_NAME_MAGICNO-15 "20971521.0000000000"
*MEAS_COND_AXIS_NAME_MAGICNO-16 "20971521.0000000000"
*MEAS_COND_AXIS_NAME_MAGICNO-17 "20971521.0000000000"
*MEAS_COND_AXIS_NAME_MAGICNO-18 "23068673.0000000000"
*MEAS_COND_AXIS_NAME_MAGICNO-19 "23068673.0000000000"
*MEAS_COND_AXIS_NAME_MAGICNO-20 "20971521.0000000000"
*MEAS_COND_AXIS_NAME_MAGICNO-21 "20971521.0000000000"
*MEAS_COND_AXIS_NAME_MAGICNO-22 "20971521.0000000000"
*MEAS_COND_AXIS_NAME_MAGICNO-23 "25165824.0000000000"
*MEAS_COND_AXIS_NAME_MAGICNO-24 "25165824.0000000000"
*MEAS_COND_AXIS_NAME_MAGICNO-25 "285343744.0000000000"
*MEAS_COND_AXIS_NAME_MAGICNO-26 "17301505.0000000000"
*MEAS_COND_AXIS_NAME_MAGICNO-27 "20971521.0000000000"
*MEAS_COND_AXIS_NAME_MAGICNO-28 "20971521.0000000000"
*MEAS_COND_AXIS_NAME_MAGICNO-29 "20971521.0000000000"
*MEAS_COND_AXIS_NAME_MAGICNO-30 "0.0000000000"
*MEAS_COND_AXIS_OFFSET-0 "-"
*MEAS_COND_AXIS_OFFSET-1 "-0.1081000000"
*MEAS_COND_AXIS_OFFSET-2 "0.3758000000"
*MEAS_COND_AXIS_OFFSET-3 "-"
*MEAS_COND_AXIS_OFFSET-4 "-"
*MEAS_COND_AXIS_OFFSET-5 "0.3758000000"
*MEAS_COND_AXIS_OFFSET-6 "-0.4839000000"
*MEAS_COND_AXIS_OFFSET-7 "-"
*MEAS_COND_AXIS_OFFSET-8 "-"
*MEAS_COND_AXIS_OFFSET-9 "-"
*MEAS_COND_AXIS_OFFSET-10 "-"
*MEAS_COND_AXIS_OFFSET-11 "-"
*MEAS_COND_AXIS_OFFSET-12 "-"
*MEAS_COND_AXIS_OFFSET-13 "-"
*MEAS_COND_AXIS_OFFSET-14 "-"
*MEAS_COND_AXIS_OFFSET-15 "-"
*MEAS_COND_AXIS_OFFSET-16 "-"
*MEAS_COND_AXIS_OFFSET-17 "-"
*MEAS_COND_AXIS_OFFSET-18 "-"
*MEAS_COND_AXIS_OFFSET-19 "-"
*MEAS_COND_AXIS_OFFSET-20 "-"
*MEAS_COND_AXIS_OFFSET-21 "-"
*MEAS_COND_AXIS_OFFSET-22 "-"
*MEAS_COND_AXIS_OFFSET-23 "-"
*MEAS_COND_AXIS_OFFSET-24 "-"
*MEAS_COND_AXIS_OFFSET-25 "-"
*MEAS_COND_AXIS_OFFSET-26 "-"
*MEAS_COND_AXIS_OFFSET-27 "-"
*MEAS_COND_AXIS_OFFSET-28 "-"
*MEAS_COND_AXIS_OFFSET-29 "-"
*MEAS_COND_AXIS_OFFSET-30 "-"
*MEAS_COND_AXIS_POSITION-0 "0.0000000000"
*MEAS_COND_AXIS_POSITION-1 "0.0000000000"
*MEAS_COND_AXIS_POSITION-2 "0.0000000000"
*MEAS_COND_AXIS_POSITION-3 "-0.5500000000"
*MEAS_COND_AXIS_POSITION-4 "0.0000000000"
*MEAS_COND_AXIS_POSITION-5 "0.0000000000"
*MEAS_COND_AXIS_POSITION-6 "0.0000000000"
*MEAS_COND_AXIS_POSITION-7 "-0.4278800000"
*MEAS_COND_AXIS_POSITION-8 "BB"
*MEAS_COND_AXIS_POSITION-9 "0.0000000000"
*MEAS_COND_AXIS_POSITION-10 "Soller_slit_5.0deg"
*MEAS_COND_AXIS_POSITION-11 "2/3deg"
*MEAS_COND_AXIS_POSITION-12 "2.2088000000"
*MEAS_COND_AXIS_POSITION-13 "-0.4140600000"
*MEAS_COND_AXIS_POSITION-14 "0.0000000000"
*MEAS_COND_AXIS_POSITION-15 "10.0mm"
*MEAS_COND_AXIS_POSITION-16 "None"
*MEAS_COND_AXIS_POSITION-17 "Cu_K-beta"
*MEAS_COND_AXIS_POSITION-18 "13.000mm"
*MEAS_COND_AXIS_POSITION-19 "13.000mm"
*MEAS_COND_AXIS_POSITION-20 "No_unit"
*MEAS_COND_AXIS_POSITION-21 "Soller_slit_5.0deg"
*MEAS_COND_AXIS_POSITION-22 "None"
*MEAS_COND_AXIS_POSITION-23 "13.0000000000"
*MEAS_COND_AXIS_POSITION-24 "13.0000000000"
*MEAS_COND_AXIS_POSITION-25 "0.0109400000"
*MEAS_COND_AXIS_POSITION-26 "Open"
*MEAS_COND_AXIS_POSITION-27 "None"
*MEAS_COND_AXIS_POSITION-28 "None"
*MEAS_COND_AXIS_POSITION-29 "None"
*MEAS_COND_AXIS_POSITION-30 "38.0000000000"
*MEAS_COND_AXIS_UNIT-0 "deg"
*MEAS_COND_AXIS_UNIT-1 "deg"
*MEAS_COND_AXIS_UNIT-2 "deg"
*MEAS_COND_AXIS_UNIT-3 "mm"
*MEAS_COND_AXIS_UNIT-4 "deg"
*MEAS_COND_AXIS_UNIT-5 "deg"
*MEAS_COND_AXIS_UNIT-6 "deg"
*MEAS_COND_AXIS_UNIT-7 "mm"
*MEAS_COND_AXIS_UNIT-8 ""
*MEAS_COND_AXIS_UNIT-9 "pulse"
*MEAS_COND_AXIS_UNIT-10 ""
*MEAS_COND_AXIS_UNIT-11 ""
*MEAS_COND_AXIS_UNIT-12 "mm"
*MEAS_COND_AXIS_UNIT-13 "mm"
*MEAS_COND_AXIS_UNIT-14 ""
*MEAS_COND_AXIS_UNIT-15 ""
*MEAS_COND_AXIS_UNIT-16 ""
*MEAS_COND_AXIS_UNIT-17 ""
*MEAS_COND_AXIS_UNIT-18 ""
*MEAS_COND_AXIS_UNIT-19 ""
*MEAS_COND_AXIS_UNIT-20 ""
*MEAS_COND_AXIS_UNIT-21 ""
*MEAS_COND_AXIS_UNIT-22 ""
*MEAS_COND_AXIS_UNIT-23 "mm"
*MEAS_COND_AXIS_UNIT-24 "mm"
*MEAS_COND_AXIS_UNIT-25 "mm"
*MEAS_COND_AXIS_UNIT-26 ""
*MEAS_COND_AXIS_UNIT-27 ""
*MEAS_COND_AXIS_UNIT-28 ""
*MEAS_COND_AXIS_UNIT-29 ""
*MEAS_COND_AXIS_UNIT-30 "div"
*MEAS_COND_COUNTER_CNTLOSS_CORR "0.0000000000"
*MEAS_COND_COUNTER_PHABASE "38.0000000000"
*MEAS_COND_COUNTER_PHAWINDOW "16.0000000000"
*MEAS_COND_COUNTER_PHA_UNIT "div"
*MEAS_COND_COUNTER_TAUDIFF "30.0000000000"
*MEAS_COND_COUNTER_TAUINT "0.0000000000"
*MEAS_COND_IRRADIATION_MODE "OFF"
*MEAS_COND_IRRADIATION_WIDTH ""
*MEAS_COND_OPT_ATTR "集中法"
*MEAS_COND_OPT_NAME "@集中法"
*MEAS_COND_UNSYMMETRIC_MODE "OFF"
*MEAS_COND_XG_CURRENT "30.0000000000"
*MEAS_COND_XG_VOLTAGE "40.0000000000"
*MEAS_COND_XG_WAVE_TYPE "Ka"
*MEAS_DATA_COUNT "5001.0000000000"
*MEAS_SCAN_AXIS_X "2θ/θ"
*MEAS_SCAN_AXIS_X_INTERNAL "TwoThetaTheta"
*MEAS_SCAN_END_TIME "07/06/21 19:42:10"
*MEAS_SCAN_MODE "CONTINUOUS"
*MEAS_SCAN_MONITOR "0"
*MEAS_SCAN_RESOLUTION_X "0.0002"
*MEAS_SCAN_SPEED "1.0"
*MEAS_SCAN_SPEED_UNIT "deg/min"
*MEAS_SCAN_START "20.0000000000"
*MEAS_SCAN_START_TIME "07/06/21 18:49:17"
*MEAS_SCAN_STEP "0.0100000000"
*MEAS_SCAN_STOP "70.0000000000"
*MEAS_SCAN_UNIT_X "deg"
*MEAS_SCAN_UNIT_Y "counts"
*RAS_HEADER_END
*RAS_INT_START
20.0000 1544.0000 1.0000
20.0400 1578.0000 1.0000
20.0800 1560.0000 1.0000
20.1200 1537.0000 1.0000
20.1600 1614.0000 1.0000
20.2000 1593.0000 1.0000
20.2400 1597.0000 1.0000
20.2800 1576.0000 1.0000
20.3200 1545.0000 1.0000
20.3600 1558.0000 1.0000
20.4000 1598.0000 1.0000
20.4400 1614.0000 1.0000
20.4800 1577.0000 1.0000
20.5200 1528.0000 1.0000
20.5600 1604.0000 1.0000
20.6000 1554.0000 1.0000
20.6400 1579.0000 1.0000
20.6800 1518.0000 1.0000
20.7200 1535.0000 1.0000
20.7600 1512.0000 1.0000
20.8000 1530.0000 1.0000
20.8400 1564.0000 1.0000
20.8800 1575.0000 1.0000
20.9200 1516.0000 1.0000
20.9600 1666.0000 1.0000
21.0000 1520.0000 1.0000
21.0400 1547.0000 1.0000
21.0800 1544.0000 1.0000
21.1200 1587.0000 1.0000
21.1600 1565.0000 1.0000
21.2000 1611.0000 1.0000
21.2400 1586.0000 1.0000
21.2800 1552.0000 1.0000
21.3200 1608.0000 1.0000
21.3600 1619.0000 1.0000
21.4000 1623.0000 1.0000
21.4400 1617.0000 1.0000
21.4800 1571.0000 1.0000
21.5200 1624.0000 1.0000
21.5600 1655.0000 1.0000
21.6000 1509.0000 1.0000
21.6400 1516.0000 1.0000
21.6800 1633.0000 1.0000
21.7200 1587.0000 1.0000
21.7600 1609.0000 1.0000
21.8000 1574.0000 1.0000
21.8400 1540.0000 1.0000
21.8800 1579.0000 1.0000
21.9200 1545.0000 1.0000
21.9600 1548.0000 1.0000
22.0000 1575.0000 1.0000
22.0400 1636.0000 1.0000
22.0800 1541.0000 1.0000
22.1200 1546.0000 1.0000
22.1600 1566.0000 1.0000
22.2000 1566.0000 1.0000
22.2400 1603.0000 1.0000
22.2800 1568.0000 1.0000
22.3200 1553.0000 1.0000
22.3600 1544.0000 1.0000
22.4000 1604.0000 1.0000
22.4400 1614.0000 1.0000
22.4800 1599.0000 1.0000
22.5200 1641.0000 1.0000
22.5600 1575.0000 1.0000
22.6000 1569.0000 1.0000
22.6400 1559.0000 1.0000
22.6800 1651.0000 1.0000
22.7200 1631.0000 1.0000
22.7600 1626.0000 1.0000
22.8000 1606.0000 1.0000
22.8400 1670.0000 1.0000
22.8800 1580.0000 1.0000
22.9200 1594.0000 1.0000
22.9600 1616.0000 1.0000
23.0000 1615.0000 1.0000
23.0400 1616.0000 1.0000
23.0800 1533.0000 1.0000
23.1200 1614.0000 1.0000
23.1600 1613.0000 1.0000
23.2000 1677.0000 1.0000
23.2400 1622.0000 1.0000
23.2800 1645.0000 1.0000
23.3200 1635.0000 1.0000
23.3600 1606.0000 1.0000
23.4000 1641.0000 1.0000
23.4400 1553.0000 1.0000
23.4800 1639.0000 1.0000
23.5200 1565.0000 1.0000
23.5600 1609.0000 1.0000
23.6000 1619.0000 1.0000
23.6400 1648.0000 1.0000
23.6800 1600.0000 1.0000
23.7200 1638.0000 1.0000
23.7600 1563.0000 1.0000
23.8000 1616.0000 1.0000
23.8400 1607.0000 1.0000
23.8800 1607.0000 1.0000
23.9200 1621.0000 1.0000
23.9600 1628.0000 1.0000
24.0000 1624.0000 1.0000
24.0400 1627.0000 1.0000
24.0800 1556.0000 1.0000
24.1200 1591.0000 1.0000
24.1600 1614.0000 1.0000
24.2000 1627.0000 1.0000
24.2400 1624.0000 1.0000
24.2800 1658.0000 1.0000
24.3200 1632.0000 1.0000
24.3600 1601.0000 1.0000
24.4000 1607.0000 1.0000
24.4400 1565.0000 1.0000
24.4800 1602.0000 1.0000
24.5200 1660.0000 1.0000
24.5600 1658.0000 1.0000
24.6000 1678.0000 1.0000
24.6400 1625.0000 1.0000
24.6800 1686.0000 1.0000
24.7200 1676.0000 1.0000
24.7600 1730.0000 1.0000
24.8000 1698.0000 1.0000
24.8400 1722.0000 1.0000
24.8800 1641.0000 1.0000
24.9200 1767.0000 1.0000
24.9600 1770.0000 1.0000
25.0000 1746.0000 1.0000
25.0400 1680.0000 1.0000
25.0800 1674.0000 1.0000
25.1200 1739.0000 1.0000
25.1600 1708.0000 1.0000
25.2000 1708.0000 1.0000
25.2400 1667.0000 1.0000
25.2800 1701.0000 1.0000
25.3200 1728.0000 1.0000
25.3600 1747.0000 1.0000
25.4000 1677.0000 1.0000
25.4400 1715.0000 1.0000
25.4800 1687.0000 1.0000
25.5200 1664.0000 1.0000
25.5600 1640.0000 1.0000
25.6000 1657.0000 1.0000
25.6400 1708.0000 1.0000
25.6800 1713.0000 1.0000
25.7200 1711.0000 1.0000
25.7600 1665.0000 1.0000
25.8000 1719.0000 1.0000
25.8400 1627.0000 1.0000
25.8800 1730.0000 1.0000
25.9200 1624.0000 1.0000
25.9600 1689.0000 1.0000
26.0000 1716.0000 1.0000
26.0400 1686.0000 1.0000
26.0800 1743.0000 1.0000
26.1200 1698.0000 1.0000
26.1600 1722.0000 1.0000
26.2000 1741.0000 1.0000
26.2400 1718.0000 1.0000
26.2800 1711.0000 1.0000
26.3200 1786.0000 1.0000
26.3600 1762.0000 1.0000
26.4000 1742.0000 1.0000
26.4400 1777.0000 1.0000
26.4800 1732.0000 1.0000
26.5200 1726.0000 1.0000
26.5600 1784.0000 1.0000
26.6000 1756.0000 1.0000
26.6400 1770.0000 1.0000
26.6800 1760.0000 1.0000
26.7200 1825.0000 1.0000
26.7600 1803.0000 1.0000
26.8000 1809.0000 1.0000
26.8400 1908.0000 1.0000
26.8800 1970.0000 1.0000
26.9200 2023.0000 1.0000
26.9600 2126.0000 1.0000
27.0000 2276.0000 1.0000
27.0400 2518.0000 1.0000
27.0800 2773.0000 1.0000
27.1200 3063.0000 1.0000
27.1600 3623.0000 1.0000
27.2000 4448.0000 1.0000
27.2400 5310.0000 1.0000
27.2800 6080.0000 1.0000
27.3200 6367.0000 1.0000
27.3600 5695.0000 1.0000
27.4000 4688.0000 1.0000
27.4400 3844.0000 1.0000
27.4800 3272.0000 1.0000
27.5200 2886.0000 1.0000
27.5600 2575.0000 1.0000
27.6000 2208.0000 1.0000
27.6400 2087.0000 1.0000
27.6800 2007.0000 1.0000
27.7200 1960.0000 1.0000
27.7600 1880.0000 1.0000
27.8000 1867.0000 1.0000
27.8400 1795.0000 1.0000
27.8800 1780.0000 1.0000
27.9200 1785.0000 1.0000
27.9600 1785.0000 1.0000
28.0000 1707.0000 1.0000
28.0400 1639.0000 1.0000
28.0800 1638.0000 1.0000
28.1200 1647.0000 1.0000
28.1600 1650.0000 1.0000
28.2000 1622.0000 1.0000
28.2400 1651.0000 1.0000
28.2800 1622.0000 1.0000
28.3200 1610.0000 1.0000
28.3600 1608.0000 1.0000
28.4000 1642.0000 1.0000
28.4400 1542.0000 1.0000
28.4800 1655.0000 1.0000
28.5200 1633.0000 1.0000
28.5600 1599.0000 1.0000
28.6000 1632.0000 1.0000
28.6400 1588.0000 1.0000
28.6800 1610.0000 1.0000
28.7200 1587.0000 1.0000
28.7600 1569.0000 1.0000
28.8000 1633.0000 1.0000
28.8400 1591.0000 1.0000
28.8800 1579.0000 1.0000
28.9200 1527.0000 1.0000
28.9600 1538.0000 1.0000
29.0000 1614.0000 1.0000
29.0400 1538.0000 1.0000
29.0800 1510.0000 1.0000
29.1200 1484.0000 1.0000
29.1600 1536.0000 1.0000
29.2000 1516.0000 1.0000
29.2400 1609.0000 1.0000
29.2800 1521.0000 1.0000
29.3200 1525.0000 1.0000
29.3600 1516.0000 1.0000
29.4000 1509.0000 1.0000
29.4400 1520.0000 1.0000
29.4800 1564.0000 1.0000
29.5200 1479.0000 1.0000
29.5600 1509.0000 1.0000
29.6000 1459.0000 1.0000
29.6400 1478.0000 1.0000
29.6800 1547.0000 1.0000
29.7200 1463.0000 1.0000
29.7600 1523.0000 1.0000
29.8000 1463.0000 1.0000
29.8400 1478.0000 1.0000
29.8800 1470.0000 1.0000
29.9200 1493.0000 1.0000
29.9600 1513.0000 1.0000
30.0000 1514.0000 1.0000
30.0400 1407.0000 1.0000
30.0800 1470.0000 1.0000
30.1200 1514.0000 1.0000
30.1600 1449.0000 1.0000
30.2000 1469.0000 1.0000
30.2400 1432.0000 1.0000
30.2800 1427.0000 1.0000
30.3200 1357.0000 1.0000
30.3600 1428.0000 1.0000
30.4000 1420.0000 1.0000
30.4400 1446.0000 1.0000
30.4800 1447.0000 1.0000
30.5200 1411.0000 1.0000
30.5600 1459.0000 1.0000
30.6000 1418.0000 1.0000
30.6400 1486.0000 1.0000
30.6800 1414.0000 1.0000
30.7200 1420.0000 1.0000
30.7600 1436.0000 1.0000
30.8000 1368.0000 1.0000
30.8400 1405.0000 1.0000
30.8800 1481.0000 1.0000
30.9200 1357.0000 1.0000
30.9600 1401.0000 1.0000
31.0000 1443.0000 1.0000
31.0400 1413.0000 1.0000
31.0800 1442.0000 1.0000
31.1200 1406.0000 1.0000
31.1600 1393.0000 1.0000
31.2000 1376.0000 1.0000
31.2400 1362.0000 1.0000
31.2800 1378.0000 1.0000
31.3200 1377.0000 1.0000
31.3600 1396.0000 1.0000
31.4000 1348.0000 1.0000
31.4400 1373.0000 1.0000
31.4800 1369.0000 1.0000
31.5200 1404.0000 1.0000
31.5600 1391.0000 1.0000
31.6000 1337.0000 1.0000
31.6400 1338.0000 1.0000
31.6800 1328.0000 1.0000
31.7200 1392.0000 1.0000
31.7600 1362.0000 1.0000
31.8000 1393.0000 1.0000
31.8400 1343.0000 1.0000
31.8800 1393.0000 1.0000
31.9200 1388.0000 1.0000
31.9600 1449.0000 1.0000
32.0000 1429.0000 1.0000
32.0400 1377.0000 1.0000
32.0800 1357.0000 1.0000
32.1200 1454.0000 1.0000
32.1600 1401.0000 1.0000
32.2000 1371.0000 1.0000
32.2400 1337.0000 1.0000
32.2800 1357.0000 1.0000
32.3200 1364.0000 1.0000
32.3600 1318.0000 1.0000
32.4000 1366.0000 1.0000
32.4400 1355.0000 1.0000
32.4800 1345.0000 1.0000
32.5200 1346.0000 1.0000
32.5600 1341.0000 1.0000
32.6000 1327.0000 1.0000
32.6400 1330.0000 1.0000
32.6800 1357.0000 1.0000
32.7200 1366.0000 1.0000
32.7600 1345.0000 1.0000
32.8000 1253.0000 1.0000
32.8400 1274.0000 1.0000
32.8800 1340.0000 1.0000
32.9200 1302.0000 1.0000
32.9600 1321.0000 1.0000
33.0000 1338.0000 1.0000
33.0400 1293.0000 1.0000
33.0800 1320.0000 1.0000
33.1200 1207.0000 1.0000
33.1600 1262.0000 1.0000
33.2000 1298.0000 1.0000
33.2400 1292.0000 1.0000
33.2800 1347.0000 1.0000
33.3200 1252.0000 1.0000
33.3600 1304.0000 1.0000
33.4000 1282.0000 1.0000
33.4400 1279.0000 1.0000
33.4800 1277.0000 1.0000
33.5200 1251.0000 1.0000
33.5600 1308.0000 1.0000
33.6000 1397.0000 1.0000
33.6400 1296.0000 1.0000
33.6800 1300.0000 1.0000
33.7200 1332.0000 1.0000
33.7600 1358.0000 1.0000
33.8000 1343.0000 1.0000
33.8400 1411.0000 1.0000
33.8800 1448.0000 1.0000
33.9200 1476.0000 1.0000
33.9600 1536.0000 1.0000
34.0000 1434.0000 1.0000
34.0400 1422.0000 1.0000
34.0800 1400.0000 1.0000
34.1200 1395.0000 1.0000
34.1600 1439.0000 1.0000
34.2000 1489.0000 1.0000
34.2400 1574.0000 1.0000
34.2800 1651.0000 1.0000
34.3200 1807.0000 1.0000
34.3600 1909.0000 1.0000
34.4000 2225.0000 1.0000
34.4400 2602.0000 1.0000
34.4800 2769.0000 1.0000
34.5200 2902.0000 1.0000
34.5600 2756.0000 1.0000
34.6000 2490.0000 1.0000
34.6400 2199.0000 1.0000
34.6800 1887.0000 1.0000
34.7200 1694.0000 1.0000
34.7600 1599.0000 1.0000
34.8000 1511.0000 1.0000
34.8400 1442.0000 1.0000
34.8800 1436.0000 1.0000
34.9200 1339.0000 1.0000
34.9600 1304.0000 1.0000
35.0000 1271.0000 1.0000
35.0400 1293.0000 1.0000
35.0800 1280.0000 1.0000
35.1200 1233.0000 1.0000
35.1600 1250.0000 1.0000
35.2000 1180.0000 1.0000
35.2400 1137.0000 1.0000
35.2800 1182.0000 1.0000
35.3200 1086.0000 1.0000
35.3600 1155.0000 1.0000
35.4000 1128.0000 1.0000
35.4400 1128.0000 1.0000
35.4800 1112.0000 1.0000
35.5200 1109.0000 1.0000
35.5600 1179.0000 1.0000
35.6000 1137.0000 1.0000
35.6400 1121.0000 1.0000
35.6800 1117.0000 1.0000
35.7200 1090.0000 1.0000
35.7600 1116.0000 1.0000
35.8000 1107.0000 1.0000
35.8400 1142.0000 1.0000
35.8800 1122.0000 1.0000
35.9200 1091.0000 1.0000
35.9600 1117.0000 1.0000
36.0000 1140.0000 1.0000
36.0400 1180.0000 1.0000
36.0800 1193.0000 1.0000
36.1200 1214.0000 1.0000
36.1600 1187.0000 1.0000
36.2000 1201.0000 1.0000
36.2400 1241.0000 1.0000
36.2800 1382.0000 1.0000
36.3200 1609.0000 1.0000
36.3600 1834.0000 1.0000
36.4000 2021.0000 1.0000
36.4400 2164.0000 1.0000
36.4800 1839.0000 1.0000
36.5200 1735.0000 1.0000
36.5600 1460.0000 1.0000
36.6000 1252.0000 1.0000
36.6400 1161.0000 1.0000
36.6800 1116.0000 1.0000
36.7200 1055.0000 1.0000
36.7600 1065.0000 1.0000
36.8000 1109.0000 1.0000
36.8400 1097.0000 1.0000
36.8800 1063.0000 1.0000
36.9200 1041.0000 1.0000
36.9600 1062.0000 1.0000
37.0000 1023.0000 1.0000
37.0400 1027.0000 1.0000
37.0800 1036.0000 1.0000
37.1200 1015.0000 1.0000
37.1600 1032.0000 1.0000
37.2000 1034.0000 1.0000
37.2400 1057.0000 1.0000
37.2800 1060.0000 1.0000
37.3200 960.0000 1.0000
37.3600 1034.0000 1.0000
37.4000 1032.0000 1.0000
37.4400 1025.0000 1.0000
37.4800 988.0000 1.0000
37.5200 1032.0000 1.0000
37.5600 1034.0000 1.0000
37.6000 1008.0000 1.0000
37.6400 1043.0000 1.0000
37.6800 1037.0000 1.0000
37.7200 979.0000 1.0000
37.7600 1055.0000 1.0000
37.8000 1047.0000 1.0000
37.8400 989.0000 1.0000
37.8800 1058.0000 1.0000
37.9200 1067.0000 1.0000
37.9600 1090.0000 1.0000
38.0000 1093.0000 1.0000
38.0400 1071.0000 1.0000
38.0800 1115.0000 1.0000
38.1200 1197.0000 1.0000
38.1600 1280.0000 1.0000
38.2000 1350.0000 1.0000
38.2400 1543.0000 1.0000
38.2800 1715.0000 1.0000
38.3200 2066.0000 1.0000
38.3600 2508.0000 1.0000
38.4000 3171.0000 1.0000
38.4400 4219.0000 1.0000
38.4800 5382.0000 1.0000
38.5200 6679.0000 1.0000
38.5600 7273.0000 1.0000
38.6000 6958.0000 1.0000
38.6400 6078.0000 1.0000
38.6800 4893.0000 1.0000
38.7200 3740.0000 1.0000
38.7600 2826.0000 1.0000
38.8000 2150.0000 1.0000
38.8400 1851.0000 1.0000
38.8800 1571.0000 1.0000
38.9200 1348.0000 1.0000
38.9600 1236.0000 1.0000
39.0000 1118.0000 1.0000
39.0400 1044.0000 1.0000
39.0800 1037.0000 1.0000
39.1200 999.0000 1.0000
39.1600 1020.0000 1.0000
39.2000 982.0000 1.0000
39.2400 982.0000 1.0000
39.2800 979.0000 1.0000
39.3200 934.0000 1.0000
39.3600 931.0000 1.0000
39.4000 970.0000 1.0000
39.4400 954.0000 1.0000
39.4800 925.0000 1.0000
39.5200 930.0000 1.0000
39.5600 956.0000 1.0000
39.6000 906.0000 1.0000
39.6400 996.0000 1.0000
39.6800 898.0000 1.0000
39.7200 974.0000 1.0000
39.7600 921.0000 1.0000
39.8000 926.0000 1.0000
39.8400 922.0000 1.0000
39.8800 900.0000 1.0000
39.9200 812.0000 1.0000
39.9600 915.0000 1.0000
40.0000 817.0000 1.0000
40.0400 920.0000 1.0000
40.0800 907.0000 1.0000
40.1200 910.0000 1.0000
40.1600 857.0000 1.0000
40.2000 842.0000 1.0000
40.2400 875.0000 1.0000
40.2800 807.0000 1.0000
40.3200 854.0000 1.0000
40.3600 886.0000 1.0000
40.4000 850.0000 1.0000
40.4400 869.0000 1.0000
40.4800 849.0000 1.0000
40.5200 860.0000 1.0000
40.5600 853.0000 1.0000
40.6000 870.0000 1.0000
40.6400 845.0000 1.0000
40.6800 810.0000 1.0000
40.7200 848.0000 1.0000
40.7600 822.0000 1.0000
40.8000 844.0000 1.0000
40.8400 843.0000 1.0000
40.8800 899.0000 1.0000
40.9200 835.0000 1.0000
40.9600 825.0000 1.0000
41.0000 829.0000 1.0000
41.0400 851.0000 1.0000
41.0800 838.0000 1.0000
41.1200 813.0000 1.0000
41.1600 817.0000 1.0000
41.2000 886.0000 1.0000
41.2400 880.0000 1.0000
41.2800 836.0000 1.0000
41.3200 850.0000 1.0000
41.3600 833.0000 1.0000
41.4000 782.0000 1.0000
41.4400 825.0000 1.0000
41.4800 813.0000 1.0000
41.5200 841.0000 1.0000
41.5600 867.0000 1.0000
41.6000 856.0000 1.0000
41.6400 806.0000 1.0000
41.6800 890.0000 1.0000
41.7200 846.0000 1.0000
41.7600 820.0000 1.0000
41.8000 786.0000 1.0000
41.8400 809.0000 1.0000
41.8800 803.0000 1.0000
41.9200 772.0000 1.0000
41.9600 840.0000 1.0000
42.0000 799.0000 1.0000
42.0400 829.0000 1.0000
42.0800 829.0000 1.0000
42.1200 834.0000 1.0000
42.1600 828.0000 1.0000
42.2000 782.0000 1.0000
42.2400 798.0000 1.0000
42.2800 811.0000 1.0000
42.3200 784.0000 1.0000
42.3600 777.0000 1.0000
42.4000 811.0000 1.0000
42.4400 839.0000 1.0000
42.4800 803.0000 1.0000
42.5200 828.0000 1.0000
42.5600 846.0000 1.0000
42.6000 815.0000 1.0000
42.6400 803.0000 1.0000
42.6800 804.0000 1.0000
42.7200 803.0000 1.0000
42.7600 801.0000 1.0000
42.8000 779.0000 1.0000
42.8400 797.0000 1.0000
42.8800 832.0000 1.0000
42.9200 829.0000 1.0000
42.9600 820.0000 1.0000
43.0000 804.0000 1.0000
43.0400 847.0000 1.0000
43.0800 853.0000 1.0000
43.1200 875.0000 1.0000
43.1600 872.0000 1.0000
43.2000 899.0000 1.0000
43.2400 890.0000 1.0000
43.2800 977.0000 1.0000
43.3200 865.0000 1.0000
43.3600 849.0000 1.0000
43.4000 836.0000 1.0000
43.4400 888.0000 1.0000
43.4800 762.0000 1.0000
43.5200 852.0000 1.0000
43.5600 836.0000 1.0000
43.6000 822.0000 1.0000
43.6400 767.0000 1.0000
43.6800 764.0000 1.0000
43.7200 822.0000 1.0000
43.7600 774.0000 1.0000
43.8000 788.0000 1.0000
43.8400 827.0000 1.0000
43.8800 805.0000 1.0000
43.9200 782.0000 1.0000
43.9600 784.0000 1.0000
44.0000 789.0000 1.0000
44.0400 802.0000 1.0000
44.0800 791.0000 1.0000
44.1200 831.0000 1.0000
44.1600 783.0000 1.0000
44.2000 787.0000 1.0000
44.2400 813.0000 1.0000
44.2800 800.0000 1.0000
44.3200 831.0000 1.0000
44.3600 778.0000 1.0000
44.4000 886.0000 1.0000
44.4400 785.0000 1.0000
44.4800 812.0000 1.0000
44.5200 781.0000 1.0000
44.5600 785.0000 1.0000
44.6000 780.0000 1.0000
44.6400 775.0000 1.0000
44.6800 827.0000 1.0000
44.7200 841.0000 1.0000
44.7600 769.0000 1.0000
44.8000 781.0000 1.0000
44.8400 744.0000 1.0000
44.8800 739.0000 1.0000
44.9200 763.0000 1.0000
44.9600 805.0000 1.0000
45.0000 745.0000 1.0000
45.0400 783.0000 1.0000
45.0800 746.0000 1.0000
45.1200 800.0000 1.0000
45.1600 743.0000 1.0000
45.2000 760.0000 1.0000
45.2400 803.0000 1.0000
45.2800 754.0000 1.0000
45.3200 744.0000 1.0000
45.3600 749.0000 1.0000
45.4000 779.0000 1.0000
45.4400 790.0000 1.0000
45.4800 825.0000 1.0000
45.5200 752.0000 1.0000
45.5600 773.0000 1.0000
45.6000 764.0000 1.0000
45.6400 770.0000 1.0000
45.6800 752.0000 1.0000
45.7200 755.0000 1.0000
45.7600 769.0000 1.0000
45.8000 785.0000 1.0000
45.8400 727.0000 1.0000
45.8800 740.0000 1.0000
45.9200 759.0000 1.0000
45.9600 729.0000 1.0000
46.0000 731.0000 1.0000
46.0400 753.0000 1.0000
46.0800 755.0000 1.0000
46.1200 751.0000 1.0000
46.1600 728.0000 1.0000
46.2000 740.0000 1.0000
46.2400 722.0000 1.0000
46.2800 756.0000 1.0000
46.3200 730.0000 1.0000
46.3600 705.0000 1.0000
46.4000 750.0000 1.0000
46.4400 760.0000 1.0000
46.4800 677.0000 1.0000
46.5200 722.0000 1.0000
46.5600 768.0000 1.0000
46.6000 728.0000 1.0000
46.6400 746.0000 1.0000
46.6800 694.0000 1.0000
46.7200 752.0000 1.0000
46.7600 735.0000 1.0000
46.8000 780.0000 1.0000
46.8400 744.0000 1.0000
46.8800 730.0000 1.0000
46.9200 793.0000 1.0000
46.9600 767.0000 1.0000
47.0000 779.0000 1.0000
47.0400 748.0000 1.0000
47.0800 773.0000 1.0000
47.1200 749.0000 1.0000
47.1600 753.0000 1.0000
47.2000 758.0000 1.0000
47.2400 790.0000 1.0000
47.2800 759.0000 1.0000
47.3200 743.0000 1.0000
47.3600 769.0000 1.0000
47.4000 753.0000 1.0000
47.4400 699.0000 1.0000
47.4800 691.0000 1.0000
47.5200 740.0000 1.0000
47.5600 761.0000 1.0000
47.6000 752.0000 1.0000
47.6400 694.0000 1.0000
47.6800 707.0000 1.0000
47.7200 740.0000 1.0000
47.7600 724.0000 1.0000
47.8000 696.0000 1.0000
47.8400 695.0000 1.0000
47.8800 704.0000 1.0000
47.9200 686.0000 1.0000
47.9600 668.0000 1.0000
48.0000 684.0000 1.0000
48.0400 737.0000 1.0000
48.0800 697.0000 1.0000
48.1200 720.0000 1.0000
48.1600 696.0000 1.0000
48.2000 714.0000 1.0000
48.2400 741.0000 1.0000
48.2800 718.0000 1.0000
48.3200 713.0000 1.0000
48.3600 718.0000 1.0000
48.4000 657.0000 1.0000
48.4400 716.0000 1.0000
48.4800 770.0000 1.0000
48.5200 730.0000 1.0000
48.5600 728.0000 1.0000
48.6000 686.0000 1.0000
48.6400 703.0000 1.0000
48.6800 661.0000 1.0000
48.7200 664.0000 1.0000
48.7600 714.0000 1.0000
48.8000 734.0000 1.0000
48.8400 712.0000 1.0000
48.8800 652.0000 1.0000
48.9200 688.0000 1.0000
48.9600 699.0000 1.0000
49.0000 711.0000 1.0000
49.0400 692.0000 1.0000
49.0800 702.0000 1.0000
49.1200 683.0000 1.0000
49.1600 716.0000 1.0000
49.2000 739.0000 1.0000
49.2400 701.0000 1.0000
49.2800 658.0000 1.0000
49.3200 700.0000 1.0000
49.3600 661.0000 1.0000
49.4000 667.0000 1.0000
49.4400 685.0000 1.0000
49.4800 657.0000 1.0000
49.5200 663.0000 1.0000
49.5600 694.0000 1.0000
49.6000 692.0000 1.0000
49.6400 700.0000 1.0000
49.6800 683.0000 1.0000
49.7200 715.0000 1.0000
49.7600 664.0000 1.0000
49.8000 717.0000 1.0000
49.8400 707.0000 1.0000
49.8800 695.0000 1.0000
49.9200 681.0000 1.0000
49.9600 695.0000 1.0000
50.0000 740.0000 1.0000
50.0400 683.0000 1.0000
50.0800 701.0000 1.0000
50.1200 643.0000 1.0000
50.1600 707.0000 1.0000
50.2000 736.0000 1.0000
50.2400 698.0000 1.0000
50.2800 748.0000 1.0000
50.3200 727.0000 1.0000
50.3600 753.0000 1.0000
50.4000 698.0000 1.0000
50.4400 700.0000 1.0000
50.4800 752.0000 1.0000
50.5200 687.0000 1.0000
50.5600 708.0000 1.0000
50.6000 747.0000 1.0000
50.6400 703.0000 1.0000
50.6800 681.0000 1.0000
50.7200 691.0000 1.0000
50.7600 696.0000 1.0000
50.8000 702.0000 1.0000
50.8400 681.0000 1.0000
50.8800 744.0000 1.0000
50.9200 665.0000 1.0000
50.9600 712.0000 1.0000
51.0000 713.0000 1.0000
51.0400 731.0000 1.0000
51.0800 677.0000 1.0000
51.1200 688.0000 1.0000
51.1600 728.0000 1.0000
51.2000 719.0000 1.0000
51.2400 664.0000 1.0000
51.2800 739.0000 1.0000
51.3200 672.0000 1.0000
51.3600 677.0000 1.0000
51.4000 726.0000 1.0000
51.4400 756.0000 1.0000
51.4800 693.0000 1.0000
51.5200 706.0000 1.0000
51.5600 731.0000 1.0000
51.6000 745.0000 1.0000
51.6400 724.0000 1.0000
51.6800 750.0000 1.0000
51.7200 723.0000 1.0000
51.7600 809.0000 1.0000
51.8000 760.0000 1.0000
51.8400 796.0000 1.0000
51.8800 855.0000 1.0000
51.9200 877.0000 1.0000
51.9600 961.0000 1.0000
52.0000 1073.0000 1.0000
52.0400 1187.0000 1.0000
52.0800 1404.0000 1.0000
52.1200 1675.0000 1.0000
52.1600 2311.0000 1.0000
52.2000 3095.0000 1.0000
52.2400 4099.0000 1.0000
52.2800 4765.0000 1.0000
52.3200 4467.0000 1.0000
52.3600 3980.0000 1.0000
52.4000 3585.0000 1.0000
52.4400 3207.0000 1.0000
52.4800 2480.0000 1.0000
52.5200 1884.0000 1.0000
52.5600 1437.0000 1.0000
52.6000 1284.0000 1.0000
52.6400 1049.0000 1.0000
52.6800 983.0000 1.0000
52.7200 897.0000 1.0000
52.7600 907.0000 1.0000
52.8000 819.0000 1.0000
52.8400 793.0000 1.0000
52.8800 800.0000 1.0000
52.9200 788.0000 1.0000
52.9600 787.0000 1.0000
53.0000 733.0000 1.0000
53.0400 729.0000 1.0000
53.0800 738.0000 1.0000
53.1200 770.0000 1.0000
53.1600 712.0000 1.0000
53.2000 726.0000 1.0000
53.2400 735.0000 1.0000
53.2800 709.0000 1.0000
53.3200 702.0000 1.0000
53.3600 681.0000 1.0000
53.4000 695.0000 1.0000
53.4400 711.0000 1.0000
53.4800 669.0000 1.0000
53.5200 669.0000 1.0000
53.5600 673.0000 1.0000
53.6000 650.0000 1.0000
53.6400 702.0000 1.0000
53.6800 682.0000 1.0000
53.7200 668.0000 1.0000
53.7600 651.0000 1.0000
53.8000 656.0000 1.0000
53.8400 677.0000 1.0000
53.8800 694.0000 1.0000
53.9200 656.0000 1.0000
53.9600 698.0000 1.0000
54.0000 685.0000 1.0000
54.0400 689.0000 1.0000
54.0800 637.0000 1.0000
54.1200 690.0000 1.0000
54.1600 660.0000 1.0000
54.2000 614.0000 1.0000
54.2400 719.0000 1.0000
54.2800 675.0000 1.0000
54.3200 701.0000 1.0000
54.3600 693.0000 1.0000
54.4000 659.0000 1.0000
54.4400 642.0000 1.0000
54.4800 653.0000 1.0000
54.5200 684.0000 1.0000
54.5600 701.0000 1.0000
54.6000 712.0000 1.0000
54.6400 694.0000 1.0000
54.6800 657.0000 1.0000
54.7200 731.0000 1.0000
54.7600 714.0000 1.0000
54.8000 708.0000 1.0000
54.8400 693.0000 1.0000
54.8800 733.0000 1.0000
54.9200 744.0000 1.0000
54.9600 750.0000 1.0000
55.0000 749.0000 1.0000
55.0400 740.0000 1.0000
55.0800 793.0000 1.0000
55.1200 808.0000 1.0000
55.1600 829.0000 1.0000
55.2000 918.0000 1.0000
55.2400 1019.0000 1.0000
55.2800 1042.0000 1.0000
55.3200 971.0000 1.0000
55.3600 1020.0000 1.0000
55.4000 940.0000 1.0000
55.4400 918.0000 1.0000
55.4800 846.0000 1.0000
55.5200 889.0000 1.0000
55.5600 814.0000 1.0000
55.6000 740.0000 1.0000
55.6400 721.0000 1.0000
55.6800 728.0000 1.0000
55.7200 722.0000 1.0000
55.7600 691.0000 1.0000
55.8000 712.0000 1.0000
55.8400 683.0000 1.0000
55.8800 680.0000 1.0000
55.9200 688.0000 1.0000
55.9600 686.0000 1.0000
56.0000 631.0000 1.0000
56.0400 675.0000 1.0000
56.0800 680.0000 1.0000
56.1200 654.0000 1.0000
56.1600 649.0000 1.0000
56.2000 625.0000 1.0000
56.2400 690.0000 1.0000
56.2800 608.0000 1.0000
56.3200 674.0000 1.0000
56.3600 640.0000 1.0000
56.4000 611.0000 1.0000
56.4400 681.0000 1.0000
56.4800 639.0000 1.0000
56.5200 666.0000 1.0000
56.5600 645.0000 1.0000
56.6000 620.0000 1.0000
56.6400 664.0000 1.0000
56.6800 620.0000 1.0000
56.7200 660.0000 1.0000
56.7600 638.0000 1.0000
56.8000 650.0000 1.0000
56.8400 654.0000 1.0000
56.8800 651.0000 1.0000
56.9200 656.0000 1.0000
56.9600 645.0000 1.0000
57.0000 618.0000 1.0000
57.0400 707.0000 1.0000
57.0800 661.0000 1.0000
57.1200 629.0000 1.0000
57.1600 653.0000 1.0000
57.2000 648.0000 1.0000
57.2400 699.0000 1.0000
57.2800 648.0000 1.0000
57.3200 669.0000 1.0000
57.3600 658.0000 1.0000
57.4000 660.0000 1.0000
57.4400 657.0000 1.0000
57.4800 655.0000 1.0000
57.5200 632.0000 1.0000
57.5600 629.0000 1.0000
57.6000 657.0000 1.0000
57.6400 669.0000 1.0000
57.6800 654.0000 1.0000
57.7200 631.0000 1.0000
57.7600 672.0000 1.0000
57.8000 667.0000 1.0000
57.8400 642.0000 1.0000
57.8800 643.0000 1.0000
57.9200 686.0000 1.0000
57.9600 698.0000 1.0000
58.0000 663.0000 1.0000
58.0400 650.0000 1.0000
58.0800 688.0000 1.0000
58.1200 661.0000 1.0000
58.1600 687.0000 1.0000
58.2000 685.0000 1.0000
58.2400 713.0000 1.0000
58.2800 592.0000 1.0000
58.3200 655.0000 1.0000
58.3600 634.0000 1.0000
58.4000 634.0000 1.0000
58.4400 675.0000 1.0000
58.4800 605.0000 1.0000
58.5200 637.0000 1.0000
58.5600 631.0000 1.0000
58.6000 620.0000 1.0000
58.6400 642.0000 1.0000
58.6800 626.0000 1.0000
58.7200 637.0000 1.0000
58.7600 628.0000 1.0000
58.8000 625.0000 1.0000
58.8400 672.0000 1.0000
58.8800 624.0000 1.0000
58.9200 655.0000 1.0000
58.9600 640.0000 1.0000
59.0000 637.0000 1.0000
59.0400 675.0000 1.0000
59.0800 652.0000 1.0000
59.1200 634.0000 1.0000
59.1600 654.0000 1.0000
59.2000 631.0000 1.0000
59.2400 643.0000 1.0000
59.2800 652.0000 1.0000
59.3200 656.0000 1.0000
59.3600 642.0000 1.0000
59.4000 633.0000 1.0000
59.4400 633.0000 1.0000
59.4800 677.0000 1.0000
59.5200 646.0000 1.0000
59.5600 659.0000 1.0000
59.6000 573.0000 1.0000
59.6400 682.0000 1.0000
59.6800 665.0000 1.0000
59.7200 658.0000 1.0000
59.7600 645.0000 1.0000
59.8000 626.0000 1.0000
59.8400 605.0000 1.0000
59.8800 671.0000 1.0000
59.9200 637.0000 1.0000
59.9600 640.0000 1.0000
60.0000 641.0000 1.0000
60.0400 649.0000 1.0000
60.0800 680.0000 1.0000
60.1200 657.0000 1.0000
60.1600 620.0000 1.0000
60.2000 608.0000 1.0000
60.2400 601.0000 1.0000
60.2800 668.0000 1.0000
60.3200 672.0000 1.0000
60.3600 686.0000 1.0000
60.4000 637.0000 1.0000
60.4400 606.0000 1.0000
60.4800 631.0000 1.0000
60.5200 648.0000 1.0000
60.5600 582.0000 1.0000
60.6000 592.0000 1.0000
60.6400 619.0000 1.0000
60.6800 646.0000 1.0000
60.7200 676.0000 1.0000
60.7600 639.0000 1.0000
60.8000 677.0000 1.0000
60.8400 579.0000 1.0000
60.8800 625.0000 1.0000
60.9200 634.0000 1.0000
60.9600 625.0000 1.0000
61.0000 643.0000 1.0000
61.0400 602.0000 1.0000
61.0800 642.0000 1.0000
61.1200 643.0000 1.0000
61.1600 662.0000 1.0000
61.2000 661.0000 1.0000
61.2400 584.0000 1.0000
61.2800 625.0000 1.0000
61.3200 645.0000 1.0000
61.3600 618.0000 1.0000
61.4000 658.0000 1.0000
61.4400 637.0000 1.0000
61.4800 618.0000 1.0000
61.5200 660.0000 1.0000
61.5600 658.0000 1.0000
61.6000 643.0000 1.0000
61.6400 668.0000 1.0000
61.6800 636.0000 1.0000
61.7200 693.0000 1.0000
61.7600 667.0000 1.0000
61.8000 682.0000 1.0000
61.8400 697.0000 1.0000
61.8800 731.0000 1.0000
61.9200 774.0000 1.0000
61.9600 819.0000 1.0000
62.0000 850.0000 1.0000
62.0400 873.0000 1.0000
62.0800 914.0000 1.0000
62.1200 983.0000 1.0000
62.1600 1188.0000 1.0000
62.2000 1311.0000 1.0000
62.2400 1458.0000 1.0000
62.2800 1536.0000 1.0000
62.3200 1588.0000 1.0000
62.3600 1531.0000 1.0000
62.4000 1510.0000 1.0000
62.4400 1494.0000 1.0000
62.4800 1369.0000 1.0000
62.5200 1277.0000 1.0000
62.5600 1131.0000 1.0000
62.6000 1021.0000 1.0000
62.6400 961.0000 1.0000
62.6800 896.0000 1.0000
62.7200 819.0000 1.0000
62.7600 808.0000 1.0000
62.8000 759.0000 1.0000
62.8400 731.0000 1.0000
62.8800 732.0000 1.0000
62.9200 690.0000 1.0000
62.9600 712.0000 1.0000
63.0000 725.0000 1.0000
63.0400 671.0000 1.0000
63.0800 738.0000 1.0000
63.1200 708.0000 1.0000
63.1600 709.0000 1.0000
63.2000 701.0000 1.0000
63.2400 677.0000 1.0000
63.2800 684.0000 1.0000
63.3200 664.0000 1.0000
63.3600 668.0000 1.0000
63.4000 658.0000 1.0000
63.4400 644.0000 1.0000
63.4800 627.0000 1.0000
63.5200 620.0000 1.0000
63.5600 612.0000 1.0000
63.6000 620.0000 1.0000
63.6400 662.0000 1.0000
63.6800 592.0000 1.0000
63.7200 642.0000 1.0000
63.7600 685.0000 1.0000
63.8000 634.0000 1.0000
63.8400 573.0000 1.0000
63.8800 602.0000 1.0000
63.9200 637.0000 1.0000
63.9600 639.0000 1.0000
64.0000 624.0000 1.0000
64.0400 652.0000 1.0000
64.0800 654.0000 1.0000
64.1200 642.0000 1.0000
64.1600 649.0000 1.0000
64.2000 561.0000 1.0000
64.2400 670.0000 1.0000
64.2800 691.0000 1.0000
64.3200 686.0000 1.0000
64.3600 677.0000 1.0000
64.4000 656.0000 1.0000
64.4400 656.0000 1.0000
64.4800 684.0000 1.0000
64.5200 721.0000 1.0000
64.5600 685.0000 1.0000
64.6000 771.0000 1.0000
64.6400 757.0000 1.0000
64.6800 810.0000 1.0000
64.7200 804.0000 1.0000
64.7600 841.0000 1.0000
64.8000 757.0000 1.0000
64.8400 744.0000 1.0000
64.8800 827.0000 1.0000
64.9200 748.0000 1.0000
64.9600 717.0000 1.0000
65.0000 673.0000 1.0000
65.0400 705.0000 1.0000
65.0800 678.0000 1.0000
65.1200 672.0000 1.0000
65.1600 703.0000 1.0000
65.2000 677.0000 1.0000
65.2400 689.0000 1.0000
65.2800 665.0000 1.0000
65.3200 661.0000 1.0000
65.3600 678.0000 1.0000
65.4000 676.0000 1.0000
65.4400 657.0000 1.0000
65.4800 677.0000 1.0000
65.5200 694.0000 1.0000
65.5600 723.0000 1.0000
65.6000 631.0000 1.0000
65.6400 690.0000 1.0000
65.6800 696.0000 1.0000
65.7200 696.0000 1.0000
65.7600 731.0000 1.0000
65.8000 682.0000 1.0000
65.8400 751.0000 1.0000
65.8800 807.0000 1.0000
65.9200 777.0000 1.0000
65.9600 862.0000 1.0000
66.0000 955.0000 1.0000
66.0400 1071.0000 1.0000
66.0800 1157.0000 1.0000
66.1200 1361.0000 1.0000
66.1600 1699.0000 1.0000
66.2000 2135.0000 1.0000
66.2400 2393.0000 1.0000
66.2800 2646.0000 1.0000
66.3200 2516.0000 1.0000
66.3600 2321.0000 1.0000
66.4000 2102.0000 1.0000
66.4400 2020.0000 1.0000
66.4800 1941.0000 1.0000
66.5200 1674.0000 1.0000
66.5600 1414.0000 1.0000
66.6000 1136.0000 1.0000
66.6400 1063.0000 1.0000
66.6800 923.0000 1.0000
66.7200 899.0000 1.0000
66.7600 787.0000 1.0000
66.8000 740.0000 1.0000
66.8400 713.0000 1.0000
66.8800 689.0000 1.0000
66.9200 681.0000 1.0000
66.9600 694.0000 1.0000
67.0000 668.0000 1.0000
67.0400 631.0000 1.0000
67.0800 608.0000 1.0000
67.1200 626.0000 1.0000
67.1600 627.0000 1.0000
67.2000 599.0000 1.0000
67.2400 591.0000 1.0000
67.2800 623.0000 1.0000
67.3200 610.0000 1.0000
67.3600 572.0000 1.0000
67.4000 567.0000 1.0000
67.4400 603.0000 1.0000
67.4800 610.0000 1.0000
67.5200 579.0000 1.0000
67.5600 604.0000 1.0000
67.6000 612.0000 1.0000
67.6400 553.0000 1.0000
67.6800 581.0000 1.0000
67.7200 612.0000 1.0000
67.7600 639.0000 1.0000
67.8000 599.0000 1.0000
67.8400 594.0000 1.0000
67.8800 576.0000 1.0000
67.9200 572.0000 1.0000
67.9600 603.0000 1.0000
68.0000 568.0000 1.0000
68.0400 544.0000 1.0000
68.0800 595.0000 1.0000
68.1200 602.0000 1.0000
68.1600 534.0000 1.0000
68.2000 557.0000 1.0000
68.2400 539.0000 1.0000
68.2800 588.0000 1.0000
68.3200 572.0000 1.0000
68.3600 567.0000 1.0000
68.4000 574.0000 1.0000
68.4400 565.0000 1.0000
68.4800 543.0000 1.0000
68.5200 569.0000 1.0000
68.5600 519.0000 1.0000
68.6000 564.0000 1.0000
68.6400 588.0000 1.0000
68.6800 567.0000 1.0000
68.7200 548.0000 1.0000
68.7600 565.0000 1.0000
68.8000 545.0000 1.0000
68.8400 579.0000 1.0000
68.8800 540.0000 1.0000
68.9200 554.0000 1.0000
68.9600 554.0000 1.0000
69.0000 592.0000 1.0000
69.0400 540.0000 1.0000
69.0800 566.0000 1.0000
69.1200 564.0000 1.0000
69.1600 519.0000 1.0000
69.2000 552.0000 1.0000
69.2400 580.0000 1.0000
69.2800 524.0000 1.0000
69.3200 552.0000 1.0000
69.3600 599.0000 1.0000
69.4000 571.0000 1.0000
69.4400 577.0000 1.0000
69.4800 546.0000 1.0000
69.5200 557.0000 1.0000
69.5600 563.0000 1.0000
69.6000 571.0000 1.0000
69.6400 570.0000 1.0000
69.6800 595.0000 1.0000
69.7200 549.0000 1.0000
69.7600 551.0000 1.0000
69.8000 548.0000 1.0000
69.8400 527.0000 1.0000
69.8800 561.0000 1.0000
69.9200 563.0000 1.0000
69.9600 542.0000 1.0000
70.0000 541.0000 1.0000
*RAS_INT_END
*RAS_TEMPERATURE_START
*RAS_TEMPERATURE_END
*RAS_DATA_END