File: Data/Dataset1_Only_water/5_XRD/No_103_Hematite_TiO2_250d_Air_3.ras
*RAS_DATA_START
*RAS_HEADER_START
*DISP_FMT_X "%.2f"
*DISP_FMT_Y "%.0f"
*DISP_FULLSCALE "14725.0000000000"
*DISP_LINE_COLOR "255.0000000000"
*DISP_LINE_STYLE "0.0000000000"
*DISP_LINE_WIDTH "0.2500000000"
*DISP_NOTE "測定データ-3"
*DISP_OFFSET_Y "0.0000000000"
*DISP_PEAKSEARCH_UNIT_Y "cps"
*DISP_RANGE_BOTTOM "0.0000000000"
*DISP_RANGE_LEFT "20.0000000000"
*DISP_RANGE_LOGCUTOFF "0.0100000000"
*DISP_RANGE_RIGHT "70.0000000000"
*DISP_RANGE_TOP "14725.0000000000"
*DISP_SCALE_MODE_Y "0.0000000000"
*DISP_TAB_NAME "2θ/θ"
*DISP_TITLE_Y "強度"
*DISP_UNIT_Y "cps"
*DISP_WINDOW_NAME "MSG_MACROENGINE"
*FILE_COMMENT " "
*FILE_MD5 ""
*FILE_MEMO " "
*FILE_OPERATOR "Administrator"
*FILE_SAMPLE " "
*FILE_TYPE "RAS_RAW"
*FILE_USERGROUP "システムマネージャ"
*FILE_VERSION "1.0000000000"
*HW_ATTACHMENT_ID "ATT0025"
*HW_ATTACHMENT_NAME "標準|Standard"
*HW_COUNTER_ID-0 "CUT0025"
*HW_COUNTER_ID-1 "CUT0020"
*HW_COUNTER_ID-2 "CUT0020"
*HW_COUNTER_ID-3 "CSL0021"
*HW_COUNTER_ID-4 "CMC0021"
*HW_COUNTER_NAME-0 "D/teX Ultra|D/teX Ultra"
*HW_COUNTER_NAME-1 "None|None"
*HW_COUNTER_NAME-2 "None|None"
*HW_COUNTER_NAME-3 "BBM|BBM"
*HW_COUNTER_NAME-4 "検出器モノクロメータ|Detector monochromator"
*HW_COUNTER_SELECT_NAME "D/teX Ultra|D/teX Ultra"
*HW_GONIOMETER_ID "GON0023"
*HW_GONIOMETER_NAME "SmartLab|SmartLab"
*HW_GONIOMETER_RADIUS-0 "90.0"
*HW_GONIOMETER_RADIUS-1 "114.0"
*HW_GONIOMETER_RADIUS-2 "190.0"
*HW_GONIOMETER_RADIUS-3 "300.0"
*HW_GONIOMETER_RADIUS-4 "187.0"
*HW_GONIOMETER_RADIUS-5 "300.0"
*HW_GONIOMETER_RADIUS-6 "113.0"
*HW_GONIOMETER_RADIUS-7 "331.0"
*HW_I_OPT_ID-0 "CBO0021"
*HW_I_OPT_ID-1 "ICR0023"
*HW_I_OPT_ID-2 "ISL0021"
*HW_I_OPT_ID-3 "ISO0021"
*HW_I_OPT_ID-4 "IAD0021"
*HW_I_OPT_ID-5 "IPR0001"
*HW_I_OPT_NAME-0 "CBOユニット|CBO unit"
*HW_I_OPT_NAME-1 "標準入射光学ユニット|Standard incident optical unit"
*HW_I_OPT_NAME-2 "標準入射スリットボックス|Standard incident slit box"
*HW_I_OPT_NAME-3 "入射平行スリット|Incident parallel slit"
*HW_I_OPT_NAME-4 "長手制限スリット|Length limiting slit"
*HW_I_OPT_NAME-5 "None|None"
*HW_R_ATTENUATER_AUTOMODE "0"
*HW_R_OPT_ID-0 "RSS0021"
*HW_R_OPT_ID-1 "RCR0023"
*HW_R_OPT_ID-2 "RSO0021"
*HW_R_OPT_ID-3 "RRS0021"
*HW_R_OPT_ID-4 "ATN0021"
*HW_R_OPT_ID-5 "RFL0021"
*HW_R_OPT_ID-6 "RAD0021"
*HW_R_OPT_NAME-0 "標準受光スリットボックス1|Standard receiving slit box # 1"
*HW_R_OPT_NAME-1 "標準受光光学ユニット1|Standard receiving unit # 1"
*HW_R_OPT_NAME-2 "標準受光光学ユニット2|Standard receiving optical unit # 2"
*HW_R_OPT_NAME-3 "標準受光スリットボックス2|Standard receiving slit box # 2"
*HW_R_OPT_NAME-4 "標準アッテネータ|Standard Attenuator"
*HW_R_OPT_NAME-5 "Cu Kβ|Cu K-beta"
*HW_R_OPT_NAME-6 "調整用受光スリット|Alignment receiving slit"
*HW_SAMPLE_HOLDER_ID "SMP0023"
*HW_SAMPLE_HOLDER_NAME "標準Zステージ|Standard Z stage"
*HW_XG_CURRENT_MAX "50"
*HW_XG_CURRENT_MIN "2"
*HW_XG_CURRENT_RESOLUTION "1"
*HW_XG_CURRENT_UNIT "mA"
*HW_XG_FOCUS "1mm x 10mm"
*HW_XG_FOCUS_TYPE "Normal"
*HW_XG_ID ""
*HW_XG_NAME "3kW 封入管(ID:1200)|3kW Sealed tube(ID:1200)"
*HW_XG_TARGET_ATOMIC_NUMBER "29.0000000000"
*HW_XG_TARGET_NAME "Cu"
*HW_XG_TYPE "Hermetic"
*HW_XG_VOLTAGE_MAX "60"
*HW_XG_VOLTAGE_MIN "20"
*HW_XG_VOLTAGE_RESOLUTION "1"
*HW_XG_VOLTAGE_UNIT "kV"
*HW_XG_WATT_MAX "1.500"
*HW_XG_WATT_UNIT "kW"
*HW_XG_WAVE_LENGTH_ALPHA1 "1.540593"
*HW_XG_WAVE_LENGTH_ALPHA2 "1.544414"
*HW_XG_WAVE_LENGTH_BETA "1.392250"
*MEAS_COND_AXIS_NAME-0 "2θ/θ"
*MEAS_COND_AXIS_NAME-1 "2θ"
*MEAS_COND_AXIS_NAME-2 "ω"
*MEAS_COND_AXIS_NAME-3 "Z"
*MEAS_COND_AXIS_NAME-4 "2θ/ω"
*MEAS_COND_AXIS_NAME-5 "θs"
*MEAS_COND_AXIS_NAME-6 "θd"
*MEAS_COND_AXIS_NAME-7 "Ts"
*MEAS_COND_AXIS_NAME-8 "CBO選択スリット"
*MEAS_COND_AXIS_NAME-9 "M"
*MEAS_COND_AXIS_NAME-10 "入射平行スリット"
*MEAS_COND_AXIS_NAME-11 "入射スリット"
*MEAS_COND_AXIS_NAME-12 ""
*MEAS_COND_AXIS_NAME-13 "Zs"
*MEAS_COND_AXIS_NAME-14 "入射光学素子"
*MEAS_COND_AXIS_NAME-15 "長手制限スリット"
*MEAS_COND_AXIS_NAME-16 "センタースリット"
*MEAS_COND_AXIS_NAME-17 "フィルター"
*MEAS_COND_AXIS_NAME-18 "受光スリット1"
*MEAS_COND_AXIS_NAME-19 "受光スリット2"
*MEAS_COND_AXIS_NAME-20 "受光光学素子"
*MEAS_COND_AXIS_NAME-21 "受光平行スリット"
*MEAS_COND_AXIS_NAME-22 "調整用受光スリット"
*MEAS_COND_AXIS_NAME-23 ""
*MEAS_COND_AXIS_NAME-24 ""
*MEAS_COND_AXIS_NAME-25 "Zd"
*MEAS_COND_AXIS_NAME-26 "アッテネータ"
*MEAS_COND_AXIS_NAME-27 "検出器モノクロメータ"
*MEAS_COND_AXIS_NAME-28 "モノクロメータスリット"
*MEAS_COND_AXIS_NAME-29 "プライマリビーム"
*MEAS_COND_AXIS_NAME-30 "PHA"
*MEAS_COND_AXIS_NAME_INTERNAL-0 "TwoThetaTheta"
*MEAS_COND_AXIS_NAME_INTERNAL-1 "TwoTheta"
*MEAS_COND_AXIS_NAME_INTERNAL-2 "Omega"
*MEAS_COND_AXIS_NAME_INTERNAL-3 "Z"
*MEAS_COND_AXIS_NAME_INTERNAL-4 "TwoThetaOmega"
*MEAS_COND_AXIS_NAME_INTERNAL-5 "ThetaS"
*MEAS_COND_AXIS_NAME_INTERNAL-6 "ThetaD"
*MEAS_COND_AXIS_NAME_INTERNAL-7 "Ts"
*MEAS_COND_AXIS_NAME_INTERNAL-8 "CBO"
*MEAS_COND_AXIS_NAME_INTERNAL-9 "CBO-M"
*MEAS_COND_AXIS_NAME_INTERNAL-10 "IncidentSollerSlit"
*MEAS_COND_AXIS_NAME_INTERNAL-11 "IncidentSlitBox"
*MEAS_COND_AXIS_NAME_INTERNAL-12 "IncidentSlitBox-_Axis"
*MEAS_COND_AXIS_NAME_INTERNAL-13 "Zs"
*MEAS_COND_AXIS_NAME_INTERNAL-14 "IncidentMonochromator"
*MEAS_COND_AXIS_NAME_INTERNAL-15 "IncidentAxdSlit"
*MEAS_COND_AXIS_NAME_INTERNAL-16 "CenterSlit"
*MEAS_COND_AXIS_NAME_INTERNAL-17 "Filter"
*MEAS_COND_AXIS_NAME_INTERNAL-18 "ReceivingSlitBox1"
*MEAS_COND_AXIS_NAME_INTERNAL-19 "ReceivingSlitBox2"
*MEAS_COND_AXIS_NAME_INTERNAL-20 "ReceivingOptics"
*MEAS_COND_AXIS_NAME_INTERNAL-21 "ReceivingSollerSlit"
*MEAS_COND_AXIS_NAME_INTERNAL-22 "ReceivingAxdSlit"
*MEAS_COND_AXIS_NAME_INTERNAL-23 "ReceivingSlitBox1-_Axis"
*MEAS_COND_AXIS_NAME_INTERNAL-24 "ReceivingSlitBox2-_Axis"
*MEAS_COND_AXIS_NAME_INTERNAL-25 "ReceivingSlitBox2-Zd"
*MEAS_COND_AXIS_NAME_INTERNAL-26 "Attenuator"
*MEAS_COND_AXIS_NAME_INTERNAL-27 "CounterMonochromator"
*MEAS_COND_AXIS_NAME_INTERNAL-28 "CounterSlit"
*MEAS_COND_AXIS_NAME_INTERNAL-29 "IncidentPrimary"
*MEAS_COND_AXIS_NAME_INTERNAL-30 "PHA"
*MEAS_COND_AXIS_NAME_MAGICNO-0 "83951616.0000000000"
*MEAS_COND_AXIS_NAME_MAGICNO-1 "268632064.0000000000"
*MEAS_COND_AXIS_NAME_MAGICNO-2 "268500992.0000000000"
*MEAS_COND_AXIS_NAME_MAGICNO-3 "285278208.0000000000"
*MEAS_COND_AXIS_NAME_MAGICNO-4 "83951616.0000000000"
*MEAS_COND_AXIS_NAME_MAGICNO-5 "131072.0000000000"
*MEAS_COND_AXIS_NAME_MAGICNO-6 "131072.0000000000"
*MEAS_COND_AXIS_NAME_MAGICNO-7 "318898176.0000000000"
*MEAS_COND_AXIS_NAME_MAGICNO-8 "20971521.0000000000"
*MEAS_COND_AXIS_NAME_MAGICNO-9 "285343744.0000000000"
*MEAS_COND_AXIS_NAME_MAGICNO-10 "20971521.0000000000"
*MEAS_COND_AXIS_NAME_MAGICNO-11 "22020097.0000000000"
*MEAS_COND_AXIS_NAME_MAGICNO-12 "25165824.0000000000"
*MEAS_COND_AXIS_NAME_MAGICNO-13 "318898176.0000000000"
*MEAS_COND_AXIS_NAME_MAGICNO-14 "1.0000000000"
*MEAS_COND_AXIS_NAME_MAGICNO-15 "20971521.0000000000"
*MEAS_COND_AXIS_NAME_MAGICNO-16 "20971521.0000000000"
*MEAS_COND_AXIS_NAME_MAGICNO-17 "20971521.0000000000"
*MEAS_COND_AXIS_NAME_MAGICNO-18 "23068673.0000000000"
*MEAS_COND_AXIS_NAME_MAGICNO-19 "23068673.0000000000"
*MEAS_COND_AXIS_NAME_MAGICNO-20 "20971521.0000000000"
*MEAS_COND_AXIS_NAME_MAGICNO-21 "20971521.0000000000"
*MEAS_COND_AXIS_NAME_MAGICNO-22 "20971521.0000000000"
*MEAS_COND_AXIS_NAME_MAGICNO-23 "25165824.0000000000"
*MEAS_COND_AXIS_NAME_MAGICNO-24 "25165824.0000000000"
*MEAS_COND_AXIS_NAME_MAGICNO-25 "285343744.0000000000"
*MEAS_COND_AXIS_NAME_MAGICNO-26 "17301505.0000000000"
*MEAS_COND_AXIS_NAME_MAGICNO-27 "20971521.0000000000"
*MEAS_COND_AXIS_NAME_MAGICNO-28 "20971521.0000000000"
*MEAS_COND_AXIS_NAME_MAGICNO-29 "20971521.0000000000"
*MEAS_COND_AXIS_NAME_MAGICNO-30 "0.0000000000"
*MEAS_COND_AXIS_OFFSET-0 "-"
*MEAS_COND_AXIS_OFFSET-1 "-0.0310000000"
*MEAS_COND_AXIS_OFFSET-2 "0.3978000000"
*MEAS_COND_AXIS_OFFSET-3 "-"
*MEAS_COND_AXIS_OFFSET-4 "-"
*MEAS_COND_AXIS_OFFSET-5 "0.3978000000"
*MEAS_COND_AXIS_OFFSET-6 "-0.4288000000"
*MEAS_COND_AXIS_OFFSET-7 "-"
*MEAS_COND_AXIS_OFFSET-8 "-"
*MEAS_COND_AXIS_OFFSET-9 "-"
*MEAS_COND_AXIS_OFFSET-10 "-"
*MEAS_COND_AXIS_OFFSET-11 "-"
*MEAS_COND_AXIS_OFFSET-12 "-"
*MEAS_COND_AXIS_OFFSET-13 "-"
*MEAS_COND_AXIS_OFFSET-14 "-"
*MEAS_COND_AXIS_OFFSET-15 "-"
*MEAS_COND_AXIS_OFFSET-16 "-"
*MEAS_COND_AXIS_OFFSET-17 "-"
*MEAS_COND_AXIS_OFFSET-18 "-"
*MEAS_COND_AXIS_OFFSET-19 "-"
*MEAS_COND_AXIS_OFFSET-20 "-"
*MEAS_COND_AXIS_OFFSET-21 "-"
*MEAS_COND_AXIS_OFFSET-22 "-"
*MEAS_COND_AXIS_OFFSET-23 "-"
*MEAS_COND_AXIS_OFFSET-24 "-"
*MEAS_COND_AXIS_OFFSET-25 "-"
*MEAS_COND_AXIS_OFFSET-26 "-"
*MEAS_COND_AXIS_OFFSET-27 "-"
*MEAS_COND_AXIS_OFFSET-28 "-"
*MEAS_COND_AXIS_OFFSET-29 "-"
*MEAS_COND_AXIS_OFFSET-30 "-"
*MEAS_COND_AXIS_POSITION-0 "0.0000000000"
*MEAS_COND_AXIS_POSITION-1 "0.0000000000"
*MEAS_COND_AXIS_POSITION-2 "0.0000000000"
*MEAS_COND_AXIS_POSITION-3 "-2.9770000000"
*MEAS_COND_AXIS_POSITION-4 "0.0000000000"
*MEAS_COND_AXIS_POSITION-5 "0.0000000000"
*MEAS_COND_AXIS_POSITION-6 "0.0000000000"
*MEAS_COND_AXIS_POSITION-7 "-0.7498700000"
*MEAS_COND_AXIS_POSITION-8 "BB"
*MEAS_COND_AXIS_POSITION-9 "0.0000000000"
*MEAS_COND_AXIS_POSITION-10 "Soller_slit_5.0deg"
*MEAS_COND_AXIS_POSITION-11 "2/3deg"
*MEAS_COND_AXIS_POSITION-12 "2.2088000000"
*MEAS_COND_AXIS_POSITION-13 "-0.6412500000"
*MEAS_COND_AXIS_POSITION-14 "0.0000000000"
*MEAS_COND_AXIS_POSITION-15 "10.0mm"
*MEAS_COND_AXIS_POSITION-16 "None"
*MEAS_COND_AXIS_POSITION-17 "Cu_K-beta"
*MEAS_COND_AXIS_POSITION-18 "13.000mm"
*MEAS_COND_AXIS_POSITION-19 "13.000mm"
*MEAS_COND_AXIS_POSITION-20 "No_unit"
*MEAS_COND_AXIS_POSITION-21 "Soller_slit_5.0deg"
*MEAS_COND_AXIS_POSITION-22 "None"
*MEAS_COND_AXIS_POSITION-23 "13.0000000000"
*MEAS_COND_AXIS_POSITION-24 "13.0000000000"
*MEAS_COND_AXIS_POSITION-25 "0.0281300000"
*MEAS_COND_AXIS_POSITION-26 "Open"
*MEAS_COND_AXIS_POSITION-27 "None"
*MEAS_COND_AXIS_POSITION-28 "None"
*MEAS_COND_AXIS_POSITION-29 "None"
*MEAS_COND_AXIS_POSITION-30 "38.0000000000"
*MEAS_COND_AXIS_UNIT-0 "deg"
*MEAS_COND_AXIS_UNIT-1 "deg"
*MEAS_COND_AXIS_UNIT-2 "deg"
*MEAS_COND_AXIS_UNIT-3 "mm"
*MEAS_COND_AXIS_UNIT-4 "deg"
*MEAS_COND_AXIS_UNIT-5 "deg"
*MEAS_COND_AXIS_UNIT-6 "deg"
*MEAS_COND_AXIS_UNIT-7 "mm"
*MEAS_COND_AXIS_UNIT-8 ""
*MEAS_COND_AXIS_UNIT-9 "pulse"
*MEAS_COND_AXIS_UNIT-10 ""
*MEAS_COND_AXIS_UNIT-11 ""
*MEAS_COND_AXIS_UNIT-12 "mm"
*MEAS_COND_AXIS_UNIT-13 "mm"
*MEAS_COND_AXIS_UNIT-14 ""
*MEAS_COND_AXIS_UNIT-15 ""
*MEAS_COND_AXIS_UNIT-16 ""
*MEAS_COND_AXIS_UNIT-17 ""
*MEAS_COND_AXIS_UNIT-18 ""
*MEAS_COND_AXIS_UNIT-19 ""
*MEAS_COND_AXIS_UNIT-20 ""
*MEAS_COND_AXIS_UNIT-21 ""
*MEAS_COND_AXIS_UNIT-22 ""
*MEAS_COND_AXIS_UNIT-23 "mm"
*MEAS_COND_AXIS_UNIT-24 "mm"
*MEAS_COND_AXIS_UNIT-25 "mm"
*MEAS_COND_AXIS_UNIT-26 ""
*MEAS_COND_AXIS_UNIT-27 ""
*MEAS_COND_AXIS_UNIT-28 ""
*MEAS_COND_AXIS_UNIT-29 ""
*MEAS_COND_AXIS_UNIT-30 "div"
*MEAS_COND_COUNTER_CNTLOSS_CORR "0.0000000000"
*MEAS_COND_COUNTER_PHABASE "38.0000000000"
*MEAS_COND_COUNTER_PHAWINDOW "16.0000000000"
*MEAS_COND_COUNTER_PHA_UNIT "div"
*MEAS_COND_COUNTER_TAUDIFF "30.0000000000"
*MEAS_COND_COUNTER_TAUINT "0.0000000000"
*MEAS_COND_IRRADIATION_MODE "OFF"
*MEAS_COND_IRRADIATION_WIDTH ""
*MEAS_COND_OPT_ATTR "集中法"
*MEAS_COND_OPT_NAME "@集中法"
*MEAS_COND_UNSYMMETRIC_MODE "OFF"
*MEAS_COND_XG_CURRENT "30.0000000000"
*MEAS_COND_XG_VOLTAGE "40.0000000000"
*MEAS_COND_XG_WAVE_TYPE "Ka"
*MEAS_DATA_COUNT "5001.0000000000"
*MEAS_SCAN_AXIS_X "2θ/θ"
*MEAS_SCAN_AXIS_X_INTERNAL "TwoThetaTheta"
*MEAS_SCAN_END_TIME "05/18/23 18:58:36"
*MEAS_SCAN_MODE "CONTINUOUS"
*MEAS_SCAN_MONITOR "0"
*MEAS_SCAN_RESOLUTION_X "0.0002"
*MEAS_SCAN_SPEED "2.5"
*MEAS_SCAN_SPEED_UNIT "deg/min"
*MEAS_SCAN_START "20.0000000000"
*MEAS_SCAN_START_TIME "05/18/23 18:37:12"
*MEAS_SCAN_STEP "0.0100000000"
*MEAS_SCAN_STOP "70.0000000000"
*MEAS_SCAN_UNIT_X "deg"
*MEAS_SCAN_UNIT_Y "counts"
*RAS_HEADER_END
*RAS_INT_START
20.0000 857.0000 1.0000
20.0400 855.0000 1.0000
20.0800 891.0000 1.0000
20.1200 837.0000 1.0000
20.1600 869.0000 1.0000
20.2000 856.0000 1.0000
20.2400 868.0000 1.0000
20.2800 897.0000 1.0000
20.3200 852.0000 1.0000
20.3600 849.0000 1.0000
20.4000 875.0000 1.0000
20.4400 887.0000 1.0000
20.4800 852.0000 1.0000
20.5200 840.0000 1.0000
20.5600 816.0000 1.0000
20.6000 806.0000 1.0000
20.6400 884.0000 1.0000
20.6800 867.0000 1.0000
20.7200 822.0000 1.0000
20.7600 827.0000 1.0000
20.8000 825.0000 1.0000
20.8400 813.0000 1.0000
20.8800 802.0000 1.0000
20.9200 875.0000 1.0000
20.9600 824.0000 1.0000
21.0000 873.0000 1.0000
21.0400 835.0000 1.0000
21.0800 848.0000 1.0000
21.1200 869.0000 1.0000
21.1600 820.0000 1.0000
21.2000 830.0000 1.0000
21.2400 847.0000 1.0000
21.2800 782.0000 1.0000
21.3200 866.0000 1.0000
21.3600 837.0000 1.0000
21.4000 880.0000 1.0000
21.4400 868.0000 1.0000
21.4800 822.0000 1.0000
21.5200 863.0000 1.0000
21.5600 805.0000 1.0000
21.6000 845.0000 1.0000
21.6400 841.0000 1.0000
21.6800 818.0000 1.0000
21.7200 861.0000 1.0000
21.7600 878.0000 1.0000
21.8000 835.0000 1.0000
21.8400 854.0000 1.0000
21.8800 874.0000 1.0000
21.9200 820.0000 1.0000
21.9600 830.0000 1.0000
22.0000 838.0000 1.0000
22.0400 854.0000 1.0000
22.0800 812.0000 1.0000
22.1200 864.0000 1.0000
22.1600 779.0000 1.0000
22.2000 875.0000 1.0000
22.2400 837.0000 1.0000
22.2800 871.0000 1.0000
22.3200 856.0000 1.0000
22.3600 829.0000 1.0000
22.4000 865.0000 1.0000
22.4400 822.0000 1.0000
22.4800 839.0000 1.0000
22.5200 894.0000 1.0000
22.5600 797.0000 1.0000
22.6000 800.0000 1.0000
22.6400 834.0000 1.0000
22.6800 792.0000 1.0000
22.7200 832.0000 1.0000
22.7600 794.0000 1.0000
22.8000 837.0000 1.0000
22.8400 822.0000 1.0000
22.8800 853.0000 1.0000
22.9200 852.0000 1.0000
22.9600 829.0000 1.0000
23.0000 794.0000 1.0000
23.0400 850.0000 1.0000
23.0800 845.0000 1.0000
23.1200 855.0000 1.0000
23.1600 838.0000 1.0000
23.2000 864.0000 1.0000
23.2400 819.0000 1.0000
23.2800 800.0000 1.0000
23.3200 831.0000 1.0000
23.3600 801.0000 1.0000
23.4000 815.0000 1.0000
23.4400 849.0000 1.0000
23.4800 802.0000 1.0000
23.5200 807.0000 1.0000
23.5600 849.0000 1.0000
23.6000 823.0000 1.0000
23.6400 877.0000 1.0000
23.6800 840.0000 1.0000
23.7200 830.0000 1.0000
23.7600 845.0000 1.0000
23.8000 819.0000 1.0000
23.8400 870.0000 1.0000
23.8800 819.0000 1.0000
23.9200 860.0000 1.0000
23.9600 809.0000 1.0000
24.0000 835.0000 1.0000
24.0400 840.0000 1.0000
24.0800 889.0000 1.0000
24.1200 866.0000 1.0000
24.1600 846.0000 1.0000
24.2000 856.0000 1.0000
24.2400 849.0000 1.0000
24.2800 827.0000 1.0000
24.3200 806.0000 1.0000
24.3600 783.0000 1.0000
24.4000 791.0000 1.0000
24.4400 833.0000 1.0000
24.4800 842.0000 1.0000
24.5200 775.0000 1.0000
24.5600 769.0000 1.0000
24.6000 813.0000 1.0000
24.6400 810.0000 1.0000
24.6800 817.0000 1.0000
24.7200 811.0000 1.0000
24.7600 765.0000 1.0000
24.8000 785.0000 1.0000
24.8400 787.0000 1.0000
24.8800 795.0000 1.0000
24.9200 806.0000 1.0000
24.9600 802.0000 1.0000
25.0000 753.0000 1.0000
25.0400 839.0000 1.0000
25.0800 786.0000 1.0000
25.1200 832.0000 1.0000
25.1600 763.0000 1.0000
25.2000 780.0000 1.0000
25.2400 752.0000 1.0000
25.2800 782.0000 1.0000
25.3200 806.0000 1.0000
25.3600 776.0000 1.0000
25.4000 830.0000 1.0000
25.4400 773.0000 1.0000
25.4800 784.0000 1.0000
25.5200 812.0000 1.0000
25.5600 781.0000 1.0000
25.6000 834.0000 1.0000
25.6400 862.0000 1.0000
25.6800 829.0000 1.0000
25.7200 819.0000 1.0000
25.7600 831.0000 1.0000
25.8000 813.0000 1.0000
25.8400 830.0000 1.0000
25.8800 872.0000 1.0000
25.9200 842.0000 1.0000
25.9600 853.0000 1.0000
26.0000 900.0000 1.0000
26.0400 916.0000 1.0000
26.0800 948.0000 1.0000
26.1200 1013.0000 1.0000
26.1600 1116.0000 1.0000
26.2000 1221.0000 1.0000
26.2400 1319.0000 1.0000
26.2800 1631.0000 1.0000
26.3200 1891.0000 1.0000
26.3600 2429.0000 1.0000
26.4000 2937.0000 1.0000
26.4400 2884.0000 1.0000
26.4800 2618.0000 1.0000
26.5200 2150.0000 1.0000
26.5600 1724.0000 1.0000
26.6000 1400.0000 1.0000
26.6400 1220.0000 1.0000
26.6800 1122.0000 1.0000
26.7200 1050.0000 1.0000
26.7600 977.0000 1.0000
26.8000 936.0000 1.0000
26.8400 898.0000 1.0000
26.8800 892.0000 1.0000
26.9200 855.0000 1.0000
26.9600 807.0000 1.0000
27.0000 793.0000 1.0000
27.0400 784.0000 1.0000
27.0800 760.0000 1.0000
27.1200 803.0000 1.0000
27.1600 828.0000 1.0000
27.2000 796.0000 1.0000
27.2400 752.0000 1.0000
27.2800 712.0000 1.0000
27.3200 708.0000 1.0000
27.3600 752.0000 1.0000
27.4000 725.0000 1.0000
27.4400 765.0000 1.0000
27.4800 709.0000 1.0000
27.5200 728.0000 1.0000
27.5600 744.0000 1.0000
27.6000 692.0000 1.0000
27.6400 697.0000 1.0000
27.6800 709.0000 1.0000
27.7200 748.0000 1.0000
27.7600 704.0000 1.0000
27.8000 738.0000 1.0000
27.8400 750.0000 1.0000
27.8800 736.0000 1.0000
27.9200 708.0000 1.0000
27.9600 731.0000 1.0000
28.0000 688.0000 1.0000
28.0400 681.0000 1.0000
28.0800 730.0000 1.0000
28.1200 721.0000 1.0000
28.1600 698.0000 1.0000
28.2000 756.0000 1.0000
28.2400 707.0000 1.0000
28.2800 702.0000 1.0000
28.3200 641.0000 1.0000
28.3600 664.0000 1.0000
28.4000 680.0000 1.0000
28.4400 727.0000 1.0000
28.4800 698.0000 1.0000
28.5200 694.0000 1.0000
28.5600 697.0000 1.0000
28.6000 687.0000 1.0000
28.6400 681.0000 1.0000
28.6800 695.0000 1.0000
28.7200 675.0000 1.0000
28.7600 691.0000 1.0000
28.8000 708.0000 1.0000
28.8400 644.0000 1.0000
28.8800 677.0000 1.0000
28.9200 690.0000 1.0000
28.9600 685.0000 1.0000
29.0000 656.0000 1.0000
29.0400 643.0000 1.0000
29.0800 679.0000 1.0000
29.1200 684.0000 1.0000
29.1600 666.0000 1.0000
29.2000 650.0000 1.0000
29.2400 694.0000 1.0000
29.2800 655.0000 1.0000
29.3200 668.0000 1.0000
29.3600 667.0000 1.0000
29.4000 667.0000 1.0000
29.4400 639.0000 1.0000
29.4800 710.0000 1.0000
29.5200 650.0000 1.0000
29.5600 648.0000 1.0000
29.6000 699.0000 1.0000
29.6400 629.0000 1.0000
29.6800 646.0000 1.0000
29.7200 682.0000 1.0000
29.7600 639.0000 1.0000
29.8000 655.0000 1.0000
29.8400 634.0000 1.0000
29.8800 652.0000 1.0000
29.9200 641.0000 1.0000
29.9600 578.0000 1.0000
30.0000 625.0000 1.0000
30.0400 627.0000 1.0000
30.0800 624.0000 1.0000
30.1200 660.0000 1.0000
30.1600 661.0000 1.0000
30.2000 630.0000 1.0000
30.2400 648.0000 1.0000
30.2800 633.0000 1.0000
30.3200 613.0000 1.0000
30.3600 666.0000 1.0000
30.4000 606.0000 1.0000
30.4400 633.0000 1.0000
30.4800 621.0000 1.0000
30.5200 622.0000 1.0000
30.5600 630.0000 1.0000
30.6000 645.0000 1.0000
30.6400 606.0000 1.0000
30.6800 646.0000 1.0000
30.7200 635.0000 1.0000
30.7600 574.0000 1.0000
30.8000 604.0000 1.0000
30.8400 595.0000 1.0000
30.8800 596.0000 1.0000
30.9200 602.0000 1.0000
30.9600 618.0000 1.0000
31.0000 681.0000 1.0000
31.0400 650.0000 1.0000
31.0800 593.0000 1.0000
31.1200 643.0000 1.0000
31.1600 652.0000 1.0000
31.2000 607.0000 1.0000
31.2400 615.0000 1.0000
31.2800 636.0000 1.0000
31.3200 598.0000 1.0000
31.3600 665.0000 1.0000
31.4000 612.0000 1.0000
31.4400 609.0000 1.0000
31.4800 611.0000 1.0000
31.5200 604.0000 1.0000
31.5600 589.0000 1.0000
31.6000 631.0000 1.0000
31.6400 571.0000 1.0000
31.6800 574.0000 1.0000
31.7200 620.0000 1.0000
31.7600 623.0000 1.0000
31.8000 624.0000 1.0000
31.8400 598.0000 1.0000
31.8800 587.0000 1.0000
31.9200 582.0000 1.0000
31.9600 601.0000 1.0000
32.0000 611.0000 1.0000
32.0400 593.0000 1.0000
32.0800 598.0000 1.0000
32.1200 579.0000 1.0000
32.1600 576.0000 1.0000
32.2000 575.0000 1.0000
32.2400 537.0000 1.0000
32.2800 591.0000 1.0000
32.3200 594.0000 1.0000
32.3600 569.0000 1.0000
32.4000 574.0000 1.0000
32.4400 614.0000 1.0000
32.4800 569.0000 1.0000
32.5200 587.0000 1.0000
32.5600 598.0000 1.0000
32.6000 581.0000 1.0000
32.6400 566.0000 1.0000
32.6800 596.0000 1.0000
32.7200 575.0000 1.0000
32.7600 552.0000 1.0000
32.8000 602.0000 1.0000
32.8400 573.0000 1.0000
32.8800 610.0000 1.0000
32.9200 643.0000 1.0000
32.9600 655.0000 1.0000
33.0000 612.0000 1.0000
33.0400 672.0000 1.0000
33.0800 673.0000 1.0000
33.1200 687.0000 1.0000
33.1600 650.0000 1.0000
33.2000 632.0000 1.0000
33.2400 667.0000 1.0000
33.2800 654.0000 1.0000
33.3200 655.0000 1.0000
33.3600 683.0000 1.0000
33.4000 698.0000 1.0000
33.4400 733.0000 1.0000
33.4800 845.0000 1.0000
33.5200 1042.0000 1.0000
33.5600 1187.0000 1.0000
33.6000 1435.0000 1.0000
33.6400 1431.0000 1.0000
33.6800 1384.0000 1.0000
33.7200 1212.0000 1.0000
33.7600 1023.0000 1.0000
33.8000 853.0000 1.0000
33.8400 758.0000 1.0000
33.8800 704.0000 1.0000
33.9200 698.0000 1.0000
33.9600 625.0000 1.0000
34.0000 652.0000 1.0000
34.0400 610.0000 1.0000
34.0800 617.0000 1.0000
34.1200 600.0000 1.0000
34.1600 546.0000 1.0000
34.2000 559.0000 1.0000
34.2400 528.0000 1.0000
34.2800 548.0000 1.0000
34.3200 553.0000 1.0000
34.3600 547.0000 1.0000
34.4000 533.0000 1.0000
34.4400 568.0000 1.0000
34.4800 546.0000 1.0000
34.5200 543.0000 1.0000
34.5600 521.0000 1.0000
34.6000 543.0000 1.0000
34.6400 487.0000 1.0000
34.6800 543.0000 1.0000
34.7200 448.0000 1.0000
34.7600 518.0000 1.0000
34.8000 477.0000 1.0000
34.8400 505.0000 1.0000
34.8800 505.0000 1.0000
34.9200 526.0000 1.0000
34.9600 466.0000 1.0000
35.0000 482.0000 1.0000
35.0400 513.0000 1.0000
35.0800 540.0000 1.0000
35.1200 476.0000 1.0000
35.1600 565.0000 1.0000
35.2000 537.0000 1.0000
35.2400 535.0000 1.0000
35.2800 533.0000 1.0000
35.3200 517.0000 1.0000
35.3600 584.0000 1.0000
35.4000 645.0000 1.0000
35.4400 702.0000 1.0000
35.4800 721.0000 1.0000
35.5200 792.0000 1.0000
35.5600 831.0000 1.0000
35.6000 822.0000 1.0000
35.6400 754.0000 1.0000
35.6800 707.0000 1.0000
35.7200 605.0000 1.0000
35.7600 551.0000 1.0000
35.8000 512.0000 1.0000
35.8400 529.0000 1.0000
35.8800 511.0000 1.0000
35.9200 451.0000 1.0000
35.9600 458.0000 1.0000
36.0000 486.0000 1.0000
36.0400 473.0000 1.0000
36.0800 478.0000 1.0000
36.1200 455.0000 1.0000
36.1600 454.0000 1.0000
36.2000 454.0000 1.0000
36.2400 422.0000 1.0000
36.2800 510.0000 1.0000
36.3200 483.0000 1.0000
36.3600 475.0000 1.0000
36.4000 441.0000 1.0000
36.4400 468.0000 1.0000
36.4800 439.0000 1.0000
36.5200 462.0000 1.0000
36.5600 465.0000 1.0000
36.6000 466.0000 1.0000
36.6400 453.0000 1.0000
36.6800 447.0000 1.0000
36.7200 455.0000 1.0000
36.7600 436.0000 1.0000
36.8000 451.0000 1.0000
36.8400 460.0000 1.0000
36.8800 436.0000 1.0000
36.9200 430.0000 1.0000
36.9600 466.0000 1.0000
37.0000 461.0000 1.0000
37.0400 437.0000 1.0000
37.0800 424.0000 1.0000
37.1200 482.0000 1.0000
37.1600 483.0000 1.0000
37.2000 524.0000 1.0000
37.2400 470.0000 1.0000
37.2800 545.0000 1.0000
37.3200 543.0000 1.0000
37.3600 576.0000 1.0000
37.4000 673.0000 1.0000
37.4400 743.0000 1.0000
37.4800 826.0000 1.0000
37.5200 1048.0000 1.0000
37.5600 1318.0000 1.0000
37.6000 1743.0000 1.0000
37.6400 2153.0000 1.0000
37.6800 2351.0000 1.0000
37.7200 2304.0000 1.0000
37.7600 2077.0000 1.0000
37.8000 1649.0000 1.0000
37.8400 1289.0000 1.0000
37.8800 1022.0000 1.0000
37.9200 817.0000 1.0000
37.9600 690.0000 1.0000
38.0000 616.0000 1.0000
38.0400 552.0000 1.0000
38.0800 547.0000 1.0000
38.1200 483.0000 1.0000
38.1600 470.0000 1.0000
38.2000 450.0000 1.0000
38.2400 429.0000 1.0000
38.2800 439.0000 1.0000
38.3200 430.0000 1.0000
38.3600 433.0000 1.0000
38.4000 434.0000 1.0000
38.4400 443.0000 1.0000
38.4800 395.0000 1.0000
38.5200 414.0000 1.0000
38.5600 420.0000 1.0000
38.6000 380.0000 1.0000
38.6400 435.0000 1.0000
38.6800 410.0000 1.0000
38.7200 418.0000 1.0000
38.7600 380.0000 1.0000
38.8000 414.0000 1.0000
38.8400 453.0000 1.0000
38.8800 436.0000 1.0000
38.9200 418.0000 1.0000
38.9600 409.0000 1.0000
39.0000 373.0000 1.0000
39.0400 424.0000 1.0000
39.0800 433.0000 1.0000
39.1200 450.0000 1.0000
39.1600 390.0000 1.0000
39.2000 373.0000 1.0000
39.2400 380.0000 1.0000
39.2800 406.0000 1.0000
39.3200 397.0000 1.0000
39.3600 398.0000 1.0000
39.4000 398.0000 1.0000
39.4400 393.0000 1.0000
39.4800 390.0000 1.0000
39.5200 352.0000 1.0000
39.5600 342.0000 1.0000
39.6000 394.0000 1.0000
39.6400 388.0000 1.0000
39.6800 370.0000 1.0000
39.7200 380.0000 1.0000
39.7600 354.0000 1.0000
39.8000 369.0000 1.0000
39.8400 400.0000 1.0000
39.8800 364.0000 1.0000
39.9200 345.0000 1.0000
39.9600 349.0000 1.0000
40.0000 361.0000 1.0000
40.0400 363.0000 1.0000
40.0800 397.0000 1.0000
40.1200 402.0000 1.0000
40.1600 386.0000 1.0000
40.2000 412.0000 1.0000
40.2400 366.0000 1.0000
40.2800 367.0000 1.0000
40.3200 369.0000 1.0000
40.3600 367.0000 1.0000
40.4000 397.0000 1.0000
40.4400 360.0000 1.0000
40.4800 372.0000 1.0000
40.5200 376.0000 1.0000
40.5600 362.0000 1.0000
40.6000 378.0000 1.0000
40.6400 397.0000 1.0000
40.6800 361.0000 1.0000
40.7200 389.0000 1.0000
40.7600 384.0000 1.0000
40.8000 405.0000 1.0000
40.8400 435.0000 1.0000
40.8800 354.0000 1.0000
40.9200 395.0000 1.0000
40.9600 368.0000 1.0000
41.0000 401.0000 1.0000
41.0400 392.0000 1.0000
41.0800 399.0000 1.0000
41.1200 374.0000 1.0000
41.1600 394.0000 1.0000
41.2000 395.0000 1.0000
41.2400 388.0000 1.0000
41.2800 377.0000 1.0000
41.3200 393.0000 1.0000
41.3600 373.0000 1.0000
41.4000 383.0000 1.0000
41.4400 360.0000 1.0000
41.4800 353.0000 1.0000
41.5200 366.0000 1.0000
41.5600 336.0000 1.0000
41.6000 388.0000 1.0000
41.6400 375.0000 1.0000
41.6800 348.0000 1.0000
41.7200 328.0000 1.0000
41.7600 364.0000 1.0000
41.8000 366.0000 1.0000
41.8400 355.0000 1.0000
41.8800 368.0000 1.0000
41.9200 349.0000 1.0000
41.9600 376.0000 1.0000
42.0000 355.0000 1.0000
42.0400 345.0000 1.0000
42.0800 346.0000 1.0000
42.1200 384.0000 1.0000
42.1600 339.0000 1.0000
42.2000 381.0000 1.0000
42.2400 340.0000 1.0000
42.2800 388.0000 1.0000
42.3200 398.0000 1.0000
42.3600 366.0000 1.0000
42.4000 384.0000 1.0000
42.4400 404.0000 1.0000
42.4800 400.0000 1.0000
42.5200 363.0000 1.0000
42.5600 368.0000 1.0000
42.6000 407.0000 1.0000
42.6400 362.0000 1.0000
42.6800 356.0000 1.0000
42.7200 365.0000 1.0000
42.7600 333.0000 1.0000
42.8000 361.0000 1.0000
42.8400 343.0000 1.0000
42.8800 366.0000 1.0000
42.9200 371.0000 1.0000
42.9600 334.0000 1.0000
43.0000 363.0000 1.0000
43.0400 350.0000 1.0000
43.0800 400.0000 1.0000
43.1200 346.0000 1.0000
43.1600 345.0000 1.0000
43.2000 361.0000 1.0000
43.2400 359.0000 1.0000
43.2800 340.0000 1.0000
43.3200 365.0000 1.0000
43.3600 352.0000 1.0000
43.4000 332.0000 1.0000
43.4400 367.0000 1.0000
43.4800 377.0000 1.0000
43.5200 349.0000 1.0000
43.5600 338.0000 1.0000
43.6000 353.0000 1.0000
43.6400 344.0000 1.0000
43.6800 356.0000 1.0000
43.7200 352.0000 1.0000
43.7600 363.0000 1.0000
43.8000 338.0000 1.0000
43.8400 359.0000 1.0000
43.8800 334.0000 1.0000
43.9200 338.0000 1.0000
43.9600 351.0000 1.0000
44.0000 361.0000 1.0000
44.0400 332.0000 1.0000
44.0800 354.0000 1.0000
44.1200 336.0000 1.0000
44.1600 371.0000 1.0000
44.2000 361.0000 1.0000
44.2400 318.0000 1.0000
44.2800 342.0000 1.0000
44.3200 333.0000 1.0000
44.3600 359.0000 1.0000
44.4000 343.0000 1.0000
44.4400 330.0000 1.0000
44.4800 338.0000 1.0000
44.5200 347.0000 1.0000
44.5600 337.0000 1.0000
44.6000 327.0000 1.0000
44.6400 326.0000 1.0000
44.6800 340.0000 1.0000
44.7200 332.0000 1.0000
44.7600 316.0000 1.0000
44.8000 337.0000 1.0000
44.8400 351.0000 1.0000
44.8800 316.0000 1.0000
44.9200 313.0000 1.0000
44.9600 345.0000 1.0000
45.0000 329.0000 1.0000
45.0400 312.0000 1.0000
45.0800 341.0000 1.0000
45.1200 327.0000 1.0000
45.1600 324.0000 1.0000
45.2000 306.0000 1.0000
45.2400 370.0000 1.0000
45.2800 328.0000 1.0000
45.3200 349.0000 1.0000
45.3600 322.0000 1.0000
45.4000 349.0000 1.0000
45.4400 348.0000 1.0000
45.4800 332.0000 1.0000
45.5200 358.0000 1.0000
45.5600 346.0000 1.0000
45.6000 340.0000 1.0000
45.6400 327.0000 1.0000
45.6800 325.0000 1.0000
45.7200 331.0000 1.0000
45.7600 292.0000 1.0000
45.8000 327.0000 1.0000
45.8400 315.0000 1.0000
45.8800 341.0000 1.0000
45.9200 328.0000 1.0000
45.9600 321.0000 1.0000
46.0000 293.0000 1.0000
46.0400 322.0000 1.0000
46.0800 336.0000 1.0000
46.1200 370.0000 1.0000
46.1600 313.0000 1.0000
46.2000 314.0000 1.0000
46.2400 318.0000 1.0000
46.2800 323.0000 1.0000
46.3200 313.0000 1.0000
46.3600 337.0000 1.0000
46.4000 322.0000 1.0000
46.4400 315.0000 1.0000
46.4800 331.0000 1.0000
46.5200 328.0000 1.0000
46.5600 309.0000 1.0000
46.6000 333.0000 1.0000
46.6400 330.0000 1.0000
46.6800 310.0000 1.0000
46.7200 309.0000 1.0000
46.7600 327.0000 1.0000
46.8000 315.0000 1.0000
46.8400 325.0000 1.0000
46.8800 328.0000 1.0000
46.9200 316.0000 1.0000
46.9600 343.0000 1.0000
47.0000 306.0000 1.0000
47.0400 311.0000 1.0000
47.0800 308.0000 1.0000
47.1200 282.0000 1.0000
47.1600 300.0000 1.0000
47.2000 311.0000 1.0000
47.2400 341.0000 1.0000
47.2800 316.0000 1.0000
47.3200 338.0000 1.0000
47.3600 321.0000 1.0000
47.4000 322.0000 1.0000
47.4400 305.0000 1.0000
47.4800 315.0000 1.0000
47.5200 325.0000 1.0000
47.5600 330.0000 1.0000
47.6000 322.0000 1.0000
47.6400 332.0000 1.0000
47.6800 294.0000 1.0000
47.7200 305.0000 1.0000
47.7600 319.0000 1.0000
47.8000 306.0000 1.0000
47.8400 297.0000 1.0000
47.8800 309.0000 1.0000
47.9200 320.0000 1.0000
47.9600 294.0000 1.0000
48.0000 316.0000 1.0000
48.0400 308.0000 1.0000
48.0800 297.0000 1.0000
48.1200 299.0000 1.0000
48.1600 313.0000 1.0000
48.2000 331.0000 1.0000
48.2400 313.0000 1.0000
48.2800 314.0000 1.0000
48.3200 294.0000 1.0000
48.3600 277.0000 1.0000
48.4000 297.0000 1.0000
48.4400 319.0000 1.0000
48.4800 297.0000 1.0000
48.5200 341.0000 1.0000
48.5600 299.0000 1.0000
48.6000 290.0000 1.0000
48.6400 303.0000 1.0000
48.6800 335.0000 1.0000
48.7200 290.0000 1.0000
48.7600 310.0000 1.0000
48.8000 305.0000 1.0000
48.8400 318.0000 1.0000
48.8800 308.0000 1.0000
48.9200 289.0000 1.0000
48.9600 299.0000 1.0000
49.0000 287.0000 1.0000
49.0400 301.0000 1.0000
49.0800 308.0000 1.0000
49.1200 292.0000 1.0000
49.1600 315.0000 1.0000
49.2000 291.0000 1.0000
49.2400 314.0000 1.0000
49.2800 297.0000 1.0000
49.3200 323.0000 1.0000
49.3600 314.0000 1.0000
49.4000 328.0000 1.0000
49.4400 334.0000 1.0000
49.4800 346.0000 1.0000
49.5200 306.0000 1.0000
49.5600 305.0000 1.0000
49.6000 329.0000 1.0000
49.6400 304.0000 1.0000
49.6800 327.0000 1.0000
49.7200 328.0000 1.0000
49.7600 286.0000 1.0000
49.8000 299.0000 1.0000
49.8400 305.0000 1.0000
49.8800 316.0000 1.0000
49.9200 315.0000 1.0000
49.9600 296.0000 1.0000
50.0000 324.0000 1.0000
50.0400 311.0000 1.0000
50.0800 299.0000 1.0000
50.1200 281.0000 1.0000
50.1600 291.0000 1.0000
50.2000 309.0000 1.0000
50.2400 306.0000 1.0000
50.2800 315.0000 1.0000
50.3200 315.0000 1.0000
50.3600 293.0000 1.0000
50.4000 316.0000 1.0000
50.4400 308.0000 1.0000
50.4800 321.0000 1.0000
50.5200 325.0000 1.0000
50.5600 294.0000 1.0000
50.6000 329.0000 1.0000
50.6400 351.0000 1.0000
50.6800 310.0000 1.0000
50.7200 309.0000 1.0000
50.7600 330.0000 1.0000
50.8000 324.0000 1.0000
50.8400 311.0000 1.0000
50.8800 322.0000 1.0000
50.9200 339.0000 1.0000
50.9600 317.0000 1.0000
51.0000 330.0000 1.0000
51.0400 349.0000 1.0000
51.0800 369.0000 1.0000
51.1200 417.0000 1.0000
51.1600 424.0000 1.0000
51.2000 502.0000 1.0000
51.2400 569.0000 1.0000
51.2800 712.0000 1.0000
51.3200 895.0000 1.0000
51.3600 1252.0000 1.0000
51.4000 1673.0000 1.0000
51.4400 2093.0000 1.0000
51.4800 2246.0000 1.0000
51.5200 1977.0000 1.0000
51.5600 1748.0000 1.0000
51.6000 1563.0000 1.0000
51.6400 1239.0000 1.0000
51.6800 944.0000 1.0000
51.7200 705.0000 1.0000
51.7600 576.0000 1.0000
51.8000 557.0000 1.0000
51.8400 459.0000 1.0000
51.8800 432.0000 1.0000
51.9200 379.0000 1.0000
51.9600 389.0000 1.0000
52.0000 361.0000 1.0000
52.0400 353.0000 1.0000
52.0800 328.0000 1.0000
52.1200 324.0000 1.0000
52.1600 322.0000 1.0000
52.2000 314.0000 1.0000
52.2400 301.0000 1.0000
52.2800 331.0000 1.0000
52.3200 326.0000 1.0000
52.3600 325.0000 1.0000
52.4000 301.0000 1.0000
52.4400 320.0000 1.0000
52.4800 304.0000 1.0000
52.5200 329.0000 1.0000
52.5600 307.0000 1.0000
52.6000 300.0000 1.0000
52.6400 295.0000 1.0000
52.6800 288.0000 1.0000
52.7200 335.0000 1.0000
52.7600 281.0000 1.0000
52.8000 285.0000 1.0000
52.8400 314.0000 1.0000
52.8800 292.0000 1.0000
52.9200 317.0000 1.0000
52.9600 286.0000 1.0000
53.0000 305.0000 1.0000
53.0400 300.0000 1.0000
53.0800 282.0000 1.0000
53.1200 276.0000 1.0000
53.1600 288.0000 1.0000
53.2000 304.0000 1.0000
53.2400 288.0000 1.0000
53.2800 296.0000 1.0000
53.3200 261.0000 1.0000
53.3600 294.0000 1.0000
53.4000 262.0000 1.0000
53.4400 301.0000 1.0000
53.4800 288.0000 1.0000
53.5200 286.0000 1.0000
53.5600 274.0000 1.0000
53.6000 294.0000 1.0000
53.6400 311.0000 1.0000
53.6800 290.0000 1.0000
53.7200 280.0000 1.0000
53.7600 287.0000 1.0000
53.8000 312.0000 1.0000
53.8400 309.0000 1.0000
53.8800 313.0000 1.0000
53.9200 332.0000 1.0000
53.9600 290.0000 1.0000
54.0000 299.0000 1.0000
54.0400 299.0000 1.0000
54.0800 339.0000 1.0000
54.1200 319.0000 1.0000
54.1600 326.0000 1.0000
54.2000 310.0000 1.0000
54.2400 346.0000 1.0000
54.2800 342.0000 1.0000
54.3200 398.0000 1.0000
54.3600 345.0000 1.0000
54.4000 402.0000 1.0000
54.4400 441.0000 1.0000
54.4800 462.0000 1.0000
54.5200 406.0000 1.0000
54.5600 464.0000 1.0000
54.6000 432.0000 1.0000
54.6400 447.0000 1.0000
54.6800 382.0000 1.0000
54.7200 382.0000 1.0000
54.7600 365.0000 1.0000
54.8000 350.0000 1.0000
54.8400 309.0000 1.0000
54.8800 329.0000 1.0000
54.9200 316.0000 1.0000
54.9600 289.0000 1.0000
55.0000 322.0000 1.0000
55.0400 266.0000 1.0000
55.0800 319.0000 1.0000
55.1200 310.0000 1.0000
55.1600 316.0000 1.0000
55.2000 269.0000 1.0000
55.2400 288.0000 1.0000
55.2800 299.0000 1.0000
55.3200 284.0000 1.0000
55.3600 270.0000 1.0000
55.4000 287.0000 1.0000
55.4400 289.0000 1.0000
55.4800 295.0000 1.0000
55.5200 273.0000 1.0000
55.5600 294.0000 1.0000
55.6000 283.0000 1.0000
55.6400 277.0000 1.0000
55.6800 290.0000 1.0000
55.7200 277.0000 1.0000
55.7600 306.0000 1.0000
55.8000 263.0000 1.0000
55.8400 291.0000 1.0000
55.8800 302.0000 1.0000
55.9200 280.0000 1.0000
55.9600 297.0000 1.0000
56.0000 278.0000 1.0000
56.0400 289.0000 1.0000
56.0800 290.0000 1.0000
56.1200 284.0000 1.0000
56.1600 291.0000 1.0000
56.2000 280.0000 1.0000
56.2400 306.0000 1.0000
56.2800 274.0000 1.0000
56.3200 278.0000 1.0000
56.3600 285.0000 1.0000
56.4000 296.0000 1.0000
56.4400 282.0000 1.0000
56.4800 268.0000 1.0000
56.5200 277.0000 1.0000
56.5600 301.0000 1.0000
56.6000 295.0000 1.0000
56.6400 278.0000 1.0000
56.6800 271.0000 1.0000
56.7200 312.0000 1.0000
56.7600 289.0000 1.0000
56.8000 290.0000 1.0000
56.8400 296.0000 1.0000
56.8800 300.0000 1.0000
56.9200 262.0000 1.0000
56.9600 261.0000 1.0000
57.0000 284.0000 1.0000
57.0400 322.0000 1.0000
57.0800 286.0000 1.0000
57.1200 277.0000 1.0000
57.1600 279.0000 1.0000
57.2000 304.0000 1.0000
57.2400 277.0000 1.0000
57.2800 273.0000 1.0000
57.3200 299.0000 1.0000
57.3600 289.0000 1.0000
57.4000 281.0000 1.0000
57.4400 285.0000 1.0000
57.4800 290.0000 1.0000
57.5200 270.0000 1.0000
57.5600 258.0000 1.0000
57.6000 281.0000 1.0000
57.6400 291.0000 1.0000
57.6800 299.0000 1.0000
57.7200 286.0000 1.0000
57.7600 276.0000 1.0000
57.8000 288.0000 1.0000
57.8400 276.0000 1.0000
57.8800 302.0000 1.0000
57.9200 280.0000 1.0000
57.9600 260.0000 1.0000
58.0000 280.0000 1.0000
58.0400 293.0000 1.0000
58.0800 273.0000 1.0000
58.1200 267.0000 1.0000
58.1600 283.0000 1.0000
58.2000 274.0000 1.0000
58.2400 286.0000 1.0000
58.2800 281.0000 1.0000
58.3200 264.0000 1.0000
58.3600 284.0000 1.0000
58.4000 303.0000 1.0000
58.4400 276.0000 1.0000
58.4800 303.0000 1.0000
58.5200 273.0000 1.0000
58.5600 286.0000 1.0000
58.6000 276.0000 1.0000
58.6400 265.0000 1.0000
58.6800 274.0000 1.0000
58.7200 282.0000 1.0000
58.7600 273.0000 1.0000
58.8000 275.0000 1.0000
58.8400 293.0000 1.0000
58.8800 281.0000 1.0000
58.9200 280.0000 1.0000
58.9600 262.0000 1.0000
59.0000 245.0000 1.0000
59.0400 276.0000 1.0000
59.0800 283.0000 1.0000
59.1200 272.0000 1.0000
59.1600 265.0000 1.0000
59.2000 268.0000 1.0000
59.2400 264.0000 1.0000
59.2800 266.0000 1.0000
59.3200 281.0000 1.0000
59.3600 249.0000 1.0000
59.4000 284.0000 1.0000
59.4400 286.0000 1.0000
59.4800 289.0000 1.0000
59.5200 269.0000 1.0000
59.5600 274.0000 1.0000
59.6000 281.0000 1.0000
59.6400 268.0000 1.0000
59.6800 296.0000 1.0000
59.7200 281.0000 1.0000
59.7600 281.0000 1.0000
59.8000 261.0000 1.0000
59.8400 270.0000 1.0000
59.8800 244.0000 1.0000
59.9200 286.0000 1.0000
59.9600 308.0000 1.0000
60.0000 284.0000 1.0000
60.0400 290.0000 1.0000
60.0800 293.0000 1.0000
60.1200 267.0000 1.0000
60.1600 250.0000 1.0000
60.2000 270.0000 1.0000
60.2400 284.0000 1.0000
60.2800 255.0000 1.0000
60.3200 250.0000 1.0000
60.3600 276.0000 1.0000
60.4000 293.0000 1.0000
60.4400 276.0000 1.0000
60.4800 283.0000 1.0000
60.5200 291.0000 1.0000
60.5600 283.0000 1.0000
60.6000 264.0000 1.0000
60.6400 260.0000 1.0000
60.6800 286.0000 1.0000
60.7200 288.0000 1.0000
60.7600 282.0000 1.0000
60.8000 283.0000 1.0000
60.8400 271.0000 1.0000
60.8800 308.0000 1.0000
60.9200 300.0000 1.0000
60.9600 279.0000 1.0000
61.0000 290.0000 1.0000
61.0400 298.0000 1.0000
61.0800 314.0000 1.0000
61.1200 327.0000 1.0000
61.1600 346.0000 1.0000
61.2000 327.0000 1.0000
61.2400 357.0000 1.0000
61.2800 371.0000 1.0000
61.3200 412.0000 1.0000
61.3600 471.0000 1.0000
61.4000 517.0000 1.0000
61.4400 532.0000 1.0000
61.4800 579.0000 1.0000
61.5200 584.0000 1.0000
61.5600 628.0000 1.0000
61.6000 580.0000 1.0000
61.6400 590.0000 1.0000
61.6800 492.0000 1.0000
61.7200 483.0000 1.0000
61.7600 469.0000 1.0000
61.8000 418.0000 1.0000
61.8400 414.0000 1.0000
61.8800 369.0000 1.0000
61.9200 351.0000 1.0000
61.9600 323.0000 1.0000
62.0000 321.0000 1.0000
62.0400 328.0000 1.0000
62.0800 314.0000 1.0000
62.1200 303.0000 1.0000
62.1600 291.0000 1.0000
62.2000 284.0000 1.0000
62.2400 321.0000 1.0000
62.2800 301.0000 1.0000
62.3200 302.0000 1.0000
62.3600 294.0000 1.0000
62.4000 289.0000 1.0000
62.4400 304.0000 1.0000
62.4800 291.0000 1.0000
62.5200 321.0000 1.0000
62.5600 283.0000 1.0000
62.6000 296.0000 1.0000
62.6400 297.0000 1.0000
62.6800 276.0000 1.0000
62.7200 285.0000 1.0000
62.7600 273.0000 1.0000
62.8000 269.0000 1.0000
62.8400 272.0000 1.0000
62.8800 294.0000 1.0000
62.9200 270.0000 1.0000
62.9600 287.0000 1.0000
63.0000 272.0000 1.0000
63.0400 300.0000 1.0000
63.0800 283.0000 1.0000
63.1200 305.0000 1.0000
63.1600 291.0000 1.0000
63.2000 275.0000 1.0000
63.2400 288.0000 1.0000
63.2800 275.0000 1.0000
63.3200 288.0000 1.0000
63.3600 278.0000 1.0000
63.4000 277.0000 1.0000
63.4400 294.0000 1.0000
63.4800 316.0000 1.0000
63.5200 292.0000 1.0000
63.5600 278.0000 1.0000
63.6000 292.0000 1.0000
63.6400 294.0000 1.0000
63.6800 288.0000 1.0000
63.7200 344.0000 1.0000
63.7600 309.0000 1.0000
63.8000 344.0000 1.0000
63.8400 383.0000 1.0000
63.8800 357.0000 1.0000
63.9200 414.0000 1.0000
63.9600 384.0000 1.0000
64.0000 378.0000 1.0000
64.0400 362.0000 1.0000
64.0800 367.0000 1.0000
64.1200 377.0000 1.0000
64.1600 357.0000 1.0000
64.2000 351.0000 1.0000
64.2400 341.0000 1.0000
64.2800 322.0000 1.0000
64.3200 306.0000 1.0000
64.3600 342.0000 1.0000
64.4000 291.0000 1.0000
64.4400 302.0000 1.0000
64.4800 305.0000 1.0000
64.5200 299.0000 1.0000
64.5600 298.0000 1.0000
64.6000 302.0000 1.0000
64.6400 297.0000 1.0000
64.6800 320.0000 1.0000
64.7200 264.0000 1.0000
64.7600 281.0000 1.0000
64.8000 314.0000 1.0000
64.8400 285.0000 1.0000
64.8800 310.0000 1.0000
64.9200 299.0000 1.0000
64.9600 313.0000 1.0000
65.0000 276.0000 1.0000
65.0400 298.0000 1.0000
65.0800 319.0000 1.0000
65.1200 339.0000 1.0000
65.1600 363.0000 1.0000
65.2000 362.0000 1.0000
65.2400 394.0000 1.0000
65.2800 451.0000 1.0000
65.3200 512.0000 1.0000
65.3600 606.0000 1.0000
65.4000 763.0000 1.0000
65.4400 883.0000 1.0000
65.4800 1006.0000 1.0000
65.5200 1072.0000 1.0000
65.5600 1014.0000 1.0000
65.6000 945.0000 1.0000
65.6400 924.0000 1.0000
65.6800 821.0000 1.0000
65.7200 742.0000 1.0000
65.7600 656.0000 1.0000
65.8000 558.0000 1.0000
65.8400 498.0000 1.0000
65.8800 460.0000 1.0000
65.9200 374.0000 1.0000
65.9600 344.0000 1.0000
66.0000 365.0000 1.0000
66.0400 333.0000 1.0000
66.0800 300.0000 1.0000
66.1200 310.0000 1.0000
66.1600 319.0000 1.0000
66.2000 302.0000 1.0000
66.2400 239.0000 1.0000
66.2800 273.0000 1.0000
66.3200 252.0000 1.0000
66.3600 282.0000 1.0000
66.4000 301.0000 1.0000
66.4400 280.0000 1.0000
66.4800 279.0000 1.0000
66.5200 287.0000 1.0000
66.5600 262.0000 1.0000
66.6000 270.0000 1.0000
66.6400 272.0000 1.0000
66.6800 253.0000 1.0000
66.7200 242.0000 1.0000
66.7600 268.0000 1.0000
66.8000 270.0000 1.0000
66.8400 256.0000 1.0000
66.8800 255.0000 1.0000
66.9200 260.0000 1.0000
66.9600 280.0000 1.0000
67.0000 278.0000 1.0000
67.0400 266.0000 1.0000
67.0800 245.0000 1.0000
67.1200 273.0000 1.0000
67.1600 247.0000 1.0000
67.2000 265.0000 1.0000
67.2400 272.0000 1.0000
67.2800 270.0000 1.0000
67.3200 264.0000 1.0000
67.3600 244.0000 1.0000
67.4000 288.0000 1.0000
67.4400 250.0000 1.0000
67.4800 241.0000 1.0000
67.5200 253.0000 1.0000
67.5600 254.0000 1.0000
67.6000 257.0000 1.0000
67.6400 229.0000 1.0000
67.6800 250.0000 1.0000
67.7200 230.0000 1.0000
67.7600 272.0000 1.0000
67.8000 231.0000 1.0000
67.8400 243.0000 1.0000
67.8800 246.0000 1.0000
67.9200 264.0000 1.0000
67.9600 232.0000 1.0000
68.0000 258.0000 1.0000
68.0400 243.0000 1.0000
68.0800 245.0000 1.0000
68.1200 249.0000 1.0000
68.1600 263.0000 1.0000
68.2000 245.0000 1.0000
68.2400 277.0000 1.0000
68.2800 251.0000 1.0000
68.3200 261.0000 1.0000
68.3600 246.0000 1.0000
68.4000 233.0000 1.0000
68.4400 255.0000 1.0000
68.4800 246.0000 1.0000
68.5200 250.0000 1.0000
68.5600 236.0000 1.0000
68.6000 229.0000 1.0000
68.6400 244.0000 1.0000
68.6800 224.0000 1.0000
68.7200 230.0000 1.0000
68.7600 239.0000 1.0000
68.8000 261.0000 1.0000
68.8400 240.0000 1.0000
68.8800 262.0000 1.0000
68.9200 245.0000 1.0000
68.9600 253.0000 1.0000
69.0000 220.0000 1.0000
69.0400 274.0000 1.0000
69.0800 215.0000 1.0000
69.1200 230.0000 1.0000
69.1600 229.0000 1.0000
69.2000 271.0000 1.0000
69.2400 226.0000 1.0000
69.2800 243.0000 1.0000
69.3200 232.0000 1.0000
69.3600 244.0000 1.0000
69.4000 241.0000 1.0000
69.4400 242.0000 1.0000
69.4800 242.0000 1.0000
69.5200 229.0000 1.0000
69.5600 252.0000 1.0000
69.6000 208.0000 1.0000
69.6400 230.0000 1.0000
69.6800 236.0000 1.0000
69.7200 258.0000 1.0000
69.7600 231.0000 1.0000
69.8000 235.0000 1.0000
69.8400 222.0000 1.0000
69.8800 273.0000 1.0000
69.9200 236.0000 1.0000
69.9600 227.0000 1.0000
70.0000 241.0000 1.0000
*RAS_INT_END
*RAS_TEMPERATURE_START
*RAS_TEMPERATURE_END
*RAS_DATA_END